ts_recv,ts_event,rtype,publisher_id,instrument_id,action,side,depth,price,size,flags,ts_in_delta,sequence,bid_px_00,ask_px_00,bid_sz_00,ask_sz_00,bid_ct_00,ask_ct_00,bid_px_01,ask_px_01,bid_sz_01,ask_sz_01,bid_ct_01,ask_ct_01,bid_px_02,ask_px_02,bid_sz_02,ask_sz_02,bid_ct_02,ask_ct_02,bid_px_03,ask_px_03,bid_sz_03,ask_sz_03,bid_ct_03,ask_ct_03,bid_px_04,ask_px_04,bid_sz_04,ask_sz_04,bid_ct_04,ask_ct_04,bid_px_05,ask_px_05,bid_sz_05,ask_sz_05,bid_ct_05,ask_ct_05,bid_px_06,ask_px_06,bid_sz_06,ask_sz_06,bid_ct_06,ask_ct_06,bid_px_07,ask_px_07,bid_sz_07,ask_sz_07,bid_ct_07,ask_ct_07,bid_px_08,ask_px_08,bid_sz_08,ask_sz_08,bid_ct_08,ask_ct_08,bid_px_09,ask_px_09,bid_sz_09,ask_sz_09,bid_ct_09,ask_ct_09,symbol
2025-06-11T00:00:04.462534683Z,2025-06-11T00:00:04.462435379Z,10,1,42026514,M,A,3,64.820000000,1,130,15202,79298037,64.770000000,64.790000000,9,4,5,2,64.760000000,64.800000000,8,3,8,3,64.750000000,64.810000000,6,4,6,4,64.740000000,64.820000000,12,10,11,7,64.730000000,64.830000000,6,9,6,9,64.720000000,64.840000000,8,6,5,5,64.710000000,64.850000000,8,9,7,6,64.700000000,64.860000000,7,4,6,3,64.690000000,64.870000000,4,4,3,3,64.680000000,64.880000000,4,4,2,3,MCLN5
2025-06-11T00:00:04.462542639Z,2025-06-11T00:00:04.462436127Z,10,1,42026514,M,A,3,64.820000000,1,130,11355,79298038,64.770000000,64.790000000,9,4,5,2,64.760000000,64.800000000,8,3,8,3,64.750000000,64.810000000,6,4,6,4,64.740000000,64.820000000,12,11,11,8,64.730000000,64.830000000,6,8,6,8,64.720000000,64.840000000,8,6,5,5,64.710000000,64.850000000,8,9,7,6,64.700000000,64.860000000,7,4,6,3,64.690000000,64.870000000,4,4,3,3,64.680000000,64.880000000,4,4,2,3,MCLN5
2025-06-11T00:00:04.462550480Z,2025-06-11T00:00:04.462437107Z,10,1,42026514,C,B,4,64.730000000,1,130,11285,79298039,64.770000000,64.790000000,9,4,5,2,64.760000000,64.800000000,8,3,8,3,64.750000000,64.810000000,6,4,6,4,64.740000000,64.820000000,12,11,11,8,64.730000000,64.830000000,5,8,5,8,64.720000000,64.840000000,8,6,5,5,64.710000000,64.850000000,8,9,7,6,64.700000000,64.860000000,7,4,6,3,64.690000000,64.870000000,4,4,3,3,64.680000000,64.880000000,4,4,2,3,MCLN5
2025-06-11T00:00:04.479526812Z,2025-06-11T00:00:04.479413533Z,10,1,42026514,A,B,5,64.720000000,1,130,15330,79298043,64.770000000,64.790000000,9,4,5,2,64.760000000,64.800000000,8,3,8,3,64.750000000,64.810000000,6,4,6,4,64.740000000,64.820000000,12,11,11,8,64.730000000,64.830000000,5,8,5,8,64.720000000,64.840000000,9,6,6,5,64.710000000,64.850000000,8,9,7,6,64.700000000,64.860000000,7,4,6,3,64.690000000,64.870000000,4,4,3,3,64.680000000,64.880000000,4,4,2,3,MCLN5
2025-06-11T00:00:04.479535128Z,2025-06-11T00:00:04.479415031Z,10,1,42026514,C,A,6,64.850000000,1,130,11471,79298044,64.770000000,64.790000000,9,4,5,2,64.760000000,64.800000000,8,3,8,3,64.750000000,64.810000000,6,4,6,4,64.740000000,64.820000000,12,11,11,8,64.730000000,64.830000000,5,8,5,8,64.720000000,64.840000000,9,6,6,5,64.710000000,64.850000000,8,8,7,5,64.700000000,64.860000000,7,4,6,3,64.690000000,64.870000000,4,4,3,3,64.680000000,64.880000000,4,4,2,3,MCLN5
2025-06-11T00:00:04.479664046Z,2025-06-11T00:00:04.479562519Z,10,1,42026514,A,A,5,64.840000000,1,130,15089,79298045,64.770000000,64.790000000,9,4,5,2,64.760000000,64.800000000,8,3,8,3,64.750000000,64.810000000,6,4,6,4,64.740000000,64.820000000,12,11,11,8,64.730000000,64.830000000,5,8,5,8,64.720000000,64.840000000,9,7,6,6,64.710000000,64.850000000,8,8,7,5,64.700000000,64.860000000,7,4,6,3,64.690000000,64.870000000,4,4,3,3,64.680000000,64.880000000,4,4,2,3,MCLN5
2025-06-11T00:00:04.703242291Z,2025-06-11T00:00:04.703078977Z,10,1,42026514,A,B,0,64.780000000,1,130,17173,79298108,64.780000000,64.790000000,1,4,1,2,64.770000000,64.800000000,9,3,5,3,64.760000000,64.810000000,8,4,8,4,64.750000000,64.820000000,6,11,6,8,64.740000000,64.830000000,12,8,11,8,64.730000000,64.840000000,5,7,5,6,64.720000000,64.850000000,9,8,6,5,64.710000000,64.860000000,8,4,7,3,64.700000000,64.870000000,7,4,6,3,64.690000000,64.880000000,4,4,3,3,MCLN5
2025-06-11T00:00:04.703341495Z,2025-06-11T00:00:04.703250597Z,10,1,42026514,C,A,5,64.840000000,1,130,14674,79298109,64.780000000,64.790000000,1,4,1,2,64.770000000,64.800000000,9,3,5,3,64.760000000,64.810000000,8,4,8,4,64.750000000,64.820000000,6,11,6,8,64.740000000,64.830000000,12,8,11,8,64.730000000,64.840000000,5,6,5,5,64.720000000,64.850000000,9,8,6,5,64.710000000,64.860000000,8,4,7,3,64.700000000,64.870000000,7,4,6,3,64.690000000,64.880000000,4,4,3,3,MCLN5
2025-06-11T00:00:04.703349253Z,2025-06-11T00:00:04.703256837Z,10,1,42026514,M,B,4,64.730000000,1,130,11832,79298110,64.780000000,64.790000000,1,4,1,2,64.770000000,64.800000000,9,3,5,3,64.760000000,64.810000000,8,4,8,4,64.750000000,64.820000000,6,11,6,8,64.740000000,64.830000000,11,8,10,8,64.730000000,64.840000000,6,6,6,5,64.720000000,64.850000000,9,8,6,5,64.710000000,64.860000000,8,4,7,3,64.700000000,64.870000000,7,4,6,3,64.690000000,64.880000000,4,4,3,3,MCLN5
2025-06-11T00:00:04.703363552Z,2025-06-11T00:00:04.703257355Z,10,1,42026514,M,A,3,64.820000000,1,130,11473,79298111,64.780000000,64.790000000,1,4,1,2,64.770000000,64.800000000,9,3,5,3,64.760000000,64.810000000,8,4,8,4,64.750000000,64.820000000,6,12,6,9,64.740000000,64.830000000,11,7,10,7,64.730000000,64.840000000,6,6,6,5,64.720000000,64.850000000,9,8,6,5,64.710000000,64.860000000,8,4,7,3,64.700000000,64.870000000,7,4,6,3,64.690000000,64.880000000,4,4,3,3,MCLN5
2025-06-11T00:00:04.717477090Z,2025-06-11T00:00:04.717372591Z,10,1,42026514,C,B,6,64.720000000,1,130,15234,79298115,64.780000000,64.790000000,1,4,1,2,64.770000000,64.800000000,9,3,5,3,64.760000000,64.810000000,8,4,8,4,64.750000000,64.820000000,6,12,6,9,64.740000000,64.830000000,11,7,10,7,64.730000000,64.840000000,6,6,6,5,64.720000000,64.850000000,8,8,5,5,64.710000000,64.860000000,8,4,7,3,64.700000000,64.870000000,7,4,6,3,64.690000000,64.880000000,4,4,3,3,MCLN5
2025-06-11T00:00:04.717485945Z,2025-06-11T00:00:04.717375279Z,10,1,42026514,A,A,6,64.850000000,1,130,11932,79298116,64.780000000,64.790000000,1,4,1,2,64.770000000,64.800000000,9,3,5,3,64.760000000,64.810000000,8,4,8,4,64.750000000,64.820000000,6,12,6,9,64.740000000,64.830000000,11,7,10,7,64.730000000,64.840000000,6,6,6,5,64.720000000,64.850000000,8,9,5,6,64.710000000,64.860000000,8,4,7,3,64.700000000,64.870000000,7,4,6,3,64.690000000,64.880000000,4,4,3,3,MCLN5
2025-06-11T00:00:04.717598266Z,2025-06-11T00:00:04.717503509Z,10,1,42026514,A,B,5,64.730000000,1,130,14643,79298117,64.780000000,64.790000000,1,4,1,2,64.770000000,64.800000000,9,3,5,3,64.760000000,64.810000000,8,4,8,4,64.750000000,64.820000000,6,12,6,9,64.740000000,64.830000000,11,7,10,7,64.730000000,64.840000000,7,6,7,5,64.720000000,64.850000000,8,9,5,6,64.710000000,64.860000000,8,4,7,3,64.700000000,64.870000000,7,4,6,3,64.690000000,64.880000000,4,4,3,3,MCLN5
2025-06-11T00:00:04.783110350Z,2025-06-11T00:00:04.782917359Z,10,1,42284507,M,B,0,0.960000000,3,130,13206,79298143,0.990000000,1.000000000,9,5,5,3,0.980000000,1.010000000,23,25,7,8,0.970000000,1.020000000,21,18,6,5,0.960000000,1.030000000,20,23,7,7,0.950000000,1.040000000,10,15,6,4,0.940000000,1.050000000,4,8,3,4,0.930000000,1.060000000,3,4,2,2,0.920000000,1.070000000,3,2,2,1,0.910000000,1.080000000,3,2,2,1,0.900000000,1.090000000,2,4,1,2,MCLQ5-MCLU5
2025-06-11T00:00:04.784772168Z,2025-06-11T00:00:04.783134925Z,10,1,42284507,A,A,0,1.000000000,3,130,15235,79298144,0.990000000,1.000000000,9,8,5,4,0.980000000,1.010000000,23,25,7,8,0.970000000,1.020000000,21,18,6,5,0.960000000,1.030000000,20,23,7,7,0.950000000,1.040000000,10,15,6,4,0.940000000,1.050000000,4,8,3,4,0.930000000,1.060000000,3,4,2,2,0.920000000,1.070000000,3,2,2,1,0.910000000,1.080000000,3,2,2,1,0.900000000,1.090000000,2,4,1,2,MCLQ5-MCLU5
2025-06-11T00:00:04.784894289Z,2025-06-11T00:00:04.784783787Z,10,1,42284507,M,A,0,1.000000000,3,130,15048,79298145,0.990000000,1.000000000,9,11,5,5,0.980000000,1.010000000,23,25,7,8,0.970000000,1.020000000,21,18,6,5,0.960000000,1.030000000,20,20,7,6,0.950000000,1.040000000,10,15,6,4,0.940000000,1.050000000,4,8,3,4,0.930000000,1.060000000,3,4,2,2,0.920000000,1.070000000,3,2,2,1,0.910000000,1.080000000,3,2,2,1,0.900000000,1.090000000,2,4,1,2,MCLQ5-MCLU5
2025-06-11T00:00:04.785327026Z,2025-06-11T00:00:04.784900633Z,10,1,42284507,M,B,2,0.960000000,3,130,14764,79298146,0.990000000,1.000000000,9,11,5,5,0.980000000,1.010000000,23,25,7,8,0.970000000,1.020000000,18,18,5,5,0.960000000,1.030000000,23,20,8,6,0.950000000,1.040000000,10,15,6,4,0.940000000,1.050000000,4,8,3,4,0.930000000,1.060000000,3,4,2,2,0.920000000,1.070000000,3,2,2,1,0.910000000,1.080000000,3,2,2,1,0.900000000,1.090000000,2,4,1,2,MCLQ5-MCLU5
2025-06-11T00:00:04.785335013Z,2025-06-11T00:00:04.784901111Z,10,1,42284507,M,A,2,1.020000000,3,130,11476,79298147,0.990000000,1.000000000,9,11,5,5,0.980000000,1.010000000,23,25,7,8,0.970000000,1.020000000,18,21,5,6,0.960000000,1.030000000,23,17,8,5,0.950000000,1.040000000,10,15,6,4,0.940000000,1.050000000,4,8,3,4,0.930000000,1.060000000,3,4,2,2,0.920000000,1.070000000,3,2,2,1,0.910000000,1.080000000,3,2,2,1,0.900000000,1.090000000,2,4,1,2,MCLQ5-MCLU5
2025-06-11T00:00:04.785344213Z,2025-06-11T00:00:04.784911689Z,10,1,42284507,M,B,0,0.890000000,2,130,11363,79298148,0.990000000,1.000000000,8,11,4,5,0.980000000,1.010000000,23,25,7,8,0.970000000,1.020000000,18,21,5,6,0.960000000,1.030000000,23,17,8,5,0.950000000,1.040000000,10,15,6,4,0.940000000,1.050000000,4,8,3,4,0.930000000,1.060000000,3,4,2,2,0.920000000,1.070000000,3,2,2,1,0.910000000,1.080000000,3,2,2,1,0.900000000,1.090000000,2,4,1,2,MCLQ5-MCLU5
2025-06-11T00:00:04.785356670Z,2025-06-11T00:00:04.784924745Z,10,1,42284507,M,B,0,0.880000000,2,130,11691,79298149,0.990000000,1.000000000,7,11,3,5,0.980000000,1.010000000,23,25,7,8,0.970000000,1.020000000,18,21,5,6,0.960000000,1.030000000,23,17,8,5,0.950000000,1.040000000,10,15,6,4,0.940000000,1.050000000,4,8,3,4,0.930000000,1.060000000,3,4,2,2,0.920000000,1.070000000,3,2,2,1,0.910000000,1.080000000,3,2,2,1,0.900000000,1.090000000,2,4,1,2,MCLQ5-MCLU5
2025-06-11T00:00:05.359634136Z,2025-06-11T00:00:05.359511469Z,10,1,42026514,A,B,0,64.780000000,1,130,17598,79299223,64.780000000,64.790000000,2,4,2,2,64.770000000,64.800000000,9,3,5,3,64.760000000,64.810000000,8,4,8,4,64.750000000,64.820000000,6,12,6,9,64.740000000,64.830000000,11,7,10,7,64.730000000,64.840000000,7,6,7,5,64.720000000,64.850000000,8,9,5,6,64.710000000,64.860000000,8,4,7,3,64.700000000,64.870000000,7,4,6,3,64.690000000,64.880000000,4,4,3,3,MCLN5
2025-06-11T00:00:05.359802296Z,2025-06-11T00:00:05.359681747Z,10,1,42025623,A,B,0,63.690000000,1,130,16082,79299226,63.690000000,63.710000000,2,1,2,1,63.680000000,63.720000000,1,3,1,3,63.670000000,63.730000000,2,2,2,2,63.660000000,63.740000000,3,3,3,3,63.650000000,63.750000000,5,5,5,5,63.640000000,63.760000000,5,3,5,3,63.630000000,63.770000000,5,2,5,2,63.620000000,63.780000000,3,4,3,4,63.610000000,63.790000000,2,1,2,1,63.600000000,63.800000000,6,3,6,3,MCLQ5
2025-06-11T00:00:05.391541371Z,2025-06-11T00:00:05.391350093Z,10,1,42026514,C,B,0,64.780000000,1,130,15454,79299248,64.780000000,64.790000000,1,4,1,2,64.770000000,64.800000000,9,3,5,3,64.760000000,64.810000000,8,4,8,4,64.750000000,64.820000000,6,12,6,9,64.740000000,64.830000000,11,7,10,7,64.730000000,64.840000000,7,6,7,5,64.720000000,64.850000000,8,9,5,6,64.710000000,64.860000000,8,4,7,3,64.700000000,64.870000000,7,4,6,3,64.690000000,64.880000000,4,4,3,3,MCLN5
2025-06-11T00:00:05.396908164Z,2025-06-11T00:00:05.391916719Z,10,1,42025623,C,B,0,63.690000000,1,130,13402,79299274,63.690000000,63.710000000,1,1,1,1,63.680000000,63.720000000,1,3,1,3,63.670000000,63.730000000,2,2,2,2,63.660000000,63.740000000,3,3,3,3,63.650000000,63.750000000,5,5,5,5,63.640000000,63.760000000,5,3,5,3,63.630000000,63.770000000,5,2,5,2,63.620000000,63.780000000,3,4,3,4,63.610000000,63.790000000,2,1,2,1,63.600000000,63.800000000,6,3,6,3,MCLQ5
2025-06-11T00:00:05.491985651Z,2025-06-11T00:00:05.491868017Z,10,1,42026514,A,B,0,64.780000000,1,130,17785,79299356,64.780000000,64.790000000,2,4,2,2,64.770000000,64.800000000,9,3,5,3,64.760000000,64.810000000,8,4,8,4,64.750000000,64.820000000,6,12,6,9,64.740000000,64.830000000,11,7,10,7,64.730000000,64.840000000,7,6,7,5,64.720000000,64.850000000,8,9,5,6,64.710000000,64.860000000,8,4,7,3,64.700000000,64.870000000,7,4,6,3,64.690000000,64.880000000,4,4,3,3,MCLN5
2025-06-11T00:00:06.020241258Z,2025-06-11T00:00:06.019922777Z,10,1,42025611,A,A,0,2.080000000,3,130,11565,79299452,2.070000000,2.080000000,3,3,2,1,2.060000000,2.090000000,23,27,3,6,2.050000000,2.100000000,23,27,3,6,2.040000000,2.110000000,23,23,3,4,2.030000000,2.120000000,2,2,1,1,2.020000000,2.130000000,2,2,2,2,2.010000000,2.140000000,2,2,1,1,2.000000000,2.150000000,2,2,2,1,1.990000000,2.160000000,2,2,1,1,1.980000000,2.170000000,2,2,2,1,MCLN5-MCLU5
2025-06-11T00:00:06.023185393Z,2025-06-11T00:00:06.019941399Z,10,1,42026514,C,B,0,64.780000000,1,130,17506,79299455,64.780000000,64.790000000,1,4,1,2,64.770000000,64.800000000,9,3,5,3,64.760000000,64.810000000,8,4,8,4,64.750000000,64.820000000,6,12,6,9,64.740000000,64.830000000,11,7,10,7,64.730000000,64.840000000,7,6,7,5,64.720000000,64.850000000,8,9,5,6,64.710000000,64.860000000,8,4,7,3,64.700000000,64.870000000,7,4,6,3,64.690000000,64.880000000,4,4,3,3,MCLN5
2025-06-11T00:00:06.023196152Z,2025-06-11T00:00:06.020137559Z,10,1,42026514,C,B,1,64.770000000,1,130,12904,79299456,64.780000000,64.790000000,1,4,1,2,64.770000000,64.800000000,8,3,4,3,64.760000000,64.810000000,8,4,8,4,64.750000000,64.820000000,6,12,6,9,64.740000000,64.830000000,11,7,10,7,64.730000000,64.840000000,7,6,7,5,64.720000000,64.850000000,8,9,5,6,64.710000000,64.860000000,8,4,7,3,64.700000000,64.870000000,7,4,6,3,64.690000000,64.880000000,4,4,3,3,MCLN5
2025-06-11T00:00:06.023297983Z,2025-06-11T00:00:06.020173461Z,10,1,42026514,A,A,0,64.790000000,1,130,12861,79299461,64.780000000,64.790000000,1,5,1,3,64.770000000,64.800000000,8,3,4,3,64.760000000,64.810000000,8,4,8,4,64.750000000,64.820000000,6,12,6,9,64.740000000,64.830000000,11,7,10,7,64.730000000,64.840000000,7,6,7,5,64.720000000,64.850000000,8,9,5,6,64.710000000,64.860000000,8,4,7,3,64.700000000,64.870000000,7,4,6,3,64.690000000,64.880000000,4,4,3,3,MCLN5
2025-06-11T00:00:06.023331589Z,2025-06-11T00:00:06.020180717Z,10,1,42026514,C,B,0,64.780000000,1,130,11785,79299463,64.770000000,64.790000000,8,5,4,3,64.760000000,64.800000000,8,3,8,3,64.750000000,64.810000000,6,4,6,4,64.740000000,64.820000000,11,12,10,9,64.730000000,64.830000000,7,7,7,7,64.720000000,64.840000000,8,6,5,5,64.710000000,64.850000000,8,9,7,6,64.700000000,64.860000000,7,4,6,3,64.690000000,64.870000000,4,4,3,3,64.680000000,64.880000000,4,4,2,3,MCLN5
2025-06-11T00:00:06.023924454Z,2025-06-11T00:00:06.020552757Z,10,1,42025623,A,A,0,63.710000000,1,130,12763,79299498,63.690000000,63.710000000,1,2,1,2,63.680000000,63.720000000,1,3,1,3,63.670000000,63.730000000,2,2,2,2,63.660000000,63.740000000,3,3,3,3,63.650000000,63.750000000,5,5,5,5,63.640000000,63.760000000,5,3,5,3,63.630000000,63.770000000,5,2,5,2,63.620000000,63.780000000,3,4,3,4,63.610000000,63.790000000,2,1,2,1,63.600000000,63.800000000,6,3,6,3,MCLQ5
2025-06-11T00:00:06.024957705Z,2025-06-11T00:00:06.021075761Z,10,1,42025611,C,B,0,2.070000000,2,130,11596,79299558,2.070000000,2.080000000,1,3,1,1,2.060000000,2.090000000,23,27,3,6,2.050000000,2.100000000,23,27,3,6,2.040000000,2.110000000,23,23,3,4,2.030000000,2.120000000,2,2,1,1,2.020000000,2.130000000,2,2,2,2,2.010000000,2.140000000,2,2,1,1,2.000000000,2.150000000,2,2,2,1,1.990000000,2.160000000,2,2,1,1,1.980000000,2.170000000,2,2,2,1,MCLN5-MCLU5
2025-06-11T00:00:06.025040552Z,2025-06-11T00:00:06.023197135Z,10,1,42026514,C,A,0,64.790000000,1,130,13316,79299564,64.770000000,64.790000000,8,4,4,2,64.760000000,64.800000000,8,3,8,3,64.750000000,64.810000000,6,4,6,4,64.740000000,64.820000000,11,12,10,9,64.730000000,64.830000000,7,7,7,7,64.720000000,64.840000000,8,6,5,5,64.710000000,64.850000000,8,9,7,6,64.700000000,64.860000000,7,4,6,3,64.690000000,64.870000000,4,4,3,3,64.680000000,64.880000000,4,4,2,3,MCLN5
2025-06-11T00:00:06.025065765Z,2025-06-11T00:00:06.023339399Z,10,1,42026514,M,A,3,64.830000000,1,130,11589,79299566,64.770000000,64.790000000,8,4,4,2,64.760000000,64.800000000,8,3,8,3,64.750000000,64.810000000,6,4,6,4,64.740000000,64.820000000,11,11,10,8,64.730000000,64.830000000,7,8,7,8,64.720000000,64.840000000,8,6,5,5,64.710000000,64.850000000,8,9,7,6,64.700000000,64.860000000,7,4,6,3,64.690000000,64.870000000,4,4,3,3,64.680000000,64.880000000,4,4,2,3,MCLN5
2025-06-11T00:00:06.025076608Z,2025-06-11T00:00:06.023340015Z,10,1,42026514,M,B,3,64.740000000,1,130,11831,79299567,64.770000000,64.790000000,8,4,4,2,64.760000000,64.800000000,8,3,8,3,64.750000000,64.810000000,6,4,6,4,64.740000000,64.820000000,12,11,11,8,64.730000000,64.830000000,6,8,6,8,64.720000000,64.840000000,8,6,5,5,64.710000000,64.850000000,8,9,7,6,64.700000000,64.860000000,7,4,6,3,64.690000000,64.870000000,4,4,3,3,64.680000000,64.880000000,4,4,2,3,MCLN5
2025-06-11T00:00:06.025087045Z,2025-06-11T00:00:06.023341473Z,10,1,42026514,C,B,4,64.730000000,1,130,12569,79299568,64.770000000,64.790000000,8,4,4,2,64.760000000,64.800000000,8,3,8,3,64.750000000,64.810000000,6,4,6,4,64.740000000,64.820000000,12,11,11,8,64.730000000,64.830000000,5,8,5,8,64.720000000,64.840000000,8,6,5,5,64.710000000,64.850000000,8,9,7,6,64.700000000,64.860000000,7,4,6,3,64.690000000,64.870000000,4,4,3,3,64.680000000,64.880000000,4,4,2,3,MCLN5
2025-06-11T00:00:06.025117164Z,2025-06-11T00:00:06.023344909Z,10,1,42026514,A,A,0,64.780000000,1,130,15561,79299569,64.770000000,64.780000000,8,1,4,1,64.760000000,64.790000000,8,4,8,2,64.750000000,64.800000000,6,3,6,3,64.740000000,64.810000000,12,4,11,4,64.730000000,64.820000000,5,11,5,8,64.720000000,64.830000000,8,8,5,8,64.710000000,64.840000000,8,6,7,5,64.700000000,64.850000000,7,9,6,6,64.690000000,64.860000000,4,4,3,3,64.680000000,64.870000000,4,4,2,3,MCLN5
2025-06-11T00:00:06.025145678Z,2025-06-11T00:00:06.023369119Z,10,1,42026514,M,A,1,64.790000000,1,130,11699,79299572,64.770000000,64.780000000,8,1,4,1,64.760000000,64.790000000,8,5,8,3,64.750000000,64.800000000,6,3,6,3,64.740000000,64.810000000,12,4,11,4,64.730000000,64.820000000,5,11,5,8,64.720000000,64.830000000,8,8,5,8,64.710000000,64.840000000,8,6,7,5,64.700000000,64.850000000,7,9,6,6,64.690000000,64.860000000,4,4,3,3,64.680000000,64.870000000,4,4,2,3,MCLN5
2025-06-11T00:00:06.026062300Z,2025-06-11T00:00:06.023568081Z,10,1,42026514,M,A,2,64.800000000,1,130,11599,79299622,64.770000000,64.780000000,8,1,4,1,64.760000000,64.790000000,8,5,8,3,64.750000000,64.800000000,6,4,6,4,64.740000000,64.810000000,12,4,11,4,64.730000000,64.820000000,5,11,5,8,64.720000000,64.830000000,8,8,5,8,64.710000000,64.840000000,8,6,7,5,64.700000000,64.850000000,7,9,6,6,64.690000000,64.860000000,4,4,3,3,64.680000000,64.870000000,4,4,2,3,MCLN5
2025-06-11T00:00:06.027933264Z,2025-06-11T00:00:06.025053251Z,10,1,42026514,A,A,1,64.790000000,1,130,13568,79299759,64.770000000,64.780000000,8,1,4,1,64.760000000,64.790000000,8,6,8,4,64.750000000,64.800000000,6,4,6,4,64.740000000,64.810000000,12,4,11,4,64.730000000,64.820000000,5,11,5,8,64.720000000,64.830000000,8,8,5,8,64.710000000,64.840000000,8,6,7,5,64.700000000,64.850000000,7,9,6,6,64.690000000,64.860000000,4,4,3,3,64.680000000,64.870000000,4,4,2,3,MCLN5
2025-06-11T00:00:06.027975970Z,2025-06-11T00:00:06.025086101Z,10,1,42026514,C,A,0,64.780000000,1,130,15324,79299761,64.770000000,64.790000000,8,6,4,4,64.760000000,64.800000000,8,4,8,4,64.750000000,64.810000000,6,4,6,4,64.740000000,64.820000000,12,11,11,8,64.730000000,64.830000000,5,8,5,8,64.720000000,64.840000000,8,6,5,5,64.710000000,64.850000000,8,9,7,6,64.700000000,64.860000000,7,4,6,3,64.690000000,64.870000000,4,4,3,3,64.680000000,64.880000000,4,4,2,3,MCLN5
2025-06-11T00:00:06.028134431Z,2025-06-11T00:00:06.025320811Z,10,1,42026514,M,B,0,62.810000000,2,130,13834,79299775,64.770000000,64.790000000,7,6,3,4,64.760000000,64.800000000,8,4,8,4,64.750000000,64.810000000,6,4,6,4,64.740000000,64.820000000,12,11,11,8,64.730000000,64.830000000,5,8,5,8,64.720000000,64.840000000,8,6,5,5,64.710000000,64.850000000,8,9,7,6,64.700000000,64.860000000,7,4,6,3,64.690000000,64.870000000,4,4,3,3,64.680000000,64.880000000,4,4,2,3,MCLN5
2025-06-11T00:00:06.028206128Z,2025-06-11T00:00:06.025348091Z,10,1,42026514,M,B,3,64.730000000,1,130,11777,79299781,64.770000000,64.790000000,7,6,3,4,64.760000000,64.800000000,8,4,8,4,64.750000000,64.810000000,6,4,6,4,64.740000000,64.820000000,11,11,10,8,64.730000000,64.830000000,6,8,6,8,64.720000000,64.840000000,8,6,5,5,64.710000000,64.850000000,8,9,7,6,64.700000000,64.860000000,7,4,6,3,64.690000000,64.870000000,4,4,3,3,64.680000000,64.880000000,4,4,2,3,MCLN5
2025-06-11T00:00:06.028216679Z,2025-06-11T00:00:06.025348553Z,10,1,42026514,M,A,3,64.820000000,1,130,11787,79299782,64.770000000,64.790000000,7,6,3,4,64.760000000,64.800000000,8,4,8,4,64.750000000,64.810000000,6,4,6,4,64.740000000,64.820000000,11,12,10,9,64.730000000,64.830000000,6,7,6,7,64.720000000,64.840000000,8,6,5,5,64.710000000,64.850000000,8,9,7,6,64.700000000,64.860000000,7,4,6,3,64.690000000,64.870000000,4,4,3,3,64.680000000,64.880000000,4,4,2,3,MCLN5
2025-06-11T00:00:06.028395269Z,2025-06-11T00:00:06.025377523Z,10,1,42026514,A,A,0,64.780000000,1,130,11595,79299794,64.770000000,64.780000000,7,1,3,1,64.760000000,64.790000000,8,6,8,4,64.750000000,64.800000000,6,4,6,4,64.740000000,64.810000000,11,4,10,4,64.730000000,64.820000000,6,12,6,9,64.720000000,64.830000000,8,7,5,7,64.710000000,64.840000000,8,6,7,5,64.700000000,64.850000000,7,9,6,6,64.690000000,64.860000000,4,4,3,3,64.680000000,64.870000000,4,4,2,3,MCLN5
2025-06-11T00:00:06.030528315Z,2025-06-11T00:00:06.028337555Z,10,1,42026514,M,A,4,64.830000000,1,130,11508,79299963,64.770000000,64.780000000,7,1,3,1,64.760000000,64.790000000,8,6,8,4,64.750000000,64.800000000,6,4,6,4,64.740000000,64.810000000,11,4,10,4,64.730000000,64.820000000,6,11,6,8,64.720000000,64.830000000,8,8,5,8,64.710000000,64.840000000,8,6,7,5,64.700000000,64.850000000,7,9,6,6,64.690000000,64.860000000,4,4,3,3,64.680000000,64.870000000,4,4,2,3,MCLN5
2025-06-11T00:00:06.030825315Z,2025-06-11T00:00:06.028343543Z,10,1,42026514,A,A,0,64.780000000,1,130,11932,79299979,64.770000000,64.780000000,7,2,3,2,64.760000000,64.790000000,8,6,8,4,64.750000000,64.800000000,6,4,6,4,64.740000000,64.810000000,11,4,10,4,64.730000000,64.820000000,6,11,6,8,64.720000000,64.830000000,8,8,5,8,64.710000000,64.840000000,8,6,7,5,64.700000000,64.850000000,7,9,6,6,64.690000000,64.860000000,4,4,3,3,64.680000000,64.870000000,4,4,2,3,MCLN5
2025-06-11T00:00:06.031246188Z,2025-06-11T00:00:06.028798525Z,10,1,42463766,C,B,0,1.080000000,7,130,11758,79300007,1.080000000,1.090000000,8,29,2,12,1.070000000,1.100000000,61,56,19,14,1.060000000,1.110000000,52,57,14,13,1.050000000,1.120000000,56,54,13,12,1.040000000,1.130000000,52,40,11,10,1.030000000,1.140000000,39,38,9,8,1.020000000,1.150000000,38,41,8,10,1.010000000,1.160000000,35,36,8,7,1.000000000,1.170000000,40,38,9,9,0.990000000,1.180000000,35,37,8,9,MCLN5-MCLQ5
2025-06-11T00:00:06.031255419Z,2025-06-11T00:00:06.028799369Z,10,1,42463766,C,B,0,1.080000000,5,130,11712,79300008,1.080000000,1.090000000,3,29,1,12,1.070000000,1.100000000,61,56,19,14,1.060000000,1.110000000,52,57,14,13,1.050000000,1.120000000,56,54,13,12,1.040000000,1.130000000,52,40,11,10,1.030000000,1.140000000,39,38,9,8,1.020000000,1.150000000,38,41,8,10,1.010000000,1.160000000,35,36,8,7,1.000000000,1.170000000,40,38,9,9,0.990000000,1.180000000,35,37,8,9,MCLN5-MCLQ5
2025-06-11T00:00:06.031856194Z,2025-06-11T00:00:06.030419375Z,10,1,42025611,M,A,0,2.080000000,1,130,11575,79300059,2.070000000,2.080000000,1,4,1,2,2.060000000,2.090000000,23,27,3,6,2.050000000,2.100000000,23,27,3,6,2.040000000,2.110000000,23,22,3,3,2.030000000,2.120000000,2,2,1,1,2.020000000,2.130000000,2,2,2,2,2.010000000,2.140000000,2,2,1,1,2.000000000,2.150000000,2,2,2,1,1.990000000,2.160000000,2,2,1,1,1.980000000,2.170000000,2,2,2,1,MCLN5-MCLU5
2025-06-11T00:00:06.031948195Z,2025-06-11T00:00:06.030869229Z,10,1,42025623,M,B,4,63.640000000,1,130,12022,79300066,63.690000000,63.710000000,1,2,1,2,63.680000000,63.720000000,1,3,1,3,63.670000000,63.730000000,2,2,2,2,63.660000000,63.740000000,3,3,3,3,63.650000000,63.750000000,4,5,4,5,63.640000000,63.760000000,6,3,6,3,63.630000000,63.770000000,5,2,5,2,63.620000000,63.780000000,3,4,3,4,63.610000000,63.790000000,2,1,2,1,63.600000000,63.800000000,6,3,6,3,MCLQ5
2025-06-11T00:00:06.031959177Z,2025-06-11T00:00:06.030869731Z,10,1,42025623,M,A,3,63.740000000,1,130,12033,79300067,63.690000000,63.710000000,1,2,1,2,63.680000000,63.720000000,1,3,1,3,63.670000000,63.730000000,2,2,2,2,63.660000000,63.740000000,3,4,3,4,63.650000000,63.750000000,4,4,4,4,63.640000000,63.760000000,6,3,6,3,63.630000000,63.770000000,5,2,5,2,63.620000000,63.780000000,3,4,3,4,63.610000000,63.790000000,2,1,2,1,63.600000000,63.800000000,6,3,6,3,MCLQ5
2025-06-11T00:00:06.031970527Z,2025-06-11T00:00:06.030870287Z,10,1,42025623,M,B,4,63.640000000,1,130,11963,79300068,63.690000000,63.710000000,1,2,1,2,63.680000000,63.720000000,1,3,1,3,63.670000000,63.730000000,2,2,2,2,63.660000000,63.740000000,3,4,3,4,63.650000000,63.750000000,3,4,3,4,63.640000000,63.760000000,7,3,7,3,63.630000000,63.770000000,5,2,5,2,63.620000000,63.780000000,3,4,3,4,63.610000000,63.790000000,2,1,2,1,63.600000000,63.800000000,6,3,6,3,MCLQ5
2025-06-11T00:00:06.031981855Z,2025-06-11T00:00:06.030870805Z,10,1,42025623,M,A,3,63.740000000,1,130,11889,79300069,63.690000000,63.710000000,1,2,1,2,63.680000000,63.720000000,1,3,1,3,63.670000000,63.730000000,2,2,2,2,63.660000000,63.740000000,3,5,3,5,63.650000000,63.750000000,3,3,3,3,63.640000000,63.760000000,7,3,7,3,63.630000000,63.770000000,5,2,5,2,63.620000000,63.780000000,3,4,3,4,63.610000000,63.790000000,2,1,2,1,63.600000000,63.800000000,6,3,6,3,MCLQ5
2025-06-11T00:00:06.032386247Z,2025-06-11T00:00:06.031287023Z,10,1,42284507,C,B,0,0.990000000,4,130,14810,79300095,0.990000000,1.000000000,3,11,2,5,0.980000000,1.010000000,23,25,7,8,0.970000000,1.020000000,18,21,5,6,0.960000000,1.030000000,23,17,8,5,0.950000000,1.040000000,10,15,6,4,0.940000000,1.050000000,4,8,3,4,0.930000000,1.060000000,3,4,2,2,0.920000000,1.070000000,3,2,2,1,0.910000000,1.080000000,3,2,2,1,0.900000000,1.090000000,2,4,1,2,MCLQ5-MCLU5
2025-06-11T00:00:06.032394764Z,2025-06-11T00:00:06.031288099Z,10,1,42022708,M,A,0,2.830000000,10,130,11792,79300096,2.810000000,2.830000000,1,12,1,3,2.800000000,2.840000000,12,2,3,2,2.790000000,2.850000000,2,1,2,1,2.780000000,2.870000000,1,1,1,1,,,0,0,0,0,,,0,0,0,0,,,0,0,0,0,,,0,0,0,0,,,0,0,0,0,,,0,0,0,0,MCLN5-MCLV5
2025-06-11T00:00:06.032624829Z,2025-06-11T00:00:06.031820759Z,10,1,42026514,C,A,0,64.780000000,1,130,16005,79300114,64.770000000,64.780000000,7,1,3,1,64.760000000,64.790000000,8,6,8,4,64.750000000,64.800000000,6,4,6,4,64.740000000,64.810000000,11,4,10,4,64.730000000,64.820000000,6,11,6,8,64.720000000,64.830000000,8,8,5,8,64.710000000,64.840000000,8,6,7,5,64.700000000,64.850000000,7,9,6,6,64.690000000,64.860000000,4,4,3,3,64.680000000,64.870000000,4,4,2,3,MCLN5
2025-06-11T00:00:06.032992559Z,2025-06-11T00:00:06.032414091Z,10,1,42284507,C,B,0,0.990000000,1,130,11688,79300140,0.990000000,1.000000000,2,11,1,5,0.980000000,1.010000000,23,25,7,8,0.970000000,1.020000000,18,21,5,6,0.960000000,1.030000000,23,17,8,5,0.950000000,1.040000000,10,15,6,4,0.940000000,1.050000000,4,8,3,4,0.930000000,1.060000000,3,4,2,2,0.920000000,1.070000000,3,2,2,1,0.910000000,1.080000000,3,2,2,1,0.900000000,1.090000000,2,4,1,2,MCLQ5-MCLU5
2025-06-11T00:00:06.033000315Z,2025-06-11T00:00:06.032432521Z,10,1,42025611,A,A,0,2.080000000,2,130,11467,79300141,2.070000000,2.080000000,1,6,1,3,2.060000000,2.090000000,23,27,3,6,2.050000000,2.100000000,23,27,3,6,2.040000000,2.110000000,23,22,3,3,2.030000000,2.120000000,2,2,1,1,2.020000000,2.130000000,2,2,2,2,2.010000000,2.140000000,2,2,1,1,2.000000000,2.150000000,2,2,2,1,1.990000000,2.160000000,2,2,1,1,1.980000000,2.170000000,2,2,2,1,MCLN5-MCLU5
2025-06-11T00:00:06.033206312Z,2025-06-11T00:00:06.032671531Z,10,1,42418117,M,A,0,3.270000000,1,130,11748,79300158,3.250000000,3.270000000,11,1,2,1,3.240000000,3.280000000,1,1,1,1,3.230000000,3.290000000,1,11,1,2,,,0,0,0,0,,,0,0,0,0,,,0,0,0,0,,,0,0,0,0,,,0,0,0,0,,,0,0,0,0,,,0,0,0,0,MCLN5-MCLX5
2025-06-11T00:00:06.033478247Z,2025-06-11T00:00:06.032818041Z,10,1,42284507,M,B,0,0.990000000,1,130,15859,79300180,0.990000000,1.000000000,3,11,2,5,0.980000000,1.010000000,23,25,7,8,0.970000000,1.020000000,18,21,5,6,0.960000000,1.030000000,23,17,8,5,0.950000000,1.040000000,10,15,6,4,0.940000000,1.050000000,4,8,3,4,0.930000000,1.060000000,3,4,2,2,0.920000000,1.070000000,3,2,2,1,0.910000000,1.080000000,3,2,2,1,0.900000000,1.090000000,2,4,1,2,MCLQ5-MCLU5
2025-06-11T00:00:06.033897609Z,2025-06-11T00:00:06.033510225Z,10,1,42026514,M,A,5,64.830000000,1,130,15297,79300215,64.770000000,64.780000000,7,1,3,1,64.760000000,64.790000000,8,6,8,4,64.750000000,64.800000000,6,4,6,4,64.740000000,64.810000000,11,4,10,4,64.730000000,64.820000000,6,11,6,8,64.720000000,64.830000000,8,9,5,9,64.710000000,64.840000000,8,6,7,5,64.700000000,64.850000000,7,9,6,6,64.690000000,64.860000000,4,4,3,3,64.680000000,64.870000000,4,4,2,3,MCLN5
2025-06-11T00:00:06.033906090Z,2025-06-11T00:00:06.033524069Z,10,1,42284507,C,B,0,0.990000000,2,130,12125,79300216,0.990000000,1.000000000,1,11,1,5,0.980000000,1.010000000,23,25,7,8,0.970000000,1.020000000,18,21,5,6,0.960000000,1.030000000,23,17,8,5,0.950000000,1.040000000,10,15,6,4,0.940000000,1.050000000,4,8,3,4,0.930000000,1.060000000,3,4,2,2,0.920000000,1.070000000,3,2,2,1,0.910000000,1.080000000,3,2,2,1,0.900000000,1.090000000,2,4,1,2,MCLQ5-MCLU5
2025-06-11T00:00:06.034236446Z,2025-06-11T00:00:06.034069017Z,10,1,42284507,M,B,0,0.880000000,2,130,11730,79300241,0.980000000,1.000000000,23,11,7,5,0.970000000,1.010000000,18,25,5,8,0.960000000,1.020000000,23,21,8,6,0.950000000,1.030000000,10,17,6,5,0.940000000,1.040000000,4,15,3,4,0.930000000,1.050000000,3,8,2,4,0.920000000,1.060000000,3,4,2,2,0.910000000,1.070000000,3,2,2,1,0.900000000,1.080000000,2,2,1,1,0.890000000,1.090000000,2,4,1,2,MCLQ5-MCLU5
2025-06-11T00:00:06.034383764Z,2025-06-11T00:00:06.034149615Z,10,1,42418117,M,B,0,3.240000000,10,130,11720,79300252,3.250000000,3.270000000,1,1,1,1,3.240000000,3.280000000,11,1,2,1,3.230000000,3.290000000,1,11,1,2,,,0,0,0,0,,,0,0,0,0,,,0,0,0,0,,,0,0,0,0,,,0,0,0,0,,,0,0,0,0,,,0,0,0,0,MCLN5-MCLX5
2025-06-11T00:00:06.034394730Z,2025-06-11T00:00:06.034150097Z,10,1,42418117,M,A,1,3.280000000,10,130,12708,79300253,3.250000000,3.270000000,1,1,1,1,3.240000000,3.280000000,11,11,2,2,3.230000000,3.290000000,1,1,1,1,,,0,0,0,0,,,0,0,0,0,,,0,0,0,0,,,0,0,0,0,,,0,0,0,0,,,0,0,0,0,,,0,0,0,0,MCLN5-MCLX5
2025-06-11T00:00:06.034624534Z,2025-06-11T00:00:06.034248857Z,10,1,42284507,C,B,3,0.950000000,2,130,16032,79300274,0.980000000,1.000000000,23,11,7,5,0.970000000,1.010000000,18,25,5,8,0.960000000,1.020000000,23,21,8,6,0.950000000,1.030000000,8,17,5,5,0.940000000,1.040000000,4,15,3,4,0.930000000,1.050000000,3,8,2,4,0.920000000,1.060000000,3,4,2,2,0.910000000,1.070000000,3,2,2,1,0.900000000,1.080000000,2,2,1,1,0.890000000,1.090000000,2,4,1,2,MCLQ5-MCLU5
2025-06-11T00:00:06.034767675Z,2025-06-11T00:00:06.034422169Z,10,1,42022708,M,A,0,2.820000000,1,130,11578,79300286,2.810000000,2.820000000,1,1,1,1,2.800000000,2.830000000,12,12,3,3,2.790000000,2.840000000,2,2,2,2,2.780000000,2.870000000,1,1,1,1,,,0,0,0,0,,,0,0,0,0,,,0,0,0,0,,,0,0,0,0,,,0,0,0,0,,,0,0,0,0,MCLN5-MCLV5
2025-06-11T00:00:06.034778518Z,2025-06-11T00:00:06.034423973Z,10,1,42418117,M,B,0,3.220000000,1,130,11115,79300287,3.240000000,3.270000000,11,1,2,1,3.230000000,3.280000000,1,11,1,2,3.220000000,3.290000000,1,1,1,1,,,0,0,0,0,,,0,0,0,0,,,0,0,0,0,,,0,0,0,0,,,0,0,0,0,,,0,0,0,0,,,0,0,0,0,MCLN5-MCLX5
2025-06-11T00:00:06.035477054Z,2025-06-11T00:00:06.035373447Z,10,1,42284507,A,A,0,1.000000000,4,130,11456,79300308,0.980000000,1.000000000,23,15,7,6,0.970000000,1.010000000,18,25,5,8,0.960000000,1.020000000,23,21,8,6,0.950000000,1.030000000,8,17,5,5,0.940000000,1.040000000,4,15,3,4,0.930000000,1.050000000,3,8,2,4,0.920000000,1.060000000,3,4,2,2,0.910000000,1.070000000,3,2,2,1,0.900000000,1.080000000,2,2,1,1,0.890000000,1.090000000,2,4,1,2,MCLQ5-MCLU5
2025-06-11T00:00:06.035640230Z,2025-06-11T00:00:06.035511027Z,10,1,42022708,C,B,0,2.810000000,1,130,11790,79300321,2.800000000,2.820000000,12,1,3,1,2.790000000,2.830000000,2,12,2,3,2.780000000,2.840000000,1,2,1,2,,2.870000000,0,1,0,1,,,0,0,0,0,,,0,0,0,0,,,0,0,0,0,,,0,0,0,0,,,0,0,0,0,,,0,0,0,0,MCLN5-MCLV5
2025-06-11T00:00:06.035920497Z,2025-06-11T00:00:06.035561043Z,10,1,42064377,C,B,0,0.730000000,10,130,11479,79300339,0.730000000,0.750000000,11,13,4,4,0.720000000,0.760000000,15,15,4,4,0.710000000,0.770000000,16,16,4,4,0.700000000,0.780000000,12,12,3,3,0.690000000,0.790000000,6,5,3,3,0.680000000,0.800000000,6,6,4,4,0.670000000,0.810000000,2,2,2,1,0.660000000,0.820000000,2,1,1,1,0.600000000,0.830000000,10,1,1,1,0.560000000,0.840000000,10,1,1,1,MCLU5-MCLV5
2025-06-11T00:00:06.035929098Z,2025-06-11T00:00:06.035562559Z,10,1,42022708,M,B,0,2.770000000,1,130,11811,79300340,2.800000000,2.820000000,11,1,2,1,2.790000000,2.830000000,2,12,2,3,2.780000000,2.840000000,1,2,1,2,2.770000000,2.870000000,1,1,1,1,,,0,0,0,0,,,0,0,0,0,,,0,0,0,0,,,0,0,0,0,,,0,0,0,0,,,0,0,0,0,MCLN5-MCLV5
2025-06-11T00:00:06.036144672Z,2025-06-11T00:00:06.035595715Z,10,1,42284507,M,A,0,1.000000000,1,130,11516,79300357,0.980000000,1.000000000,23,16,7,7,0.970000000,1.010000000,18,25,5,8,0.960000000,1.020000000,23,21,8,6,0.950000000,1.030000000,8,17,5,5,0.940000000,1.040000000,4,15,3,4,0.930000000,1.050000000,3,8,2,4,0.920000000,1.060000000,3,4,2,2,0.910000000,1.070000000,3,2,2,1,0.900000000,1.080000000,2,2,1,1,0.890000000,1.090000000,2,2,1,1,MCLQ5-MCLU5
2025-06-11T00:00:06.036304730Z,2025-06-11T00:00:06.035676927Z,10,1,42284507,M,A,0,1.100000000,2,130,11774,79300370,0.980000000,1.000000000,23,15,7,6,0.970000000,1.010000000,18,25,5,8,0.960000000,1.020000000,23,21,8,6,0.950000000,1.030000000,8,17,5,5,0.940000000,1.040000000,4,15,3,4,0.930000000,1.050000000,3,8,2,4,0.920000000,1.060000000,3,4,2,2,0.910000000,1.070000000,3,2,2,1,0.900000000,1.080000000,2,2,1,1,0.890000000,1.090000000,2,2,1,1,MCLQ5-MCLU5
2025-06-11T00:00:06.036321963Z,2025-06-11T00:00:06.035701521Z,10,1,42284507,C,A,0,1.000000000,1,130,11572,79300372,0.980000000,1.000000000,23,14,7,5,0.970000000,1.010000000,18,25,5,8,0.960000000,1.020000000,23,21,8,6,0.950000000,1.030000000,8,17,5,5,0.940000000,1.040000000,4,15,3,4,0.930000000,1.050000000,3,8,2,4,0.920000000,1.060000000,3,4,2,2,0.910000000,1.070000000,3,2,2,1,0.900000000,1.080000000,2,2,1,1,0.890000000,1.090000000,2,2,1,1,MCLQ5-MCLU5
2025-06-11T00:00:06.036622389Z,2025-06-11T00:00:06.036055017Z,10,1,42064377,M,A,0,0.750000000,2,130,11844,79300396,0.730000000,0.750000000,11,15,4,5,0.720000000,0.760000000,15,15,4,4,0.710000000,0.770000000,16,16,4,4,0.700000000,0.780000000,12,12,3,3,0.690000000,0.790000000,6,5,3,3,0.680000000,0.800000000,6,6,4,4,0.670000000,0.810000000,2,2,2,1,0.660000000,0.820000000,2,1,1,1,0.600000000,0.830000000,10,1,1,1,0.560000000,0.880000000,10,10,1,1,MCLU5-MCLV5
2025-06-11T00:00:06.036742605Z,2025-06-11T00:00:06.036417709Z,10,1,42284507,A,A,9,1.090000000,2,130,11336,79300407,0.980000000,1.000000000,23,14,7,5,0.970000000,1.010000000,18,25,5,8,0.960000000,1.020000000,23,21,8,6,0.950000000,1.030000000,8,17,5,5,0.940000000,1.040000000,4,15,3,4,0.930000000,1.050000000,3,8,2,4,0.920000000,1.060000000,3,4,2,2,0.910000000,1.070000000,3,2,2,1,0.900000000,1.080000000,2,2,1,1,0.890000000,1.090000000,2,4,1,2,MCLQ5-MCLU5
2025-06-11T00:00:06.037268480Z,2025-06-11T00:00:06.037082767Z,10,1,42026514,M,B,3,64.730000000,1,130,13337,79300426,64.770000000,64.780000000,7,1,3,1,64.760000000,64.790000000,8,6,8,4,64.750000000,64.800000000,6,4,6,4,64.740000000,64.810000000,10,4,9,4,64.730000000,64.820000000,7,11,7,8,64.720000000,64.830000000,8,9,5,9,64.710000000,64.840000000,8,6,7,5,64.700000000,64.850000000,7,9,6,6,64.690000000,64.860000000,4,4,3,3,64.680000000,64.870000000,4,4,2,3,MCLN5
2025-06-11T00:00:06.037279800Z,2025-06-11T00:00:06.037083227Z,10,1,42026514,M,A,3,64.810000000,1,130,12389,79300427,64.770000000,64.780000000,7,1,3,1,64.760000000,64.790000000,8,6,8,4,64.750000000,64.800000000,6,4,6,4,64.740000000,64.810000000,10,5,9,5,64.730000000,64.820000000,7,10,7,7,64.720000000,64.830000000,8,9,5,9,64.710000000,64.840000000,8,6,7,5,64.700000000,64.850000000,7,9,6,6,64.690000000,64.860000000,4,4,3,3,64.680000000,64.870000000,4,4,2,3,MCLN5
2025-06-11T00:00:06.037279800Z,2025-06-11T00:00:06.037083707Z,10,1,42026514,M,B,3,64.730000000,1,130,12389,79300427,64.770000000,64.780000000,7,1,3,1,64.760000000,64.790000000,8,6,8,4,64.750000000,64.800000000,6,4,6,4,64.740000000,64.810000000,9,5,8,5,64.730000000,64.820000000,8,10,8,7,64.720000000,64.830000000,8,9,5,9,64.710000000,64.840000000,8,6,7,5,64.700000000,64.850000000,7,9,6,6,64.690000000,64.860000000,4,4,3,3,64.680000000,64.870000000,4,4,2,3,MCLN5
2025-06-11T00:00:06.037287964Z,2025-06-11T00:00:06.037084167Z,10,1,42026514,M,A,3,64.810000000,1,130,11788,79300428,64.770000000,64.780000000,7,1,3,1,64.760000000,64.790000000,8,6,8,4,64.750000000,64.800000000,6,4,6,4,64.740000000,64.810000000,9,6,8,6,64.730000000,64.820000000,8,9,8,6,64.720000000,64.830000000,8,9,5,9,64.710000000,64.840000000,8,6,7,5,64.700000000,64.850000000,7,9,6,6,64.690000000,64.860000000,4,4,3,3,64.680000000,64.870000000,4,4,2,3,MCLN5
2025-06-11T00:00:06.037296288Z,2025-06-11T00:00:06.037086087Z,10,1,42026514,A,A,0,64.780000000,1,130,11458,79300429,64.770000000,64.780000000,7,2,3,2,64.760000000,64.790000000,8,6,8,4,64.750000000,64.800000000,6,4,6,4,64.740000000,64.810000000,9,6,8,6,64.730000000,64.820000000,8,9,8,6,64.720000000,64.830000000,8,9,5,9,64.710000000,64.840000000,8,6,7,5,64.700000000,64.850000000,7,9,6,6,64.690000000,64.860000000,4,4,3,3,64.680000000,64.870000000,4,4,2,3,MCLN5
2025-06-11T00:00:06.037765144Z,2025-06-11T00:00:06.037326347Z,10,1,42025623,M,B,5,63.630000000,1,130,11745,79300454,63.690000000,63.710000000,1,2,1,2,63.680000000,63.720000000,1,3,1,3,63.670000000,63.730000000,2,2,2,2,63.660000000,63.740000000,3,5,3,5,63.650000000,63.750000000,3,3,3,3,63.640000000,63.760000000,6,3,6,3,63.630000000,63.770000000,6,2,6,2,63.620000000,63.780000000,3,4,3,4,63.610000000,63.790000000,2,1,2,1,63.600000000,63.800000000,6,3,6,3,MCLQ5
2025-06-11T00:00:06.037776302Z,2025-06-11T00:00:06.037326825Z,10,1,42025623,M,A,3,63.740000000,1,130,11952,79300455,63.690000000,63.710000000,1,2,1,2,63.680000000,63.720000000,1,3,1,3,63.670000000,63.730000000,2,2,2,2,63.660000000,63.740000000,3,6,3,6,63.650000000,63.750000000,3,2,3,2,63.640000000,63.760000000,6,3,6,3,63.630000000,63.770000000,6,2,6,2,63.620000000,63.780000000,3,4,3,4,63.610000000,63.790000000,2,1,2,1,63.600000000,63.800000000,6,3,6,3,MCLQ5
2025-06-11T00:00:06.037840358Z,2025-06-11T00:00:06.037378567Z,10,1,42025623,A,A,0,63.700000000,1,130,15991,79300458,63.690000000,63.700000000,1,1,1,1,63.680000000,63.710000000,1,2,1,2,63.670000000,63.720000000,2,3,2,3,63.660000000,63.730000000,3,2,3,2,63.650000000,63.740000000,3,6,3,6,63.640000000,63.750000000,6,2,6,2,63.630000000,63.760000000,6,3,6,3,63.620000000,63.770000000,3,2,3,2,63.610000000,63.780000000,2,4,2,4,63.600000000,63.790000000,6,1,6,1,MCLQ5
2025-06-11T00:00:06.037928312Z,2025-06-11T00:00:06.037778467Z,10,1,42026514,A,A,0,64.780000000,1,130,12953,79300464,64.770000000,64.780000000,7,3,3,3,64.760000000,64.790000000,8,6,8,4,64.750000000,64.800000000,6,4,6,4,64.740000000,64.810000000,9,6,8,6,64.730000000,64.820000000,8,9,8,6,64.720000000,64.830000000,8,9,5,9,64.710000000,64.840000000,8,6,7,5,64.700000000,64.850000000,7,9,6,6,64.690000000,64.860000000,4,4,3,3,64.680000000,64.870000000,4,4,2,3,MCLN5
2025-06-11T00:00:06.043542565Z,2025-06-11T00:00:06.042753409Z,10,1,42026514,T,A,0,64.770000000,7,0,15094,79300589,64.770000000,64.780000000,7,3,3,3,64.760000000,64.790000000,8,6,8,4,64.750000000,64.800000000,6,4,6,4,64.740000000,64.810000000,9,6,8,6,64.730000000,64.820000000,8,9,8,6,64.720000000,64.830000000,8,9,5,9,64.710000000,64.840000000,8,6,7,5,64.700000000,64.850000000,7,9,6,6,64.690000000,64.860000000,4,4,3,3,64.680000000,64.870000000,4,4,2,3,MCLN5
2025-06-11T00:00:06.043552233Z,2025-06-11T00:00:06.042753409Z,10,1,42026514,C,B,0,64.770000000,4,130,11678,79300590,64.760000000,64.780000000,8,3,8,3,64.750000000,64.790000000,6,6,6,4,64.740000000,64.800000000,9,4,8,4,64.730000000,64.810000000,8,6,8,6,64.720000000,64.820000000,8,9,5,6,64.710000000,64.830000000,8,9,7,9,64.700000000,64.840000000,7,6,6,5,64.690000000,64.850000000,4,9,3,6,64.680000000,64.860000000,4,4,2,3,64.670000000,64.870000000,6,4,4,3,MCLN5
2025-06-11T00:00:06.043585831Z,2025-06-11T00:00:06.042753755Z,10,1,42025623,T,A,0,63.690000000,1,0,14584,79300592,63.690000000,63.700000000,1,1,1,1,63.680000000,63.710000000,1,2,1,2,63.670000000,63.720000000,2,3,2,3,63.660000000,63.730000000,3,2,3,2,63.650000000,63.740000000,3,6,3,6,63.640000000,63.750000000,6,2,6,2,63.630000000,63.760000000,6,3,6,3,63.620000000,63.770000000,3,2,3,2,63.610000000,63.780000000,2,4,2,4,63.600000000,63.790000000,6,1,6,1,MCLQ5
2025-06-11T00:00:06.043585831Z,2025-06-11T00:00:06.042753755Z,10,1,42025623,C,B,0,63.690000000,1,130,14584,79300592,63.680000000,63.700000000,1,1,1,1,63.670000000,63.710000000,2,2,2,2,63.660000000,63.720000000,3,3,3,3,63.650000000,63.730000000,3,2,3,2,63.640000000,63.740000000,6,6,6,6,63.630000000,63.750000000,6,2,6,2,63.620000000,63.760000000,3,3,3,3,63.610000000,63.770000000,2,2,2,2,63.600000000,63.780000000,6,4,6,4,63.590000000,63.790000000,1,1,1,1,MCLQ5
2025-06-11T00:00:06.043914163Z,2025-06-11T00:00:06.042784551Z,10,1,42026514,A,B,4,64.720000000,1,130,13104,79300613,64.760000000,64.780000000,8,3,8,3,64.750000000,64.790000000,6,6,6,4,64.740000000,64.800000000,9,4,8,4,64.730000000,64.810000000,8,6,8,6,64.720000000,64.820000000,9,9,6,6,64.710000000,64.830000000,8,9,7,9,64.700000000,64.840000000,7,6,6,5,64.690000000,64.850000000,4,9,3,6,64.680000000,64.860000000,4,4,2,3,64.670000000,64.870000000,6,4,4,3,MCLN5
2025-06-11T00:00:06.043953700Z,2025-06-11T00:00:06.042786815Z,10,1,42026514,C,A,7,64.850000000,1,130,11709,79300616,64.760000000,64.780000000,8,3,8,3,64.750000000,64.790000000,6,6,6,4,64.740000000,64.800000000,9,4,8,4,64.730000000,64.810000000,8,6,8,6,64.720000000,64.820000000,9,9,6,6,64.710000000,64.830000000,8,9,7,9,64.700000000,64.840000000,7,6,6,5,64.690000000,64.850000000,4,8,3,5,64.680000000,64.860000000,4,4,2,3,64.670000000,64.870000000,6,4,4,3,MCLN5
2025-06-11T00:00:06.044099243Z,2025-06-11T00:00:06.042797971Z,10,1,42026514,A,A,0,64.770000000,2,130,11404,79300622,64.760000000,64.770000000,8,2,8,1,64.750000000,64.780000000,6,3,6,3,64.740000000,64.790000000,9,6,8,4,64.730000000,64.800000000,8,4,8,4,64.720000000,64.810000000,9,6,6,6,64.710000000,64.820000000,8,9,7,6,64.700000000,64.830000000,7,9,6,9,64.690000000,64.840000000,4,6,3,5,64.680000000,64.850000000,4,8,2,5,64.670000000,64.860000000,6,4,4,3,MCLN5
2025-06-11T00:00:06.044636730Z,2025-06-11T00:00:06.042832357Z,10,1,42026514,M,B,1,62.800000000,2,130,12314,79300654,64.760000000,64.770000000,8,2,8,1,64.750000000,64.780000000,5,3,5,3,64.740000000,64.790000000,9,6,8,4,64.730000000,64.800000000,8,4,8,4,64.720000000,64.810000000,9,6,6,6,64.710000000,64.820000000,8,9,7,6,64.700000000,64.830000000,7,9,6,9,64.690000000,64.840000000,4,6,3,5,64.680000000,64.850000000,4,8,2,5,64.670000000,64.860000000,6,4,4,3,MCLN5
2025-06-11T00:00:06.044894503Z,2025-06-11T00:00:06.042838959Z,10,1,42025623,A,A,0,63.690000000,1,130,16077,79300667,63.680000000,63.690000000,1,1,1,1,63.670000000,63.700000000,2,1,2,1,63.660000000,63.710000000,3,2,3,2,63.650000000,63.720000000,3,3,3,3,63.640000000,63.730000000,6,2,6,2,63.630000000,63.740000000,6,6,6,6,63.620000000,63.750000000,3,2,3,2,63.610000000,63.760000000,2,3,2,3,63.600000000,63.770000000,6,2,6,2,63.590000000,63.780000000,1,4,1,4,MCLQ5
2025-06-11T00:00:06.044910869Z,2025-06-11T00:00:06.042845969Z,10,1,42026514,M,B,1,62.790000000,2,130,11947,79300668,64.760000000,64.770000000,8,2,8,1,64.750000000,64.780000000,4,3,4,3,64.740000000,64.790000000,9,6,8,4,64.730000000,64.800000000,8,4,8,4,64.720000000,64.810000000,9,6,6,6,64.710000000,64.820000000,8,9,7,6,64.700000000,64.830000000,7,9,6,9,64.690000000,64.840000000,4,6,3,5,64.680000000,64.850000000,4,8,2,5,64.670000000,64.860000000,6,4,4,3,MCLN5
2025-06-11T00:00:06.045301530Z,2025-06-11T00:00:06.042917445Z,10,1,42025623,C,B,0,63.680000000,1,130,14076,79300685,63.670000000,63.690000000,2,1,2,1,63.660000000,63.700000000,3,1,3,1,63.650000000,63.710000000,3,2,3,2,63.640000000,63.720000000,6,3,6,3,63.630000000,63.730000000,6,2,6,2,63.620000000,63.740000000,3,6,3,6,63.610000000,63.750000000,2,2,2,2,63.600000000,63.760000000,6,3,6,3,63.590000000,63.770000000,1,2,1,2,63.580000000,63.780000000,6,4,4,4,MCLQ5
2025-06-11T00:00:06.045341879Z,2025-06-11T00:00:06.042952773Z,10,1,42026514,C,B,0,64.760000000,1,130,13505,79300687,64.760000000,64.770000000,7,2,7,1,64.750000000,64.780000000,4,3,4,3,64.740000000,64.790000000,9,6,8,4,64.730000000,64.800000000,8,4,8,4,64.720000000,64.810000000,9,6,6,6,64.710000000,64.820000000,8,9,7,6,64.700000000,64.830000000,7,9,6,9,64.690000000,64.840000000,4,6,3,5,64.680000000,64.850000000,4,8,2,5,64.670000000,64.860000000,6,4,4,3,MCLN5
2025-06-11T00:00:06.045574540Z,2025-06-11T00:00:06.043595809Z,10,1,42025623,C,B,4,63.630000000,1,130,11894,79300704,63.670000000,63.690000000,2,1,2,1,63.660000000,63.700000000,3,1,3,1,63.650000000,63.710000000,3,2,3,2,63.640000000,63.720000000,6,3,6,3,63.630000000,63.730000000,5,2,5,2,63.620000000,63.740000000,3,6,3,6,63.610000000,63.750000000,2,2,2,2,63.600000000,63.760000000,6,3,6,3,63.590000000,63.770000000,1,2,1,2,63.580000000,63.780000000,6,4,4,4,MCLQ5
2025-06-11T00:00:06.045668699Z,2025-06-11T00:00:06.043789183Z,10,1,42026514,C,B,4,64.720000000,1,130,11526,79300711,64.760000000,64.770000000,7,2,7,1,64.750000000,64.780000000,4,3,4,3,64.740000000,64.790000000,9,6,8,4,64.730000000,64.800000000,8,4,8,4,64.720000000,64.810000000,8,6,5,6,64.710000000,64.820000000,8,9,7,6,64.700000000,64.830000000,7,9,6,9,64.690000000,64.840000000,4,6,3,5,64.680000000,64.850000000,4,8,2,5,64.670000000,64.860000000,6,4,4,3,MCLN5
2025-06-11T00:00:06.045703680Z,2025-06-11T00:00:06.043798571Z,10,1,42026514,M,B,0,62.780000000,2,130,14296,79300713,64.760000000,64.770000000,6,2,6,1,64.750000000,64.780000000,4,3,4,3,64.740000000,64.790000000,9,6,8,4,64.730000000,64.800000000,8,4,8,4,64.720000000,64.810000000,8,6,5,6,64.710000000,64.820000000,8,9,7,6,64.700000000,64.830000000,7,9,6,9,64.690000000,64.840000000,4,6,3,5,64.680000000,64.850000000,4,8,2,5,64.670000000,64.860000000,6,4,4,3,MCLN5
2025-06-11T00:00:06.045816539Z,2025-06-11T00:00:06.043896181Z,10,1,42026514,M,B,0,62.770000000,2,130,12253,79300717,64.760000000,64.770000000,5,2,5,1,64.750000000,64.780000000,4,3,4,3,64.740000000,64.790000000,9,6,8,4,64.730000000,64.800000000,8,4,8,4,64.720000000,64.810000000,8,6,5,6,64.710000000,64.820000000,8,9,7,6,64.700000000,64.830000000,7,9,6,9,64.690000000,64.840000000,4,6,3,5,64.680000000,64.850000000,4,8,2,5,64.670000000,64.860000000,6,4,4,3,MCLN5
2025-06-11T00:00:06.046022521Z,2025-06-11T00:00:06.044249175Z,10,1,42026514,M,A,1,64.780000000,1,130,12467,79300730,64.760000000,64.770000000,5,2,5,1,64.750000000,64.780000000,4,4,4,4,64.740000000,64.790000000,9,6,8,4,64.730000000,64.800000000,8,4,8,4,64.720000000,64.810000000,8,6,5,6,64.710000000,64.820000000,8,9,7,6,64.700000000,64.830000000,7,9,6,9,64.690000000,64.840000000,4,6,3,5,64.680000000,64.850000000,4,8,2,5,64.670000000,64.860000000,6,4,4,3,MCLN5
2025-06-11T00:00:06.046180982Z,2025-06-11T00:00:06.044328335Z,10,1,42026514,C,A,1,64.780000000,1,130,12778,79300743,64.760000000,64.770000000,5,2,5,1,64.750000000,64.780000000,4,3,4,3,64.740000000,64.790000000,9,6,8,4,64.730000000,64.800000000,8,4,8,4,64.720000000,64.810000000,8,6,5,6,64.710000000,64.820000000,8,9,7,6,64.700000000,64.830000000,7,9,6,9,64.690000000,64.840000000,4,6,3,5,64.680000000,64.850000000,4,8,2,5,64.670000000,64.860000000,6,4,4,3,MCLN5
2025-06-11T00:00:06.046340027Z,2025-06-11T00:00:06.044591305Z,10,1,42284507,A,B,4,0.940000000,2,130,11615,79300753,0.980000000,1.000000000,23,14,7,5,0.970000000,1.010000000,18,25,5,8,0.960000000,1.020000000,23,21,8,6,0.950000000,1.030000000,8,17,5,5,0.940000000,1.040000000,6,15,4,4,0.930000000,1.050000000,3,8,2,4,0.920000000,1.060000000,3,4,2,2,0.910000000,1.070000000,3,2,2,1,0.900000000,1.080000000,2,2,1,1,0.890000000,1.090000000,2,4,1,2,MCLQ5-MCLU5
2025-06-11T00:00:06.046348835Z,2025-06-11T00:00:06.044598159Z,10,1,42284507,C,A,5,1.050000000,2,130,11614,79300754,0.980000000,1.000000000,23,14,7,5,0.970000000,1.010000000,18,25,5,8,0.960000000,1.020000000,23,21,8,6,0.950000000,1.030000000,8,17,5,5,0.940000000,1.040000000,6,15,4,4,0.930000000,1.050000000,3,6,2,3,0.920000000,1.060000000,3,4,2,2,0.910000000,1.070000000,3,2,2,1,0.900000000,1.080000000,2,2,1,1,0.890000000,1.090000000,2,4,1,2,MCLQ5-MCLU5
2025-06-11T00:00:06.046720282Z,2025-06-11T00:00:06.045073991Z,10,1,42026514,M,B,1,64.750000000,1,130,13085,79300783,64.760000000,64.770000000,5,2,5,1,64.750000000,64.780000000,5,3,5,3,64.740000000,64.790000000,9,6,8,4,64.730000000,64.800000000,8,4,8,4,64.720000000,64.810000000,8,6,5,6,64.710000000,64.820000000,8,9,7,6,64.700000000,64.830000000,7,9,6,9,64.690000000,64.840000000,4,6,3,5,64.680000000,64.850000000,4,8,2,5,64.670000000,64.860000000,6,4,4,3,MCLN5
2025-06-11T00:00:06.046848938Z,2025-06-11T00:00:06.045548343Z,10,1,42284507,M,A,0,1.000000000,2,130,11941,79300792,0.980000000,1.000000000,23,16,7,6,0.970000000,1.010000000,18,25,5,8,0.960000000,1.020000000,23,21,8,6,0.950000000,1.030000000,8,17,5,5,0.940000000,1.040000000,6,15,4,4,0.930000000,1.050000000,3,6,2,3,0.920000000,1.060000000,3,4,2,2,0.910000000,1.070000000,3,2,2,1,0.900000000,1.090000000,2,4,1,2,0.890000000,1.100000000,2,2,1,1,MCLQ5-MCLU5
2025-06-11T00:00:06.046857386Z,2025-06-11T00:00:06.045579755Z,10,1,42284507,A,A,4,1.040000000,2,130,11723,79300793,0.980000000,1.000000000,23,16,7,6,0.970000000,1.010000000,18,25,5,8,0.960000000,1.020000000,23,21,8,6,0.950000000,1.030000000,8,17,5,5,0.940000000,1.040000000,6,17,4,5,0.930000000,1.050000000,3,6,2,3,0.920000000,1.060000000,3,4,2,2,0.910000000,1.070000000,3,2,2,1,0.900000000,1.090000000,2,4,1,2,0.890000000,1.100000000,2,2,1,1,MCLQ5-MCLU5
2025-06-11T00:00:06.047226029Z,2025-06-11T00:00:06.047130757Z,10,1,42284507,A,A,8,1.080000000,2,130,12456,79300808,0.980000000,1.000000000,23,16,7,6,0.970000000,1.010000000,18,25,5,8,0.960000000,1.020000000,23,21,8,6,0.950000000,1.030000000,8,17,5,5,0.940000000,1.040000000,6,17,4,5,0.930000000,1.050000000,3,6,2,3,0.920000000,1.060000000,3,4,2,2,0.910000000,1.070000000,3,2,2,1,0.900000000,1.080000000,2,2,1,1,0.890000000,1.090000000,2,4,1,2,MCLQ5-MCLU5
2025-06-11T00:00:06.054843229Z,2025-06-11T00:00:06.054739573Z,10,1,42026514,A,B,5,64.710000000,1,130,15079,79300823,64.760000000,64.770000000,5,2,5,1,64.750000000,64.780000000,5,3,5,3,64.740000000,64.790000000,9,6,8,4,64.730000000,64.800000000,8,4,8,4,64.720000000,64.810000000,8,6,5,6,64.710000000,64.820000000,9,9,8,6,64.700000000,64.830000000,7,9,6,9,64.690000000,64.840000000,4,6,3,5,64.680000000,64.850000000,4,8,2,5,64.670000000,64.860000000,6,4,4,3,MCLN5
2025-06-11T00:00:06.054851246Z,2025-06-11T00:00:06.054741263Z,10,1,42026514,A,A,6,64.830000000,1,130,11286,79300824,64.760000000,64.770000000,5,2,5,1,64.750000000,64.780000000,5,3,5,3,64.740000000,64.790000000,9,6,8,4,64.730000000,64.800000000,8,4,8,4,64.720000000,64.810000000,8,6,5,6,64.710000000,64.820000000,9,9,8,6,64.700000000,64.830000000,7,10,6,10,64.690000000,64.840000000,4,6,3,5,64.680000000,64.850000000,4,8,2,5,64.670000000,64.860000000,6,4,4,3,MCLN5
2025-06-11T00:00:06.056484765Z,2025-06-11T00:00:06.056383941Z,10,1,42025623,A,B,6,63.610000000,1,130,15055,79300839,63.670000000,63.690000000,2,1,2,1,63.660000000,63.700000000,3,1,3,1,63.650000000,63.710000000,3,2,3,2,63.640000000,63.720000000,6,3,6,3,63.630000000,63.730000000,5,2,5,2,63.620000000,63.740000000,3,6,3,6,63.610000000,63.750000000,3,2,3,2,63.600000000,63.760000000,6,3,6,3,63.590000000,63.770000000,1,2,1,2,63.580000000,63.780000000,6,4,4,4,MCLQ5
2025-06-11T00:00:06.056492867Z,2025-06-11T00:00:06.056385515Z,10,1,42025623,C,A,8,63.770000000,1,130,11429,79300840,63.670000000,63.690000000,2,1,2,1,63.660000000,63.700000000,3,1,3,1,63.650000000,63.710000000,3,2,3,2,63.640000000,63.720000000,6,3,6,3,63.630000000,63.730000000,5,2,5,2,63.620000000,63.740000000,3,6,3,6,63.610000000,63.750000000,3,2,3,2,63.600000000,63.760000000,6,3,6,3,63.590000000,63.770000000,1,1,1,1,63.580000000,63.780000000,6,4,4,4,MCLQ5
2025-06-11T00:00:06.056609751Z,2025-06-11T00:00:06.056513323Z,10,1,42025623,A,A,6,63.750000000,1,130,15054,79300841,63.670000000,63.690000000,2,1,2,1,63.660000000,63.700000000,3,1,3,1,63.650000000,63.710000000,3,2,3,2,63.640000000,63.720000000,6,3,6,3,63.630000000,63.730000000,5,2,5,2,63.620000000,63.740000000,3,6,3,6,63.610000000,63.750000000,3,3,3,3,63.600000000,63.760000000,6,3,6,3,63.590000000,63.770000000,1,1,1,1,63.580000000,63.780000000,6,4,4,4,MCLQ5
2025-06-11T00:00:06.068225723Z,2025-06-11T00:00:06.068048947Z,10,1,42064377,A,B,0,0.730000000,10,130,11227,79300990,0.730000000,0.750000000,21,15,5,5,0.720000000,0.760000000,15,15,4,4,0.710000000,0.770000000,16,16,4,4,0.700000000,0.780000000,12,12,3,3,0.690000000,0.790000000,6,5,3,3,0.680000000,0.800000000,6,6,4,4,0.670000000,0.810000000,2,2,2,1,0.660000000,0.820000000,2,1,1,1,0.600000000,0.830000000,10,1,1,1,0.560000000,0.880000000,10,10,1,1,MCLU5-MCLV5
2025-06-11T00:00:06.068303863Z,2025-06-11T00:00:06.068083097Z,10,1,42022708,A,B,0,2.810000000,1,130,11837,79300997,2.810000000,2.820000000,1,1,1,1,2.800000000,2.830000000,11,12,2,3,2.790000000,2.840000000,2,2,2,2,2.780000000,2.870000000,1,1,1,1,2.770000000,,1,0,1,0,,,0,0,0,0,,,0,0,0,0,,,0,0,0,0,,,0,0,0,0,,,0,0,0,0,MCLN5-MCLV5
2025-06-11T00:00:06.068504331Z,2025-06-11T00:00:06.068405145Z,10,1,42064377,M,A,0,0.840000000,1,130,14979,79301011,0.730000000,0.750000000,21,13,5,4,0.720000000,0.760000000,15,15,4,4,0.710000000,0.770000000,16,16,4,4,0.700000000,0.780000000,12,12,3,3,0.690000000,0.790000000,6,5,3,3,0.680000000,0.800000000,6,6,4,4,0.670000000,0.810000000,2,2,2,1,0.660000000,0.820000000,2,1,1,1,0.600000000,0.830000000,10,1,1,1,0.560000000,0.840000000,10,1,1,1,MCLU5-MCLV5
2025-06-11T00:00:06.068694993Z,2025-06-11T00:00:06.068602359Z,10,1,42022708,M,A,0,2.850000000,1,130,11467,79301014,2.810000000,2.830000000,1,12,1,3,2.800000000,2.840000000,11,2,2,2,2.790000000,2.850000000,2,1,2,1,2.780000000,2.870000000,1,1,1,1,2.770000000,,1,0,1,0,,,0,0,0,0,,,0,0,0,0,,,0,0,0,0,,,0,0,0,0,,,0,0,0,0,MCLN5-MCLV5
2025-06-11T00:00:06.101420447Z,2025-06-11T00:00:06.101291237Z,10,1,42026514,M,A,1,64.780000000,1,130,16680,79301038,64.760000000,64.770000000,5,2,5,1,64.750000000,64.780000000,5,4,5,4,64.740000000,64.790000000,9,6,8,4,64.730000000,64.800000000,8,4,8,4,64.720000000,64.810000000,8,6,5,6,64.710000000,64.820000000,9,9,8,6,64.700000000,64.830000000,7,10,6,10,64.690000000,64.840000000,4,6,3,5,64.680000000,64.850000000,4,8,2,5,64.670000000,64.860000000,6,4,4,3,MCLN5
2025-06-11T00:00:06.256658405Z,2025-06-11T00:00:06.255799267Z,10,1,42026514,A,A,0,64.770000000,1,130,17711,79301469,64.760000000,64.770000000,5,3,5,2,64.750000000,64.780000000,5,4,5,4,64.740000000,64.790000000,9,6,8,4,64.730000000,64.800000000,8,4,8,4,64.720000000,64.810000000,8,6,5,6,64.710000000,64.820000000,9,9,8,6,64.700000000,64.830000000,7,10,6,10,64.690000000,64.840000000,4,6,3,5,64.680000000,64.850000000,4,8,2,5,64.670000000,64.860000000,6,4,4,3,MCLN5
2025-06-11T00:00:06.256816482Z,2025-06-11T00:00:06.255820883Z,10,1,42026514,C,B,0,64.760000000,1,130,13388,79301478,64.760000000,64.770000000,4,3,4,2,64.750000000,64.780000000,5,4,5,4,64.740000000,64.790000000,9,6,8,4,64.730000000,64.800000000,8,4,8,4,64.720000000,64.810000000,8,6,5,6,64.710000000,64.820000000,9,9,8,6,64.700000000,64.830000000,7,10,6,10,64.690000000,64.840000000,4,6,3,5,64.680000000,64.850000000,4,8,2,5,64.670000000,64.860000000,6,4,4,3,MCLN5
2025-06-11T00:00:06.257251938Z,2025-06-11T00:00:06.256071319Z,10,1,42026514,M,B,3,64.720000000,1,130,11771,79301500,64.760000000,64.770000000,4,3,4,2,64.750000000,64.780000000,5,4,5,4,64.740000000,64.790000000,9,6,8,4,64.730000000,64.800000000,7,4,7,4,64.720000000,64.810000000,9,6,6,6,64.710000000,64.820000000,9,9,8,6,64.700000000,64.830000000,7,10,6,10,64.690000000,64.840000000,4,6,3,5,64.680000000,64.850000000,4,8,2,5,64.670000000,64.860000000,6,4,4,3,MCLN5
2025-06-11T00:00:06.257273832Z,2025-06-11T00:00:06.256079113Z,10,1,42026514,C,B,0,64.760000000,1,130,16992,79301501,64.760000000,64.770000000,3,3,3,2,64.750000000,64.780000000,5,4,5,4,64.740000000,64.790000000,9,6,8,4,64.730000000,64.800000000,7,4,7,4,64.720000000,64.810000000,9,6,6,6,64.710000000,64.820000000,9,9,8,6,64.700000000,64.830000000,7,10,6,10,64.690000000,64.840000000,4,6,3,5,64.680000000,64.850000000,4,8,2,5,64.670000000,64.860000000,6,4,4,3,MCLN5
2025-06-11T00:00:06.257660600Z,2025-06-11T00:00:06.256672021Z,10,1,42026514,A,A,0,64.770000000,1,130,13544,79301524,64.760000000,64.770000000,3,4,3,3,64.750000000,64.780000000,5,4,5,4,64.740000000,64.790000000,9,6,8,4,64.730000000,64.800000000,7,4,7,4,64.720000000,64.810000000,9,6,6,6,64.710000000,64.820000000,9,9,8,6,64.700000000,64.830000000,7,10,6,10,64.690000000,64.840000000,4,6,3,5,64.680000000,64.850000000,4,8,2,5,64.670000000,64.860000000,6,4,4,3,MCLN5
2025-06-11T00:00:06.257768037Z,2025-06-11T00:00:06.256752563Z,10,1,42025623,M,B,3,63.630000000,1,130,12699,79301529,63.670000000,63.690000000,2,1,2,1,63.660000000,63.700000000,3,1,3,1,63.650000000,63.710000000,3,2,3,2,63.640000000,63.720000000,5,3,5,3,63.630000000,63.730000000,6,2,6,2,63.620000000,63.740000000,3,6,3,6,63.610000000,63.750000000,3,3,3,3,63.600000000,63.760000000,6,3,6,3,63.590000000,63.770000000,1,1,1,1,63.580000000,63.780000000,6,4,4,4,MCLQ5
2025-06-11T00:00:06.257777876Z,2025-06-11T00:00:06.256753331Z,10,1,42025623,M,B,3,63.630000000,1,130,11441,79301530,63.670000000,63.690000000,2,1,2,1,63.660000000,63.700000000,3,1,3,1,63.650000000,63.710000000,3,2,3,2,63.640000000,63.720000000,4,3,4,3,63.630000000,63.730000000,7,2,7,2,63.620000000,63.740000000,3,6,3,6,63.610000000,63.750000000,3,3,3,3,63.600000000,63.760000000,6,3,6,3,63.590000000,63.770000000,1,1,1,1,63.580000000,63.780000000,6,4,4,4,MCLQ5
2025-06-11T00:00:06.258017609Z,2025-06-11T00:00:06.256802845Z,10,1,42026514,C,A,0,64.770000000,1,130,16783,79301547,64.760000000,64.770000000,3,3,3,2,64.750000000,64.780000000,5,4,5,4,64.740000000,64.790000000,9,6,8,4,64.730000000,64.800000000,7,4,7,4,64.720000000,64.810000000,9,6,6,6,64.710000000,64.820000000,9,9,8,6,64.700000000,64.830000000,7,10,6,10,64.690000000,64.840000000,4,6,3,5,64.680000000,64.850000000,4,8,2,5,64.670000000,64.860000000,6,4,4,3,MCLN5
2025-06-11T00:00:06.258077787Z,2025-06-11T00:00:06.256828109Z,10,1,42026514,C,A,0,64.770000000,1,130,13449,79301552,64.760000000,64.770000000,3,2,3,1,64.750000000,64.780000000,5,4,5,4,64.740000000,64.790000000,9,6,8,4,64.730000000,64.800000000,7,4,7,4,64.720000000,64.810000000,9,6,6,6,64.710000000,64.820000000,9,9,8,6,64.700000000,64.830000000,7,10,6,10,64.690000000,64.840000000,4,6,3,5,64.680000000,64.850000000,4,8,2,5,64.670000000,64.860000000,6,4,4,3,MCLN5
2025-06-11T00:00:06.258186583Z,2025-06-11T00:00:06.256903217Z,10,1,42026514,C,A,0,64.770000000,2,130,11907,79301558,64.760000000,64.780000000,3,4,3,4,64.750000000,64.790000000,5,6,5,4,64.740000000,64.800000000,9,4,8,4,64.730000000,64.810000000,7,6,7,6,64.720000000,64.820000000,9,9,6,6,64.710000000,64.830000000,9,10,8,10,64.700000000,64.840000000,7,6,6,5,64.690000000,64.850000000,4,8,3,5,64.680000000,64.860000000,4,4,2,3,64.670000000,64.870000000,6,4,4,3,MCLN5
2025-06-11T00:00:06.258840155Z,2025-06-11T00:00:06.257301811Z,10,1,42026514,A,A,0,64.770000000,2,130,11679,79301592,64.760000000,64.770000000,3,2,3,1,64.750000000,64.780000000,5,4,5,4,64.740000000,64.790000000,9,6,8,4,64.730000000,64.800000000,7,4,7,4,64.720000000,64.810000000,9,6,6,6,64.710000000,64.820000000,9,9,8,6,64.700000000,64.830000000,7,10,6,10,64.690000000,64.840000000,4,6,3,5,64.680000000,64.850000000,4,8,2,5,64.670000000,64.860000000,6,4,4,3,MCLN5
2025-06-11T00:00:06.258877447Z,2025-06-11T00:00:06.257330015Z,10,1,42026514,M,B,3,64.720000000,1,130,11423,79301596,64.760000000,64.770000000,3,2,3,1,64.750000000,64.780000000,5,4,5,4,64.740000000,64.790000000,9,6,8,4,64.730000000,64.800000000,6,4,6,4,64.720000000,64.810000000,10,6,7,6,64.710000000,64.820000000,9,9,8,6,64.700000000,64.830000000,7,10,6,10,64.690000000,64.840000000,4,6,3,5,64.680000000,64.850000000,4,8,2,5,64.670000000,64.860000000,6,4,4,3,MCLN5
2025-06-11T00:00:06.258890687Z,2025-06-11T00:00:06.257330667Z,10,1,42026514,M,B,3,64.720000000,1,130,15795,79301597,64.760000000,64.770000000,3,2,3,1,64.750000000,64.780000000,5,4,5,4,64.740000000,64.790000000,9,6,8,4,64.730000000,64.800000000,5,4,5,4,64.720000000,64.810000000,11,6,8,6,64.710000000,64.820000000,9,9,8,6,64.700000000,64.830000000,7,10,6,10,64.690000000,64.840000000,4,6,3,5,64.680000000,64.850000000,4,8,2,5,64.670000000,64.860000000,6,4,4,3,MCLN5
2025-06-11T00:00:06.260763049Z,2025-06-11T00:00:06.258120809Z,10,1,42026514,A,B,0,64.760000000,1,130,13111,79301703,64.760000000,64.770000000,4,2,4,1,64.750000000,64.780000000,5,4,5,4,64.740000000,64.790000000,9,6,8,4,64.730000000,64.800000000,5,4,5,4,64.720000000,64.810000000,11,6,8,6,64.710000000,64.820000000,9,9,8,6,64.700000000,64.830000000,7,10,6,10,64.690000000,64.840000000,4,6,3,5,64.680000000,64.850000000,4,8,2,5,64.670000000,64.860000000,6,4,4,3,MCLN5
2025-06-11T00:00:06.260910897Z,2025-06-11T00:00:06.258418857Z,10,1,42026514,M,B,1,62.760000000,2,130,13192,79301715,64.760000000,64.770000000,4,2,4,1,64.750000000,64.780000000,4,4,4,4,64.740000000,64.790000000,9,6,8,4,64.730000000,64.800000000,5,4,5,4,64.720000000,64.810000000,11,6,8,6,64.710000000,64.820000000,9,9,8,6,64.700000000,64.830000000,7,10,6,10,64.690000000,64.840000000,4,6,3,5,64.680000000,64.850000000,4,8,2,5,64.670000000,64.860000000,6,4,4,3,MCLN5
2025-06-11T00:00:06.261321463Z,2025-06-11T00:00:06.258873357Z,10,1,42026514,A,A,0,64.770000000,1,130,12121,79301740,64.760000000,64.770000000,4,3,4,2,64.750000000,64.780000000,4,4,4,4,64.740000000,64.790000000,9,6,8,4,64.730000000,64.800000000,5,4,5,4,64.720000000,64.810000000,11,6,8,6,64.710000000,64.820000000,9,9,8,6,64.700000000,64.830000000,7,10,6,10,64.690000000,64.840000000,4,6,3,5,64.680000000,64.850000000,4,8,2,5,64.670000000,64.860000000,6,4,4,3,MCLN5
2025-06-11T00:00:06.261373094Z,2025-06-11T00:00:06.258873685Z,10,1,42025623,A,A,1,63.700000000,1,130,12649,79301743,63.670000000,63.690000000,2,1,2,1,63.660000000,63.700000000,3,2,3,2,63.650000000,63.710000000,3,2,3,2,63.640000000,63.720000000,4,3,4,3,63.630000000,63.730000000,7,2,7,2,63.620000000,63.740000000,3,6,3,6,63.610000000,63.750000000,3,3,3,3,63.600000000,63.760000000,6,3,6,3,63.590000000,63.770000000,1,1,1,1,63.580000000,63.780000000,6,4,4,4,MCLQ5
2025-06-11T00:00:06.261724358Z,2025-06-11T00:00:06.258939785Z,10,1,42026514,M,B,2,62.750000000,2,130,11379,79301759,64.760000000,64.770000000,4,3,4,2,64.750000000,64.780000000,4,4,4,4,64.740000000,64.790000000,8,6,7,4,64.730000000,64.800000000,5,4,5,4,64.720000000,64.810000000,11,6,8,6,64.710000000,64.820000000,9,9,8,6,64.700000000,64.830000000,7,10,6,10,64.690000000,64.840000000,4,6,3,5,64.680000000,64.850000000,4,8,2,5,64.670000000,64.860000000,6,4,4,3,MCLN5
2025-06-11T00:00:06.262018778Z,2025-06-11T00:00:06.259588391Z,10,1,42026514,C,B,0,64.760000000,1,130,11959,79301776,64.760000000,64.770000000,3,3,3,2,64.750000000,64.780000000,4,4,4,4,64.740000000,64.790000000,8,6,7,4,64.730000000,64.800000000,5,4,5,4,64.720000000,64.810000000,11,6,8,6,64.710000000,64.820000000,9,9,8,6,64.700000000,64.830000000,7,10,6,10,64.690000000,64.840000000,4,6,3,5,64.680000000,64.850000000,4,8,2,5,64.670000000,64.860000000,6,4,4,3,MCLN5
2025-06-11T00:00:06.262043699Z,2025-06-11T00:00:06.259588795Z,10,1,42025623,A,A,0,63.690000000,1,130,13473,79301777,63.670000000,63.690000000,2,2,2,2,63.660000000,63.700000000,3,2,3,2,63.650000000,63.710000000,3,2,3,2,63.640000000,63.720000000,4,3,4,3,63.630000000,63.730000000,7,2,7,2,63.620000000,63.740000000,3,6,3,6,63.610000000,63.750000000,3,3,3,3,63.600000000,63.760000000,6,3,6,3,63.590000000,63.770000000,1,1,1,1,63.580000000,63.780000000,6,4,4,4,MCLQ5
2025-06-11T00:00:06.262065678Z,2025-06-11T00:00:06.259589063Z,10,1,42026514,C,B,0,64.760000000,1,130,16953,79301778,64.760000000,64.770000000,2,3,2,2,64.750000000,64.780000000,4,4,4,4,64.740000000,64.790000000,8,6,7,4,64.730000000,64.800000000,5,4,5,4,64.720000000,64.810000000,11,6,8,6,64.710000000,64.820000000,9,9,8,6,64.700000000,64.830000000,7,10,6,10,64.690000000,64.840000000,4,6,3,5,64.680000000,64.850000000,4,8,2,5,64.670000000,64.860000000,6,4,4,3,MCLN5
2025-06-11T00:00:06.262356995Z,2025-06-11T00:00:06.260181587Z,10,1,42026514,A,A,0,64.770000000,1,130,13032,79301799,64.760000000,64.770000000,2,4,2,3,64.750000000,64.780000000,4,4,4,4,64.740000000,64.790000000,8,6,7,4,64.730000000,64.800000000,5,4,5,4,64.720000000,64.810000000,11,6,8,6,64.710000000,64.820000000,9,9,8,6,64.700000000,64.830000000,7,10,6,10,64.690000000,64.840000000,4,6,3,5,64.680000000,64.850000000,4,8,2,5,64.670000000,64.860000000,6,4,4,3,MCLN5
2025-06-11T00:00:06.263810674Z,2025-06-11T00:00:06.261595549Z,10,1,42025623,C,B,3,63.640000000,1,130,12765,79301887,63.670000000,63.690000000,2,2,2,2,63.660000000,63.700000000,3,2,3,2,63.650000000,63.710000000,3,2,3,2,63.640000000,63.720000000,3,3,3,3,63.630000000,63.730000000,7,2,7,2,63.620000000,63.740000000,3,6,3,6,63.610000000,63.750000000,3,3,3,3,63.600000000,63.760000000,6,3,6,3,63.590000000,63.770000000,1,1,1,1,63.580000000,63.780000000,6,4,4,4,MCLQ5
2025-06-11T00:00:06.266971695Z,2025-06-11T00:00:06.266611269Z,10,1,42025623,M,A,0,63.690000000,1,130,12799,79302129,63.670000000,63.690000000,2,3,2,3,63.660000000,63.700000000,3,2,3,2,63.650000000,63.710000000,3,2,3,2,63.640000000,63.720000000,3,3,3,3,63.630000000,63.730000000,7,2,7,2,63.620000000,63.740000000,3,6,3,6,63.610000000,63.750000000,3,3,3,3,63.600000000,63.760000000,6,3,6,3,63.590000000,63.770000000,1,1,1,1,63.580000000,63.780000000,6,4,4,4,MCLQ5
2025-06-11T00:00:06.294893370Z,2025-06-11T00:00:06.294795353Z,10,1,42025623,C,A,9,63.780000000,1,130,11595,79302899,63.670000000,63.690000000,2,3,2,3,63.660000000,63.700000000,3,2,3,2,63.650000000,63.710000000,3,2,3,2,63.640000000,63.720000000,3,3,3,3,63.630000000,63.730000000,7,2,7,2,63.620000000,63.740000000,3,6,3,6,63.610000000,63.750000000,3,3,3,3,63.600000000,63.760000000,6,3,6,3,63.590000000,63.770000000,1,1,1,1,63.580000000,63.780000000,6,3,4,3,MCLQ5
2025-06-11T00:00:06.294909572Z,2025-06-11T00:00:06.294795775Z,10,1,42025623,A,B,7,63.600000000,1,130,15371,79302900,63.670000000,63.690000000,2,3,2,3,63.660000000,63.700000000,3,2,3,2,63.650000000,63.710000000,3,2,3,2,63.640000000,63.720000000,3,3,3,3,63.630000000,63.730000000,7,2,7,2,63.620000000,63.740000000,3,6,3,6,63.610000000,63.750000000,3,3,3,3,63.600000000,63.760000000,7,3,7,3,63.590000000,63.770000000,1,1,1,1,63.580000000,63.780000000,6,3,4,3,MCLQ5
2025-06-11T00:00:06.294916970Z,2025-06-11T00:00:06.294796081Z,10,1,42025623,A,A,5,63.740000000,1,130,11189,79302901,63.670000000,63.690000000,2,3,2,3,63.660000000,63.700000000,3,2,3,2,63.650000000,63.710000000,3,2,3,2,63.640000000,63.720000000,3,3,3,3,63.630000000,63.730000000,7,2,7,2,63.620000000,63.740000000,3,7,3,7,63.610000000,63.750000000,3,3,3,3,63.600000000,63.760000000,7,3,7,3,63.590000000,63.770000000,1,1,1,1,63.580000000,63.780000000,6,3,4,3,MCLQ5
2025-06-11T00:00:06.362515330Z,2025-06-11T00:00:06.362382567Z,10,1,42026514,A,B,0,64.760000000,1,130,12850,79303291,64.760000000,64.770000000,3,4,3,3,64.750000000,64.780000000,4,4,4,4,64.740000000,64.790000000,8,6,7,4,64.730000000,64.800000000,5,4,5,4,64.720000000,64.810000000,11,6,8,6,64.710000000,64.820000000,9,9,8,6,64.700000000,64.830000000,7,10,6,10,64.690000000,64.840000000,4,6,3,5,64.680000000,64.850000000,4,8,2,5,64.670000000,64.860000000,6,4,4,3,MCLN5
2025-06-11T00:00:06.362635438Z,2025-06-11T00:00:06.362528785Z,10,1,42025623,M,B,4,63.620000000,1,130,11555,79303293,63.670000000,63.690000000,2,3,2,3,63.660000000,63.700000000,3,2,3,2,63.650000000,63.710000000,3,2,3,2,63.640000000,63.720000000,3,3,3,3,63.630000000,63.730000000,6,2,6,2,63.620000000,63.740000000,4,7,4,7,63.610000000,63.750000000,3,3,3,3,63.600000000,63.760000000,7,3,7,3,63.590000000,63.770000000,1,1,1,1,63.580000000,63.780000000,6,3,4,3,MCLQ5
2025-06-11T00:00:06.362646305Z,2025-06-11T00:00:06.362529287Z,10,1,42025623,M,A,4,63.730000000,1,130,11389,79303294,63.670000000,63.690000000,2,3,2,3,63.660000000,63.700000000,3,2,3,2,63.650000000,63.710000000,3,2,3,2,63.640000000,63.720000000,3,3,3,3,63.630000000,63.730000000,6,3,6,3,63.620000000,63.740000000,4,6,4,6,63.610000000,63.750000000,3,3,3,3,63.600000000,63.760000000,7,3,7,3,63.590000000,63.770000000,1,1,1,1,63.580000000,63.780000000,6,3,4,3,MCLQ5
2025-06-11T00:00:06.387013962Z,2025-06-11T00:00:06.386784015Z,10,1,42026514,C,B,0,64.760000000,1,130,17252,79303507,64.760000000,64.770000000,2,4,2,3,64.750000000,64.780000000,4,4,4,4,64.740000000,64.790000000,8,6,7,4,64.730000000,64.800000000,5,4,5,4,64.720000000,64.810000000,11,6,8,6,64.710000000,64.820000000,9,9,8,6,64.700000000,64.830000000,7,10,6,10,64.690000000,64.840000000,4,6,3,5,64.680000000,64.850000000,4,8,2,5,64.670000000,64.860000000,6,4,4,3,MCLN5
2025-06-11T00:00:06.387114834Z,2025-06-11T00:00:06.386979003Z,10,1,42026514,C,A,0,64.770000000,1,130,15862,79303515,64.760000000,64.770000000,2,3,2,2,64.750000000,64.780000000,4,4,4,4,64.740000000,64.790000000,8,6,7,4,64.730000000,64.800000000,5,4,5,4,64.720000000,64.810000000,11,6,8,6,64.710000000,64.820000000,9,9,8,6,64.700000000,64.830000000,7,10,6,10,64.690000000,64.840000000,4,6,3,5,64.680000000,64.850000000,4,8,2,5,64.670000000,64.860000000,6,4,4,3,MCLN5
2025-06-11T00:00:06.387235934Z,2025-06-11T00:00:06.387100053Z,10,1,42418117,M,A,1,3.290000000,10,130,11561,79303523,3.240000000,3.270000000,11,1,2,1,3.230000000,3.280000000,1,1,1,1,3.220000000,3.290000000,1,11,1,2,,,0,0,0,0,,,0,0,0,0,,,0,0,0,0,,,0,0,0,0,,,0,0,0,0,,,0,0,0,0,,,0,0,0,0,MCLN5-MCLX5
2025-06-11T00:00:06.387296963Z,2025-06-11T00:00:06.387163333Z,10,1,42026514,A,B,0,64.760000000,1,130,13200,79303527,64.760000000,64.770000000,3,3,3,2,64.750000000,64.780000000,4,4,4,4,64.740000000,64.790000000,8,6,7,4,64.730000000,64.800000000,5,4,5,4,64.720000000,64.810000000,11,6,8,6,64.710000000,64.820000000,9,9,8,6,64.700000000,64.830000000,7,10,6,10,64.690000000,64.840000000,4,6,3,5,64.680000000,64.850000000,4,8,2,5,64.670000000,64.860000000,6,4,4,3,MCLN5
2025-06-11T00:00:06.545868237Z,2025-06-11T00:00:06.541431545Z,10,1,42026514,M,A,4,64.810000000,1,130,11380,79303884,64.760000000,64.770000000,3,3,3,2,64.750000000,64.780000000,4,4,4,4,64.740000000,64.790000000,8,6,7,4,64.730000000,64.800000000,5,4,5,4,64.720000000,64.810000000,11,7,8,7,64.710000000,64.820000000,9,9,8,6,64.700000000,64.830000000,7,9,6,9,64.690000000,64.840000000,4,6,3,5,64.680000000,64.850000000,4,8,2,5,64.670000000,64.860000000,6,4,4,3,MCLN5
2025-06-11T00:00:06.545881231Z,2025-06-11T00:00:06.541433427Z,10,1,42025623,M,A,4,63.730000000,1,130,11423,79303885,63.670000000,63.690000000,2,3,2,3,63.660000000,63.700000000,3,2,3,2,63.650000000,63.710000000,3,2,3,2,63.640000000,63.720000000,3,3,3,3,63.630000000,63.730000000,6,4,6,4,63.620000000,63.740000000,4,5,4,5,63.610000000,63.750000000,3,3,3,3,63.600000000,63.760000000,7,3,7,3,63.590000000,63.770000000,1,1,1,1,63.580000000,63.780000000,6,3,4,3,MCLQ5
2025-06-11T00:00:06.545891752Z,2025-06-11T00:00:06.541434233Z,10,1,42025623,M,A,4,63.730000000,1,130,10770,79303886,63.670000000,63.690000000,2,3,2,3,63.660000000,63.700000000,3,2,3,2,63.650000000,63.710000000,3,2,3,2,63.640000000,63.720000000,3,3,3,3,63.630000000,63.730000000,6,5,6,5,63.620000000,63.740000000,4,4,4,4,63.610000000,63.750000000,3,3,3,3,63.600000000,63.760000000,7,3,7,3,63.590000000,63.770000000,1,1,1,1,63.580000000,63.780000000,6,3,4,3,MCLQ5
2025-06-11T00:00:06.545901928Z,2025-06-11T00:00:06.541435233Z,10,1,42026514,M,A,3,64.800000000,1,130,11456,79303887,64.760000000,64.770000000,3,3,3,2,64.750000000,64.780000000,4,4,4,4,64.740000000,64.790000000,8,6,7,4,64.730000000,64.800000000,5,5,5,5,64.720000000,64.810000000,11,6,8,6,64.710000000,64.820000000,9,9,8,6,64.700000000,64.830000000,7,9,6,9,64.690000000,64.840000000,4,6,3,5,64.680000000,64.850000000,4,8,2,5,64.670000000,64.860000000,6,4,4,3,MCLN5
2025-06-11T00:00:06.545911804Z,2025-06-11T00:00:06.541436001Z,10,1,42026514,M,A,3,64.800000000,1,130,11311,79303888,64.760000000,64.770000000,3,3,3,2,64.750000000,64.780000000,4,4,4,4,64.740000000,64.790000000,8,6,7,4,64.730000000,64.800000000,5,6,5,6,64.720000000,64.810000000,11,5,8,5,64.710000000,64.820000000,9,9,8,6,64.700000000,64.830000000,7,9,6,9,64.690000000,64.840000000,4,6,3,5,64.680000000,64.850000000,4,8,2,5,64.670000000,64.860000000,6,4,4,3,MCLN5
2025-06-11T00:00:06.641649318Z,2025-06-11T00:00:06.641527183Z,10,1,42022708,M,B,1,2.800000000,1,130,15083,79304063,2.810000000,2.830000000,1,12,1,3,2.800000000,2.840000000,12,2,3,2,2.790000000,2.850000000,2,1,2,1,2.780000000,2.870000000,1,1,1,1,,,0,0,0,0,,,0,0,0,0,,,0,0,0,0,,,0,0,0,0,,,0,0,0,0,,,0,0,0,0,MCLN5-MCLV5
2025-06-11T00:00:06.641665422Z,2025-06-11T00:00:06.641528663Z,10,1,42418117,M,B,0,3.250000000,1,130,11994,79304064,3.250000000,3.270000000,1,1,1,1,3.240000000,3.280000000,11,1,2,1,3.230000000,3.290000000,1,11,1,2,,,0,0,0,0,,,0,0,0,0,,,0,0,0,0,,,0,0,0,0,,,0,0,0,0,,,0,0,0,0,,,0,0,0,0,MCLN5-MCLX5
2025-06-11T00:00:06.714940318Z,2025-06-11T00:00:06.714812129Z,10,1,42025623,M,A,0,65.070000000,1,130,16942,79304176,63.670000000,63.690000000,2,2,2,2,63.660000000,63.700000000,3,2,3,2,63.650000000,63.710000000,3,2,3,2,63.640000000,63.720000000,3,3,3,3,63.630000000,63.730000000,6,5,6,5,63.620000000,63.740000000,4,4,4,4,63.610000000,63.750000000,3,3,3,3,63.600000000,63.760000000,7,3,7,3,63.590000000,63.770000000,1,1,1,1,63.580000000,63.780000000,6,3,4,3,MCLQ5
2025-06-11T00:00:06.715051802Z,2025-06-11T00:00:06.714951227Z,10,1,42025623,M,A,4,63.740000000,1,130,15402,79304177,63.670000000,63.690000000,2,2,2,2,63.660000000,63.700000000,3,2,3,2,63.650000000,63.710000000,3,2,3,2,63.640000000,63.720000000,3,3,3,3,63.630000000,63.730000000,6,4,6,4,63.620000000,63.740000000,4,5,4,5,63.610000000,63.750000000,3,3,3,3,63.600000000,63.760000000,7,3,7,3,63.590000000,63.770000000,1,1,1,1,63.580000000,63.780000000,6,3,4,3,MCLQ5
2025-06-11T00:00:06.715059766Z,2025-06-11T00:00:06.714951745Z,10,1,42025623,M,B,4,63.630000000,1,130,11112,79304178,63.670000000,63.690000000,2,2,2,2,63.660000000,63.700000000,3,2,3,2,63.650000000,63.710000000,3,2,3,2,63.640000000,63.720000000,3,3,3,3,63.630000000,63.730000000,7,4,7,4,63.620000000,63.740000000,3,5,3,5,63.610000000,63.750000000,3,3,3,3,63.600000000,63.760000000,7,3,7,3,63.590000000,63.770000000,1,1,1,1,63.580000000,63.780000000,6,3,4,3,MCLQ5
2025-06-11T00:00:06.715107226Z,2025-06-11T00:00:06.714976051Z,10,1,42025623,C,A,0,63.690000000,1,130,14243,79304180,63.670000000,63.690000000,2,1,2,1,63.660000000,63.700000000,3,2,3,2,63.650000000,63.710000000,3,2,3,2,63.640000000,63.720000000,3,3,3,3,63.630000000,63.730000000,7,4,7,4,63.620000000,63.740000000,3,5,3,5,63.610000000,63.750000000,3,3,3,3,63.600000000,63.760000000,7,3,7,3,63.590000000,63.770000000,1,1,1,1,63.580000000,63.780000000,6,3,4,3,MCLQ5
2025-06-11T00:00:06.835774098Z,2025-06-11T00:00:06.835617105Z,10,1,42026514,A,A,0,64.770000000,1,130,16303,79304363,64.760000000,64.770000000,3,4,3,3,64.750000000,64.780000000,4,4,4,4,64.740000000,64.790000000,8,6,7,4,64.730000000,64.800000000,5,6,5,6,64.720000000,64.810000000,11,5,8,5,64.710000000,64.820000000,9,9,8,6,64.700000000,64.830000000,7,9,6,9,64.690000000,64.840000000,4,6,3,5,64.680000000,64.850000000,4,8,2,5,64.670000000,64.860000000,6,4,4,3,MCLN5
2025-06-11T00:00:06.835886742Z,2025-06-11T00:00:06.835786231Z,10,1,42026514,M,B,4,64.710000000,1,130,14819,79304364,64.760000000,64.770000000,3,4,3,3,64.750000000,64.780000000,4,4,4,4,64.740000000,64.790000000,8,6,7,4,64.730000000,64.800000000,5,6,5,6,64.720000000,64.810000000,10,5,7,5,64.710000000,64.820000000,10,9,9,6,64.700000000,64.830000000,7,9,6,9,64.690000000,64.840000000,4,6,3,5,64.680000000,64.850000000,4,8,2,5,64.670000000,64.860000000,6,4,4,3,MCLN5
2025-06-11T00:00:06.835894721Z,2025-06-11T00:00:06.835786979Z,10,1,42026514,M,A,3,64.800000000,1,130,11411,79304365,64.760000000,64.770000000,3,4,3,3,64.750000000,64.780000000,4,4,4,4,64.740000000,64.790000000,8,6,7,4,64.730000000,64.800000000,5,7,5,7,64.720000000,64.810000000,10,4,7,4,64.710000000,64.820000000,10,9,9,6,64.700000000,64.830000000,7,9,6,9,64.690000000,64.840000000,4,6,3,5,64.680000000,64.850000000,4,8,2,5,64.670000000,64.860000000,6,4,4,3,MCLN5
2025-06-11T00:00:06.835930861Z,2025-06-11T00:00:06.835827489Z,10,1,42026514,C,B,0,64.760000000,1,130,13297,79304366,64.760000000,64.770000000,2,4,2,3,64.750000000,64.780000000,4,4,4,4,64.740000000,64.790000000,8,6,7,4,64.730000000,64.800000000,5,7,5,7,64.720000000,64.810000000,10,4,7,4,64.710000000,64.820000000,10,9,9,6,64.700000000,64.830000000,7,9,6,9,64.690000000,64.840000000,4,6,3,5,64.680000000,64.850000000,4,8,2,5,64.670000000,64.860000000,6,4,4,3,MCLN5
2025-06-11T00:00:06.836139808Z,2025-06-11T00:00:06.836037797Z,10,1,42026514,M,A,3,64.800000000,1,130,14915,79304367,64.760000000,64.770000000,2,4,2,3,64.750000000,64.780000000,4,4,4,4,64.740000000,64.790000000,8,6,7,4,64.730000000,64.800000000,5,8,5,8,64.720000000,64.810000000,10,4,7,4,64.710000000,64.820000000,10,9,9,6,64.700000000,64.830000000,7,9,6,9,64.690000000,64.840000000,4,6,3,5,64.680000000,64.850000000,4,8,2,5,64.670000000,64.860000000,6,4,4,3,MCLN5
2025-06-11T00:00:06.889331866Z,2025-06-11T00:00:06.888972103Z,10,1,42026514,A,B,0,64.760000000,1,130,12794,79304483,64.760000000,64.770000000,3,4,3,3,64.750000000,64.780000000,4,4,4,4,64.740000000,64.790000000,8,6,7,4,64.730000000,64.800000000,5,8,5,8,64.720000000,64.810000000,10,4,7,4,64.710000000,64.820000000,10,9,9,6,64.700000000,64.830000000,7,9,6,9,64.690000000,64.840000000,4,6,3,5,64.680000000,64.850000000,4,8,2,5,64.670000000,64.860000000,6,4,4,3,MCLN5
2025-06-11T00:00:06.892991455Z,2025-06-11T00:00:06.888997293Z,10,1,42026514,C,A,0,64.770000000,1,130,12999,79304494,64.760000000,64.770000000,3,3,3,2,64.750000000,64.780000000,4,4,4,4,64.740000000,64.790000000,8,6,7,4,64.730000000,64.800000000,5,8,5,8,64.720000000,64.810000000,10,4,7,4,64.710000000,64.820000000,10,9,9,6,64.700000000,64.830000000,7,9,6,9,64.690000000,64.840000000,4,6,3,5,64.680000000,64.850000000,4,8,2,5,64.670000000,64.860000000,6,4,4,3,MCLN5
2025-06-11T00:00:06.893112593Z,2025-06-11T00:00:06.889143461Z,10,1,42026514,A,B,0,64.760000000,1,130,13200,79304499,64.760000000,64.770000000,4,3,4,2,64.750000000,64.780000000,4,4,4,4,64.740000000,64.790000000,8,6,7,4,64.730000000,64.800000000,5,8,5,8,64.720000000,64.810000000,10,4,7,4,64.710000000,64.820000000,10,9,9,6,64.700000000,64.830000000,7,9,6,9,64.690000000,64.840000000,4,6,3,5,64.680000000,64.850000000,4,8,2,5,64.670000000,64.860000000,6,4,4,3,MCLN5
2025-06-11T00:00:06.893433977Z,2025-06-11T00:00:06.889279653Z,10,1,42026514,A,B,0,64.760000000,1,130,13542,79304513,64.760000000,64.770000000,5,3,5,2,64.750000000,64.780000000,4,4,4,4,64.740000000,64.790000000,8,6,7,4,64.730000000,64.800000000,5,8,5,8,64.720000000,64.810000000,10,4,7,4,64.710000000,64.820000000,10,9,9,6,64.700000000,64.830000000,7,9,6,9,64.690000000,64.840000000,4,6,3,5,64.680000000,64.850000000,4,8,2,5,64.670000000,64.860000000,6,4,4,3,MCLN5
2025-06-11T00:00:06.893775235Z,2025-06-11T00:00:06.889316669Z,10,1,42026514,C,A,0,64.770000000,1,130,11667,79304533,64.760000000,64.770000000,5,2,5,1,64.750000000,64.780000000,4,4,4,4,64.740000000,64.790000000,8,6,7,4,64.730000000,64.800000000,5,8,5,8,64.720000000,64.810000000,10,4,7,4,64.710000000,64.820000000,10,9,9,6,64.700000000,64.830000000,7,9,6,9,64.690000000,64.840000000,4,6,3,5,64.680000000,64.850000000,4,8,2,5,64.670000000,64.860000000,6,4,4,3,MCLN5
2025-06-11T00:00:06.894548955Z,2025-06-11T00:00:06.889475101Z,10,1,42026514,C,B,0,64.760000000,1,130,13233,79304571,64.760000000,64.770000000,4,2,4,1,64.750000000,64.780000000,4,4,4,4,64.740000000,64.790000000,8,6,7,4,64.730000000,64.800000000,5,8,5,8,64.720000000,64.810000000,10,4,7,4,64.710000000,64.820000000,10,9,9,6,64.700000000,64.830000000,7,9,6,9,64.690000000,64.840000000,4,6,3,5,64.680000000,64.850000000,4,8,2,5,64.670000000,64.860000000,6,4,4,3,MCLN5
2025-06-11T00:00:06.894579996Z,2025-06-11T00:00:06.889658433Z,10,1,42026514,C,A,0,64.770000000,2,130,11624,79304572,64.760000000,64.780000000,4,4,4,4,64.750000000,64.790000000,4,6,4,4,64.740000000,64.800000000,8,8,7,8,64.730000000,64.810000000,5,4,5,4,64.720000000,64.820000000,10,9,7,6,64.710000000,64.830000000,10,9,9,9,64.700000000,64.840000000,7,6,6,5,64.690000000,64.850000000,4,8,3,5,64.680000000,64.860000000,4,4,2,3,64.670000000,64.870000000,6,4,4,3,MCLN5
2025-06-11T00:00:06.894650118Z,2025-06-11T00:00:06.889686925Z,10,1,42026514,A,B,0,64.760000000,1,130,12095,79304577,64.760000000,64.780000000,5,4,5,4,64.750000000,64.790000000,4,6,4,4,64.740000000,64.800000000,8,8,7,8,64.730000000,64.810000000,5,4,5,4,64.720000000,64.820000000,10,9,7,6,64.710000000,64.830000000,10,9,9,9,64.700000000,64.840000000,7,6,6,5,64.690000000,64.850000000,4,8,3,5,64.680000000,64.860000000,4,4,2,3,64.670000000,64.870000000,6,4,4,3,MCLN5
2025-06-11T00:00:06.894875982Z,2025-06-11T00:00:06.892848545Z,10,1,42026514,M,A,2,64.810000000,1,130,11606,79304591,64.760000000,64.780000000,5,4,5,4,64.750000000,64.790000000,4,6,4,4,64.740000000,64.800000000,8,7,7,7,64.730000000,64.810000000,5,5,5,5,64.720000000,64.820000000,10,9,7,6,64.710000000,64.830000000,10,9,9,9,64.700000000,64.840000000,7,6,6,5,64.690000000,64.850000000,4,8,3,5,64.680000000,64.860000000,4,4,2,3,64.670000000,64.870000000,6,4,4,3,MCLN5
2025-06-11T00:00:06.894887271Z,2025-06-11T00:00:06.892849083Z,10,1,42026514,M,B,4,64.720000000,1,130,12617,79304592,64.760000000,64.780000000,5,4,5,4,64.750000000,64.790000000,4,6,4,4,64.740000000,64.800000000,8,7,7,7,64.730000000,64.810000000,5,5,5,5,64.720000000,64.820000000,11,9,8,6,64.710000000,64.830000000,9,9,8,9,64.700000000,64.840000000,7,6,6,5,64.690000000,64.850000000,4,8,3,5,64.680000000,64.860000000,4,4,2,3,64.670000000,64.870000000,6,4,4,3,MCLN5
2025-06-11T00:00:06.895376469Z,2025-06-11T00:00:06.893022893Z,10,1,42026514,M,A,2,64.810000000,1,130,11293,79304614,64.760000000,64.780000000,5,4,5,4,64.750000000,64.790000000,4,6,4,4,64.740000000,64.800000000,8,6,7,6,64.730000000,64.810000000,5,6,5,6,64.720000000,64.820000000,11,9,8,6,64.710000000,64.830000000,9,9,8,9,64.700000000,64.840000000,7,6,6,5,64.690000000,64.850000000,4,8,3,5,64.680000000,64.860000000,4,4,2,3,64.670000000,64.870000000,6,4,4,3,MCLN5
2025-06-11T00:00:06.895388119Z,2025-06-11T00:00:06.893023391Z,10,1,42026514,M,B,3,64.730000000,1,130,13506,79304615,64.760000000,64.780000000,5,4,5,4,64.750000000,64.790000000,4,6,4,4,64.740000000,64.800000000,8,6,7,6,64.730000000,64.810000000,6,6,6,6,64.720000000,64.820000000,10,9,7,6,64.710000000,64.830000000,9,9,8,9,64.700000000,64.840000000,7,6,6,5,64.690000000,64.850000000,4,8,3,5,64.680000000,64.860000000,4,4,2,3,64.670000000,64.870000000,6,4,4,3,MCLN5
2025-06-11T00:00:06.895396359Z,2025-06-11T00:00:06.893023871Z,10,1,42026514,M,A,2,64.810000000,1,130,11290,79304616,64.760000000,64.780000000,5,4,5,4,64.750000000,64.790000000,4,6,4,4,64.740000000,64.800000000,8,5,7,5,64.730000000,64.810000000,6,7,6,7,64.720000000,64.820000000,10,9,7,6,64.710000000,64.830000000,9,9,8,9,64.700000000,64.840000000,7,6,6,5,64.690000000,64.850000000,4,8,3,5,64.680000000,64.860000000,4,4,2,3,64.670000000,64.870000000,6,4,4,3,MCLN5
2025-06-11T00:00:06.895405183Z,2025-06-11T00:00:06.893024543Z,10,1,42026514,M,B,3,64.730000000,1,130,11355,79304617,64.760000000,64.780000000,5,4,5,4,64.750000000,64.790000000,4,6,4,4,64.740000000,64.800000000,8,5,7,5,64.730000000,64.810000000,7,7,7,7,64.720000000,64.820000000,9,9,6,6,64.710000000,64.830000000,9,9,8,9,64.700000000,64.840000000,7,6,6,5,64.690000000,64.850000000,4,8,3,5,64.680000000,64.860000000,4,4,2,3,64.670000000,64.870000000,6,4,4,3,MCLN5
2025-06-11T00:00:06.895461436Z,2025-06-11T00:00:06.893030439Z,10,1,42025623,C,A,0,63.690000000,1,130,19128,79304620,63.670000000,63.700000000,2,2,2,2,63.660000000,63.710000000,3,2,3,2,63.650000000,63.720000000,3,3,3,3,63.640000000,63.730000000,3,4,3,4,63.630000000,63.740000000,7,5,7,5,63.620000000,63.750000000,3,3,3,3,63.610000000,63.760000000,3,3,3,3,63.600000000,63.770000000,7,1,7,1,63.590000000,63.780000000,1,3,1,3,63.580000000,63.790000000,6,1,4,1,MCLQ5
2025-06-11T00:00:06.897088358Z,2025-06-11T00:00:06.894592403Z,10,1,42026514,A,A,0,64.780000000,1,130,13213,79304737,64.760000000,64.780000000,5,5,5,5,64.750000000,64.790000000,4,6,4,4,64.740000000,64.800000000,8,5,7,5,64.730000000,64.810000000,7,7,7,7,64.720000000,64.820000000,9,9,6,6,64.710000000,64.830000000,9,9,8,9,64.700000000,64.840000000,7,6,6,5,64.690000000,64.850000000,4,8,3,5,64.680000000,64.860000000,4,4,2,3,64.670000000,64.870000000,6,4,4,3,MCLN5
2025-06-11T00:00:06.897554280Z,2025-06-11T00:00:06.895074283Z,10,1,42026514,A,A,0,64.770000000,2,130,14735,79304773,64.760000000,64.770000000,5,2,5,1,64.750000000,64.780000000,4,5,4,5,64.740000000,64.790000000,8,6,7,4,64.730000000,64.800000000,7,5,7,5,64.720000000,64.810000000,9,7,6,7,64.710000000,64.820000000,9,9,8,6,64.700000000,64.830000000,7,9,6,9,64.690000000,64.840000000,4,6,3,5,64.680000000,64.850000000,4,8,2,5,64.670000000,64.860000000,6,4,4,3,MCLN5
2025-06-11T00:00:06.897587678Z,2025-06-11T00:00:06.895141671Z,10,1,42026514,A,A,0,64.770000000,1,130,13430,79304776,64.760000000,64.770000000,5,3,5,2,64.750000000,64.780000000,4,5,4,5,64.740000000,64.790000000,8,6,7,4,64.730000000,64.800000000,7,5,7,5,64.720000000,64.810000000,9,7,6,7,64.710000000,64.820000000,9,9,8,6,64.700000000,64.830000000,7,9,6,9,64.690000000,64.840000000,4,6,3,5,64.680000000,64.850000000,4,8,2,5,64.670000000,64.860000000,6,4,4,3,MCLN5
2025-06-11T00:00:06.897876093Z,2025-06-11T00:00:06.895469229Z,10,1,42025623,C,A,5,63.750000000,1,130,11894,79304791,63.670000000,63.700000000,2,2,2,2,63.660000000,63.710000000,3,2,3,2,63.650000000,63.720000000,3,3,3,3,63.640000000,63.730000000,3,4,3,4,63.630000000,63.740000000,7,5,7,5,63.620000000,63.750000000,3,2,3,2,63.610000000,63.760000000,3,3,3,3,63.600000000,63.770000000,7,1,7,1,63.590000000,63.780000000,1,3,1,3,63.580000000,63.790000000,6,1,4,1,MCLQ5
2025-06-11T00:00:06.897890085Z,2025-06-11T00:00:06.895473413Z,10,1,42025623,M,A,3,63.740000000,1,130,11716,79304792,63.670000000,63.700000000,2,2,2,2,63.660000000,63.710000000,3,2,3,2,63.650000000,63.720000000,3,3,3,3,63.640000000,63.730000000,3,3,3,3,63.630000000,63.740000000,7,6,7,6,63.620000000,63.750000000,3,2,3,2,63.610000000,63.760000000,3,3,3,3,63.600000000,63.770000000,7,1,7,1,63.590000000,63.780000000,1,3,1,3,63.580000000,63.790000000,6,1,4,1,MCLQ5
2025-06-11T00:00:06.897890085Z,2025-06-11T00:00:06.895474029Z,10,1,42025623,M,B,3,63.640000000,1,130,11716,79304792,63.670000000,63.700000000,2,2,2,2,63.660000000,63.710000000,3,2,3,2,63.650000000,63.720000000,3,3,3,3,63.640000000,63.730000000,4,3,4,3,63.630000000,63.740000000,6,6,6,6,63.620000000,63.750000000,3,2,3,2,63.610000000,63.760000000,3,3,3,3,63.600000000,63.770000000,7,1,7,1,63.590000000,63.780000000,1,3,1,3,63.580000000,63.790000000,6,1,4,1,MCLQ5
2025-06-11T00:00:06.897897189Z,2025-06-11T00:00:06.895474797Z,10,1,42025623,M,A,3,63.740000000,1,130,11512,79304793,63.670000000,63.700000000,2,2,2,2,63.660000000,63.710000000,3,2,3,2,63.650000000,63.720000000,3,3,3,3,63.640000000,63.730000000,4,2,4,2,63.630000000,63.740000000,6,7,6,7,63.620000000,63.750000000,3,2,3,2,63.610000000,63.760000000,3,3,3,3,63.600000000,63.770000000,7,1,7,1,63.590000000,63.780000000,1,3,1,3,63.580000000,63.790000000,6,1,4,1,MCLQ5
2025-06-11T00:00:06.897907364Z,2025-06-11T00:00:06.895475353Z,10,1,42025623,M,B,3,63.640000000,1,130,11418,79304794,63.670000000,63.700000000,2,2,2,2,63.660000000,63.710000000,3,2,3,2,63.650000000,63.720000000,3,3,3,3,63.640000000,63.730000000,5,2,5,2,63.630000000,63.740000000,5,7,5,7,63.620000000,63.750000000,3,2,3,2,63.610000000,63.760000000,3,3,3,3,63.600000000,63.770000000,7,1,7,1,63.590000000,63.780000000,1,3,1,3,63.580000000,63.790000000,6,1,4,1,MCLQ5
2025-06-11T00:00:06.897979975Z,2025-06-11T00:00:06.895591817Z,10,1,42026514,A,B,0,64.760000000,1,130,11321,79304798,64.760000000,64.770000000,6,3,6,2,64.750000000,64.780000000,4,5,4,5,64.740000000,64.790000000,8,6,7,4,64.730000000,64.800000000,7,5,7,5,64.720000000,64.810000000,9,7,6,7,64.710000000,64.820000000,9,9,8,6,64.700000000,64.830000000,7,9,6,9,64.690000000,64.840000000,4,6,3,5,64.680000000,64.850000000,4,8,2,5,64.670000000,64.860000000,6,4,4,3,MCLN5
2025-06-11T00:00:06.898099984Z,2025-06-11T00:00:06.895616603Z,10,1,42026514,A,A,0,64.770000000,1,130,13220,79304803,64.760000000,64.770000000,6,4,6,3,64.750000000,64.780000000,4,5,4,5,64.740000000,64.790000000,8,6,7,4,64.730000000,64.800000000,7,5,7,5,64.720000000,64.810000000,9,7,6,7,64.710000000,64.820000000,9,9,8,6,64.700000000,64.830000000,7,9,6,9,64.690000000,64.840000000,4,6,3,5,64.680000000,64.850000000,4,8,2,5,64.670000000,64.860000000,6,4,4,3,MCLN5
2025-06-11T00:00:06.898169300Z,2025-06-11T00:00:06.895626971Z,10,1,42025623,A,A,0,63.690000000,1,130,18339,79304806,63.670000000,63.690000000,2,1,2,1,63.660000000,63.700000000,3,2,3,2,63.650000000,63.710000000,3,2,3,2,63.640000000,63.720000000,5,3,5,3,63.630000000,63.730000000,5,2,5,2,63.620000000,63.740000000,3,7,3,7,63.610000000,63.750000000,3,2,3,2,63.600000000,63.760000000,7,3,7,3,63.590000000,63.770000000,1,1,1,1,63.580000000,63.780000000,6,3,4,3,MCLQ5
2025-06-11T00:00:06.898308961Z,2025-06-11T00:00:06.895869281Z,10,1,42026514,C,B,0,64.760000000,1,130,13138,79304814,64.760000000,64.770000000,5,4,5,3,64.750000000,64.780000000,4,5,4,5,64.740000000,64.790000000,8,6,7,4,64.730000000,64.800000000,7,5,7,5,64.720000000,64.810000000,9,7,6,7,64.710000000,64.820000000,9,9,8,6,64.700000000,64.830000000,7,9,6,9,64.690000000,64.840000000,4,6,3,5,64.680000000,64.850000000,4,8,2,5,64.670000000,64.860000000,6,4,4,3,MCLN5
2025-06-11T00:00:06.898344126Z,2025-06-11T00:00:06.896371283Z,10,1,42026514,M,A,4,64.820000000,1,130,11572,79304816,64.760000000,64.770000000,5,4,5,3,64.750000000,64.780000000,4,5,4,5,64.740000000,64.790000000,8,6,7,4,64.730000000,64.800000000,7,5,7,5,64.720000000,64.810000000,9,6,6,6,64.710000000,64.820000000,9,10,8,7,64.700000000,64.830000000,7,9,6,9,64.690000000,64.840000000,4,6,3,5,64.680000000,64.850000000,4,8,2,5,64.670000000,64.860000000,6,4,4,3,MCLN5
2025-06-11T00:00:06.898961059Z,2025-06-11T00:00:06.897170657Z,10,1,42026514,C,A,0,64.770000000,1,130,11370,79304850,64.760000000,64.770000000,5,3,5,2,64.750000000,64.780000000,4,5,4,5,64.740000000,64.790000000,8,6,7,4,64.730000000,64.800000000,7,5,7,5,64.720000000,64.810000000,9,6,6,6,64.710000000,64.820000000,9,10,8,7,64.700000000,64.830000000,7,9,6,9,64.690000000,64.840000000,4,6,3,5,64.680000000,64.850000000,4,8,2,5,64.670000000,64.860000000,6,4,4,3,MCLN5
2025-06-11T00:00:06.899082081Z,2025-06-11T00:00:06.897199437Z,10,1,42025623,C,A,0,63.690000000,1,130,19152,79304857,63.670000000,63.700000000,2,2,2,2,63.660000000,63.710000000,3,2,3,2,63.650000000,63.720000000,3,3,3,3,63.640000000,63.730000000,5,2,5,2,63.630000000,63.740000000,5,7,5,7,63.620000000,63.750000000,3,2,3,2,63.610000000,63.760000000,3,3,3,3,63.600000000,63.770000000,7,1,7,1,63.590000000,63.780000000,1,3,1,3,63.580000000,63.790000000,6,1,4,1,MCLQ5
2025-06-11T00:00:06.899330578Z,2025-06-11T00:00:06.897621953Z,10,1,42026514,A,A,0,64.770000000,1,130,13328,79304872,64.760000000,64.770000000,5,4,5,3,64.750000000,64.780000000,4,5,4,5,64.740000000,64.790000000,8,6,7,4,64.730000000,64.800000000,7,5,7,5,64.720000000,64.810000000,9,6,6,6,64.710000000,64.820000000,9,10,8,7,64.700000000,64.830000000,7,9,6,9,64.690000000,64.840000000,4,6,3,5,64.680000000,64.850000000,4,8,2,5,64.670000000,64.860000000,6,4,4,3,MCLN5
2025-06-11T00:00:06.899385679Z,2025-06-11T00:00:06.897835199Z,10,1,42026514,M,B,1,64.750000000,1,130,13209,79304875,64.760000000,64.770000000,5,4,5,3,64.750000000,64.780000000,5,5,5,5,64.740000000,64.790000000,8,6,7,4,64.730000000,64.800000000,7,5,7,5,64.720000000,64.810000000,9,6,6,6,64.710000000,64.820000000,9,10,8,7,64.700000000,64.830000000,7,9,6,9,64.690000000,64.840000000,4,6,3,5,64.680000000,64.850000000,4,8,2,5,64.670000000,64.860000000,6,4,4,3,MCLN5
2025-06-11T00:00:06.899787030Z,2025-06-11T00:00:06.898327331Z,10,1,42025623,A,A,0,63.690000000,1,130,15224,79304896,63.670000000,63.690000000,2,1,2,1,63.660000000,63.700000000,3,2,3,2,63.650000000,63.710000000,3,2,3,2,63.640000000,63.720000000,5,3,5,3,63.630000000,63.730000000,5,2,5,2,63.620000000,63.740000000,3,7,3,7,63.610000000,63.750000000,3,2,3,2,63.600000000,63.760000000,7,3,7,3,63.590000000,63.770000000,1,1,1,1,63.580000000,63.780000000,6,3,4,3,MCLQ5
2025-06-11T00:00:06.911149806Z,2025-06-11T00:00:06.911036689Z,10,1,42025623,A,A,6,63.750000000,1,130,15349,79304949,63.670000000,63.690000000,2,1,2,1,63.660000000,63.700000000,3,2,3,2,63.650000000,63.710000000,3,2,3,2,63.640000000,63.720000000,5,3,5,3,63.630000000,63.730000000,5,2,5,2,63.620000000,63.740000000,3,7,3,7,63.610000000,63.750000000,3,3,3,3,63.600000000,63.760000000,7,3,7,3,63.590000000,63.770000000,1,1,1,1,63.580000000,63.780000000,6,3,4,3,MCLQ5
2025-06-11T00:00:07.101387216Z,2025-06-11T00:00:07.100973045Z,10,1,42026514,C,A,0,64.770000000,1,130,13706,79305629,64.760000000,64.770000000,5,3,5,2,64.750000000,64.780000000,5,5,5,5,64.740000000,64.790000000,8,6,7,4,64.730000000,64.800000000,7,5,7,5,64.720000000,64.810000000,9,6,6,6,64.710000000,64.820000000,9,10,8,7,64.700000000,64.830000000,7,9,6,9,64.690000000,64.840000000,4,6,3,5,64.680000000,64.850000000,4,8,2,5,64.670000000,64.860000000,6,4,4,3,MCLN5
2025-06-11T00:00:07.101666661Z,2025-06-11T00:00:07.101153997Z,10,1,42026514,C,A,0,64.770000000,1,130,16897,79305641,64.760000000,64.770000000,5,2,5,1,64.750000000,64.780000000,5,5,5,5,64.740000000,64.790000000,8,6,7,4,64.730000000,64.800000000,7,5,7,5,64.720000000,64.810000000,9,6,6,6,64.710000000,64.820000000,9,10,8,7,64.700000000,64.830000000,7,9,6,9,64.690000000,64.840000000,4,6,3,5,64.680000000,64.850000000,4,8,2,5,64.670000000,64.860000000,6,4,4,3,MCLN5
2025-06-11T00:00:07.101691190Z,2025-06-11T00:00:07.101160775Z,10,1,42026514,M,A,4,64.810000000,1,130,11291,79305643,64.760000000,64.770000000,5,2,5,1,64.750000000,64.780000000,5,5,5,5,64.740000000,64.790000000,8,6,7,4,64.730000000,64.800000000,7,5,7,5,64.720000000,64.810000000,9,7,6,7,64.710000000,64.820000000,9,9,8,6,64.700000000,64.830000000,7,9,6,9,64.690000000,64.840000000,4,6,3,5,64.680000000,64.850000000,4,8,2,5,64.670000000,64.860000000,6,4,4,3,MCLN5
2025-06-11T00:00:07.102021266Z,2025-06-11T00:00:07.101226205Z,10,1,42026514,C,A,0,64.770000000,2,130,11411,79305659,64.760000000,64.780000000,5,5,5,5,64.750000000,64.790000000,5,6,5,4,64.740000000,64.800000000,8,5,7,5,64.730000000,64.810000000,7,7,7,7,64.720000000,64.820000000,9,9,6,6,64.710000000,64.830000000,9,9,8,9,64.700000000,64.840000000,7,6,6,5,64.690000000,64.850000000,4,8,3,5,64.680000000,64.860000000,4,4,2,3,64.670000000,64.870000000,6,4,4,3,MCLN5
2025-06-11T00:00:07.102774688Z,2025-06-11T00:00:07.101714747Z,10,1,42025623,C,A,0,63.690000000,1,130,19260,79305700,63.670000000,63.700000000,2,2,2,2,63.660000000,63.710000000,3,2,3,2,63.650000000,63.720000000,3,3,3,3,63.640000000,63.730000000,5,2,5,2,63.630000000,63.740000000,5,7,5,7,63.620000000,63.750000000,3,3,3,3,63.610000000,63.760000000,3,3,3,3,63.600000000,63.770000000,7,1,7,1,63.590000000,63.780000000,1,3,1,3,63.580000000,63.790000000,6,1,4,1,MCLQ5
2025-06-11T00:00:07.102794079Z,2025-06-11T00:00:07.101716591Z,10,1,42026514,A,B,0,64.770000000,2,130,14430,79305701,64.770000000,64.780000000,2,5,1,5,64.760000000,64.790000000,5,6,5,4,64.750000000,64.800000000,5,5,5,5,64.740000000,64.810000000,8,7,7,7,64.730000000,64.820000000,7,9,7,6,64.720000000,64.830000000,9,9,6,9,64.710000000,64.840000000,9,6,8,5,64.700000000,64.850000000,7,8,6,5,64.690000000,64.860000000,4,4,3,3,64.680000000,64.870000000,4,4,2,3,MCLN5
2025-06-11T00:00:07.103483047Z,2025-06-11T00:00:07.102726427Z,10,1,42025623,M,B,2,62.290000000,1,130,11837,79305738,63.670000000,63.700000000,2,2,2,2,63.660000000,63.710000000,3,2,3,2,63.650000000,63.720000000,2,3,2,3,63.640000000,63.730000000,5,2,5,2,63.630000000,63.740000000,5,7,5,7,63.620000000,63.750000000,3,3,3,3,63.610000000,63.760000000,3,3,3,3,63.600000000,63.770000000,7,1,7,1,63.590000000,63.780000000,1,3,1,3,63.580000000,63.790000000,6,1,4,1,MCLQ5
2025-06-11T00:00:07.103525300Z,2025-06-11T00:00:07.102782469Z,10,1,42025623,C,A,5,63.750000000,1,130,11510,79305740,63.670000000,63.700000000,2,2,2,2,63.660000000,63.710000000,3,2,3,2,63.650000000,63.720000000,2,3,2,3,63.640000000,63.730000000,5,2,5,2,63.630000000,63.740000000,5,7,5,7,63.620000000,63.750000000,3,2,3,2,63.610000000,63.760000000,3,3,3,3,63.600000000,63.770000000,7,1,7,1,63.590000000,63.780000000,1,3,1,3,63.580000000,63.790000000,6,1,4,1,MCLQ5
2025-06-11T00:00:07.103534938Z,2025-06-11T00:00:07.102801379Z,10,1,42026514,C,A,5,64.830000000,1,130,11701,79305741,64.770000000,64.780000000,2,5,1,5,64.760000000,64.790000000,5,6,5,4,64.750000000,64.800000000,5,5,5,5,64.740000000,64.810000000,8,7,7,7,64.730000000,64.820000000,7,9,7,6,64.720000000,64.830000000,9,8,6,8,64.710000000,64.840000000,9,6,8,5,64.700000000,64.850000000,7,8,6,5,64.690000000,64.860000000,4,4,3,3,64.680000000,64.870000000,4,4,2,3,MCLN5
2025-06-11T00:00:07.103560711Z,2025-06-11T00:00:07.102813303Z,10,1,42026514,C,B,0,64.770000000,2,130,13699,79305742,64.760000000,64.780000000,5,5,5,5,64.750000000,64.790000000,5,6,5,4,64.740000000,64.800000000,8,5,7,5,64.730000000,64.810000000,7,7,7,7,64.720000000,64.820000000,9,9,6,6,64.710000000,64.830000000,9,8,8,8,64.700000000,64.840000000,7,6,6,5,64.690000000,64.850000000,4,8,3,5,64.680000000,64.860000000,4,4,2,3,64.670000000,64.870000000,6,4,4,3,MCLN5
2025-06-11T00:00:07.103600261Z,2025-06-11T00:00:07.103018657Z,10,1,42026514,M,B,2,64.740000000,1,130,11351,79305746,64.760000000,64.780000000,5,5,5,5,64.750000000,64.790000000,5,6,5,4,64.740000000,64.800000000,9,5,8,5,64.730000000,64.810000000,7,7,7,7,64.720000000,64.820000000,9,9,6,6,64.710000000,64.830000000,9,8,8,8,64.700000000,64.840000000,7,6,6,5,64.690000000,64.850000000,4,8,3,5,64.680000000,64.860000000,4,4,2,3,64.670000000,64.870000000,6,4,4,3,MCLN5
2025-06-11T00:00:07.104015081Z,2025-06-11T00:00:07.103592885Z,10,1,42025623,M,B,2,63.650000000,1,130,11689,79305786,63.670000000,63.700000000,2,2,2,2,63.660000000,63.710000000,3,2,3,2,63.650000000,63.720000000,3,3,3,3,63.640000000,63.730000000,5,2,5,2,63.630000000,63.740000000,5,7,5,7,63.620000000,63.750000000,3,2,3,2,63.610000000,63.760000000,3,3,3,3,63.600000000,63.770000000,7,1,7,1,63.590000000,63.780000000,1,3,1,3,63.580000000,63.790000000,6,1,4,1,MCLQ5
2025-06-11T00:00:07.118375765Z,2025-06-11T00:00:07.118264895Z,10,1,42026514,A,A,5,64.830000000,1,130,15322,79305850,64.760000000,64.780000000,5,5,5,5,64.750000000,64.790000000,5,6,5,4,64.740000000,64.800000000,9,5,8,5,64.730000000,64.810000000,7,7,7,7,64.720000000,64.820000000,9,9,6,6,64.710000000,64.830000000,9,9,8,9,64.700000000,64.840000000,7,6,6,5,64.690000000,64.850000000,4,8,3,5,64.680000000,64.860000000,4,4,2,3,64.670000000,64.870000000,6,4,4,3,MCLN5
2025-06-11T00:00:07.118384527Z,2025-06-11T00:00:07.118267447Z,10,1,42025623,C,B,6,63.610000000,1,130,11755,79305851,63.670000000,63.700000000,2,2,2,2,63.660000000,63.710000000,3,2,3,2,63.650000000,63.720000000,3,3,3,3,63.640000000,63.730000000,5,2,5,2,63.630000000,63.740000000,5,7,5,7,63.620000000,63.750000000,3,2,3,2,63.610000000,63.760000000,2,3,2,3,63.600000000,63.770000000,7,1,7,1,63.590000000,63.780000000,1,3,1,3,63.580000000,63.790000000,6,1,4,1,MCLQ5
2025-06-11T00:00:07.118394165Z,2025-06-11T00:00:07.118269023Z,10,1,42025623,A,A,6,63.760000000,1,130,11290,79305852,63.670000000,63.700000000,2,2,2,2,63.660000000,63.710000000,3,2,3,2,63.650000000,63.720000000,3,3,3,3,63.640000000,63.730000000,5,2,5,2,63.630000000,63.740000000,5,7,5,7,63.620000000,63.750000000,3,2,3,2,63.610000000,63.760000000,2,4,2,4,63.600000000,63.770000000,7,1,7,1,63.590000000,63.780000000,1,3,1,3,63.580000000,63.790000000,6,1,4,1,MCLQ5
2025-06-11T00:00:07.118504943Z,2025-06-11T00:00:07.118418755Z,10,1,42025623,A,B,5,63.620000000,1,130,11452,79305854,63.670000000,63.700000000,2,2,2,2,63.660000000,63.710000000,3,2,3,2,63.650000000,63.720000000,3,3,3,3,63.640000000,63.730000000,5,2,5,2,63.630000000,63.740000000,5,7,5,7,63.620000000,63.750000000,4,2,4,2,63.610000000,63.760000000,2,4,2,4,63.600000000,63.770000000,7,1,7,1,63.590000000,63.780000000,1,3,1,3,63.580000000,63.790000000,6,1,4,1,MCLQ5
2025-06-11T00:00:07.201391667Z,2025-06-11T00:00:07.201241187Z,10,1,42026514,A,A,0,64.770000000,2,130,15139,79306033,64.760000000,64.770000000,5,2,5,1,64.750000000,64.780000000,5,5,5,5,64.740000000,64.790000000,9,6,8,4,64.730000000,64.800000000,7,5,7,5,64.720000000,64.810000000,9,7,6,7,64.710000000,64.820000000,9,9,8,6,64.700000000,64.830000000,7,9,6,9,64.690000000,64.840000000,4,6,3,5,64.680000000,64.850000000,4,8,2,5,64.670000000,64.860000000,6,4,4,3,MCLN5
2025-06-11T00:00:07.201509480Z,2025-06-11T00:00:07.201412733Z,10,1,42025623,C,B,5,63.620000000,1,130,15656,79306036,63.670000000,63.700000000,2,2,2,2,63.660000000,63.710000000,3,2,3,2,63.650000000,63.720000000,3,3,3,3,63.640000000,63.730000000,5,2,5,2,63.630000000,63.740000000,5,7,5,7,63.620000000,63.750000000,3,2,3,2,63.610000000,63.760000000,2,4,2,4,63.600000000,63.770000000,7,1,7,1,63.590000000,63.780000000,1,3,1,3,63.580000000,63.790000000,6,1,4,1,MCLQ5
2025-06-11T00:00:07.201519655Z,2025-06-11T00:00:07.201414883Z,10,1,42025623,M,B,3,63.630000000,1,130,13159,79306037,63.670000000,63.700000000,2,2,2,2,63.660000000,63.710000000,3,2,3,2,63.650000000,63.720000000,3,3,3,3,63.640000000,63.730000000,4,2,4,2,63.630000000,63.740000000,6,7,6,7,63.620000000,63.750000000,3,2,3,2,63.610000000,63.760000000,2,4,2,4,63.600000000,63.770000000,7,1,7,1,63.590000000,63.780000000,1,3,1,3,63.580000000,63.790000000,6,1,4,1,MCLQ5
2025-06-11T00:00:07.201530284Z,2025-06-11T00:00:07.201415381Z,10,1,42025623,M,A,3,63.730000000,1,130,11335,79306038,63.670000000,63.700000000,2,2,2,2,63.660000000,63.710000000,3,2,3,2,63.650000000,63.720000000,3,3,3,3,63.640000000,63.730000000,4,3,4,3,63.630000000,63.740000000,6,6,6,6,63.620000000,63.750000000,3,2,3,2,63.610000000,63.760000000,2,4,2,4,63.600000000,63.770000000,7,1,7,1,63.590000000,63.780000000,1,3,1,3,63.580000000,63.790000000,6,1,4,1,MCLQ5
2025-06-11T00:00:07.201538286Z,2025-06-11T00:00:07.201415957Z,10,1,42025623,M,B,3,63.630000000,1,130,11475,79306039,63.670000000,63.700000000,2,2,2,2,63.660000000,63.710000000,3,2,3,2,63.650000000,63.720000000,3,3,3,3,63.640000000,63.730000000,3,3,3,3,63.630000000,63.740000000,7,6,7,6,63.620000000,63.750000000,3,2,3,2,63.610000000,63.760000000,2,4,2,4,63.600000000,63.770000000,7,1,7,1,63.590000000,63.780000000,1,3,1,3,63.580000000,63.790000000,6,1,4,1,MCLQ5
2025-06-11T00:00:07.201549598Z,2025-06-11T00:00:07.201416533Z,10,1,42025623,M,A,3,63.730000000,1,130,11308,79306040,63.670000000,63.700000000,2,2,2,2,63.660000000,63.710000000,3,2,3,2,63.650000000,63.720000000,3,3,3,3,63.640000000,63.730000000,3,4,3,4,63.630000000,63.740000000,7,5,7,5,63.620000000,63.750000000,3,2,3,2,63.610000000,63.760000000,2,4,2,4,63.600000000,63.770000000,7,1,7,1,63.590000000,63.780000000,1,3,1,3,63.580000000,63.790000000,6,1,4,1,MCLQ5
2025-06-11T00:00:07.201563606Z,2025-06-11T00:00:07.201417225Z,10,1,42025623,C,A,6,63.760000000,1,130,14431,79306041,63.670000000,63.700000000,2,2,2,2,63.660000000,63.710000000,3,2,3,2,63.650000000,63.720000000,3,3,3,3,63.640000000,63.730000000,3,4,3,4,63.630000000,63.740000000,7,5,7,5,63.620000000,63.750000000,3,2,3,2,63.610000000,63.760000000,2,3,2,3,63.600000000,63.770000000,7,1,7,1,63.590000000,63.780000000,1,3,1,3,63.580000000,63.790000000,6,1,4,1,MCLQ5
2025-06-11T00:00:07.201643897Z,2025-06-11T00:00:07.201547395Z,10,1,42025623,A,B,6,63.610000000,1,130,14671,79306042,63.670000000,63.700000000,2,2,2,2,63.660000000,63.710000000,3,2,3,2,63.650000000,63.720000000,3,3,3,3,63.640000000,63.730000000,3,4,3,4,63.630000000,63.740000000,7,5,7,5,63.620000000,63.750000000,3,2,3,2,63.610000000,63.760000000,3,3,3,3,63.600000000,63.770000000,7,1,7,1,63.590000000,63.780000000,1,3,1,3,63.580000000,63.790000000,6,1,4,1,MCLQ5
2025-06-11T00:00:07.201685681Z,2025-06-11T00:00:07.201597965Z,10,1,42025623,A,A,5,63.750000000,1,130,11457,79306043,63.670000000,63.700000000,2,2,2,2,63.660000000,63.710000000,3,2,3,2,63.650000000,63.720000000,3,3,3,3,63.640000000,63.730000000,3,4,3,4,63.630000000,63.740000000,7,5,7,5,63.620000000,63.750000000,3,3,3,3,63.610000000,63.760000000,3,3,3,3,63.600000000,63.770000000,7,1,7,1,63.590000000,63.780000000,1,3,1,3,63.580000000,63.790000000,6,1,4,1,MCLQ5
2025-06-11T00:00:07.203052135Z,2025-06-11T00:00:07.202942423Z,10,1,42026514,M,A,4,64.810000000,1,130,15472,79306044,64.760000000,64.770000000,5,2,5,1,64.750000000,64.780000000,5,5,5,5,64.740000000,64.790000000,9,6,8,4,64.730000000,64.800000000,7,5,7,5,64.720000000,64.810000000,9,8,6,8,64.710000000,64.820000000,9,9,8,6,64.700000000,64.830000000,7,9,6,9,64.690000000,64.840000000,4,6,3,5,64.680000000,64.850000000,4,8,2,5,64.670000000,64.860000000,6,4,4,3,MCLN5
2025-06-11T00:00:07.305188197Z,2025-06-11T00:00:07.304941683Z,10,1,42025623,A,A,0,63.690000000,1,130,15569,79306146,63.670000000,63.690000000,2,1,2,1,63.660000000,63.700000000,3,2,3,2,63.650000000,63.710000000,3,2,3,2,63.640000000,63.720000000,3,3,3,3,63.630000000,63.730000000,7,4,7,4,63.620000000,63.740000000,3,5,3,5,63.610000000,63.750000000,3,3,3,3,63.600000000,63.760000000,7,3,7,3,63.590000000,63.770000000,1,1,1,1,63.580000000,63.780000000,6,3,4,3,MCLQ5
2025-06-11T00:00:07.318807753Z,2025-06-11T00:00:07.318679035Z,10,1,42025623,C,A,0,63.690000000,1,130,19641,79306201,63.670000000,63.700000000,2,2,2,2,63.660000000,63.710000000,3,2,3,2,63.650000000,63.720000000,3,3,3,3,63.640000000,63.730000000,3,4,3,4,63.630000000,63.740000000,7,5,7,5,63.620000000,63.750000000,3,3,3,3,63.610000000,63.760000000,3,3,3,3,63.600000000,63.770000000,7,1,7,1,63.590000000,63.780000000,1,3,1,3,63.580000000,63.790000000,6,1,4,1,MCLQ5
2025-06-11T00:00:07.620586055Z,2025-06-11T00:00:07.620468207Z,10,1,42026514,C,A,0,64.770000000,2,130,14605,79306444,64.760000000,64.780000000,5,5,5,5,64.750000000,64.790000000,5,6,5,4,64.740000000,64.800000000,9,5,8,5,64.730000000,64.810000000,7,8,7,8,64.720000000,64.820000000,9,9,6,6,64.710000000,64.830000000,9,9,8,9,64.700000000,64.840000000,7,6,6,5,64.690000000,64.850000000,4,8,3,5,64.680000000,64.860000000,4,4,2,3,64.670000000,64.870000000,6,4,4,3,MCLN5
2025-06-11T00:00:07.620688047Z,2025-06-11T00:00:07.620594095Z,10,1,42026514,M,A,3,64.820000000,1,130,15298,79306447,64.760000000,64.780000000,5,5,5,5,64.750000000,64.790000000,5,6,5,4,64.740000000,64.800000000,9,5,8,5,64.730000000,64.810000000,7,7,7,7,64.720000000,64.820000000,9,10,6,7,64.710000000,64.830000000,9,9,8,9,64.700000000,64.840000000,7,6,6,5,64.690000000,64.850000000,4,8,3,5,64.680000000,64.860000000,4,4,2,3,64.670000000,64.870000000,6,4,4,3,MCLN5
2025-06-11T00:00:07.620696418Z,2025-06-11T00:00:07.620594843Z,10,1,42026514,M,B,3,64.730000000,1,130,11384,79306448,64.760000000,64.780000000,5,5,5,5,64.750000000,64.790000000,5,6,5,4,64.740000000,64.800000000,9,5,8,5,64.730000000,64.810000000,8,7,8,7,64.720000000,64.820000000,8,10,5,7,64.710000000,64.830000000,9,9,8,9,64.700000000,64.840000000,7,6,6,5,64.690000000,64.850000000,4,8,3,5,64.680000000,64.860000000,4,4,2,3,64.670000000,64.870000000,6,4,4,3,MCLN5
2025-06-11T00:00:07.620706686Z,2025-06-11T00:00:07.620607247Z,10,1,42025623,C,A,5,63.750000000,1,130,11688,79306449,63.670000000,63.700000000,2,2,2,2,63.660000000,63.710000000,3,2,3,2,63.650000000,63.720000000,3,3,3,3,63.640000000,63.730000000,3,4,3,4,63.630000000,63.740000000,7,5,7,5,63.620000000,63.750000000,3,2,3,2,63.610000000,63.760000000,3,3,3,3,63.600000000,63.770000000,7,1,7,1,63.590000000,63.780000000,1,3,1,3,63.580000000,63.790000000,6,1,4,1,MCLQ5
2025-06-11T00:00:07.620718643Z,2025-06-11T00:00:07.620610665Z,10,1,42025623,M,A,3,63.740000000,1,130,12070,79306450,63.670000000,63.700000000,2,2,2,2,63.660000000,63.710000000,3,2,3,2,63.650000000,63.720000000,3,3,3,3,63.640000000,63.730000000,3,3,3,3,63.630000000,63.740000000,7,6,7,6,63.620000000,63.750000000,3,2,3,2,63.610000000,63.760000000,3,3,3,3,63.600000000,63.770000000,7,1,7,1,63.590000000,63.780000000,1,3,1,3,63.580000000,63.790000000,6,1,4,1,MCLQ5
2025-06-11T00:00:07.620734593Z,2025-06-11T00:00:07.620611163Z,10,1,42025623,M,B,3,63.640000000,1,130,11817,79306451,63.670000000,63.700000000,2,2,2,2,63.660000000,63.710000000,3,2,3,2,63.650000000,63.720000000,3,3,3,3,63.640000000,63.730000000,4,3,4,3,63.630000000,63.740000000,6,6,6,6,63.620000000,63.750000000,3,2,3,2,63.610000000,63.760000000,3,3,3,3,63.600000000,63.770000000,7,1,7,1,63.590000000,63.780000000,1,3,1,3,63.580000000,63.790000000,6,1,4,1,MCLQ5
2025-06-11T00:00:07.620745537Z,2025-06-11T00:00:07.620611605Z,10,1,42025623,M,A,3,63.740000000,1,130,11376,79306452,63.670000000,63.700000000,2,2,2,2,63.660000000,63.710000000,3,2,3,2,63.650000000,63.720000000,3,3,3,3,63.640000000,63.730000000,4,2,4,2,63.630000000,63.740000000,6,7,6,7,63.620000000,63.750000000,3,2,3,2,63.610000000,63.760000000,3,3,3,3,63.600000000,63.770000000,7,1,7,1,63.590000000,63.780000000,1,3,1,3,63.580000000,63.790000000,6,1,4,1,MCLQ5
2025-06-11T00:00:07.620756595Z,2025-06-11T00:00:07.620612143Z,10,1,42025623,M,B,3,63.640000000,1,130,11402,79306453,63.670000000,63.700000000,2,2,2,2,63.660000000,63.710000000,3,2,3,2,63.650000000,63.720000000,3,3,3,3,63.640000000,63.730000000,5,2,5,2,63.630000000,63.740000000,5,7,5,7,63.620000000,63.750000000,3,2,3,2,63.610000000,63.760000000,3,3,3,3,63.600000000,63.770000000,7,1,7,1,63.590000000,63.780000000,1,3,1,3,63.580000000,63.790000000,6,1,4,1,MCLQ5
2025-06-11T00:00:07.620767231Z,2025-06-11T00:00:07.620612835Z,10,1,42025623,C,B,6,63.610000000,1,130,11388,79306454,63.670000000,63.700000000,2,2,2,2,63.660000000,63.710000000,3,2,3,2,63.650000000,63.720000000,3,3,3,3,63.640000000,63.730000000,5,2,5,2,63.630000000,63.740000000,5,7,5,7,63.620000000,63.750000000,3,2,3,2,63.610000000,63.760000000,2,3,2,3,63.600000000,63.770000000,7,1,7,1,63.590000000,63.780000000,1,3,1,3,63.580000000,63.790000000,6,1,4,1,MCLQ5
2025-06-11T00:00:07.620833476Z,2025-06-11T00:00:07.620737033Z,10,1,42025623,A,A,6,63.760000000,1,130,14859,79306455,63.670000000,63.700000000,2,2,2,2,63.660000000,63.710000000,3,2,3,2,63.650000000,63.720000000,3,3,3,3,63.640000000,63.730000000,5,2,5,2,63.630000000,63.740000000,5,7,5,7,63.620000000,63.750000000,3,2,3,2,63.610000000,63.760000000,2,4,2,4,63.600000000,63.770000000,7,1,7,1,63.590000000,63.780000000,1,3,1,3,63.580000000,63.790000000,6,1,4,1,MCLQ5
2025-06-11T00:00:07.620870929Z,2025-06-11T00:00:07.620784437Z,10,1,42025623,A,B,5,63.620000000,1,130,11327,79306456,63.670000000,63.700000000,2,2,2,2,63.660000000,63.710000000,3,2,3,2,63.650000000,63.720000000,3,3,3,3,63.640000000,63.730000000,5,2,5,2,63.630000000,63.740000000,5,7,5,7,63.620000000,63.750000000,4,2,4,2,63.610000000,63.760000000,2,4,2,4,63.600000000,63.770000000,7,1,7,1,63.590000000,63.780000000,1,3,1,3,63.580000000,63.790000000,6,1,4,1,MCLQ5
2025-06-11T00:00:07.742839468Z,2025-06-11T00:00:07.734666523Z,10,1,42026514,A,A,0,64.770000000,2,130,15156,79306493,64.760000000,64.770000000,5,2,5,1,64.750000000,64.780000000,5,5,5,5,64.740000000,64.790000000,9,6,8,4,64.730000000,64.800000000,8,5,8,5,64.720000000,64.810000000,8,7,5,7,64.710000000,64.820000000,9,10,8,7,64.700000000,64.830000000,7,9,6,9,64.690000000,64.840000000,4,6,3,5,64.680000000,64.850000000,4,8,2,5,64.670000000,64.860000000,6,4,4,3,MCLN5
2025-06-11T00:00:07.742961382Z,2025-06-11T00:00:07.742860989Z,10,1,42025623,C,B,5,63.620000000,1,130,14986,79306496,63.670000000,63.700000000,2,2,2,2,63.660000000,63.710000000,3,2,3,2,63.650000000,63.720000000,3,3,3,3,63.640000000,63.730000000,5,2,5,2,63.630000000,63.740000000,5,7,5,7,63.620000000,63.750000000,3,2,3,2,63.610000000,63.760000000,2,4,2,4,63.600000000,63.770000000,7,1,7,1,63.590000000,63.780000000,1,3,1,3,63.580000000,63.790000000,6,1,4,1,MCLQ5
2025-06-11T00:00:07.742971350Z,2025-06-11T00:00:07.742866845Z,10,1,42025623,C,A,6,63.760000000,1,130,11376,79306497,63.670000000,63.700000000,2,2,2,2,63.660000000,63.710000000,3,2,3,2,63.650000000,63.720000000,3,3,3,3,63.640000000,63.730000000,5,2,5,2,63.630000000,63.740000000,5,7,5,7,63.620000000,63.750000000,3,2,3,2,63.610000000,63.760000000,2,3,2,3,63.600000000,63.770000000,7,1,7,1,63.590000000,63.780000000,1,3,1,3,63.580000000,63.790000000,6,1,4,1,MCLQ5
2025-06-11T00:00:07.743093094Z,2025-06-11T00:00:07.742991429Z,10,1,42025623,A,B,6,63.610000000,1,130,14672,79306498,63.670000000,63.700000000,2,2,2,2,63.660000000,63.710000000,3,2,3,2,63.650000000,63.720000000,3,3,3,3,63.640000000,63.730000000,5,2,5,2,63.630000000,63.740000000,5,7,5,7,63.620000000,63.750000000,3,2,3,2,63.610000000,63.760000000,3,3,3,3,63.600000000,63.770000000,7,1,7,1,63.590000000,63.780000000,1,3,1,3,63.580000000,63.790000000,6,1,4,1,MCLQ5
2025-06-11T00:00:07.743101565Z,2025-06-11T00:00:07.743001739Z,10,1,42025623,A,A,5,63.750000000,1,130,11333,79306499,63.670000000,63.700000000,2,2,2,2,63.660000000,63.710000000,3,2,3,2,63.650000000,63.720000000,3,3,3,3,63.640000000,63.730000000,5,2,5,2,63.630000000,63.740000000,5,7,5,7,63.620000000,63.750000000,3,3,3,3,63.610000000,63.760000000,3,3,3,3,63.600000000,63.770000000,7,1,7,1,63.590000000,63.780000000,1,3,1,3,63.580000000,63.790000000,6,1,4,1,MCLQ5
2025-06-11T00:00:07.991524842Z,2025-06-11T00:00:07.991400259Z,10,1,42026514,C,A,0,64.770000000,2,130,14971,79306648,64.760000000,64.780000000,5,5,5,5,64.750000000,64.790000000,5,6,5,4,64.740000000,64.800000000,9,5,8,5,64.730000000,64.810000000,8,7,8,7,64.720000000,64.820000000,8,10,5,7,64.710000000,64.830000000,9,9,8,9,64.700000000,64.840000000,7,6,6,5,64.690000000,64.850000000,4,8,3,5,64.680000000,64.860000000,4,4,2,3,64.670000000,64.870000000,6,4,4,3,MCLN5
2025-06-11T00:00:07.991648507Z,2025-06-11T00:00:07.991546903Z,10,1,42025623,C,A,5,63.750000000,1,130,14907,79306651,63.670000000,63.700000000,2,2,2,2,63.660000000,63.710000000,3,2,3,2,63.650000000,63.720000000,3,3,3,3,63.640000000,63.730000000,5,2,5,2,63.630000000,63.740000000,5,7,5,7,63.620000000,63.750000000,3,2,3,2,63.610000000,63.760000000,3,3,3,3,63.600000000,63.770000000,7,1,7,1,63.590000000,63.780000000,1,3,1,3,63.580000000,63.790000000,6,1,4,1,MCLQ5
2025-06-11T00:00:07.991658329Z,2025-06-11T00:00:07.991551569Z,10,1,42025623,C,B,6,63.610000000,1,130,11820,79306652,63.670000000,63.700000000,2,2,2,2,63.660000000,63.710000000,3,2,3,2,63.650000000,63.720000000,3,3,3,3,63.640000000,63.730000000,5,2,5,2,63.630000000,63.740000000,5,7,5,7,63.620000000,63.750000000,3,2,3,2,63.610000000,63.760000000,2,3,2,3,63.600000000,63.770000000,7,1,7,1,63.590000000,63.780000000,1,3,1,3,63.580000000,63.790000000,6,1,4,1,MCLQ5
2025-06-11T00:00:07.991768293Z,2025-06-11T00:00:07.991670929Z,10,1,42025623,A,A,6,63.760000000,1,130,14595,79306653,63.670000000,63.700000000,2,2,2,2,63.660000000,63.710000000,3,2,3,2,63.650000000,63.720000000,3,3,3,3,63.640000000,63.730000000,5,2,5,2,63.630000000,63.740000000,5,7,5,7,63.620000000,63.750000000,3,2,3,2,63.610000000,63.760000000,2,4,2,4,63.600000000,63.770000000,7,1,7,1,63.590000000,63.780000000,1,3,1,3,63.580000000,63.790000000,6,1,4,1,MCLQ5
2025-06-11T00:00:07.991776956Z,2025-06-11T00:00:07.991679145Z,10,1,42025623,A,B,5,63.620000000,1,130,11488,79306654,63.670000000,63.700000000,2,2,2,2,63.660000000,63.710000000,3,2,3,2,63.650000000,63.720000000,3,3,3,3,63.640000000,63.730000000,5,2,5,2,63.630000000,63.740000000,5,7,5,7,63.620000000,63.750000000,4,2,4,2,63.610000000,63.760000000,2,4,2,4,63.600000000,63.770000000,7,1,7,1,63.590000000,63.780000000,1,3,1,3,63.580000000,63.790000000,6,1,4,1,MCLQ5
2025-06-11T00:00:09.050137410Z,2025-06-11T00:00:09.049983599Z,10,1,42026514,A,A,0,64.770000000,2,130,14691,79306825,64.760000000,64.770000000,5,2,5,1,64.750000000,64.780000000,5,5,5,5,64.740000000,64.790000000,9,6,8,4,64.730000000,64.800000000,8,5,8,5,64.720000000,64.810000000,8,7,5,7,64.710000000,64.820000000,9,10,8,7,64.700000000,64.830000000,7,9,6,9,64.690000000,64.840000000,4,6,3,5,64.680000000,64.850000000,4,8,2,5,64.670000000,64.860000000,6,4,4,3,MCLN5
2025-06-11T00:00:09.050239410Z,2025-06-11T00:00:09.050146945Z,10,1,42026514,M,B,3,64.720000000,1,130,14775,79306828,64.760000000,64.770000000,5,2,5,1,64.750000000,64.780000000,5,5,5,5,64.740000000,64.790000000,9,6,8,4,64.730000000,64.800000000,7,5,7,5,64.720000000,64.810000000,9,7,6,7,64.710000000,64.820000000,9,10,8,7,64.700000000,64.830000000,7,9,6,9,64.690000000,64.840000000,4,6,3,5,64.680000000,64.850000000,4,8,2,5,64.670000000,64.860000000,6,4,4,3,MCLN5
2025-06-11T00:00:09.050249009Z,2025-06-11T00:00:09.050147463Z,10,1,42026514,M,A,4,64.810000000,1,130,12410,79306829,64.760000000,64.770000000,5,2,5,1,64.750000000,64.780000000,5,5,5,5,64.740000000,64.790000000,9,6,8,4,64.730000000,64.800000000,7,5,7,5,64.720000000,64.810000000,9,8,6,8,64.710000000,64.820000000,9,9,8,6,64.700000000,64.830000000,7,9,6,9,64.690000000,64.840000000,4,6,3,5,64.680000000,64.850000000,4,8,2,5,64.670000000,64.860000000,6,4,4,3,MCLN5
2025-06-11T00:00:09.050258878Z,2025-06-11T00:00:09.050158177Z,10,1,42025623,C,B,5,63.620000000,1,130,12574,79306830,63.670000000,63.700000000,2,2,2,2,63.660000000,63.710000000,3,2,3,2,63.650000000,63.720000000,3,3,3,3,63.640000000,63.730000000,5,2,5,2,63.630000000,63.740000000,5,7,5,7,63.620000000,63.750000000,3,2,3,2,63.610000000,63.760000000,2,4,2,4,63.600000000,63.770000000,7,1,7,1,63.590000000,63.780000000,1,3,1,3,63.580000000,63.790000000,6,1,4,1,MCLQ5
2025-06-11T00:00:09.050268300Z,2025-06-11T00:00:09.050161229Z,10,1,42025623,M,B,3,63.630000000,1,130,11686,79306831,63.670000000,63.700000000,2,2,2,2,63.660000000,63.710000000,3,2,3,2,63.650000000,63.720000000,3,3,3,3,63.640000000,63.730000000,4,2,4,2,63.630000000,63.740000000,6,7,6,7,63.620000000,63.750000000,3,2,3,2,63.610000000,63.760000000,2,4,2,4,63.600000000,63.770000000,7,1,7,1,63.590000000,63.780000000,1,3,1,3,63.580000000,63.790000000,6,1,4,1,MCLQ5
2025-06-11T00:00:09.050284789Z,2025-06-11T00:00:09.050161709Z,10,1,42025623,M,A,3,63.730000000,1,130,11617,79306832,63.670000000,63.700000000,2,2,2,2,63.660000000,63.710000000,3,2,3,2,63.650000000,63.720000000,3,3,3,3,63.640000000,63.730000000,4,3,4,3,63.630000000,63.740000000,6,6,6,6,63.620000000,63.750000000,3,2,3,2,63.610000000,63.760000000,2,4,2,4,63.600000000,63.770000000,7,1,7,1,63.590000000,63.780000000,1,3,1,3,63.580000000,63.790000000,6,1,4,1,MCLQ5
2025-06-11T00:00:09.050296969Z,2025-06-11T00:00:09.050162457Z,10,1,42025623,M,B,3,63.630000000,1,130,11749,79306833,63.670000000,63.700000000,2,2,2,2,63.660000000,63.710000000,3,2,3,2,63.650000000,63.720000000,3,3,3,3,63.640000000,63.730000000,3,3,3,3,63.630000000,63.740000000,7,6,7,6,63.620000000,63.750000000,3,2,3,2,63.610000000,63.760000000,2,4,2,4,63.600000000,63.770000000,7,1,7,1,63.590000000,63.780000000,1,3,1,3,63.580000000,63.790000000,6,1,4,1,MCLQ5
2025-06-11T00:00:09.050307859Z,2025-06-11T00:00:09.050162995Z,10,1,42025623,M,A,3,63.730000000,1,130,11691,79306834,63.670000000,63.700000000,2,2,2,2,63.660000000,63.710000000,3,2,3,2,63.650000000,63.720000000,3,3,3,3,63.640000000,63.730000000,3,4,3,4,63.630000000,63.740000000,7,5,7,5,63.620000000,63.750000000,3,2,3,2,63.610000000,63.760000000,2,4,2,4,63.600000000,63.770000000,7,1,7,1,63.590000000,63.780000000,1,3,1,3,63.580000000,63.790000000,6,1,4,1,MCLQ5
2025-06-11T00:00:09.050318533Z,2025-06-11T00:00:09.050163897Z,10,1,42025623,C,A,6,63.760000000,1,130,11270,79306835,63.670000000,63.700000000,2,2,2,2,63.660000000,63.710000000,3,2,3,2,63.650000000,63.720000000,3,3,3,3,63.640000000,63.730000000,3,4,3,4,63.630000000,63.740000000,7,5,7,5,63.620000000,63.750000000,3,2,3,2,63.610000000,63.760000000,2,3,2,3,63.600000000,63.770000000,7,1,7,1,63.590000000,63.780000000,1,3,1,3,63.580000000,63.790000000,6,1,4,1,MCLQ5
2025-06-11T00:00:09.050383894Z,2025-06-11T00:00:09.050289727Z,10,1,42025623,A,B,6,63.610000000,1,130,14580,79306836,63.670000000,63.700000000,2,2,2,2,63.660000000,63.710000000,3,2,3,2,63.650000000,63.720000000,3,3,3,3,63.640000000,63.730000000,3,4,3,4,63.630000000,63.740000000,7,5,7,5,63.620000000,63.750000000,3,2,3,2,63.610000000,63.760000000,3,3,3,3,63.600000000,63.770000000,7,1,7,1,63.590000000,63.780000000,1,3,1,3,63.580000000,63.790000000,6,1,4,1,MCLQ5
2025-06-11T00:00:09.050429818Z,2025-06-11T00:00:09.050344351Z,10,1,42025623,A,A,5,63.750000000,1,130,11244,79306837,63.670000000,63.700000000,2,2,2,2,63.660000000,63.710000000,3,2,3,2,63.650000000,63.720000000,3,3,3,3,63.640000000,63.730000000,3,4,3,4,63.630000000,63.740000000,7,5,7,5,63.620000000,63.750000000,3,3,3,3,63.610000000,63.760000000,3,3,3,3,63.600000000,63.770000000,7,1,7,1,63.590000000,63.780000000,1,3,1,3,63.580000000,63.790000000,6,1,4,1,MCLQ5
2025-06-11T00:00:09.060873133Z,2025-06-11T00:00:09.060736851Z,10,1,42026514,C,A,0,64.770000000,2,130,14683,79306838,64.760000000,64.780000000,5,5,5,5,64.750000000,64.790000000,5,6,5,4,64.740000000,64.800000000,9,5,8,5,64.730000000,64.810000000,7,8,7,8,64.720000000,64.820000000,9,9,6,6,64.710000000,64.830000000,9,9,8,9,64.700000000,64.840000000,7,6,6,5,64.690000000,64.850000000,4,8,3,5,64.680000000,64.860000000,4,4,2,3,64.670000000,64.870000000,6,4,4,3,MCLN5
2025-06-11T00:00:09.060969266Z,2025-06-11T00:00:09.060857401Z,10,1,42026514,C,A,0,64.780000000,1,130,17402,79306841,64.760000000,64.780000000,5,4,5,4,64.750000000,64.790000000,5,6,5,4,64.740000000,64.800000000,9,5,8,5,64.730000000,64.810000000,7,8,7,8,64.720000000,64.820000000,9,9,6,6,64.710000000,64.830000000,9,9,8,9,64.700000000,64.840000000,7,6,6,5,64.690000000,64.850000000,4,8,3,5,64.680000000,64.860000000,4,4,2,3,64.670000000,64.870000000,6,4,4,3,MCLN5
2025-06-11T00:00:09.060980294Z,2025-06-11T00:00:09.060893401Z,10,1,42025623,C,A,5,63.750000000,1,130,11314,79306842,63.670000000,63.700000000,2,2,2,2,63.660000000,63.710000000,3,2,3,2,63.650000000,63.720000000,3,3,3,3,63.640000000,63.730000000,3,4,3,4,63.630000000,63.740000000,7,5,7,5,63.620000000,63.750000000,3,2,3,2,63.610000000,63.760000000,3,3,3,3,63.600000000,63.770000000,7,1,7,1,63.590000000,63.780000000,1,3,1,3,63.580000000,63.790000000,6,1,4,1,MCLQ5
2025-06-11T00:00:09.060998072Z,2025-06-11T00:00:09.060897701Z,10,1,42025623,C,B,6,63.610000000,1,130,11442,79306843,63.670000000,63.700000000,2,2,2,2,63.660000000,63.710000000,3,2,3,2,63.650000000,63.720000000,3,3,3,3,63.640000000,63.730000000,3,4,3,4,63.630000000,63.740000000,7,5,7,5,63.620000000,63.750000000,3,2,3,2,63.610000000,63.760000000,2,3,2,3,63.600000000,63.770000000,7,1,7,1,63.590000000,63.780000000,1,3,1,3,63.580000000,63.790000000,6,1,4,1,MCLQ5
2025-06-11T00:00:09.061110832Z,2025-06-11T00:00:09.061008805Z,10,1,42025623,A,A,6,63.760000000,1,130,14615,79306844,63.670000000,63.700000000,2,2,2,2,63.660000000,63.710000000,3,2,3,2,63.650000000,63.720000000,3,3,3,3,63.640000000,63.730000000,3,4,3,4,63.630000000,63.740000000,7,5,7,5,63.620000000,63.750000000,3,2,3,2,63.610000000,63.760000000,2,4,2,4,63.600000000,63.770000000,7,1,7,1,63.590000000,63.780000000,1,3,1,3,63.580000000,63.790000000,6,1,4,1,MCLQ5
2025-06-11T00:00:09.061125254Z,2025-06-11T00:00:09.061034457Z,10,1,42025623,A,B,5,63.620000000,1,130,11460,79306845,63.670000000,63.700000000,2,2,2,2,63.660000000,63.710000000,3,2,3,2,63.650000000,63.720000000,3,3,3,3,63.640000000,63.730000000,3,4,3,4,63.630000000,63.740000000,7,5,7,5,63.620000000,63.750000000,4,2,4,2,63.610000000,63.760000000,2,4,2,4,63.600000000,63.770000000,7,1,7,1,63.590000000,63.780000000,1,3,1,3,63.580000000,63.790000000,6,1,4,1,MCLQ5
2025-06-11T00:00:09.061188925Z,2025-06-11T00:00:09.061084873Z,10,1,42026514,A,A,0,64.780000000,1,130,13543,79306846,64.760000000,64.780000000,5,5,5,5,64.750000000,64.790000000,5,6,5,4,64.740000000,64.800000000,9,5,8,5,64.730000000,64.810000000,7,8,7,8,64.720000000,64.820000000,9,9,6,6,64.710000000,64.830000000,9,9,8,9,64.700000000,64.840000000,7,6,6,5,64.690000000,64.850000000,4,8,3,5,64.680000000,64.860000000,4,4,2,3,64.670000000,64.870000000,6,4,4,3,MCLN5
2025-06-11T00:00:09.125515788Z,2025-06-11T00:00:09.125368373Z,10,1,42026514,A,A,0,64.770000000,2,130,15380,79306848,64.760000000,64.770000000,5,2,5,1,64.750000000,64.780000000,5,5,5,5,64.740000000,64.790000000,9,6,8,4,64.730000000,64.800000000,7,5,7,5,64.720000000,64.810000000,9,8,6,8,64.710000000,64.820000000,9,9,8,6,64.700000000,64.830000000,7,9,6,9,64.690000000,64.840000000,4,6,3,5,64.680000000,64.850000000,4,8,2,5,64.670000000,64.860000000,6,4,4,3,MCLN5
2025-06-11T00:00:09.125622082Z,2025-06-11T00:00:09.125527649Z,10,1,42026514,C,A,1,64.780000000,1,130,17097,79306851,64.760000000,64.770000000,5,2,5,1,64.750000000,64.780000000,5,4,5,4,64.740000000,64.790000000,9,6,8,4,64.730000000,64.800000000,7,5,7,5,64.720000000,64.810000000,9,8,6,8,64.710000000,64.820000000,9,9,8,6,64.700000000,64.830000000,7,9,6,9,64.690000000,64.840000000,4,6,3,5,64.680000000,64.850000000,4,8,2,5,64.670000000,64.860000000,6,4,4,3,MCLN5
2025-06-11T00:00:09.125629731Z,2025-06-11T00:00:09.125536575Z,10,1,42025623,C,B,5,63.620000000,1,130,11302,79306852,63.670000000,63.700000000,2,2,2,2,63.660000000,63.710000000,3,2,3,2,63.650000000,63.720000000,3,3,3,3,63.640000000,63.730000000,3,4,3,4,63.630000000,63.740000000,7,5,7,5,63.620000000,63.750000000,3,2,3,2,63.610000000,63.760000000,2,4,2,4,63.600000000,63.770000000,7,1,7,1,63.590000000,63.780000000,1,3,1,3,63.580000000,63.790000000,6,1,4,1,MCLQ5
2025-06-11T00:00:09.125638071Z,2025-06-11T00:00:09.125542279Z,10,1,42025623,C,A,6,63.760000000,1,130,11533,79306853,63.670000000,63.700000000,2,2,2,2,63.660000000,63.710000000,3,2,3,2,63.650000000,63.720000000,3,3,3,3,63.640000000,63.730000000,3,4,3,4,63.630000000,63.740000000,7,5,7,5,63.620000000,63.750000000,3,2,3,2,63.610000000,63.760000000,2,3,2,3,63.600000000,63.770000000,7,1,7,1,63.590000000,63.780000000,1,3,1,3,63.580000000,63.790000000,6,1,4,1,MCLQ5
2025-06-11T00:00:09.125741054Z,2025-06-11T00:00:09.125644533Z,10,1,42025623,A,B,6,63.610000000,1,130,14617,79306854,63.670000000,63.700000000,2,2,2,2,63.660000000,63.710000000,3,2,3,2,63.650000000,63.720000000,3,3,3,3,63.640000000,63.730000000,3,4,3,4,63.630000000,63.740000000,7,5,7,5,63.620000000,63.750000000,3,2,3,2,63.610000000,63.760000000,3,3,3,3,63.600000000,63.770000000,7,1,7,1,63.590000000,63.780000000,1,3,1,3,63.580000000,63.790000000,6,1,4,1,MCLQ5
2025-06-11T00:00:09.125750301Z,2025-06-11T00:00:09.125665441Z,10,1,42025623,A,A,5,63.750000000,1,130,11300,79306855,63.670000000,63.700000000,2,2,2,2,63.660000000,63.710000000,3,2,3,2,63.650000000,63.720000000,3,3,3,3,63.640000000,63.730000000,3,4,3,4,63.630000000,63.740000000,7,5,7,5,63.620000000,63.750000000,3,3,3,3,63.610000000,63.760000000,3,3,3,3,63.600000000,63.770000000,7,1,7,1,63.590000000,63.780000000,1,3,1,3,63.580000000,63.790000000,6,1,4,1,MCLQ5
2025-06-11T00:00:09.143330257Z,2025-06-11T00:00:09.143206169Z,10,1,42026514,C,A,0,64.770000000,2,130,15357,79306856,64.760000000,64.780000000,5,4,5,4,64.750000000,64.790000000,5,6,5,4,64.740000000,64.800000000,9,5,8,5,64.730000000,64.810000000,7,8,7,8,64.720000000,64.820000000,9,9,6,6,64.710000000,64.830000000,9,9,8,9,64.700000000,64.840000000,7,6,6,5,64.690000000,64.850000000,4,8,3,5,64.680000000,64.860000000,4,4,2,3,64.670000000,64.870000000,6,4,4,3,MCLN5
2025-06-11T00:00:09.143448116Z,2025-06-11T00:00:09.143340123Z,10,1,42026514,A,A,0,64.780000000,1,130,16892,79306859,64.760000000,64.780000000,5,5,5,5,64.750000000,64.790000000,5,6,5,4,64.740000000,64.800000000,9,5,8,5,64.730000000,64.810000000,7,8,7,8,64.720000000,64.820000000,9,9,6,6,64.710000000,64.830000000,9,9,8,9,64.700000000,64.840000000,7,6,6,5,64.690000000,64.850000000,4,8,3,5,64.680000000,64.860000000,4,4,2,3,64.670000000,64.870000000,6,4,4,3,MCLN5
2025-06-11T00:00:09.143455366Z,2025-06-11T00:00:09.143351009Z,10,1,42025623,C,A,5,63.750000000,1,130,11638,79306860,63.670000000,63.700000000,2,2,2,2,63.660000000,63.710000000,3,2,3,2,63.650000000,63.720000000,3,3,3,3,63.640000000,63.730000000,3,4,3,4,63.630000000,63.740000000,7,5,7,5,63.620000000,63.750000000,3,2,3,2,63.610000000,63.760000000,3,3,3,3,63.600000000,63.770000000,7,1,7,1,63.590000000,63.780000000,1,3,1,3,63.580000000,63.790000000,6,1,4,1,MCLQ5
2025-06-11T00:00:09.143463176Z,2025-06-11T00:00:09.143355655Z,10,1,42025623,C,B,6,63.610000000,1,130,11295,79306861,63.670000000,63.700000000,2,2,2,2,63.660000000,63.710000000,3,2,3,2,63.650000000,63.720000000,3,3,3,3,63.640000000,63.730000000,3,4,3,4,63.630000000,63.740000000,7,5,7,5,63.620000000,63.750000000,3,2,3,2,63.610000000,63.760000000,2,3,2,3,63.600000000,63.770000000,7,1,7,1,63.590000000,63.780000000,1,3,1,3,63.580000000,63.790000000,6,1,4,1,MCLQ5
2025-06-11T00:00:09.143576465Z,2025-06-11T00:00:09.143480677Z,10,1,42025623,A,A,6,63.760000000,1,130,14481,79306862,63.670000000,63.700000000,2,2,2,2,63.660000000,63.710000000,3,2,3,2,63.650000000,63.720000000,3,3,3,3,63.640000000,63.730000000,3,4,3,4,63.630000000,63.740000000,7,5,7,5,63.620000000,63.750000000,3,2,3,2,63.610000000,63.760000000,2,4,2,4,63.600000000,63.770000000,7,1,7,1,63.590000000,63.780000000,1,3,1,3,63.580000000,63.790000000,6,1,4,1,MCLQ5
2025-06-11T00:00:09.143585213Z,2025-06-11T00:00:09.143490567Z,10,1,42025623,A,B,5,63.620000000,1,130,11167,79306863,63.670000000,63.700000000,2,2,2,2,63.660000000,63.710000000,3,2,3,2,63.650000000,63.720000000,3,3,3,3,63.640000000,63.730000000,3,4,3,4,63.630000000,63.740000000,7,5,7,5,63.620000000,63.750000000,4,2,4,2,63.610000000,63.760000000,2,4,2,4,63.600000000,63.770000000,7,1,7,1,63.590000000,63.780000000,1,3,1,3,63.580000000,63.790000000,6,1,4,1,MCLQ5
2025-06-11T00:00:09.143710897Z,2025-06-11T00:00:09.143601883Z,10,1,42026514,M,B,1,62.760000000,2,130,16596,79306864,64.760000000,64.780000000,5,5,5,5,64.750000000,64.790000000,4,6,4,4,64.740000000,64.800000000,9,5,8,5,64.730000000,64.810000000,7,8,7,8,64.720000000,64.820000000,9,9,6,6,64.710000000,64.830000000,9,9,8,9,64.700000000,64.840000000,7,6,6,5,64.690000000,64.850000000,4,8,3,5,64.680000000,64.860000000,4,4,2,3,64.670000000,64.870000000,6,4,4,3,MCLN5
2025-06-11T00:00:09.143835475Z,2025-06-11T00:00:09.143725889Z,10,1,42026514,A,A,0,64.770000000,2,130,14594,79306865,64.760000000,64.770000000,5,2,5,1,64.750000000,64.780000000,4,5,4,5,64.740000000,64.790000000,9,6,8,4,64.730000000,64.800000000,7,5,7,5,64.720000000,64.810000000,9,8,6,8,64.710000000,64.820000000,9,9,8,6,64.700000000,64.830000000,7,9,6,9,64.690000000,64.840000000,4,6,3,5,64.680000000,64.850000000,4,8,2,5,64.670000000,64.860000000,6,4,4,3,MCLN5
2025-06-11T00:00:09.143940578Z,2025-06-11T00:00:09.143844445Z,10,1,42026514,C,A,1,64.780000000,1,130,15570,79306868,64.760000000,64.770000000,5,2,5,1,64.750000000,64.780000000,4,4,4,4,64.740000000,64.790000000,9,6,8,4,64.730000000,64.800000000,7,5,7,5,64.720000000,64.810000000,9,8,6,8,64.710000000,64.820000000,9,9,8,6,64.700000000,64.830000000,7,9,6,9,64.690000000,64.840000000,4,6,3,5,64.680000000,64.850000000,4,8,2,5,64.670000000,64.860000000,6,4,4,3,MCLN5
2025-06-11T00:00:09.143949148Z,2025-06-11T00:00:09.143856177Z,10,1,42025623,C,B,5,63.620000000,1,130,11784,79306869,63.670000000,63.700000000,2,2,2,2,63.660000000,63.710000000,3,2,3,2,63.650000000,63.720000000,3,3,3,3,63.640000000,63.730000000,3,4,3,4,63.630000000,63.740000000,7,5,7,5,63.620000000,63.750000000,3,2,3,2,63.610000000,63.760000000,2,4,2,4,63.600000000,63.770000000,7,1,7,1,63.590000000,63.780000000,1,3,1,3,63.580000000,63.790000000,6,1,4,1,MCLQ5
2025-06-11T00:00:09.143956966Z,2025-06-11T00:00:09.143860707Z,10,1,42025623,C,A,6,63.760000000,1,130,11200,79306870,63.670000000,63.700000000,2,2,2,2,63.660000000,63.710000000,3,2,3,2,63.650000000,63.720000000,3,3,3,3,63.640000000,63.730000000,3,4,3,4,63.630000000,63.740000000,7,5,7,5,63.620000000,63.750000000,3,2,3,2,63.610000000,63.760000000,2,3,2,3,63.600000000,63.770000000,7,1,7,1,63.590000000,63.780000000,1,3,1,3,63.580000000,63.790000000,6,1,4,1,MCLQ5
2025-06-11T00:00:09.144078642Z,2025-06-11T00:00:09.143975787Z,10,1,42025623,A,B,6,63.610000000,1,130,14925,79306871,63.670000000,63.700000000,2,2,2,2,63.660000000,63.710000000,3,2,3,2,63.650000000,63.720000000,3,3,3,3,63.640000000,63.730000000,3,4,3,4,63.630000000,63.740000000,7,5,7,5,63.620000000,63.750000000,3,2,3,2,63.610000000,63.760000000,3,3,3,3,63.600000000,63.770000000,7,1,7,1,63.590000000,63.780000000,1,3,1,3,63.580000000,63.790000000,6,1,4,1,MCLQ5
2025-06-11T00:00:09.144086936Z,2025-06-11T00:00:09.143990743Z,10,1,42025623,A,A,5,63.750000000,1,130,11238,79306872,63.670000000,63.700000000,2,2,2,2,63.660000000,63.710000000,3,2,3,2,63.650000000,63.720000000,3,3,3,3,63.640000000,63.730000000,3,4,3,4,63.630000000,63.740000000,7,5,7,5,63.620000000,63.750000000,3,3,3,3,63.610000000,63.760000000,3,3,3,3,63.600000000,63.770000000,7,1,7,1,63.590000000,63.780000000,1,3,1,3,63.580000000,63.790000000,6,1,4,1,MCLQ5
2025-06-11T00:00:09.144204871Z,2025-06-11T00:00:09.144090693Z,10,1,42026514,M,B,1,64.750000000,1,130,15861,79306873,64.760000000,64.770000000,5,2,5,1,64.750000000,64.780000000,5,4,5,4,64.740000000,64.790000000,9,6,8,4,64.730000000,64.800000000,7,5,7,5,64.720000000,64.810000000,9,8,6,8,64.710000000,64.820000000,9,9,8,6,64.700000000,64.830000000,7,9,6,9,64.690000000,64.840000000,4,6,3,5,64.680000000,64.850000000,4,8,2,5,64.670000000,64.860000000,6,4,4,3,MCLN5
2025-06-11T00:00:09.160100831Z,2025-06-11T00:00:09.159975035Z,10,1,42026514,C,A,0,64.770000000,2,130,15739,79306874,64.760000000,64.780000000,5,4,5,4,64.750000000,64.790000000,5,6,5,4,64.740000000,64.800000000,9,5,8,5,64.730000000,64.810000000,7,8,7,8,64.720000000,64.820000000,9,9,6,6,64.710000000,64.830000000,9,9,8,9,64.700000000,64.840000000,7,6,6,5,64.690000000,64.850000000,4,8,3,5,64.680000000,64.860000000,4,4,2,3,64.670000000,64.870000000,6,4,4,3,MCLN5
2025-06-11T00:00:09.160211840Z,2025-06-11T00:00:09.160122387Z,10,1,42025623,C,A,5,63.750000000,1,130,15186,79306877,63.670000000,63.700000000,2,2,2,2,63.660000000,63.710000000,3,2,3,2,63.650000000,63.720000000,3,3,3,3,63.640000000,63.730000000,3,4,3,4,63.630000000,63.740000000,7,5,7,5,63.620000000,63.750000000,3,2,3,2,63.610000000,63.760000000,3,3,3,3,63.600000000,63.770000000,7,1,7,1,63.590000000,63.780000000,1,3,1,3,63.580000000,63.790000000,6,1,4,1,MCLQ5
2025-06-11T00:00:09.160220042Z,2025-06-11T00:00:09.160126745Z,10,1,42025623,C,B,6,63.610000000,1,130,11128,79306878,63.670000000,63.700000000,2,2,2,2,63.660000000,63.710000000,3,2,3,2,63.650000000,63.720000000,3,3,3,3,63.640000000,63.730000000,3,4,3,4,63.630000000,63.740000000,7,5,7,5,63.620000000,63.750000000,3,2,3,2,63.610000000,63.760000000,2,3,2,3,63.600000000,63.770000000,7,1,7,1,63.590000000,63.780000000,1,3,1,3,63.580000000,63.790000000,6,1,4,1,MCLQ5
2025-06-11T00:00:09.160335335Z,2025-06-11T00:00:09.160240403Z,10,1,42025623,A,A,6,63.760000000,1,130,14745,79306879,63.670000000,63.700000000,2,2,2,2,63.660000000,63.710000000,3,2,3,2,63.650000000,63.720000000,3,3,3,3,63.640000000,63.730000000,3,4,3,4,63.630000000,63.740000000,7,5,7,5,63.620000000,63.750000000,3,2,3,2,63.610000000,63.760000000,2,4,2,4,63.600000000,63.770000000,7,1,7,1,63.590000000,63.780000000,1,3,1,3,63.580000000,63.790000000,6,1,4,1,MCLQ5
2025-06-11T00:00:09.160343606Z,2025-06-11T00:00:09.160248219Z,10,1,42025623,A,B,5,63.620000000,1,130,11561,79306880,63.670000000,63.700000000,2,2,2,2,63.660000000,63.710000000,3,2,3,2,63.650000000,63.720000000,3,3,3,3,63.640000000,63.730000000,3,4,3,4,63.630000000,63.740000000,7,5,7,5,63.620000000,63.750000000,4,2,4,2,63.610000000,63.760000000,2,4,2,4,63.600000000,63.770000000,7,1,7,1,63.590000000,63.780000000,1,3,1,3,63.580000000,63.790000000,6,1,4,1,MCLQ5
2025-06-11T00:00:09.160923208Z,2025-06-11T00:00:09.160823673Z,10,1,42026514,M,B,1,62.770000000,2,130,15825,79306881,64.760000000,64.780000000,5,4,5,4,64.750000000,64.790000000,4,6,4,4,64.740000000,64.800000000,9,5,8,5,64.730000000,64.810000000,7,8,7,8,64.720000000,64.820000000,9,9,6,6,64.710000000,64.830000000,9,9,8,9,64.700000000,64.840000000,7,6,6,5,64.690000000,64.850000000,4,8,3,5,64.680000000,64.860000000,4,4,2,3,64.670000000,64.870000000,6,4,4,3,MCLN5
2025-06-11T00:00:09.204026667Z,2025-06-11T00:00:09.203902865Z,10,1,42026514,A,A,0,64.780000000,1,130,17883,79306882,64.760000000,64.780000000,5,5,5,5,64.750000000,64.790000000,4,6,4,4,64.740000000,64.800000000,9,5,8,5,64.730000000,64.810000000,7,8,7,8,64.720000000,64.820000000,9,9,6,6,64.710000000,64.830000000,9,9,8,9,64.700000000,64.840000000,7,6,6,5,64.690000000,64.850000000,4,8,3,5,64.680000000,64.860000000,4,4,2,3,64.670000000,64.870000000,6,4,4,3,MCLN5
2025-06-11T00:00:09.512577114Z,2025-06-11T00:00:09.512477645Z,10,1,42025623,M,A,3,63.740000000,1,130,15515,79306914,63.670000000,63.700000000,2,2,2,2,63.660000000,63.710000000,3,2,3,2,63.650000000,63.720000000,3,3,3,3,63.640000000,63.730000000,3,3,3,3,63.630000000,63.740000000,7,6,7,6,63.620000000,63.750000000,4,2,4,2,63.610000000,63.760000000,2,4,2,4,63.600000000,63.770000000,7,1,7,1,63.590000000,63.780000000,1,3,1,3,63.580000000,63.790000000,6,1,4,1,MCLQ5
2025-06-11T00:00:09.512586859Z,2025-06-11T00:00:09.512478125Z,10,1,42025623,M,B,3,63.640000000,1,130,12046,79306915,63.670000000,63.700000000,2,2,2,2,63.660000000,63.710000000,3,2,3,2,63.650000000,63.720000000,3,3,3,3,63.640000000,63.730000000,4,3,4,3,63.630000000,63.740000000,6,6,6,6,63.620000000,63.750000000,4,2,4,2,63.610000000,63.760000000,2,4,2,4,63.600000000,63.770000000,7,1,7,1,63.590000000,63.780000000,1,3,1,3,63.580000000,63.790000000,6,1,4,1,MCLQ5
2025-06-11T00:00:09.512598355Z,2025-06-11T00:00:09.512478623Z,10,1,42025623,M,A,3,63.740000000,1,130,11745,79306916,63.670000000,63.700000000,2,2,2,2,63.660000000,63.710000000,3,2,3,2,63.650000000,63.720000000,3,3,3,3,63.640000000,63.730000000,4,2,4,2,63.630000000,63.740000000,6,7,6,7,63.620000000,63.750000000,4,2,4,2,63.610000000,63.760000000,2,4,2,4,63.600000000,63.770000000,7,1,7,1,63.590000000,63.780000000,1,3,1,3,63.580000000,63.790000000,6,1,4,1,MCLQ5
2025-06-11T00:00:09.512609015Z,2025-06-11T00:00:09.512479141Z,10,1,42025623,M,B,3,63.640000000,1,130,11443,79306917,63.670000000,63.700000000,2,2,2,2,63.660000000,63.710000000,3,2,3,2,63.650000000,63.720000000,3,3,3,3,63.640000000,63.730000000,5,2,5,2,63.630000000,63.740000000,5,7,5,7,63.620000000,63.750000000,4,2,4,2,63.610000000,63.760000000,2,4,2,4,63.600000000,63.770000000,7,1,7,1,63.590000000,63.780000000,1,3,1,3,63.580000000,63.790000000,6,1,4,1,MCLQ5
2025-06-11T00:00:09.524975546Z,2025-06-11T00:00:09.524843797Z,10,1,42025623,M,A,0,63.700000000,1,130,16716,79306927,63.670000000,63.700000000,2,3,2,3,63.660000000,63.710000000,3,2,3,2,63.650000000,63.720000000,3,2,3,2,63.640000000,63.730000000,5,2,5,2,63.630000000,63.740000000,5,7,5,7,63.620000000,63.750000000,4,2,4,2,63.610000000,63.760000000,2,4,2,4,63.600000000,63.770000000,7,1,7,1,63.590000000,63.780000000,1,3,1,3,63.580000000,63.790000000,6,1,4,1,MCLQ5
2025-06-11T00:00:09.535299673Z,2025-06-11T00:00:09.535167317Z,10,1,42026514,A,A,0,64.770000000,2,130,15175,79306932,64.760000000,64.770000000,5,2,5,1,64.750000000,64.780000000,4,5,4,5,64.740000000,64.790000000,9,6,8,4,64.730000000,64.800000000,7,5,7,5,64.720000000,64.810000000,9,8,6,8,64.710000000,64.820000000,9,9,8,6,64.700000000,64.830000000,7,9,6,9,64.690000000,64.840000000,4,6,3,5,64.680000000,64.850000000,4,8,2,5,64.670000000,64.860000000,6,4,4,3,MCLN5
2025-06-11T00:00:09.535404046Z,2025-06-11T00:00:09.535310043Z,10,1,42026514,C,A,1,64.780000000,1,130,15821,79306936,64.760000000,64.770000000,5,2,5,1,64.750000000,64.780000000,4,4,4,4,64.740000000,64.790000000,9,6,8,4,64.730000000,64.800000000,7,5,7,5,64.720000000,64.810000000,9,8,6,8,64.710000000,64.820000000,9,9,8,6,64.700000000,64.830000000,7,9,6,9,64.690000000,64.840000000,4,6,3,5,64.680000000,64.850000000,4,8,2,5,64.670000000,64.860000000,6,4,4,3,MCLN5
2025-06-11T00:00:09.535412171Z,2025-06-11T00:00:09.535319969Z,10,1,42025623,C,B,5,63.620000000,1,130,11319,79306937,63.670000000,63.700000000,2,3,2,3,63.660000000,63.710000000,3,2,3,2,63.650000000,63.720000000,3,2,3,2,63.640000000,63.730000000,5,2,5,2,63.630000000,63.740000000,5,7,5,7,63.620000000,63.750000000,3,2,3,2,63.610000000,63.760000000,2,4,2,4,63.600000000,63.770000000,7,1,7,1,63.590000000,63.780000000,1,3,1,3,63.580000000,63.790000000,6,1,4,1,MCLQ5
2025-06-11T00:00:09.535422093Z,2025-06-11T00:00:09.535324845Z,10,1,42025623,C,A,6,63.760000000,1,130,11421,79306938,63.670000000,63.700000000,2,3,2,3,63.660000000,63.710000000,3,2,3,2,63.650000000,63.720000000,3,2,3,2,63.640000000,63.730000000,5,2,5,2,63.630000000,63.740000000,5,7,5,7,63.620000000,63.750000000,3,2,3,2,63.610000000,63.760000000,2,3,2,3,63.600000000,63.770000000,7,1,7,1,63.590000000,63.780000000,1,3,1,3,63.580000000,63.790000000,6,1,4,1,MCLQ5
2025-06-11T00:00:09.535529070Z,2025-06-11T00:00:09.535436737Z,10,1,42025623,A,B,6,63.610000000,1,130,14791,79306939,63.670000000,63.700000000,2,3,2,3,63.660000000,63.710000000,3,2,3,2,63.650000000,63.720000000,3,2,3,2,63.640000000,63.730000000,5,2,5,2,63.630000000,63.740000000,5,7,5,7,63.620000000,63.750000000,3,2,3,2,63.610000000,63.760000000,3,3,3,3,63.600000000,63.770000000,7,1,7,1,63.590000000,63.780000000,1,3,1,3,63.580000000,63.790000000,6,1,4,1,MCLQ5
2025-06-11T00:00:09.535540267Z,2025-06-11T00:00:09.535453595Z,10,1,42025623,A,A,5,63.750000000,1,130,11137,79306940,63.670000000,63.700000000,2,3,2,3,63.660000000,63.710000000,3,2,3,2,63.650000000,63.720000000,3,2,3,2,63.640000000,63.730000000,5,2,5,2,63.630000000,63.740000000,5,7,5,7,63.620000000,63.750000000,3,3,3,3,63.610000000,63.760000000,3,3,3,3,63.600000000,63.770000000,7,1,7,1,63.590000000,63.780000000,1,3,1,3,63.580000000,63.790000000,6,1,4,1,MCLQ5
2025-06-11T00:00:09.545974327Z,2025-06-11T00:00:09.545859305Z,10,1,42026514,C,A,0,64.770000000,2,130,14754,79306941,64.760000000,64.780000000,5,4,5,4,64.750000000,64.790000000,4,6,4,4,64.740000000,64.800000000,9,5,8,5,64.730000000,64.810000000,7,8,7,8,64.720000000,64.820000000,9,9,6,6,64.710000000,64.830000000,9,9,8,9,64.700000000,64.840000000,7,6,6,5,64.690000000,64.850000000,4,8,3,5,64.680000000,64.860000000,4,4,2,3,64.670000000,64.870000000,6,4,4,3,MCLN5
2025-06-11T00:00:09.546074746Z,2025-06-11T00:00:09.545981525Z,10,1,42026514,M,A,3,64.820000000,1,130,15414,79306944,64.760000000,64.780000000,5,4,5,4,64.750000000,64.790000000,4,6,4,4,64.740000000,64.800000000,9,5,8,5,64.730000000,64.810000000,7,7,7,7,64.720000000,64.820000000,9,10,6,7,64.710000000,64.830000000,9,9,8,9,64.700000000,64.840000000,7,6,6,5,64.690000000,64.850000000,4,8,3,5,64.680000000,64.860000000,4,4,2,3,64.670000000,64.870000000,6,4,4,3,MCLN5
2025-06-11T00:00:09.546083285Z,2025-06-11T00:00:09.545982043Z,10,1,42026514,M,B,3,64.730000000,1,130,11730,79306945,64.760000000,64.780000000,5,4,5,4,64.750000000,64.790000000,4,6,4,4,64.740000000,64.800000000,9,5,8,5,64.730000000,64.810000000,8,7,8,7,64.720000000,64.820000000,8,10,5,7,64.710000000,64.830000000,9,9,8,9,64.700000000,64.840000000,7,6,6,5,64.690000000,64.850000000,4,8,3,5,64.680000000,64.860000000,4,4,2,3,64.670000000,64.870000000,6,4,4,3,MCLN5
2025-06-11T00:00:09.546100357Z,2025-06-11T00:00:09.545983619Z,10,1,42026514,A,A,0,64.780000000,1,130,13367,79306946,64.760000000,64.780000000,5,5,5,5,64.750000000,64.790000000,4,6,4,4,64.740000000,64.800000000,9,5,8,5,64.730000000,64.810000000,8,7,8,7,64.720000000,64.820000000,8,10,5,7,64.710000000,64.830000000,9,9,8,9,64.700000000,64.840000000,7,6,6,5,64.690000000,64.850000000,4,8,3,5,64.680000000,64.860000000,4,4,2,3,64.670000000,64.870000000,6,4,4,3,MCLN5
2025-06-11T00:00:09.546110356Z,2025-06-11T00:00:09.545996885Z,10,1,42025623,C,A,5,63.750000000,1,130,11343,79306947,63.670000000,63.700000000,2,3,2,3,63.660000000,63.710000000,3,2,3,2,63.650000000,63.720000000,3,2,3,2,63.640000000,63.730000000,5,2,5,2,63.630000000,63.740000000,5,7,5,7,63.620000000,63.750000000,3,2,3,2,63.610000000,63.760000000,3,3,3,3,63.600000000,63.770000000,7,1,7,1,63.590000000,63.780000000,1,3,1,3,63.580000000,63.790000000,6,1,4,1,MCLQ5
2025-06-11T00:00:09.546121921Z,2025-06-11T00:00:09.546001877Z,10,1,42025623,C,B,6,63.610000000,1,130,11917,79306948,63.670000000,63.700000000,2,3,2,3,63.660000000,63.710000000,3,2,3,2,63.650000000,63.720000000,3,2,3,2,63.640000000,63.730000000,5,2,5,2,63.630000000,63.740000000,5,7,5,7,63.620000000,63.750000000,3,2,3,2,63.610000000,63.760000000,2,3,2,3,63.600000000,63.770000000,7,1,7,1,63.590000000,63.780000000,1,3,1,3,63.580000000,63.790000000,6,1,4,1,MCLQ5
2025-06-11T00:00:09.546235856Z,2025-06-11T00:00:09.546138633Z,10,1,42025623,A,A,6,63.760000000,1,130,14913,79306949,63.670000000,63.700000000,2,3,2,3,63.660000000,63.710000000,3,2,3,2,63.650000000,63.720000000,3,2,3,2,63.640000000,63.730000000,5,2,5,2,63.630000000,63.740000000,5,7,5,7,63.620000000,63.750000000,3,2,3,2,63.610000000,63.760000000,2,4,2,4,63.600000000,63.770000000,7,1,7,1,63.590000000,63.780000000,1,3,1,3,63.580000000,63.790000000,6,1,4,1,MCLQ5
2025-06-11T00:00:09.546243912Z,2025-06-11T00:00:09.546143375Z,10,1,42025623,A,B,5,63.620000000,1,130,11381,79306950,63.670000000,63.700000000,2,3,2,3,63.660000000,63.710000000,3,2,3,2,63.650000000,63.720000000,3,2,3,2,63.640000000,63.730000000,5,2,5,2,63.630000000,63.740000000,5,7,5,7,63.620000000,63.750000000,4,2,4,2,63.610000000,63.760000000,2,4,2,4,63.600000000,63.770000000,7,1,7,1,63.590000000,63.780000000,1,3,1,3,63.580000000,63.790000000,6,1,4,1,MCLQ5
2025-06-11T00:00:10.153598995Z,2025-06-11T00:00:10.153484075Z,10,1,42418117,M,B,0,3.250000000,10,130,15045,79307385,3.250000000,3.270000000,11,1,2,1,3.240000000,3.280000000,1,1,1,1,3.230000000,3.290000000,1,11,1,2,,,0,0,0,0,,,0,0,0,0,,,0,0,0,0,,,0,0,0,0,,,0,0,0,0,,,0,0,0,0,,,0,0,0,0,MCLN5-MCLX5
2025-06-11T00:00:10.751479156Z,2025-06-11T00:00:10.751368963Z,10,1,42026514,C,A,0,64.780000000,1,130,16600,79307721,64.760000000,64.780000000,5,4,5,4,64.750000000,64.790000000,4,6,4,4,64.740000000,64.800000000,9,5,8,5,64.730000000,64.810000000,8,7,8,7,64.720000000,64.820000000,8,10,5,7,64.710000000,64.830000000,9,9,8,9,64.700000000,64.840000000,7,6,6,5,64.690000000,64.850000000,4,8,3,5,64.680000000,64.860000000,4,4,2,3,64.670000000,64.870000000,6,4,4,3,MCLN5
2025-06-11T00:00:10.786900814Z,2025-06-11T00:00:10.786775057Z,10,1,42026514,A,A,0,64.780000000,1,130,17360,79307744,64.760000000,64.780000000,5,5,5,5,64.750000000,64.790000000,4,6,4,4,64.740000000,64.800000000,9,5,8,5,64.730000000,64.810000000,8,7,8,7,64.720000000,64.820000000,8,10,5,7,64.710000000,64.830000000,9,9,8,9,64.700000000,64.840000000,7,6,6,5,64.690000000,64.850000000,4,8,3,5,64.680000000,64.860000000,4,4,2,3,64.670000000,64.870000000,6,4,4,3,MCLN5
2025-06-11T00:00:10.792159740Z,2025-06-11T00:00:10.792061179Z,10,1,42026514,C,A,0,64.780000000,1,130,16534,79307755,64.760000000,64.780000000,5,4,5,4,64.750000000,64.790000000,4,6,4,4,64.740000000,64.800000000,9,5,8,5,64.730000000,64.810000000,8,7,8,7,64.720000000,64.820000000,8,10,5,7,64.710000000,64.830000000,9,9,8,9,64.700000000,64.840000000,7,6,6,5,64.690000000,64.850000000,4,8,3,5,64.680000000,64.860000000,4,4,2,3,64.670000000,64.870000000,6,4,4,3,MCLN5
2025-06-11T00:00:10.792286952Z,2025-06-11T00:00:10.792184687Z,10,1,42026514,A,A,0,64.780000000,1,130,16774,79307756,64.760000000,64.780000000,5,5,5,5,64.750000000,64.790000000,4,6,4,4,64.740000000,64.800000000,9,5,8,5,64.730000000,64.810000000,8,7,8,7,64.720000000,64.820000000,8,10,5,7,64.710000000,64.830000000,9,9,8,9,64.700000000,64.840000000,7,6,6,5,64.690000000,64.850000000,4,8,3,5,64.680000000,64.860000000,4,4,2,3,64.670000000,64.870000000,6,4,4,3,MCLN5
2025-06-11T00:00:10.792705920Z,2025-06-11T00:00:10.792608853Z,10,1,42026514,C,A,0,64.780000000,1,130,15651,79307757,64.760000000,64.780000000,5,4,5,4,64.750000000,64.790000000,4,6,4,4,64.740000000,64.800000000,9,5,8,5,64.730000000,64.810000000,8,7,8,7,64.720000000,64.820000000,8,10,5,7,64.710000000,64.830000000,9,9,8,9,64.700000000,64.840000000,7,6,6,5,64.690000000,64.850000000,4,8,3,5,64.680000000,64.860000000,4,4,2,3,64.670000000,64.870000000,6,4,4,3,MCLN5
2025-06-11T00:00:10.796371545Z,2025-06-11T00:00:10.796255903Z,10,1,42026514,A,A,0,64.780000000,1,130,17087,79307759,64.760000000,64.780000000,5,5,5,5,64.750000000,64.790000000,4,6,4,4,64.740000000,64.800000000,9,5,8,5,64.730000000,64.810000000,8,7,8,7,64.720000000,64.820000000,8,10,5,7,64.710000000,64.830000000,9,9,8,9,64.700000000,64.840000000,7,6,6,5,64.690000000,64.850000000,4,8,3,5,64.680000000,64.860000000,4,4,2,3,64.670000000,64.870000000,6,4,4,3,MCLN5
2025-06-11T00:00:10.860546524Z,2025-06-11T00:00:10.860432657Z,10,1,42026514,C,A,0,64.780000000,1,130,17713,79307797,64.760000000,64.780000000,5,4,5,4,64.750000000,64.790000000,4,6,4,4,64.740000000,64.800000000,9,5,8,5,64.730000000,64.810000000,8,7,8,7,64.720000000,64.820000000,8,10,5,7,64.710000000,64.830000000,9,9,8,9,64.700000000,64.840000000,7,6,6,5,64.690000000,64.850000000,4,8,3,5,64.680000000,64.860000000,4,4,2,3,64.670000000,64.870000000,6,4,4,3,MCLN5
2025-06-11T00:00:10.860716911Z,2025-06-11T00:00:10.860607505Z,10,1,42026514,A,A,0,64.780000000,1,130,17512,79307798,64.760000000,64.780000000,5,5,5,5,64.750000000,64.790000000,4,6,4,4,64.740000000,64.800000000,9,5,8,5,64.730000000,64.810000000,8,7,8,7,64.720000000,64.820000000,8,10,5,7,64.710000000,64.830000000,9,9,8,9,64.700000000,64.840000000,7,6,6,5,64.690000000,64.850000000,4,8,3,5,64.680000000,64.860000000,4,4,2,3,64.670000000,64.870000000,6,4,4,3,MCLN5
2025-06-11T00:00:10.860836160Z,2025-06-11T00:00:10.860738979Z,10,1,42026514,C,A,0,64.780000000,1,130,17079,79307799,64.760000000,64.780000000,5,4,5,4,64.750000000,64.790000000,4,6,4,4,64.740000000,64.800000000,9,5,8,5,64.730000000,64.810000000,8,7,8,7,64.720000000,64.820000000,8,10,5,7,64.710000000,64.830000000,9,9,8,9,64.700000000,64.840000000,7,6,6,5,64.690000000,64.850000000,4,8,3,5,64.680000000,64.860000000,4,4,2,3,64.670000000,64.870000000,6,4,4,3,MCLN5
2025-06-11T00:00:10.861508862Z,2025-06-11T00:00:10.861403943Z,10,1,42026514,A,A,0,64.780000000,1,130,17098,79307800,64.760000000,64.780000000,5,5,5,5,64.750000000,64.790000000,4,6,4,4,64.740000000,64.800000000,9,5,8,5,64.730000000,64.810000000,8,7,8,7,64.720000000,64.820000000,8,10,5,7,64.710000000,64.830000000,9,9,8,9,64.700000000,64.840000000,7,6,6,5,64.690000000,64.850000000,4,8,3,5,64.680000000,64.860000000,4,4,2,3,64.670000000,64.870000000,6,4,4,3,MCLN5
2025-06-11T00:00:10.863213018Z,2025-06-11T00:00:10.863115183Z,10,1,42026514,C,A,0,64.780000000,1,130,16515,79307805,64.760000000,64.780000000,5,4,5,4,64.750000000,64.790000000,4,6,4,4,64.740000000,64.800000000,9,5,8,5,64.730000000,64.810000000,8,7,8,7,64.720000000,64.820000000,8,10,5,7,64.710000000,64.830000000,9,9,8,9,64.700000000,64.840000000,7,6,6,5,64.690000000,64.850000000,4,8,3,5,64.680000000,64.860000000,4,4,2,3,64.670000000,64.870000000,6,4,4,3,MCLN5
2025-06-11T00:00:10.863724271Z,2025-06-11T00:00:10.863618315Z,10,1,42026514,A,A,0,64.780000000,1,130,16512,79307808,64.760000000,64.780000000,5,5,5,5,64.750000000,64.790000000,4,6,4,4,64.740000000,64.800000000,9,5,8,5,64.730000000,64.810000000,8,7,8,7,64.720000000,64.820000000,8,10,5,7,64.710000000,64.830000000,9,9,8,9,64.700000000,64.840000000,7,6,6,5,64.690000000,64.850000000,4,8,3,5,64.680000000,64.860000000,4,4,2,3,64.670000000,64.870000000,6,4,4,3,MCLN5
2025-06-11T00:00:10.880769633Z,2025-06-11T00:00:10.880668677Z,10,1,42026514,C,A,0,64.780000000,1,130,16933,79307817,64.760000000,64.780000000,5,4,5,4,64.750000000,64.790000000,4,6,4,4,64.740000000,64.800000000,9,5,8,5,64.730000000,64.810000000,8,7,8,7,64.720000000,64.820000000,8,10,5,7,64.710000000,64.830000000,9,9,8,9,64.700000000,64.840000000,7,6,6,5,64.690000000,64.850000000,4,8,3,5,64.680000000,64.860000000,4,4,2,3,64.670000000,64.870000000,6,4,4,3,MCLN5
2025-06-11T00:00:10.880997733Z,2025-06-11T00:00:10.880895015Z,10,1,42026514,A,A,0,64.780000000,1,130,17130,79307818,64.760000000,64.780000000,5,5,5,5,64.750000000,64.790000000,4,6,4,4,64.740000000,64.800000000,9,5,8,5,64.730000000,64.810000000,8,7,8,7,64.720000000,64.820000000,8,10,5,7,64.710000000,64.830000000,9,9,8,9,64.700000000,64.840000000,7,6,6,5,64.690000000,64.850000000,4,8,3,5,64.680000000,64.860000000,4,4,2,3,64.670000000,64.870000000,6,4,4,3,MCLN5
2025-06-11T00:00:10.881920321Z,2025-06-11T00:00:10.881809107Z,10,1,42026514,C,A,0,64.780000000,1,130,15756,79307819,64.760000000,64.780000000,5,4,5,4,64.750000000,64.790000000,4,6,4,4,64.740000000,64.800000000,9,5,8,5,64.730000000,64.810000000,8,7,8,7,64.720000000,64.820000000,8,10,5,7,64.710000000,64.830000000,9,9,8,9,64.700000000,64.840000000,7,6,6,5,64.690000000,64.850000000,4,8,3,5,64.680000000,64.860000000,4,4,2,3,64.670000000,64.870000000,6,4,4,3,MCLN5
2025-06-11T00:00:11.172027711Z,2025-06-11T00:00:11.171742167Z,10,1,42026514,A,A,0,64.780000000,1,130,13158,79308381,64.760000000,64.780000000,5,5,5,5,64.750000000,64.790000000,4,6,4,4,64.740000000,64.800000000,9,5,8,5,64.730000000,64.810000000,8,7,8,7,64.720000000,64.820000000,8,10,5,7,64.710000000,64.830000000,9,9,8,9,64.700000000,64.840000000,7,6,6,5,64.690000000,64.850000000,4,8,3,5,64.680000000,64.860000000,4,4,2,3,64.670000000,64.870000000,6,4,4,3,MCLN5
2025-06-11T00:00:11.172140502Z,2025-06-11T00:00:11.172038487Z,10,1,42026514,C,A,0,64.780000000,1,130,16410,79308382,64.760000000,64.780000000,5,4,5,4,64.750000000,64.790000000,4,6,4,4,64.740000000,64.800000000,9,5,8,5,64.730000000,64.810000000,8,7,8,7,64.720000000,64.820000000,8,10,5,7,64.710000000,64.830000000,9,9,8,9,64.700000000,64.840000000,7,6,6,5,64.690000000,64.850000000,4,8,3,5,64.680000000,64.860000000,4,4,2,3,64.670000000,64.870000000,6,4,4,3,MCLN5
2025-06-11T00:00:11.190299076Z,2025-06-11T00:00:11.190197581Z,10,1,42026514,A,A,0,64.780000000,1,130,12975,79308388,64.760000000,64.780000000,5,5,5,5,64.750000000,64.790000000,4,6,4,4,64.740000000,64.800000000,9,5,8,5,64.730000000,64.810000000,8,7,8,7,64.720000000,64.820000000,8,10,5,7,64.710000000,64.830000000,9,9,8,9,64.700000000,64.840000000,7,6,6,5,64.690000000,64.850000000,4,8,3,5,64.680000000,64.860000000,4,4,2,3,64.670000000,64.870000000,6,4,4,3,MCLN5
2025-06-11T00:00:11.196690167Z,2025-06-11T00:00:11.196577633Z,10,1,42026514,C,A,0,64.780000000,1,130,17193,79308390,64.760000000,64.780000000,5,4,5,4,64.750000000,64.790000000,4,6,4,4,64.740000000,64.800000000,9,5,8,5,64.730000000,64.810000000,8,7,8,7,64.720000000,64.820000000,8,10,5,7,64.710000000,64.830000000,9,9,8,9,64.700000000,64.840000000,7,6,6,5,64.690000000,64.850000000,4,8,3,5,64.680000000,64.860000000,4,4,2,3,64.670000000,64.870000000,6,4,4,3,MCLN5
2025-06-11T00:00:11.197800406Z,2025-06-11T00:00:11.197683063Z,10,1,42026514,A,A,0,64.780000000,1,130,17396,79308391,64.760000000,64.780000000,5,5,5,5,64.750000000,64.790000000,4,6,4,4,64.740000000,64.800000000,9,5,8,5,64.730000000,64.810000000,8,7,8,7,64.720000000,64.820000000,8,10,5,7,64.710000000,64.830000000,9,9,8,9,64.700000000,64.840000000,7,6,6,5,64.690000000,64.850000000,4,8,3,5,64.680000000,64.860000000,4,4,2,3,64.670000000,64.870000000,6,4,4,3,MCLN5
2025-06-11T00:00:11.217184368Z,2025-06-11T00:00:11.217088125Z,10,1,42026514,C,A,0,64.780000000,1,130,13165,79308393,64.760000000,64.780000000,5,4,5,4,64.750000000,64.790000000,4,6,4,4,64.740000000,64.800000000,9,5,8,5,64.730000000,64.810000000,8,7,8,7,64.720000000,64.820000000,8,10,5,7,64.710000000,64.830000000,9,9,8,9,64.700000000,64.840000000,7,6,6,5,64.690000000,64.850000000,4,8,3,5,64.680000000,64.860000000,4,4,2,3,64.670000000,64.870000000,6,4,4,3,MCLN5
2025-06-11T00:00:11.217421484Z,2025-06-11T00:00:11.217278713Z,10,1,42026514,A,A,0,64.770000000,2,130,11286,79308398,64.760000000,64.770000000,5,2,5,1,64.750000000,64.780000000,4,4,4,4,64.740000000,64.790000000,9,6,8,4,64.730000000,64.800000000,8,5,8,5,64.720000000,64.810000000,8,7,5,7,64.710000000,64.820000000,9,10,8,7,64.700000000,64.830000000,7,9,6,9,64.690000000,64.840000000,4,6,3,5,64.680000000,64.850000000,4,8,2,5,64.670000000,64.860000000,6,4,4,3,MCLN5
2025-06-11T00:00:11.217525581Z,2025-06-11T00:00:11.217429619Z,10,1,42026514,M,B,3,64.720000000,1,130,11584,79308403,64.760000000,64.770000000,5,2,5,1,64.750000000,64.780000000,4,4,4,4,64.740000000,64.790000000,9,6,8,4,64.730000000,64.800000000,7,5,7,5,64.720000000,64.810000000,9,7,6,7,64.710000000,64.820000000,9,10,8,7,64.700000000,64.830000000,7,9,6,9,64.690000000,64.840000000,4,6,3,5,64.680000000,64.850000000,4,8,2,5,64.670000000,64.860000000,6,4,4,3,MCLN5
2025-06-11T00:00:11.217536233Z,2025-06-11T00:00:11.217430139Z,10,1,42026514,M,A,4,64.810000000,1,130,12608,79308404,64.760000000,64.770000000,5,2,5,1,64.750000000,64.780000000,4,4,4,4,64.740000000,64.790000000,9,6,8,4,64.730000000,64.800000000,7,5,7,5,64.720000000,64.810000000,9,8,6,8,64.710000000,64.820000000,9,9,8,6,64.700000000,64.830000000,7,9,6,9,64.690000000,64.840000000,4,6,3,5,64.680000000,64.850000000,4,8,2,5,64.670000000,64.860000000,6,4,4,3,MCLN5
2025-06-11T00:00:11.217547767Z,2025-06-11T00:00:11.217443443Z,10,1,42025623,C,B,5,63.620000000,1,130,11531,79308405,63.670000000,63.700000000,2,3,2,3,63.660000000,63.710000000,3,2,3,2,63.650000000,63.720000000,3,2,3,2,63.640000000,63.730000000,5,2,5,2,63.630000000,63.740000000,5,7,5,7,63.620000000,63.750000000,3,2,3,2,63.610000000,63.760000000,2,4,2,4,63.600000000,63.770000000,7,1,7,1,63.590000000,63.780000000,1,3,1,3,63.580000000,63.790000000,6,1,4,1,MCLQ5
2025-06-11T00:00:11.217561575Z,2025-06-11T00:00:11.217445209Z,10,1,42025623,M,B,3,63.630000000,1,130,14567,79308406,63.670000000,63.700000000,2,3,2,3,63.660000000,63.710000000,3,2,3,2,63.650000000,63.720000000,3,2,3,2,63.640000000,63.730000000,4,2,4,2,63.630000000,63.740000000,6,7,6,7,63.620000000,63.750000000,3,2,3,2,63.610000000,63.760000000,2,4,2,4,63.600000000,63.770000000,7,1,7,1,63.590000000,63.780000000,1,3,1,3,63.580000000,63.790000000,6,1,4,1,MCLQ5
2025-06-11T00:00:11.217577733Z,2025-06-11T00:00:11.217445709Z,10,1,42025623,M,A,3,63.730000000,1,130,15263,79308407,63.670000000,63.700000000,2,3,2,3,63.660000000,63.710000000,3,2,3,2,63.650000000,63.720000000,3,2,3,2,63.640000000,63.730000000,4,3,4,3,63.630000000,63.740000000,6,6,6,6,63.620000000,63.750000000,3,2,3,2,63.610000000,63.760000000,2,4,2,4,63.600000000,63.770000000,7,1,7,1,63.590000000,63.780000000,1,3,1,3,63.580000000,63.790000000,6,1,4,1,MCLQ5
2025-06-11T00:00:11.217588477Z,2025-06-11T00:00:11.217446111Z,10,1,42025623,M,B,3,63.630000000,1,130,12538,79308408,63.670000000,63.700000000,2,3,2,3,63.660000000,63.710000000,3,2,3,2,63.650000000,63.720000000,3,2,3,2,63.640000000,63.730000000,3,3,3,3,63.630000000,63.740000000,7,6,7,6,63.620000000,63.750000000,3,2,3,2,63.610000000,63.760000000,2,4,2,4,63.600000000,63.770000000,7,1,7,1,63.590000000,63.780000000,1,3,1,3,63.580000000,63.790000000,6,1,4,1,MCLQ5
2025-06-11T00:00:11.217598798Z,2025-06-11T00:00:11.217446649Z,10,1,42025623,M,A,3,63.730000000,1,130,11793,79308409,63.670000000,63.700000000,2,3,2,3,63.660000000,63.710000000,3,2,3,2,63.650000000,63.720000000,3,2,3,2,63.640000000,63.730000000,3,4,3,4,63.630000000,63.740000000,7,5,7,5,63.620000000,63.750000000,3,2,3,2,63.610000000,63.760000000,2,4,2,4,63.600000000,63.770000000,7,1,7,1,63.590000000,63.780000000,1,3,1,3,63.580000000,63.790000000,6,1,4,1,MCLQ5
2025-06-11T00:00:11.217609772Z,2025-06-11T00:00:11.217450643Z,10,1,42025623,C,A,6,63.760000000,1,130,11456,79308410,63.670000000,63.700000000,2,3,2,3,63.660000000,63.710000000,3,2,3,2,63.650000000,63.720000000,3,2,3,2,63.640000000,63.730000000,3,4,3,4,63.630000000,63.740000000,7,5,7,5,63.620000000,63.750000000,3,2,3,2,63.610000000,63.760000000,2,3,2,3,63.600000000,63.770000000,7,1,7,1,63.590000000,63.780000000,1,3,1,3,63.580000000,63.790000000,6,1,4,1,MCLQ5
2025-06-11T00:00:11.217640330Z,2025-06-11T00:00:11.217463103Z,10,1,42025623,A,A,0,63.690000000,1,130,15532,79308411,63.670000000,63.690000000,2,1,2,1,63.660000000,63.700000000,3,3,3,3,63.650000000,63.710000000,3,2,3,2,63.640000000,63.720000000,3,2,3,2,63.630000000,63.730000000,7,4,7,4,63.620000000,63.740000000,3,5,3,5,63.610000000,63.750000000,2,2,2,2,63.600000000,63.760000000,7,3,7,3,63.590000000,63.770000000,1,1,1,1,63.580000000,63.780000000,6,3,4,3,MCLQ5
2025-06-11T00:00:11.217737853Z,2025-06-11T00:00:11.217589817Z,10,1,42025623,A,B,6,63.610000000,1,130,10632,79308414,63.670000000,63.690000000,2,1,2,1,63.660000000,63.700000000,3,3,3,3,63.650000000,63.710000000,3,2,3,2,63.640000000,63.720000000,3,2,3,2,63.630000000,63.730000000,7,4,7,4,63.620000000,63.740000000,3,5,3,5,63.610000000,63.750000000,3,2,3,2,63.600000000,63.760000000,7,3,7,3,63.590000000,63.770000000,1,1,1,1,63.580000000,63.780000000,6,3,4,3,MCLQ5
2025-06-11T00:00:11.217744618Z,2025-06-11T00:00:11.217634437Z,10,1,42025623,A,A,6,63.750000000,1,130,11611,79308415,63.670000000,63.690000000,2,1,2,1,63.660000000,63.700000000,3,3,3,3,63.650000000,63.710000000,3,2,3,2,63.640000000,63.720000000,3,2,3,2,63.630000000,63.730000000,7,4,7,4,63.620000000,63.740000000,3,5,3,5,63.610000000,63.750000000,3,3,3,3,63.600000000,63.760000000,7,3,7,3,63.590000000,63.770000000,1,1,1,1,63.580000000,63.780000000,6,3,4,3,MCLQ5
2025-06-11T00:00:11.217812207Z,2025-06-11T00:00:11.217702555Z,10,1,42025623,M,B,2,62.280000000,1,130,14771,79308416,63.670000000,63.690000000,2,1,2,1,63.660000000,63.700000000,3,3,3,3,63.650000000,63.710000000,2,2,2,2,63.640000000,63.720000000,3,2,3,2,63.630000000,63.730000000,7,4,7,4,63.620000000,63.740000000,3,5,3,5,63.610000000,63.750000000,3,3,3,3,63.600000000,63.760000000,7,3,7,3,63.590000000,63.770000000,1,1,1,1,63.580000000,63.780000000,6,3,4,3,MCLQ5
2025-06-11T00:00:11.217826314Z,2025-06-11T00:00:11.217725343Z,10,1,42026514,M,A,1,66.730000000,2,130,12543,79308417,64.760000000,64.770000000,5,2,5,1,64.750000000,64.780000000,4,3,4,3,64.740000000,64.790000000,9,6,8,4,64.730000000,64.800000000,7,5,7,5,64.720000000,64.810000000,9,8,6,8,64.710000000,64.820000000,9,9,8,6,64.700000000,64.830000000,7,9,6,9,64.690000000,64.840000000,4,6,3,5,64.680000000,64.850000000,4,8,2,5,64.670000000,64.860000000,6,4,4,3,MCLN5
2025-06-11T00:00:11.218369169Z,2025-06-11T00:00:11.218264321Z,10,1,42026514,M,B,0,64.760000000,1,130,16260,79308418,64.760000000,64.770000000,6,2,6,1,64.750000000,64.780000000,4,3,4,3,64.740000000,64.790000000,9,6,8,4,64.730000000,64.800000000,7,5,7,5,64.720000000,64.810000000,9,8,6,8,64.710000000,64.820000000,9,9,8,6,64.700000000,64.830000000,7,9,6,9,64.690000000,64.840000000,4,6,3,5,64.680000000,64.850000000,4,8,2,5,64.670000000,64.860000000,6,4,4,3,MCLN5
2025-06-11T00:00:11.227743752Z,2025-06-11T00:00:11.227631261Z,10,1,42026514,C,A,0,64.770000000,2,130,14499,79308422,64.760000000,64.780000000,6,3,6,3,64.750000000,64.790000000,4,6,4,4,64.740000000,64.800000000,9,5,8,5,64.730000000,64.810000000,7,8,7,8,64.720000000,64.820000000,9,9,6,6,64.710000000,64.830000000,9,9,8,9,64.700000000,64.840000000,7,6,6,5,64.690000000,64.850000000,4,8,3,5,64.680000000,64.860000000,4,4,2,3,64.670000000,64.870000000,6,4,4,3,MCLN5
2025-06-11T00:00:11.227762959Z,2025-06-11T00:00:11.227631411Z,10,1,42025623,C,A,0,63.690000000,1,130,13833,79308424,63.670000000,63.700000000,2,3,2,3,63.660000000,63.710000000,3,2,3,2,63.650000000,63.720000000,2,2,2,2,63.640000000,63.730000000,3,4,3,4,63.630000000,63.740000000,7,5,7,5,63.620000000,63.750000000,3,3,3,3,63.610000000,63.760000000,3,3,3,3,63.600000000,63.770000000,7,1,7,1,63.590000000,63.780000000,1,3,1,3,63.580000000,63.790000000,6,1,4,1,MCLQ5
2025-06-11T00:00:11.227861388Z,2025-06-11T00:00:11.227753349Z,10,1,42026514,A,A,0,64.780000000,1,130,16687,79308427,64.760000000,64.780000000,6,4,6,4,64.750000000,64.790000000,4,6,4,4,64.740000000,64.800000000,9,5,8,5,64.730000000,64.810000000,7,8,7,8,64.720000000,64.820000000,9,9,6,6,64.710000000,64.830000000,9,9,8,9,64.700000000,64.840000000,7,6,6,5,64.690000000,64.850000000,4,8,3,5,64.680000000,64.860000000,4,4,2,3,64.670000000,64.870000000,6,4,4,3,MCLN5
2025-06-11T00:00:11.227868968Z,2025-06-11T00:00:11.227773681Z,10,1,42025623,C,A,5,63.750000000,1,130,11234,79308428,63.670000000,63.700000000,2,3,2,3,63.660000000,63.710000000,3,2,3,2,63.650000000,63.720000000,2,2,2,2,63.640000000,63.730000000,3,4,3,4,63.630000000,63.740000000,7,5,7,5,63.620000000,63.750000000,3,2,3,2,63.610000000,63.760000000,3,3,3,3,63.600000000,63.770000000,7,1,7,1,63.590000000,63.780000000,1,3,1,3,63.580000000,63.790000000,6,1,4,1,MCLQ5
2025-06-11T00:00:11.227920590Z,2025-06-11T00:00:11.227804189Z,10,1,42026514,A,B,0,64.770000000,2,130,17636,79308429,64.770000000,64.780000000,2,4,1,4,64.760000000,64.790000000,6,6,6,4,64.750000000,64.800000000,4,5,4,5,64.740000000,64.810000000,9,8,8,8,64.730000000,64.820000000,7,9,7,6,64.720000000,64.830000000,9,9,6,9,64.710000000,64.840000000,9,6,8,5,64.700000000,64.850000000,7,8,6,5,64.690000000,64.860000000,4,4,3,3,64.680000000,64.870000000,4,4,2,3,MCLN5
2025-06-11T00:00:11.228008307Z,2025-06-11T00:00:11.227917635Z,10,1,42025623,M,B,2,63.650000000,1,130,11355,79308432,63.670000000,63.700000000,2,3,2,3,63.660000000,63.710000000,3,2,3,2,63.650000000,63.720000000,3,2,3,2,63.640000000,63.730000000,3,4,3,4,63.630000000,63.740000000,7,5,7,5,63.620000000,63.750000000,3,2,3,2,63.610000000,63.760000000,3,3,3,3,63.600000000,63.770000000,7,1,7,1,63.590000000,63.780000000,1,3,1,3,63.580000000,63.790000000,6,1,4,1,MCLQ5
2025-06-11T00:00:11.228027552Z,2025-06-11T00:00:11.227928637Z,10,1,42026514,C,A,5,64.830000000,1,130,11463,79308433,64.770000000,64.780000000,2,4,1,4,64.760000000,64.790000000,6,6,6,4,64.750000000,64.800000000,4,5,4,5,64.740000000,64.810000000,9,8,8,8,64.730000000,64.820000000,7,9,7,6,64.720000000,64.830000000,9,8,6,8,64.710000000,64.840000000,9,6,8,5,64.700000000,64.850000000,7,8,6,5,64.690000000,64.860000000,4,4,3,3,64.680000000,64.870000000,4,4,2,3,MCLN5
2025-06-11T00:00:11.228095554Z,2025-06-11T00:00:11.227985119Z,10,1,42026514,M,A,0,64.780000000,1,130,17097,79308435,64.770000000,64.780000000,2,5,1,5,64.760000000,64.790000000,6,6,6,4,64.750000000,64.800000000,4,5,4,5,64.740000000,64.810000000,9,8,8,8,64.730000000,64.820000000,7,9,7,6,64.720000000,64.830000000,9,8,6,8,64.710000000,64.840000000,9,6,8,5,64.700000000,64.850000000,7,8,6,5,64.690000000,64.860000000,4,4,3,3,64.680000000,64.870000000,4,4,2,3,MCLN5
2025-06-11T00:00:11.228124806Z,2025-06-11T00:00:11.228028779Z,10,1,42026514,M,B,1,62.760000000,2,130,12780,79308436,64.770000000,64.780000000,2,5,1,5,64.760000000,64.790000000,5,6,5,4,64.750000000,64.800000000,4,5,4,5,64.740000000,64.810000000,9,8,8,8,64.730000000,64.820000000,7,9,7,6,64.720000000,64.830000000,9,8,6,8,64.710000000,64.840000000,9,6,8,5,64.700000000,64.850000000,7,8,6,5,64.690000000,64.860000000,4,4,3,3,64.680000000,64.870000000,4,4,2,3,MCLN5
2025-06-11T00:00:11.232078639Z,2025-06-11T00:00:11.231962341Z,10,1,42026514,C,B,0,64.770000000,2,130,15760,79308438,64.760000000,64.780000000,5,5,5,5,64.750000000,64.790000000,4,6,4,4,64.740000000,64.800000000,9,5,8,5,64.730000000,64.810000000,7,8,7,8,64.720000000,64.820000000,9,9,6,6,64.710000000,64.830000000,9,8,8,8,64.700000000,64.840000000,7,6,6,5,64.690000000,64.850000000,4,8,3,5,64.680000000,64.860000000,4,4,2,3,64.670000000,64.870000000,6,4,4,3,MCLN5
2025-06-11T00:00:11.243580639Z,2025-06-11T00:00:11.243473037Z,10,1,42026514,A,A,5,64.830000000,1,130,15176,79308441,64.760000000,64.780000000,5,5,5,5,64.750000000,64.790000000,4,6,4,4,64.740000000,64.800000000,9,5,8,5,64.730000000,64.810000000,7,8,7,8,64.720000000,64.820000000,9,9,6,6,64.710000000,64.830000000,9,9,8,9,64.700000000,64.840000000,7,6,6,5,64.690000000,64.850000000,4,8,3,5,64.680000000,64.860000000,4,4,2,3,64.670000000,64.870000000,6,4,4,3,MCLN5
2025-06-11T00:00:11.243589325Z,2025-06-11T00:00:11.243474343Z,10,1,42025623,C,B,6,63.610000000,1,130,11609,79308442,63.670000000,63.700000000,2,3,2,3,63.660000000,63.710000000,3,2,3,2,63.650000000,63.720000000,3,2,3,2,63.640000000,63.730000000,3,4,3,4,63.630000000,63.740000000,7,5,7,5,63.620000000,63.750000000,3,2,3,2,63.610000000,63.760000000,2,3,2,3,63.600000000,63.770000000,7,1,7,1,63.590000000,63.780000000,1,3,1,3,63.580000000,63.790000000,6,1,4,1,MCLQ5
2025-06-11T00:00:11.243600069Z,2025-06-11T00:00:11.243476377Z,10,1,42025623,A,A,6,63.760000000,1,130,11655,79308443,63.670000000,63.700000000,2,3,2,3,63.660000000,63.710000000,3,2,3,2,63.650000000,63.720000000,3,2,3,2,63.640000000,63.730000000,3,4,3,4,63.630000000,63.740000000,7,5,7,5,63.620000000,63.750000000,3,2,3,2,63.610000000,63.760000000,2,4,2,4,63.600000000,63.770000000,7,1,7,1,63.590000000,63.780000000,1,3,1,3,63.580000000,63.790000000,6,1,4,1,MCLQ5
2025-06-11T00:00:11.243712621Z,2025-06-11T00:00:11.243613767Z,10,1,42025623,A,B,5,63.620000000,1,130,14876,79308444,63.670000000,63.700000000,2,3,2,3,63.660000000,63.710000000,3,2,3,2,63.650000000,63.720000000,3,2,3,2,63.640000000,63.730000000,3,4,3,4,63.630000000,63.740000000,7,5,7,5,63.620000000,63.750000000,4,2,4,2,63.610000000,63.760000000,2,4,2,4,63.600000000,63.770000000,7,1,7,1,63.590000000,63.780000000,1,3,1,3,63.580000000,63.790000000,6,1,4,1,MCLQ5
2025-06-11T00:00:11.397704118Z,2025-06-11T00:00:11.397565269Z,10,1,42026514,A,A,0,64.770000000,2,130,14491,79308451,64.760000000,64.770000000,5,2,5,1,64.750000000,64.780000000,4,5,4,5,64.740000000,64.790000000,9,6,8,4,64.730000000,64.800000000,7,5,7,5,64.720000000,64.810000000,9,8,6,8,64.710000000,64.820000000,9,9,8,6,64.700000000,64.830000000,7,9,6,9,64.690000000,64.840000000,4,6,3,5,64.680000000,64.850000000,4,8,2,5,64.670000000,64.860000000,6,4,4,3,MCLN5
2025-06-11T00:00:11.397814581Z,2025-06-11T00:00:11.397724641Z,10,1,42025623,C,B,5,63.620000000,1,130,14964,79308454,63.670000000,63.700000000,2,3,2,3,63.660000000,63.710000000,3,2,3,2,63.650000000,63.720000000,3,2,3,2,63.640000000,63.730000000,3,4,3,4,63.630000000,63.740000000,7,5,7,5,63.620000000,63.750000000,3,2,3,2,63.610000000,63.760000000,2,4,2,4,63.600000000,63.770000000,7,1,7,1,63.590000000,63.780000000,1,3,1,3,63.580000000,63.790000000,6,1,4,1,MCLQ5
2025-06-11T00:00:11.397822269Z,2025-06-11T00:00:11.397730921Z,10,1,42025623,C,A,6,63.760000000,1,130,11192,79308455,63.670000000,63.700000000,2,3,2,3,63.660000000,63.710000000,3,2,3,2,63.650000000,63.720000000,3,2,3,2,63.640000000,63.730000000,3,4,3,4,63.630000000,63.740000000,7,5,7,5,63.620000000,63.750000000,3,2,3,2,63.610000000,63.760000000,2,3,2,3,63.600000000,63.770000000,7,1,7,1,63.590000000,63.780000000,1,3,1,3,63.580000000,63.790000000,6,1,4,1,MCLQ5
2025-06-11T00:00:11.397936080Z,2025-06-11T00:00:11.397842351Z,10,1,42025623,A,B,6,63.610000000,1,130,14784,79308456,63.670000000,63.700000000,2,3,2,3,63.660000000,63.710000000,3,2,3,2,63.650000000,63.720000000,3,2,3,2,63.640000000,63.730000000,3,4,3,4,63.630000000,63.740000000,7,5,7,5,63.620000000,63.750000000,3,2,3,2,63.610000000,63.760000000,3,3,3,3,63.600000000,63.770000000,7,1,7,1,63.590000000,63.780000000,1,3,1,3,63.580000000,63.790000000,6,1,4,1,MCLQ5
2025-06-11T00:00:11.397943883Z,2025-06-11T00:00:11.397855617Z,10,1,42025623,A,A,5,63.750000000,1,130,11294,79308457,63.670000000,63.700000000,2,3,2,3,63.660000000,63.710000000,3,2,3,2,63.650000000,63.720000000,3,2,3,2,63.640000000,63.730000000,3,4,3,4,63.630000000,63.740000000,7,5,7,5,63.620000000,63.750000000,3,3,3,3,63.610000000,63.760000000,3,3,3,3,63.600000000,63.770000000,7,1,7,1,63.590000000,63.780000000,1,3,1,3,63.580000000,63.790000000,6,1,4,1,MCLQ5
2025-06-11T00:00:11.398058846Z,2025-06-11T00:00:11.397948907Z,10,1,42026514,M,A,1,66.720000000,2,130,16224,79308458,64.760000000,64.770000000,5,2,5,1,64.750000000,64.780000000,4,4,4,4,64.740000000,64.790000000,9,6,8,4,64.730000000,64.800000000,7,5,7,5,64.720000000,64.810000000,9,8,6,8,64.710000000,64.820000000,9,9,8,6,64.700000000,64.830000000,7,9,6,9,64.690000000,64.840000000,4,6,3,5,64.680000000,64.850000000,4,8,2,5,64.670000000,64.860000000,6,4,4,3,MCLN5
2025-06-11T00:00:11.398084381Z,2025-06-11T00:00:11.397993737Z,10,1,42025623,M,B,2,62.290000000,1,130,11805,79308459,63.670000000,63.700000000,2,3,2,3,63.660000000,63.710000000,3,2,3,2,63.650000000,63.720000000,2,2,2,2,63.640000000,63.730000000,3,4,3,4,63.630000000,63.740000000,7,5,7,5,63.620000000,63.750000000,3,3,3,3,63.610000000,63.760000000,3,3,3,3,63.600000000,63.770000000,7,1,7,1,63.590000000,63.780000000,1,3,1,3,63.580000000,63.790000000,6,1,4,1,MCLQ5
2025-06-11T00:00:11.398164510Z,2025-06-11T00:00:11.398068767Z,10,1,42026514,C,A,1,64.780000000,1,130,16193,79308460,64.760000000,64.770000000,5,2,5,1,64.750000000,64.780000000,4,3,4,3,64.740000000,64.790000000,9,6,8,4,64.730000000,64.800000000,7,5,7,5,64.720000000,64.810000000,9,8,6,8,64.710000000,64.820000000,9,9,8,6,64.700000000,64.830000000,7,9,6,9,64.690000000,64.840000000,4,6,3,5,64.680000000,64.850000000,4,8,2,5,64.670000000,64.860000000,6,4,4,3,MCLN5
2025-06-11T00:00:11.408241714Z,2025-06-11T00:00:11.408122863Z,10,1,42026514,C,A,0,64.770000000,2,130,14636,79308461,64.760000000,64.780000000,5,3,5,3,64.750000000,64.790000000,4,6,4,4,64.740000000,64.800000000,9,5,8,5,64.730000000,64.810000000,7,8,7,8,64.720000000,64.820000000,9,9,6,6,64.710000000,64.830000000,9,9,8,9,64.700000000,64.840000000,7,6,6,5,64.690000000,64.850000000,4,8,3,5,64.680000000,64.860000000,4,4,2,3,64.670000000,64.870000000,6,4,4,3,MCLN5
2025-06-11T00:00:11.408360218Z,2025-06-11T00:00:11.408251497Z,10,1,42026514,A,A,0,64.780000000,1,130,17350,79308464,64.760000000,64.780000000,5,4,5,4,64.750000000,64.790000000,4,6,4,4,64.740000000,64.800000000,9,5,8,5,64.730000000,64.810000000,7,8,7,8,64.720000000,64.820000000,9,9,6,6,64.710000000,64.830000000,9,9,8,9,64.700000000,64.840000000,7,6,6,5,64.690000000,64.850000000,4,8,3,5,64.680000000,64.860000000,4,4,2,3,64.670000000,64.870000000,6,4,4,3,MCLN5
2025-06-11T00:00:11.408367437Z,2025-06-11T00:00:11.408262231Z,10,1,42025623,C,A,5,63.750000000,1,130,11214,79308465,63.670000000,63.700000000,2,3,2,3,63.660000000,63.710000000,3,2,3,2,63.650000000,63.720000000,2,2,2,2,63.640000000,63.730000000,3,4,3,4,63.630000000,63.740000000,7,5,7,5,63.620000000,63.750000000,3,2,3,2,63.610000000,63.760000000,3,3,3,3,63.600000000,63.770000000,7,1,7,1,63.590000000,63.780000000,1,3,1,3,63.580000000,63.790000000,6,1,4,1,MCLQ5
2025-06-11T00:00:11.408375331Z,2025-06-11T00:00:11.408266589Z,10,1,42025623,C,B,6,63.610000000,1,130,11288,79308466,63.670000000,63.700000000,2,3,2,3,63.660000000,63.710000000,3,2,3,2,63.650000000,63.720000000,2,2,2,2,63.640000000,63.730000000,3,4,3,4,63.630000000,63.740000000,7,5,7,5,63.620000000,63.750000000,3,2,3,2,63.610000000,63.760000000,2,3,2,3,63.600000000,63.770000000,7,1,7,1,63.590000000,63.780000000,1,3,1,3,63.580000000,63.790000000,6,1,4,1,MCLQ5
2025-06-11T00:00:11.408453870Z,2025-06-11T00:00:11.408351851Z,10,1,42026514,M,B,0,64.760000000,1,130,16828,79308467,64.760000000,64.780000000,6,4,6,4,64.750000000,64.790000000,4,6,4,4,64.740000000,64.800000000,9,5,8,5,64.730000000,64.810000000,7,8,7,8,64.720000000,64.820000000,9,9,6,6,64.710000000,64.830000000,9,9,8,9,64.700000000,64.840000000,7,6,6,5,64.690000000,64.850000000,4,8,3,5,64.680000000,64.860000000,4,4,2,3,64.670000000,64.870000000,6,4,4,3,MCLN5
2025-06-11T00:00:11.408489849Z,2025-06-11T00:00:11.408382167Z,10,1,42026514,A,A,0,64.770000000,2,130,11605,79308468,64.760000000,64.770000000,6,2,6,1,64.750000000,64.780000000,4,4,4,4,64.740000000,64.790000000,9,6,8,4,64.730000000,64.800000000,7,5,7,5,64.720000000,64.810000000,9,8,6,8,64.710000000,64.820000000,9,9,8,6,64.700000000,64.830000000,7,9,6,9,64.690000000,64.840000000,4,6,3,5,64.680000000,64.850000000,4,8,2,5,64.670000000,64.860000000,6,4,4,3,MCLN5
2025-06-11T00:00:11.408507167Z,2025-06-11T00:00:11.408384087Z,10,1,42025623,A,A,6,63.760000000,1,130,12025,79308470,63.670000000,63.700000000,2,3,2,3,63.660000000,63.710000000,3,2,3,2,63.650000000,63.720000000,2,2,2,2,63.640000000,63.730000000,3,4,3,4,63.630000000,63.740000000,7,5,7,5,63.620000000,63.750000000,3,2,3,2,63.610000000,63.760000000,2,4,2,4,63.600000000,63.770000000,7,1,7,1,63.590000000,63.780000000,1,3,1,3,63.580000000,63.790000000,6,1,4,1,MCLQ5
2025-06-11T00:00:11.408516298Z,2025-06-11T00:00:11.408392419Z,10,1,42025623,A,B,5,63.620000000,1,130,11361,79308471,63.670000000,63.700000000,2,3,2,3,63.660000000,63.710000000,3,2,3,2,63.650000000,63.720000000,2,2,2,2,63.640000000,63.730000000,3,4,3,4,63.630000000,63.740000000,7,5,7,5,63.620000000,63.750000000,4,2,4,2,63.610000000,63.760000000,2,4,2,4,63.600000000,63.770000000,7,1,7,1,63.590000000,63.780000000,1,3,1,3,63.580000000,63.790000000,6,1,4,1,MCLQ5
2025-06-11T00:00:11.408562752Z,2025-06-11T00:00:11.408456735Z,10,1,42026514,M,A,1,64.780000000,1,130,17512,79308472,64.760000000,64.770000000,6,2,6,1,64.750000000,64.780000000,4,5,4,5,64.740000000,64.790000000,9,6,8,4,64.730000000,64.800000000,7,5,7,5,64.720000000,64.810000000,9,8,6,8,64.710000000,64.820000000,9,9,8,6,64.700000000,64.830000000,7,9,6,9,64.690000000,64.840000000,4,6,3,5,64.680000000,64.850000000,4,8,2,5,64.670000000,64.860000000,6,4,4,3,MCLN5
2025-06-11T00:00:11.408596911Z,2025-06-11T00:00:11.408497765Z,10,1,42026514,C,B,0,64.760000000,1,130,13028,79308473,64.760000000,64.770000000,5,2,5,1,64.750000000,64.780000000,4,5,4,5,64.740000000,64.790000000,9,6,8,4,64.730000000,64.800000000,7,5,7,5,64.720000000,64.810000000,9,8,6,8,64.710000000,64.820000000,9,9,8,6,64.700000000,64.830000000,7,9,6,9,64.690000000,64.840000000,4,6,3,5,64.680000000,64.850000000,4,8,2,5,64.670000000,64.860000000,6,4,4,3,MCLN5
2025-06-11T00:00:11.408610542Z,2025-06-11T00:00:11.408498897Z,10,1,42026514,C,A,1,64.780000000,1,130,12485,79308474,64.760000000,64.770000000,5,2,5,1,64.750000000,64.780000000,4,4,4,4,64.740000000,64.790000000,9,6,8,4,64.730000000,64.800000000,7,5,7,5,64.720000000,64.810000000,9,8,6,8,64.710000000,64.820000000,9,9,8,6,64.700000000,64.830000000,7,9,6,9,64.690000000,64.840000000,4,6,3,5,64.680000000,64.850000000,4,8,2,5,64.670000000,64.860000000,6,4,4,3,MCLN5
2025-06-11T00:00:11.408620648Z,2025-06-11T00:00:11.408512953Z,10,1,42025623,C,A,6,63.760000000,1,130,11234,79308475,63.670000000,63.700000000,2,3,2,3,63.660000000,63.710000000,3,2,3,2,63.650000000,63.720000000,2,2,2,2,63.640000000,63.730000000,3,4,3,4,63.630000000,63.740000000,7,5,7,5,63.620000000,63.750000000,4,2,4,2,63.610000000,63.760000000,2,3,2,3,63.600000000,63.770000000,7,1,7,1,63.590000000,63.780000000,1,3,1,3,63.580000000,63.790000000,6,1,4,1,MCLQ5
2025-06-11T00:00:11.408728194Z,2025-06-11T00:00:11.408638361Z,10,1,42025623,A,A,5,63.750000000,1,130,14515,79308476,63.670000000,63.700000000,2,3,2,3,63.660000000,63.710000000,3,2,3,2,63.650000000,63.720000000,2,2,2,2,63.640000000,63.730000000,3,4,3,4,63.630000000,63.740000000,7,5,7,5,63.620000000,63.750000000,4,3,4,3,63.610000000,63.760000000,2,3,2,3,63.600000000,63.770000000,7,1,7,1,63.590000000,63.780000000,1,3,1,3,63.580000000,63.790000000,6,1,4,1,MCLQ5
2025-06-11T00:00:11.408829856Z,2025-06-11T00:00:11.408735335Z,10,1,42025623,C,B,5,63.620000000,1,130,14588,79308477,63.670000000,63.700000000,2,3,2,3,63.660000000,63.710000000,3,2,3,2,63.650000000,63.720000000,2,2,2,2,63.640000000,63.730000000,3,4,3,4,63.630000000,63.740000000,7,5,7,5,63.620000000,63.750000000,3,3,3,3,63.610000000,63.760000000,2,3,2,3,63.600000000,63.770000000,7,1,7,1,63.590000000,63.780000000,1,3,1,3,63.580000000,63.790000000,6,1,4,1,MCLQ5
2025-06-11T00:00:11.408862103Z,2025-06-11T00:00:11.408764729Z,10,1,42026514,M,A,1,66.730000000,2,130,12897,79308478,64.760000000,64.770000000,5,2,5,1,64.750000000,64.780000000,4,3,4,3,64.740000000,64.790000000,9,6,8,4,64.730000000,64.800000000,7,5,7,5,64.720000000,64.810000000,9,8,6,8,64.710000000,64.820000000,9,9,8,6,64.700000000,64.830000000,7,9,6,9,64.690000000,64.840000000,4,6,3,5,64.680000000,64.850000000,4,8,2,5,64.670000000,64.860000000,6,4,4,3,MCLN5
2025-06-11T00:00:11.408946955Z,2025-06-11T00:00:11.408855137Z,10,1,42025623,A,B,6,63.610000000,1,130,14559,79308479,63.670000000,63.700000000,2,3,2,3,63.660000000,63.710000000,3,2,3,2,63.650000000,63.720000000,2,2,2,2,63.640000000,63.730000000,3,4,3,4,63.630000000,63.740000000,7,5,7,5,63.620000000,63.750000000,3,3,3,3,63.610000000,63.760000000,3,3,3,3,63.600000000,63.770000000,7,1,7,1,63.590000000,63.780000000,1,3,1,3,63.580000000,63.790000000,6,1,4,1,MCLQ5
2025-06-11T00:00:11.420841067Z,2025-06-11T00:00:11.420722305Z,10,1,42026514,C,A,0,64.770000000,2,130,15545,79308480,64.760000000,64.780000000,5,3,5,3,64.750000000,64.790000000,4,6,4,4,64.740000000,64.800000000,9,5,8,5,64.730000000,64.810000000,7,8,7,8,64.720000000,64.820000000,9,9,6,6,64.710000000,64.830000000,9,9,8,9,64.700000000,64.840000000,7,6,6,5,64.690000000,64.850000000,4,8,3,5,64.680000000,64.860000000,4,4,2,3,64.670000000,64.870000000,6,4,4,3,MCLN5
2025-06-11T00:00:11.420954364Z,2025-06-11T00:00:11.420849923Z,10,1,42026514,A,A,0,64.780000000,1,130,16541,79308483,64.760000000,64.780000000,5,4,5,4,64.750000000,64.790000000,4,6,4,4,64.740000000,64.800000000,9,5,8,5,64.730000000,64.810000000,7,8,7,8,64.720000000,64.820000000,9,9,6,6,64.710000000,64.830000000,9,9,8,9,64.700000000,64.840000000,7,6,6,5,64.690000000,64.850000000,4,8,3,5,64.680000000,64.860000000,4,4,2,3,64.670000000,64.870000000,6,4,4,3,MCLN5
2025-06-11T00:00:11.420961322Z,2025-06-11T00:00:11.420862459Z,10,1,42025623,C,A,5,63.750000000,1,130,11436,79308484,63.670000000,63.700000000,2,3,2,3,63.660000000,63.710000000,3,2,3,2,63.650000000,63.720000000,2,2,2,2,63.640000000,63.730000000,3,4,3,4,63.630000000,63.740000000,7,5,7,5,63.620000000,63.750000000,3,2,3,2,63.610000000,63.760000000,3,3,3,3,63.600000000,63.770000000,7,1,7,1,63.590000000,63.780000000,1,3,1,3,63.580000000,63.790000000,6,1,4,1,MCLQ5
2025-06-11T00:00:11.420970837Z,2025-06-11T00:00:11.420866741Z,10,1,42025623,C,B,6,63.610000000,1,130,11440,79308485,63.670000000,63.700000000,2,3,2,3,63.660000000,63.710000000,3,2,3,2,63.650000000,63.720000000,2,2,2,2,63.640000000,63.730000000,3,4,3,4,63.630000000,63.740000000,7,5,7,5,63.620000000,63.750000000,3,2,3,2,63.610000000,63.760000000,2,3,2,3,63.600000000,63.770000000,7,1,7,1,63.590000000,63.780000000,1,3,1,3,63.580000000,63.790000000,6,1,4,1,MCLQ5
2025-06-11T00:00:11.421081754Z,2025-06-11T00:00:11.420986967Z,10,1,42025623,A,A,6,63.760000000,1,130,15086,79308486,63.670000000,63.700000000,2,3,2,3,63.660000000,63.710000000,3,2,3,2,63.650000000,63.720000000,2,2,2,2,63.640000000,63.730000000,3,4,3,4,63.630000000,63.740000000,7,5,7,5,63.620000000,63.750000000,3,2,3,2,63.610000000,63.760000000,2,4,2,4,63.600000000,63.770000000,7,1,7,1,63.590000000,63.780000000,1,3,1,3,63.580000000,63.790000000,6,1,4,1,MCLQ5
2025-06-11T00:00:11.421090424Z,2025-06-11T00:00:11.420991709Z,10,1,42025623,A,B,5,63.620000000,1,130,11933,79308487,63.670000000,63.700000000,2,3,2,3,63.660000000,63.710000000,3,2,3,2,63.650000000,63.720000000,2,2,2,2,63.640000000,63.730000000,3,4,3,4,63.630000000,63.740000000,7,5,7,5,63.620000000,63.750000000,4,2,4,2,63.610000000,63.760000000,2,4,2,4,63.600000000,63.770000000,7,1,7,1,63.590000000,63.780000000,1,3,1,3,63.580000000,63.790000000,6,1,4,1,MCLQ5
2025-06-11T00:00:11.504243848Z,2025-06-11T00:00:11.504119769Z,10,1,42026514,M,A,0,64.780000000,1,130,16976,79308494,64.760000000,64.780000000,5,5,5,5,64.750000000,64.790000000,4,6,4,4,64.740000000,64.800000000,9,5,8,5,64.730000000,64.810000000,7,8,7,8,64.720000000,64.820000000,9,9,6,6,64.710000000,64.830000000,9,9,8,9,64.700000000,64.840000000,7,6,6,5,64.690000000,64.850000000,4,8,3,5,64.680000000,64.860000000,4,4,2,3,64.670000000,64.870000000,6,4,4,3,MCLN5
2025-06-11T00:00:11.504342815Z,2025-06-11T00:00:11.504252725Z,10,1,42026514,M,A,3,64.820000000,1,130,15268,79308495,64.760000000,64.780000000,5,5,5,5,64.750000000,64.790000000,4,6,4,4,64.740000000,64.800000000,9,5,8,5,64.730000000,64.810000000,7,7,7,7,64.720000000,64.820000000,9,10,6,7,64.710000000,64.830000000,9,9,8,9,64.700000000,64.840000000,7,6,6,5,64.690000000,64.850000000,4,8,3,5,64.680000000,64.860000000,4,4,2,3,64.670000000,64.870000000,6,4,4,3,MCLN5
2025-06-11T00:00:11.504351332Z,2025-06-11T00:00:11.504253281Z,10,1,42026514,M,B,3,64.730000000,1,130,11857,79308496,64.760000000,64.780000000,5,5,5,5,64.750000000,64.790000000,4,6,4,4,64.740000000,64.800000000,9,5,8,5,64.730000000,64.810000000,8,7,8,7,64.720000000,64.820000000,8,10,5,7,64.710000000,64.830000000,9,9,8,9,64.700000000,64.840000000,7,6,6,5,64.690000000,64.850000000,4,8,3,5,64.680000000,64.860000000,4,4,2,3,64.670000000,64.870000000,6,4,4,3,MCLN5
2025-06-11T00:00:11.504381113Z,2025-06-11T00:00:11.504271271Z,10,1,42026514,A,A,0,64.770000000,2,130,11307,79308497,64.760000000,64.770000000,5,2,5,1,64.750000000,64.780000000,4,5,4,5,64.740000000,64.790000000,9,6,8,4,64.730000000,64.800000000,8,5,8,5,64.720000000,64.810000000,8,7,5,7,64.710000000,64.820000000,9,10,8,7,64.700000000,64.830000000,7,9,6,9,64.690000000,64.840000000,4,6,3,5,64.680000000,64.850000000,4,8,2,5,64.670000000,64.860000000,6,4,4,3,MCLN5
2025-06-11T00:00:11.504493289Z,2025-06-11T00:00:11.504401633Z,10,1,42025623,C,B,5,63.620000000,1,130,15074,79308500,63.670000000,63.700000000,2,3,2,3,63.660000000,63.710000000,3,2,3,2,63.650000000,63.720000000,2,2,2,2,63.640000000,63.730000000,3,4,3,4,63.630000000,63.740000000,7,5,7,5,63.620000000,63.750000000,3,2,3,2,63.610000000,63.760000000,2,4,2,4,63.600000000,63.770000000,7,1,7,1,63.590000000,63.780000000,1,3,1,3,63.580000000,63.790000000,6,1,4,1,MCLQ5
2025-06-11T00:00:11.504502251Z,2025-06-11T00:00:11.504406165Z,10,1,42025623,C,A,6,63.760000000,1,130,12197,79308501,63.670000000,63.700000000,2,3,2,3,63.660000000,63.710000000,3,2,3,2,63.650000000,63.720000000,2,2,2,2,63.640000000,63.730000000,3,4,3,4,63.630000000,63.740000000,7,5,7,5,63.620000000,63.750000000,3,2,3,2,63.610000000,63.760000000,2,3,2,3,63.600000000,63.770000000,7,1,7,1,63.590000000,63.780000000,1,3,1,3,63.580000000,63.790000000,6,1,4,1,MCLQ5
2025-06-11T00:00:11.504724890Z,2025-06-11T00:00:11.504624479Z,10,1,42026514,M,A,1,66.730000000,2,130,16357,79308502,64.760000000,64.770000000,5,2,5,1,64.750000000,64.780000000,4,4,4,4,64.740000000,64.790000000,9,6,8,4,64.730000000,64.800000000,8,5,8,5,64.720000000,64.810000000,8,7,5,7,64.710000000,64.820000000,9,10,8,7,64.700000000,64.830000000,7,9,6,9,64.690000000,64.840000000,4,6,3,5,64.680000000,64.850000000,4,8,2,5,64.670000000,64.860000000,6,4,4,3,MCLN5
2025-06-11T00:00:11.504825916Z,2025-06-11T00:00:11.504733491Z,10,1,42026514,C,A,1,64.780000000,1,130,16005,79308503,64.760000000,64.770000000,5,2,5,1,64.750000000,64.780000000,4,3,4,3,64.740000000,64.790000000,9,6,8,4,64.730000000,64.800000000,8,5,8,5,64.720000000,64.810000000,8,7,5,7,64.710000000,64.820000000,9,10,8,7,64.700000000,64.830000000,7,9,6,9,64.690000000,64.840000000,4,6,3,5,64.680000000,64.850000000,4,8,2,5,64.670000000,64.860000000,6,4,4,3,MCLN5
2025-06-11T00:00:11.517290952Z,2025-06-11T00:00:11.517174137Z,10,1,42026514,C,A,0,64.770000000,2,130,14863,79308504,64.760000000,64.780000000,5,3,5,3,64.750000000,64.790000000,4,6,4,4,64.740000000,64.800000000,9,5,8,5,64.730000000,64.810000000,8,7,8,7,64.720000000,64.820000000,8,10,5,7,64.710000000,64.830000000,9,9,8,9,64.700000000,64.840000000,7,6,6,5,64.690000000,64.850000000,4,8,3,5,64.680000000,64.860000000,4,4,2,3,64.670000000,64.870000000,6,4,4,3,MCLN5
2025-06-11T00:00:11.517404303Z,2025-06-11T00:00:11.517310047Z,10,1,42025623,M,A,3,63.740000000,1,130,15415,79308507,63.670000000,63.700000000,2,3,2,3,63.660000000,63.710000000,3,2,3,2,63.650000000,63.720000000,2,2,2,2,63.640000000,63.730000000,3,3,3,3,63.630000000,63.740000000,7,6,7,6,63.620000000,63.750000000,3,2,3,2,63.610000000,63.760000000,2,3,2,3,63.600000000,63.770000000,7,1,7,1,63.590000000,63.780000000,1,3,1,3,63.580000000,63.790000000,6,1,4,1,MCLQ5
2025-06-11T00:00:11.517412305Z,2025-06-11T00:00:11.517310529Z,10,1,42025623,M,B,3,63.640000000,1,130,11474,79308508,63.670000000,63.700000000,2,3,2,3,63.660000000,63.710000000,3,2,3,2,63.650000000,63.720000000,2,2,2,2,63.640000000,63.730000000,4,3,4,3,63.630000000,63.740000000,6,6,6,6,63.620000000,63.750000000,3,2,3,2,63.610000000,63.760000000,2,3,2,3,63.600000000,63.770000000,7,1,7,1,63.590000000,63.780000000,1,3,1,3,63.580000000,63.790000000,6,1,4,1,MCLQ5
2025-06-11T00:00:11.517422642Z,2025-06-11T00:00:11.517311007Z,10,1,42025623,M,A,3,63.740000000,1,130,11317,79308509,63.670000000,63.700000000,2,3,2,3,63.660000000,63.710000000,3,2,3,2,63.650000000,63.720000000,2,2,2,2,63.640000000,63.730000000,4,2,4,2,63.630000000,63.740000000,6,7,6,7,63.620000000,63.750000000,3,2,3,2,63.610000000,63.760000000,2,3,2,3,63.600000000,63.770000000,7,1,7,1,63.590000000,63.780000000,1,3,1,3,63.580000000,63.790000000,6,1,4,1,MCLQ5
2025-06-11T00:00:11.517434085Z,2025-06-11T00:00:11.517311583Z,10,1,42025623,M,B,3,63.640000000,1,130,10642,79308510,63.670000000,63.700000000,2,3,2,3,63.660000000,63.710000000,3,2,3,2,63.650000000,63.720000000,2,2,2,2,63.640000000,63.730000000,5,2,5,2,63.630000000,63.740000000,5,7,5,7,63.620000000,63.750000000,3,2,3,2,63.610000000,63.760000000,2,3,2,3,63.600000000,63.770000000,7,1,7,1,63.590000000,63.780000000,1,3,1,3,63.580000000,63.790000000,6,1,4,1,MCLQ5
2025-06-11T00:00:11.520922610Z,2025-06-11T00:00:11.520801319Z,10,1,42026514,A,A,0,64.780000000,1,130,17417,79308515,64.760000000,64.780000000,5,4,5,4,64.750000000,64.790000000,4,6,4,4,64.740000000,64.800000000,9,5,8,5,64.730000000,64.810000000,8,7,8,7,64.720000000,64.820000000,8,10,5,7,64.710000000,64.830000000,9,9,8,9,64.700000000,64.840000000,7,6,6,5,64.690000000,64.850000000,4,8,3,5,64.680000000,64.860000000,4,4,2,3,64.670000000,64.870000000,6,4,4,3,MCLN5
2025-06-11T00:00:11.521140903Z,2025-06-11T00:00:11.521018805Z,10,1,42026514,M,A,0,64.780000000,1,130,13573,79308520,64.760000000,64.780000000,5,5,5,5,64.750000000,64.790000000,4,6,4,4,64.740000000,64.800000000,9,5,8,5,64.730000000,64.810000000,8,7,8,7,64.720000000,64.820000000,8,10,5,7,64.710000000,64.830000000,9,9,8,9,64.700000000,64.840000000,7,6,6,5,64.690000000,64.850000000,4,8,3,5,64.680000000,64.860000000,4,4,2,3,64.670000000,64.870000000,6,4,4,3,MCLN5
2025-06-11T00:00:11.521270081Z,2025-06-11T00:00:11.521162683Z,10,1,42026514,A,A,0,64.770000000,2,130,11863,79308522,64.760000000,64.770000000,5,2,5,1,64.750000000,64.780000000,4,5,4,5,64.740000000,64.790000000,9,6,8,4,64.730000000,64.800000000,8,5,8,5,64.720000000,64.810000000,8,7,5,7,64.710000000,64.820000000,9,10,8,7,64.700000000,64.830000000,7,9,6,9,64.690000000,64.840000000,4,6,3,5,64.680000000,64.850000000,4,8,2,5,64.670000000,64.860000000,6,4,4,3,MCLN5
2025-06-11T00:00:11.521633565Z,2025-06-11T00:00:11.521494581Z,10,1,42026514,M,A,1,66.720000000,2,130,12540,79308531,64.760000000,64.770000000,5,2,5,1,64.750000000,64.780000000,4,4,4,4,64.740000000,64.790000000,9,6,8,4,64.730000000,64.800000000,8,5,8,5,64.720000000,64.810000000,8,7,5,7,64.710000000,64.820000000,9,10,8,7,64.700000000,64.830000000,7,9,6,9,64.690000000,64.840000000,4,6,3,5,64.680000000,64.850000000,4,8,2,5,64.670000000,64.860000000,6,4,4,3,MCLN5
2025-06-11T00:00:11.521736932Z,2025-06-11T00:00:11.521642277Z,10,1,42026514,C,A,1,64.780000000,1,130,15973,79308532,64.760000000,64.770000000,5,2,5,1,64.750000000,64.780000000,4,3,4,3,64.740000000,64.790000000,9,6,8,4,64.730000000,64.800000000,8,5,8,5,64.720000000,64.810000000,8,7,5,7,64.710000000,64.820000000,9,10,8,7,64.700000000,64.830000000,7,9,6,9,64.690000000,64.840000000,4,6,3,5,64.680000000,64.850000000,4,8,2,5,64.670000000,64.860000000,6,4,4,3,MCLN5
2025-06-11T00:00:11.525685481Z,2025-06-11T00:00:11.525568159Z,10,1,42026514,C,A,0,64.770000000,2,130,15060,79308533,64.760000000,64.780000000,5,3,5,3,64.750000000,64.790000000,4,6,4,4,64.740000000,64.800000000,9,5,8,5,64.730000000,64.810000000,8,7,8,7,64.720000000,64.820000000,8,10,5,7,64.710000000,64.830000000,9,9,8,9,64.700000000,64.840000000,7,6,6,5,64.690000000,64.850000000,4,8,3,5,64.680000000,64.860000000,4,4,2,3,64.670000000,64.870000000,6,4,4,3,MCLN5
2025-06-11T00:00:11.525797534Z,2025-06-11T00:00:11.525694183Z,10,1,42026514,A,A,0,64.780000000,1,130,17111,79308536,64.760000000,64.780000000,5,4,5,4,64.750000000,64.790000000,4,6,4,4,64.740000000,64.800000000,9,5,8,5,64.730000000,64.810000000,8,7,8,7,64.720000000,64.820000000,8,10,5,7,64.710000000,64.830000000,9,9,8,9,64.700000000,64.840000000,7,6,6,5,64.690000000,64.850000000,4,8,3,5,64.680000000,64.860000000,4,4,2,3,64.670000000,64.870000000,6,4,4,3,MCLN5
2025-06-11T00:00:12.220778150Z,2025-06-11T00:00:12.220671923Z,10,1,42025623,A,B,5,63.620000000,1,130,15341,79308613,63.670000000,63.700000000,2,3,2,3,63.660000000,63.710000000,3,2,3,2,63.650000000,63.720000000,2,2,2,2,63.640000000,63.730000000,5,2,5,2,63.630000000,63.740000000,5,7,5,7,63.620000000,63.750000000,4,2,4,2,63.610000000,63.760000000,2,3,2,3,63.600000000,63.770000000,7,1,7,1,63.590000000,63.780000000,1,3,1,3,63.580000000,63.790000000,6,1,4,1,MCLQ5
2025-06-11T00:00:12.220787150Z,2025-06-11T00:00:12.220674305Z,10,1,42025623,A,A,6,63.760000000,1,130,11555,79308614,63.670000000,63.700000000,2,3,2,3,63.660000000,63.710000000,3,2,3,2,63.650000000,63.720000000,2,2,2,2,63.640000000,63.730000000,5,2,5,2,63.630000000,63.740000000,5,7,5,7,63.620000000,63.750000000,4,2,4,2,63.610000000,63.760000000,2,4,2,4,63.600000000,63.770000000,7,1,7,1,63.590000000,63.780000000,1,3,1,3,63.580000000,63.790000000,6,1,4,1,MCLQ5
2025-06-11T00:00:12.517200493Z,2025-06-11T00:00:12.517024335Z,10,1,42026514,A,B,0,64.770000000,1,130,19943,79308649,64.770000000,64.780000000,1,4,1,4,64.760000000,64.790000000,5,6,5,4,64.750000000,64.800000000,4,5,4,5,64.740000000,64.810000000,9,7,8,7,64.730000000,64.820000000,8,10,8,7,64.720000000,64.830000000,8,9,5,9,64.710000000,64.840000000,9,6,8,5,64.700000000,64.850000000,7,8,6,5,64.690000000,64.860000000,4,4,3,3,64.680000000,64.870000000,4,4,2,3,MCLN5
2025-06-11T00:00:12.517309528Z,2025-06-11T00:00:12.517209145Z,10,1,42026514,C,A,5,64.830000000,1,130,15226,79308650,64.770000000,64.780000000,1,4,1,4,64.760000000,64.790000000,5,6,5,4,64.750000000,64.800000000,4,5,4,5,64.740000000,64.810000000,9,7,8,7,64.730000000,64.820000000,8,10,8,7,64.720000000,64.830000000,8,8,5,8,64.710000000,64.840000000,9,6,8,5,64.700000000,64.850000000,7,8,6,5,64.690000000,64.860000000,4,4,3,3,64.680000000,64.870000000,4,4,2,3,MCLN5
2025-06-11T00:00:12.517333696Z,2025-06-11T00:00:12.517215633Z,10,1,42026514,M,B,4,64.720000000,1,130,11471,79308652,64.770000000,64.780000000,1,4,1,4,64.760000000,64.790000000,5,6,5,4,64.750000000,64.800000000,4,5,4,5,64.740000000,64.810000000,9,7,8,7,64.730000000,64.820000000,7,10,7,7,64.720000000,64.830000000,9,8,6,8,64.710000000,64.840000000,9,6,8,5,64.700000000,64.850000000,7,8,6,5,64.690000000,64.860000000,4,4,3,3,64.680000000,64.870000000,4,4,2,3,MCLN5
2025-06-11T00:00:12.517344086Z,2025-06-11T00:00:12.517216209Z,10,1,42026514,M,A,3,64.810000000,1,130,11341,79308653,64.770000000,64.780000000,1,4,1,4,64.760000000,64.790000000,5,6,5,4,64.750000000,64.800000000,4,5,4,5,64.740000000,64.810000000,9,8,8,8,64.730000000,64.820000000,7,9,7,6,64.720000000,64.830000000,9,8,6,8,64.710000000,64.840000000,9,6,8,5,64.700000000,64.850000000,7,8,6,5,64.690000000,64.860000000,4,4,3,3,64.680000000,64.870000000,4,4,2,3,MCLN5
2025-06-11T00:00:12.517468596Z,2025-06-11T00:00:12.517372683Z,10,1,42025623,M,B,2,63.650000000,1,130,11549,79308657,63.670000000,63.700000000,2,3,2,3,63.660000000,63.710000000,3,2,3,2,63.650000000,63.720000000,3,2,3,2,63.640000000,63.730000000,5,2,5,2,63.630000000,63.740000000,5,7,5,7,63.620000000,63.750000000,4,2,4,2,63.610000000,63.760000000,2,4,2,4,63.600000000,63.770000000,7,1,7,1,63.590000000,63.780000000,1,3,1,3,63.580000000,63.790000000,6,1,4,1,MCLQ5
2025-06-11T00:00:12.517638468Z,2025-06-11T00:00:12.517532325Z,10,1,42026514,M,A,0,64.780000000,1,130,16608,79308659,64.770000000,64.780000000,1,5,1,5,64.760000000,64.790000000,5,6,5,4,64.750000000,64.800000000,4,5,4,5,64.740000000,64.810000000,9,8,8,8,64.730000000,64.820000000,7,9,7,6,64.720000000,64.830000000,9,8,6,8,64.710000000,64.840000000,9,6,8,5,64.700000000,64.850000000,7,8,6,5,64.690000000,64.860000000,4,4,3,3,64.680000000,64.870000000,4,4,2,3,MCLN5
2025-06-11T00:00:12.529087109Z,2025-06-11T00:00:12.528981335Z,10,1,42026514,C,B,6,64.710000000,1,130,15034,79308661,64.770000000,64.780000000,1,5,1,5,64.760000000,64.790000000,5,6,5,4,64.750000000,64.800000000,4,5,4,5,64.740000000,64.810000000,9,8,8,8,64.730000000,64.820000000,7,9,7,6,64.720000000,64.830000000,9,8,6,8,64.710000000,64.840000000,8,6,7,5,64.700000000,64.850000000,7,8,6,5,64.690000000,64.860000000,4,4,3,3,64.680000000,64.870000000,4,4,2,3,MCLN5
2025-06-11T00:00:12.529096217Z,2025-06-11T00:00:12.528984137Z,10,1,42026514,A,A,6,64.840000000,1,130,11828,79308662,64.770000000,64.780000000,1,5,1,5,64.760000000,64.790000000,5,6,5,4,64.750000000,64.800000000,4,5,4,5,64.740000000,64.810000000,9,8,8,8,64.730000000,64.820000000,7,9,7,6,64.720000000,64.830000000,9,8,6,8,64.710000000,64.840000000,8,7,7,6,64.700000000,64.850000000,7,8,6,5,64.690000000,64.860000000,4,4,3,3,64.680000000,64.870000000,4,4,2,3,MCLN5
2025-06-11T00:00:12.529210912Z,2025-06-11T00:00:12.529112791Z,10,1,42026514,A,B,5,64.720000000,1,130,14588,79308663,64.770000000,64.780000000,1,5,1,5,64.760000000,64.790000000,5,6,5,4,64.750000000,64.800000000,4,5,4,5,64.740000000,64.810000000,9,8,8,8,64.730000000,64.820000000,7,9,7,6,64.720000000,64.830000000,10,8,7,8,64.710000000,64.840000000,8,7,7,6,64.700000000,64.850000000,7,8,6,5,64.690000000,64.860000000,4,4,3,3,64.680000000,64.870000000,4,4,2,3,MCLN5
2025-06-11T00:00:12.538692862Z,2025-06-11T00:00:12.538595905Z,10,1,42418117,M,B,0,3.240000000,10,130,13773,79308672,3.250000000,3.270000000,1,1,1,1,3.240000000,3.280000000,11,1,2,1,3.230000000,3.290000000,1,11,1,2,,,0,0,0,0,,,0,0,0,0,,,0,0,0,0,,,0,0,0,0,,,0,0,0,0,,,0,0,0,0,,,0,0,0,0,MCLN5-MCLX5
2025-06-11T00:00:12.968554261Z,2025-06-11T00:00:12.968414053Z,10,1,42025623,A,A,0,63.690000000,1,130,19036,79308699,63.670000000,63.690000000,2,1,2,1,63.660000000,63.700000000,3,3,3,3,63.650000000,63.710000000,3,2,3,2,63.640000000,63.720000000,5,2,5,2,63.630000000,63.730000000,5,2,5,2,63.620000000,63.740000000,4,7,4,7,63.610000000,63.750000000,2,2,2,2,63.600000000,63.760000000,7,4,7,4,63.590000000,63.770000000,1,1,1,1,63.580000000,63.780000000,6,3,4,3,MCLQ5
2025-06-11T00:00:13.121798367Z,2025-06-11T00:00:13.121664749Z,10,1,42025623,C,A,0,63.690000000,1,130,15703,79308727,63.670000000,63.700000000,2,3,2,3,63.660000000,63.710000000,3,2,3,2,63.650000000,63.720000000,3,2,3,2,63.640000000,63.730000000,5,2,5,2,63.630000000,63.740000000,5,7,5,7,63.620000000,63.750000000,4,2,4,2,63.610000000,63.760000000,2,4,2,4,63.600000000,63.770000000,7,1,7,1,63.590000000,63.780000000,1,3,1,3,63.580000000,63.790000000,6,1,4,1,MCLQ5
2025-06-11T00:00:16.037568234Z,2025-06-11T00:00:16.037462285Z,10,1,42418117,M,A,1,3.280000000,10,130,18969,79309732,3.250000000,3.270000000,1,1,1,1,3.240000000,3.280000000,11,11,2,2,3.230000000,3.290000000,1,1,1,1,,,0,0,0,0,,,0,0,0,0,,,0,0,0,0,,,0,0,0,0,,,0,0,0,0,,,0,0,0,0,,,0,0,0,0,MCLN5-MCLX5
2025-06-11T00:00:16.496893526Z,2025-06-11T00:00:16.496721741Z,10,1,42026514,A,B,0,64.770000000,1,130,17431,79309919,64.770000000,64.780000000,2,5,2,5,64.760000000,64.790000000,5,6,5,4,64.750000000,64.800000000,4,5,4,5,64.740000000,64.810000000,9,8,8,8,64.730000000,64.820000000,7,9,7,6,64.720000000,64.830000000,10,8,7,8,64.710000000,64.840000000,8,7,7,6,64.700000000,64.850000000,7,8,6,5,64.690000000,64.860000000,4,4,3,3,64.680000000,64.870000000,4,4,2,3,MCLN5
2025-06-11T00:00:17.105677826Z,2025-06-11T00:00:17.105556405Z,10,1,42175405,M,A,0,4.110000000,10,130,16466,79309968,3.050000000,4.110000000,10,10,1,1,,,0,0,0,0,,,0,0,0,0,,,0,0,0,0,,,0,0,0,0,,,0,0,0,0,,,0,0,0,0,,,0,0,0,0,,,0,0,0,0,,,0,0,0,0,MCLN5-MCLJ6
2025-06-11T00:00:17.616518368Z,2025-06-11T00:00:17.616210375Z,10,1,42026514,T,A,0,64.770000000,2,0,14766,79309989,64.770000000,64.780000000,2,5,2,5,64.760000000,64.790000000,5,6,5,4,64.750000000,64.800000000,4,5,4,5,64.740000000,64.810000000,9,8,8,8,64.730000000,64.820000000,7,9,7,6,64.720000000,64.830000000,10,8,7,8,64.710000000,64.840000000,8,7,7,6,64.700000000,64.850000000,7,8,6,5,64.690000000,64.860000000,4,4,3,3,64.680000000,64.870000000,4,4,2,3,MCLN5
2025-06-11T00:00:17.616528329Z,2025-06-11T00:00:17.616210375Z,10,1,42026514,C,B,0,64.770000000,1,130,11602,79309990,64.760000000,64.780000000,5,5,5,5,64.750000000,64.790000000,4,6,4,4,64.740000000,64.800000000,9,5,8,5,64.730000000,64.810000000,7,8,7,8,64.720000000,64.820000000,10,9,7,6,64.710000000,64.830000000,8,8,7,8,64.700000000,64.840000000,7,7,6,6,64.690000000,64.850000000,4,8,3,5,64.680000000,64.860000000,4,4,2,3,64.670000000,64.870000000,6,4,4,3,MCLN5
