ts_recv,ts_event,rtype,publisher_id,instrument_id,action,side,depth,price,size,flags,ts_in_delta,sequence,bid_px_00,ask_px_00,bid_sz_00,ask_sz_00,bid_ct_00,ask_ct_00,bid_px_01,ask_px_01,bid_sz_01,ask_sz_01,bid_ct_01,ask_ct_01,bid_px_02,ask_px_02,bid_sz_02,ask_sz_02,bid_ct_02,ask_ct_02,bid_px_03,ask_px_03,bid_sz_03,ask_sz_03,bid_ct_03,ask_ct_03,bid_px_04,ask_px_04,bid_sz_04,ask_sz_04,bid_ct_04,ask_ct_04,bid_px_05,ask_px_05,bid_sz_05,ask_sz_05,bid_ct_05,ask_ct_05,bid_px_06,ask_px_06,bid_sz_06,ask_sz_06,bid_ct_06,ask_ct_06,bid_px_07,ask_px_07,bid_sz_07,ask_sz_07,bid_ct_07,ask_ct_07,bid_px_08,ask_px_08,bid_sz_08,ask_sz_08,bid_ct_08,ask_ct_08,bid_px_09,ask_px_09,bid_sz_09,ask_sz_09,bid_ct_09,ask_ct_09,symbol
2025-06-11T00:00:31.013888510Z,2025-06-11T00:00:31.013255579Z,10,1,42022708,M,A,0,2.830000000,10,130,14291,79331168,2.810000000,2.830000000,1,12,1,3,2.800000000,2.840000000,12,2,3,2,2.790000000,2.850000000,2,1,2,1,2.780000000,2.870000000,1,1,1,1,,,0,0,0,0,,,0,0,0,0,,,0,0,0,0,,,0,0,0,0,,,0,0,0,0,,,0,0,0,0,MCLN5-MCLV5
2025-06-11T00:00:31.014040306Z,2025-06-11T00:00:31.013552783Z,10,1,42025611,M,A,0,2.110000000,1,130,14967,79331179,2.070000000,2.080000000,3,5,2,2,2.060000000,2.090000000,27,7,5,5,2.050000000,2.100000000,23,27,3,6,2.040000000,2.110000000,23,23,3,4,2.030000000,2.120000000,2,22,1,2,2.020000000,2.130000000,2,2,2,2,2.010000000,2.140000000,2,2,1,1,2.000000000,2.150000000,2,2,2,1,1.990000000,2.160000000,2,2,1,1,1.980000000,2.170000000,2,2,2,1,MCLN5-MCLU5
2025-06-11T00:00:31.014831972Z,2025-06-11T00:00:31.014559105Z,10,1,42026514,C,B,6,64.730000000,1,130,11647,79331223,64.790000000,64.800000000,1,6,1,6,64.780000000,64.810000000,5,3,5,3,64.770000000,64.820000000,6,9,5,6,64.760000000,64.830000000,8,10,8,10,64.750000000,64.840000000,9,6,9,5,64.740000000,64.850000000,9,8,8,5,64.730000000,64.860000000,6,4,6,3,64.720000000,64.870000000,8,4,5,3,64.710000000,64.880000000,8,4,7,3,64.700000000,64.890000000,7,3,6,2,MCLN5
2025-06-11T00:00:31.014840082Z,2025-06-11T00:00:31.014561581Z,10,1,42026514,A,A,6,64.860000000,1,130,11560,79331224,64.790000000,64.800000000,1,6,1,6,64.780000000,64.810000000,5,3,5,3,64.770000000,64.820000000,6,9,5,6,64.760000000,64.830000000,8,10,8,10,64.750000000,64.840000000,9,6,9,5,64.740000000,64.850000000,9,8,8,5,64.730000000,64.860000000,6,5,6,4,64.720000000,64.870000000,8,4,5,3,64.710000000,64.880000000,8,4,7,3,64.700000000,64.890000000,7,3,6,2,MCLN5
2025-06-11T00:00:31.014866945Z,2025-06-11T00:00:31.014707573Z,10,1,42026514,A,B,5,64.740000000,1,130,11523,79331226,64.790000000,64.800000000,1,6,1,6,64.780000000,64.810000000,5,3,5,3,64.770000000,64.820000000,6,9,5,6,64.760000000,64.830000000,8,10,8,10,64.750000000,64.840000000,9,6,9,5,64.740000000,64.850000000,10,8,9,5,64.730000000,64.860000000,6,5,6,4,64.720000000,64.870000000,8,4,5,3,64.710000000,64.880000000,8,4,7,3,64.700000000,64.890000000,7,3,6,2,MCLN5
2025-06-11T00:00:31.213141687Z,2025-06-11T00:00:31.212917013Z,10,1,42022708,M,A,0,2.840000000,10,130,11430,79331264,2.810000000,2.830000000,1,2,1,2,2.800000000,2.840000000,12,12,3,3,2.790000000,2.850000000,2,1,2,1,2.780000000,2.870000000,1,1,1,1,,,0,0,0,0,,,0,0,0,0,,,0,0,0,0,,,0,0,0,0,,,0,0,0,0,,,0,0,0,0,MCLN5-MCLV5
2025-06-11T00:00:32.044952197Z,2025-06-11T00:00:32.044838287Z,10,1,42026514,M,B,4,64.740000000,1,130,11922,79331396,64.790000000,64.800000000,1,6,1,6,64.780000000,64.810000000,5,3,5,3,64.770000000,64.820000000,6,9,5,6,64.760000000,64.830000000,8,10,8,10,64.750000000,64.840000000,8,6,8,5,64.740000000,64.850000000,11,8,10,5,64.730000000,64.860000000,6,5,6,4,64.720000000,64.870000000,8,4,5,3,64.710000000,64.880000000,8,4,7,3,64.700000000,64.890000000,7,3,6,2,MCLN5
2025-06-11T00:00:32.044976794Z,2025-06-11T00:00:32.044838875Z,10,1,42026514,M,A,3,64.830000000,1,130,11936,79331398,64.790000000,64.800000000,1,6,1,6,64.780000000,64.810000000,5,3,5,3,64.770000000,64.820000000,6,9,5,6,64.760000000,64.830000000,8,11,8,11,64.750000000,64.840000000,8,5,8,4,64.740000000,64.850000000,11,8,10,5,64.730000000,64.860000000,6,5,6,4,64.720000000,64.870000000,8,4,5,3,64.710000000,64.880000000,8,4,7,3,64.700000000,64.890000000,7,3,6,2,MCLN5
2025-06-11T00:00:32.053441836Z,2025-06-11T00:00:32.045262167Z,10,1,42026514,M,A,3,64.840000000,1,130,11506,79331414,64.790000000,64.800000000,1,6,1,6,64.780000000,64.810000000,5,3,5,3,64.770000000,64.820000000,6,9,5,6,64.760000000,64.830000000,8,10,8,10,64.750000000,64.840000000,8,6,8,5,64.740000000,64.850000000,11,8,10,5,64.730000000,64.860000000,6,5,6,4,64.720000000,64.870000000,8,4,5,3,64.710000000,64.880000000,8,4,7,3,64.700000000,64.890000000,7,3,6,2,MCLN5
2025-06-11T00:00:32.053451581Z,2025-06-11T00:00:32.045262703Z,10,1,42026514,M,B,4,64.750000000,1,130,11826,79331415,64.790000000,64.800000000,1,6,1,6,64.780000000,64.810000000,5,3,5,3,64.770000000,64.820000000,6,9,5,6,64.760000000,64.830000000,8,10,8,10,64.750000000,64.840000000,9,6,9,5,64.740000000,64.850000000,10,8,9,5,64.730000000,64.860000000,6,5,6,4,64.720000000,64.870000000,8,4,5,3,64.710000000,64.880000000,8,4,7,3,64.700000000,64.890000000,7,3,6,2,MCLN5
2025-06-11T00:00:32.054642541Z,2025-06-11T00:00:32.053860063Z,10,1,42026514,M,B,4,64.740000000,1,130,12519,79331479,64.790000000,64.800000000,1,6,1,6,64.780000000,64.810000000,5,3,5,3,64.770000000,64.820000000,6,9,5,6,64.760000000,64.830000000,8,10,8,10,64.750000000,64.840000000,8,6,8,5,64.740000000,64.850000000,11,8,10,5,64.730000000,64.860000000,6,5,6,4,64.720000000,64.870000000,8,4,5,3,64.710000000,64.880000000,8,4,7,3,64.700000000,64.890000000,7,3,6,2,MCLN5
2025-06-11T00:00:32.055206500Z,2025-06-11T00:00:32.055045075Z,10,1,42026514,C,B,0,64.790000000,1,130,11390,79331519,64.780000000,64.800000000,5,6,5,6,64.770000000,64.810000000,6,3,5,3,64.760000000,64.820000000,8,9,8,6,64.750000000,64.830000000,8,10,8,10,64.740000000,64.840000000,11,6,10,5,64.730000000,64.850000000,6,8,6,5,64.720000000,64.860000000,8,5,5,4,64.710000000,64.870000000,8,4,7,3,64.700000000,64.880000000,7,4,6,3,64.690000000,64.890000000,4,3,3,2,MCLN5
2025-06-11T00:00:32.055362503Z,2025-06-11T00:00:32.055216637Z,10,1,42026514,C,B,4,64.740000000,1,130,11406,79331528,64.780000000,64.800000000,5,6,5,6,64.770000000,64.810000000,6,3,5,3,64.760000000,64.820000000,8,9,8,6,64.750000000,64.830000000,8,10,8,10,64.740000000,64.840000000,10,6,9,5,64.730000000,64.850000000,6,8,6,5,64.720000000,64.860000000,8,5,5,4,64.710000000,64.870000000,8,4,7,3,64.700000000,64.880000000,7,4,6,3,64.690000000,64.890000000,4,3,3,2,MCLN5
2025-06-11T00:00:32.055546184Z,2025-06-11T00:00:32.055237987Z,10,1,42026514,C,B,0,64.780000000,1,130,13176,79331538,64.780000000,64.800000000,4,6,4,6,64.770000000,64.810000000,6,3,5,3,64.760000000,64.820000000,8,9,8,6,64.750000000,64.830000000,8,10,8,10,64.740000000,64.840000000,10,6,9,5,64.730000000,64.850000000,6,8,6,5,64.720000000,64.860000000,8,5,5,4,64.710000000,64.870000000,8,4,7,3,64.700000000,64.880000000,7,4,6,3,64.690000000,64.890000000,4,3,3,2,MCLN5
2025-06-11T00:00:32.055746690Z,2025-06-11T00:00:32.055310367Z,10,1,42025623,A,A,0,63.710000000,1,130,17211,79331547,63.690000000,63.710000000,3,1,3,1,63.680000000,63.720000000,2,2,2,2,63.670000000,63.730000000,3,2,3,2,63.660000000,63.740000000,5,3,5,3,63.650000000,63.750000000,4,2,4,2,63.640000000,63.760000000,4,7,4,7,63.630000000,63.770000000,4,1,4,1,63.620000000,63.780000000,4,4,4,4,63.610000000,63.790000000,2,1,2,1,63.600000000,63.800000000,6,3,6,3,MCLQ5
2025-06-11T00:00:32.055924795Z,2025-06-11T00:00:32.055756863Z,10,1,42025623,C,B,5,63.640000000,1,130,11909,79331558,63.690000000,63.710000000,3,1,3,1,63.680000000,63.720000000,2,2,2,2,63.670000000,63.730000000,3,2,3,2,63.660000000,63.740000000,5,3,5,3,63.650000000,63.750000000,4,2,4,2,63.640000000,63.760000000,3,7,3,7,63.630000000,63.770000000,4,1,4,1,63.620000000,63.780000000,4,4,4,4,63.610000000,63.790000000,2,1,2,1,63.600000000,63.800000000,6,3,6,3,MCLQ5
2025-06-11T00:00:32.055924795Z,2025-06-11T00:00:32.055759185Z,10,1,42025623,M,B,3,63.650000000,1,130,11909,79331558,63.690000000,63.710000000,3,1,3,1,63.680000000,63.720000000,2,2,2,2,63.670000000,63.730000000,3,2,3,2,63.660000000,63.740000000,4,3,4,3,63.650000000,63.750000000,5,2,5,2,63.640000000,63.760000000,3,7,3,7,63.630000000,63.770000000,4,1,4,1,63.620000000,63.780000000,4,4,4,4,63.610000000,63.790000000,2,1,2,1,63.600000000,63.800000000,6,3,6,3,MCLQ5
2025-06-11T00:00:32.055936384Z,2025-06-11T00:00:32.055759781Z,10,1,42025623,M,A,4,63.750000000,1,130,15178,79331559,63.690000000,63.710000000,3,1,3,1,63.680000000,63.720000000,2,2,2,2,63.670000000,63.730000000,3,2,3,2,63.660000000,63.740000000,4,3,4,3,63.650000000,63.750000000,5,3,5,3,63.640000000,63.760000000,3,6,3,6,63.630000000,63.770000000,4,1,4,1,63.620000000,63.780000000,4,4,4,4,63.610000000,63.790000000,2,1,2,1,63.600000000,63.800000000,6,3,6,3,MCLQ5
2025-06-11T00:00:32.055944854Z,2025-06-11T00:00:32.055760529Z,10,1,42025623,M,B,3,63.650000000,1,130,11516,79331560,63.690000000,63.710000000,3,1,3,1,63.680000000,63.720000000,2,2,2,2,63.670000000,63.730000000,3,2,3,2,63.660000000,63.740000000,3,3,3,3,63.650000000,63.750000000,6,3,6,3,63.640000000,63.760000000,3,6,3,6,63.630000000,63.770000000,4,1,4,1,63.620000000,63.780000000,4,4,4,4,63.610000000,63.790000000,2,1,2,1,63.600000000,63.800000000,6,3,6,3,MCLQ5
2025-06-11T00:00:32.055953886Z,2025-06-11T00:00:32.055761049Z,10,1,42025623,M,A,4,63.750000000,1,130,11868,79331561,63.690000000,63.710000000,3,1,3,1,63.680000000,63.720000000,2,2,2,2,63.670000000,63.730000000,3,2,3,2,63.660000000,63.740000000,3,3,3,3,63.650000000,63.750000000,6,4,6,4,63.640000000,63.760000000,3,5,3,5,63.630000000,63.770000000,4,1,4,1,63.620000000,63.780000000,4,4,4,4,63.610000000,63.790000000,2,1,2,1,63.600000000,63.800000000,6,3,6,3,MCLQ5
2025-06-11T00:00:32.056796644Z,2025-06-11T00:00:32.056685737Z,10,1,42025623,C,A,0,63.710000000,1,130,19343,79331568,63.690000000,63.720000000,3,2,3,2,63.680000000,63.730000000,2,2,2,2,63.670000000,63.740000000,3,3,3,3,63.660000000,63.750000000,3,4,3,4,63.650000000,63.760000000,6,5,6,5,63.640000000,63.770000000,3,1,3,1,63.630000000,63.780000000,4,4,4,4,63.620000000,63.790000000,4,1,4,1,63.610000000,63.800000000,2,3,2,3,63.600000000,63.810000000,6,4,6,2,MCLQ5
2025-06-11T00:00:32.068573043Z,2025-06-11T00:00:32.068462343Z,10,1,42026514,A,B,5,64.730000000,1,130,15394,79331570,64.780000000,64.800000000,4,6,4,6,64.770000000,64.810000000,6,3,5,3,64.760000000,64.820000000,8,9,8,6,64.750000000,64.830000000,8,10,8,10,64.740000000,64.840000000,10,6,9,5,64.730000000,64.850000000,7,8,7,5,64.720000000,64.860000000,8,5,5,4,64.710000000,64.870000000,8,4,7,3,64.700000000,64.880000000,7,4,6,3,64.690000000,64.890000000,4,3,3,2,MCLN5
2025-06-11T00:00:32.068581913Z,2025-06-11T00:00:32.068464589Z,10,1,42026514,C,A,6,64.860000000,1,130,11246,79331571,64.780000000,64.800000000,4,6,4,6,64.770000000,64.810000000,6,3,5,3,64.760000000,64.820000000,8,9,8,6,64.750000000,64.830000000,8,10,8,10,64.740000000,64.840000000,10,6,9,5,64.730000000,64.850000000,7,8,7,5,64.720000000,64.860000000,8,4,5,3,64.710000000,64.870000000,8,4,7,3,64.700000000,64.880000000,7,4,6,3,64.690000000,64.890000000,4,3,3,2,MCLN5
2025-06-11T00:00:32.068597165Z,2025-06-11T00:00:32.068466567Z,10,1,42025623,A,B,5,63.640000000,1,130,11485,79331572,63.690000000,63.720000000,3,2,3,2,63.680000000,63.730000000,2,2,2,2,63.670000000,63.740000000,3,3,3,3,63.660000000,63.750000000,3,4,3,4,63.650000000,63.760000000,6,5,6,5,63.640000000,63.770000000,4,1,4,1,63.630000000,63.780000000,4,4,4,4,63.620000000,63.790000000,4,1,4,1,63.610000000,63.800000000,2,3,2,3,63.600000000,63.810000000,6,4,6,2,MCLQ5
2025-06-11T00:00:32.068707782Z,2025-06-11T00:00:32.068611463Z,10,1,42026514,A,A,5,64.850000000,1,130,14919,79331573,64.780000000,64.800000000,4,6,4,6,64.770000000,64.810000000,6,3,5,3,64.760000000,64.820000000,8,9,8,6,64.750000000,64.830000000,8,10,8,10,64.740000000,64.840000000,10,6,9,5,64.730000000,64.850000000,7,9,7,6,64.720000000,64.860000000,8,4,5,3,64.710000000,64.870000000,8,4,7,3,64.700000000,64.880000000,7,4,6,3,64.690000000,64.890000000,4,3,3,2,MCLN5
2025-06-11T00:00:32.332310556Z,2025-06-11T00:00:32.332203001Z,10,1,42026514,M,A,3,64.830000000,1,130,16235,79331588,64.780000000,64.800000000,4,6,4,6,64.770000000,64.810000000,6,3,5,3,64.760000000,64.820000000,8,9,8,6,64.750000000,64.830000000,8,11,8,11,64.740000000,64.840000000,10,5,9,4,64.730000000,64.850000000,7,9,7,6,64.720000000,64.860000000,8,4,5,3,64.710000000,64.870000000,8,4,7,3,64.700000000,64.880000000,7,4,6,3,64.690000000,64.890000000,4,3,3,2,MCLN5
2025-06-11T00:00:33.138112406Z,2025-06-11T00:00:33.137930183Z,10,1,42026514,A,B,0,64.780000000,1,130,16434,79331730,64.780000000,64.800000000,5,6,5,6,64.770000000,64.810000000,6,3,5,3,64.760000000,64.820000000,8,9,8,6,64.750000000,64.830000000,8,11,8,11,64.740000000,64.840000000,10,5,9,4,64.730000000,64.850000000,7,9,7,6,64.720000000,64.860000000,8,4,5,3,64.710000000,64.870000000,8,4,7,3,64.700000000,64.880000000,7,4,6,3,64.690000000,64.890000000,4,3,3,2,MCLN5
2025-06-11T00:00:33.138215327Z,2025-06-11T00:00:33.138070815Z,10,1,42026514,A,B,0,64.790000000,1,130,23737,79331731,64.790000000,64.800000000,1,6,1,6,64.780000000,64.810000000,5,3,5,3,64.770000000,64.820000000,6,9,5,6,64.760000000,64.830000000,8,11,8,11,64.750000000,64.840000000,8,5,8,4,64.740000000,64.850000000,10,9,9,6,64.730000000,64.860000000,7,4,7,3,64.720000000,64.870000000,8,4,5,3,64.710000000,64.880000000,8,4,7,3,64.700000000,64.890000000,7,3,6,2,MCLN5
2025-06-11T00:00:33.138268509Z,2025-06-11T00:00:33.138124573Z,10,1,42025623,M,A,3,63.760000000,1,130,14018,79331734,63.690000000,63.720000000,3,2,3,2,63.680000000,63.730000000,2,2,2,2,63.670000000,63.740000000,3,3,3,3,63.660000000,63.750000000,3,3,3,3,63.650000000,63.760000000,6,6,6,6,63.640000000,63.770000000,4,1,4,1,63.630000000,63.780000000,4,4,4,4,63.620000000,63.790000000,4,1,4,1,63.610000000,63.800000000,2,3,2,3,63.600000000,63.810000000,6,4,6,2,MCLQ5
2025-06-11T00:00:33.138268509Z,2025-06-11T00:00:33.138125073Z,10,1,42025623,M,B,3,63.660000000,1,130,14018,79331734,63.690000000,63.720000000,3,2,3,2,63.680000000,63.730000000,2,2,2,2,63.670000000,63.740000000,3,3,3,3,63.660000000,63.750000000,4,3,4,3,63.650000000,63.760000000,5,6,5,6,63.640000000,63.770000000,4,1,4,1,63.630000000,63.780000000,4,4,4,4,63.620000000,63.790000000,4,1,4,1,63.610000000,63.800000000,2,3,2,3,63.600000000,63.810000000,6,4,6,2,MCLQ5
2025-06-11T00:00:33.138279798Z,2025-06-11T00:00:33.138125533Z,10,1,42025623,M,A,3,63.760000000,1,130,14090,79331735,63.690000000,63.720000000,3,2,3,2,63.680000000,63.730000000,2,2,2,2,63.670000000,63.740000000,3,3,3,3,63.660000000,63.750000000,4,2,4,2,63.650000000,63.760000000,5,7,5,7,63.640000000,63.770000000,4,1,4,1,63.630000000,63.780000000,4,4,4,4,63.620000000,63.790000000,4,1,4,1,63.610000000,63.800000000,2,3,2,3,63.600000000,63.810000000,6,4,6,2,MCLQ5
2025-06-11T00:00:33.138292124Z,2025-06-11T00:00:33.138126053Z,10,1,42025623,M,B,3,63.660000000,1,130,14672,79331736,63.690000000,63.720000000,3,2,3,2,63.680000000,63.730000000,2,2,2,2,63.670000000,63.740000000,3,3,3,3,63.660000000,63.750000000,5,2,5,2,63.650000000,63.760000000,4,7,4,7,63.640000000,63.770000000,4,1,4,1,63.630000000,63.780000000,4,4,4,4,63.620000000,63.790000000,4,1,4,1,63.610000000,63.800000000,2,3,2,3,63.600000000,63.810000000,6,4,6,2,MCLQ5
2025-06-11T00:00:33.138320707Z,2025-06-11T00:00:33.138224371Z,10,1,42026514,C,A,5,64.850000000,1,130,15789,79331738,64.790000000,64.800000000,1,6,1,6,64.780000000,64.810000000,5,3,5,3,64.770000000,64.820000000,6,9,5,6,64.760000000,64.830000000,8,11,8,11,64.750000000,64.840000000,8,5,8,4,64.740000000,64.850000000,10,8,9,5,64.730000000,64.860000000,7,4,7,3,64.720000000,64.870000000,8,4,5,3,64.710000000,64.880000000,8,4,7,3,64.700000000,64.890000000,7,3,6,2,MCLN5
2025-06-11T00:00:33.138346257Z,2025-06-11T00:00:33.138227481Z,10,1,42026514,A,B,0,64.790000000,1,130,16933,79331739,64.790000000,64.800000000,2,6,2,6,64.780000000,64.810000000,5,3,5,3,64.770000000,64.820000000,6,9,5,6,64.760000000,64.830000000,8,11,8,11,64.750000000,64.840000000,8,5,8,4,64.740000000,64.850000000,10,8,9,5,64.730000000,64.860000000,7,4,7,3,64.720000000,64.870000000,8,4,5,3,64.710000000,64.880000000,8,4,7,3,64.700000000,64.890000000,7,3,6,2,MCLN5
2025-06-11T00:00:33.138357961Z,2025-06-11T00:00:33.138228229Z,10,1,42026514,M,A,3,64.840000000,1,130,12625,79331740,64.790000000,64.800000000,2,6,2,6,64.780000000,64.810000000,5,3,5,3,64.770000000,64.820000000,6,9,5,6,64.760000000,64.830000000,8,10,8,10,64.750000000,64.840000000,8,6,8,5,64.740000000,64.850000000,10,8,9,5,64.730000000,64.860000000,7,4,7,3,64.720000000,64.870000000,8,4,5,3,64.710000000,64.880000000,8,4,7,3,64.700000000,64.890000000,7,3,6,2,MCLN5
2025-06-11T00:00:33.138367944Z,2025-06-11T00:00:33.138228835Z,10,1,42026514,M,B,4,64.750000000,1,130,13505,79331741,64.790000000,64.800000000,2,6,2,6,64.780000000,64.810000000,5,3,5,3,64.770000000,64.820000000,6,9,5,6,64.760000000,64.830000000,8,10,8,10,64.750000000,64.840000000,9,6,9,5,64.740000000,64.850000000,9,8,8,5,64.730000000,64.860000000,7,4,7,3,64.720000000,64.870000000,8,4,5,3,64.710000000,64.880000000,8,4,7,3,64.700000000,64.890000000,7,3,6,2,MCLN5
2025-06-11T00:00:33.155667865Z,2025-06-11T00:00:33.155555943Z,10,1,42026514,C,B,6,64.730000000,1,130,17286,79331747,64.790000000,64.800000000,2,6,2,6,64.780000000,64.810000000,5,3,5,3,64.770000000,64.820000000,6,9,5,6,64.760000000,64.830000000,8,10,8,10,64.750000000,64.840000000,9,6,9,5,64.740000000,64.850000000,9,8,8,5,64.730000000,64.860000000,6,4,6,3,64.720000000,64.870000000,8,4,5,3,64.710000000,64.880000000,8,4,7,3,64.700000000,64.890000000,7,3,6,2,MCLN5
2025-06-11T00:00:33.155679100Z,2025-06-11T00:00:33.155558901Z,10,1,42026514,A,A,6,64.860000000,1,130,13589,79331748,64.790000000,64.800000000,2,6,2,6,64.780000000,64.810000000,5,3,5,3,64.770000000,64.820000000,6,9,5,6,64.760000000,64.830000000,8,10,8,10,64.750000000,64.840000000,9,6,9,5,64.740000000,64.850000000,9,8,8,5,64.730000000,64.860000000,6,5,6,4,64.720000000,64.870000000,8,4,5,3,64.710000000,64.880000000,8,4,7,3,64.700000000,64.890000000,7,3,6,2,MCLN5
2025-06-11T00:00:33.155797466Z,2025-06-11T00:00:33.155691431Z,10,1,42026514,A,B,5,64.740000000,1,130,17755,79331749,64.790000000,64.800000000,2,6,2,6,64.780000000,64.810000000,5,3,5,3,64.770000000,64.820000000,6,9,5,6,64.760000000,64.830000000,8,10,8,10,64.750000000,64.840000000,9,6,9,5,64.740000000,64.850000000,10,8,9,5,64.730000000,64.860000000,6,5,6,4,64.720000000,64.870000000,8,4,5,3,64.710000000,64.880000000,8,4,7,3,64.700000000,64.890000000,7,3,6,2,MCLN5
2025-06-11T00:00:33.361662099Z,2025-06-11T00:00:33.361561393Z,10,1,42022708,M,A,0,2.830000000,10,130,17935,79331851,2.810000000,2.830000000,1,12,1,3,2.800000000,2.840000000,12,2,3,2,2.790000000,2.850000000,2,1,2,1,2.780000000,2.870000000,1,1,1,1,,,0,0,0,0,,,0,0,0,0,,,0,0,0,0,,,0,0,0,0,,,0,0,0,0,,,0,0,0,0,MCLN5-MCLV5
2025-06-11T00:00:33.373917715Z,2025-06-11T00:00:33.373822355Z,10,1,42022708,M,A,0,2.840000000,10,130,18449,79331873,2.810000000,2.830000000,1,2,1,2,2.800000000,2.840000000,12,12,3,3,2.790000000,2.850000000,2,1,2,1,2.780000000,2.870000000,1,1,1,1,,,0,0,0,0,,,0,0,0,0,,,0,0,0,0,,,0,0,0,0,,,0,0,0,0,,,0,0,0,0,MCLN5-MCLV5
2025-06-11T00:00:34.077148340Z,2025-06-11T00:00:34.077027125Z,10,1,42026514,M,B,4,64.740000000,1,130,13455,79332131,64.790000000,64.800000000,2,6,2,6,64.780000000,64.810000000,5,3,5,3,64.770000000,64.820000000,6,9,5,6,64.760000000,64.830000000,8,10,8,10,64.750000000,64.840000000,8,6,8,5,64.740000000,64.850000000,11,8,10,5,64.730000000,64.860000000,6,5,6,4,64.720000000,64.870000000,8,4,5,3,64.710000000,64.880000000,8,4,7,3,64.700000000,64.890000000,7,3,6,2,MCLN5
2025-06-11T00:00:34.077162363Z,2025-06-11T00:00:34.077027681Z,10,1,42026514,M,A,3,64.830000000,1,130,13332,79332132,64.790000000,64.800000000,2,6,2,6,64.780000000,64.810000000,5,3,5,3,64.770000000,64.820000000,6,9,5,6,64.760000000,64.830000000,8,11,8,11,64.750000000,64.840000000,8,5,8,4,64.740000000,64.850000000,11,8,10,5,64.730000000,64.860000000,6,5,6,4,64.720000000,64.870000000,8,4,5,3,64.710000000,64.880000000,8,4,7,3,64.700000000,64.890000000,7,3,6,2,MCLN5
2025-06-11T00:00:34.077504712Z,2025-06-11T00:00:34.077217409Z,10,1,42026514,C,B,1,64.780000000,1,130,18229,79332146,64.790000000,64.800000000,2,6,2,6,64.780000000,64.810000000,4,3,4,3,64.770000000,64.820000000,6,9,5,6,64.760000000,64.830000000,8,11,8,11,64.750000000,64.840000000,8,5,8,4,64.740000000,64.850000000,11,8,10,5,64.730000000,64.860000000,6,5,6,4,64.720000000,64.870000000,8,4,5,3,64.710000000,64.880000000,8,4,7,3,64.700000000,64.890000000,7,3,6,2,MCLN5
2025-06-11T00:00:34.077528856Z,2025-06-11T00:00:34.077217985Z,10,1,42025623,A,A,0,63.710000000,1,130,20691,79332147,63.690000000,63.710000000,3,1,3,1,63.680000000,63.720000000,2,2,2,2,63.670000000,63.730000000,3,2,3,2,63.660000000,63.740000000,5,3,5,3,63.650000000,63.750000000,4,2,4,2,63.640000000,63.760000000,4,7,4,7,63.630000000,63.770000000,4,1,4,1,63.620000000,63.780000000,4,4,4,4,63.610000000,63.790000000,2,1,2,1,63.600000000,63.800000000,6,3,6,3,MCLQ5
2025-06-11T00:00:34.085802738Z,2025-06-11T00:00:34.085706081Z,10,1,42022708,M,A,0,2.830000000,10,130,16855,79332165,2.810000000,2.830000000,1,12,1,3,2.800000000,2.840000000,12,2,3,2,2.790000000,2.850000000,2,1,2,1,2.780000000,2.870000000,1,1,1,1,,,0,0,0,0,,,0,0,0,0,,,0,0,0,0,,,0,0,0,0,,,0,0,0,0,,,0,0,0,0,MCLN5-MCLV5
2025-06-11T00:00:34.091134083Z,2025-06-11T00:00:34.091038473Z,10,1,42022708,M,A,0,2.840000000,10,130,16777,79332168,2.810000000,2.830000000,1,2,1,2,2.800000000,2.840000000,12,12,3,3,2.790000000,2.850000000,2,1,2,1,2.780000000,2.870000000,1,1,1,1,,,0,0,0,0,,,0,0,0,0,,,0,0,0,0,,,0,0,0,0,,,0,0,0,0,,,0,0,0,0,MCLN5-MCLV5
2025-06-11T00:00:34.142113430Z,2025-06-11T00:00:34.141980387Z,10,1,42026514,C,B,0,64.790000000,1,130,19742,79332175,64.790000000,64.800000000,1,6,1,6,64.780000000,64.810000000,4,3,4,3,64.770000000,64.820000000,6,9,5,6,64.760000000,64.830000000,8,11,8,11,64.750000000,64.840000000,8,5,8,4,64.740000000,64.850000000,11,8,10,5,64.730000000,64.860000000,6,5,6,4,64.720000000,64.870000000,8,4,5,3,64.710000000,64.880000000,8,4,7,3,64.700000000,64.890000000,7,3,6,2,MCLN5
2025-06-11T00:00:34.142393796Z,2025-06-11T00:00:34.142148667Z,10,1,42026514,T,A,0,64.790000000,1,0,15886,79332176,64.790000000,64.800000000,1,6,1,6,64.780000000,64.810000000,4,3,4,3,64.770000000,64.820000000,6,9,5,6,64.760000000,64.830000000,8,11,8,11,64.750000000,64.840000000,8,5,8,4,64.740000000,64.850000000,11,8,10,5,64.730000000,64.860000000,6,5,6,4,64.720000000,64.870000000,8,4,5,3,64.710000000,64.880000000,8,4,7,3,64.700000000,64.890000000,7,3,6,2,MCLN5
2025-06-11T00:00:34.142405016Z,2025-06-11T00:00:34.142148667Z,10,1,42026514,C,B,0,64.790000000,1,130,13908,79332177,64.780000000,64.800000000,4,6,4,6,64.770000000,64.810000000,6,3,5,3,64.760000000,64.820000000,8,9,8,6,64.750000000,64.830000000,8,11,8,11,64.740000000,64.840000000,11,5,10,4,64.730000000,64.850000000,6,8,6,5,64.720000000,64.860000000,8,5,5,4,64.710000000,64.870000000,8,4,7,3,64.700000000,64.880000000,7,4,6,3,64.690000000,64.890000000,4,3,3,2,MCLN5
2025-06-11T00:00:34.142432209Z,2025-06-11T00:00:34.142154197Z,10,1,42026514,A,A,0,64.790000000,2,130,12896,79332179,64.780000000,64.790000000,4,2,4,1,64.770000000,64.800000000,6,6,5,6,64.760000000,64.810000000,8,3,8,3,64.750000000,64.820000000,8,9,8,6,64.740000000,64.830000000,11,11,10,11,64.730000000,64.840000000,6,5,6,4,64.720000000,64.850000000,8,8,5,5,64.710000000,64.860000000,8,5,7,4,64.700000000,64.870000000,7,4,6,3,64.690000000,64.880000000,4,4,3,3,MCLN5
2025-06-11T00:00:34.142469571Z,2025-06-11T00:00:34.142264149Z,10,1,42026514,M,A,1,64.800000000,1,130,16897,79332182,64.780000000,64.790000000,4,2,4,1,64.770000000,64.800000000,6,7,5,7,64.760000000,64.810000000,8,3,8,3,64.750000000,64.820000000,8,9,8,6,64.740000000,64.830000000,11,11,10,11,64.730000000,64.840000000,6,5,6,4,64.720000000,64.850000000,8,8,5,5,64.710000000,64.860000000,8,5,7,4,64.700000000,64.870000000,7,4,6,3,64.690000000,64.880000000,4,4,3,3,MCLN5
2025-06-11T00:00:34.146636971Z,2025-06-11T00:00:34.142403267Z,10,1,42026514,C,B,4,64.740000000,1,130,17780,79332184,64.780000000,64.790000000,4,2,4,1,64.770000000,64.800000000,6,7,5,7,64.760000000,64.810000000,8,3,8,3,64.750000000,64.820000000,8,9,8,6,64.740000000,64.830000000,10,11,9,11,64.730000000,64.840000000,6,5,6,4,64.720000000,64.850000000,8,8,5,5,64.710000000,64.860000000,8,5,7,4,64.700000000,64.870000000,7,4,6,3,64.690000000,64.880000000,4,4,3,3,MCLN5
2025-06-11T00:00:34.146648713Z,2025-06-11T00:00:34.142430827Z,10,1,42025623,C,B,5,63.640000000,1,130,13790,79332185,63.690000000,63.710000000,3,1,3,1,63.680000000,63.720000000,2,2,2,2,63.670000000,63.730000000,3,2,3,2,63.660000000,63.740000000,5,3,5,3,63.650000000,63.750000000,4,2,4,2,63.640000000,63.760000000,3,7,3,7,63.630000000,63.770000000,4,1,4,1,63.620000000,63.780000000,4,4,4,4,63.610000000,63.790000000,2,1,2,1,63.600000000,63.800000000,6,3,6,3,MCLQ5
2025-06-11T00:00:34.146659542Z,2025-06-11T00:00:34.142431279Z,10,1,42025623,M,B,3,63.650000000,1,130,14676,79332186,63.690000000,63.710000000,3,1,3,1,63.680000000,63.720000000,2,2,2,2,63.670000000,63.730000000,3,2,3,2,63.660000000,63.740000000,4,3,4,3,63.650000000,63.750000000,5,2,5,2,63.640000000,63.760000000,3,7,3,7,63.630000000,63.770000000,4,1,4,1,63.620000000,63.780000000,4,4,4,4,63.610000000,63.790000000,2,1,2,1,63.600000000,63.800000000,6,3,6,3,MCLQ5
2025-06-11T00:00:34.146670408Z,2025-06-11T00:00:34.142431815Z,10,1,42025623,M,A,4,63.750000000,1,130,13746,79332187,63.690000000,63.710000000,3,1,3,1,63.680000000,63.720000000,2,2,2,2,63.670000000,63.730000000,3,2,3,2,63.660000000,63.740000000,4,3,4,3,63.650000000,63.750000000,5,3,5,3,63.640000000,63.760000000,3,6,3,6,63.630000000,63.770000000,4,1,4,1,63.620000000,63.780000000,4,4,4,4,63.610000000,63.790000000,2,1,2,1,63.600000000,63.800000000,6,3,6,3,MCLQ5
2025-06-11T00:00:34.146681175Z,2025-06-11T00:00:34.142432565Z,10,1,42025623,M,B,3,63.650000000,1,130,14169,79332188,63.690000000,63.710000000,3,1,3,1,63.680000000,63.720000000,2,2,2,2,63.670000000,63.730000000,3,2,3,2,63.660000000,63.740000000,3,3,3,3,63.650000000,63.750000000,6,3,6,3,63.640000000,63.760000000,3,6,3,6,63.630000000,63.770000000,4,1,4,1,63.620000000,63.780000000,4,4,4,4,63.610000000,63.790000000,2,1,2,1,63.600000000,63.800000000,6,3,6,3,MCLQ5
2025-06-11T00:00:34.146691427Z,2025-06-11T00:00:34.142433065Z,10,1,42025623,M,A,4,63.750000000,1,130,13587,79332189,63.690000000,63.710000000,3,1,3,1,63.680000000,63.720000000,2,2,2,2,63.670000000,63.730000000,3,2,3,2,63.660000000,63.740000000,3,3,3,3,63.650000000,63.750000000,6,4,6,4,63.640000000,63.760000000,3,5,3,5,63.630000000,63.770000000,4,1,4,1,63.620000000,63.780000000,4,4,4,4,63.610000000,63.790000000,2,1,2,1,63.600000000,63.800000000,6,3,6,3,MCLQ5
2025-06-11T00:00:34.146704229Z,2025-06-11T00:00:34.142435907Z,10,1,42025623,C,A,7,63.780000000,1,130,15112,79332190,63.690000000,63.710000000,3,1,3,1,63.680000000,63.720000000,2,2,2,2,63.670000000,63.730000000,3,2,3,2,63.660000000,63.740000000,3,3,3,3,63.650000000,63.750000000,6,4,6,4,63.640000000,63.760000000,3,5,3,5,63.630000000,63.770000000,4,1,4,1,63.620000000,63.780000000,4,3,4,3,63.610000000,63.790000000,2,1,2,1,63.600000000,63.800000000,6,3,6,3,MCLQ5
2025-06-11T00:00:34.146714566Z,2025-06-11T00:00:34.142554423Z,10,1,42025623,A,B,6,63.630000000,1,130,13323,79332191,63.690000000,63.710000000,3,1,3,1,63.680000000,63.720000000,2,2,2,2,63.670000000,63.730000000,3,2,3,2,63.660000000,63.740000000,3,3,3,3,63.650000000,63.750000000,6,4,6,4,63.640000000,63.760000000,3,5,3,5,63.630000000,63.770000000,5,1,5,1,63.620000000,63.780000000,4,3,4,3,63.610000000,63.790000000,2,1,2,1,63.600000000,63.800000000,6,3,6,3,MCLQ5
2025-06-11T00:00:34.146745361Z,2025-06-11T00:00:34.142611175Z,10,1,42025623,A,A,6,63.770000000,1,130,13807,79332193,63.690000000,63.710000000,3,1,3,1,63.680000000,63.720000000,2,2,2,2,63.670000000,63.730000000,3,2,3,2,63.660000000,63.740000000,3,3,3,3,63.650000000,63.750000000,6,4,6,4,63.640000000,63.760000000,3,5,3,5,63.630000000,63.770000000,5,2,5,2,63.620000000,63.780000000,4,3,4,3,63.610000000,63.790000000,2,1,2,1,63.600000000,63.800000000,6,3,6,3,MCLQ5
2025-06-11T00:00:34.146757165Z,2025-06-11T00:00:34.142729077Z,10,1,42026514,M,A,1,66.780000000,2,130,13951,79332194,64.780000000,64.790000000,4,2,4,1,64.770000000,64.800000000,6,6,5,6,64.760000000,64.810000000,8,3,8,3,64.750000000,64.820000000,8,9,8,6,64.740000000,64.830000000,10,11,9,11,64.730000000,64.840000000,6,5,6,4,64.720000000,64.850000000,8,8,5,5,64.710000000,64.860000000,8,5,7,4,64.700000000,64.870000000,7,4,6,3,64.690000000,64.880000000,4,4,3,3,MCLN5
2025-06-11T00:00:34.153967483Z,2025-06-11T00:00:34.153836707Z,10,1,42026514,C,A,0,64.790000000,2,130,16424,79332197,64.780000000,64.800000000,4,6,4,6,64.770000000,64.810000000,6,3,5,3,64.760000000,64.820000000,8,9,8,6,64.750000000,64.830000000,8,11,8,11,64.740000000,64.840000000,10,5,9,4,64.730000000,64.850000000,6,8,6,5,64.720000000,64.860000000,8,5,5,4,64.710000000,64.870000000,8,4,7,3,64.700000000,64.880000000,7,4,6,3,64.690000000,64.890000000,4,3,3,2,MCLN5
2025-06-11T00:00:34.165298326Z,2025-06-11T00:00:34.165172019Z,10,1,42026514,A,B,5,64.730000000,1,130,16788,79332200,64.780000000,64.800000000,4,6,4,6,64.770000000,64.810000000,6,3,5,3,64.760000000,64.820000000,8,9,8,6,64.750000000,64.830000000,8,11,8,11,64.740000000,64.840000000,10,5,9,4,64.730000000,64.850000000,7,8,7,5,64.720000000,64.860000000,8,5,5,4,64.710000000,64.870000000,8,4,7,3,64.700000000,64.880000000,7,4,6,3,64.690000000,64.890000000,4,3,3,2,MCLN5
2025-06-11T00:00:34.165310667Z,2025-06-11T00:00:34.165173921Z,10,1,42026514,C,A,6,64.860000000,1,130,15324,79332201,64.780000000,64.800000000,4,6,4,6,64.770000000,64.810000000,6,3,5,3,64.760000000,64.820000000,8,9,8,6,64.750000000,64.830000000,8,11,8,11,64.740000000,64.840000000,10,5,9,4,64.730000000,64.850000000,7,8,7,5,64.720000000,64.860000000,8,4,5,3,64.710000000,64.870000000,8,4,7,3,64.700000000,64.880000000,7,4,6,3,64.690000000,64.890000000,4,3,3,2,MCLN5
2025-06-11T00:00:34.165412659Z,2025-06-11T00:00:34.165317435Z,10,1,42026514,A,A,5,64.850000000,1,130,16762,79332202,64.780000000,64.800000000,4,6,4,6,64.770000000,64.810000000,6,3,5,3,64.760000000,64.820000000,8,9,8,6,64.750000000,64.830000000,8,11,8,11,64.740000000,64.840000000,10,5,9,4,64.730000000,64.850000000,7,9,7,6,64.720000000,64.860000000,8,4,5,3,64.710000000,64.870000000,8,4,7,3,64.700000000,64.880000000,7,4,6,3,64.690000000,64.890000000,4,3,3,2,MCLN5
2025-06-11T00:00:34.191808756Z,2025-06-11T00:00:34.191712101Z,10,1,42022708,M,A,0,2.830000000,10,130,17351,79332207,2.810000000,2.830000000,1,12,1,3,2.800000000,2.840000000,12,2,3,2,2.790000000,2.850000000,2,1,2,1,2.780000000,2.870000000,1,1,1,1,,,0,0,0,0,,,0,0,0,0,,,0,0,0,0,,,0,0,0,0,,,0,0,0,0,,,0,0,0,0,MCLN5-MCLV5
2025-06-11T00:00:34.358687828Z,2025-06-11T00:00:34.358536213Z,10,1,42026514,A,A,0,64.790000000,2,130,17045,79332224,64.780000000,64.790000000,4,2,4,1,64.770000000,64.800000000,6,6,5,6,64.760000000,64.810000000,8,3,8,3,64.750000000,64.820000000,8,9,8,6,64.740000000,64.830000000,10,11,9,11,64.730000000,64.840000000,7,5,7,4,64.720000000,64.850000000,8,9,5,6,64.710000000,64.860000000,8,4,7,3,64.700000000,64.870000000,7,4,6,3,64.690000000,64.880000000,4,4,3,3,MCLN5
2025-06-11T00:00:34.358943044Z,2025-06-11T00:00:34.358702669Z,10,1,42026514,T,B,0,64.790000000,2,0,18157,79332227,64.780000000,64.790000000,4,2,4,1,64.770000000,64.800000000,6,6,5,6,64.760000000,64.810000000,8,3,8,3,64.750000000,64.820000000,8,9,8,6,64.740000000,64.830000000,10,11,9,11,64.730000000,64.840000000,7,5,7,4,64.720000000,64.850000000,8,9,5,6,64.710000000,64.860000000,8,4,7,3,64.700000000,64.870000000,7,4,6,3,64.690000000,64.880000000,4,4,3,3,MCLN5
2025-06-11T00:00:34.358955492Z,2025-06-11T00:00:34.358702669Z,10,1,42026514,C,A,0,64.790000000,2,130,15197,79332228,64.780000000,64.800000000,4,6,4,6,64.770000000,64.810000000,6,3,5,3,64.760000000,64.820000000,8,9,8,6,64.750000000,64.830000000,8,11,8,11,64.740000000,64.840000000,10,5,9,4,64.730000000,64.850000000,7,9,7,6,64.720000000,64.860000000,8,4,5,3,64.710000000,64.870000000,8,4,7,3,64.700000000,64.880000000,7,4,6,3,64.690000000,64.890000000,4,3,3,2,MCLN5
2025-06-11T00:00:34.367084037Z,2025-06-11T00:00:34.358975873Z,10,1,42026514,M,B,0,64.780000000,1,130,17928,79332234,64.780000000,64.800000000,5,6,5,6,64.770000000,64.810000000,6,3,5,3,64.760000000,64.820000000,8,9,8,6,64.750000000,64.830000000,8,11,8,11,64.740000000,64.840000000,10,5,9,4,64.730000000,64.850000000,7,9,7,6,64.720000000,64.860000000,8,4,5,3,64.710000000,64.870000000,8,4,7,3,64.700000000,64.880000000,7,4,6,3,64.690000000,64.890000000,4,3,3,2,MCLN5
2025-06-11T00:00:34.367097307Z,2025-06-11T00:00:34.359112799Z,10,1,42026514,C,B,0,64.780000000,1,130,17070,79332235,64.780000000,64.800000000,4,6,4,6,64.770000000,64.810000000,6,3,5,3,64.760000000,64.820000000,8,9,8,6,64.750000000,64.830000000,8,11,8,11,64.740000000,64.840000000,10,5,9,4,64.730000000,64.850000000,7,9,7,6,64.720000000,64.860000000,8,4,5,3,64.710000000,64.870000000,8,4,7,3,64.700000000,64.880000000,7,4,6,3,64.690000000,64.890000000,4,3,3,2,MCLN5
2025-06-11T00:00:34.367231539Z,2025-06-11T00:00:34.367019741Z,10,1,42026514,A,B,0,64.780000000,1,130,16863,79332241,64.780000000,64.800000000,5,6,5,6,64.770000000,64.810000000,6,3,5,3,64.760000000,64.820000000,8,9,8,6,64.750000000,64.830000000,8,11,8,11,64.740000000,64.840000000,10,5,9,4,64.730000000,64.850000000,7,9,7,6,64.720000000,64.860000000,8,4,5,3,64.710000000,64.870000000,8,4,7,3,64.700000000,64.880000000,7,4,6,3,64.690000000,64.890000000,4,3,3,2,MCLN5
2025-06-11T00:00:34.367274767Z,2025-06-11T00:00:34.367023657Z,10,1,42025623,C,A,0,63.710000000,1,130,22961,79332243,63.690000000,63.720000000,3,2,3,2,63.680000000,63.730000000,2,2,2,2,63.670000000,63.740000000,3,3,3,3,63.660000000,63.750000000,3,4,3,4,63.650000000,63.760000000,6,5,6,5,63.640000000,63.770000000,3,2,3,2,63.630000000,63.780000000,5,3,5,3,63.620000000,63.790000000,4,1,4,1,63.610000000,63.800000000,2,3,2,3,63.600000000,63.810000000,6,4,6,2,MCLQ5
2025-06-11T00:00:34.367539521Z,2025-06-11T00:00:34.367282519Z,10,1,42025623,C,A,5,63.770000000,1,130,15061,79332258,63.690000000,63.720000000,3,2,3,2,63.680000000,63.730000000,2,2,2,2,63.670000000,63.740000000,3,3,3,3,63.660000000,63.750000000,3,4,3,4,63.650000000,63.760000000,6,5,6,5,63.640000000,63.770000000,3,1,3,1,63.630000000,63.780000000,5,3,5,3,63.620000000,63.790000000,4,1,4,1,63.610000000,63.800000000,2,3,2,3,63.600000000,63.810000000,6,4,6,2,MCLQ5
2025-06-11T00:00:34.367539521Z,2025-06-11T00:00:34.367254547Z,10,1,42022708,M,A,0,2.840000000,10,130,15061,79332258,2.810000000,2.830000000,1,2,1,2,2.800000000,2.840000000,12,12,3,3,2.790000000,2.850000000,2,1,2,1,2.780000000,2.870000000,1,1,1,1,,,0,0,0,0,,,0,0,0,0,,,0,0,0,0,,,0,0,0,0,,,0,0,0,0,,,0,0,0,0,MCLN5-MCLV5
2025-06-11T00:00:34.367678084Z,2025-06-11T00:00:34.367533547Z,10,1,42026514,A,B,0,64.790000000,1,130,23969,79332261,64.790000000,64.800000000,1,6,1,6,64.780000000,64.810000000,5,3,5,3,64.770000000,64.820000000,6,9,5,6,64.760000000,64.830000000,8,11,8,11,64.750000000,64.840000000,8,5,8,4,64.740000000,64.850000000,10,9,9,6,64.730000000,64.860000000,7,4,7,3,64.720000000,64.870000000,8,4,5,3,64.710000000,64.880000000,8,4,7,3,64.700000000,64.890000000,7,3,6,2,MCLN5
2025-06-11T00:00:34.367781973Z,2025-06-11T00:00:34.367685259Z,10,1,42026514,C,A,5,64.850000000,1,130,16914,79332262,64.790000000,64.800000000,1,6,1,6,64.780000000,64.810000000,5,3,5,3,64.770000000,64.820000000,6,9,5,6,64.760000000,64.830000000,8,11,8,11,64.750000000,64.840000000,8,5,8,4,64.740000000,64.850000000,10,8,9,5,64.730000000,64.860000000,7,4,7,3,64.720000000,64.870000000,8,4,5,3,64.710000000,64.880000000,8,4,7,3,64.700000000,64.890000000,7,3,6,2,MCLN5
2025-06-11T00:00:34.367812285Z,2025-06-11T00:00:34.367689695Z,10,1,42026514,A,B,0,64.790000000,1,130,18349,79332263,64.790000000,64.800000000,2,6,2,6,64.780000000,64.810000000,5,3,5,3,64.770000000,64.820000000,6,9,5,6,64.760000000,64.830000000,8,11,8,11,64.750000000,64.840000000,8,5,8,4,64.740000000,64.850000000,10,8,9,5,64.730000000,64.860000000,7,4,7,3,64.720000000,64.870000000,8,4,5,3,64.710000000,64.880000000,8,4,7,3,64.700000000,64.890000000,7,3,6,2,MCLN5
2025-06-11T00:00:34.367822691Z,2025-06-11T00:00:34.367689941Z,10,1,42026514,M,A,3,64.840000000,1,130,13309,79332264,64.790000000,64.800000000,2,6,2,6,64.780000000,64.810000000,5,3,5,3,64.770000000,64.820000000,6,9,5,6,64.760000000,64.830000000,8,10,8,10,64.750000000,64.840000000,8,6,8,5,64.740000000,64.850000000,10,8,9,5,64.730000000,64.860000000,7,4,7,3,64.720000000,64.870000000,8,4,5,3,64.710000000,64.880000000,8,4,7,3,64.700000000,64.890000000,7,3,6,2,MCLN5
2025-06-11T00:00:34.367833196Z,2025-06-11T00:00:34.367690347Z,10,1,42026514,M,B,4,64.750000000,1,130,13493,79332265,64.790000000,64.800000000,2,6,2,6,64.780000000,64.810000000,5,3,5,3,64.770000000,64.820000000,6,9,5,6,64.760000000,64.830000000,8,10,8,10,64.750000000,64.840000000,9,6,9,5,64.740000000,64.850000000,9,8,8,5,64.730000000,64.860000000,7,4,7,3,64.720000000,64.870000000,8,4,5,3,64.710000000,64.880000000,8,4,7,3,64.700000000,64.890000000,7,3,6,2,MCLN5
2025-06-11T00:00:34.367966522Z,2025-06-11T00:00:34.367858455Z,10,1,42026514,M,B,1,64.780000000,1,130,18520,79332267,64.790000000,64.800000000,2,6,2,6,64.780000000,64.810000000,6,3,6,3,64.770000000,64.820000000,6,9,5,6,64.760000000,64.830000000,8,10,8,10,64.750000000,64.840000000,9,6,9,5,64.740000000,64.850000000,9,8,8,5,64.730000000,64.860000000,7,4,7,3,64.720000000,64.870000000,8,4,5,3,64.710000000,64.880000000,8,4,7,3,64.700000000,64.890000000,7,3,6,2,MCLN5
2025-06-11T00:00:34.379591516Z,2025-06-11T00:00:34.379495637Z,10,1,42026514,C,B,6,64.730000000,1,130,16841,79332272,64.790000000,64.800000000,2,6,2,6,64.780000000,64.810000000,6,3,6,3,64.770000000,64.820000000,6,9,5,6,64.760000000,64.830000000,8,10,8,10,64.750000000,64.840000000,9,6,9,5,64.740000000,64.850000000,9,8,8,5,64.730000000,64.860000000,6,4,6,3,64.720000000,64.870000000,8,4,5,3,64.710000000,64.880000000,8,4,7,3,64.700000000,64.890000000,7,3,6,2,MCLN5
2025-06-11T00:00:34.379602314Z,2025-06-11T00:00:34.379498709Z,10,1,42026514,A,A,6,64.860000000,1,130,13532,79332273,64.790000000,64.800000000,2,6,2,6,64.780000000,64.810000000,6,3,6,3,64.770000000,64.820000000,6,9,5,6,64.760000000,64.830000000,8,10,8,10,64.750000000,64.840000000,9,6,9,5,64.740000000,64.850000000,9,8,8,5,64.730000000,64.860000000,6,5,6,4,64.720000000,64.870000000,8,4,5,3,64.710000000,64.880000000,8,4,7,3,64.700000000,64.890000000,7,3,6,2,MCLN5
2025-06-11T00:00:34.379615000Z,2025-06-11T00:00:34.379501397Z,10,1,42025623,A,A,6,63.780000000,1,130,13233,79332274,63.690000000,63.720000000,3,2,3,2,63.680000000,63.730000000,2,2,2,2,63.670000000,63.740000000,3,3,3,3,63.660000000,63.750000000,3,4,3,4,63.650000000,63.760000000,6,5,6,5,63.640000000,63.770000000,3,1,3,1,63.630000000,63.780000000,5,4,5,4,63.620000000,63.790000000,4,1,4,1,63.610000000,63.800000000,2,3,2,3,63.600000000,63.810000000,6,4,6,2,MCLQ5
2025-06-11T00:00:34.379625590Z,2025-06-11T00:00:34.379503277Z,10,1,42025623,C,B,6,63.630000000,1,130,13077,79332275,63.690000000,63.720000000,3,2,3,2,63.680000000,63.730000000,2,2,2,2,63.670000000,63.740000000,3,3,3,3,63.660000000,63.750000000,3,4,3,4,63.650000000,63.760000000,6,5,6,5,63.640000000,63.770000000,3,1,3,1,63.630000000,63.780000000,4,4,4,4,63.620000000,63.790000000,4,1,4,1,63.610000000,63.800000000,2,3,2,3,63.600000000,63.810000000,6,4,6,2,MCLQ5
2025-06-11T00:00:34.379710335Z,2025-06-11T00:00:34.379614979Z,10,1,42026514,A,B,5,64.740000000,1,130,17403,79332276,64.790000000,64.800000000,2,6,2,6,64.780000000,64.810000000,6,3,6,3,64.770000000,64.820000000,6,9,5,6,64.760000000,64.830000000,8,10,8,10,64.750000000,64.840000000,9,6,9,5,64.740000000,64.850000000,10,8,9,5,64.730000000,64.860000000,6,5,6,4,64.720000000,64.870000000,8,4,5,3,64.710000000,64.880000000,8,4,7,3,64.700000000,64.890000000,7,3,6,2,MCLN5
2025-06-11T00:00:34.379743143Z,2025-06-11T00:00:34.379651897Z,10,1,42025623,A,B,5,63.640000000,1,130,13357,79332277,63.690000000,63.720000000,3,2,3,2,63.680000000,63.730000000,2,2,2,2,63.670000000,63.740000000,3,3,3,3,63.660000000,63.750000000,3,4,3,4,63.650000000,63.760000000,6,5,6,5,63.640000000,63.770000000,4,1,4,1,63.630000000,63.780000000,4,4,4,4,63.620000000,63.790000000,4,1,4,1,63.610000000,63.800000000,2,3,2,3,63.600000000,63.810000000,6,4,6,2,MCLQ5
2025-06-11T00:00:34.913009553Z,2025-06-11T00:00:34.912837453Z,10,1,42026514,A,A,0,64.800000000,1,130,18672,79332316,64.790000000,64.800000000,2,7,2,7,64.780000000,64.810000000,6,3,6,3,64.770000000,64.820000000,6,9,5,6,64.760000000,64.830000000,8,10,8,10,64.750000000,64.840000000,9,6,9,5,64.740000000,64.850000000,10,8,9,5,64.730000000,64.860000000,6,5,6,4,64.720000000,64.870000000,8,4,5,3,64.710000000,64.880000000,8,4,7,3,64.700000000,64.890000000,7,3,6,2,MCLN5
2025-06-11T00:00:35.736825356Z,2025-06-11T00:00:35.736696349Z,10,1,42025623,M,A,3,63.760000000,1,130,14087,79332592,63.690000000,63.720000000,3,2,3,2,63.680000000,63.730000000,2,2,2,2,63.670000000,63.740000000,3,3,3,3,63.660000000,63.750000000,3,3,3,3,63.650000000,63.760000000,6,6,6,6,63.640000000,63.770000000,4,1,4,1,63.630000000,63.780000000,4,4,4,4,63.620000000,63.790000000,4,1,4,1,63.610000000,63.800000000,2,3,2,3,63.600000000,63.810000000,6,4,6,2,MCLQ5
2025-06-11T00:00:35.736836269Z,2025-06-11T00:00:35.736696827Z,10,1,42025623,M,B,3,63.660000000,1,130,14122,79332593,63.690000000,63.720000000,3,2,3,2,63.680000000,63.730000000,2,2,2,2,63.670000000,63.740000000,3,3,3,3,63.660000000,63.750000000,4,3,4,3,63.650000000,63.760000000,5,6,5,6,63.640000000,63.770000000,4,1,4,1,63.630000000,63.780000000,4,4,4,4,63.620000000,63.790000000,4,1,4,1,63.610000000,63.800000000,2,3,2,3,63.600000000,63.810000000,6,4,6,2,MCLQ5
2025-06-11T00:00:35.736848679Z,2025-06-11T00:00:35.736697807Z,10,1,42025623,M,A,3,63.760000000,1,130,15808,79332594,63.690000000,63.720000000,3,2,3,2,63.680000000,63.730000000,2,2,2,2,63.670000000,63.740000000,3,3,3,3,63.660000000,63.750000000,4,2,4,2,63.650000000,63.760000000,5,7,5,7,63.640000000,63.770000000,4,1,4,1,63.630000000,63.780000000,4,4,4,4,63.620000000,63.790000000,4,1,4,1,63.610000000,63.800000000,2,3,2,3,63.600000000,63.810000000,6,4,6,2,MCLQ5
2025-06-11T00:00:35.736860029Z,2025-06-11T00:00:35.736698307Z,10,1,42025623,M,B,3,63.660000000,1,130,14380,79332595,63.690000000,63.720000000,3,2,3,2,63.680000000,63.730000000,2,2,2,2,63.670000000,63.740000000,3,3,3,3,63.660000000,63.750000000,5,2,5,2,63.650000000,63.760000000,4,7,4,7,63.640000000,63.770000000,4,1,4,1,63.630000000,63.780000000,4,4,4,4,63.620000000,63.790000000,4,1,4,1,63.610000000,63.800000000,2,3,2,3,63.600000000,63.810000000,6,4,6,2,MCLQ5
2025-06-11T00:00:35.819270976Z,2025-06-11T00:00:35.819168393Z,10,1,42026514,M,B,4,64.740000000,1,130,19574,79332617,64.790000000,64.800000000,2,7,2,7,64.780000000,64.810000000,6,3,6,3,64.770000000,64.820000000,6,9,5,6,64.760000000,64.830000000,8,10,8,10,64.750000000,64.840000000,8,6,8,5,64.740000000,64.850000000,11,8,10,5,64.730000000,64.860000000,6,5,6,4,64.720000000,64.870000000,8,4,5,3,64.710000000,64.880000000,8,4,7,3,64.700000000,64.890000000,7,3,6,2,MCLN5
2025-06-11T00:00:35.819282672Z,2025-06-11T00:00:35.819168951Z,10,1,42026514,M,A,3,64.830000000,1,130,15143,79332618,64.790000000,64.800000000,2,7,2,7,64.780000000,64.810000000,6,3,6,3,64.770000000,64.820000000,6,9,5,6,64.760000000,64.830000000,8,11,8,11,64.750000000,64.840000000,8,5,8,4,64.740000000,64.850000000,11,8,10,5,64.730000000,64.860000000,6,5,6,4,64.720000000,64.870000000,8,4,5,3,64.710000000,64.880000000,8,4,7,3,64.700000000,64.890000000,7,3,6,2,MCLN5
2025-06-11T00:00:35.827674843Z,2025-06-11T00:00:35.819514191Z,10,1,42026514,M,A,3,64.840000000,1,130,16936,79332629,64.790000000,64.800000000,2,7,2,7,64.780000000,64.810000000,6,3,6,3,64.770000000,64.820000000,6,9,5,6,64.760000000,64.830000000,8,10,8,10,64.750000000,64.840000000,8,6,8,5,64.740000000,64.850000000,11,8,10,5,64.730000000,64.860000000,6,5,6,4,64.720000000,64.870000000,8,4,5,3,64.710000000,64.880000000,8,4,7,3,64.700000000,64.890000000,7,3,6,2,MCLN5
2025-06-11T00:00:35.827688037Z,2025-06-11T00:00:35.819514767Z,10,1,42026514,M,B,4,64.750000000,1,130,15223,79332630,64.790000000,64.800000000,2,7,2,7,64.780000000,64.810000000,6,3,6,3,64.770000000,64.820000000,6,9,5,6,64.760000000,64.830000000,8,10,8,10,64.750000000,64.840000000,9,6,9,5,64.740000000,64.850000000,10,8,9,5,64.730000000,64.860000000,6,5,6,4,64.720000000,64.870000000,8,4,5,3,64.710000000,64.880000000,8,4,7,3,64.700000000,64.890000000,7,3,6,2,MCLN5
2025-06-11T00:00:35.828061887Z,2025-06-11T00:00:35.820806581Z,10,1,42026514,T,A,0,64.790000000,2,0,14104,79332652,64.790000000,64.800000000,2,7,2,7,64.780000000,64.810000000,6,3,6,3,64.770000000,64.820000000,6,9,5,6,64.760000000,64.830000000,8,10,8,10,64.750000000,64.840000000,9,6,9,5,64.740000000,64.850000000,10,8,9,5,64.730000000,64.860000000,6,5,6,4,64.720000000,64.870000000,8,4,5,3,64.710000000,64.880000000,8,4,7,3,64.700000000,64.890000000,7,3,6,2,MCLN5
2025-06-11T00:00:35.828082660Z,2025-06-11T00:00:35.820806581Z,10,1,42026514,C,B,0,64.790000000,1,130,15013,79332653,64.780000000,64.800000000,6,7,6,7,64.770000000,64.810000000,6,3,5,3,64.760000000,64.820000000,8,9,8,6,64.750000000,64.830000000,9,10,9,10,64.740000000,64.840000000,10,6,9,5,64.730000000,64.850000000,6,8,6,5,64.720000000,64.860000000,8,5,5,4,64.710000000,64.870000000,8,4,7,3,64.700000000,64.880000000,7,4,6,3,64.690000000,64.890000000,4,3,3,2,MCLN5
2025-06-11T00:00:35.828113233Z,2025-06-11T00:00:35.820812167Z,10,1,42026514,A,A,0,64.790000000,2,130,16513,79332655,64.780000000,64.790000000,6,2,6,1,64.770000000,64.800000000,6,7,5,7,64.760000000,64.810000000,8,3,8,3,64.750000000,64.820000000,9,9,9,6,64.740000000,64.830000000,10,10,9,10,64.730000000,64.840000000,6,6,6,5,64.720000000,64.850000000,8,8,5,5,64.710000000,64.860000000,8,5,7,4,64.700000000,64.870000000,7,4,6,3,64.690000000,64.880000000,4,4,3,3,MCLN5
2025-06-11T00:00:35.828509792Z,2025-06-11T00:00:35.827875037Z,10,1,42022708,M,A,0,2.830000000,10,130,11508,79332676,2.810000000,2.830000000,1,12,1,3,2.800000000,2.840000000,12,2,3,2,2.790000000,2.850000000,2,1,2,1,2.780000000,2.870000000,1,1,1,1,,,0,0,0,0,,,0,0,0,0,,,0,0,0,0,,,0,0,0,0,,,0,0,0,0,,,0,0,0,0,MCLN5-MCLV5
2025-06-11T00:00:35.828535357Z,2025-06-11T00:00:35.828071003Z,10,1,42026514,C,B,4,64.740000000,1,130,11384,79332678,64.780000000,64.790000000,6,2,6,1,64.770000000,64.800000000,6,7,5,7,64.760000000,64.810000000,8,3,8,3,64.750000000,64.820000000,9,9,9,6,64.740000000,64.830000000,9,10,8,10,64.730000000,64.840000000,6,6,6,5,64.720000000,64.850000000,8,8,5,5,64.710000000,64.860000000,8,5,7,4,64.700000000,64.870000000,7,4,6,3,64.690000000,64.880000000,4,4,3,3,MCLN5
2025-06-11T00:00:35.828547022Z,2025-06-11T00:00:35.828144343Z,10,1,42025623,C,B,5,63.640000000,1,130,11377,79332679,63.690000000,63.720000000,3,2,3,2,63.680000000,63.730000000,2,2,2,2,63.670000000,63.740000000,3,3,3,3,63.660000000,63.750000000,5,2,5,2,63.650000000,63.760000000,4,7,4,7,63.640000000,63.770000000,3,1,3,1,63.630000000,63.780000000,4,4,4,4,63.620000000,63.790000000,4,1,4,1,63.610000000,63.800000000,2,3,2,3,63.600000000,63.810000000,6,4,6,2,MCLQ5
2025-06-11T00:00:35.828560884Z,2025-06-11T00:00:35.828149757Z,10,1,42025623,C,A,6,63.780000000,1,130,14290,79332680,63.690000000,63.720000000,3,2,3,2,63.680000000,63.730000000,2,2,2,2,63.670000000,63.740000000,3,3,3,3,63.660000000,63.750000000,5,2,5,2,63.650000000,63.760000000,4,7,4,7,63.640000000,63.770000000,3,1,3,1,63.630000000,63.780000000,4,3,4,3,63.620000000,63.790000000,4,1,4,1,63.610000000,63.800000000,2,3,2,3,63.600000000,63.810000000,6,4,6,2,MCLQ5
2025-06-11T00:00:35.828585128Z,2025-06-11T00:00:35.828236423Z,10,1,42026514,M,B,0,62.840000000,2,130,17193,79332681,64.780000000,64.790000000,5,2,5,1,64.770000000,64.800000000,6,7,5,7,64.760000000,64.810000000,8,3,8,3,64.750000000,64.820000000,9,9,9,6,64.740000000,64.830000000,9,10,8,10,64.730000000,64.840000000,6,6,6,5,64.720000000,64.850000000,8,8,5,5,64.710000000,64.860000000,8,5,7,4,64.700000000,64.870000000,7,4,6,3,64.690000000,64.880000000,4,4,3,3,MCLN5
2025-06-11T00:00:35.828595795Z,2025-06-11T00:00:35.828249305Z,10,1,42026514,T,B,0,64.790000000,1,0,12013,79332682,64.780000000,64.790000000,5,2,5,1,64.770000000,64.800000000,6,7,5,7,64.760000000,64.810000000,8,3,8,3,64.750000000,64.820000000,9,9,9,6,64.740000000,64.830000000,9,10,8,10,64.730000000,64.840000000,6,6,6,5,64.720000000,64.850000000,8,8,5,5,64.710000000,64.860000000,8,5,7,4,64.700000000,64.870000000,7,4,6,3,64.690000000,64.880000000,4,4,3,3,MCLN5
2025-06-11T00:00:35.828595795Z,2025-06-11T00:00:35.828249305Z,10,1,42026514,M,A,0,64.790000000,1,130,12013,79332682,64.780000000,64.790000000,5,1,5,1,64.770000000,64.800000000,6,7,5,7,64.760000000,64.810000000,8,3,8,3,64.750000000,64.820000000,9,9,9,6,64.740000000,64.830000000,9,10,8,10,64.730000000,64.840000000,6,6,6,5,64.720000000,64.850000000,8,8,5,5,64.710000000,64.860000000,8,5,7,4,64.700000000,64.870000000,7,4,6,3,64.690000000,64.880000000,4,4,3,3,MCLN5
2025-06-11T00:00:35.828618166Z,2025-06-11T00:00:35.828260459Z,10,1,42025623,A,B,6,63.630000000,1,130,11361,79332684,63.690000000,63.720000000,3,2,3,2,63.680000000,63.730000000,2,2,2,2,63.670000000,63.740000000,3,3,3,3,63.660000000,63.750000000,5,2,5,2,63.650000000,63.760000000,4,7,4,7,63.640000000,63.770000000,3,1,3,1,63.630000000,63.780000000,5,3,5,3,63.620000000,63.790000000,4,1,4,1,63.610000000,63.800000000,2,3,2,3,63.600000000,63.810000000,6,4,6,2,MCLQ5
2025-06-11T00:00:35.828628495Z,2025-06-11T00:00:35.828277029Z,10,1,42025623,A,A,5,63.770000000,1,130,11377,79332685,63.690000000,63.720000000,3,2,3,2,63.680000000,63.730000000,2,2,2,2,63.670000000,63.740000000,3,3,3,3,63.660000000,63.750000000,5,2,5,2,63.650000000,63.760000000,4,7,4,7,63.640000000,63.770000000,3,2,3,2,63.630000000,63.780000000,5,3,5,3,63.620000000,63.790000000,4,1,4,1,63.610000000,63.800000000,2,3,2,3,63.600000000,63.810000000,6,4,6,2,MCLQ5
2025-06-11T00:00:35.828666048Z,2025-06-11T00:00:35.828482557Z,10,1,42026514,C,A,0,64.790000000,1,130,11800,79332687,64.780000000,64.800000000,5,7,5,7,64.770000000,64.810000000,6,3,5,3,64.760000000,64.820000000,8,9,8,6,64.750000000,64.830000000,9,10,9,10,64.740000000,64.840000000,9,6,8,5,64.730000000,64.850000000,6,8,6,5,64.720000000,64.860000000,8,5,5,4,64.710000000,64.870000000,8,4,7,3,64.700000000,64.880000000,7,4,6,3,64.690000000,64.890000000,4,3,3,2,MCLN5
2025-06-11T00:00:35.828790121Z,2025-06-11T00:00:35.828691671Z,10,1,42025623,C,A,5,63.770000000,1,130,14834,79332690,63.690000000,63.720000000,3,2,3,2,63.680000000,63.730000000,2,2,2,2,63.670000000,63.740000000,3,3,3,3,63.660000000,63.750000000,5,2,5,2,63.650000000,63.760000000,4,7,4,7,63.640000000,63.770000000,3,1,3,1,63.630000000,63.780000000,5,3,5,3,63.620000000,63.790000000,4,1,4,1,63.610000000,63.800000000,2,3,2,3,63.600000000,63.810000000,6,4,6,2,MCLQ5
2025-06-11T00:00:35.828798929Z,2025-06-11T00:00:35.828696223Z,10,1,42025623,C,B,6,63.630000000,1,130,11969,79332691,63.690000000,63.720000000,3,2,3,2,63.680000000,63.730000000,2,2,2,2,63.670000000,63.740000000,3,3,3,3,63.660000000,63.750000000,5,2,5,2,63.650000000,63.760000000,4,7,4,7,63.640000000,63.770000000,3,1,3,1,63.630000000,63.780000000,4,3,4,3,63.620000000,63.790000000,4,1,4,1,63.610000000,63.800000000,2,3,2,3,63.600000000,63.810000000,6,4,6,2,MCLQ5
2025-06-11T00:00:35.828909930Z,2025-06-11T00:00:35.828814873Z,10,1,42025623,A,A,6,63.780000000,1,130,14863,79332692,63.690000000,63.720000000,3,2,3,2,63.680000000,63.730000000,2,2,2,2,63.670000000,63.740000000,3,3,3,3,63.660000000,63.750000000,5,2,5,2,63.650000000,63.760000000,4,7,4,7,63.640000000,63.770000000,3,1,3,1,63.630000000,63.780000000,4,4,4,4,63.620000000,63.790000000,4,1,4,1,63.610000000,63.800000000,2,3,2,3,63.600000000,63.810000000,6,4,6,2,MCLQ5
2025-06-11T00:00:35.828917955Z,2025-06-11T00:00:35.828819807Z,10,1,42025623,A,B,5,63.640000000,1,130,11370,79332693,63.690000000,63.720000000,3,2,3,2,63.680000000,63.730000000,2,2,2,2,63.670000000,63.740000000,3,3,3,3,63.660000000,63.750000000,5,2,5,2,63.650000000,63.760000000,4,7,4,7,63.640000000,63.770000000,4,1,4,1,63.630000000,63.780000000,4,4,4,4,63.620000000,63.790000000,4,1,4,1,63.610000000,63.800000000,2,3,2,3,63.600000000,63.810000000,6,4,6,2,MCLQ5
2025-06-11T00:00:35.831763883Z,2025-06-11T00:00:35.831672455Z,10,1,42022708,M,A,0,2.840000000,10,130,14926,79332696,2.810000000,2.830000000,1,2,1,2,2.800000000,2.840000000,12,12,3,3,2.790000000,2.850000000,2,1,2,1,2.780000000,2.870000000,1,1,1,1,,,0,0,0,0,,,0,0,0,0,,,0,0,0,0,,,0,0,0,0,,,0,0,0,0,,,0,0,0,0,MCLN5-MCLV5
2025-06-11T00:00:35.855235925Z,2025-06-11T00:00:35.855136237Z,10,1,42026514,A,B,5,64.730000000,1,130,14762,79332702,64.780000000,64.800000000,5,7,5,7,64.770000000,64.810000000,6,3,5,3,64.760000000,64.820000000,8,9,8,6,64.750000000,64.830000000,9,10,9,10,64.740000000,64.840000000,9,6,8,5,64.730000000,64.850000000,7,8,7,5,64.720000000,64.860000000,8,5,5,4,64.710000000,64.870000000,8,4,7,3,64.700000000,64.880000000,7,4,6,3,64.690000000,64.890000000,4,3,3,2,MCLN5
2025-06-11T00:00:35.855244372Z,2025-06-11T00:00:35.855137697Z,10,1,42026514,C,A,6,64.860000000,1,130,11543,79332703,64.780000000,64.800000000,5,7,5,7,64.770000000,64.810000000,6,3,5,3,64.760000000,64.820000000,8,9,8,6,64.750000000,64.830000000,9,10,9,10,64.740000000,64.840000000,9,6,8,5,64.730000000,64.850000000,7,8,7,5,64.720000000,64.860000000,8,4,5,3,64.710000000,64.870000000,8,4,7,3,64.700000000,64.880000000,7,4,6,3,64.690000000,64.890000000,4,3,3,2,MCLN5
2025-06-11T00:00:35.855364296Z,2025-06-11T00:00:35.855269671Z,10,1,42026514,A,A,5,64.850000000,1,130,14683,79332704,64.780000000,64.800000000,5,7,5,7,64.770000000,64.810000000,6,3,5,3,64.760000000,64.820000000,8,9,8,6,64.750000000,64.830000000,9,10,9,10,64.740000000,64.840000000,9,6,8,5,64.730000000,64.850000000,7,9,7,6,64.720000000,64.860000000,8,4,5,3,64.710000000,64.870000000,8,4,7,3,64.700000000,64.880000000,7,4,6,3,64.690000000,64.890000000,4,3,3,2,MCLN5
2025-06-11T00:00:36.316244259Z,2025-06-11T00:00:36.316141239Z,10,1,42026514,M,B,3,64.740000000,1,130,16835,79332798,64.780000000,64.800000000,5,7,5,7,64.770000000,64.810000000,6,3,5,3,64.760000000,64.820000000,8,9,8,6,64.750000000,64.830000000,8,10,8,10,64.740000000,64.840000000,10,6,9,5,64.730000000,64.850000000,7,9,7,6,64.720000000,64.860000000,8,4,5,3,64.710000000,64.870000000,8,4,7,3,64.700000000,64.880000000,7,4,6,3,64.690000000,64.890000000,4,3,3,2,MCLN5
2025-06-11T00:00:36.316254396Z,2025-06-11T00:00:36.316141835Z,10,1,42026514,M,A,3,64.830000000,1,130,13259,79332799,64.780000000,64.800000000,5,7,5,7,64.770000000,64.810000000,6,3,5,3,64.760000000,64.820000000,8,9,8,6,64.750000000,64.830000000,8,11,8,11,64.740000000,64.840000000,10,5,9,4,64.730000000,64.850000000,7,9,7,6,64.720000000,64.860000000,8,4,5,3,64.710000000,64.870000000,8,4,7,3,64.700000000,64.880000000,7,4,6,3,64.690000000,64.890000000,4,3,3,2,MCLN5
2025-06-11T00:00:36.318760493Z,2025-06-11T00:00:36.318544973Z,10,1,42026514,A,B,0,64.790000000,2,130,14721,79332805,64.790000000,64.800000000,2,7,1,7,64.780000000,64.810000000,5,3,5,3,64.770000000,64.820000000,6,9,5,6,64.760000000,64.830000000,8,11,8,11,64.750000000,64.840000000,8,5,8,4,64.740000000,64.850000000,10,9,9,6,64.730000000,64.860000000,7,4,7,3,64.720000000,64.870000000,8,4,5,3,64.710000000,64.880000000,8,4,7,3,64.700000000,64.890000000,7,3,6,2,MCLN5
2025-06-11T00:00:36.318867309Z,2025-06-11T00:00:36.318770103Z,10,1,42026514,C,A,5,64.850000000,1,130,14103,79332811,64.790000000,64.800000000,2,7,1,7,64.780000000,64.810000000,5,3,5,3,64.770000000,64.820000000,6,9,5,6,64.760000000,64.830000000,8,11,8,11,64.750000000,64.840000000,8,5,8,4,64.740000000,64.850000000,10,8,9,5,64.730000000,64.860000000,7,4,7,3,64.720000000,64.870000000,8,4,5,3,64.710000000,64.880000000,8,4,7,3,64.700000000,64.890000000,7,3,6,2,MCLN5
2025-06-11T00:00:36.319096183Z,2025-06-11T00:00:36.318996979Z,10,1,42026514,M,A,3,64.840000000,1,130,16217,79332818,64.790000000,64.800000000,2,7,1,7,64.780000000,64.810000000,5,3,5,3,64.770000000,64.820000000,6,9,5,6,64.760000000,64.830000000,8,10,8,10,64.750000000,64.840000000,8,6,8,5,64.740000000,64.850000000,10,8,9,5,64.730000000,64.860000000,7,4,7,3,64.720000000,64.870000000,8,4,5,3,64.710000000,64.880000000,8,4,7,3,64.700000000,64.890000000,7,3,6,2,MCLN5
2025-06-11T00:00:36.319104669Z,2025-06-11T00:00:36.318997517Z,10,1,42026514,M,B,4,64.750000000,1,130,11637,79332819,64.790000000,64.800000000,2,7,1,7,64.780000000,64.810000000,5,3,5,3,64.770000000,64.820000000,6,9,5,6,64.760000000,64.830000000,8,10,8,10,64.750000000,64.840000000,9,6,9,5,64.740000000,64.850000000,9,8,8,5,64.730000000,64.860000000,7,4,7,3,64.720000000,64.870000000,8,4,5,3,64.710000000,64.880000000,8,4,7,3,64.700000000,64.890000000,7,3,6,2,MCLN5
2025-06-11T00:00:36.319997377Z,2025-06-11T00:00:36.319800157Z,10,1,42026514,C,A,0,64.800000000,1,130,13898,79332860,64.790000000,64.800000000,2,6,1,6,64.780000000,64.810000000,5,3,5,3,64.770000000,64.820000000,6,9,5,6,64.760000000,64.830000000,8,10,8,10,64.750000000,64.840000000,9,6,9,5,64.740000000,64.850000000,9,8,8,5,64.730000000,64.860000000,7,4,7,3,64.720000000,64.870000000,8,4,5,3,64.710000000,64.880000000,8,4,7,3,64.700000000,64.890000000,7,3,6,2,MCLN5
2025-06-11T00:00:36.320015931Z,2025-06-11T00:00:36.319806493Z,10,1,42026514,A,B,0,64.790000000,1,130,12910,79332861,64.790000000,64.800000000,3,6,2,6,64.780000000,64.810000000,5,3,5,3,64.770000000,64.820000000,6,9,5,6,64.760000000,64.830000000,8,10,8,10,64.750000000,64.840000000,9,6,9,5,64.740000000,64.850000000,9,8,8,5,64.730000000,64.860000000,7,4,7,3,64.720000000,64.870000000,8,4,5,3,64.710000000,64.880000000,8,4,7,3,64.700000000,64.890000000,7,3,6,2,MCLN5
2025-06-11T00:00:36.320104822Z,2025-06-11T00:00:36.320005683Z,10,1,42026514,C,B,0,64.790000000,1,130,13545,79332864,64.790000000,64.800000000,2,6,1,6,64.780000000,64.810000000,5,3,5,3,64.770000000,64.820000000,6,9,5,6,64.760000000,64.830000000,8,10,8,10,64.750000000,64.840000000,9,6,9,5,64.740000000,64.850000000,9,8,8,5,64.730000000,64.860000000,7,4,7,3,64.720000000,64.870000000,8,4,5,3,64.710000000,64.880000000,8,4,7,3,64.700000000,64.890000000,7,3,6,2,MCLN5
2025-06-11T00:00:36.320279410Z,2025-06-11T00:00:36.320173215Z,10,1,42026514,M,B,1,64.780000000,1,130,16478,79332865,64.790000000,64.800000000,2,6,1,6,64.780000000,64.810000000,6,3,6,3,64.770000000,64.820000000,6,9,5,6,64.760000000,64.830000000,8,10,8,10,64.750000000,64.840000000,9,6,9,5,64.740000000,64.850000000,9,8,8,5,64.730000000,64.860000000,7,4,7,3,64.720000000,64.870000000,8,4,5,3,64.710000000,64.880000000,8,4,7,3,64.700000000,64.890000000,7,3,6,2,MCLN5
2025-06-11T00:00:36.331936658Z,2025-06-11T00:00:36.331827023Z,10,1,42026514,C,B,6,64.730000000,1,130,18071,79332912,64.790000000,64.800000000,2,6,1,6,64.780000000,64.810000000,6,3,6,3,64.770000000,64.820000000,6,9,5,6,64.760000000,64.830000000,8,10,8,10,64.750000000,64.840000000,9,6,9,5,64.740000000,64.850000000,9,8,8,5,64.730000000,64.860000000,6,4,6,3,64.720000000,64.870000000,8,4,5,3,64.710000000,64.880000000,8,4,7,3,64.700000000,64.890000000,7,3,6,2,MCLN5
2025-06-11T00:00:36.331945781Z,2025-06-11T00:00:36.331829559Z,10,1,42026514,A,A,6,64.860000000,1,130,11992,79332913,64.790000000,64.800000000,2,6,1,6,64.780000000,64.810000000,6,3,6,3,64.770000000,64.820000000,6,9,5,6,64.760000000,64.830000000,8,10,8,10,64.750000000,64.840000000,9,6,9,5,64.740000000,64.850000000,9,8,8,5,64.730000000,64.860000000,6,5,6,4,64.720000000,64.870000000,8,4,5,3,64.710000000,64.880000000,8,4,7,3,64.700000000,64.890000000,7,3,6,2,MCLN5
2025-06-11T00:00:36.332051260Z,2025-06-11T00:00:36.331956849Z,10,1,42026514,A,B,5,64.740000000,1,130,15259,79332914,64.790000000,64.800000000,2,6,1,6,64.780000000,64.810000000,6,3,6,3,64.770000000,64.820000000,6,9,5,6,64.760000000,64.830000000,8,10,8,10,64.750000000,64.840000000,9,6,9,5,64.740000000,64.850000000,10,8,9,5,64.730000000,64.860000000,6,5,6,4,64.720000000,64.870000000,8,4,5,3,64.710000000,64.880000000,8,4,7,3,64.700000000,64.890000000,7,3,6,2,MCLN5
2025-06-11T00:00:36.433147809Z,2025-06-11T00:00:36.432730101Z,10,1,42026514,C,B,0,64.790000000,2,130,11256,79332964,64.780000000,64.800000000,6,6,6,6,64.770000000,64.810000000,6,3,5,3,64.760000000,64.820000000,8,9,8,6,64.750000000,64.830000000,9,10,9,10,64.740000000,64.840000000,10,6,9,5,64.730000000,64.850000000,6,8,6,5,64.720000000,64.860000000,8,5,5,4,64.710000000,64.870000000,8,4,7,3,64.700000000,64.880000000,7,4,6,3,64.690000000,64.890000000,4,3,3,2,MCLN5
2025-06-11T00:00:36.433258818Z,2025-06-11T00:00:36.432795225Z,10,1,42022708,M,A,0,2.830000000,10,130,11514,79332970,2.810000000,2.830000000,1,12,1,3,2.800000000,2.840000000,12,2,3,2,2.790000000,2.850000000,2,1,2,1,2.780000000,2.870000000,1,1,1,1,,,0,0,0,0,,,0,0,0,0,,,0,0,0,0,,,0,0,0,0,,,0,0,0,0,,,0,0,0,0,MCLN5-MCLV5
2025-06-11T00:00:36.433317283Z,2025-06-11T00:00:36.433156225Z,10,1,42026514,C,B,4,64.740000000,1,130,11253,79332974,64.780000000,64.800000000,6,6,6,6,64.770000000,64.810000000,6,3,5,3,64.760000000,64.820000000,8,9,8,6,64.750000000,64.830000000,9,10,9,10,64.740000000,64.840000000,9,6,8,5,64.730000000,64.850000000,6,8,6,5,64.720000000,64.860000000,8,5,5,4,64.710000000,64.870000000,8,4,7,3,64.700000000,64.880000000,7,4,6,3,64.690000000,64.890000000,4,3,3,2,MCLN5
2025-06-11T00:00:36.433525884Z,2025-06-11T00:00:36.433333779Z,10,1,42026514,M,B,0,62.840000000,2,130,11575,79332983,64.780000000,64.800000000,5,6,5,6,64.770000000,64.810000000,6,3,5,3,64.760000000,64.820000000,8,9,8,6,64.750000000,64.830000000,9,10,9,10,64.740000000,64.840000000,9,6,8,5,64.730000000,64.850000000,6,8,6,5,64.720000000,64.860000000,8,5,5,4,64.710000000,64.870000000,8,4,7,3,64.700000000,64.880000000,7,4,6,3,64.690000000,64.890000000,4,3,3,2,MCLN5
2025-06-11T00:00:36.443316737Z,2025-06-11T00:00:36.443208537Z,10,1,42026514,A,B,5,64.730000000,1,130,15516,79332992,64.780000000,64.800000000,5,6,5,6,64.770000000,64.810000000,6,3,5,3,64.760000000,64.820000000,8,9,8,6,64.750000000,64.830000000,9,10,9,10,64.740000000,64.840000000,9,6,8,5,64.730000000,64.850000000,7,8,7,5,64.720000000,64.860000000,8,5,5,4,64.710000000,64.870000000,8,4,7,3,64.700000000,64.880000000,7,4,6,3,64.690000000,64.890000000,4,3,3,2,MCLN5
2025-06-11T00:00:36.443324862Z,2025-06-11T00:00:36.443209997Z,10,1,42026514,C,A,6,64.860000000,1,130,11757,79332993,64.780000000,64.800000000,5,6,5,6,64.770000000,64.810000000,6,3,5,3,64.760000000,64.820000000,8,9,8,6,64.750000000,64.830000000,9,10,9,10,64.740000000,64.840000000,9,6,8,5,64.730000000,64.850000000,7,8,7,5,64.720000000,64.860000000,8,4,5,3,64.710000000,64.870000000,8,4,7,3,64.700000000,64.880000000,7,4,6,3,64.690000000,64.890000000,4,3,3,2,MCLN5
2025-06-11T00:00:36.443446069Z,2025-06-11T00:00:36.443350975Z,10,1,42026514,A,A,5,64.850000000,1,130,14446,79332994,64.780000000,64.800000000,5,6,5,6,64.770000000,64.810000000,6,3,5,3,64.760000000,64.820000000,8,9,8,6,64.750000000,64.830000000,9,10,9,10,64.740000000,64.840000000,9,6,8,5,64.730000000,64.850000000,7,9,7,6,64.720000000,64.860000000,8,4,5,3,64.710000000,64.870000000,8,4,7,3,64.700000000,64.880000000,7,4,6,3,64.690000000,64.890000000,4,3,3,2,MCLN5
2025-06-11T00:00:36.759401612Z,2025-06-11T00:00:36.759237103Z,10,1,42026514,C,B,0,64.780000000,1,130,11350,79333026,64.780000000,64.800000000,4,6,4,6,64.770000000,64.810000000,6,3,5,3,64.760000000,64.820000000,8,9,8,6,64.750000000,64.830000000,9,10,9,10,64.740000000,64.840000000,9,6,8,5,64.730000000,64.850000000,7,9,7,6,64.720000000,64.860000000,8,4,5,3,64.710000000,64.870000000,8,4,7,3,64.700000000,64.880000000,7,4,6,3,64.690000000,64.890000000,4,3,3,2,MCLN5
2025-06-11T00:00:36.759477179Z,2025-06-11T00:00:36.759380155Z,10,1,42026514,M,B,3,64.740000000,1,130,15378,79333028,64.780000000,64.800000000,4,6,4,6,64.770000000,64.810000000,6,3,5,3,64.760000000,64.820000000,8,9,8,6,64.750000000,64.830000000,8,10,8,10,64.740000000,64.840000000,10,6,9,5,64.730000000,64.850000000,7,9,7,6,64.720000000,64.860000000,8,4,5,3,64.710000000,64.870000000,8,4,7,3,64.700000000,64.880000000,7,4,6,3,64.690000000,64.890000000,4,3,3,2,MCLN5
2025-06-11T00:00:36.759485926Z,2025-06-11T00:00:36.759380731Z,10,1,42026514,M,A,3,64.830000000,1,130,11993,79333029,64.780000000,64.800000000,4,6,4,6,64.770000000,64.810000000,6,3,5,3,64.760000000,64.820000000,8,9,8,6,64.750000000,64.830000000,8,11,8,11,64.740000000,64.840000000,10,5,9,4,64.730000000,64.850000000,7,9,7,6,64.720000000,64.860000000,8,4,5,3,64.710000000,64.870000000,8,4,7,3,64.700000000,64.880000000,7,4,6,3,64.690000000,64.890000000,4,3,3,2,MCLN5
2025-06-11T00:00:36.759592834Z,2025-06-11T00:00:36.759394459Z,10,1,42025623,A,A,0,63.710000000,1,130,11469,79333033,63.690000000,63.710000000,3,1,3,1,63.680000000,63.720000000,2,2,2,2,63.670000000,63.730000000,3,2,3,2,63.660000000,63.740000000,5,3,5,3,63.650000000,63.750000000,4,2,4,2,63.640000000,63.760000000,4,7,4,7,63.630000000,63.770000000,4,1,4,1,63.620000000,63.780000000,4,4,4,4,63.610000000,63.790000000,2,1,2,1,63.600000000,63.800000000,6,3,6,3,MCLQ5
2025-06-11T00:00:36.760121851Z,2025-06-11T00:00:36.759478781Z,10,1,42026514,A,A,0,64.790000000,2,130,11504,79333057,64.780000000,64.790000000,4,2,4,1,64.770000000,64.800000000,6,6,5,6,64.760000000,64.810000000,8,3,8,3,64.750000000,64.820000000,8,9,8,6,64.740000000,64.830000000,10,11,9,11,64.730000000,64.840000000,7,5,7,4,64.720000000,64.850000000,8,9,5,6,64.710000000,64.860000000,8,4,7,3,64.700000000,64.870000000,7,4,6,3,64.690000000,64.880000000,4,4,3,3,MCLN5
2025-06-11T00:00:36.760264384Z,2025-06-11T00:00:36.759601561Z,10,1,42025623,M,B,3,63.650000000,1,130,15082,79333064,63.690000000,63.710000000,3,1,3,1,63.680000000,63.720000000,2,2,2,2,63.670000000,63.730000000,3,2,3,2,63.660000000,63.740000000,4,3,4,3,63.650000000,63.750000000,5,2,5,2,63.640000000,63.760000000,4,7,4,7,63.630000000,63.770000000,4,1,4,1,63.620000000,63.780000000,4,4,4,4,63.610000000,63.790000000,2,1,2,1,63.600000000,63.800000000,6,3,6,3,MCLQ5
2025-06-11T00:00:36.760278423Z,2025-06-11T00:00:36.759602039Z,10,1,42025623,M,A,4,63.750000000,1,130,11217,79333066,63.690000000,63.710000000,3,1,3,1,63.680000000,63.720000000,2,2,2,2,63.670000000,63.730000000,3,2,3,2,63.660000000,63.740000000,4,3,4,3,63.650000000,63.750000000,5,3,5,3,63.640000000,63.760000000,4,6,4,6,63.630000000,63.770000000,4,1,4,1,63.620000000,63.780000000,4,4,4,4,63.610000000,63.790000000,2,1,2,1,63.600000000,63.800000000,6,3,6,3,MCLQ5
2025-06-11T00:00:36.760290026Z,2025-06-11T00:00:36.759602501Z,10,1,42025623,M,B,3,63.650000000,1,130,13209,79333067,63.690000000,63.710000000,3,1,3,1,63.680000000,63.720000000,2,2,2,2,63.670000000,63.730000000,3,2,3,2,63.660000000,63.740000000,3,3,3,3,63.650000000,63.750000000,6,3,6,3,63.640000000,63.760000000,4,6,4,6,63.630000000,63.770000000,4,1,4,1,63.620000000,63.780000000,4,4,4,4,63.610000000,63.790000000,2,1,2,1,63.600000000,63.800000000,6,3,6,3,MCLQ5
2025-06-11T00:00:36.760299357Z,2025-06-11T00:00:36.759602771Z,10,1,42025623,C,B,5,63.640000000,1,130,11636,79333068,63.690000000,63.710000000,3,1,3,1,63.680000000,63.720000000,2,2,2,2,63.670000000,63.730000000,3,2,3,2,63.660000000,63.740000000,3,3,3,3,63.650000000,63.750000000,6,3,6,3,63.640000000,63.760000000,3,6,3,6,63.630000000,63.770000000,4,1,4,1,63.620000000,63.780000000,4,4,4,4,63.610000000,63.790000000,2,1,2,1,63.600000000,63.800000000,6,3,6,3,MCLQ5
2025-06-11T00:00:36.760308373Z,2025-06-11T00:00:36.759602981Z,10,1,42025623,M,A,4,63.750000000,1,130,11526,79333069,63.690000000,63.710000000,3,1,3,1,63.680000000,63.720000000,2,2,2,2,63.670000000,63.730000000,3,2,3,2,63.660000000,63.740000000,3,3,3,3,63.650000000,63.750000000,6,4,6,4,63.640000000,63.760000000,3,5,3,5,63.630000000,63.770000000,4,1,4,1,63.620000000,63.780000000,4,4,4,4,63.610000000,63.790000000,2,1,2,1,63.600000000,63.800000000,6,3,6,3,MCLQ5
2025-06-11T00:00:36.760723662Z,2025-06-11T00:00:36.759946993Z,10,1,42026514,C,B,0,64.780000000,1,130,12589,79333085,64.780000000,64.790000000,3,2,3,1,64.770000000,64.800000000,6,6,5,6,64.760000000,64.810000000,8,3,8,3,64.750000000,64.820000000,8,9,8,6,64.740000000,64.830000000,10,11,9,11,64.730000000,64.840000000,7,5,7,4,64.720000000,64.850000000,8,9,5,6,64.710000000,64.860000000,8,4,7,3,64.700000000,64.870000000,7,4,6,3,64.690000000,64.880000000,4,4,3,3,MCLN5
2025-06-11T00:00:36.766205533Z,2025-06-11T00:00:36.765980307Z,10,1,42026514,A,A,0,64.790000000,2,130,17085,79333320,64.780000000,64.790000000,3,4,3,2,64.770000000,64.800000000,6,6,5,6,64.760000000,64.810000000,8,3,8,3,64.750000000,64.820000000,8,9,8,6,64.740000000,64.830000000,10,11,9,11,64.730000000,64.840000000,7,5,7,4,64.720000000,64.850000000,8,9,5,6,64.710000000,64.860000000,8,4,7,3,64.700000000,64.870000000,7,4,6,3,64.690000000,64.880000000,4,4,3,3,MCLN5
2025-06-11T00:00:36.766359916Z,2025-06-11T00:00:36.765982977Z,10,1,42026514,C,B,0,64.780000000,1,130,12847,79333327,64.780000000,64.790000000,2,4,2,2,64.770000000,64.800000000,6,6,5,6,64.760000000,64.810000000,8,3,8,3,64.750000000,64.820000000,8,9,8,6,64.740000000,64.830000000,10,11,9,11,64.730000000,64.840000000,7,5,7,4,64.720000000,64.850000000,8,9,5,6,64.710000000,64.860000000,8,4,7,3,64.700000000,64.870000000,7,4,6,3,64.690000000,64.880000000,4,4,3,3,MCLN5
2025-06-11T00:00:36.766473597Z,2025-06-11T00:00:36.766216647Z,10,1,42026514,M,B,3,64.740000000,1,130,11775,79333333,64.780000000,64.790000000,2,4,2,2,64.770000000,64.800000000,6,6,5,6,64.760000000,64.810000000,8,3,8,3,64.750000000,64.820000000,7,9,7,6,64.740000000,64.830000000,11,11,10,11,64.730000000,64.840000000,7,5,7,4,64.720000000,64.850000000,8,9,5,6,64.710000000,64.860000000,8,4,7,3,64.700000000,64.870000000,7,4,6,3,64.690000000,64.880000000,4,4,3,3,MCLN5
2025-06-11T00:00:36.766473597Z,2025-06-11T00:00:36.766217165Z,10,1,42026514,M,A,3,64.820000000,1,130,11775,79333333,64.780000000,64.790000000,2,4,2,2,64.770000000,64.800000000,6,6,5,6,64.760000000,64.810000000,8,3,8,3,64.750000000,64.820000000,7,10,7,7,64.740000000,64.830000000,11,10,10,10,64.730000000,64.840000000,7,5,7,4,64.720000000,64.850000000,8,9,5,6,64.710000000,64.860000000,8,4,7,3,64.700000000,64.870000000,7,4,6,3,64.690000000,64.880000000,4,4,3,3,MCLN5
2025-06-11T00:00:36.766484256Z,2025-06-11T00:00:36.766217607Z,10,1,42026514,M,B,3,64.740000000,1,130,11059,79333334,64.780000000,64.790000000,2,4,2,2,64.770000000,64.800000000,6,6,5,6,64.760000000,64.810000000,8,3,8,3,64.750000000,64.820000000,6,10,6,7,64.740000000,64.830000000,12,10,11,10,64.730000000,64.840000000,7,5,7,4,64.720000000,64.850000000,8,9,5,6,64.710000000,64.860000000,8,4,7,3,64.700000000,64.870000000,7,4,6,3,64.690000000,64.880000000,4,4,3,3,MCLN5
2025-06-11T00:00:36.766491721Z,2025-06-11T00:00:36.766218049Z,10,1,42026514,M,A,3,64.820000000,1,130,11456,79333335,64.780000000,64.790000000,2,4,2,2,64.770000000,64.800000000,6,6,5,6,64.760000000,64.810000000,8,3,8,3,64.750000000,64.820000000,6,11,6,8,64.740000000,64.830000000,12,9,11,9,64.730000000,64.840000000,7,5,7,4,64.720000000,64.850000000,8,9,5,6,64.710000000,64.860000000,8,4,7,3,64.700000000,64.870000000,7,4,6,3,64.690000000,64.880000000,4,4,3,3,MCLN5
2025-06-11T00:00:36.766519713Z,2025-06-11T00:00:36.766278469Z,10,1,42026514,C,B,0,64.780000000,1,130,17184,79333337,64.780000000,64.790000000,1,4,1,2,64.770000000,64.800000000,6,6,5,6,64.760000000,64.810000000,8,3,8,3,64.750000000,64.820000000,6,11,6,8,64.740000000,64.830000000,12,9,11,9,64.730000000,64.840000000,7,5,7,4,64.720000000,64.850000000,8,9,5,6,64.710000000,64.860000000,8,4,7,3,64.700000000,64.870000000,7,4,6,3,64.690000000,64.880000000,4,4,3,3,MCLN5
2025-06-11T00:00:36.766943381Z,2025-06-11T00:00:36.766557527Z,10,1,42026514,A,B,0,64.780000000,1,130,13016,79333369,64.780000000,64.790000000,2,4,2,2,64.770000000,64.800000000,6,6,5,6,64.760000000,64.810000000,8,3,8,3,64.750000000,64.820000000,6,11,6,8,64.740000000,64.830000000,12,9,11,9,64.730000000,64.840000000,7,5,7,4,64.720000000,64.850000000,8,9,5,6,64.710000000,64.860000000,8,4,7,3,64.700000000,64.870000000,7,4,6,3,64.690000000,64.880000000,4,4,3,3,MCLN5
2025-06-11T00:00:36.769840186Z,2025-06-11T00:00:36.769729419Z,10,1,42025623,A,B,6,63.630000000,1,130,15725,79333454,63.690000000,63.710000000,3,1,3,1,63.680000000,63.720000000,2,2,2,2,63.670000000,63.730000000,3,2,3,2,63.660000000,63.740000000,3,3,3,3,63.650000000,63.750000000,6,4,6,4,63.640000000,63.760000000,3,5,3,5,63.630000000,63.770000000,5,1,5,1,63.620000000,63.780000000,4,4,4,4,63.610000000,63.790000000,2,1,2,1,63.600000000,63.800000000,6,3,6,3,MCLQ5
2025-06-11T00:00:36.769849224Z,2025-06-11T00:00:36.769732415Z,10,1,42025623,C,A,7,63.780000000,1,130,11747,79333455,63.690000000,63.710000000,3,1,3,1,63.680000000,63.720000000,2,2,2,2,63.670000000,63.730000000,3,2,3,2,63.660000000,63.740000000,3,3,3,3,63.650000000,63.750000000,6,4,6,4,63.640000000,63.760000000,3,5,3,5,63.630000000,63.770000000,5,1,5,1,63.620000000,63.780000000,4,3,4,3,63.610000000,63.790000000,2,1,2,1,63.600000000,63.800000000,6,3,6,3,MCLQ5
2025-06-11T00:00:36.769966731Z,2025-06-11T00:00:36.769868287Z,10,1,42025623,A,A,6,63.770000000,1,130,14810,79333456,63.690000000,63.710000000,3,1,3,1,63.680000000,63.720000000,2,2,2,2,63.670000000,63.730000000,3,2,3,2,63.660000000,63.740000000,3,3,3,3,63.650000000,63.750000000,6,4,6,4,63.640000000,63.760000000,3,5,3,5,63.630000000,63.770000000,5,2,5,2,63.620000000,63.780000000,4,3,4,3,63.610000000,63.790000000,2,1,2,1,63.600000000,63.800000000,6,3,6,3,MCLQ5
2025-06-11T00:00:36.770533523Z,2025-06-11T00:00:36.770425869Z,10,1,42026514,M,A,5,64.840000000,1,130,15096,79333457,64.780000000,64.790000000,2,4,2,2,64.770000000,64.800000000,6,6,5,6,64.760000000,64.810000000,8,3,8,3,64.750000000,64.820000000,6,11,6,8,64.740000000,64.830000000,12,9,11,9,64.730000000,64.840000000,7,6,7,5,64.720000000,64.850000000,8,9,5,6,64.710000000,64.860000000,8,4,7,3,64.700000000,64.870000000,7,4,6,3,64.690000000,64.880000000,4,4,3,3,MCLN5
2025-06-11T00:00:36.775972849Z,2025-06-11T00:00:36.775837265Z,10,1,42026514,C,A,0,64.790000000,2,130,15791,79333460,64.780000000,64.790000000,2,2,2,1,64.770000000,64.800000000,6,6,5,6,64.760000000,64.810000000,8,3,8,3,64.750000000,64.820000000,6,11,6,8,64.740000000,64.830000000,12,9,11,9,64.730000000,64.840000000,7,6,7,5,64.720000000,64.850000000,8,9,5,6,64.710000000,64.860000000,8,4,7,3,64.700000000,64.870000000,7,4,6,3,64.690000000,64.880000000,4,4,3,3,MCLN5
2025-06-11T00:00:36.776100937Z,2025-06-11T00:00:36.775985847Z,10,1,42026514,A,A,0,64.790000000,1,130,16733,79333462,64.780000000,64.790000000,2,3,2,2,64.770000000,64.800000000,6,6,5,6,64.760000000,64.810000000,8,3,8,3,64.750000000,64.820000000,6,11,6,8,64.740000000,64.830000000,12,9,11,9,64.730000000,64.840000000,7,6,7,5,64.720000000,64.850000000,8,9,5,6,64.710000000,64.860000000,8,4,7,3,64.700000000,64.870000000,7,4,6,3,64.690000000,64.880000000,4,4,3,3,MCLN5
2025-06-11T00:00:36.811775174Z,2025-06-11T00:00:36.803471947Z,10,1,42026514,C,B,0,64.780000000,1,130,14155,79333491,64.780000000,64.790000000,1,3,1,2,64.770000000,64.800000000,6,6,5,6,64.760000000,64.810000000,8,3,8,3,64.750000000,64.820000000,6,11,6,8,64.740000000,64.830000000,12,9,11,9,64.730000000,64.840000000,7,6,7,5,64.720000000,64.850000000,8,9,5,6,64.710000000,64.860000000,8,4,7,3,64.700000000,64.870000000,7,4,6,3,64.690000000,64.880000000,4,4,3,3,MCLN5
2025-06-11T00:00:36.811785887Z,2025-06-11T00:00:36.803473827Z,10,1,42026514,C,B,0,64.780000000,1,130,11874,79333492,64.770000000,64.790000000,6,3,5,2,64.760000000,64.800000000,8,6,8,6,64.750000000,64.810000000,6,3,6,3,64.740000000,64.820000000,12,11,11,8,64.730000000,64.830000000,7,9,7,9,64.720000000,64.840000000,8,6,5,5,64.710000000,64.850000000,8,9,7,6,64.700000000,64.860000000,7,4,6,3,64.690000000,64.870000000,4,4,3,3,64.680000000,64.880000000,4,4,2,3,MCLN5
2025-06-11T00:00:36.812627855Z,2025-06-11T00:00:36.804053183Z,10,1,42026514,A,A,0,64.790000000,1,130,13212,79333537,64.770000000,64.790000000,6,4,5,3,64.760000000,64.800000000,8,6,8,6,64.750000000,64.810000000,6,3,6,3,64.740000000,64.820000000,12,11,11,8,64.730000000,64.830000000,7,9,7,9,64.720000000,64.840000000,8,6,5,5,64.710000000,64.850000000,8,9,7,6,64.700000000,64.860000000,7,4,6,3,64.690000000,64.870000000,4,4,3,3,64.680000000,64.880000000,4,4,2,3,MCLN5
2025-06-11T00:00:36.813031456Z,2025-06-11T00:00:36.804128847Z,10,1,42026514,A,A,0,64.790000000,1,130,13924,79333553,64.770000000,64.790000000,6,5,5,4,64.760000000,64.800000000,8,6,8,6,64.750000000,64.810000000,6,3,6,3,64.740000000,64.820000000,12,11,11,8,64.730000000,64.830000000,7,9,7,9,64.720000000,64.840000000,8,6,5,5,64.710000000,64.850000000,8,9,7,6,64.700000000,64.860000000,7,4,6,3,64.690000000,64.870000000,4,4,3,3,64.680000000,64.880000000,4,4,2,3,MCLN5
2025-06-11T00:00:36.814007863Z,2025-06-11T00:00:36.805135035Z,10,1,42026514,A,A,0,64.790000000,1,130,13804,79333606,64.770000000,64.790000000,6,6,5,5,64.760000000,64.800000000,8,6,8,6,64.750000000,64.810000000,6,3,6,3,64.740000000,64.820000000,12,11,11,8,64.730000000,64.830000000,7,9,7,9,64.720000000,64.840000000,8,6,5,5,64.710000000,64.850000000,8,9,7,6,64.700000000,64.860000000,7,4,6,3,64.690000000,64.870000000,4,4,3,3,64.680000000,64.880000000,4,4,2,3,MCLN5
2025-06-11T00:00:36.814374387Z,2025-06-11T00:00:36.805379691Z,10,1,42026514,A,A,0,64.780000000,1,130,15100,79333622,64.770000000,64.780000000,6,1,5,1,64.760000000,64.790000000,8,6,8,5,64.750000000,64.800000000,6,6,6,6,64.740000000,64.810000000,12,3,11,3,64.730000000,64.820000000,7,11,7,8,64.720000000,64.830000000,8,9,5,9,64.710000000,64.840000000,8,6,7,5,64.700000000,64.850000000,7,9,6,6,64.690000000,64.860000000,4,4,3,3,64.680000000,64.870000000,4,4,2,3,MCLN5
2025-06-11T00:00:36.814671749Z,2025-06-11T00:00:36.805412867Z,10,1,42026514,C,B,4,64.730000000,1,130,11545,79333639,64.770000000,64.780000000,6,1,5,1,64.760000000,64.790000000,8,6,8,5,64.750000000,64.800000000,6,6,6,6,64.740000000,64.810000000,12,3,11,3,64.730000000,64.820000000,6,11,6,8,64.720000000,64.830000000,8,9,5,9,64.710000000,64.840000000,8,6,7,5,64.700000000,64.850000000,7,9,6,6,64.690000000,64.860000000,4,4,3,3,64.680000000,64.870000000,4,4,2,3,MCLN5
2025-06-11T00:00:36.814780430Z,2025-06-11T00:00:36.805458887Z,10,1,42026514,C,B,1,64.760000000,1,130,16031,79333642,64.770000000,64.780000000,6,1,5,1,64.760000000,64.790000000,7,6,7,5,64.750000000,64.800000000,6,6,6,6,64.740000000,64.810000000,12,3,11,3,64.730000000,64.820000000,6,11,6,8,64.720000000,64.830000000,8,9,5,9,64.710000000,64.840000000,8,6,7,5,64.700000000,64.850000000,7,9,6,6,64.690000000,64.860000000,4,4,3,3,64.680000000,64.870000000,4,4,2,3,MCLN5
2025-06-11T00:00:36.814978863Z,2025-06-11T00:00:36.805469061Z,10,1,42026514,A,A,0,64.780000000,1,130,15864,79333652,64.770000000,64.780000000,6,2,5,2,64.760000000,64.790000000,7,6,7,5,64.750000000,64.800000000,6,6,6,6,64.740000000,64.810000000,12,3,11,3,64.730000000,64.820000000,6,11,6,8,64.720000000,64.830000000,8,9,5,9,64.710000000,64.840000000,8,6,7,5,64.700000000,64.850000000,7,9,6,6,64.690000000,64.860000000,4,4,3,3,64.680000000,64.870000000,4,4,2,3,MCLN5
2025-06-11T00:00:36.815358281Z,2025-06-11T00:00:36.805661311Z,10,1,42025623,C,B,0,63.690000000,1,130,13277,79333675,63.690000000,63.710000000,2,1,2,1,63.680000000,63.720000000,2,2,2,2,63.670000000,63.730000000,3,2,3,2,63.660000000,63.740000000,3,3,3,3,63.650000000,63.750000000,6,4,6,4,63.640000000,63.760000000,3,5,3,5,63.630000000,63.770000000,5,2,5,2,63.620000000,63.780000000,4,3,4,3,63.610000000,63.790000000,2,1,2,1,63.600000000,63.800000000,6,3,6,3,MCLQ5
2025-06-11T00:00:36.815431721Z,2025-06-11T00:00:36.805665201Z,10,1,42026514,C,B,0,64.770000000,2,130,14847,79333681,64.770000000,64.780000000,4,2,4,2,64.760000000,64.790000000,7,6,7,5,64.750000000,64.800000000,6,6,6,6,64.740000000,64.810000000,12,3,11,3,64.730000000,64.820000000,6,11,6,8,64.720000000,64.830000000,8,9,5,9,64.710000000,64.840000000,8,6,7,5,64.700000000,64.850000000,7,9,6,6,64.690000000,64.860000000,4,4,3,3,64.680000000,64.870000000,4,4,2,3,MCLN5
2025-06-11T00:00:36.815779967Z,2025-06-11T00:00:36.805774809Z,10,1,42025623,A,A,0,63.710000000,1,130,11936,79333706,63.690000000,63.710000000,2,2,2,2,63.680000000,63.720000000,2,2,2,2,63.670000000,63.730000000,3,2,3,2,63.660000000,63.740000000,3,3,3,3,63.650000000,63.750000000,6,4,6,4,63.640000000,63.760000000,3,5,3,5,63.630000000,63.770000000,5,2,5,2,63.620000000,63.780000000,4,3,4,3,63.610000000,63.790000000,2,1,2,1,63.600000000,63.800000000,6,3,6,3,MCLQ5
2025-06-11T00:00:36.816026306Z,2025-06-11T00:00:36.805792759Z,10,1,42025623,A,A,0,63.700000000,1,130,16162,79333723,63.690000000,63.700000000,2,1,2,1,63.680000000,63.710000000,2,2,2,2,63.670000000,63.720000000,3,2,3,2,63.660000000,63.730000000,3,2,3,2,63.650000000,63.740000000,6,3,6,3,63.640000000,63.750000000,3,4,3,4,63.630000000,63.760000000,5,5,5,5,63.620000000,63.770000000,4,2,4,2,63.610000000,63.780000000,2,3,2,3,63.600000000,63.790000000,6,1,6,1,MCLQ5
2025-06-11T00:00:36.816040636Z,2025-06-11T00:00:36.805796907Z,10,1,42025623,C,B,0,63.690000000,1,130,12905,79333724,63.690000000,63.700000000,1,1,1,1,63.680000000,63.710000000,2,2,2,2,63.670000000,63.720000000,3,2,3,2,63.660000000,63.730000000,3,2,3,2,63.650000000,63.740000000,6,3,6,3,63.640000000,63.750000000,3,4,3,4,63.630000000,63.760000000,5,5,5,5,63.620000000,63.770000000,4,2,4,2,63.610000000,63.780000000,2,3,2,3,63.600000000,63.790000000,6,1,6,1,MCLQ5
2025-06-11T00:00:36.816950199Z,2025-06-11T00:00:36.806789023Z,10,1,42026514,C,B,0,64.770000000,1,130,13107,79333793,64.770000000,64.780000000,3,2,3,2,64.760000000,64.790000000,7,6,7,5,64.750000000,64.800000000,6,6,6,6,64.740000000,64.810000000,12,3,11,3,64.730000000,64.820000000,6,11,6,8,64.720000000,64.830000000,8,9,5,9,64.710000000,64.840000000,8,6,7,5,64.700000000,64.850000000,7,9,6,6,64.690000000,64.860000000,4,4,3,3,64.680000000,64.870000000,4,4,2,3,MCLN5
2025-06-11T00:00:36.816972025Z,2025-06-11T00:00:36.806789291Z,10,1,42026514,A,A,0,64.780000000,1,130,13693,79333794,64.770000000,64.780000000,3,3,3,3,64.760000000,64.790000000,7,6,7,5,64.750000000,64.800000000,6,6,6,6,64.740000000,64.810000000,12,3,11,3,64.730000000,64.820000000,6,11,6,8,64.720000000,64.830000000,8,9,5,9,64.710000000,64.840000000,8,6,7,5,64.700000000,64.850000000,7,9,6,6,64.690000000,64.860000000,4,4,3,3,64.680000000,64.870000000,4,4,2,3,MCLN5
2025-06-11T00:00:36.817382253Z,2025-06-11T00:00:36.807746407Z,10,1,42025623,C,A,0,63.700000000,1,130,16335,79333824,63.690000000,63.710000000,1,2,1,2,63.680000000,63.720000000,2,2,2,2,63.670000000,63.730000000,3,2,3,2,63.660000000,63.740000000,3,3,3,3,63.650000000,63.750000000,6,4,6,4,63.640000000,63.760000000,3,5,3,5,63.630000000,63.770000000,5,2,5,2,63.620000000,63.780000000,4,3,4,3,63.610000000,63.790000000,2,1,2,1,63.600000000,63.800000000,6,3,6,3,MCLQ5
2025-06-11T00:00:36.817674470Z,2025-06-11T00:00:36.811760509Z,10,1,42418117,M,A,0,3.280000000,10,130,11748,79333842,3.250000000,3.280000000,1,11,1,2,3.240000000,3.290000000,11,1,2,1,3.230000000,3.300000000,1,1,1,1,,,0,0,0,0,,,0,0,0,0,,,0,0,0,0,,,0,0,0,0,,,0,0,0,0,,,0,0,0,0,,,0,0,0,0,MCLN5-MCLX5
2025-06-11T00:00:36.817694860Z,2025-06-11T00:00:36.811785583Z,10,1,42026514,C,A,1,64.790000000,1,130,12483,79333843,64.770000000,64.780000000,3,3,3,3,64.760000000,64.790000000,7,5,7,4,64.750000000,64.800000000,6,6,6,6,64.740000000,64.810000000,12,3,11,3,64.730000000,64.820000000,6,11,6,8,64.720000000,64.830000000,8,9,5,9,64.710000000,64.840000000,8,6,7,5,64.700000000,64.850000000,7,9,6,6,64.690000000,64.860000000,4,4,3,3,64.680000000,64.870000000,4,4,2,3,MCLN5
2025-06-11T00:00:36.817718198Z,2025-06-11T00:00:36.811786907Z,10,1,42026514,A,A,0,64.780000000,1,130,16631,79333844,64.770000000,64.780000000,3,4,3,4,64.760000000,64.790000000,7,5,7,4,64.750000000,64.800000000,6,6,6,6,64.740000000,64.810000000,12,3,11,3,64.730000000,64.820000000,6,11,6,8,64.720000000,64.830000000,8,9,5,9,64.710000000,64.840000000,8,6,7,5,64.700000000,64.850000000,7,9,6,6,64.690000000,64.860000000,4,4,3,3,64.680000000,64.870000000,4,4,2,3,MCLN5
2025-06-11T00:00:36.817728650Z,2025-06-11T00:00:36.811811347Z,10,1,42025623,M,B,4,63.640000000,1,130,11943,79333845,63.690000000,63.710000000,1,2,1,2,63.680000000,63.720000000,2,2,2,2,63.670000000,63.730000000,3,2,3,2,63.660000000,63.740000000,3,3,3,3,63.650000000,63.750000000,5,4,5,4,63.640000000,63.760000000,4,5,4,5,63.630000000,63.770000000,5,2,5,2,63.620000000,63.780000000,4,3,4,3,63.610000000,63.790000000,2,1,2,1,63.600000000,63.800000000,6,3,6,3,MCLQ5
2025-06-11T00:00:36.817739232Z,2025-06-11T00:00:36.811811827Z,10,1,42025623,M,A,4,63.750000000,1,130,11496,79333846,63.690000000,63.710000000,1,2,1,2,63.680000000,63.720000000,2,2,2,2,63.670000000,63.730000000,3,2,3,2,63.660000000,63.740000000,3,3,3,3,63.650000000,63.750000000,5,5,5,5,63.640000000,63.760000000,4,4,4,4,63.630000000,63.770000000,5,2,5,2,63.620000000,63.780000000,4,3,4,3,63.610000000,63.790000000,2,1,2,1,63.600000000,63.800000000,6,3,6,3,MCLQ5
2025-06-11T00:00:36.817752910Z,2025-06-11T00:00:36.811933685Z,10,1,42026514,M,A,1,64.790000000,1,130,11988,79333847,64.770000000,64.780000000,3,4,3,4,64.760000000,64.790000000,7,6,7,5,64.750000000,64.800000000,6,6,6,6,64.740000000,64.810000000,12,3,11,3,64.730000000,64.820000000,6,11,6,8,64.720000000,64.830000000,8,9,5,9,64.710000000,64.840000000,8,6,7,5,64.700000000,64.850000000,7,9,6,6,64.690000000,64.860000000,4,4,3,3,64.680000000,64.870000000,4,4,2,3,MCLN5
2025-06-11T00:00:36.817763999Z,2025-06-11T00:00:36.811950925Z,10,1,42026514,M,A,2,64.800000000,1,130,11579,79333848,64.770000000,64.780000000,3,4,3,4,64.760000000,64.790000000,7,6,7,5,64.750000000,64.800000000,6,7,6,7,64.740000000,64.810000000,12,3,11,3,64.730000000,64.820000000,6,11,6,8,64.720000000,64.830000000,8,9,5,9,64.710000000,64.840000000,8,6,7,5,64.700000000,64.850000000,7,9,6,6,64.690000000,64.860000000,4,4,3,3,64.680000000,64.870000000,4,4,2,3,MCLN5
2025-06-11T00:00:36.817772638Z,2025-06-11T00:00:36.811970259Z,10,1,42026514,M,A,3,64.810000000,1,130,11478,79333849,64.770000000,64.780000000,3,4,3,4,64.760000000,64.790000000,7,6,7,5,64.750000000,64.800000000,6,7,6,7,64.740000000,64.810000000,12,4,11,4,64.730000000,64.820000000,6,11,6,8,64.720000000,64.830000000,8,9,5,9,64.710000000,64.840000000,8,6,7,5,64.700000000,64.850000000,7,9,6,6,64.690000000,64.860000000,4,4,3,3,64.680000000,64.870000000,4,4,2,3,MCLN5
2025-06-11T00:00:36.817795508Z,2025-06-11T00:00:36.811990609Z,10,1,42026514,M,B,0,62.830000000,2,130,14684,79333850,64.770000000,64.780000000,2,4,2,4,64.760000000,64.790000000,7,6,7,5,64.750000000,64.800000000,6,7,6,7,64.740000000,64.810000000,12,4,11,4,64.730000000,64.820000000,6,11,6,8,64.720000000,64.830000000,8,9,5,9,64.710000000,64.840000000,8,6,7,5,64.700000000,64.850000000,7,9,6,6,64.690000000,64.860000000,4,4,3,3,64.680000000,64.870000000,4,4,2,3,MCLN5
2025-06-11T00:00:36.817806083Z,2025-06-11T00:00:36.811993279Z,10,1,42026514,A,A,1,64.790000000,1,130,12016,79333851,64.770000000,64.780000000,2,4,2,4,64.760000000,64.790000000,7,7,7,6,64.750000000,64.800000000,6,7,6,7,64.740000000,64.810000000,12,4,11,4,64.730000000,64.820000000,6,11,6,8,64.720000000,64.830000000,8,9,5,9,64.710000000,64.840000000,8,6,7,5,64.700000000,64.850000000,7,9,6,6,64.690000000,64.860000000,4,4,3,3,64.680000000,64.870000000,4,4,2,3,MCLN5
2025-06-11T00:00:36.817864072Z,2025-06-11T00:00:36.812030045Z,10,1,42025623,M,B,0,62.300000000,1,130,13365,79333854,63.680000000,63.710000000,2,2,2,2,63.670000000,63.720000000,3,2,3,2,63.660000000,63.730000000,3,2,3,2,63.650000000,63.740000000,5,3,5,3,63.640000000,63.750000000,4,5,4,5,63.630000000,63.760000000,5,4,5,4,63.620000000,63.770000000,4,2,4,2,63.610000000,63.780000000,2,3,2,3,63.600000000,63.790000000,6,1,6,1,63.590000000,63.800000000,1,3,1,3,MCLQ5
2025-06-11T00:00:36.817937995Z,2025-06-11T00:00:36.812115027Z,10,1,42026514,C,A,1,64.790000000,1,130,15158,79333860,64.770000000,64.780000000,2,4,2,4,64.760000000,64.790000000,7,6,7,5,64.750000000,64.800000000,6,7,6,7,64.740000000,64.810000000,12,4,11,4,64.730000000,64.820000000,6,11,6,8,64.720000000,64.830000000,8,9,5,9,64.710000000,64.840000000,8,6,7,5,64.700000000,64.850000000,7,9,6,6,64.690000000,64.860000000,4,4,3,3,64.680000000,64.870000000,4,4,2,3,MCLN5
2025-06-11T00:00:36.818602818Z,2025-06-11T00:00:36.812637545Z,10,1,42026514,C,A,1,64.790000000,1,130,11261,79333901,64.770000000,64.780000000,2,4,2,4,64.760000000,64.790000000,7,5,7,4,64.750000000,64.800000000,6,7,6,7,64.740000000,64.810000000,12,4,11,4,64.730000000,64.820000000,6,11,6,8,64.720000000,64.830000000,8,9,5,9,64.710000000,64.840000000,8,6,7,5,64.700000000,64.850000000,7,9,6,6,64.690000000,64.860000000,4,4,3,3,64.680000000,64.870000000,4,4,2,3,MCLN5
2025-06-11T00:00:36.818616357Z,2025-06-11T00:00:36.812649985Z,10,1,42026514,A,A,1,64.790000000,2,130,12091,79333902,64.770000000,64.780000000,2,4,2,4,64.760000000,64.790000000,7,7,7,5,64.750000000,64.800000000,6,7,6,7,64.740000000,64.810000000,12,4,11,4,64.730000000,64.820000000,6,11,6,8,64.720000000,64.830000000,8,9,5,9,64.710000000,64.840000000,8,6,7,5,64.700000000,64.850000000,7,9,6,6,64.690000000,64.860000000,4,4,3,3,64.680000000,64.870000000,4,4,2,3,MCLN5
2025-06-11T00:00:36.818658917Z,2025-06-11T00:00:36.812694047Z,10,1,42025611,M,A,1,2.090000000,20,130,15574,79333905,2.070000000,2.080000000,3,5,2,2,2.060000000,2.090000000,27,27,5,6,2.050000000,2.100000000,23,27,3,6,2.040000000,2.110000000,23,23,3,4,2.030000000,2.120000000,2,2,1,1,2.020000000,2.130000000,2,2,2,2,2.010000000,2.140000000,2,2,1,1,2.000000000,2.150000000,2,2,2,1,1.990000000,2.160000000,2,2,1,1,1.980000000,2.170000000,2,2,2,1,MCLN5-MCLU5
2025-06-11T00:00:36.819215082Z,2025-06-11T00:00:36.813623211Z,10,1,42026514,C,A,0,64.780000000,1,130,14541,79333939,64.770000000,64.780000000,2,3,2,3,64.760000000,64.790000000,7,7,7,5,64.750000000,64.800000000,6,7,6,7,64.740000000,64.810000000,12,4,11,4,64.730000000,64.820000000,6,11,6,8,64.720000000,64.830000000,8,9,5,9,64.710000000,64.840000000,8,6,7,5,64.700000000,64.850000000,7,9,6,6,64.690000000,64.860000000,4,4,3,3,64.680000000,64.870000000,4,4,2,3,MCLN5
2025-06-11T00:00:36.821221621Z,2025-06-11T00:00:36.814229615Z,10,1,42025623,M,A,1,63.720000000,1,130,11347,79334045,63.680000000,63.710000000,2,2,2,2,63.670000000,63.720000000,3,3,3,3,63.660000000,63.730000000,3,2,3,2,63.650000000,63.740000000,5,3,5,3,63.640000000,63.750000000,4,5,4,5,63.630000000,63.760000000,5,4,5,4,63.620000000,63.770000000,4,2,4,2,63.610000000,63.780000000,2,3,2,3,63.600000000,63.790000000,6,1,6,1,63.590000000,63.800000000,1,3,1,3,MCLQ5
2025-06-11T00:00:36.821511649Z,2025-06-11T00:00:36.814472907Z,10,1,42026514,C,A,0,64.780000000,1,130,14269,79334062,64.770000000,64.780000000,2,2,2,2,64.760000000,64.790000000,7,7,7,5,64.750000000,64.800000000,6,7,6,7,64.740000000,64.810000000,12,4,11,4,64.730000000,64.820000000,6,11,6,8,64.720000000,64.830000000,8,9,5,9,64.710000000,64.840000000,8,6,7,5,64.700000000,64.850000000,7,9,6,6,64.690000000,64.860000000,4,4,3,3,64.680000000,64.870000000,4,4,2,3,MCLN5
2025-06-11T00:00:36.821527108Z,2025-06-11T00:00:36.814481835Z,10,1,42026514,M,A,1,64.790000000,1,130,16354,79334063,64.770000000,64.780000000,2,2,2,2,64.760000000,64.790000000,7,8,7,6,64.750000000,64.800000000,6,7,6,7,64.740000000,64.810000000,12,4,11,4,64.730000000,64.820000000,6,11,6,8,64.720000000,64.830000000,8,9,5,9,64.710000000,64.840000000,8,6,7,5,64.700000000,64.850000000,7,9,6,6,64.690000000,64.860000000,4,4,3,3,64.680000000,64.870000000,4,4,2,3,MCLN5
2025-06-11T00:00:36.821661331Z,2025-06-11T00:00:36.814602539Z,10,1,42026514,M,B,1,62.820000000,2,130,13599,79334069,64.770000000,64.780000000,2,2,2,2,64.760000000,64.790000000,6,8,6,6,64.750000000,64.800000000,6,7,6,7,64.740000000,64.810000000,12,4,11,4,64.730000000,64.820000000,6,11,6,8,64.720000000,64.830000000,8,9,5,9,64.710000000,64.840000000,8,6,7,5,64.700000000,64.850000000,7,9,6,6,64.690000000,64.860000000,4,4,3,3,64.680000000,64.870000000,4,4,2,3,MCLN5
2025-06-11T00:00:36.821677535Z,2025-06-11T00:00:36.814613521Z,10,1,42026514,M,B,1,62.810000000,2,130,13435,79334070,64.770000000,64.780000000,2,2,2,2,64.760000000,64.790000000,5,8,5,6,64.750000000,64.800000000,6,7,6,7,64.740000000,64.810000000,12,4,11,4,64.730000000,64.820000000,6,11,6,8,64.720000000,64.830000000,8,9,5,9,64.710000000,64.840000000,8,6,7,5,64.700000000,64.850000000,7,9,6,6,64.690000000,64.860000000,4,4,3,3,64.680000000,64.870000000,4,4,2,3,MCLN5
2025-06-11T00:00:36.821721831Z,2025-06-11T00:00:36.814641821Z,10,1,42026514,M,A,2,64.800000000,1,130,15500,79334074,64.770000000,64.780000000,2,2,2,2,64.760000000,64.790000000,5,8,5,6,64.750000000,64.800000000,6,8,6,8,64.740000000,64.810000000,12,4,11,4,64.730000000,64.820000000,6,11,6,8,64.720000000,64.830000000,8,9,5,9,64.710000000,64.840000000,8,6,7,5,64.700000000,64.850000000,7,9,6,6,64.690000000,64.860000000,4,4,3,3,64.680000000,64.870000000,4,4,2,3,MCLN5
2025-06-11T00:00:36.822143464Z,2025-06-11T00:00:36.814887435Z,10,1,42026514,A,A,0,64.780000000,1,130,16108,79334097,64.770000000,64.780000000,2,3,2,3,64.760000000,64.790000000,5,8,5,6,64.750000000,64.800000000,6,8,6,8,64.740000000,64.810000000,12,4,11,4,64.730000000,64.820000000,6,11,6,8,64.720000000,64.830000000,8,9,5,9,64.710000000,64.840000000,8,6,7,5,64.700000000,64.850000000,7,9,6,6,64.690000000,64.860000000,4,4,3,3,64.680000000,64.870000000,4,4,2,3,MCLN5
2025-06-11T00:00:36.823777874Z,2025-06-11T00:00:36.816462745Z,10,1,42025623,A,A,0,63.700000000,1,130,15814,79334219,63.680000000,63.700000000,2,1,2,1,63.670000000,63.710000000,3,2,3,2,63.660000000,63.720000000,3,3,3,3,63.650000000,63.730000000,5,2,5,2,63.640000000,63.740000000,4,3,4,3,63.630000000,63.750000000,5,5,5,5,63.620000000,63.760000000,4,4,4,4,63.610000000,63.770000000,2,2,2,2,63.600000000,63.780000000,6,3,6,3,63.590000000,63.790000000,1,1,1,1,MCLQ5
2025-06-11T00:00:36.823829535Z,2025-06-11T00:00:36.816495959Z,10,1,42026514,T,A,0,64.770000000,1,0,11788,79334223,64.770000000,64.780000000,2,3,2,3,64.760000000,64.790000000,5,8,5,6,64.750000000,64.800000000,6,8,6,8,64.740000000,64.810000000,12,4,11,4,64.730000000,64.820000000,6,11,6,8,64.720000000,64.830000000,8,9,5,9,64.710000000,64.840000000,8,6,7,5,64.700000000,64.850000000,7,9,6,6,64.690000000,64.860000000,4,4,3,3,64.680000000,64.870000000,4,4,2,3,MCLN5
2025-06-11T00:00:36.823856091Z,2025-06-11T00:00:36.816495959Z,10,1,42026514,C,B,0,64.770000000,1,130,18838,79334224,64.770000000,64.780000000,1,3,1,3,64.760000000,64.790000000,5,8,5,6,64.750000000,64.800000000,6,8,6,8,64.740000000,64.810000000,12,4,11,4,64.730000000,64.820000000,6,11,6,8,64.720000000,64.830000000,8,9,5,9,64.710000000,64.840000000,8,6,7,5,64.700000000,64.850000000,7,9,6,6,64.690000000,64.860000000,4,4,3,3,64.680000000,64.870000000,4,4,2,3,MCLN5
2025-06-11T00:00:36.824600274Z,2025-06-11T00:00:36.817873575Z,10,1,42025623,C,B,5,63.630000000,1,130,12012,79334283,63.680000000,63.700000000,2,1,2,1,63.670000000,63.710000000,3,2,3,2,63.660000000,63.720000000,3,3,3,3,63.650000000,63.730000000,5,2,5,2,63.640000000,63.740000000,4,3,4,3,63.630000000,63.750000000,4,5,4,5,63.620000000,63.760000000,4,4,4,4,63.610000000,63.770000000,2,2,2,2,63.600000000,63.780000000,6,3,6,3,63.590000000,63.790000000,1,1,1,1,MCLQ5
2025-06-11T00:00:36.824626408Z,2025-06-11T00:00:36.817882927Z,10,1,42026514,C,B,0,64.770000000,1,130,15319,79334284,64.760000000,64.780000000,5,3,5,3,64.750000000,64.790000000,6,8,6,6,64.740000000,64.800000000,12,8,11,8,64.730000000,64.810000000,6,4,6,4,64.720000000,64.820000000,8,11,5,8,64.710000000,64.830000000,8,9,7,9,64.700000000,64.840000000,7,6,6,5,64.690000000,64.850000000,4,9,3,6,64.680000000,64.860000000,4,4,2,3,64.670000000,64.870000000,6,4,4,3,MCLN5
2025-06-11T00:00:36.825726656Z,2025-06-11T00:00:36.819242937Z,10,1,42026514,A,B,0,64.770000000,2,130,15296,79334347,64.770000000,64.780000000,2,3,1,3,64.760000000,64.790000000,5,8,5,6,64.750000000,64.800000000,6,8,6,8,64.740000000,64.810000000,12,4,11,4,64.730000000,64.820000000,6,11,6,8,64.720000000,64.830000000,8,9,5,9,64.710000000,64.840000000,8,6,7,5,64.700000000,64.850000000,7,9,6,6,64.690000000,64.860000000,4,4,3,3,64.680000000,64.870000000,4,4,2,3,MCLN5
2025-06-11T00:00:36.826466984Z,2025-06-11T00:00:36.820523115Z,10,1,42026514,M,A,1,64.790000000,1,130,14882,79334409,64.770000000,64.780000000,2,3,1,3,64.760000000,64.790000000,5,9,5,7,64.750000000,64.800000000,6,8,6,8,64.740000000,64.810000000,12,4,11,4,64.730000000,64.820000000,6,11,6,8,64.720000000,64.830000000,8,9,5,9,64.710000000,64.840000000,8,6,7,5,64.700000000,64.850000000,7,9,6,6,64.690000000,64.860000000,4,4,3,3,64.680000000,64.870000000,4,4,2,3,MCLN5
2025-06-11T00:00:36.826974329Z,2025-06-11T00:00:36.821729879Z,10,1,42026514,A,A,0,64.780000000,1,130,13631,79334449,64.770000000,64.780000000,2,4,1,4,64.760000000,64.790000000,5,9,5,7,64.750000000,64.800000000,6,8,6,8,64.740000000,64.810000000,12,4,11,4,64.730000000,64.820000000,6,11,6,8,64.720000000,64.830000000,8,9,5,9,64.710000000,64.840000000,8,6,7,5,64.700000000,64.850000000,7,9,6,6,64.690000000,64.860000000,4,4,3,3,64.680000000,64.870000000,4,4,2,3,MCLN5
2025-06-11T00:00:36.827188919Z,2025-06-11T00:00:36.822151645Z,10,1,42026514,C,A,0,64.780000000,1,130,14070,79334464,64.770000000,64.780000000,2,3,1,3,64.760000000,64.790000000,5,9,5,7,64.750000000,64.800000000,6,8,6,8,64.740000000,64.810000000,12,4,11,4,64.730000000,64.820000000,6,11,6,8,64.720000000,64.830000000,8,9,5,9,64.710000000,64.840000000,8,6,7,5,64.700000000,64.850000000,7,9,6,6,64.690000000,64.860000000,4,4,3,3,64.680000000,64.870000000,4,4,2,3,MCLN5
2025-06-11T00:00:36.827359498Z,2025-06-11T00:00:36.822409221Z,10,1,42418117,M,B,0,3.220000000,1,130,11965,79334476,3.240000000,3.280000000,11,11,2,2,3.230000000,3.290000000,1,1,1,1,3.220000000,3.300000000,1,1,1,1,,,0,0,0,0,,,0,0,0,0,,,0,0,0,0,,,0,0,0,0,,,0,0,0,0,,,0,0,0,0,,,0,0,0,0,MCLN5-MCLX5
2025-06-11T00:00:36.828273040Z,2025-06-11T00:00:36.823045809Z,10,1,42026514,A,A,0,64.780000000,1,130,11588,79334541,64.770000000,64.780000000,2,4,1,4,64.760000000,64.790000000,5,9,5,7,64.750000000,64.800000000,6,8,6,8,64.740000000,64.810000000,12,4,11,4,64.730000000,64.820000000,6,11,6,8,64.720000000,64.830000000,8,9,5,9,64.710000000,64.840000000,8,6,7,5,64.700000000,64.850000000,7,9,6,6,64.690000000,64.860000000,4,4,3,3,64.680000000,64.870000000,4,4,2,3,MCLN5
2025-06-11T00:00:36.828551779Z,2025-06-11T00:00:36.823465253Z,10,1,42026514,M,B,3,64.730000000,1,130,11630,79334554,64.770000000,64.780000000,2,4,1,4,64.760000000,64.790000000,5,9,5,7,64.750000000,64.800000000,6,8,6,8,64.740000000,64.810000000,11,4,10,4,64.730000000,64.820000000,7,11,7,8,64.720000000,64.830000000,8,9,5,9,64.710000000,64.840000000,8,6,7,5,64.700000000,64.850000000,7,9,6,6,64.690000000,64.860000000,4,4,3,3,64.680000000,64.870000000,4,4,2,3,MCLN5
2025-06-11T00:00:36.828589378Z,2025-06-11T00:00:36.823466193Z,10,1,42026514,M,B,3,64.730000000,1,130,11605,79334556,64.770000000,64.780000000,2,4,1,4,64.760000000,64.790000000,5,9,5,7,64.750000000,64.800000000,6,8,6,8,64.740000000,64.810000000,10,4,9,4,64.730000000,64.820000000,8,11,8,8,64.720000000,64.830000000,8,9,5,9,64.710000000,64.840000000,8,6,7,5,64.700000000,64.850000000,7,9,6,6,64.690000000,64.860000000,4,4,3,3,64.680000000,64.870000000,4,4,2,3,MCLN5
2025-06-11T00:00:36.828666174Z,2025-06-11T00:00:36.823467103Z,10,1,42026514,M,B,3,64.730000000,1,130,11165,79334560,64.770000000,64.780000000,2,4,1,4,64.760000000,64.790000000,5,9,5,7,64.750000000,64.800000000,6,8,6,8,64.740000000,64.810000000,9,4,8,4,64.730000000,64.820000000,9,11,9,8,64.720000000,64.830000000,8,9,5,9,64.710000000,64.840000000,8,6,7,5,64.700000000,64.850000000,7,9,6,6,64.690000000,64.860000000,4,4,3,3,64.680000000,64.870000000,4,4,2,3,MCLN5
2025-06-11T00:00:36.828686551Z,2025-06-11T00:00:36.823469783Z,10,1,42026514,C,B,0,64.770000000,2,130,13133,79334561,64.760000000,64.780000000,5,4,5,4,64.750000000,64.790000000,6,9,6,7,64.740000000,64.800000000,9,8,8,8,64.730000000,64.810000000,9,4,9,4,64.720000000,64.820000000,8,11,5,8,64.710000000,64.830000000,8,9,7,9,64.700000000,64.840000000,7,6,6,5,64.690000000,64.850000000,4,9,3,6,64.680000000,64.860000000,4,4,2,3,64.670000000,64.870000000,6,4,4,3,MCLN5
2025-06-11T00:00:36.829466788Z,2025-06-11T00:00:36.823864211Z,10,1,42026514,C,A,0,64.780000000,1,130,14150,79334605,64.760000000,64.780000000,5,3,5,3,64.750000000,64.790000000,6,9,6,7,64.740000000,64.800000000,9,8,8,8,64.730000000,64.810000000,9,4,9,4,64.720000000,64.820000000,8,11,5,8,64.710000000,64.830000000,8,9,7,9,64.700000000,64.840000000,7,6,6,5,64.690000000,64.850000000,4,9,3,6,64.680000000,64.860000000,4,4,2,3,64.670000000,64.870000000,6,4,4,3,MCLN5
2025-06-11T00:00:36.829715299Z,2025-06-11T00:00:36.824152101Z,10,1,42026514,A,A,0,64.780000000,1,130,13954,79334626,64.760000000,64.780000000,5,4,5,4,64.750000000,64.790000000,6,9,6,7,64.740000000,64.800000000,9,8,8,8,64.730000000,64.810000000,9,4,9,4,64.720000000,64.820000000,8,11,5,8,64.710000000,64.830000000,8,9,7,9,64.700000000,64.840000000,7,6,6,5,64.690000000,64.850000000,4,9,3,6,64.680000000,64.860000000,4,4,2,3,64.670000000,64.870000000,6,4,4,3,MCLN5
2025-06-11T00:00:36.830321572Z,2025-06-11T00:00:36.824612247Z,10,1,42026514,A,B,4,64.720000000,1,130,11616,79334665,64.760000000,64.780000000,5,4,5,4,64.750000000,64.790000000,6,9,6,7,64.740000000,64.800000000,9,8,8,8,64.730000000,64.810000000,9,4,9,4,64.720000000,64.820000000,9,11,6,8,64.710000000,64.830000000,8,9,7,9,64.700000000,64.840000000,7,6,6,5,64.690000000,64.850000000,4,9,3,6,64.680000000,64.860000000,4,4,2,3,64.670000000,64.870000000,6,4,4,3,MCLN5
2025-06-11T00:00:36.830353980Z,2025-06-11T00:00:36.824613839Z,10,1,42026514,C,A,7,64.850000000,1,130,11644,79334667,64.760000000,64.780000000,5,4,5,4,64.750000000,64.790000000,6,9,6,7,64.740000000,64.800000000,9,8,8,8,64.730000000,64.810000000,9,4,9,4,64.720000000,64.820000000,9,11,6,8,64.710000000,64.830000000,8,9,7,9,64.700000000,64.840000000,7,6,6,5,64.690000000,64.850000000,4,8,3,5,64.680000000,64.860000000,4,4,2,3,64.670000000,64.870000000,6,4,4,3,MCLN5
2025-06-11T00:00:36.830401617Z,2025-06-11T00:00:36.824619947Z,10,1,42026514,C,A,0,64.780000000,1,130,17869,79334669,64.760000000,64.780000000,5,3,5,3,64.750000000,64.790000000,6,9,6,7,64.740000000,64.800000000,9,8,8,8,64.730000000,64.810000000,9,4,9,4,64.720000000,64.820000000,9,11,6,8,64.710000000,64.830000000,8,9,7,9,64.700000000,64.840000000,7,6,6,5,64.690000000,64.850000000,4,8,3,5,64.680000000,64.860000000,4,4,2,3,64.670000000,64.870000000,6,4,4,3,MCLN5
2025-06-11T00:00:36.830670218Z,2025-06-11T00:00:36.824745949Z,10,1,42026514,A,B,0,64.770000000,1,130,13005,79334682,64.770000000,64.780000000,1,3,1,3,64.760000000,64.790000000,5,9,5,7,64.750000000,64.800000000,6,8,6,8,64.740000000,64.810000000,9,4,8,4,64.730000000,64.820000000,9,11,9,8,64.720000000,64.830000000,9,9,6,9,64.710000000,64.840000000,8,6,7,5,64.700000000,64.850000000,7,8,6,5,64.690000000,64.860000000,4,4,3,3,64.680000000,64.870000000,4,4,2,3,MCLN5
2025-06-11T00:00:36.830839515Z,2025-06-11T00:00:36.824771869Z,10,1,42026514,M,B,2,62.800000000,2,130,14813,79334691,64.770000000,64.780000000,1,3,1,3,64.760000000,64.790000000,5,9,5,7,64.750000000,64.800000000,5,8,5,8,64.740000000,64.810000000,9,4,8,4,64.730000000,64.820000000,9,11,9,8,64.720000000,64.830000000,9,9,6,9,64.710000000,64.840000000,8,6,7,5,64.700000000,64.850000000,7,8,6,5,64.690000000,64.860000000,4,4,3,3,64.680000000,64.870000000,4,4,2,3,MCLN5
2025-06-11T00:00:36.831163240Z,2025-06-11T00:00:36.825151455Z,10,1,42025623,M,B,3,63.640000000,1,130,11716,79334709,63.680000000,63.700000000,2,1,2,1,63.670000000,63.710000000,3,2,3,2,63.660000000,63.720000000,3,3,3,3,63.650000000,63.730000000,4,2,4,2,63.640000000,63.740000000,5,3,5,3,63.630000000,63.750000000,4,5,4,5,63.620000000,63.760000000,4,4,4,4,63.610000000,63.770000000,2,2,2,2,63.600000000,63.780000000,6,3,6,3,63.590000000,63.790000000,1,1,1,1,MCLQ5
2025-06-11T00:00:36.831174422Z,2025-06-11T00:00:36.825152147Z,10,1,42025623,M,B,3,63.640000000,1,130,11909,79334710,63.680000000,63.700000000,2,1,2,1,63.670000000,63.710000000,3,2,3,2,63.660000000,63.720000000,3,3,3,3,63.650000000,63.730000000,3,2,3,2,63.640000000,63.740000000,6,3,6,3,63.630000000,63.750000000,4,5,4,5,63.620000000,63.760000000,4,4,4,4,63.610000000,63.770000000,2,2,2,2,63.600000000,63.780000000,6,3,6,3,63.590000000,63.790000000,1,1,1,1,MCLQ5
2025-06-11T00:00:36.831206408Z,2025-06-11T00:00:36.825152759Z,10,1,42025623,M,B,4,63.630000000,1,130,11260,79334712,63.680000000,63.700000000,2,1,2,1,63.670000000,63.710000000,3,2,3,2,63.660000000,63.720000000,3,3,3,3,63.650000000,63.730000000,3,2,3,2,63.640000000,63.740000000,5,3,5,3,63.630000000,63.750000000,5,5,5,5,63.620000000,63.760000000,4,4,4,4,63.610000000,63.770000000,2,2,2,2,63.600000000,63.780000000,6,3,6,3,63.590000000,63.790000000,1,1,1,1,MCLQ5
2025-06-11T00:00:36.831685699Z,2025-06-11T00:00:36.825906867Z,10,1,42026514,C,A,1,64.790000000,1,130,11473,79334742,64.770000000,64.780000000,1,3,1,3,64.760000000,64.790000000,5,8,5,6,64.750000000,64.800000000,5,8,5,8,64.740000000,64.810000000,9,4,8,4,64.730000000,64.820000000,9,11,9,8,64.720000000,64.830000000,9,9,6,9,64.710000000,64.840000000,8,6,7,5,64.700000000,64.850000000,7,8,6,5,64.690000000,64.860000000,4,4,3,3,64.680000000,64.870000000,4,4,2,3,MCLN5
2025-06-11T00:00:36.831736583Z,2025-06-11T00:00:36.825926525Z,10,1,42026514,M,A,1,66.730000000,2,130,13325,79334745,64.770000000,64.780000000,1,3,1,3,64.760000000,64.790000000,5,7,5,5,64.750000000,64.800000000,5,8,5,8,64.740000000,64.810000000,9,4,8,4,64.730000000,64.820000000,9,11,9,8,64.720000000,64.830000000,9,9,6,9,64.710000000,64.840000000,8,6,7,5,64.700000000,64.850000000,7,8,6,5,64.690000000,64.860000000,4,4,3,3,64.680000000,64.870000000,4,4,2,3,MCLN5
2025-06-11T00:00:36.832467113Z,2025-06-11T00:00:36.827212291Z,10,1,42026514,A,B,0,64.770000000,2,130,11936,79334798,64.770000000,64.780000000,3,3,2,3,64.760000000,64.790000000,5,7,5,5,64.750000000,64.800000000,5,8,5,8,64.740000000,64.810000000,9,4,8,4,64.730000000,64.820000000,9,11,9,8,64.720000000,64.830000000,9,9,6,9,64.710000000,64.840000000,8,6,7,5,64.700000000,64.850000000,7,8,6,5,64.690000000,64.860000000,4,4,3,3,64.680000000,64.870000000,4,4,2,3,MCLN5
2025-06-11T00:00:36.832862643Z,2025-06-11T00:00:36.827746317Z,10,1,42025623,M,B,4,63.640000000,1,130,11413,79334829,63.680000000,63.700000000,2,1,2,1,63.670000000,63.710000000,3,2,3,2,63.660000000,63.720000000,3,3,3,3,63.650000000,63.730000000,3,2,3,2,63.640000000,63.740000000,6,3,6,3,63.630000000,63.750000000,4,5,4,5,63.620000000,63.760000000,4,4,4,4,63.610000000,63.770000000,2,2,2,2,63.600000000,63.780000000,6,3,6,3,63.590000000,63.790000000,1,1,1,1,MCLQ5
2025-06-11T00:00:36.832954230Z,2025-06-11T00:00:36.827833117Z,10,1,42026514,C,B,0,64.770000000,1,130,13713,79334835,64.770000000,64.780000000,2,3,1,3,64.760000000,64.790000000,5,7,5,5,64.750000000,64.800000000,5,8,5,8,64.740000000,64.810000000,9,4,8,4,64.730000000,64.820000000,9,11,9,8,64.720000000,64.830000000,9,9,6,9,64.710000000,64.840000000,8,6,7,5,64.700000000,64.850000000,7,8,6,5,64.690000000,64.860000000,4,4,3,3,64.680000000,64.870000000,4,4,2,3,MCLN5
2025-06-11T00:00:36.833215597Z,2025-06-11T00:00:36.828281763Z,10,1,42026514,A,B,0,64.770000000,1,130,16957,79334851,64.770000000,64.780000000,3,3,2,3,64.760000000,64.790000000,5,7,5,5,64.750000000,64.800000000,5,8,5,8,64.740000000,64.810000000,9,4,8,4,64.730000000,64.820000000,9,11,9,8,64.720000000,64.830000000,9,9,6,9,64.710000000,64.840000000,8,6,7,5,64.700000000,64.850000000,7,8,6,5,64.690000000,64.860000000,4,4,3,3,64.680000000,64.870000000,4,4,2,3,MCLN5
2025-06-11T00:00:36.833278723Z,2025-06-11T00:00:36.828694255Z,10,1,42026514,C,B,5,64.720000000,1,130,11344,79334855,64.770000000,64.780000000,3,3,2,3,64.760000000,64.790000000,5,7,5,5,64.750000000,64.800000000,5,8,5,8,64.740000000,64.810000000,9,4,8,4,64.730000000,64.820000000,9,11,9,8,64.720000000,64.830000000,8,9,5,9,64.710000000,64.840000000,8,6,7,5,64.700000000,64.850000000,7,8,6,5,64.690000000,64.860000000,4,4,3,3,64.680000000,64.870000000,4,4,2,3,MCLN5
2025-06-11T00:00:36.835054967Z,2025-06-11T00:00:36.830887299Z,10,1,42025623,M,B,4,63.630000000,1,130,13606,79334981,63.680000000,63.700000000,2,1,2,1,63.670000000,63.710000000,3,2,3,2,63.660000000,63.720000000,3,3,3,3,63.650000000,63.730000000,3,2,3,2,63.640000000,63.740000000,5,3,5,3,63.630000000,63.750000000,5,5,5,5,63.620000000,63.760000000,4,4,4,4,63.610000000,63.770000000,2,2,2,2,63.600000000,63.780000000,6,3,6,3,63.590000000,63.790000000,1,1,1,1,MCLQ5
2025-06-11T00:00:36.835100838Z,2025-06-11T00:00:36.831283645Z,10,1,42418117,M,A,0,3.290000000,10,130,12050,79334985,3.240000000,3.280000000,11,1,2,1,3.230000000,3.290000000,1,11,1,2,3.220000000,3.300000000,1,1,1,1,,,0,0,0,0,,,0,0,0,0,,,0,0,0,0,,,0,0,0,0,,,0,0,0,0,,,0,0,0,0,,,0,0,0,0,MCLN5-MCLX5
2025-06-11T00:00:36.835349572Z,2025-06-11T00:00:36.831479535Z,10,1,42026514,A,B,0,64.770000000,1,130,13238,79335000,64.770000000,64.780000000,4,3,3,3,64.760000000,64.790000000,5,7,5,5,64.750000000,64.800000000,5,8,5,8,64.740000000,64.810000000,9,4,8,4,64.730000000,64.820000000,9,11,9,8,64.720000000,64.830000000,8,9,5,9,64.710000000,64.840000000,8,6,7,5,64.700000000,64.850000000,7,8,6,5,64.690000000,64.860000000,4,4,3,3,64.680000000,64.870000000,4,4,2,3,MCLN5
2025-06-11T00:00:36.835367296Z,2025-06-11T00:00:36.831485505Z,10,1,42026514,A,B,0,64.770000000,1,130,14039,79335001,64.770000000,64.780000000,5,3,4,3,64.760000000,64.790000000,5,7,5,5,64.750000000,64.800000000,5,8,5,8,64.740000000,64.810000000,9,4,8,4,64.730000000,64.820000000,9,11,9,8,64.720000000,64.830000000,8,9,5,9,64.710000000,64.840000000,8,6,7,5,64.700000000,64.850000000,7,8,6,5,64.690000000,64.860000000,4,4,3,3,64.680000000,64.870000000,4,4,2,3,MCLN5
2025-06-11T00:00:36.835390796Z,2025-06-11T00:00:36.831486293Z,10,1,42026514,C,A,0,64.780000000,1,130,14678,79335002,64.770000000,64.780000000,5,2,4,2,64.760000000,64.790000000,5,7,5,5,64.750000000,64.800000000,5,8,5,8,64.740000000,64.810000000,9,4,8,4,64.730000000,64.820000000,9,11,9,8,64.720000000,64.830000000,8,9,5,9,64.710000000,64.840000000,8,6,7,5,64.700000000,64.850000000,7,8,6,5,64.690000000,64.860000000,4,4,3,3,64.680000000,64.870000000,4,4,2,3,MCLN5
2025-06-11T00:00:36.836021544Z,2025-06-11T00:00:36.832475931Z,10,1,42026514,C,B,0,64.770000000,1,130,13950,79335040,64.770000000,64.780000000,4,2,3,2,64.760000000,64.790000000,5,7,5,5,64.750000000,64.800000000,5,8,5,8,64.740000000,64.810000000,9,4,8,4,64.730000000,64.820000000,9,11,9,8,64.720000000,64.830000000,8,9,5,9,64.710000000,64.840000000,8,6,7,5,64.700000000,64.850000000,7,8,6,5,64.690000000,64.860000000,4,4,3,3,64.680000000,64.870000000,4,4,2,3,MCLN5
2025-06-11T00:00:36.836118192Z,2025-06-11T00:00:36.833269201Z,10,1,42026514,M,A,1,64.790000000,2,130,12610,79335049,64.770000000,64.780000000,4,2,3,2,64.760000000,64.790000000,5,9,5,6,64.750000000,64.800000000,5,8,5,8,64.740000000,64.810000000,9,4,8,4,64.730000000,64.820000000,9,11,9,8,64.720000000,64.830000000,8,9,5,9,64.710000000,64.840000000,8,6,7,5,64.700000000,64.850000000,7,8,6,5,64.690000000,64.860000000,4,4,3,3,64.680000000,64.870000000,4,4,2,3,MCLN5
2025-06-11T00:00:36.837331637Z,2025-06-11T00:00:36.834757693Z,10,1,42022708,M,A,0,2.840000000,10,130,15062,79335139,2.810000000,2.830000000,1,2,1,2,2.800000000,2.840000000,12,12,3,3,2.790000000,2.850000000,2,1,2,1,2.780000000,2.870000000,1,1,1,1,,,0,0,0,0,,,0,0,0,0,,,0,0,0,0,,,0,0,0,0,,,0,0,0,0,,,0,0,0,0,MCLN5-MCLV5
2025-06-11T00:00:36.837778812Z,2025-06-11T00:00:36.835067893Z,10,1,42025623,A,B,6,63.620000000,1,130,11744,79335172,63.680000000,63.700000000,2,1,2,1,63.670000000,63.710000000,3,2,3,2,63.660000000,63.720000000,3,3,3,3,63.650000000,63.730000000,3,2,3,2,63.640000000,63.740000000,5,3,5,3,63.630000000,63.750000000,5,5,5,5,63.620000000,63.760000000,5,4,5,4,63.610000000,63.770000000,2,2,2,2,63.600000000,63.780000000,6,3,6,3,63.590000000,63.790000000,1,1,1,1,MCLQ5
2025-06-11T00:00:36.837789894Z,2025-06-11T00:00:36.835070447Z,10,1,42025623,C,A,7,63.770000000,1,130,11681,79335173,63.680000000,63.700000000,2,1,2,1,63.670000000,63.710000000,3,2,3,2,63.660000000,63.720000000,3,3,3,3,63.650000000,63.730000000,3,2,3,2,63.640000000,63.740000000,5,3,5,3,63.630000000,63.750000000,5,5,5,5,63.620000000,63.760000000,5,4,5,4,63.610000000,63.770000000,2,1,2,1,63.600000000,63.780000000,6,3,6,3,63.590000000,63.790000000,1,1,1,1,MCLQ5
2025-06-11T00:00:36.838187466Z,2025-06-11T00:00:36.835482731Z,10,1,42025623,A,A,6,63.760000000,1,130,11003,79335203,63.680000000,63.700000000,2,1,2,1,63.670000000,63.710000000,3,2,3,2,63.660000000,63.720000000,3,3,3,3,63.650000000,63.730000000,3,2,3,2,63.640000000,63.740000000,5,3,5,3,63.630000000,63.750000000,5,5,5,5,63.620000000,63.760000000,5,5,5,5,63.610000000,63.770000000,2,1,2,1,63.600000000,63.780000000,6,3,6,3,63.590000000,63.790000000,1,1,1,1,MCLQ5
2025-06-11T00:00:36.838201397Z,2025-06-11T00:00:36.835515791Z,10,1,42026514,M,A,1,66.720000000,2,130,12587,79335204,64.770000000,64.780000000,4,2,3,2,64.760000000,64.790000000,5,7,5,5,64.750000000,64.800000000,5,8,5,8,64.740000000,64.810000000,9,4,8,4,64.730000000,64.820000000,9,11,9,8,64.720000000,64.830000000,8,9,5,9,64.710000000,64.840000000,8,6,7,5,64.700000000,64.850000000,7,8,6,5,64.690000000,64.860000000,4,4,3,3,64.680000000,64.870000000,4,4,2,3,MCLN5
2025-06-11T00:00:36.838668017Z,2025-06-11T00:00:36.836040811Z,10,1,42026514,A,A,0,64.780000000,1,130,13185,79335236,64.770000000,64.780000000,4,3,3,3,64.760000000,64.790000000,5,7,5,5,64.750000000,64.800000000,5,8,5,8,64.740000000,64.810000000,9,4,8,4,64.730000000,64.820000000,9,11,9,8,64.720000000,64.830000000,8,9,5,9,64.710000000,64.840000000,8,6,7,5,64.700000000,64.850000000,7,8,6,5,64.690000000,64.860000000,4,4,3,3,64.680000000,64.870000000,4,4,2,3,MCLN5
2025-06-11T00:00:36.838679144Z,2025-06-11T00:00:36.836163839Z,10,1,42026514,M,A,1,64.790000000,2,130,11905,79335237,64.770000000,64.780000000,4,3,3,3,64.760000000,64.790000000,5,9,5,6,64.750000000,64.800000000,5,8,5,8,64.740000000,64.810000000,9,4,8,4,64.730000000,64.820000000,9,11,9,8,64.720000000,64.830000000,8,9,5,9,64.710000000,64.840000000,8,6,7,5,64.700000000,64.850000000,7,8,6,5,64.690000000,64.860000000,4,4,3,3,64.680000000,64.870000000,4,4,2,3,MCLN5
2025-06-11T00:00:36.838702506Z,2025-06-11T00:00:36.836309387Z,10,1,42026514,A,A,0,64.780000000,1,130,14708,79335239,64.770000000,64.780000000,4,4,3,4,64.760000000,64.790000000,5,9,5,6,64.750000000,64.800000000,5,8,5,8,64.740000000,64.810000000,9,4,8,4,64.730000000,64.820000000,9,11,9,8,64.720000000,64.830000000,8,9,5,9,64.710000000,64.840000000,8,6,7,5,64.700000000,64.850000000,7,8,6,5,64.690000000,64.860000000,4,4,3,3,64.680000000,64.870000000,4,4,2,3,MCLN5
2025-06-11T00:00:36.839256528Z,2025-06-11T00:00:36.836965095Z,10,1,42026514,C,B,0,64.770000000,1,130,15658,79335271,64.770000000,64.780000000,3,4,2,4,64.760000000,64.790000000,5,9,5,6,64.750000000,64.800000000,5,8,5,8,64.740000000,64.810000000,9,4,8,4,64.730000000,64.820000000,9,11,9,8,64.720000000,64.830000000,8,9,5,9,64.710000000,64.840000000,8,6,7,5,64.700000000,64.850000000,7,8,6,5,64.690000000,64.860000000,4,4,3,3,64.680000000,64.870000000,4,4,2,3,MCLN5
2025-06-11T00:00:36.840006317Z,2025-06-11T00:00:36.838677103Z,10,1,42026514,C,A,0,64.780000000,1,130,18170,79335325,64.770000000,64.780000000,3,3,2,3,64.760000000,64.790000000,5,9,5,6,64.750000000,64.800000000,5,8,5,8,64.740000000,64.810000000,9,4,8,4,64.730000000,64.820000000,9,11,9,8,64.720000000,64.830000000,8,9,5,9,64.710000000,64.840000000,8,6,7,5,64.700000000,64.850000000,7,8,6,5,64.690000000,64.860000000,4,4,3,3,64.680000000,64.870000000,4,4,2,3,MCLN5
2025-06-11T00:00:36.850529198Z,2025-06-11T00:00:36.850425851Z,10,1,42026514,A,B,5,64.720000000,1,130,14567,79335427,64.770000000,64.780000000,3,3,2,3,64.760000000,64.790000000,5,9,5,6,64.750000000,64.800000000,5,8,5,8,64.740000000,64.810000000,9,4,8,4,64.730000000,64.820000000,9,11,9,8,64.720000000,64.830000000,9,9,6,9,64.710000000,64.840000000,8,6,7,5,64.700000000,64.850000000,7,8,6,5,64.690000000,64.860000000,4,4,3,3,64.680000000,64.870000000,4,4,2,3,MCLN5
2025-06-11T00:00:36.850536846Z,2025-06-11T00:00:36.850427655Z,10,1,42026514,A,A,6,64.840000000,1,130,11550,79335428,64.770000000,64.780000000,3,3,2,3,64.760000000,64.790000000,5,9,5,6,64.750000000,64.800000000,5,8,5,8,64.740000000,64.810000000,9,4,8,4,64.730000000,64.820000000,9,11,9,8,64.720000000,64.830000000,9,9,6,9,64.710000000,64.840000000,8,7,7,6,64.700000000,64.850000000,7,8,6,5,64.690000000,64.860000000,4,4,3,3,64.680000000,64.870000000,4,4,2,3,MCLN5
2025-06-11T00:00:36.978520279Z,2025-06-11T00:00:36.978350331Z,10,1,42022708,M,A,0,2.830000000,10,130,11977,79335839,2.810000000,2.830000000,1,12,1,3,2.800000000,2.840000000,12,2,3,2,2.790000000,2.850000000,2,1,2,1,2.780000000,2.870000000,1,1,1,1,,,0,0,0,0,,,0,0,0,0,,,0,0,0,0,,,0,0,0,0,,,0,0,0,0,,,0,0,0,0,MCLN5-MCLV5
2025-06-11T00:00:37.077424873Z,2025-06-11T00:00:37.077288819Z,10,1,42026514,A,B,0,64.770000000,1,130,17472,79336004,64.770000000,64.780000000,4,3,3,3,64.760000000,64.790000000,5,9,5,6,64.750000000,64.800000000,5,8,5,8,64.740000000,64.810000000,9,4,8,4,64.730000000,64.820000000,9,11,9,8,64.720000000,64.830000000,9,9,6,9,64.710000000,64.840000000,8,7,7,6,64.700000000,64.850000000,7,8,6,5,64.690000000,64.860000000,4,4,3,3,64.680000000,64.870000000,4,4,2,3,MCLN5
2025-06-11T00:00:37.077448772Z,2025-06-11T00:00:37.077289759Z,10,1,42026514,C,A,0,64.780000000,1,130,14934,79336005,64.770000000,64.780000000,4,2,3,2,64.760000000,64.790000000,5,9,5,6,64.750000000,64.800000000,5,8,5,8,64.740000000,64.810000000,9,4,8,4,64.730000000,64.820000000,9,11,9,8,64.720000000,64.830000000,9,9,6,9,64.710000000,64.840000000,8,7,7,6,64.700000000,64.850000000,7,8,6,5,64.690000000,64.860000000,4,4,3,3,64.680000000,64.870000000,4,4,2,3,MCLN5
2025-06-11T00:00:37.077541887Z,2025-06-11T00:00:37.077437093Z,10,1,42025623,M,A,4,63.740000000,1,130,14972,79336006,63.680000000,63.700000000,2,1,2,1,63.670000000,63.710000000,3,2,3,2,63.660000000,63.720000000,3,3,3,3,63.650000000,63.730000000,3,2,3,2,63.640000000,63.740000000,5,4,5,4,63.630000000,63.750000000,5,4,5,4,63.620000000,63.760000000,5,5,5,5,63.610000000,63.770000000,2,1,2,1,63.600000000,63.780000000,6,3,6,3,63.590000000,63.790000000,1,1,1,1,MCLQ5
2025-06-11T00:00:37.077550366Z,2025-06-11T00:00:37.077438303Z,10,1,42025623,M,A,4,63.740000000,1,130,11417,79336007,63.680000000,63.700000000,2,1,2,1,63.670000000,63.710000000,3,2,3,2,63.660000000,63.720000000,3,3,3,3,63.650000000,63.730000000,3,2,3,2,63.640000000,63.740000000,5,5,5,5,63.630000000,63.750000000,5,3,5,3,63.620000000,63.760000000,5,5,5,5,63.610000000,63.770000000,2,1,2,1,63.600000000,63.780000000,6,3,6,3,63.590000000,63.790000000,1,1,1,1,MCLQ5
2025-06-11T00:00:37.077562807Z,2025-06-11T00:00:37.077440549Z,10,1,42026514,M,B,3,64.740000000,1,130,15497,79336008,64.770000000,64.780000000,4,2,3,2,64.760000000,64.790000000,5,9,5,6,64.750000000,64.800000000,5,8,5,8,64.740000000,64.810000000,10,4,9,4,64.730000000,64.820000000,8,11,8,8,64.720000000,64.830000000,9,9,6,9,64.710000000,64.840000000,8,7,7,6,64.700000000,64.850000000,7,8,6,5,64.690000000,64.860000000,4,4,3,3,64.680000000,64.870000000,4,4,2,3,MCLN5
2025-06-11T00:00:37.077571346Z,2025-06-11T00:00:37.077441201Z,10,1,42026514,M,B,3,64.740000000,1,130,11502,79336009,64.770000000,64.780000000,4,2,3,2,64.760000000,64.790000000,5,9,5,6,64.750000000,64.800000000,5,8,5,8,64.740000000,64.810000000,11,4,10,4,64.730000000,64.820000000,7,11,7,8,64.720000000,64.830000000,9,9,6,9,64.710000000,64.840000000,8,7,7,6,64.700000000,64.850000000,7,8,6,5,64.690000000,64.860000000,4,4,3,3,64.680000000,64.870000000,4,4,2,3,MCLN5
2025-06-11T00:00:37.077579940Z,2025-06-11T00:00:37.077442257Z,10,1,42026514,M,A,4,64.820000000,1,130,11336,79336010,64.770000000,64.780000000,4,2,3,2,64.760000000,64.790000000,5,9,5,6,64.750000000,64.800000000,5,8,5,8,64.740000000,64.810000000,11,4,10,4,64.730000000,64.820000000,7,12,7,9,64.720000000,64.830000000,9,8,6,8,64.710000000,64.840000000,8,7,7,6,64.700000000,64.850000000,7,8,6,5,64.690000000,64.860000000,4,4,3,3,64.680000000,64.870000000,4,4,2,3,MCLN5
2025-06-11T00:00:37.094846588Z,2025-06-11T00:00:37.094243127Z,10,1,42025623,M,B,4,63.640000000,1,130,11747,79336057,63.680000000,63.700000000,2,1,2,1,63.670000000,63.710000000,3,2,3,2,63.660000000,63.720000000,3,3,3,3,63.650000000,63.730000000,3,2,3,2,63.640000000,63.740000000,6,5,6,5,63.630000000,63.750000000,4,3,4,3,63.620000000,63.760000000,5,5,5,5,63.610000000,63.770000000,2,1,2,1,63.600000000,63.780000000,6,3,6,3,63.590000000,63.790000000,1,1,1,1,MCLQ5
2025-06-11T00:00:37.097305732Z,2025-06-11T00:00:37.096938765Z,10,1,42026514,C,A,0,64.780000000,1,130,11474,79336218,64.770000000,64.780000000,4,1,3,1,64.760000000,64.790000000,5,9,5,6,64.750000000,64.800000000,5,8,5,8,64.740000000,64.810000000,11,4,10,4,64.730000000,64.820000000,7,12,7,9,64.720000000,64.830000000,9,8,6,8,64.710000000,64.840000000,8,7,7,6,64.700000000,64.850000000,7,8,6,5,64.690000000,64.860000000,4,4,3,3,64.680000000,64.870000000,4,4,2,3,MCLN5
2025-06-11T00:00:37.098055000Z,2025-06-11T00:00:37.097260505Z,10,1,42026514,M,A,1,66.740000000,2,130,11973,79336269,64.770000000,64.780000000,4,1,3,1,64.760000000,64.790000000,5,7,5,5,64.750000000,64.800000000,5,8,5,8,64.740000000,64.810000000,11,4,10,4,64.730000000,64.820000000,7,12,7,9,64.720000000,64.830000000,9,8,6,8,64.710000000,64.840000000,8,7,7,6,64.700000000,64.850000000,7,8,6,5,64.690000000,64.860000000,4,4,3,3,64.680000000,64.870000000,4,4,2,3,MCLN5
2025-06-11T00:00:37.098064569Z,2025-06-11T00:00:37.097288747Z,10,1,42022708,M,A,0,2.840000000,10,130,12905,79336270,2.810000000,2.830000000,1,2,1,2,2.800000000,2.840000000,12,12,3,3,2.790000000,2.850000000,2,1,2,1,2.780000000,2.870000000,1,1,1,1,,,0,0,0,0,,,0,0,0,0,,,0,0,0,0,,,0,0,0,0,,,0,0,0,0,,,0,0,0,0,MCLN5-MCLV5
2025-06-11T00:00:37.423556954Z,2025-06-11T00:00:37.423429255Z,10,1,42418117,M,B,0,3.250000000,1,130,17077,79336558,3.250000000,3.280000000,1,1,1,1,3.240000000,3.290000000,11,11,2,2,3.230000000,3.300000000,1,1,1,1,,,0,0,0,0,,,0,0,0,0,,,0,0,0,0,,,0,0,0,0,,,0,0,0,0,,,0,0,0,0,,,0,0,0,0,MCLN5-MCLX5
2025-06-11T00:00:37.530496247Z,2025-06-11T00:00:37.530404447Z,10,1,42022708,M,A,0,2.830000000,10,130,14957,79336584,2.810000000,2.830000000,1,12,1,3,2.800000000,2.840000000,12,2,3,2,2.790000000,2.850000000,2,1,2,1,2.780000000,2.870000000,1,1,1,1,,,0,0,0,0,,,0,0,0,0,,,0,0,0,0,,,0,0,0,0,,,0,0,0,0,,,0,0,0,0,MCLN5-MCLV5
2025-06-11T00:00:37.543050880Z,2025-06-11T00:00:37.542965377Z,10,1,42022708,M,A,0,2.840000000,10,130,14888,79336589,2.810000000,2.830000000,1,2,1,2,2.800000000,2.840000000,12,12,3,3,2.790000000,2.850000000,2,1,2,1,2.780000000,2.870000000,1,1,1,1,,,0,0,0,0,,,0,0,0,0,,,0,0,0,0,,,0,0,0,0,,,0,0,0,0,,,0,0,0,0,MCLN5-MCLV5
2025-06-11T00:00:40.040200833Z,2025-06-11T00:00:40.040090945Z,10,1,42022708,M,A,0,2.830000000,10,130,16381,79336969,2.810000000,2.830000000,1,12,1,3,2.800000000,2.840000000,12,2,3,2,2.790000000,2.850000000,2,1,2,1,2.780000000,2.870000000,1,1,1,1,,,0,0,0,0,,,0,0,0,0,,,0,0,0,0,,,0,0,0,0,,,0,0,0,0,,,0,0,0,0,MCLN5-MCLV5
2025-06-11T00:00:40.214975822Z,2025-06-11T00:00:40.214840353Z,10,1,42022708,M,A,0,2.840000000,10,130,14100,79337021,2.810000000,2.830000000,1,2,1,2,2.800000000,2.840000000,12,12,3,3,2.790000000,2.850000000,2,1,2,1,2.780000000,2.870000000,1,1,1,1,,,0,0,0,0,,,0,0,0,0,,,0,0,0,0,,,0,0,0,0,,,0,0,0,0,,,0,0,0,0,MCLN5-MCLV5
2025-06-11T00:00:40.739627883Z,2025-06-11T00:00:40.739518343Z,10,1,42025611,M,A,1,2.120000000,20,130,15466,79337096,2.070000000,2.080000000,3,5,2,2,2.060000000,2.090000000,27,7,5,5,2.050000000,2.100000000,23,27,3,6,2.040000000,2.110000000,23,23,3,4,2.030000000,2.120000000,2,22,1,2,2.020000000,2.130000000,2,2,2,2,2.010000000,2.140000000,2,2,1,1,2.000000000,2.150000000,2,2,2,1,1.990000000,2.160000000,2,2,1,1,1.980000000,2.170000000,2,2,2,1,MCLN5-MCLU5
2025-06-11T00:00:40.819572972Z,2025-06-11T00:00:40.819204861Z,10,1,42026514,A,A,0,64.780000000,1,130,15114,79337114,64.770000000,64.780000000,4,2,3,2,64.760000000,64.790000000,5,7,5,5,64.750000000,64.800000000,5,8,5,8,64.740000000,64.810000000,11,4,10,4,64.730000000,64.820000000,7,12,7,9,64.720000000,64.830000000,9,8,6,8,64.710000000,64.840000000,8,7,7,6,64.700000000,64.850000000,7,8,6,5,64.690000000,64.860000000,4,4,3,3,64.680000000,64.870000000,4,4,2,3,MCLN5
2025-06-11T00:00:40.828327435Z,2025-06-11T00:00:40.819753285Z,10,1,42022708,M,A,0,2.830000000,10,130,14933,79337152,2.810000000,2.830000000,1,12,1,3,2.800000000,2.840000000,12,2,3,2,2.790000000,2.850000000,2,1,2,1,2.780000000,2.870000000,1,1,1,1,,,0,0,0,0,,,0,0,0,0,,,0,0,0,0,,,0,0,0,0,,,0,0,0,0,,,0,0,0,0,MCLN5-MCLV5
2025-06-11T00:00:40.829250146Z,2025-06-11T00:00:40.828240865Z,10,1,42026514,A,A,0,64.780000000,1,130,17732,79337204,64.770000000,64.780000000,4,3,3,3,64.760000000,64.790000000,5,7,5,5,64.750000000,64.800000000,5,8,5,8,64.740000000,64.810000000,11,4,10,4,64.730000000,64.820000000,7,12,7,9,64.720000000,64.830000000,9,8,6,8,64.710000000,64.840000000,8,7,7,6,64.700000000,64.850000000,7,8,6,5,64.690000000,64.860000000,4,4,3,3,64.680000000,64.870000000,4,4,2,3,MCLN5
2025-06-11T00:00:40.829307159Z,2025-06-11T00:00:40.828523401Z,10,1,42026514,C,A,0,64.780000000,1,130,14185,79337207,64.770000000,64.780000000,4,2,3,2,64.760000000,64.790000000,5,7,5,5,64.750000000,64.800000000,5,8,5,8,64.740000000,64.810000000,11,4,10,4,64.730000000,64.820000000,7,12,7,9,64.720000000,64.830000000,9,8,6,8,64.710000000,64.840000000,8,7,7,6,64.700000000,64.850000000,7,8,6,5,64.690000000,64.860000000,4,4,3,3,64.680000000,64.870000000,4,4,2,3,MCLN5
2025-06-11T00:00:40.829853716Z,2025-06-11T00:00:40.829714745Z,10,1,42026514,C,A,0,64.780000000,1,130,15417,79337228,64.770000000,64.780000000,4,1,3,1,64.760000000,64.790000000,5,7,5,5,64.750000000,64.800000000,5,8,5,8,64.740000000,64.810000000,11,4,10,4,64.730000000,64.820000000,7,12,7,9,64.720000000,64.830000000,9,8,6,8,64.710000000,64.840000000,8,7,7,6,64.700000000,64.850000000,7,8,6,5,64.690000000,64.860000000,4,4,3,3,64.680000000,64.870000000,4,4,2,3,MCLN5
2025-06-11T00:00:40.830167174Z,2025-06-11T00:00:40.829832975Z,10,1,42022708,M,A,0,2.840000000,10,130,11499,79337245,2.810000000,2.830000000,1,2,1,2,2.800000000,2.840000000,12,12,3,3,2.790000000,2.850000000,2,1,2,1,2.780000000,2.870000000,1,1,1,1,,,0,0,0,0,,,0,0,0,0,,,0,0,0,0,,,0,0,0,0,,,0,0,0,0,,,0,0,0,0,MCLN5-MCLV5
2025-06-11T00:00:40.830245306Z,2025-06-11T00:00:40.830110191Z,10,1,42026514,M,B,2,62.790000000,2,130,11496,79337247,64.770000000,64.780000000,4,1,3,1,64.760000000,64.790000000,5,7,5,5,64.750000000,64.800000000,4,8,4,8,64.740000000,64.810000000,11,4,10,4,64.730000000,64.820000000,7,12,7,9,64.720000000,64.830000000,9,8,6,8,64.710000000,64.840000000,8,7,7,6,64.700000000,64.850000000,7,8,6,5,64.690000000,64.860000000,4,4,3,3,64.680000000,64.870000000,4,4,2,3,MCLN5
2025-06-11T00:00:41.373844743Z,2025-06-11T00:00:41.373751451Z,10,1,42022708,M,A,0,2.830000000,10,130,15200,79337509,2.810000000,2.830000000,1,12,1,3,2.800000000,2.840000000,12,2,3,2,2.790000000,2.850000000,2,1,2,1,2.780000000,2.870000000,1,1,1,1,,,0,0,0,0,,,0,0,0,0,,,0,0,0,0,,,0,0,0,0,,,0,0,0,0,,,0,0,0,0,MCLN5-MCLV5
2025-06-11T00:00:42.959598757Z,2025-06-11T00:00:42.959120493Z,10,1,42026514,T,B,0,64.780000000,1,0,15376,79337720,64.770000000,64.780000000,4,1,3,1,64.760000000,64.790000000,5,7,5,5,64.750000000,64.800000000,4,8,4,8,64.740000000,64.810000000,11,4,10,4,64.730000000,64.820000000,7,12,7,9,64.720000000,64.830000000,9,8,6,8,64.710000000,64.840000000,8,7,7,6,64.700000000,64.850000000,7,8,6,5,64.690000000,64.860000000,4,4,3,3,64.680000000,64.870000000,4,4,2,3,MCLN5
2025-06-11T00:00:42.959608978Z,2025-06-11T00:00:42.959120493Z,10,1,42026514,C,A,0,64.780000000,1,130,11675,79337721,64.770000000,64.790000000,4,7,3,5,64.760000000,64.800000000,5,8,5,8,64.750000000,64.810000000,4,4,4,4,64.740000000,64.820000000,11,12,10,9,64.730000000,64.830000000,7,8,7,8,64.720000000,64.840000000,9,7,6,6,64.710000000,64.850000000,8,8,7,5,64.700000000,64.860000000,7,4,6,3,64.690000000,64.870000000,4,4,3,3,64.680000000,64.880000000,4,4,2,3,MCLN5
2025-06-11T00:00:42.959631280Z,2025-06-11T00:00:42.959125907Z,10,1,42026514,A,B,0,64.780000000,1,130,11921,79337723,64.780000000,64.790000000,1,7,1,5,64.770000000,64.800000000,4,8,3,8,64.760000000,64.810000000,5,4,5,4,64.750000000,64.820000000,4,12,4,9,64.740000000,64.830000000,11,8,10,8,64.730000000,64.840000000,7,7,7,6,64.720000000,64.850000000,9,8,6,5,64.710000000,64.860000000,8,4,7,3,64.700000000,64.870000000,7,4,6,3,64.690000000,64.880000000,4,4,3,3,MCLN5
2025-06-11T00:00:42.959672181Z,2025-06-11T00:00:42.959146641Z,10,1,42026514,C,A,0,64.790000000,1,130,13892,79337727,64.780000000,64.790000000,1,6,1,4,64.770000000,64.800000000,4,8,3,8,64.760000000,64.810000000,5,4,5,4,64.750000000,64.820000000,4,12,4,9,64.740000000,64.830000000,11,8,10,8,64.730000000,64.840000000,7,7,7,6,64.720000000,64.850000000,9,8,6,5,64.710000000,64.860000000,8,4,7,3,64.700000000,64.870000000,7,4,6,3,64.690000000,64.880000000,4,4,3,3,MCLN5
2025-06-11T00:00:42.967865013Z,2025-06-11T00:00:42.959214779Z,10,1,42025623,C,A,0,63.700000000,1,130,19916,79337740,63.680000000,63.710000000,2,2,2,2,63.670000000,63.720000000,3,3,3,3,63.660000000,63.730000000,3,2,3,2,63.650000000,63.740000000,3,5,3,5,63.640000000,63.750000000,6,3,6,3,63.630000000,63.760000000,4,5,4,5,63.620000000,63.770000000,5,1,5,1,63.610000000,63.780000000,2,3,2,3,63.600000000,63.790000000,6,1,6,1,63.590000000,63.800000000,1,3,1,3,MCLQ5
2025-06-11T00:00:42.968190627Z,2025-06-11T00:00:42.959641019Z,10,1,42026514,M,A,3,64.830000000,1,130,11424,79337758,64.780000000,64.790000000,1,6,1,4,64.770000000,64.800000000,4,8,3,8,64.760000000,64.810000000,5,4,5,4,64.750000000,64.820000000,4,11,4,8,64.740000000,64.830000000,11,9,10,9,64.730000000,64.840000000,7,7,7,6,64.720000000,64.850000000,9,8,6,5,64.710000000,64.860000000,8,4,7,3,64.700000000,64.870000000,7,4,6,3,64.690000000,64.880000000,4,4,3,3,MCLN5
2025-06-11T00:00:42.968199036Z,2025-06-11T00:00:42.959641517Z,10,1,42026514,M,B,4,64.740000000,1,130,11484,79337759,64.780000000,64.790000000,1,6,1,4,64.770000000,64.800000000,4,8,3,8,64.760000000,64.810000000,5,4,5,4,64.750000000,64.820000000,4,11,4,8,64.740000000,64.830000000,12,9,11,9,64.730000000,64.840000000,6,7,6,6,64.720000000,64.850000000,9,8,6,5,64.710000000,64.860000000,8,4,7,3,64.700000000,64.870000000,7,4,6,3,64.690000000,64.880000000,4,4,3,3,MCLN5
2025-06-11T00:00:42.968208283Z,2025-06-11T00:00:42.959642459Z,10,1,42026514,C,A,5,64.840000000,1,130,12014,79337760,64.780000000,64.790000000,1,6,1,4,64.770000000,64.800000000,4,8,3,8,64.760000000,64.810000000,5,4,5,4,64.750000000,64.820000000,4,11,4,8,64.740000000,64.830000000,12,9,11,9,64.730000000,64.840000000,6,6,6,5,64.720000000,64.850000000,9,8,6,5,64.710000000,64.860000000,8,4,7,3,64.700000000,64.870000000,7,4,6,3,64.690000000,64.880000000,4,4,3,3,MCLN5
2025-06-11T00:00:42.968217621Z,2025-06-11T00:00:42.959644323Z,10,1,42026514,T,A,0,64.780000000,1,0,11679,79337761,64.780000000,64.790000000,1,6,1,4,64.770000000,64.800000000,4,8,3,8,64.760000000,64.810000000,5,4,5,4,64.750000000,64.820000000,4,11,4,8,64.740000000,64.830000000,12,9,11,9,64.730000000,64.840000000,6,6,6,5,64.720000000,64.850000000,9,8,6,5,64.710000000,64.860000000,8,4,7,3,64.700000000,64.870000000,7,4,6,3,64.690000000,64.880000000,4,4,3,3,MCLN5
2025-06-11T00:00:42.968236060Z,2025-06-11T00:00:42.959644323Z,10,1,42026514,C,B,0,64.780000000,1,130,11732,79337762,64.770000000,64.790000000,4,6,3,4,64.760000000,64.800000000,5,8,5,8,64.750000000,64.810000000,4,4,4,4,64.740000000,64.820000000,12,11,11,8,64.730000000,64.830000000,6,9,6,9,64.720000000,64.840000000,9,6,6,5,64.710000000,64.850000000,8,8,7,5,64.700000000,64.860000000,7,4,6,3,64.690000000,64.870000000,4,4,3,3,64.680000000,64.880000000,4,4,2,3,MCLN5
2025-06-11T00:00:42.968254360Z,2025-06-11T00:00:42.959650581Z,10,1,42025623,C,A,5,63.760000000,1,130,11653,79337764,63.680000000,63.710000000,2,2,2,2,63.670000000,63.720000000,3,3,3,3,63.660000000,63.730000000,3,2,3,2,63.650000000,63.740000000,3,5,3,5,63.640000000,63.750000000,6,3,6,3,63.630000000,63.760000000,4,4,4,4,63.620000000,63.770000000,5,1,5,1,63.610000000,63.780000000,2,3,2,3,63.600000000,63.790000000,6,1,6,1,63.590000000,63.800000000,1,3,1,3,MCLQ5
2025-06-11T00:00:42.968264044Z,2025-06-11T00:00:42.959654305Z,10,1,42025623,M,A,3,63.750000000,1,130,11566,79337765,63.680000000,63.710000000,2,2,2,2,63.670000000,63.720000000,3,3,3,3,63.660000000,63.730000000,3,2,3,2,63.650000000,63.740000000,3,4,3,4,63.640000000,63.750000000,6,4,6,4,63.630000000,63.760000000,4,4,4,4,63.620000000,63.770000000,5,1,5,1,63.610000000,63.780000000,2,3,2,3,63.600000000,63.790000000,6,1,6,1,63.590000000,63.800000000,1,3,1,3,MCLQ5
2025-06-11T00:00:42.968276024Z,2025-06-11T00:00:42.959654805Z,10,1,42025623,M,B,3,63.650000000,1,130,15282,79337766,63.680000000,63.710000000,2,2,2,2,63.670000000,63.720000000,3,3,3,3,63.660000000,63.730000000,3,2,3,2,63.650000000,63.740000000,4,4,4,4,63.640000000,63.750000000,5,4,5,4,63.630000000,63.760000000,4,4,4,4,63.620000000,63.770000000,5,1,5,1,63.610000000,63.780000000,2,3,2,3,63.600000000,63.790000000,6,1,6,1,63.590000000,63.800000000,1,3,1,3,MCLQ5
2025-06-11T00:00:42.968284702Z,2025-06-11T00:00:42.959655285Z,10,1,42025623,M,A,3,63.750000000,1,130,11777,79337767,63.680000000,63.710000000,2,2,2,2,63.670000000,63.720000000,3,3,3,3,63.660000000,63.730000000,3,2,3,2,63.650000000,63.740000000,4,3,4,3,63.640000000,63.750000000,5,5,5,5,63.630000000,63.760000000,4,4,4,4,63.620000000,63.770000000,5,1,5,1,63.610000000,63.780000000,2,3,2,3,63.600000000,63.790000000,6,1,6,1,63.590000000,63.800000000,1,3,1,3,MCLQ5
2025-06-11T00:00:42.968295753Z,2025-06-11T00:00:42.959655879Z,10,1,42025623,M,B,3,63.650000000,1,130,11252,79337768,63.680000000,63.710000000,2,2,2,2,63.670000000,63.720000000,3,3,3,3,63.660000000,63.730000000,3,2,3,2,63.650000000,63.740000000,5,3,5,3,63.640000000,63.750000000,4,5,4,5,63.630000000,63.760000000,4,4,4,4,63.620000000,63.770000000,5,1,5,1,63.610000000,63.780000000,2,3,2,3,63.600000000,63.790000000,6,1,6,1,63.590000000,63.800000000,1,3,1,3,MCLQ5
2025-06-11T00:00:42.968306758Z,2025-06-11T00:00:42.959659087Z,10,1,42025623,C,B,6,63.620000000,1,130,12142,79337769,63.680000000,63.710000000,2,2,2,2,63.670000000,63.720000000,3,3,3,3,63.660000000,63.730000000,3,2,3,2,63.650000000,63.740000000,5,3,5,3,63.640000000,63.750000000,4,5,4,5,63.630000000,63.760000000,4,4,4,4,63.620000000,63.770000000,4,1,4,1,63.610000000,63.780000000,2,3,2,3,63.600000000,63.790000000,6,1,6,1,63.590000000,63.800000000,1,3,1,3,MCLQ5
2025-06-11T00:00:42.968966689Z,2025-06-11T00:00:42.959911649Z,10,1,42026514,M,B,2,64.750000000,1,130,12058,79337814,64.770000000,64.790000000,4,6,3,4,64.760000000,64.800000000,5,8,5,8,64.750000000,64.810000000,5,4,5,4,64.740000000,64.820000000,12,11,11,8,64.730000000,64.830000000,6,9,6,9,64.720000000,64.840000000,9,6,6,5,64.710000000,64.850000000,8,8,7,5,64.700000000,64.860000000,7,4,6,3,64.690000000,64.870000000,4,4,3,3,64.680000000,64.880000000,4,4,2,3,MCLN5
2025-06-11T00:00:42.969031128Z,2025-06-11T00:00:42.959996991Z,10,1,42026514,M,A,0,64.790000000,1,130,13560,79337818,64.770000000,64.790000000,4,7,3,5,64.760000000,64.800000000,5,8,5,8,64.750000000,64.810000000,5,4,5,4,64.740000000,64.820000000,12,11,11,8,64.730000000,64.830000000,6,9,6,9,64.720000000,64.840000000,9,6,6,5,64.710000000,64.850000000,8,8,7,5,64.700000000,64.860000000,7,4,6,3,64.690000000,64.870000000,4,4,3,3,64.680000000,64.880000000,4,4,2,3,MCLN5
2025-06-11T00:00:42.969103547Z,2025-06-11T00:00:42.960115313Z,10,1,42025623,A,A,6,63.770000000,1,130,11594,79337825,63.680000000,63.710000000,2,2,2,2,63.670000000,63.720000000,3,3,3,3,63.660000000,63.730000000,3,2,3,2,63.650000000,63.740000000,5,3,5,3,63.640000000,63.750000000,4,5,4,5,63.630000000,63.760000000,4,4,4,4,63.620000000,63.770000000,4,2,4,2,63.610000000,63.780000000,2,3,2,3,63.600000000,63.790000000,6,1,6,1,63.590000000,63.800000000,1,3,1,3,MCLQ5
2025-06-11T00:00:42.969145109Z,2025-06-11T00:00:42.960158053Z,10,1,42025623,A,B,5,63.630000000,1,130,11581,79337829,63.680000000,63.710000000,2,2,2,2,63.670000000,63.720000000,3,3,3,3,63.660000000,63.730000000,3,2,3,2,63.650000000,63.740000000,5,3,5,3,63.640000000,63.750000000,4,5,4,5,63.630000000,63.760000000,5,4,5,4,63.620000000,63.770000000,4,2,4,2,63.610000000,63.780000000,2,3,2,3,63.600000000,63.790000000,6,1,6,1,63.590000000,63.800000000,1,3,1,3,MCLQ5
2025-06-11T00:00:42.969535539Z,2025-06-11T00:00:42.968352211Z,10,1,42026514,C,B,2,64.750000000,1,130,11207,79337851,64.770000000,64.790000000,4,7,3,5,64.760000000,64.800000000,5,8,5,8,64.750000000,64.810000000,4,4,4,4,64.740000000,64.820000000,12,11,11,8,64.730000000,64.830000000,6,9,6,9,64.720000000,64.840000000,9,6,6,5,64.710000000,64.850000000,8,8,7,5,64.700000000,64.860000000,7,4,6,3,64.690000000,64.870000000,4,4,3,3,64.680000000,64.880000000,4,4,2,3,MCLN5
2025-06-11T00:00:42.969680545Z,2025-06-11T00:00:42.969358401Z,10,1,42026514,M,B,1,64.760000000,1,130,12430,79337860,64.770000000,64.790000000,4,7,3,5,64.760000000,64.800000000,6,8,6,8,64.750000000,64.810000000,4,4,4,4,64.740000000,64.820000000,12,11,11,8,64.730000000,64.830000000,6,9,6,9,64.720000000,64.840000000,9,6,6,5,64.710000000,64.850000000,8,8,7,5,64.700000000,64.860000000,7,4,6,3,64.690000000,64.870000000,4,4,3,3,64.680000000,64.880000000,4,4,2,3,MCLN5
2025-06-11T00:00:42.982025335Z,2025-06-11T00:00:42.981917621Z,10,1,42026514,A,A,5,64.840000000,1,130,11682,79337949,64.770000000,64.790000000,4,7,3,5,64.760000000,64.800000000,6,8,6,8,64.750000000,64.810000000,4,4,4,4,64.740000000,64.820000000,12,11,11,8,64.730000000,64.830000000,6,9,6,9,64.720000000,64.840000000,9,7,6,6,64.710000000,64.850000000,8,8,7,5,64.700000000,64.860000000,7,4,6,3,64.690000000,64.870000000,4,4,3,3,64.680000000,64.880000000,4,4,2,3,MCLN5
2025-06-11T00:00:44.976447378Z,2025-06-11T00:00:44.976338655Z,10,1,42026514,M,B,3,64.730000000,1,130,15342,79338131,64.770000000,64.790000000,4,7,3,5,64.760000000,64.800000000,6,8,6,8,64.750000000,64.810000000,4,4,4,4,64.740000000,64.820000000,11,11,10,8,64.730000000,64.830000000,7,9,7,9,64.720000000,64.840000000,9,7,6,6,64.710000000,64.850000000,8,8,7,5,64.700000000,64.860000000,7,4,6,3,64.690000000,64.870000000,4,4,3,3,64.680000000,64.880000000,4,4,2,3,MCLN5
2025-06-11T00:00:44.976455357Z,2025-06-11T00:00:44.976339135Z,10,1,42026514,M,A,3,64.820000000,1,130,11403,79338132,64.770000000,64.790000000,4,7,3,5,64.760000000,64.800000000,6,8,6,8,64.750000000,64.810000000,4,4,4,4,64.740000000,64.820000000,11,12,10,9,64.730000000,64.830000000,7,8,7,8,64.720000000,64.840000000,9,7,6,6,64.710000000,64.850000000,8,8,7,5,64.700000000,64.860000000,7,4,6,3,64.690000000,64.870000000,4,4,3,3,64.680000000,64.880000000,4,4,2,3,MCLN5
2025-06-11T00:00:44.976464642Z,2025-06-11T00:00:44.976340421Z,10,1,42022708,M,A,0,2.840000000,10,130,11457,79338133,2.810000000,2.830000000,1,2,1,2,2.800000000,2.840000000,12,12,3,3,2.790000000,2.850000000,2,1,2,1,2.780000000,2.870000000,1,1,1,1,,,0,0,0,0,,,0,0,0,0,,,0,0,0,0,,,0,0,0,0,,,0,0,0,0,,,0,0,0,0,MCLN5-MCLV5
2025-06-11T00:00:46.305793402Z,2025-06-11T00:00:46.305468337Z,10,1,42026514,A,B,0,64.770000000,1,130,14038,79338245,64.770000000,64.790000000,5,7,4,5,64.760000000,64.800000000,6,8,6,8,64.750000000,64.810000000,4,4,4,4,64.740000000,64.820000000,11,12,10,9,64.730000000,64.830000000,7,8,7,8,64.720000000,64.840000000,9,7,6,6,64.710000000,64.850000000,8,8,7,5,64.700000000,64.860000000,7,4,6,3,64.690000000,64.870000000,4,4,3,3,64.680000000,64.880000000,4,4,2,3,MCLN5
2025-06-11T00:00:46.306130390Z,2025-06-11T00:00:46.305872171Z,10,1,42022708,M,A,0,2.830000000,10,130,12099,79338260,2.810000000,2.830000000,1,12,1,3,2.800000000,2.840000000,12,2,3,2,2.790000000,2.850000000,2,1,2,1,2.780000000,2.870000000,1,1,1,1,,,0,0,0,0,,,0,0,0,0,,,0,0,0,0,,,0,0,0,0,,,0,0,0,0,,,0,0,0,0,MCLN5-MCLV5
2025-06-11T00:00:46.306180730Z,2025-06-11T00:00:46.305961333Z,10,1,42026514,M,B,0,64.770000000,1,130,14224,79338264,64.770000000,64.790000000,6,7,5,5,64.760000000,64.800000000,6,8,6,8,64.750000000,64.810000000,4,4,4,4,64.740000000,64.820000000,11,12,10,9,64.730000000,64.830000000,7,8,7,8,64.720000000,64.840000000,9,7,6,6,64.710000000,64.850000000,8,8,7,5,64.700000000,64.860000000,7,4,6,3,64.690000000,64.870000000,4,4,3,3,64.680000000,64.880000000,4,4,2,3,MCLN5
2025-06-11T00:00:46.306319770Z,2025-06-11T00:00:46.306072381Z,10,1,42025623,A,B,0,63.690000000,1,130,12546,79338274,63.690000000,63.710000000,1,2,1,2,63.680000000,63.720000000,2,3,2,3,63.670000000,63.730000000,3,2,3,2,63.660000000,63.740000000,3,3,3,3,63.650000000,63.750000000,5,5,5,5,63.640000000,63.760000000,4,4,4,4,63.630000000,63.770000000,5,2,5,2,63.620000000,63.780000000,4,3,4,3,63.610000000,63.790000000,2,1,2,1,63.600000000,63.800000000,6,3,6,3,MCLQ5
2025-06-11T00:00:46.314905288Z,2025-06-11T00:00:46.306330417Z,10,1,42026514,M,A,3,64.830000000,1,130,11667,79338307,64.770000000,64.790000000,6,7,5,5,64.760000000,64.800000000,6,8,6,8,64.750000000,64.810000000,4,4,4,4,64.740000000,64.820000000,11,11,10,8,64.730000000,64.830000000,7,9,7,9,64.720000000,64.840000000,9,7,6,6,64.710000000,64.850000000,8,8,7,5,64.700000000,64.860000000,7,4,6,3,64.690000000,64.870000000,4,4,3,3,64.680000000,64.880000000,4,4,2,3,MCLN5
2025-06-11T00:00:46.314918351Z,2025-06-11T00:00:46.306330937Z,10,1,42026514,M,B,3,64.740000000,1,130,10980,79338308,64.770000000,64.790000000,6,7,5,5,64.760000000,64.800000000,6,8,6,8,64.750000000,64.810000000,4,4,4,4,64.740000000,64.820000000,12,11,11,8,64.730000000,64.830000000,6,9,6,9,64.720000000,64.840000000,9,7,6,6,64.710000000,64.850000000,8,8,7,5,64.700000000,64.860000000,7,4,6,3,64.690000000,64.870000000,4,4,3,3,64.680000000,64.880000000,4,4,2,3,MCLN5
2025-06-11T00:00:46.315104313Z,2025-06-11T00:00:46.306532391Z,10,1,42026514,M,A,0,66.740000000,2,130,12569,79338319,64.770000000,64.790000000,6,6,5,4,64.760000000,64.800000000,6,8,6,8,64.750000000,64.810000000,4,4,4,4,64.740000000,64.820000000,12,11,11,8,64.730000000,64.830000000,6,9,6,9,64.720000000,64.840000000,9,7,6,6,64.710000000,64.850000000,8,8,7,5,64.700000000,64.860000000,7,4,6,3,64.690000000,64.870000000,4,4,3,3,64.680000000,64.880000000,4,4,2,3,MCLN5
2025-06-11T00:00:46.315123582Z,2025-06-11T00:00:46.306548271Z,10,1,42026514,C,B,0,64.770000000,1,130,13649,79338320,64.770000000,64.790000000,5,6,4,4,64.760000000,64.800000000,6,8,6,8,64.750000000,64.810000000,4,4,4,4,64.740000000,64.820000000,12,11,11,8,64.730000000,64.830000000,6,9,6,9,64.720000000,64.840000000,9,7,6,6,64.710000000,64.850000000,8,8,7,5,64.700000000,64.860000000,7,4,6,3,64.690000000,64.870000000,4,4,3,3,64.680000000,64.880000000,4,4,2,3,MCLN5
2025-06-11T00:00:46.315862358Z,2025-06-11T00:00:46.315256217Z,10,1,42418117,M,A,0,3.280000000,10,130,14773,79338362,3.250000000,3.280000000,1,11,1,2,3.240000000,3.290000000,11,1,2,1,3.230000000,3.300000000,1,1,1,1,,,0,0,0,0,,,0,0,0,0,,,0,0,0,0,,,0,0,0,0,,,0,0,0,0,,,0,0,0,0,,,0,0,0,0,MCLN5-MCLX5
2025-06-11T00:00:46.316049948Z,2025-06-11T00:00:46.315733087Z,10,1,42026514,M,B,0,62.810000000,2,130,15247,79338376,64.770000000,64.790000000,4,6,3,4,64.760000000,64.800000000,6,8,6,8,64.750000000,64.810000000,4,4,4,4,64.740000000,64.820000000,12,11,11,8,64.730000000,64.830000000,6,9,6,9,64.720000000,64.840000000,9,7,6,6,64.710000000,64.850000000,8,8,7,5,64.700000000,64.860000000,7,4,6,3,64.690000000,64.870000000,4,4,3,3,64.680000000,64.880000000,4,4,2,3,MCLN5
2025-06-11T00:00:46.316412348Z,2025-06-11T00:00:46.316027659Z,10,1,42026514,A,A,0,64.780000000,1,130,11333,79338397,64.770000000,64.780000000,4,1,3,1,64.760000000,64.790000000,6,6,6,4,64.750000000,64.800000000,4,8,4,8,64.740000000,64.810000000,12,4,11,4,64.730000000,64.820000000,6,11,6,8,64.720000000,64.830000000,9,9,6,9,64.710000000,64.840000000,8,7,7,6,64.700000000,64.850000000,7,8,6,5,64.690000000,64.860000000,4,4,3,3,64.680000000,64.870000000,4,4,2,3,MCLN5
2025-06-11T00:00:46.316431432Z,2025-06-11T00:00:46.316028523Z,10,1,42025623,C,B,0,63.690000000,1,130,12942,79338399,63.680000000,63.710000000,2,2,2,2,63.670000000,63.720000000,3,3,3,3,63.660000000,63.730000000,3,2,3,2,63.650000000,63.740000000,5,3,5,3,63.640000000,63.750000000,4,5,4,5,63.630000000,63.760000000,5,4,5,4,63.620000000,63.770000000,4,2,4,2,63.610000000,63.780000000,2,3,2,3,63.600000000,63.790000000,6,1,6,1,63.590000000,63.800000000,1,3,1,3,MCLQ5
2025-06-11T00:00:46.316966177Z,2025-06-11T00:00:46.316429899Z,10,1,42026514,A,A,0,64.780000000,1,130,12133,79338433,64.770000000,64.780000000,4,2,3,2,64.760000000,64.790000000,6,6,6,4,64.750000000,64.800000000,4,8,4,8,64.740000000,64.810000000,12,4,11,4,64.730000000,64.820000000,6,11,6,8,64.720000000,64.830000000,9,9,6,9,64.710000000,64.840000000,8,7,7,6,64.700000000,64.850000000,7,8,6,5,64.690000000,64.860000000,4,4,3,3,64.680000000,64.870000000,4,4,2,3,MCLN5
2025-06-11T00:00:46.317017308Z,2025-06-11T00:00:46.316439659Z,10,1,42025623,M,B,3,63.640000000,1,130,11842,79338436,63.680000000,63.710000000,2,2,2,2,63.670000000,63.720000000,3,3,3,3,63.660000000,63.730000000,3,2,3,2,63.650000000,63.740000000,4,3,4,3,63.640000000,63.750000000,5,5,5,5,63.630000000,63.760000000,5,4,5,4,63.620000000,63.770000000,4,2,4,2,63.610000000,63.780000000,2,3,2,3,63.600000000,63.790000000,6,1,6,1,63.590000000,63.800000000,1,3,1,3,MCLQ5
2025-06-11T00:00:46.317030371Z,2025-06-11T00:00:46.316440095Z,10,1,42025623,M,A,3,63.740000000,1,130,11728,79338437,63.680000000,63.710000000,2,2,2,2,63.670000000,63.720000000,3,3,3,3,63.660000000,63.730000000,3,2,3,2,63.650000000,63.740000000,4,4,4,4,63.640000000,63.750000000,5,4,5,4,63.630000000,63.760000000,5,4,5,4,63.620000000,63.770000000,4,2,4,2,63.610000000,63.780000000,2,3,2,3,63.600000000,63.790000000,6,1,6,1,63.590000000,63.800000000,1,3,1,3,MCLQ5
2025-06-11T00:00:46.317043849Z,2025-06-11T00:00:46.316440517Z,10,1,42025623,M,B,3,63.640000000,1,130,15010,79338438,63.680000000,63.710000000,2,2,2,2,63.670000000,63.720000000,3,3,3,3,63.660000000,63.730000000,3,2,3,2,63.650000000,63.740000000,3,4,3,4,63.640000000,63.750000000,6,4,6,4,63.630000000,63.760000000,5,4,5,4,63.620000000,63.770000000,4,2,4,2,63.610000000,63.780000000,2,3,2,3,63.600000000,63.790000000,6,1,6,1,63.590000000,63.800000000,1,3,1,3,MCLQ5
2025-06-11T00:00:46.317053218Z,2025-06-11T00:00:46.316441055Z,10,1,42025623,M,A,3,63.740000000,1,130,11493,79338439,63.680000000,63.710000000,2,2,2,2,63.670000000,63.720000000,3,3,3,3,63.660000000,63.730000000,3,2,3,2,63.650000000,63.740000000,3,5,3,5,63.640000000,63.750000000,6,3,6,3,63.630000000,63.760000000,5,4,5,4,63.620000000,63.770000000,4,2,4,2,63.610000000,63.780000000,2,3,2,3,63.600000000,63.790000000,6,1,6,1,63.590000000,63.800000000,1,3,1,3,MCLQ5
2025-06-11T00:00:46.317061166Z,2025-06-11T00:00:46.316441343Z,10,1,42025623,C,B,5,63.630000000,1,130,11286,79338440,63.680000000,63.710000000,2,2,2,2,63.670000000,63.720000000,3,3,3,3,63.660000000,63.730000000,3,2,3,2,63.650000000,63.740000000,3,5,3,5,63.640000000,63.750000000,6,3,6,3,63.630000000,63.760000000,4,4,4,4,63.620000000,63.770000000,4,2,4,2,63.610000000,63.780000000,2,3,2,3,63.600000000,63.790000000,6,1,6,1,63.590000000,63.800000000,1,3,1,3,MCLQ5
2025-06-11T00:00:46.317120875Z,2025-06-11T00:00:46.316529659Z,10,1,42026514,M,B,3,64.730000000,1,130,14133,79338443,64.770000000,64.780000000,4,2,3,2,64.760000000,64.790000000,6,6,6,4,64.750000000,64.800000000,4,8,4,8,64.740000000,64.810000000,11,4,10,4,64.730000000,64.820000000,7,11,7,8,64.720000000,64.830000000,9,9,6,9,64.710000000,64.840000000,8,7,7,6,64.700000000,64.850000000,7,8,6,5,64.690000000,64.860000000,4,4,3,3,64.680000000,64.870000000,4,4,2,3,MCLN5
2025-06-11T00:00:46.317132356Z,2025-06-11T00:00:46.316530177Z,10,1,42026514,M,A,4,64.820000000,1,130,12357,79338444,64.770000000,64.780000000,4,2,3,2,64.760000000,64.790000000,6,6,6,4,64.750000000,64.800000000,4,8,4,8,64.740000000,64.810000000,11,4,10,4,64.730000000,64.820000000,7,12,7,9,64.720000000,64.830000000,9,8,6,8,64.710000000,64.840000000,8,7,7,6,64.700000000,64.850000000,7,8,6,5,64.690000000,64.860000000,4,4,3,3,64.680000000,64.870000000,4,4,2,3,MCLN5
2025-06-11T00:00:46.317426008Z,2025-06-11T00:00:46.316635177Z,10,1,42026514,M,B,1,62.800000000,2,130,13276,79338462,64.770000000,64.780000000,4,2,3,2,64.760000000,64.790000000,5,6,5,4,64.750000000,64.800000000,4,8,4,8,64.740000000,64.810000000,11,4,10,4,64.730000000,64.820000000,7,12,7,9,64.720000000,64.830000000,9,8,6,8,64.710000000,64.840000000,8,7,7,6,64.700000000,64.850000000,7,8,6,5,64.690000000,64.860000000,4,4,3,3,64.680000000,64.870000000,4,4,2,3,MCLN5
2025-06-11T00:00:46.318900906Z,2025-06-11T00:00:46.318031647Z,10,1,42026514,C,A,0,64.780000000,1,130,11606,79338553,64.770000000,64.780000000,4,1,3,1,64.760000000,64.790000000,5,6,5,4,64.750000000,64.800000000,4,8,4,8,64.740000000,64.810000000,11,4,10,4,64.730000000,64.820000000,7,12,7,9,64.720000000,64.830000000,9,8,6,8,64.710000000,64.840000000,8,7,7,6,64.700000000,64.850000000,7,8,6,5,64.690000000,64.860000000,4,4,3,3,64.680000000,64.870000000,4,4,2,3,MCLN5
2025-06-11T00:00:46.318961245Z,2025-06-11T00:00:46.318115567Z,10,1,42418117,M,B,0,3.220000000,1,130,11484,79338559,3.240000000,3.280000000,11,11,2,2,3.230000000,3.290000000,1,1,1,1,3.220000000,3.300000000,1,1,1,1,,,0,0,0,0,,,0,0,0,0,,,0,0,0,0,,,0,0,0,0,,,0,0,0,0,,,0,0,0,0,,,0,0,0,0,MCLN5-MCLX5
2025-06-11T00:00:46.319371465Z,2025-06-11T00:00:46.318588039Z,10,1,42418117,M,A,0,3.290000000,10,130,11519,79338583,3.240000000,3.280000000,11,1,2,1,3.230000000,3.290000000,1,11,1,2,3.220000000,3.300000000,1,1,1,1,,,0,0,0,0,,,0,0,0,0,,,0,0,0,0,,,0,0,0,0,,,0,0,0,0,,,0,0,0,0,,,0,0,0,0,MCLN5-MCLX5
2025-06-11T00:00:46.327334983Z,2025-06-11T00:00:46.327208247Z,10,1,42026514,C,A,0,64.780000000,1,130,15072,79338622,64.770000000,64.790000000,4,6,3,4,64.760000000,64.800000000,5,8,5,8,64.750000000,64.810000000,4,4,4,4,64.740000000,64.820000000,11,12,10,9,64.730000000,64.830000000,7,8,7,8,64.720000000,64.840000000,9,7,6,6,64.710000000,64.850000000,8,8,7,5,64.700000000,64.860000000,7,4,6,3,64.690000000,64.870000000,4,4,3,3,64.680000000,64.880000000,4,4,2,3,MCLN5
2025-06-11T00:00:46.327449501Z,2025-06-11T00:00:46.327348475Z,10,1,42025623,A,B,6,63.620000000,1,130,14613,79338625,63.680000000,63.710000000,2,2,2,2,63.670000000,63.720000000,3,3,3,3,63.660000000,63.730000000,3,2,3,2,63.650000000,63.740000000,3,5,3,5,63.640000000,63.750000000,6,3,6,3,63.630000000,63.760000000,4,4,4,4,63.620000000,63.770000000,5,2,5,2,63.610000000,63.780000000,2,3,2,3,63.600000000,63.790000000,6,1,6,1,63.590000000,63.800000000,1,3,1,3,MCLQ5
2025-06-11T00:00:46.327457980Z,2025-06-11T00:00:46.327350895Z,10,1,42025623,C,A,6,63.770000000,1,130,11246,79338626,63.680000000,63.710000000,2,2,2,2,63.670000000,63.720000000,3,3,3,3,63.660000000,63.730000000,3,2,3,2,63.650000000,63.740000000,3,5,3,5,63.640000000,63.750000000,6,3,6,3,63.630000000,63.760000000,4,4,4,4,63.620000000,63.770000000,5,1,5,1,63.610000000,63.780000000,2,3,2,3,63.600000000,63.790000000,6,1,6,1,63.590000000,63.800000000,1,3,1,3,MCLQ5
2025-06-11T00:00:46.327582919Z,2025-06-11T00:00:46.327486845Z,10,1,42025623,C,B,6,63.620000000,1,130,14555,79338627,63.680000000,63.710000000,2,2,2,2,63.670000000,63.720000000,3,3,3,3,63.660000000,63.730000000,3,2,3,2,63.650000000,63.740000000,3,5,3,5,63.640000000,63.750000000,6,3,6,3,63.630000000,63.760000000,4,4,4,4,63.620000000,63.770000000,4,1,4,1,63.610000000,63.780000000,2,3,2,3,63.600000000,63.790000000,6,1,6,1,63.590000000,63.800000000,1,3,1,3,MCLQ5
2025-06-11T00:00:46.327592726Z,2025-06-11T00:00:46.327494697Z,10,1,42025623,A,A,6,63.770000000,1,130,11287,79338628,63.680000000,63.710000000,2,2,2,2,63.670000000,63.720000000,3,3,3,3,63.660000000,63.730000000,3,2,3,2,63.650000000,63.740000000,3,5,3,5,63.640000000,63.750000000,6,3,6,3,63.630000000,63.760000000,4,4,4,4,63.620000000,63.770000000,4,2,4,2,63.610000000,63.780000000,2,3,2,3,63.600000000,63.790000000,6,1,6,1,63.590000000,63.800000000,1,3,1,3,MCLQ5
2025-06-11T00:00:46.327607033Z,2025-06-11T00:00:46.327501245Z,10,1,42026514,M,A,1,66.750000000,2,130,11377,79338629,64.770000000,64.790000000,4,6,3,4,64.760000000,64.800000000,5,7,5,7,64.750000000,64.810000000,4,4,4,4,64.740000000,64.820000000,11,12,10,9,64.730000000,64.830000000,7,8,7,8,64.720000000,64.840000000,9,7,6,6,64.710000000,64.850000000,8,8,7,5,64.700000000,64.860000000,7,4,6,3,64.690000000,64.870000000,4,4,3,3,64.680000000,64.880000000,4,4,2,3,MCLN5
2025-06-11T00:00:46.327622224Z,2025-06-11T00:00:46.327519943Z,10,1,42026514,M,A,1,66.760000000,2,130,11933,79338630,64.770000000,64.790000000,4,6,3,4,64.760000000,64.800000000,5,6,5,6,64.750000000,64.810000000,4,4,4,4,64.740000000,64.820000000,11,12,10,9,64.730000000,64.830000000,7,8,7,8,64.720000000,64.840000000,9,7,6,6,64.710000000,64.850000000,8,8,7,5,64.700000000,64.860000000,7,4,6,3,64.690000000,64.870000000,4,4,3,3,64.680000000,64.880000000,4,4,2,3,MCLN5
2025-06-11T00:00:46.327696647Z,2025-06-11T00:00:46.327603405Z,10,1,42025623,A,B,5,63.630000000,1,130,14814,79338631,63.680000000,63.710000000,2,2,2,2,63.670000000,63.720000000,3,3,3,3,63.660000000,63.730000000,3,2,3,2,63.650000000,63.740000000,3,5,3,5,63.640000000,63.750000000,6,3,6,3,63.630000000,63.760000000,5,4,5,4,63.620000000,63.770000000,4,2,4,2,63.610000000,63.780000000,2,3,2,3,63.600000000,63.790000000,6,1,6,1,63.590000000,63.800000000,1,3,1,3,MCLQ5
2025-06-11T00:00:46.347346681Z,2025-06-11T00:00:46.347247301Z,10,1,42022708,M,A,0,2.840000000,10,130,15967,79338657,2.810000000,2.830000000,1,2,1,2,2.800000000,2.840000000,12,12,3,3,2.790000000,2.850000000,2,1,2,1,2.780000000,2.870000000,1,1,1,1,,,0,0,0,0,,,0,0,0,0,,,0,0,0,0,,,0,0,0,0,,,0,0,0,0,,,0,0,0,0,MCLN5-MCLV5
2025-06-11T00:00:46.430708304Z,2025-06-11T00:00:46.430566819Z,10,1,42026514,A,A,0,64.780000000,1,130,15060,79338682,64.770000000,64.780000000,4,1,3,1,64.760000000,64.790000000,5,6,5,4,64.750000000,64.800000000,4,6,4,6,64.740000000,64.810000000,11,4,10,4,64.730000000,64.820000000,7,12,7,9,64.720000000,64.830000000,9,8,6,8,64.710000000,64.840000000,8,7,7,6,64.700000000,64.850000000,7,8,6,5,64.690000000,64.860000000,4,4,3,3,64.680000000,64.870000000,4,4,2,3,MCLN5
2025-06-11T00:00:46.430823905Z,2025-06-11T00:00:46.430729377Z,10,1,42025623,C,B,5,63.630000000,1,130,15553,79338685,63.680000000,63.710000000,2,2,2,2,63.670000000,63.720000000,3,3,3,3,63.660000000,63.730000000,3,2,3,2,63.650000000,63.740000000,3,5,3,5,63.640000000,63.750000000,6,3,6,3,63.630000000,63.760000000,4,4,4,4,63.620000000,63.770000000,4,2,4,2,63.610000000,63.780000000,2,3,2,3,63.600000000,63.790000000,6,1,6,1,63.590000000,63.800000000,1,3,1,3,MCLQ5
2025-06-11T00:00:46.430835056Z,2025-06-11T00:00:46.430734313Z,10,1,42025623,C,A,6,63.770000000,1,130,11305,79338686,63.680000000,63.710000000,2,2,2,2,63.670000000,63.720000000,3,3,3,3,63.660000000,63.730000000,3,2,3,2,63.650000000,63.740000000,3,5,3,5,63.640000000,63.750000000,6,3,6,3,63.630000000,63.760000000,4,4,4,4,63.620000000,63.770000000,4,1,4,1,63.610000000,63.780000000,2,3,2,3,63.600000000,63.790000000,6,1,6,1,63.590000000,63.800000000,1,3,1,3,MCLQ5
2025-06-11T00:00:46.430942516Z,2025-06-11T00:00:46.430843709Z,10,1,42025623,A,B,6,63.620000000,1,130,15217,79338687,63.680000000,63.710000000,2,2,2,2,63.670000000,63.720000000,3,3,3,3,63.660000000,63.730000000,3,2,3,2,63.650000000,63.740000000,3,5,3,5,63.640000000,63.750000000,6,3,6,3,63.630000000,63.760000000,4,4,4,4,63.620000000,63.770000000,5,1,5,1,63.610000000,63.780000000,2,3,2,3,63.600000000,63.790000000,6,1,6,1,63.590000000,63.800000000,1,3,1,3,MCLQ5
2025-06-11T00:00:46.430950564Z,2025-06-11T00:00:46.430857455Z,10,1,42025623,A,A,5,63.760000000,1,130,11433,79338688,63.680000000,63.710000000,2,2,2,2,63.670000000,63.720000000,3,3,3,3,63.660000000,63.730000000,3,2,3,2,63.650000000,63.740000000,3,5,3,5,63.640000000,63.750000000,6,3,6,3,63.630000000,63.760000000,4,5,4,5,63.620000000,63.770000000,5,1,5,1,63.610000000,63.780000000,2,3,2,3,63.600000000,63.790000000,6,1,6,1,63.590000000,63.800000000,1,3,1,3,MCLQ5
2025-06-11T00:00:46.430966584Z,2025-06-11T00:00:46.430864751Z,10,1,42026514,M,A,2,64.800000000,2,130,11435,79338689,64.770000000,64.780000000,4,1,3,1,64.760000000,64.790000000,5,6,5,4,64.750000000,64.800000000,4,8,4,7,64.740000000,64.810000000,11,4,10,4,64.730000000,64.820000000,7,12,7,9,64.720000000,64.830000000,9,8,6,8,64.710000000,64.840000000,8,7,7,6,64.700000000,64.850000000,7,8,6,5,64.690000000,64.860000000,4,4,3,3,64.680000000,64.870000000,4,4,2,3,MCLN5
2025-06-11T00:00:46.606953438Z,2025-06-11T00:00:46.606862235Z,10,1,42022708,M,A,0,2.830000000,10,130,15137,79338734,2.810000000,2.830000000,1,12,1,3,2.800000000,2.840000000,12,2,3,2,2.790000000,2.850000000,2,1,2,1,2.780000000,2.870000000,1,1,1,1,,,0,0,0,0,,,0,0,0,0,,,0,0,0,0,,,0,0,0,0,,,0,0,0,0,,,0,0,0,0,MCLN5-MCLV5
2025-06-11T00:00:46.924940348Z,2025-06-11T00:00:46.924816383Z,10,1,42418117,M,B,0,3.250000000,1,130,17491,79338805,3.250000000,3.280000000,1,1,1,1,3.240000000,3.290000000,11,11,2,2,3.230000000,3.300000000,1,1,1,1,,,0,0,0,0,,,0,0,0,0,,,0,0,0,0,,,0,0,0,0,,,0,0,0,0,,,0,0,0,0,,,0,0,0,0,MCLN5-MCLX5
2025-06-11T00:00:47.017553494Z,2025-06-11T00:00:47.017432877Z,10,1,42175560,M,B,0,2.980000000,10,130,19241,79338816,2.980000000,4.030000000,10,10,1,1,,,0,0,0,0,,,0,0,0,0,,,0,0,0,0,,,0,0,0,0,,,0,0,0,0,,,0,0,0,0,,,0,0,0,0,,,0,0,0,0,,,0,0,0,0,MCLN5-MCLZ5
2025-06-11T00:00:47.117955486Z,2025-06-11T00:00:47.117847125Z,10,1,42175560,M,B,0,3.200000000,10,130,18200,79338818,3.200000000,4.030000000,10,10,1,1,,,0,0,0,0,,,0,0,0,0,,,0,0,0,0,,,0,0,0,0,,,0,0,0,0,,,0,0,0,0,,,0,0,0,0,,,0,0,0,0,,,0,0,0,0,MCLN5-MCLZ5
2025-06-11T00:00:50.638479397Z,2025-06-11T00:00:50.638160489Z,10,1,42026514,A,A,0,64.780000000,1,130,11552,79338995,64.770000000,64.780000000,4,2,3,2,64.760000000,64.790000000,5,6,5,4,64.750000000,64.800000000,4,8,4,7,64.740000000,64.810000000,11,4,10,4,64.730000000,64.820000000,7,12,7,9,64.720000000,64.830000000,9,8,6,8,64.710000000,64.840000000,8,7,7,6,64.700000000,64.850000000,7,8,6,5,64.690000000,64.860000000,4,4,3,3,64.680000000,64.870000000,4,4,2,3,MCLN5
2025-06-11T00:00:50.646965380Z,2025-06-11T00:00:50.638639027Z,10,1,42026514,C,B,0,64.770000000,1,130,13653,79339017,64.770000000,64.780000000,3,2,2,2,64.760000000,64.790000000,5,6,5,4,64.750000000,64.800000000,4,8,4,7,64.740000000,64.810000000,11,4,10,4,64.730000000,64.820000000,7,12,7,9,64.720000000,64.830000000,9,8,6,8,64.710000000,64.840000000,8,7,7,6,64.700000000,64.850000000,7,8,6,5,64.690000000,64.860000000,4,4,3,3,64.680000000,64.870000000,4,4,2,3,MCLN5
2025-06-11T00:00:50.646987382Z,2025-06-11T00:00:50.638646745Z,10,1,42026514,A,A,0,64.780000000,1,130,15604,79339018,64.770000000,64.780000000,3,3,2,3,64.760000000,64.790000000,5,6,5,4,64.750000000,64.800000000,4,8,4,7,64.740000000,64.810000000,11,4,10,4,64.730000000,64.820000000,7,12,7,9,64.720000000,64.830000000,9,8,6,8,64.710000000,64.840000000,8,7,7,6,64.700000000,64.850000000,7,8,6,5,64.690000000,64.860000000,4,4,3,3,64.680000000,64.870000000,4,4,2,3,MCLN5
2025-06-11T00:00:50.647251959Z,2025-06-11T00:00:50.638667539Z,10,1,42026514,A,A,0,64.780000000,1,130,11281,79339031,64.770000000,64.780000000,3,4,2,4,64.760000000,64.790000000,5,6,5,4,64.750000000,64.800000000,4,8,4,7,64.740000000,64.810000000,11,4,10,4,64.730000000,64.820000000,7,12,7,9,64.720000000,64.830000000,9,8,6,8,64.710000000,64.840000000,8,7,7,6,64.700000000,64.850000000,7,8,6,5,64.690000000,64.860000000,4,4,3,3,64.680000000,64.870000000,4,4,2,3,MCLN5
2025-06-11T00:00:50.647311130Z,2025-06-11T00:00:50.638669533Z,10,1,42026514,C,B,0,64.770000000,2,130,17613,79339034,64.770000000,64.780000000,1,4,1,4,64.760000000,64.790000000,5,6,5,4,64.750000000,64.800000000,4,8,4,7,64.740000000,64.810000000,11,4,10,4,64.730000000,64.820000000,7,12,7,9,64.720000000,64.830000000,9,8,6,8,64.710000000,64.840000000,8,7,7,6,64.700000000,64.850000000,7,8,6,5,64.690000000,64.860000000,4,4,3,3,64.680000000,64.870000000,4,4,2,3,MCLN5
2025-06-11T00:00:50.647326927Z,2025-06-11T00:00:50.638669995Z,10,1,42026514,C,B,0,64.770000000,1,130,11567,79339035,64.760000000,64.780000000,5,4,5,4,64.750000000,64.790000000,4,6,4,4,64.740000000,64.800000000,11,8,10,7,64.730000000,64.810000000,7,4,7,4,64.720000000,64.820000000,9,12,6,9,64.710000000,64.830000000,8,8,7,8,64.700000000,64.840000000,7,7,6,6,64.690000000,64.850000000,4,8,3,5,64.680000000,64.860000000,4,4,2,3,64.670000000,64.870000000,6,4,4,3,MCLN5
2025-06-11T00:00:50.647441968Z,2025-06-11T00:00:50.638673145Z,10,1,42025623,A,A,0,63.700000000,1,130,12063,79339042,63.680000000,63.700000000,2,1,2,1,63.670000000,63.710000000,3,2,3,2,63.660000000,63.720000000,3,3,3,3,63.650000000,63.730000000,3,2,3,2,63.640000000,63.740000000,6,5,6,5,63.630000000,63.750000000,4,3,4,3,63.620000000,63.760000000,5,5,5,5,63.610000000,63.770000000,2,1,2,1,63.600000000,63.780000000,6,3,6,3,63.590000000,63.790000000,1,1,1,1,MCLQ5
2025-06-11T00:00:50.649340417Z,2025-06-11T00:00:50.639416055Z,10,1,42026514,M,A,1,64.790000000,1,130,11710,79339137,64.760000000,64.780000000,5,4,5,4,64.750000000,64.790000000,4,7,4,5,64.740000000,64.800000000,11,8,10,7,64.730000000,64.810000000,7,4,7,4,64.720000000,64.820000000,9,12,6,9,64.710000000,64.830000000,8,8,7,8,64.700000000,64.840000000,7,7,6,6,64.690000000,64.850000000,4,8,3,5,64.680000000,64.860000000,4,4,2,3,64.670000000,64.870000000,6,4,4,3,MCLN5
2025-06-11T00:00:50.649362311Z,2025-06-11T00:00:50.639437635Z,10,1,42026514,A,A,0,64.780000000,1,130,13630,79339138,64.760000000,64.780000000,5,5,5,5,64.750000000,64.790000000,4,7,4,5,64.740000000,64.800000000,11,8,10,7,64.730000000,64.810000000,7,4,7,4,64.720000000,64.820000000,9,12,6,9,64.710000000,64.830000000,8,8,7,8,64.700000000,64.840000000,7,7,6,6,64.690000000,64.850000000,4,8,3,5,64.680000000,64.860000000,4,4,2,3,64.670000000,64.870000000,6,4,4,3,MCLN5
2025-06-11T00:00:50.649909929Z,2025-06-11T00:00:50.647092681Z,10,1,42418117,M,A,0,3.280000000,10,130,11608,79339178,3.250000000,3.280000000,1,11,1,2,3.240000000,3.290000000,11,1,2,1,3.230000000,3.300000000,1,1,1,1,,,0,0,0,0,,,0,0,0,0,,,0,0,0,0,,,0,0,0,0,,,0,0,0,0,,,0,0,0,0,,,0,0,0,0,MCLN5-MCLX5
2025-06-11T00:00:50.649966297Z,2025-06-11T00:00:50.647143079Z,10,1,42025623,C,B,0,63.680000000,1,130,11459,79339181,63.680000000,63.700000000,1,1,1,1,63.670000000,63.710000000,3,2,3,2,63.660000000,63.720000000,3,3,3,3,63.650000000,63.730000000,3,2,3,2,63.640000000,63.740000000,6,5,6,5,63.630000000,63.750000000,4,3,4,3,63.620000000,63.760000000,5,5,5,5,63.610000000,63.770000000,2,1,2,1,63.600000000,63.780000000,6,3,6,3,63.590000000,63.790000000,1,1,1,1,MCLQ5
2025-06-11T00:00:50.650666414Z,2025-06-11T00:00:50.647258947Z,10,1,42026514,M,B,2,64.730000000,1,130,15860,79339218,64.760000000,64.780000000,5,5,5,5,64.750000000,64.790000000,4,7,4,5,64.740000000,64.800000000,10,8,9,7,64.730000000,64.810000000,8,4,8,4,64.720000000,64.820000000,9,12,6,9,64.710000000,64.830000000,8,8,7,8,64.700000000,64.840000000,7,7,6,6,64.690000000,64.850000000,4,8,3,5,64.680000000,64.860000000,4,4,2,3,64.670000000,64.870000000,6,4,4,3,MCLN5
2025-06-11T00:00:50.650675223Z,2025-06-11T00:00:50.647259445Z,10,1,42026514,M,A,3,64.810000000,1,130,11634,79339219,64.760000000,64.780000000,5,5,5,5,64.750000000,64.790000000,4,7,4,5,64.740000000,64.800000000,10,8,9,7,64.730000000,64.810000000,8,5,8,5,64.720000000,64.820000000,9,11,6,8,64.710000000,64.830000000,8,8,7,8,64.700000000,64.840000000,7,7,6,6,64.690000000,64.850000000,4,8,3,5,64.680000000,64.860000000,4,4,2,3,64.670000000,64.870000000,6,4,4,3,MCLN5
2025-06-11T00:00:50.650683901Z,2025-06-11T00:00:50.647259925Z,10,1,42026514,M,B,2,64.730000000,1,130,11396,79339220,64.760000000,64.780000000,5,5,5,5,64.750000000,64.790000000,4,7,4,5,64.740000000,64.800000000,9,8,8,7,64.730000000,64.810000000,9,5,9,5,64.720000000,64.820000000,9,11,6,8,64.710000000,64.830000000,8,8,7,8,64.700000000,64.840000000,7,7,6,6,64.690000000,64.850000000,4,8,3,5,64.680000000,64.860000000,4,4,2,3,64.670000000,64.870000000,6,4,4,3,MCLN5
2025-06-11T00:00:50.650691788Z,2025-06-11T00:00:50.647260425Z,10,1,42026514,M,A,3,64.810000000,1,130,11316,79339221,64.760000000,64.780000000,5,5,5,5,64.750000000,64.790000000,4,7,4,5,64.740000000,64.800000000,9,8,8,7,64.730000000,64.810000000,9,6,9,6,64.720000000,64.820000000,9,10,6,7,64.710000000,64.830000000,8,8,7,8,64.700000000,64.840000000,7,7,6,6,64.690000000,64.850000000,4,8,3,5,64.680000000,64.860000000,4,4,2,3,64.670000000,64.870000000,6,4,4,3,MCLN5
2025-06-11T00:00:50.650761396Z,2025-06-11T00:00:50.647338161Z,10,1,42026514,C,B,4,64.720000000,1,130,15041,79339224,64.760000000,64.780000000,5,5,5,5,64.750000000,64.790000000,4,7,4,5,64.740000000,64.800000000,9,8,8,7,64.730000000,64.810000000,9,6,9,6,64.720000000,64.820000000,8,10,5,7,64.710000000,64.830000000,8,8,7,8,64.700000000,64.840000000,7,7,6,6,64.690000000,64.850000000,4,8,3,5,64.680000000,64.860000000,4,4,2,3,64.670000000,64.870000000,6,4,4,3,MCLN5
2025-06-11T00:00:50.650769375Z,2025-06-11T00:00:50.647348951Z,10,1,42025623,M,B,4,63.630000000,1,130,11302,79339225,63.680000000,63.700000000,1,1,1,1,63.670000000,63.710000000,3,2,3,2,63.660000000,63.720000000,3,3,3,3,63.650000000,63.730000000,3,2,3,2,63.640000000,63.740000000,5,5,5,5,63.630000000,63.750000000,5,3,5,3,63.620000000,63.760000000,5,5,5,5,63.610000000,63.770000000,2,1,2,1,63.600000000,63.780000000,6,3,6,3,63.590000000,63.790000000,1,1,1,1,MCLQ5
2025-06-11T00:00:50.650781063Z,2025-06-11T00:00:50.647349489Z,10,1,42025623,M,A,4,63.740000000,1,130,11591,79339226,63.680000000,63.700000000,1,1,1,1,63.670000000,63.710000000,3,2,3,2,63.660000000,63.720000000,3,3,3,3,63.650000000,63.730000000,3,2,3,2,63.640000000,63.740000000,5,6,5,6,63.630000000,63.750000000,5,2,5,2,63.620000000,63.760000000,5,5,5,5,63.610000000,63.770000000,2,1,2,1,63.600000000,63.780000000,6,3,6,3,63.590000000,63.790000000,1,1,1,1,MCLQ5
2025-06-11T00:00:50.650810345Z,2025-06-11T00:00:50.647501663Z,10,1,42026514,M,B,1,64.750000000,1,130,12995,79339228,64.760000000,64.780000000,5,5,5,5,64.750000000,64.790000000,5,7,5,5,64.740000000,64.800000000,9,8,8,7,64.730000000,64.810000000,9,6,9,6,64.720000000,64.820000000,8,10,5,7,64.710000000,64.830000000,8,8,7,8,64.700000000,64.840000000,7,7,6,6,64.690000000,64.850000000,4,8,3,5,64.680000000,64.860000000,4,4,2,3,64.670000000,64.870000000,6,4,4,3,MCLN5
2025-06-11T00:00:50.650932873Z,2025-06-11T00:00:50.647902521Z,10,1,42025623,C,B,0,63.680000000,1,130,11064,79339233,63.670000000,63.700000000,3,1,3,1,63.660000000,63.710000000,3,2,3,2,63.650000000,63.720000000,3,3,3,3,63.640000000,63.730000000,5,2,5,2,63.630000000,63.740000000,5,6,5,6,63.620000000,63.750000000,5,2,5,2,63.610000000,63.760000000,2,5,2,5,63.600000000,63.770000000,6,1,6,1,63.590000000,63.780000000,1,3,1,3,63.580000000,63.790000000,6,1,4,1,MCLQ5
2025-06-11T00:00:50.651070238Z,2025-06-11T00:00:50.648196019Z,10,1,42025611,M,A,1,2.090000000,20,130,14183,79339240,2.070000000,2.080000000,3,5,2,2,2.060000000,2.090000000,27,27,5,6,2.050000000,2.100000000,23,27,3,6,2.040000000,2.110000000,23,23,3,4,2.030000000,2.120000000,2,2,1,1,2.020000000,2.130000000,2,2,2,2,2.010000000,2.140000000,2,2,1,1,2.000000000,2.150000000,2,2,2,1,1.990000000,2.160000000,2,2,1,1,1.980000000,2.170000000,2,2,2,1,MCLN5-MCLU5
2025-06-11T00:00:50.651765595Z,2025-06-11T00:00:50.648587203Z,10,1,42026514,C,A,0,64.780000000,1,130,11723,79339283,64.760000000,64.780000000,5,4,5,4,64.750000000,64.790000000,5,7,5,5,64.740000000,64.800000000,9,8,8,7,64.730000000,64.810000000,9,6,9,6,64.720000000,64.820000000,8,10,5,7,64.710000000,64.830000000,8,8,7,8,64.700000000,64.840000000,7,7,6,6,64.690000000,64.850000000,4,8,3,5,64.680000000,64.860000000,4,4,2,3,64.670000000,64.870000000,6,4,4,3,MCLN5
2025-06-11T00:00:50.652731511Z,2025-06-11T00:00:50.650868291Z,10,1,42026514,M,A,3,64.810000000,1,130,11499,79339346,64.760000000,64.780000000,5,4,5,4,64.750000000,64.790000000,5,7,5,5,64.740000000,64.800000000,9,8,8,7,64.730000000,64.810000000,9,7,9,7,64.720000000,64.820000000,8,10,5,7,64.710000000,64.830000000,8,8,7,8,64.700000000,64.840000000,7,7,6,6,64.690000000,64.850000000,4,8,3,5,64.680000000,64.860000000,4,4,2,3,64.670000000,64.870000000,6,4,4,3,MCLN5
2025-06-11T00:00:50.652800689Z,2025-06-11T00:00:50.651113043Z,10,1,42026514,C,A,1,64.790000000,1,130,11892,79339351,64.760000000,64.780000000,5,4,5,4,64.750000000,64.790000000,5,6,5,4,64.740000000,64.800000000,9,8,8,7,64.730000000,64.810000000,9,7,9,7,64.720000000,64.820000000,8,10,5,7,64.710000000,64.830000000,8,8,7,8,64.700000000,64.840000000,7,7,6,6,64.690000000,64.850000000,4,8,3,5,64.680000000,64.860000000,4,4,2,3,64.670000000,64.870000000,6,4,4,3,MCLN5
2025-06-11T00:00:50.653222952Z,2025-06-11T00:00:50.651792959Z,10,1,42026514,A,B,0,64.770000000,2,130,11810,79339378,64.770000000,64.780000000,2,4,1,4,64.760000000,64.790000000,5,6,5,4,64.750000000,64.800000000,5,8,5,7,64.740000000,64.810000000,9,7,8,7,64.730000000,64.820000000,9,10,9,7,64.720000000,64.830000000,8,8,5,8,64.710000000,64.840000000,8,7,7,6,64.700000000,64.850000000,7,8,6,5,64.690000000,64.860000000,4,4,3,3,64.680000000,64.870000000,4,4,2,3,MCLN5
2025-06-11T00:00:50.662738100Z,2025-06-11T00:00:50.662618325Z,10,1,42026514,C,B,0,64.770000000,2,130,15157,79339588,64.760000000,64.780000000,5,4,5,4,64.750000000,64.790000000,5,6,5,4,64.740000000,64.800000000,9,8,8,7,64.730000000,64.810000000,9,7,9,7,64.720000000,64.820000000,8,10,5,7,64.710000000,64.830000000,8,8,7,8,64.700000000,64.840000000,7,7,6,6,64.690000000,64.850000000,4,8,3,5,64.680000000,64.860000000,4,4,2,3,64.670000000,64.870000000,6,4,4,3,MCLN5
2025-06-11T00:00:50.683240468Z,2025-06-11T00:00:50.683138665Z,10,1,42026514,A,B,5,64.710000000,1,130,14843,79339604,64.760000000,64.780000000,5,4,5,4,64.750000000,64.790000000,5,6,5,4,64.740000000,64.800000000,9,8,8,7,64.730000000,64.810000000,9,7,9,7,64.720000000,64.820000000,8,10,5,7,64.710000000,64.830000000,9,8,8,8,64.700000000,64.840000000,7,7,6,6,64.690000000,64.850000000,4,8,3,5,64.680000000,64.860000000,4,4,2,3,64.670000000,64.870000000,6,4,4,3,MCLN5
2025-06-11T00:00:50.683248908Z,2025-06-11T00:00:50.683140911Z,10,1,42026514,C,A,6,64.840000000,1,130,11683,79339605,64.760000000,64.780000000,5,4,5,4,64.750000000,64.790000000,5,6,5,4,64.740000000,64.800000000,9,8,8,7,64.730000000,64.810000000,9,7,9,7,64.720000000,64.820000000,8,10,5,7,64.710000000,64.830000000,9,8,8,8,64.700000000,64.840000000,7,6,6,5,64.690000000,64.850000000,4,8,3,5,64.680000000,64.860000000,4,4,2,3,64.670000000,64.870000000,6,4,4,3,MCLN5
2025-06-11T00:00:50.683372987Z,2025-06-11T00:00:50.683271813Z,10,1,42026514,A,A,5,64.830000000,1,130,14761,79339606,64.760000000,64.780000000,5,4,5,4,64.750000000,64.790000000,5,6,5,4,64.740000000,64.800000000,9,8,8,7,64.730000000,64.810000000,9,7,9,7,64.720000000,64.820000000,8,10,5,7,64.710000000,64.830000000,9,9,8,9,64.700000000,64.840000000,7,6,6,5,64.690000000,64.850000000,4,8,3,5,64.680000000,64.860000000,4,4,2,3,64.670000000,64.870000000,6,4,4,3,MCLN5
2025-06-11T00:00:52.202768261Z,2025-06-11T00:00:52.202596475Z,10,1,42026514,A,B,0,64.770000000,2,130,15326,79339905,64.770000000,64.780000000,2,4,1,4,64.760000000,64.790000000,5,6,5,4,64.750000000,64.800000000,5,8,5,7,64.740000000,64.810000000,9,7,8,7,64.730000000,64.820000000,9,10,9,7,64.720000000,64.830000000,8,9,5,9,64.710000000,64.840000000,9,6,8,5,64.700000000,64.850000000,7,8,6,5,64.690000000,64.860000000,4,4,3,3,64.680000000,64.870000000,4,4,2,3,MCLN5
2025-06-11T00:00:52.202955259Z,2025-06-11T00:00:52.202778289Z,10,1,42026514,C,A,5,64.830000000,1,130,12134,79339913,64.770000000,64.780000000,2,4,1,4,64.760000000,64.790000000,5,6,5,4,64.750000000,64.800000000,5,8,5,7,64.740000000,64.810000000,9,7,8,7,64.730000000,64.820000000,9,10,9,7,64.720000000,64.830000000,8,8,5,8,64.710000000,64.840000000,9,6,8,5,64.700000000,64.850000000,7,8,6,5,64.690000000,64.860000000,4,4,3,3,64.680000000,64.870000000,4,4,2,3,MCLN5
2025-06-11T00:00:52.214207633Z,2025-06-11T00:00:52.214098109Z,10,1,42026514,C,B,6,64.710000000,1,130,17187,79339937,64.770000000,64.780000000,2,4,1,4,64.760000000,64.790000000,5,6,5,4,64.750000000,64.800000000,5,8,5,7,64.740000000,64.810000000,9,7,8,7,64.730000000,64.820000000,9,10,9,7,64.720000000,64.830000000,8,8,5,8,64.710000000,64.840000000,8,6,7,5,64.700000000,64.850000000,7,8,6,5,64.690000000,64.860000000,4,4,3,3,64.680000000,64.870000000,4,4,2,3,MCLN5
2025-06-11T00:00:52.214218769Z,2025-06-11T00:00:52.214101143Z,10,1,42026514,A,A,6,64.840000000,1,130,13980,79339938,64.770000000,64.780000000,2,4,1,4,64.760000000,64.790000000,5,6,5,4,64.750000000,64.800000000,5,8,5,7,64.740000000,64.810000000,9,7,8,7,64.730000000,64.820000000,9,10,9,7,64.720000000,64.830000000,8,8,5,8,64.710000000,64.840000000,8,7,7,6,64.700000000,64.850000000,7,8,6,5,64.690000000,64.860000000,4,4,3,3,64.680000000,64.870000000,4,4,2,3,MCLN5
2025-06-11T00:00:52.214335468Z,2025-06-11T00:00:52.214235673Z,10,1,42026514,A,B,5,64.720000000,1,130,16533,79339939,64.770000000,64.780000000,2,4,1,4,64.760000000,64.790000000,5,6,5,4,64.750000000,64.800000000,5,8,5,7,64.740000000,64.810000000,9,7,8,7,64.730000000,64.820000000,9,10,9,7,64.720000000,64.830000000,9,8,6,8,64.710000000,64.840000000,8,7,7,6,64.700000000,64.850000000,7,8,6,5,64.690000000,64.860000000,4,4,3,3,64.680000000,64.870000000,4,4,2,3,MCLN5
2025-06-11T00:00:52.256865631Z,2025-06-11T00:00:52.256734201Z,10,1,42026514,A,B,0,64.770000000,1,130,19425,79339945,64.770000000,64.780000000,3,4,2,4,64.760000000,64.790000000,5,6,5,4,64.750000000,64.800000000,5,8,5,7,64.740000000,64.810000000,9,7,8,7,64.730000000,64.820000000,9,10,9,7,64.720000000,64.830000000,9,8,6,8,64.710000000,64.840000000,8,7,7,6,64.700000000,64.850000000,7,8,6,5,64.690000000,64.860000000,4,4,3,3,64.680000000,64.870000000,4,4,2,3,MCLN5
2025-06-11T00:00:52.257082656Z,2025-06-11T00:00:52.256967375Z,10,1,42026514,C,A,0,64.780000000,1,130,18720,79339952,64.770000000,64.780000000,3,3,2,3,64.760000000,64.790000000,5,6,5,4,64.750000000,64.800000000,5,8,5,7,64.740000000,64.810000000,9,7,8,7,64.730000000,64.820000000,9,10,9,7,64.720000000,64.830000000,9,8,6,8,64.710000000,64.840000000,8,7,7,6,64.700000000,64.850000000,7,8,6,5,64.690000000,64.860000000,4,4,3,3,64.680000000,64.870000000,4,4,2,3,MCLN5
2025-06-11T00:00:52.258093829Z,2025-06-11T00:00:52.257091675Z,10,1,42026514,M,A,3,64.820000000,1,130,21256,79339979,64.770000000,64.780000000,3,3,2,3,64.760000000,64.790000000,5,6,5,4,64.750000000,64.800000000,5,8,5,7,64.740000000,64.810000000,9,6,8,6,64.730000000,64.820000000,9,11,9,8,64.720000000,64.830000000,9,8,6,8,64.710000000,64.840000000,8,7,7,6,64.700000000,64.850000000,7,8,6,5,64.690000000,64.860000000,4,4,3,3,64.680000000,64.870000000,4,4,2,3,MCLN5
2025-06-11T00:00:52.258093829Z,2025-06-11T00:00:52.257092111Z,10,1,42026514,M,B,3,64.740000000,1,130,21256,79339979,64.770000000,64.780000000,3,3,2,3,64.760000000,64.790000000,5,6,5,4,64.750000000,64.800000000,5,8,5,7,64.740000000,64.810000000,10,6,9,6,64.730000000,64.820000000,8,11,8,8,64.720000000,64.830000000,9,8,6,8,64.710000000,64.840000000,8,7,7,6,64.700000000,64.850000000,7,8,6,5,64.690000000,64.860000000,4,4,3,3,64.680000000,64.870000000,4,4,2,3,MCLN5
2025-06-11T00:00:52.258093829Z,2025-06-11T00:00:52.257092785Z,10,1,42026514,M,A,3,64.820000000,1,130,21256,79339979,64.770000000,64.780000000,3,3,2,3,64.760000000,64.790000000,5,6,5,4,64.750000000,64.800000000,5,8,5,7,64.740000000,64.810000000,10,5,9,5,64.730000000,64.820000000,8,12,8,9,64.720000000,64.830000000,9,8,6,8,64.710000000,64.840000000,8,7,7,6,64.700000000,64.850000000,7,8,6,5,64.690000000,64.860000000,4,4,3,3,64.680000000,64.870000000,4,4,2,3,MCLN5
2025-06-11T00:00:52.258093829Z,2025-06-11T00:00:52.257093283Z,10,1,42026514,M,B,3,64.740000000,1,130,21256,79339979,64.770000000,64.780000000,3,3,2,3,64.760000000,64.790000000,5,6,5,4,64.750000000,64.800000000,5,8,5,7,64.740000000,64.810000000,11,5,10,5,64.730000000,64.820000000,7,12,7,9,64.720000000,64.830000000,9,8,6,8,64.710000000,64.840000000,8,7,7,6,64.700000000,64.850000000,7,8,6,5,64.690000000,64.860000000,4,4,3,3,64.680000000,64.870000000,4,4,2,3,MCLN5
2025-06-11T00:00:52.258119049Z,2025-06-11T00:00:52.257106397Z,10,1,42026514,C,A,0,64.780000000,1,130,18398,79339981,64.770000000,64.780000000,3,2,2,2,64.760000000,64.790000000,5,6,5,4,64.750000000,64.800000000,5,8,5,7,64.740000000,64.810000000,11,5,10,5,64.730000000,64.820000000,7,12,7,9,64.720000000,64.830000000,9,8,6,8,64.710000000,64.840000000,8,7,7,6,64.700000000,64.850000000,7,8,6,5,64.690000000,64.860000000,4,4,3,3,64.680000000,64.870000000,4,4,2,3,MCLN5
2025-06-11T00:00:52.258243281Z,2025-06-11T00:00:52.257191257Z,10,1,42026514,C,A,0,64.780000000,1,130,15172,79339991,64.770000000,64.780000000,3,1,2,1,64.760000000,64.790000000,5,6,5,4,64.750000000,64.800000000,5,8,5,7,64.740000000,64.810000000,11,5,10,5,64.730000000,64.820000000,7,12,7,9,64.720000000,64.830000000,9,8,6,8,64.710000000,64.840000000,8,7,7,6,64.700000000,64.850000000,7,8,6,5,64.690000000,64.860000000,4,4,3,3,64.680000000,64.870000000,4,4,2,3,MCLN5
2025-06-11T00:00:52.258450492Z,2025-06-11T00:00:52.258141019Z,10,1,42025623,M,A,4,63.750000000,1,130,11478,79340008,63.670000000,63.700000000,3,1,3,1,63.660000000,63.710000000,3,2,3,2,63.650000000,63.720000000,3,3,3,3,63.640000000,63.730000000,5,2,5,2,63.630000000,63.740000000,5,5,5,5,63.620000000,63.750000000,5,3,5,3,63.610000000,63.760000000,2,5,2,5,63.600000000,63.770000000,6,1,6,1,63.590000000,63.780000000,1,3,1,3,63.580000000,63.790000000,6,1,4,1,MCLQ5
2025-06-11T00:00:52.258463340Z,2025-06-11T00:00:52.258141481Z,10,1,42025623,M,B,3,63.640000000,1,130,11648,79340009,63.670000000,63.700000000,3,1,3,1,63.660000000,63.710000000,3,2,3,2,63.650000000,63.720000000,3,3,3,3,63.640000000,63.730000000,6,2,6,2,63.630000000,63.740000000,4,5,4,5,63.620000000,63.750000000,5,3,5,3,63.610000000,63.760000000,2,5,2,5,63.600000000,63.770000000,6,1,6,1,63.590000000,63.780000000,1,3,1,3,63.580000000,63.790000000,6,1,4,1,MCLQ5
2025-06-11T00:00:52.258807370Z,2025-06-11T00:00:52.258348409Z,10,1,42025611,M,A,0,2.080000000,1,130,11765,79340030,2.070000000,2.080000000,3,6,2,3,2.060000000,2.090000000,27,27,5,6,2.050000000,2.100000000,23,27,3,6,2.040000000,2.110000000,23,22,3,3,2.030000000,2.120000000,2,2,1,1,2.020000000,2.130000000,2,2,2,2,2.010000000,2.140000000,2,2,1,1,2.000000000,2.150000000,2,2,2,1,1.990000000,2.160000000,2,2,1,1,1.980000000,2.170000000,2,2,2,1,MCLN5-MCLU5
2025-06-11T00:00:52.258927434Z,2025-06-11T00:00:52.258435457Z,10,1,42026514,M,B,2,62.800000000,2,130,11549,79340037,64.770000000,64.780000000,3,1,2,1,64.760000000,64.790000000,5,6,5,4,64.750000000,64.800000000,4,8,4,7,64.740000000,64.810000000,11,5,10,5,64.730000000,64.820000000,7,12,7,9,64.720000000,64.830000000,9,8,6,8,64.710000000,64.840000000,8,7,7,6,64.700000000,64.850000000,7,8,6,5,64.690000000,64.860000000,4,4,3,3,64.680000000,64.870000000,4,4,2,3,MCLN5
2025-06-11T00:00:52.260112718Z,2025-06-11T00:00:52.259348127Z,10,1,42418117,M,A,0,3.290000000,10,130,11527,79340119,3.250000000,3.280000000,1,1,1,1,3.240000000,3.290000000,11,11,2,2,3.230000000,3.300000000,1,1,1,1,,,0,0,0,0,,,0,0,0,0,,,0,0,0,0,,,0,0,0,0,,,0,0,0,0,,,0,0,0,0,,,0,0,0,0,MCLN5-MCLX5
2025-06-11T00:00:52.260122056Z,2025-06-11T00:00:52.259363909Z,10,1,42022708,M,A,0,2.840000000,10,130,11699,79340120,2.810000000,2.830000000,1,2,1,2,2.800000000,2.840000000,12,12,3,3,2.790000000,2.850000000,2,1,2,1,2.780000000,2.870000000,1,1,1,1,,,0,0,0,0,,,0,0,0,0,,,0,0,0,0,,,0,0,0,0,,,0,0,0,0,,,0,0,0,0,MCLN5-MCLV5
2025-06-11T00:00:52.562876388Z,2025-06-11T00:00:52.562775941Z,10,1,42022708,M,A,0,2.830000000,10,130,15800,79340229,2.810000000,2.830000000,1,12,1,3,2.800000000,2.840000000,12,2,3,2,2.790000000,2.850000000,2,1,2,1,2.780000000,2.870000000,1,1,1,1,,,0,0,0,0,,,0,0,0,0,,,0,0,0,0,,,0,0,0,0,,,0,0,0,0,,,0,0,0,0,MCLN5-MCLV5
2025-06-11T00:00:53.099949902Z,2025-06-11T00:00:53.099845403Z,10,1,42022708,M,A,0,2.840000000,10,130,17324,79340289,2.810000000,2.830000000,1,2,1,2,2.800000000,2.840000000,12,12,3,3,2.790000000,2.850000000,2,1,2,1,2.780000000,2.870000000,1,1,1,1,,,0,0,0,0,,,0,0,0,0,,,0,0,0,0,,,0,0,0,0,,,0,0,0,0,,,0,0,0,0,MCLN5-MCLV5
2025-06-11T00:00:53.752466573Z,2025-06-11T00:00:53.752333309Z,10,1,42175560,M,A,0,4.020000000,10,130,16799,79340334,3.200000000,4.020000000,10,10,1,1,,,0,0,0,0,,,0,0,0,0,,,0,0,0,0,,,0,0,0,0,,,0,0,0,0,,,0,0,0,0,,,0,0,0,0,,,0,0,0,0,,,0,0,0,0,MCLN5-MCLZ5
2025-06-11T00:00:57.868014782Z,2025-06-11T00:00:57.867893805Z,10,1,42405621,M,B,0,2.980000000,10,130,17374,79340518,2.980000000,3.770000000,10,10,1,1,,,0,0,0,0,,,0,0,0,0,,,0,0,0,0,,,0,0,0,0,,,0,0,0,0,,,0,0,0,0,,,0,0,0,0,,,0,0,0,0,,,0,0,0,0,MCLN5-MCLK6
2025-06-11T00:01:00.005710582Z,2025-06-11T00:01:00.005369765Z,10,1,42022708,M,A,0,2.830000000,10,130,17730,79340819,2.810000000,2.830000000,1,12,1,3,2.800000000,2.840000000,12,2,3,2,2.790000000,2.850000000,2,1,2,1,2.780000000,2.870000000,1,1,1,1,,,0,0,0,0,,,0,0,0,0,,,0,0,0,0,,,0,0,0,0,,,0,0,0,0,,,0,0,0,0,MCLN5-MCLV5
2025-06-11T00:01:00.005710582Z,2025-06-11T00:01:00.005352965Z,10,1,42418117,M,A,0,3.280000000,10,130,17730,79340819,3.250000000,3.280000000,1,11,1,2,3.240000000,3.290000000,11,1,2,1,3.230000000,3.300000000,1,1,1,1,,,0,0,0,0,,,0,0,0,0,,,0,0,0,0,,,0,0,0,0,,,0,0,0,0,,,0,0,0,0,,,0,0,0,0,MCLN5-MCLX5
2025-06-11T00:01:00.020480280Z,2025-06-11T00:01:00.020375763Z,10,1,42025611,M,A,1,2.120000000,20,130,15068,79341086,2.070000000,2.080000000,3,6,2,3,2.060000000,2.090000000,27,7,5,5,2.050000000,2.100000000,23,27,3,6,2.040000000,2.110000000,23,22,3,3,2.030000000,2.120000000,2,22,1,2,2.020000000,2.130000000,2,2,2,2,2.010000000,2.140000000,2,2,1,1,2.000000000,2.150000000,2,2,2,1,1.990000000,2.160000000,2,2,1,1,1.980000000,2.170000000,2,2,2,1,MCLN5-MCLU5
2025-06-11T00:01:00.024834964Z,2025-06-11T00:01:00.024642411Z,10,1,42418117,M,B,0,3.220000000,1,130,11639,79341146,3.240000000,3.280000000,11,11,2,2,3.230000000,3.290000000,1,1,1,1,3.220000000,3.300000000,1,1,1,1,,,0,0,0,0,,,0,0,0,0,,,0,0,0,0,,,0,0,0,0,,,0,0,0,0,,,0,0,0,0,,,0,0,0,0,MCLN5-MCLX5
2025-06-11T00:01:00.120572362Z,2025-06-11T00:01:00.120197103Z,10,1,42026514,A,A,0,64.780000000,1,130,15011,79342295,64.770000000,64.780000000,3,2,2,2,64.760000000,64.790000000,5,6,5,4,64.750000000,64.800000000,4,8,4,7,64.740000000,64.810000000,11,5,10,5,64.730000000,64.820000000,7,12,7,9,64.720000000,64.830000000,9,8,6,8,64.710000000,64.840000000,8,7,7,6,64.700000000,64.850000000,7,8,6,5,64.690000000,64.860000000,4,4,3,3,64.680000000,64.870000000,4,4,2,3,MCLN5
2025-06-11T00:01:00.120700250Z,2025-06-11T00:01:00.120239109Z,10,1,42026514,A,A,0,64.780000000,1,130,14726,79342300,64.770000000,64.780000000,3,3,2,3,64.760000000,64.790000000,5,6,5,4,64.750000000,64.800000000,4,8,4,7,64.740000000,64.810000000,11,5,10,5,64.730000000,64.820000000,7,12,7,9,64.720000000,64.830000000,9,8,6,8,64.710000000,64.840000000,8,7,7,6,64.700000000,64.850000000,7,8,6,5,64.690000000,64.860000000,4,4,3,3,64.680000000,64.870000000,4,4,2,3,MCLN5
2025-06-11T00:01:00.120876059Z,2025-06-11T00:01:00.120259155Z,10,1,42026514,A,A,0,64.780000000,1,130,11742,79342310,64.770000000,64.780000000,3,4,2,4,64.760000000,64.790000000,5,6,5,4,64.750000000,64.800000000,4,8,4,7,64.740000000,64.810000000,11,5,10,5,64.730000000,64.820000000,7,12,7,9,64.720000000,64.830000000,9,8,6,8,64.710000000,64.840000000,8,7,7,6,64.700000000,64.850000000,7,8,6,5,64.690000000,64.860000000,4,4,3,3,64.680000000,64.870000000,4,4,2,3,MCLN5
2025-06-11T00:01:00.120905456Z,2025-06-11T00:01:00.120262533Z,10,1,42026514,C,B,0,64.770000000,1,130,11376,79342313,64.770000000,64.780000000,2,4,1,4,64.760000000,64.790000000,5,6,5,4,64.750000000,64.800000000,4,8,4,7,64.740000000,64.810000000,11,5,10,5,64.730000000,64.820000000,7,12,7,9,64.720000000,64.830000000,9,8,6,8,64.710000000,64.840000000,8,7,7,6,64.700000000,64.850000000,7,8,6,5,64.690000000,64.860000000,4,4,3,3,64.680000000,64.870000000,4,4,2,3,MCLN5
2025-06-11T00:01:00.121249134Z,2025-06-11T00:01:00.120469173Z,10,1,42026514,C,B,0,64.770000000,2,130,11656,79342332,64.760000000,64.780000000,5,4,5,4,64.750000000,64.790000000,4,6,4,4,64.740000000,64.800000000,11,8,10,7,64.730000000,64.810000000,7,5,7,5,64.720000000,64.820000000,9,12,6,9,64.710000000,64.830000000,8,8,7,8,64.700000000,64.840000000,7,7,6,6,64.690000000,64.850000000,4,8,3,5,64.680000000,64.860000000,4,4,2,3,64.670000000,64.870000000,6,4,4,3,MCLN5
2025-06-11T00:01:00.121777052Z,2025-06-11T00:01:00.120720337Z,10,1,42025623,M,B,3,63.630000000,1,130,13814,79342360,63.670000000,63.700000000,3,1,3,1,63.660000000,63.710000000,3,2,3,2,63.650000000,63.720000000,3,3,3,3,63.640000000,63.730000000,5,2,5,2,63.630000000,63.740000000,5,5,5,5,63.620000000,63.750000000,5,3,5,3,63.610000000,63.760000000,2,5,2,5,63.600000000,63.770000000,6,1,6,1,63.590000000,63.780000000,1,3,1,3,63.580000000,63.790000000,6,1,4,1,MCLQ5
2025-06-11T00:01:00.121777052Z,2025-06-11T00:01:00.120720875Z,10,1,42025623,M,A,4,63.740000000,1,130,13814,79342360,63.670000000,63.700000000,3,1,3,1,63.660000000,63.710000000,3,2,3,2,63.650000000,63.720000000,3,3,3,3,63.640000000,63.730000000,5,2,5,2,63.630000000,63.740000000,5,6,5,6,63.620000000,63.750000000,5,2,5,2,63.610000000,63.760000000,2,5,2,5,63.600000000,63.770000000,6,1,6,1,63.590000000,63.780000000,1,3,1,3,63.580000000,63.790000000,6,1,4,1,MCLQ5
2025-06-11T00:01:00.122242167Z,2025-06-11T00:01:00.120885873Z,10,1,42026514,M,B,2,64.730000000,1,130,11627,79342383,64.760000000,64.780000000,5,4,5,4,64.750000000,64.790000000,4,6,4,4,64.740000000,64.800000000,10,8,9,7,64.730000000,64.810000000,8,5,8,5,64.720000000,64.820000000,9,12,6,9,64.710000000,64.830000000,8,8,7,8,64.700000000,64.840000000,7,7,6,6,64.690000000,64.850000000,4,8,3,5,64.680000000,64.860000000,4,4,2,3,64.670000000,64.870000000,6,4,4,3,MCLN5
2025-06-11T00:01:00.122253349Z,2025-06-11T00:01:00.120886313Z,10,1,42026514,M,A,3,64.810000000,1,130,11554,79342384,64.760000000,64.780000000,5,4,5,4,64.750000000,64.790000000,4,6,4,4,64.740000000,64.800000000,10,8,9,7,64.730000000,64.810000000,8,6,8,6,64.720000000,64.820000000,9,11,6,8,64.710000000,64.830000000,8,8,7,8,64.700000000,64.840000000,7,7,6,6,64.690000000,64.850000000,4,8,3,5,64.680000000,64.860000000,4,4,2,3,64.670000000,64.870000000,6,4,4,3,MCLN5
2025-06-11T00:01:00.122262380Z,2025-06-11T00:01:00.120886889Z,10,1,42026514,M,B,2,64.730000000,1,130,11488,79342385,64.760000000,64.780000000,5,4,5,4,64.750000000,64.790000000,4,6,4,4,64.740000000,64.800000000,9,8,8,7,64.730000000,64.810000000,9,6,9,6,64.720000000,64.820000000,9,11,6,8,64.710000000,64.830000000,8,8,7,8,64.700000000,64.840000000,7,7,6,6,64.690000000,64.850000000,4,8,3,5,64.680000000,64.860000000,4,4,2,3,64.670000000,64.870000000,6,4,4,3,MCLN5
2025-06-11T00:01:00.122273446Z,2025-06-11T00:01:00.120887409Z,10,1,42026514,M,A,3,64.810000000,1,130,11865,79342386,64.760000000,64.780000000,5,4,5,4,64.750000000,64.790000000,4,6,4,4,64.740000000,64.800000000,9,8,8,7,64.730000000,64.810000000,9,7,9,7,64.720000000,64.820000000,9,10,6,7,64.710000000,64.830000000,8,8,7,8,64.700000000,64.840000000,7,7,6,6,64.690000000,64.850000000,4,8,3,5,64.680000000,64.860000000,4,4,2,3,64.670000000,64.870000000,6,4,4,3,MCLN5
2025-06-11T00:01:00.122301999Z,2025-06-11T00:01:00.120908585Z,10,1,42026514,M,A,1,64.790000000,1,130,15051,79342388,64.760000000,64.780000000,5,4,5,4,64.750000000,64.790000000,4,7,4,5,64.740000000,64.800000000,9,8,8,7,64.730000000,64.810000000,9,7,9,7,64.720000000,64.820000000,9,10,6,7,64.710000000,64.830000000,8,8,7,8,64.700000000,64.840000000,7,7,6,6,64.690000000,64.850000000,4,8,3,5,64.680000000,64.860000000,4,4,2,3,64.670000000,64.870000000,6,4,4,3,MCLN5
2025-06-11T00:01:00.122455706Z,2025-06-11T00:01:00.120918147Z,10,1,42026514,A,A,0,64.770000000,2,130,11827,79342394,64.760000000,64.770000000,5,2,5,1,64.750000000,64.780000000,4,4,4,4,64.740000000,64.790000000,9,7,8,5,64.730000000,64.800000000,9,8,9,7,64.720000000,64.810000000,9,7,6,7,64.710000000,64.820000000,8,10,7,7,64.700000000,64.830000000,7,8,6,8,64.690000000,64.840000000,4,7,3,6,64.680000000,64.850000000,4,8,2,5,64.670000000,64.860000000,6,4,4,3,MCLN5
2025-06-11T00:01:00.123062002Z,2025-06-11T00:01:00.120953435Z,10,1,42025623,A,A,0,63.690000000,1,130,15788,79342428,63.670000000,63.690000000,3,1,3,1,63.660000000,63.700000000,3,1,3,1,63.650000000,63.710000000,3,2,3,2,63.640000000,63.720000000,5,3,5,3,63.630000000,63.730000000,5,2,5,2,63.620000000,63.740000000,5,6,5,6,63.610000000,63.750000000,2,2,2,2,63.600000000,63.760000000,6,5,6,5,63.590000000,63.770000000,1,1,1,1,63.580000000,63.780000000,6,3,4,3,MCLQ5
2025-06-11T00:01:00.124009196Z,2025-06-11T00:01:00.121259661Z,10,1,42026514,C,B,4,64.720000000,1,130,11434,79342475,64.760000000,64.770000000,5,2,5,1,64.750000000,64.780000000,4,4,4,4,64.740000000,64.790000000,9,7,8,5,64.730000000,64.800000000,9,8,9,7,64.720000000,64.810000000,8,7,5,7,64.710000000,64.820000000,8,10,7,7,64.700000000,64.830000000,7,8,6,8,64.690000000,64.840000000,4,7,3,6,64.680000000,64.850000000,4,8,2,5,64.670000000,64.860000000,6,4,4,3,MCLN5
2025-06-11T00:01:00.124306573Z,2025-06-11T00:01:00.121401407Z,10,1,42026514,M,B,1,64.750000000,1,130,11825,79342493,64.760000000,64.770000000,5,2,5,1,64.750000000,64.780000000,5,4,5,4,64.740000000,64.790000000,9,7,8,5,64.730000000,64.800000000,9,8,9,7,64.720000000,64.810000000,8,7,5,7,64.710000000,64.820000000,8,10,7,7,64.700000000,64.830000000,7,8,6,8,64.690000000,64.840000000,4,7,3,6,64.680000000,64.850000000,4,8,2,5,64.670000000,64.860000000,6,4,4,3,MCLN5
2025-06-11T00:01:00.126519072Z,2025-06-11T00:01:00.122474333Z,10,1,42026514,M,B,3,64.720000000,1,130,11668,79342657,64.760000000,64.770000000,5,2,5,1,64.750000000,64.780000000,5,4,5,4,64.740000000,64.790000000,9,7,8,5,64.730000000,64.800000000,8,8,8,7,64.720000000,64.810000000,9,7,6,7,64.710000000,64.820000000,8,10,7,7,64.700000000,64.830000000,7,8,6,8,64.690000000,64.840000000,4,7,3,6,64.680000000,64.850000000,4,8,2,5,64.670000000,64.860000000,6,4,4,3,MCLN5
2025-06-11T00:01:00.126519072Z,2025-06-11T00:01:00.122474831Z,10,1,42026514,M,A,4,64.810000000,1,130,11668,79342657,64.760000000,64.770000000,5,2,5,1,64.750000000,64.780000000,5,4,5,4,64.740000000,64.790000000,9,7,8,5,64.730000000,64.800000000,8,8,8,7,64.720000000,64.810000000,9,8,6,8,64.710000000,64.820000000,8,9,7,6,64.700000000,64.830000000,7,8,6,8,64.690000000,64.840000000,4,7,3,6,64.680000000,64.850000000,4,8,2,5,64.670000000,64.860000000,6,4,4,3,MCLN5
2025-06-11T00:01:00.126526675Z,2025-06-11T00:01:00.122480919Z,10,1,42025623,C,B,5,63.620000000,1,130,11287,79342658,63.670000000,63.690000000,3,1,3,1,63.660000000,63.700000000,3,1,3,1,63.650000000,63.710000000,3,2,3,2,63.640000000,63.720000000,5,3,5,3,63.630000000,63.730000000,5,2,5,2,63.620000000,63.740000000,4,6,4,6,63.610000000,63.750000000,2,2,2,2,63.600000000,63.760000000,6,5,6,5,63.590000000,63.770000000,1,1,1,1,63.580000000,63.780000000,6,3,4,3,MCLQ5
2025-06-11T00:01:00.126536014Z,2025-06-11T00:01:00.122483107Z,10,1,42025623,M,B,3,63.630000000,1,130,11451,79342659,63.670000000,63.690000000,3,1,3,1,63.660000000,63.700000000,3,1,3,1,63.650000000,63.710000000,3,2,3,2,63.640000000,63.720000000,4,3,4,3,63.630000000,63.730000000,6,2,6,2,63.620000000,63.740000000,4,6,4,6,63.610000000,63.750000000,2,2,2,2,63.600000000,63.760000000,6,5,6,5,63.590000000,63.770000000,1,1,1,1,63.580000000,63.780000000,6,3,4,3,MCLQ5
2025-06-11T00:01:00.126547395Z,2025-06-11T00:01:00.122483663Z,10,1,42025623,M,A,4,63.730000000,1,130,11329,79342660,63.670000000,63.690000000,3,1,3,1,63.660000000,63.700000000,3,1,3,1,63.650000000,63.710000000,3,2,3,2,63.640000000,63.720000000,4,3,4,3,63.630000000,63.730000000,6,3,6,3,63.620000000,63.740000000,4,5,4,5,63.610000000,63.750000000,2,2,2,2,63.600000000,63.760000000,6,5,6,5,63.590000000,63.770000000,1,1,1,1,63.580000000,63.780000000,6,3,4,3,MCLQ5
2025-06-11T00:01:00.126560627Z,2025-06-11T00:01:00.122484143Z,10,1,42025623,M,B,3,63.630000000,1,130,14065,79342661,63.670000000,63.690000000,3,1,3,1,63.660000000,63.700000000,3,1,3,1,63.650000000,63.710000000,3,2,3,2,63.640000000,63.720000000,3,3,3,3,63.630000000,63.730000000,7,3,7,3,63.620000000,63.740000000,4,5,4,5,63.610000000,63.750000000,2,2,2,2,63.600000000,63.760000000,6,5,6,5,63.590000000,63.770000000,1,1,1,1,63.580000000,63.780000000,6,3,4,3,MCLQ5
2025-06-11T00:01:00.126573521Z,2025-06-11T00:01:00.122484605Z,10,1,42025623,M,A,4,63.730000000,1,130,11645,79342662,63.670000000,63.690000000,3,1,3,1,63.660000000,63.700000000,3,1,3,1,63.650000000,63.710000000,3,2,3,2,63.640000000,63.720000000,3,3,3,3,63.630000000,63.730000000,7,4,7,4,63.620000000,63.740000000,4,4,4,4,63.610000000,63.750000000,2,2,2,2,63.600000000,63.760000000,6,5,6,5,63.590000000,63.770000000,1,1,1,1,63.580000000,63.780000000,6,3,4,3,MCLQ5
2025-06-11T00:01:00.126584165Z,2025-06-11T00:01:00.122487639Z,10,1,42025623,C,A,7,63.760000000,1,130,11346,79342663,63.670000000,63.690000000,3,1,3,1,63.660000000,63.700000000,3,1,3,1,63.650000000,63.710000000,3,2,3,2,63.640000000,63.720000000,3,3,3,3,63.630000000,63.730000000,7,4,7,4,63.620000000,63.740000000,4,4,4,4,63.610000000,63.750000000,2,2,2,2,63.600000000,63.760000000,6,4,6,4,63.590000000,63.770000000,1,1,1,1,63.580000000,63.780000000,6,3,4,3,MCLQ5
2025-06-11T00:01:00.126674346Z,2025-06-11T00:01:00.122667111Z,10,1,42025611,M,A,1,2.090000000,20,130,11538,79342670,2.070000000,2.080000000,3,6,2,3,2.060000000,2.090000000,27,27,5,6,2.050000000,2.100000000,23,27,3,6,2.040000000,2.110000000,23,22,3,3,2.030000000,2.120000000,2,2,1,1,2.020000000,2.130000000,2,2,2,2,2.010000000,2.140000000,2,2,1,1,2.000000000,2.150000000,2,2,2,1,1.990000000,2.160000000,2,2,1,1,1.980000000,2.170000000,2,2,2,1,MCLN5-MCLU5
2025-06-11T00:01:00.128080388Z,2025-06-11T00:01:00.126061579Z,10,1,42026514,M,A,2,64.790000000,1,130,11537,79342770,64.760000000,64.770000000,5,2,5,1,64.750000000,64.780000000,5,4,5,4,64.740000000,64.790000000,9,8,8,6,64.730000000,64.800000000,8,8,8,7,64.720000000,64.810000000,9,8,6,8,64.710000000,64.820000000,8,9,7,6,64.700000000,64.830000000,7,8,6,8,64.690000000,64.840000000,4,7,3,6,64.680000000,64.850000000,4,8,2,5,64.670000000,64.860000000,6,4,4,3,MCLN5
2025-06-11T00:01:00.128175622Z,2025-06-11T00:01:00.126229303Z,10,1,42025611,C,B,0,2.070000000,2,130,12209,79342779,2.070000000,2.080000000,1,6,1,3,2.060000000,2.090000000,27,27,5,6,2.050000000,2.100000000,23,27,3,6,2.040000000,2.110000000,23,22,3,3,2.030000000,2.120000000,2,2,1,1,2.020000000,2.130000000,2,2,2,2,2.010000000,2.140000000,2,2,1,1,2.000000000,2.150000000,2,2,2,1,1.990000000,2.160000000,2,2,1,1,1.980000000,2.170000000,2,2,2,1,MCLN5-MCLU5
2025-06-11T00:01:00.129266532Z,2025-06-11T00:01:00.127318393Z,10,1,42418117,M,A,0,3.270000000,1,130,14791,79342850,3.240000000,3.270000000,11,1,2,1,3.230000000,3.280000000,1,11,1,2,3.220000000,3.290000000,1,1,1,1,,,0,0,0,0,,,0,0,0,0,,,0,0,0,0,,,0,0,0,0,,,0,0,0,0,,,0,0,0,0,,,0,0,0,0,MCLN5-MCLX5
2025-06-11T00:01:00.129285524Z,2025-06-11T00:01:00.127377201Z,10,1,42025611,C,B,0,2.070000000,1,130,11506,79342852,2.060000000,2.080000000,27,6,5,3,2.050000000,2.090000000,23,27,3,6,2.040000000,2.100000000,23,27,3,6,2.030000000,2.110000000,2,22,1,3,2.020000000,2.120000000,2,2,2,1,2.010000000,2.130000000,2,2,1,2,2.000000000,2.140000000,2,2,2,1,1.990000000,2.150000000,2,2,1,1,1.980000000,2.160000000,2,2,2,1,1.970000000,2.170000000,2,2,1,1,MCLN5-MCLU5
2025-06-11T00:01:00.130647869Z,2025-06-11T00:01:00.128764071Z,10,1,42026514,M,A,1,64.780000000,1,130,12898,79342944,64.760000000,64.770000000,5,2,5,1,64.750000000,64.780000000,5,5,5,5,64.740000000,64.790000000,9,8,8,6,64.730000000,64.800000000,8,8,8,7,64.720000000,64.810000000,9,8,6,8,64.710000000,64.820000000,8,9,7,6,64.700000000,64.830000000,7,8,6,8,64.690000000,64.840000000,4,7,3,6,64.680000000,64.850000000,4,8,2,5,64.670000000,64.860000000,6,4,4,3,MCLN5
2025-06-11T00:01:00.131284331Z,2025-06-11T00:01:00.129414941Z,10,1,42026514,A,A,0,64.770000000,1,130,13635,79342983,64.760000000,64.770000000,5,3,5,2,64.750000000,64.780000000,5,5,5,5,64.740000000,64.790000000,9,8,8,6,64.730000000,64.800000000,8,8,8,7,64.720000000,64.810000000,9,8,6,8,64.710000000,64.820000000,8,9,7,6,64.700000000,64.830000000,7,8,6,8,64.690000000,64.840000000,4,7,3,6,64.680000000,64.850000000,4,8,2,5,64.670000000,64.860000000,6,4,4,3,MCLN5
2025-06-11T00:01:00.132282003Z,2025-06-11T00:01:00.131041627Z,10,1,42026514,M,B,1,62.800000000,2,130,13147,79343048,64.760000000,64.770000000,5,3,5,2,64.750000000,64.780000000,4,5,4,5,64.740000000,64.790000000,9,8,8,6,64.730000000,64.800000000,8,8,8,7,64.720000000,64.810000000,9,8,6,8,64.710000000,64.820000000,8,9,7,6,64.700000000,64.830000000,7,8,6,8,64.690000000,64.840000000,4,7,3,6,64.680000000,64.850000000,4,8,2,5,64.670000000,64.860000000,6,4,4,3,MCLN5
2025-06-11T00:01:00.133373969Z,2025-06-11T00:01:00.131756029Z,10,1,42022708,C,B,0,2.810000000,1,130,12870,79343114,2.800000000,2.830000000,12,12,3,3,2.790000000,2.840000000,2,2,2,2,2.780000000,2.850000000,1,1,1,1,,2.870000000,0,1,0,1,,,0,0,0,0,,,0,0,0,0,,,0,0,0,0,,,0,0,0,0,,,0,0,0,0,,,0,0,0,0,MCLN5-MCLV5
2025-06-11T00:01:00.133382274Z,2025-06-11T00:01:00.131764093Z,10,1,42022708,M,A,0,2.820000000,1,130,11792,79343115,2.800000000,2.820000000,12,1,3,1,2.790000000,2.830000000,2,12,2,3,2.780000000,2.840000000,1,2,1,2,,2.870000000,0,1,0,1,,,0,0,0,0,,,0,0,0,0,,,0,0,0,0,,,0,0,0,0,,,0,0,0,0,,,0,0,0,0,MCLN5-MCLV5
2025-06-11T00:01:00.134214265Z,2025-06-11T00:01:00.132734287Z,10,1,42026514,A,B,5,64.710000000,1,130,11760,79343183,64.760000000,64.770000000,5,3,5,2,64.750000000,64.780000000,4,5,4,5,64.740000000,64.790000000,9,8,8,6,64.730000000,64.800000000,8,8,8,7,64.720000000,64.810000000,9,8,6,8,64.710000000,64.820000000,9,9,8,6,64.700000000,64.830000000,7,8,6,8,64.690000000,64.840000000,4,7,3,6,64.680000000,64.850000000,4,8,2,5,64.670000000,64.860000000,6,4,4,3,MCLN5
2025-06-11T00:01:00.134224103Z,2025-06-11T00:01:00.132736797Z,10,1,42026514,C,A,7,64.840000000,1,130,11282,79343184,64.760000000,64.770000000,5,3,5,2,64.750000000,64.780000000,4,5,4,5,64.740000000,64.790000000,9,8,8,6,64.730000000,64.800000000,8,8,8,7,64.720000000,64.810000000,9,8,6,8,64.710000000,64.820000000,9,9,8,6,64.700000000,64.830000000,7,8,6,8,64.690000000,64.840000000,4,6,3,5,64.680000000,64.850000000,4,8,2,5,64.670000000,64.860000000,6,4,4,3,MCLN5
2025-06-11T00:01:00.134419195Z,2025-06-11T00:01:00.132903809Z,10,1,42026514,A,A,6,64.830000000,1,130,11160,79343200,64.760000000,64.770000000,5,3,5,2,64.750000000,64.780000000,4,5,4,5,64.740000000,64.790000000,9,8,8,6,64.730000000,64.800000000,8,8,8,7,64.720000000,64.810000000,9,8,6,8,64.710000000,64.820000000,9,9,8,6,64.700000000,64.830000000,7,9,6,9,64.690000000,64.840000000,4,6,3,5,64.680000000,64.850000000,4,8,2,5,64.670000000,64.860000000,6,4,4,3,MCLN5
2025-06-11T00:01:00.134759302Z,2025-06-11T00:01:00.133090867Z,10,1,42025623,A,B,6,63.610000000,1,130,11539,79343227,63.670000000,63.690000000,3,1,3,1,63.660000000,63.700000000,3,1,3,1,63.650000000,63.710000000,3,2,3,2,63.640000000,63.720000000,3,3,3,3,63.630000000,63.730000000,7,4,7,4,63.620000000,63.740000000,4,4,4,4,63.610000000,63.750000000,3,2,3,2,63.600000000,63.760000000,6,4,6,4,63.590000000,63.770000000,1,1,1,1,63.580000000,63.780000000,6,3,4,3,MCLQ5
2025-06-11T00:01:00.134767189Z,2025-06-11T00:01:00.133092749Z,10,1,42025623,A,A,6,63.750000000,1,130,11424,79343228,63.670000000,63.690000000,3,1,3,1,63.660000000,63.700000000,3,1,3,1,63.650000000,63.710000000,3,2,3,2,63.640000000,63.720000000,3,3,3,3,63.630000000,63.730000000,7,4,7,4,63.620000000,63.740000000,4,4,4,4,63.610000000,63.750000000,3,3,3,3,63.600000000,63.760000000,6,4,6,4,63.590000000,63.770000000,1,1,1,1,63.580000000,63.780000000,6,3,4,3,MCLQ5
2025-06-11T00:01:00.134890669Z,2025-06-11T00:01:00.133388321Z,10,1,42022708,M,B,0,2.400000000,10,130,12576,79343238,2.800000000,2.820000000,2,1,2,1,2.790000000,2.830000000,2,12,2,3,2.780000000,2.840000000,1,2,1,2,2.400000000,2.870000000,10,1,1,1,,,0,0,0,0,,,0,0,0,0,,,0,0,0,0,,,0,0,0,0,,,0,0,0,0,,,0,0,0,0,MCLN5-MCLV5
2025-06-11T00:01:00.180683930Z,2025-06-11T00:01:00.180574689Z,10,1,42022708,M,B,0,2.800000000,10,130,15007,79343433,2.800000000,2.820000000,12,1,3,1,2.790000000,2.830000000,2,12,2,3,2.780000000,2.840000000,1,2,1,2,,2.870000000,0,1,0,1,,,0,0,0,0,,,0,0,0,0,,,0,0,0,0,,,0,0,0,0,,,0,0,0,0,,,0,0,0,0,MCLN5-MCLV5
2025-06-11T00:01:00.361127441Z,2025-06-11T00:01:00.360999977Z,10,1,42026514,C,A,3,64.800000000,1,130,15260,79343674,64.760000000,64.770000000,5,3,5,2,64.750000000,64.780000000,4,5,4,5,64.740000000,64.790000000,9,8,8,6,64.730000000,64.800000000,8,7,8,6,64.720000000,64.810000000,9,8,6,8,64.710000000,64.820000000,9,9,8,6,64.700000000,64.830000000,7,9,6,9,64.690000000,64.840000000,4,6,3,5,64.680000000,64.850000000,4,8,2,5,64.670000000,64.860000000,6,4,4,3,MCLN5
2025-06-11T00:01:00.392769365Z,2025-06-11T00:01:00.392480671Z,10,1,42026514,C,A,0,64.770000000,2,130,15713,79343732,64.760000000,64.770000000,5,1,5,1,64.750000000,64.780000000,4,5,4,5,64.740000000,64.790000000,9,8,8,6,64.730000000,64.800000000,8,7,8,6,64.720000000,64.810000000,9,8,6,8,64.710000000,64.820000000,9,9,8,6,64.700000000,64.830000000,7,9,6,9,64.690000000,64.840000000,4,6,3,5,64.680000000,64.850000000,4,8,2,5,64.670000000,64.860000000,6,4,4,3,MCLN5
