ts_recv,ts_event,rtype,publisher_id,instrument_id,action,side,depth,price,size,flags,ts_in_delta,sequence,bid_px_00,ask_px_00,bid_sz_00,ask_sz_00,bid_ct_00,ask_ct_00,bid_px_01,ask_px_01,bid_sz_01,ask_sz_01,bid_ct_01,ask_ct_01,bid_px_02,ask_px_02,bid_sz_02,ask_sz_02,bid_ct_02,ask_ct_02,bid_px_03,ask_px_03,bid_sz_03,ask_sz_03,bid_ct_03,ask_ct_03,bid_px_04,ask_px_04,bid_sz_04,ask_sz_04,bid_ct_04,ask_ct_04,bid_px_05,ask_px_05,bid_sz_05,ask_sz_05,bid_ct_05,ask_ct_05,bid_px_06,ask_px_06,bid_sz_06,ask_sz_06,bid_ct_06,ask_ct_06,bid_px_07,ask_px_07,bid_sz_07,ask_sz_07,bid_ct_07,ask_ct_07,bid_px_08,ask_px_08,bid_sz_08,ask_sz_08,bid_ct_08,ask_ct_08,bid_px_09,ask_px_09,bid_sz_09,ask_sz_09,bid_ct_09,ask_ct_09,symbol
2025-06-11T00:00:20.806853770Z,2025-06-11T00:00:20.800675725Z,10,1,42025623,C,B,5,63.630000000,1,130,14497,79320929,63.680000000,63.710000000,2,2,2,2,63.670000000,63.720000000,3,2,3,2,63.660000000,63.730000000,3,2,3,2,63.650000000,63.740000000,5,3,5,3,63.640000000,63.750000000,4,2,4,2,63.630000000,63.760000000,4,6,4,6,63.620000000,63.770000000,3,2,3,2,63.610000000,63.780000000,2,3,2,3,63.600000000,63.790000000,7,1,7,1,63.590000000,63.800000000,1,3,1,3,MCLQ5
2025-06-11T00:00:20.806865535Z,2025-06-11T00:00:20.800684615Z,10,1,42026514,A,B,5,64.720000000,1,130,15074,79320930,64.770000000,64.780000000,5,1,4,1,64.760000000,64.790000000,8,6,8,4,64.750000000,64.800000000,6,8,6,8,64.740000000,64.810000000,11,4,10,4,64.730000000,64.820000000,6,9,6,6,64.720000000,64.830000000,9,7,6,7,64.710000000,64.840000000,8,9,7,8,64.700000000,64.850000000,7,8,6,5,64.690000000,64.860000000,4,4,3,3,64.680000000,64.870000000,4,4,2,3,MCLN5
2025-06-11T00:00:20.806873814Z,2025-06-11T00:00:20.800686763Z,10,1,42026514,A,A,6,64.840000000,1,130,11387,79320931,64.770000000,64.780000000,5,1,4,1,64.760000000,64.790000000,8,6,8,4,64.750000000,64.800000000,6,8,6,8,64.740000000,64.810000000,11,4,10,4,64.730000000,64.820000000,6,9,6,6,64.720000000,64.830000000,9,7,6,7,64.710000000,64.840000000,8,10,7,9,64.700000000,64.850000000,7,8,6,5,64.690000000,64.860000000,4,4,3,3,64.680000000,64.870000000,4,4,2,3,MCLN5
2025-06-11T00:00:20.807021055Z,2025-06-11T00:00:20.800900259Z,10,1,42026514,C,A,2,64.800000000,1,130,11352,79320943,64.770000000,64.780000000,5,1,4,1,64.760000000,64.790000000,8,6,8,4,64.750000000,64.800000000,6,7,6,7,64.740000000,64.810000000,11,4,10,4,64.730000000,64.820000000,6,9,6,6,64.720000000,64.830000000,9,7,6,7,64.710000000,64.840000000,8,10,7,9,64.700000000,64.850000000,7,8,6,5,64.690000000,64.860000000,4,4,3,3,64.680000000,64.870000000,4,4,2,3,MCLN5
2025-06-11T00:00:20.807118639Z,2025-06-11T00:00:20.800914677Z,10,1,42026514,M,A,2,66.740000000,2,130,11815,79320949,64.770000000,64.780000000,5,1,4,1,64.760000000,64.790000000,8,6,8,4,64.750000000,64.800000000,6,6,6,6,64.740000000,64.810000000,11,4,10,4,64.730000000,64.820000000,6,9,6,6,64.720000000,64.830000000,9,7,6,7,64.710000000,64.840000000,8,10,7,9,64.700000000,64.850000000,7,8,6,5,64.690000000,64.860000000,4,4,3,3,64.680000000,64.870000000,4,4,2,3,MCLN5
2025-06-11T00:00:20.808574375Z,2025-06-11T00:00:20.803386127Z,10,1,42026514,A,A,0,64.780000000,1,130,11770,79321044,64.770000000,64.780000000,5,2,4,2,64.760000000,64.790000000,8,6,8,4,64.750000000,64.800000000,6,6,6,6,64.740000000,64.810000000,11,4,10,4,64.730000000,64.820000000,6,9,6,6,64.720000000,64.830000000,9,7,6,7,64.710000000,64.840000000,8,10,7,9,64.700000000,64.850000000,7,8,6,5,64.690000000,64.860000000,4,4,3,3,64.680000000,64.870000000,4,4,2,3,MCLN5
2025-06-11T00:00:20.808830114Z,2025-06-11T00:00:20.804374097Z,10,1,42026514,M,A,5,64.830000000,1,130,11356,79321061,64.770000000,64.780000000,5,2,4,2,64.760000000,64.790000000,8,6,8,4,64.750000000,64.800000000,6,6,6,6,64.740000000,64.810000000,11,4,10,4,64.730000000,64.820000000,6,9,6,6,64.720000000,64.830000000,9,8,6,8,64.710000000,64.840000000,8,10,7,9,64.700000000,64.850000000,7,8,6,5,64.690000000,64.860000000,4,4,3,3,64.680000000,64.870000000,4,4,2,3,MCLN5
2025-06-11T00:00:20.809149546Z,2025-06-11T00:00:20.805634979Z,10,1,42026514,M,B,0,62.810000000,2,130,13669,79321082,64.770000000,64.780000000,4,2,3,2,64.760000000,64.790000000,8,6,8,4,64.750000000,64.800000000,6,6,6,6,64.740000000,64.810000000,11,4,10,4,64.730000000,64.820000000,6,9,6,6,64.720000000,64.830000000,9,8,6,8,64.710000000,64.840000000,8,10,7,9,64.700000000,64.850000000,7,8,6,5,64.690000000,64.860000000,4,4,3,3,64.680000000,64.870000000,4,4,2,3,MCLN5
2025-06-11T00:00:20.809873033Z,2025-06-11T00:00:20.807222577Z,10,1,42026514,M,A,2,64.800000000,2,130,11427,79321131,64.770000000,64.780000000,4,2,3,2,64.760000000,64.790000000,8,6,8,4,64.750000000,64.800000000,6,8,6,7,64.740000000,64.810000000,11,4,10,4,64.730000000,64.820000000,6,9,6,6,64.720000000,64.830000000,9,8,6,8,64.710000000,64.840000000,8,10,7,9,64.700000000,64.850000000,7,8,6,5,64.690000000,64.860000000,4,4,3,3,64.680000000,64.870000000,4,4,2,3,MCLN5
2025-06-11T00:00:20.811952476Z,2025-06-11T00:00:20.810623247Z,10,1,42026514,A,A,0,64.780000000,1,130,12003,79321263,64.770000000,64.780000000,4,3,3,3,64.760000000,64.790000000,8,6,8,4,64.750000000,64.800000000,6,8,6,7,64.740000000,64.810000000,11,4,10,4,64.730000000,64.820000000,6,9,6,6,64.720000000,64.830000000,9,8,6,8,64.710000000,64.840000000,8,10,7,9,64.700000000,64.850000000,7,8,6,5,64.690000000,64.860000000,4,4,3,3,64.680000000,64.870000000,4,4,2,3,MCLN5
2025-06-11T00:00:20.812040807Z,2025-06-11T00:00:20.810809977Z,10,1,42026514,C,B,0,64.770000000,2,130,16636,79321268,64.770000000,64.780000000,2,3,2,3,64.760000000,64.790000000,8,6,8,4,64.750000000,64.800000000,6,8,6,7,64.740000000,64.810000000,11,4,10,4,64.730000000,64.820000000,6,9,6,6,64.720000000,64.830000000,9,8,6,8,64.710000000,64.840000000,8,10,7,9,64.700000000,64.850000000,7,8,6,5,64.690000000,64.860000000,4,4,3,3,64.680000000,64.870000000,4,4,2,3,MCLN5
2025-06-11T00:00:20.812571144Z,2025-06-11T00:00:20.811963309Z,10,1,42025623,A,B,6,63.620000000,1,130,12104,79321302,63.680000000,63.710000000,2,2,2,2,63.670000000,63.720000000,3,2,3,2,63.660000000,63.730000000,3,2,3,2,63.650000000,63.740000000,5,3,5,3,63.640000000,63.750000000,4,2,4,2,63.630000000,63.760000000,4,6,4,6,63.620000000,63.770000000,4,2,4,2,63.610000000,63.780000000,2,3,2,3,63.600000000,63.790000000,7,1,7,1,63.590000000,63.800000000,1,3,1,3,MCLQ5
2025-06-11T00:00:20.812579661Z,2025-06-11T00:00:20.811964999Z,10,1,42025623,C,A,6,63.770000000,1,130,11692,79321303,63.680000000,63.710000000,2,2,2,2,63.670000000,63.720000000,3,2,3,2,63.660000000,63.730000000,3,2,3,2,63.650000000,63.740000000,5,3,5,3,63.640000000,63.750000000,4,2,4,2,63.630000000,63.760000000,4,6,4,6,63.620000000,63.770000000,4,1,4,1,63.610000000,63.780000000,2,3,2,3,63.600000000,63.790000000,7,1,7,1,63.590000000,63.800000000,1,3,1,3,MCLQ5
2025-06-11T00:00:20.812703072Z,2025-06-11T00:00:20.812121377Z,10,1,42025623,A,A,5,63.760000000,1,130,11532,79321309,63.680000000,63.710000000,2,2,2,2,63.670000000,63.720000000,3,2,3,2,63.660000000,63.730000000,3,2,3,2,63.650000000,63.740000000,5,3,5,3,63.640000000,63.750000000,4,2,4,2,63.630000000,63.760000000,4,7,4,7,63.620000000,63.770000000,4,1,4,1,63.610000000,63.780000000,2,3,2,3,63.600000000,63.790000000,7,1,7,1,63.590000000,63.800000000,1,3,1,3,MCLQ5
2025-06-11T00:00:20.813950753Z,2025-06-11T00:00:20.813834901Z,10,1,42026514,A,A,0,64.780000000,1,130,17513,79321353,64.770000000,64.780000000,2,4,2,4,64.760000000,64.790000000,8,6,8,4,64.750000000,64.800000000,6,8,6,7,64.740000000,64.810000000,11,4,10,4,64.730000000,64.820000000,6,9,6,6,64.720000000,64.830000000,9,8,6,8,64.710000000,64.840000000,8,10,7,9,64.700000000,64.850000000,7,8,6,5,64.690000000,64.860000000,4,4,3,3,64.680000000,64.870000000,4,4,2,3,MCLN5
2025-06-11T00:00:20.814109905Z,2025-06-11T00:00:20.813973343Z,10,1,42025623,A,A,0,63.700000000,1,130,19660,79321359,63.680000000,63.700000000,2,1,2,1,63.670000000,63.710000000,3,2,3,2,63.660000000,63.720000000,3,2,3,2,63.650000000,63.730000000,5,2,5,2,63.640000000,63.740000000,4,3,4,3,63.630000000,63.750000000,4,2,4,2,63.620000000,63.760000000,4,7,4,7,63.610000000,63.770000000,2,1,2,1,63.600000000,63.780000000,7,3,7,3,63.590000000,63.790000000,1,1,1,1,MCLQ5
2025-06-11T00:00:20.822040669Z,2025-06-11T00:00:20.821772247Z,10,1,42026514,C,B,0,64.770000000,1,130,13623,79321387,64.770000000,64.780000000,1,4,1,4,64.760000000,64.790000000,8,6,8,4,64.750000000,64.800000000,6,8,6,7,64.740000000,64.810000000,11,4,10,4,64.730000000,64.820000000,6,9,6,6,64.720000000,64.830000000,9,8,6,8,64.710000000,64.840000000,8,10,7,9,64.700000000,64.850000000,7,8,6,5,64.690000000,64.860000000,4,4,3,3,64.680000000,64.870000000,4,4,2,3,MCLN5
2025-06-11T00:00:20.822529721Z,2025-06-11T00:00:20.822049967Z,10,1,42026514,C,A,0,64.780000000,1,130,11940,79321412,64.770000000,64.780000000,1,3,1,3,64.760000000,64.790000000,8,6,8,4,64.750000000,64.800000000,6,8,6,7,64.740000000,64.810000000,11,4,10,4,64.730000000,64.820000000,6,9,6,6,64.720000000,64.830000000,9,8,6,8,64.710000000,64.840000000,8,10,7,9,64.700000000,64.850000000,7,8,6,5,64.690000000,64.860000000,4,4,3,3,64.680000000,64.870000000,4,4,2,3,MCLN5
2025-06-11T00:00:20.823681614Z,2025-06-11T00:00:20.822312805Z,10,1,42025623,A,A,0,63.690000000,1,130,15112,79321475,63.680000000,63.690000000,2,1,2,1,63.670000000,63.700000000,3,1,3,1,63.660000000,63.710000000,3,2,3,2,63.650000000,63.720000000,5,2,5,2,63.640000000,63.730000000,4,2,4,2,63.630000000,63.740000000,4,3,4,3,63.620000000,63.750000000,4,2,4,2,63.610000000,63.760000000,2,7,2,7,63.600000000,63.770000000,7,1,7,1,63.590000000,63.780000000,1,3,1,3,MCLQ5
2025-06-11T00:00:20.823824532Z,2025-06-11T00:00:20.822585969Z,10,1,42026514,A,A,0,64.780000000,1,130,13561,79321483,64.770000000,64.780000000,1,4,1,4,64.760000000,64.790000000,8,6,8,4,64.750000000,64.800000000,6,8,6,7,64.740000000,64.810000000,11,4,10,4,64.730000000,64.820000000,6,9,6,6,64.720000000,64.830000000,9,8,6,8,64.710000000,64.840000000,8,10,7,9,64.700000000,64.850000000,7,8,6,5,64.690000000,64.860000000,4,4,3,3,64.680000000,64.870000000,4,4,2,3,MCLN5
2025-06-11T00:00:20.824023572Z,2025-06-11T00:00:20.822652033Z,10,1,42026514,A,B,0,64.770000000,1,130,12609,79321496,64.770000000,64.780000000,2,4,2,4,64.760000000,64.790000000,8,6,8,4,64.750000000,64.800000000,6,8,6,7,64.740000000,64.810000000,11,4,10,4,64.730000000,64.820000000,6,9,6,6,64.720000000,64.830000000,9,8,6,8,64.710000000,64.840000000,8,10,7,9,64.700000000,64.850000000,7,8,6,5,64.690000000,64.860000000,4,4,3,3,64.680000000,64.870000000,4,4,2,3,MCLN5
2025-06-11T00:00:20.824046465Z,2025-06-11T00:00:20.822695577Z,10,1,42026514,T,A,0,64.770000000,1,0,15146,79321498,64.770000000,64.780000000,2,4,2,4,64.760000000,64.790000000,8,6,8,4,64.750000000,64.800000000,6,8,6,7,64.740000000,64.810000000,11,4,10,4,64.730000000,64.820000000,6,9,6,6,64.720000000,64.830000000,9,8,6,8,64.710000000,64.840000000,8,10,7,9,64.700000000,64.850000000,7,8,6,5,64.690000000,64.860000000,4,4,3,3,64.680000000,64.870000000,4,4,2,3,MCLN5
2025-06-11T00:00:20.824060933Z,2025-06-11T00:00:20.822695577Z,10,1,42026514,C,B,0,64.770000000,1,130,14489,79321499,64.770000000,64.780000000,1,4,1,4,64.760000000,64.790000000,8,6,8,4,64.750000000,64.800000000,6,8,6,7,64.740000000,64.810000000,11,4,10,4,64.730000000,64.820000000,6,9,6,6,64.720000000,64.830000000,9,8,6,8,64.710000000,64.840000000,8,10,7,9,64.700000000,64.850000000,7,8,6,5,64.690000000,64.860000000,4,4,3,3,64.680000000,64.870000000,4,4,2,3,MCLN5
2025-06-11T00:00:20.824832094Z,2025-06-11T00:00:20.822738315Z,10,1,42026514,T,B,0,64.780000000,1,0,12210,79321522,64.770000000,64.780000000,1,4,1,4,64.760000000,64.790000000,8,6,8,4,64.750000000,64.800000000,6,8,6,7,64.740000000,64.810000000,11,4,10,4,64.730000000,64.820000000,6,9,6,6,64.720000000,64.830000000,9,8,6,8,64.710000000,64.840000000,8,10,7,9,64.700000000,64.850000000,7,8,6,5,64.690000000,64.860000000,4,4,3,3,64.680000000,64.870000000,4,4,2,3,MCLN5
2025-06-11T00:00:20.824832094Z,2025-06-11T00:00:20.822738315Z,10,1,42026514,C,A,0,64.780000000,1,130,12210,79321522,64.770000000,64.780000000,1,3,1,3,64.760000000,64.790000000,8,6,8,4,64.750000000,64.800000000,6,8,6,7,64.740000000,64.810000000,11,4,10,4,64.730000000,64.820000000,6,9,6,6,64.720000000,64.830000000,9,8,6,8,64.710000000,64.840000000,8,10,7,9,64.700000000,64.850000000,7,8,6,5,64.690000000,64.860000000,4,4,3,3,64.680000000,64.870000000,4,4,2,3,MCLN5
2025-06-11T00:00:20.825957301Z,2025-06-11T00:00:20.823024055Z,10,1,42026514,C,B,1,64.760000000,1,130,12977,79321595,64.770000000,64.780000000,1,3,1,3,64.760000000,64.790000000,7,6,7,4,64.750000000,64.800000000,6,8,6,7,64.740000000,64.810000000,11,4,10,4,64.730000000,64.820000000,6,9,6,6,64.720000000,64.830000000,9,8,6,8,64.710000000,64.840000000,8,10,7,9,64.700000000,64.850000000,7,8,6,5,64.690000000,64.860000000,4,4,3,3,64.680000000,64.870000000,4,4,2,3,MCLN5
2025-06-11T00:00:20.826054901Z,2025-06-11T00:00:20.823028031Z,10,1,42026514,T,A,0,64.770000000,1,0,12076,79321601,64.770000000,64.780000000,1,3,1,3,64.760000000,64.790000000,7,6,7,4,64.750000000,64.800000000,6,8,6,7,64.740000000,64.810000000,11,4,10,4,64.730000000,64.820000000,6,9,6,6,64.720000000,64.830000000,9,8,6,8,64.710000000,64.840000000,8,10,7,9,64.700000000,64.850000000,7,8,6,5,64.690000000,64.860000000,4,4,3,3,64.680000000,64.870000000,4,4,2,3,MCLN5
2025-06-11T00:00:20.826074123Z,2025-06-11T00:00:20.823028031Z,10,1,42026514,C,B,0,64.770000000,1,130,11700,79321602,64.760000000,64.780000000,7,3,7,3,64.750000000,64.790000000,6,6,6,4,64.740000000,64.800000000,11,8,10,7,64.730000000,64.810000000,6,4,6,4,64.720000000,64.820000000,9,9,6,6,64.710000000,64.830000000,8,8,7,8,64.700000000,64.840000000,7,10,6,9,64.690000000,64.850000000,4,8,3,5,64.680000000,64.860000000,4,4,2,3,64.670000000,64.870000000,6,4,4,3,MCLN5
2025-06-11T00:00:20.826127903Z,2025-06-11T00:00:20.823031581Z,10,1,42026514,A,A,0,64.770000000,2,130,15395,79321606,64.760000000,64.770000000,7,2,7,1,64.750000000,64.780000000,6,3,6,3,64.740000000,64.790000000,11,6,10,4,64.730000000,64.800000000,6,8,6,7,64.720000000,64.810000000,9,4,6,4,64.710000000,64.820000000,8,9,7,6,64.700000000,64.830000000,7,8,6,8,64.690000000,64.840000000,4,10,3,9,64.680000000,64.850000000,4,8,2,5,64.670000000,64.860000000,6,4,4,3,MCLN5
2025-06-11T00:00:20.826239649Z,2025-06-11T00:00:20.823039715Z,10,1,42025623,A,A,1,63.700000000,1,130,12899,79321614,63.680000000,63.690000000,2,1,2,1,63.670000000,63.700000000,3,2,3,2,63.660000000,63.710000000,3,2,3,2,63.650000000,63.720000000,5,2,5,2,63.640000000,63.730000000,4,2,4,2,63.630000000,63.740000000,4,3,4,3,63.620000000,63.750000000,4,2,4,2,63.610000000,63.760000000,2,7,2,7,63.600000000,63.770000000,7,1,7,1,63.590000000,63.780000000,1,3,1,3,MCLQ5
2025-06-11T00:00:20.826278170Z,2025-06-11T00:00:20.823041085Z,10,1,42026514,A,A,0,64.770000000,1,130,13615,79321617,64.760000000,64.770000000,7,3,7,2,64.750000000,64.780000000,6,3,6,3,64.740000000,64.790000000,11,6,10,4,64.730000000,64.800000000,6,8,6,7,64.720000000,64.810000000,9,4,6,4,64.710000000,64.820000000,8,9,7,6,64.700000000,64.830000000,7,8,6,8,64.690000000,64.840000000,4,10,3,9,64.680000000,64.850000000,4,8,2,5,64.670000000,64.860000000,6,4,4,3,MCLN5
2025-06-11T00:00:20.826436062Z,2025-06-11T00:00:20.823066429Z,10,1,42025623,A,A,0,63.690000000,1,130,16594,79321626,63.680000000,63.690000000,2,2,2,2,63.670000000,63.700000000,3,2,3,2,63.660000000,63.710000000,3,2,3,2,63.650000000,63.720000000,5,2,5,2,63.640000000,63.730000000,4,2,4,2,63.630000000,63.740000000,4,3,4,3,63.620000000,63.750000000,4,2,4,2,63.610000000,63.760000000,2,7,2,7,63.600000000,63.770000000,7,1,7,1,63.590000000,63.780000000,1,3,1,3,MCLQ5
2025-06-11T00:00:20.826450623Z,2025-06-11T00:00:20.823067197Z,10,1,42025623,C,B,0,63.680000000,1,130,13424,79321627,63.680000000,63.690000000,1,2,1,2,63.670000000,63.700000000,3,2,3,2,63.660000000,63.710000000,3,2,3,2,63.650000000,63.720000000,5,2,5,2,63.640000000,63.730000000,4,2,4,2,63.630000000,63.740000000,4,3,4,3,63.620000000,63.750000000,4,2,4,2,63.610000000,63.760000000,2,7,2,7,63.600000000,63.770000000,7,1,7,1,63.590000000,63.780000000,1,3,1,3,MCLQ5
2025-06-11T00:00:20.826498943Z,2025-06-11T00:00:20.823076833Z,10,1,42025623,C,B,0,63.680000000,1,130,11582,79321630,63.670000000,63.690000000,3,2,3,2,63.660000000,63.700000000,3,2,3,2,63.650000000,63.710000000,5,2,5,2,63.640000000,63.720000000,4,2,4,2,63.630000000,63.730000000,4,2,4,2,63.620000000,63.740000000,4,3,4,3,63.610000000,63.750000000,2,2,2,2,63.600000000,63.760000000,7,7,7,7,63.590000000,63.770000000,1,1,1,1,63.580000000,63.780000000,6,3,4,3,MCLQ5
2025-06-11T00:00:20.826536757Z,2025-06-11T00:00:20.823085377Z,10,1,42026514,C,B,0,64.760000000,1,130,16964,79321633,64.760000000,64.770000000,6,3,6,2,64.750000000,64.780000000,6,3,6,3,64.740000000,64.790000000,11,6,10,4,64.730000000,64.800000000,6,8,6,7,64.720000000,64.810000000,9,4,6,4,64.710000000,64.820000000,8,9,7,6,64.700000000,64.830000000,7,8,6,8,64.690000000,64.840000000,4,10,3,9,64.680000000,64.850000000,4,8,2,5,64.670000000,64.860000000,6,4,4,3,MCLN5
2025-06-11T00:00:20.826810443Z,2025-06-11T00:00:20.823211975Z,10,1,42026514,A,A,2,64.790000000,1,130,11375,79321657,64.760000000,64.770000000,6,3,6,2,64.750000000,64.780000000,6,3,6,3,64.740000000,64.790000000,11,7,10,5,64.730000000,64.800000000,6,8,6,7,64.720000000,64.810000000,9,4,6,4,64.710000000,64.820000000,8,9,7,6,64.700000000,64.830000000,7,8,6,8,64.690000000,64.840000000,4,10,3,9,64.680000000,64.850000000,4,8,2,5,64.670000000,64.860000000,6,4,4,3,MCLN5
2025-06-11T00:00:20.827282439Z,2025-06-11T00:00:20.823603371Z,10,1,42025623,C,A,0,63.690000000,1,130,13815,79321694,63.670000000,63.690000000,3,1,3,1,63.660000000,63.700000000,3,2,3,2,63.650000000,63.710000000,5,2,5,2,63.640000000,63.720000000,4,2,4,2,63.630000000,63.730000000,4,2,4,2,63.620000000,63.740000000,4,3,4,3,63.610000000,63.750000000,2,2,2,2,63.600000000,63.760000000,7,7,7,7,63.590000000,63.770000000,1,1,1,1,63.580000000,63.780000000,6,3,4,3,MCLQ5
2025-06-11T00:00:20.827549750Z,2025-06-11T00:00:20.823856645Z,10,1,42025623,A,A,0,63.690000000,1,130,14186,79321710,63.670000000,63.690000000,3,2,3,2,63.660000000,63.700000000,3,2,3,2,63.650000000,63.710000000,5,2,5,2,63.640000000,63.720000000,4,2,4,2,63.630000000,63.730000000,4,2,4,2,63.620000000,63.740000000,4,3,4,3,63.610000000,63.750000000,2,2,2,2,63.600000000,63.760000000,7,7,7,7,63.590000000,63.770000000,1,1,1,1,63.580000000,63.780000000,6,3,4,3,MCLQ5
2025-06-11T00:00:20.827608307Z,2025-06-11T00:00:20.823932135Z,10,1,42026514,A,A,0,64.770000000,1,130,13157,79321714,64.760000000,64.770000000,6,4,6,3,64.750000000,64.780000000,6,3,6,3,64.740000000,64.790000000,11,7,10,5,64.730000000,64.800000000,6,8,6,7,64.720000000,64.810000000,9,4,6,4,64.710000000,64.820000000,8,9,7,6,64.700000000,64.830000000,7,8,6,8,64.690000000,64.840000000,4,10,3,9,64.680000000,64.850000000,4,8,2,5,64.670000000,64.860000000,6,4,4,3,MCLN5
2025-06-11T00:00:20.827684358Z,2025-06-11T00:00:20.823950875Z,10,1,42026514,A,A,1,64.780000000,1,130,11528,79321718,64.760000000,64.770000000,6,4,6,3,64.750000000,64.780000000,6,4,6,4,64.740000000,64.790000000,11,7,10,5,64.730000000,64.800000000,6,8,6,7,64.720000000,64.810000000,9,4,6,4,64.710000000,64.820000000,8,9,7,6,64.700000000,64.830000000,7,8,6,8,64.690000000,64.840000000,4,10,3,9,64.680000000,64.850000000,4,8,2,5,64.670000000,64.860000000,6,4,4,3,MCLN5
2025-06-11T00:00:20.827839463Z,2025-06-11T00:00:20.824109977Z,10,1,42026514,T,B,0,64.770000000,1,0,11414,79321731,64.760000000,64.770000000,6,4,6,3,64.750000000,64.780000000,6,4,6,4,64.740000000,64.790000000,11,7,10,5,64.730000000,64.800000000,6,8,6,7,64.720000000,64.810000000,9,4,6,4,64.710000000,64.820000000,8,9,7,6,64.700000000,64.830000000,7,8,6,8,64.690000000,64.840000000,4,10,3,9,64.680000000,64.850000000,4,8,2,5,64.670000000,64.860000000,6,4,4,3,MCLN5
2025-06-11T00:00:20.827867662Z,2025-06-11T00:00:20.824109977Z,10,1,42026514,C,N,0,64.770000000,1,130,15765,79321732,64.770000000,64.780000000,1,4,1,4,64.760000000,64.790000000,6,7,6,5,64.750000000,64.800000000,6,8,6,7,64.740000000,64.810000000,11,4,10,4,64.730000000,64.820000000,6,9,6,6,64.720000000,64.830000000,9,8,6,8,64.710000000,64.840000000,8,10,7,9,64.700000000,64.850000000,7,8,6,5,64.690000000,64.860000000,4,4,3,3,64.680000000,64.870000000,4,4,2,3,MCLN5
2025-06-11T00:00:20.828642257Z,2025-06-11T00:00:20.824719993Z,10,1,42026514,C,A,0,64.780000000,1,130,14063,79321783,64.770000000,64.780000000,1,3,1,3,64.760000000,64.790000000,6,7,6,5,64.750000000,64.800000000,6,8,6,7,64.740000000,64.810000000,11,4,10,4,64.730000000,64.820000000,6,9,6,6,64.720000000,64.830000000,9,8,6,8,64.710000000,64.840000000,8,10,7,9,64.700000000,64.850000000,7,8,6,5,64.690000000,64.860000000,4,4,3,3,64.680000000,64.870000000,4,4,2,3,MCLN5
2025-06-11T00:00:20.828738728Z,2025-06-11T00:00:20.824790031Z,10,1,42026514,C,B,5,64.720000000,1,130,12043,79321792,64.770000000,64.780000000,1,3,1,3,64.760000000,64.790000000,6,7,6,5,64.750000000,64.800000000,6,8,6,7,64.740000000,64.810000000,11,4,10,4,64.730000000,64.820000000,6,9,6,6,64.720000000,64.830000000,8,8,5,8,64.710000000,64.840000000,8,10,7,9,64.700000000,64.850000000,7,8,6,5,64.690000000,64.860000000,4,4,3,3,64.680000000,64.870000000,4,4,2,3,MCLN5
2025-06-11T00:00:20.828763264Z,2025-06-11T00:00:20.824843789Z,10,1,42026514,C,A,0,64.780000000,1,130,14582,79321793,64.770000000,64.780000000,1,2,1,2,64.760000000,64.790000000,6,7,6,5,64.750000000,64.800000000,6,8,6,7,64.740000000,64.810000000,11,4,10,4,64.730000000,64.820000000,6,9,6,6,64.720000000,64.830000000,8,8,5,8,64.710000000,64.840000000,8,10,7,9,64.700000000,64.850000000,7,8,6,5,64.690000000,64.860000000,4,4,3,3,64.680000000,64.870000000,4,4,2,3,MCLN5
2025-06-11T00:00:20.828773509Z,2025-06-11T00:00:20.824844385Z,10,1,42026514,C,A,1,64.790000000,1,130,11380,79321794,64.770000000,64.780000000,1,2,1,2,64.760000000,64.790000000,6,6,6,4,64.750000000,64.800000000,6,8,6,7,64.740000000,64.810000000,11,4,10,4,64.730000000,64.820000000,6,9,6,6,64.720000000,64.830000000,8,8,5,8,64.710000000,64.840000000,8,10,7,9,64.700000000,64.850000000,7,8,6,5,64.690000000,64.860000000,4,4,3,3,64.680000000,64.870000000,4,4,2,3,MCLN5
2025-06-11T00:00:20.829147251Z,2025-06-11T00:00:20.825077749Z,10,1,42025623,M,B,2,63.640000000,1,130,15518,79321814,63.670000000,63.690000000,3,2,3,2,63.660000000,63.700000000,3,2,3,2,63.650000000,63.710000000,4,2,4,2,63.640000000,63.720000000,5,2,5,2,63.630000000,63.730000000,4,2,4,2,63.620000000,63.740000000,4,3,4,3,63.610000000,63.750000000,2,2,2,2,63.600000000,63.760000000,7,7,7,7,63.590000000,63.770000000,1,1,1,1,63.580000000,63.780000000,6,3,4,3,MCLQ5
2025-06-11T00:00:20.829147251Z,2025-06-11T00:00:20.825078537Z,10,1,42025623,M,B,2,63.640000000,1,130,15518,79321814,63.670000000,63.690000000,3,2,3,2,63.660000000,63.700000000,3,2,3,2,63.650000000,63.710000000,3,2,3,2,63.640000000,63.720000000,6,2,6,2,63.630000000,63.730000000,4,2,4,2,63.620000000,63.740000000,4,3,4,3,63.610000000,63.750000000,2,2,2,2,63.600000000,63.760000000,7,7,7,7,63.590000000,63.770000000,1,1,1,1,63.580000000,63.780000000,6,3,4,3,MCLQ5
2025-06-11T00:00:20.829279909Z,2025-06-11T00:00:20.825100347Z,10,1,42025623,C,A,0,63.690000000,1,130,14527,79321822,63.670000000,63.690000000,3,1,3,1,63.660000000,63.700000000,3,2,3,2,63.650000000,63.710000000,3,2,3,2,63.640000000,63.720000000,6,2,6,2,63.630000000,63.730000000,4,2,4,2,63.620000000,63.740000000,4,3,4,3,63.610000000,63.750000000,2,2,2,2,63.600000000,63.760000000,7,7,7,7,63.590000000,63.770000000,1,1,1,1,63.580000000,63.780000000,6,3,4,3,MCLQ5
2025-06-11T00:00:20.830001783Z,2025-06-11T00:00:20.825998637Z,10,1,42025623,M,B,3,63.630000000,1,130,11524,79321873,63.670000000,63.690000000,3,1,3,1,63.660000000,63.700000000,3,2,3,2,63.650000000,63.710000000,3,2,3,2,63.640000000,63.720000000,5,2,5,2,63.630000000,63.730000000,5,2,5,2,63.620000000,63.740000000,4,3,4,3,63.610000000,63.750000000,2,2,2,2,63.600000000,63.760000000,7,7,7,7,63.590000000,63.770000000,1,1,1,1,63.580000000,63.780000000,6,3,4,3,MCLQ5
2025-06-11T00:00:20.830011322Z,2025-06-11T00:00:20.825999751Z,10,1,42026514,M,B,3,64.730000000,1,130,11300,79321874,64.770000000,64.780000000,1,2,1,2,64.760000000,64.790000000,6,6,6,4,64.750000000,64.800000000,6,8,6,7,64.740000000,64.810000000,10,4,9,4,64.730000000,64.820000000,7,9,7,6,64.720000000,64.830000000,8,8,5,8,64.710000000,64.840000000,8,10,7,9,64.700000000,64.850000000,7,8,6,5,64.690000000,64.860000000,4,4,3,3,64.680000000,64.870000000,4,4,2,3,MCLN5
2025-06-11T00:00:20.830020253Z,2025-06-11T00:00:20.826000345Z,10,1,42026514,M,B,3,64.730000000,1,130,11391,79321875,64.770000000,64.780000000,1,2,1,2,64.760000000,64.790000000,6,6,6,4,64.750000000,64.800000000,6,8,6,7,64.740000000,64.810000000,9,4,8,4,64.730000000,64.820000000,8,9,8,6,64.720000000,64.830000000,8,8,5,8,64.710000000,64.840000000,8,10,7,9,64.700000000,64.850000000,7,8,6,5,64.690000000,64.860000000,4,4,3,3,64.680000000,64.870000000,4,4,2,3,MCLN5
2025-06-11T00:00:20.830043000Z,2025-06-11T00:00:20.826006759Z,10,1,42025611,C,B,0,2.070000000,2,130,15128,79321877,2.070000000,2.080000000,1,3,1,1,2.060000000,2.090000000,23,7,3,5,2.050000000,2.100000000,23,27,3,6,2.040000000,2.110000000,23,23,3,4,2.030000000,2.120000000,2,22,1,2,2.020000000,2.130000000,2,2,2,2,2.010000000,2.140000000,2,2,1,1,2.000000000,2.150000000,2,2,2,1,1.990000000,2.160000000,2,2,1,1,1.980000000,2.170000000,2,2,2,1,MCLN5-MCLU5
2025-06-11T00:00:20.830088832Z,2025-06-11T00:00:20.826022483Z,10,1,42026514,C,B,0,64.770000000,1,130,11949,79321880,64.760000000,64.780000000,6,2,6,2,64.750000000,64.790000000,6,6,6,4,64.740000000,64.800000000,9,8,8,7,64.730000000,64.810000000,8,4,8,4,64.720000000,64.820000000,8,9,5,6,64.710000000,64.830000000,8,8,7,8,64.700000000,64.840000000,7,10,6,9,64.690000000,64.850000000,4,8,3,5,64.680000000,64.860000000,4,4,2,3,64.670000000,64.870000000,6,4,4,3,MCLN5
2025-06-11T00:00:20.830173192Z,2025-06-11T00:00:20.826195121Z,10,1,42026514,M,B,1,62.800000000,2,130,11730,79321886,64.760000000,64.780000000,6,2,6,2,64.750000000,64.790000000,5,6,5,4,64.740000000,64.800000000,9,8,8,7,64.730000000,64.810000000,8,4,8,4,64.720000000,64.820000000,8,9,5,6,64.710000000,64.830000000,8,8,7,8,64.700000000,64.840000000,7,10,6,9,64.690000000,64.850000000,4,8,3,5,64.680000000,64.860000000,4,4,2,3,64.670000000,64.870000000,6,4,4,3,MCLN5
2025-06-11T00:00:20.830206698Z,2025-06-11T00:00:20.826230889Z,10,1,42026514,M,A,1,64.790000000,1,130,12458,79321888,64.760000000,64.780000000,6,2,6,2,64.750000000,64.790000000,5,7,5,5,64.740000000,64.800000000,9,8,8,7,64.730000000,64.810000000,8,4,8,4,64.720000000,64.820000000,8,9,5,6,64.710000000,64.830000000,8,8,7,8,64.700000000,64.840000000,7,10,6,9,64.690000000,64.850000000,4,8,3,5,64.680000000,64.860000000,4,4,2,3,64.670000000,64.870000000,6,4,4,3,MCLN5
2025-06-11T00:00:20.830336406Z,2025-06-11T00:00:20.826344029Z,10,1,42026514,M,B,0,62.790000000,2,130,14042,79321898,64.760000000,64.780000000,5,2,5,2,64.750000000,64.790000000,5,7,5,5,64.740000000,64.800000000,9,8,8,7,64.730000000,64.810000000,8,4,8,4,64.720000000,64.820000000,8,9,5,6,64.710000000,64.830000000,8,8,7,8,64.700000000,64.840000000,7,10,6,9,64.690000000,64.850000000,4,8,3,5,64.680000000,64.860000000,4,4,2,3,64.670000000,64.870000000,6,4,4,3,MCLN5
2025-06-11T00:00:20.830536475Z,2025-06-11T00:00:20.826449799Z,10,1,42026514,M,A,0,64.780000000,1,130,13772,79321910,64.760000000,64.780000000,5,3,5,3,64.750000000,64.790000000,5,7,5,5,64.740000000,64.800000000,9,8,8,7,64.730000000,64.810000000,8,4,8,4,64.720000000,64.820000000,8,9,5,6,64.710000000,64.830000000,8,8,7,8,64.700000000,64.840000000,7,10,6,9,64.690000000,64.850000000,4,8,3,5,64.680000000,64.860000000,4,4,2,3,64.670000000,64.870000000,6,4,4,3,MCLN5
2025-06-11T00:00:20.830555881Z,2025-06-11T00:00:20.826507109Z,10,1,42025623,C,B,5,63.620000000,1,130,11259,79321912,63.670000000,63.690000000,3,1,3,1,63.660000000,63.700000000,3,2,3,2,63.650000000,63.710000000,3,2,3,2,63.640000000,63.720000000,5,2,5,2,63.630000000,63.730000000,5,2,5,2,63.620000000,63.740000000,3,3,3,3,63.610000000,63.750000000,2,2,2,2,63.600000000,63.760000000,7,7,7,7,63.590000000,63.770000000,1,1,1,1,63.580000000,63.780000000,6,3,4,3,MCLQ5
2025-06-11T00:00:20.830733296Z,2025-06-11T00:00:20.826633457Z,10,1,42026514,C,A,0,64.780000000,1,130,13742,79321923,64.760000000,64.780000000,5,2,5,2,64.750000000,64.790000000,5,7,5,5,64.740000000,64.800000000,9,8,8,7,64.730000000,64.810000000,8,4,8,4,64.720000000,64.820000000,8,9,5,6,64.710000000,64.830000000,8,8,7,8,64.700000000,64.840000000,7,10,6,9,64.690000000,64.850000000,4,8,3,5,64.680000000,64.860000000,4,4,2,3,64.670000000,64.870000000,6,4,4,3,MCLN5
2025-06-11T00:00:20.831253719Z,2025-06-11T00:00:20.827656351Z,10,1,42026514,M,B,3,64.720000000,1,130,11859,79321965,64.760000000,64.780000000,5,2,5,2,64.750000000,64.790000000,5,7,5,5,64.740000000,64.800000000,9,8,8,7,64.730000000,64.810000000,7,4,7,4,64.720000000,64.820000000,9,9,6,6,64.710000000,64.830000000,8,8,7,8,64.700000000,64.840000000,7,10,6,9,64.690000000,64.850000000,4,8,3,5,64.680000000,64.860000000,4,4,2,3,64.670000000,64.870000000,6,4,4,3,MCLN5
2025-06-11T00:00:20.831434727Z,2025-06-11T00:00:20.827673783Z,10,1,42025623,M,B,3,63.630000000,1,130,11727,79321978,63.670000000,63.690000000,3,1,3,1,63.660000000,63.700000000,3,2,3,2,63.650000000,63.710000000,3,2,3,2,63.640000000,63.720000000,4,2,4,2,63.630000000,63.730000000,6,2,6,2,63.620000000,63.740000000,3,3,3,3,63.610000000,63.750000000,2,2,2,2,63.600000000,63.760000000,7,7,7,7,63.590000000,63.770000000,1,1,1,1,63.580000000,63.780000000,6,3,4,3,MCLQ5
2025-06-11T00:00:20.831457742Z,2025-06-11T00:00:20.827674377Z,10,1,42025623,M,B,3,63.630000000,1,130,11318,79321980,63.670000000,63.690000000,3,1,3,1,63.660000000,63.700000000,3,2,3,2,63.650000000,63.710000000,3,2,3,2,63.640000000,63.720000000,3,2,3,2,63.630000000,63.730000000,7,2,7,2,63.620000000,63.740000000,3,3,3,3,63.610000000,63.750000000,2,2,2,2,63.600000000,63.760000000,7,7,7,7,63.590000000,63.770000000,1,1,1,1,63.580000000,63.780000000,6,3,4,3,MCLQ5
2025-06-11T00:00:20.831999584Z,2025-06-11T00:00:20.827802301Z,10,1,42026514,M,A,1,64.790000000,1,130,11849,79322009,64.760000000,64.780000000,5,2,5,2,64.750000000,64.790000000,5,8,5,6,64.740000000,64.800000000,9,8,8,7,64.730000000,64.810000000,7,4,7,4,64.720000000,64.820000000,9,9,6,6,64.710000000,64.830000000,8,8,7,8,64.700000000,64.840000000,7,10,6,9,64.690000000,64.850000000,4,8,3,5,64.680000000,64.860000000,4,4,2,3,64.670000000,64.870000000,6,4,4,3,MCLN5
2025-06-11T00:00:20.832259362Z,2025-06-11T00:00:20.827881613Z,10,1,42026514,A,A,0,64.780000000,1,130,14140,79322028,64.760000000,64.780000000,5,3,5,3,64.750000000,64.790000000,5,8,5,6,64.740000000,64.800000000,9,8,8,7,64.730000000,64.810000000,7,4,7,4,64.720000000,64.820000000,9,9,6,6,64.710000000,64.830000000,8,8,7,8,64.700000000,64.840000000,7,10,6,9,64.690000000,64.850000000,4,8,3,5,64.680000000,64.860000000,4,4,2,3,64.670000000,64.870000000,6,4,4,3,MCLN5
2025-06-11T00:00:20.832439310Z,2025-06-11T00:00:20.828067441Z,10,1,42026514,M,A,1,66.720000000,2,130,11515,79322043,64.760000000,64.780000000,5,3,5,3,64.750000000,64.790000000,5,7,5,5,64.740000000,64.800000000,9,8,8,7,64.730000000,64.810000000,7,4,7,4,64.720000000,64.820000000,9,9,6,6,64.710000000,64.830000000,8,8,7,8,64.700000000,64.840000000,7,10,6,9,64.690000000,64.850000000,4,8,3,5,64.680000000,64.860000000,4,4,2,3,64.670000000,64.870000000,6,4,4,3,MCLN5
2025-06-11T00:00:20.832455199Z,2025-06-11T00:00:20.828083971Z,10,1,42026514,C,A,1,64.790000000,1,130,12793,79322044,64.760000000,64.780000000,5,3,5,3,64.750000000,64.790000000,5,6,5,4,64.740000000,64.800000000,9,8,8,7,64.730000000,64.810000000,7,4,7,4,64.720000000,64.820000000,9,9,6,6,64.710000000,64.830000000,8,8,7,8,64.700000000,64.840000000,7,10,6,9,64.690000000,64.850000000,4,8,3,5,64.680000000,64.860000000,4,4,2,3,64.670000000,64.870000000,6,4,4,3,MCLN5
2025-06-11T00:00:20.832470927Z,2025-06-11T00:00:20.828150727Z,10,1,42026514,M,A,1,64.790000000,2,130,14537,79322045,64.760000000,64.780000000,5,3,5,3,64.750000000,64.790000000,5,8,5,5,64.740000000,64.800000000,9,8,8,7,64.730000000,64.810000000,7,4,7,4,64.720000000,64.820000000,9,9,6,6,64.710000000,64.830000000,8,8,7,8,64.700000000,64.840000000,7,10,6,9,64.690000000,64.850000000,4,8,3,5,64.680000000,64.860000000,4,4,2,3,64.670000000,64.870000000,6,4,4,3,MCLN5
2025-06-11T00:00:20.832982948Z,2025-06-11T00:00:20.829062305Z,10,1,42026514,C,A,1,64.790000000,2,130,12742,79322082,64.760000000,64.780000000,5,3,5,3,64.750000000,64.790000000,5,6,5,4,64.740000000,64.800000000,9,8,8,7,64.730000000,64.810000000,7,4,7,4,64.720000000,64.820000000,9,9,6,6,64.710000000,64.830000000,8,8,7,8,64.700000000,64.840000000,7,10,6,9,64.690000000,64.850000000,4,8,3,5,64.680000000,64.860000000,4,4,2,3,64.670000000,64.870000000,6,4,4,3,MCLN5
2025-06-11T00:00:20.833386112Z,2025-06-11T00:00:20.830038465Z,10,1,42025611,M,A,1,2.090000000,20,130,11398,79322110,2.070000000,2.080000000,1,3,1,1,2.060000000,2.090000000,23,27,3,6,2.050000000,2.100000000,23,27,3,6,2.040000000,2.110000000,23,23,3,4,2.030000000,2.120000000,2,2,1,1,2.020000000,2.130000000,2,2,2,2,2.010000000,2.140000000,2,2,1,1,2.000000000,2.150000000,2,2,2,1,1.990000000,2.160000000,2,2,1,1,1.980000000,2.170000000,2,2,2,1,MCLN5-MCLU5
2025-06-11T00:00:20.833394998Z,2025-06-11T00:00:20.830038925Z,10,1,42025623,C,A,0,63.690000000,1,130,11417,79322111,63.670000000,63.700000000,3,2,3,2,63.660000000,63.710000000,3,2,3,2,63.650000000,63.720000000,3,2,3,2,63.640000000,63.730000000,3,2,3,2,63.630000000,63.740000000,7,3,7,3,63.620000000,63.750000000,3,2,3,2,63.610000000,63.760000000,2,7,2,7,63.600000000,63.770000000,7,1,7,1,63.590000000,63.780000000,1,3,1,3,63.580000000,63.790000000,6,1,4,1,MCLQ5
2025-06-11T00:00:20.833659521Z,2025-06-11T00:00:20.830253573Z,10,1,42025623,M,B,2,62.290000000,1,130,11796,79322133,63.670000000,63.700000000,3,2,3,2,63.660000000,63.710000000,3,2,3,2,63.650000000,63.720000000,2,2,2,2,63.640000000,63.730000000,3,2,3,2,63.630000000,63.740000000,7,3,7,3,63.620000000,63.750000000,3,2,3,2,63.610000000,63.760000000,2,7,2,7,63.600000000,63.770000000,7,1,7,1,63.590000000,63.780000000,1,3,1,3,63.580000000,63.790000000,6,1,4,1,MCLQ5
2025-06-11T00:00:20.833828718Z,2025-06-11T00:00:20.830820889Z,10,1,42418117,M,A,0,3.270000000,1,130,11246,79322145,3.250000000,3.270000000,1,1,1,1,3.240000000,3.280000000,11,1,2,1,3.230000000,3.290000000,1,11,1,2,,,0,0,0,0,,,0,0,0,0,,,0,0,0,0,,,0,0,0,0,,,0,0,0,0,,,0,0,0,0,,,0,0,0,0,MCLN5-MCLX5
2025-06-11T00:00:20.834321394Z,2025-06-11T00:00:20.831883847Z,10,1,42025623,A,A,0,63.690000000,1,130,14052,79322182,63.670000000,63.690000000,3,1,3,1,63.660000000,63.700000000,3,2,3,2,63.650000000,63.710000000,2,2,2,2,63.640000000,63.720000000,3,2,3,2,63.630000000,63.730000000,7,2,7,2,63.620000000,63.740000000,3,3,3,3,63.610000000,63.750000000,2,2,2,2,63.600000000,63.760000000,7,7,7,7,63.590000000,63.770000000,1,1,1,1,63.580000000,63.780000000,6,3,4,3,MCLQ5
2025-06-11T00:00:20.836188988Z,2025-06-11T00:00:20.833420607Z,10,1,42025611,A,A,0,2.080000000,2,130,11824,79322304,2.070000000,2.080000000,1,5,1,2,2.060000000,2.090000000,23,27,3,6,2.050000000,2.100000000,23,27,3,6,2.040000000,2.110000000,23,23,3,4,2.030000000,2.120000000,2,2,1,1,2.020000000,2.130000000,2,2,2,2,2.010000000,2.140000000,2,2,1,1,2.000000000,2.150000000,2,2,2,1,1.990000000,2.160000000,2,2,1,1,1.980000000,2.170000000,2,2,2,1,MCLN5-MCLU5
2025-06-11T00:00:20.836196491Z,2025-06-11T00:00:20.833475477Z,10,1,42418117,M,B,0,3.220000000,1,130,11218,79322305,3.240000000,3.270000000,11,1,2,1,3.230000000,3.280000000,1,1,1,1,3.220000000,3.290000000,1,11,1,2,,,0,0,0,0,,,0,0,0,0,,,0,0,0,0,,,0,0,0,0,,,0,0,0,0,,,0,0,0,0,,,0,0,0,0,MCLN5-MCLX5
2025-06-11T00:00:20.836282479Z,2025-06-11T00:00:20.833803515Z,10,1,42025623,M,B,2,63.650000000,1,130,11441,79322311,63.670000000,63.690000000,3,1,3,1,63.660000000,63.700000000,3,2,3,2,63.650000000,63.710000000,3,2,3,2,63.640000000,63.720000000,3,2,3,2,63.630000000,63.730000000,7,2,7,2,63.620000000,63.740000000,3,3,3,3,63.610000000,63.750000000,2,2,2,2,63.600000000,63.760000000,7,7,7,7,63.590000000,63.770000000,1,1,1,1,63.580000000,63.780000000,6,3,4,3,MCLQ5
2025-06-11T00:00:20.836748999Z,2025-06-11T00:00:20.834468227Z,10,1,42025623,M,B,2,62.280000000,1,130,11639,79322343,63.670000000,63.690000000,3,1,3,1,63.660000000,63.700000000,3,2,3,2,63.650000000,63.710000000,2,2,2,2,63.640000000,63.720000000,3,2,3,2,63.630000000,63.730000000,7,2,7,2,63.620000000,63.740000000,3,3,3,3,63.610000000,63.750000000,2,2,2,2,63.600000000,63.760000000,7,7,7,7,63.590000000,63.770000000,1,1,1,1,63.580000000,63.780000000,6,3,4,3,MCLQ5
2025-06-11T00:00:20.837494105Z,2025-06-11T00:00:20.834915587Z,10,1,42025623,A,A,0,63.690000000,1,130,13488,79322390,63.670000000,63.690000000,3,2,3,2,63.660000000,63.700000000,3,2,3,2,63.650000000,63.710000000,2,2,2,2,63.640000000,63.720000000,3,2,3,2,63.630000000,63.730000000,7,2,7,2,63.620000000,63.740000000,3,3,3,3,63.610000000,63.750000000,2,2,2,2,63.600000000,63.760000000,7,7,7,7,63.590000000,63.770000000,1,1,1,1,63.580000000,63.780000000,6,3,4,3,MCLQ5
2025-06-11T00:00:20.838642580Z,2025-06-11T00:00:20.836042615Z,10,1,42026514,A,A,0,64.770000000,2,130,11204,79322457,64.760000000,64.770000000,5,2,5,1,64.750000000,64.780000000,5,3,5,3,64.740000000,64.790000000,9,6,8,4,64.730000000,64.800000000,7,8,7,7,64.720000000,64.810000000,9,4,6,4,64.710000000,64.820000000,8,9,7,6,64.700000000,64.830000000,7,8,6,8,64.690000000,64.840000000,4,10,3,9,64.680000000,64.850000000,4,8,2,5,64.670000000,64.860000000,6,4,4,3,MCLN5
2025-06-11T00:00:20.838685387Z,2025-06-11T00:00:20.836128167Z,10,1,42026514,A,A,0,64.770000000,1,130,13260,79322461,64.760000000,64.770000000,5,3,5,2,64.750000000,64.780000000,5,3,5,3,64.740000000,64.790000000,9,6,8,4,64.730000000,64.800000000,7,8,7,7,64.720000000,64.810000000,9,4,6,4,64.710000000,64.820000000,8,9,7,6,64.700000000,64.830000000,7,8,6,8,64.690000000,64.840000000,4,10,3,9,64.680000000,64.850000000,4,8,2,5,64.670000000,64.860000000,6,4,4,3,MCLN5
2025-06-11T00:00:20.840013166Z,2025-06-11T00:00:20.837813085Z,10,1,42418117,M,A,1,3.280000000,10,130,11258,79322545,3.240000000,3.270000000,11,1,2,1,3.230000000,3.280000000,1,11,1,2,3.220000000,3.290000000,1,1,1,1,,,0,0,0,0,,,0,0,0,0,,,0,0,0,0,,,0,0,0,0,,,0,0,0,0,,,0,0,0,0,,,0,0,0,0,MCLN5-MCLX5
2025-06-11T00:00:20.840309943Z,2025-06-11T00:00:20.838646155Z,10,1,42026514,T,B,0,64.770000000,1,0,12144,79322565,64.760000000,64.770000000,5,3,5,2,64.750000000,64.780000000,5,3,5,3,64.740000000,64.790000000,9,6,8,4,64.730000000,64.800000000,7,8,7,7,64.720000000,64.810000000,9,4,6,4,64.710000000,64.820000000,8,9,7,6,64.700000000,64.830000000,7,8,6,8,64.690000000,64.840000000,4,10,3,9,64.680000000,64.850000000,4,8,2,5,64.670000000,64.860000000,6,4,4,3,MCLN5
2025-06-11T00:00:20.840332475Z,2025-06-11T00:00:20.838646155Z,10,1,42026514,M,A,0,64.770000000,1,130,13868,79322566,64.760000000,64.770000000,5,2,5,2,64.750000000,64.780000000,5,3,5,3,64.740000000,64.790000000,9,6,8,4,64.730000000,64.800000000,7,8,7,7,64.720000000,64.810000000,9,4,6,4,64.710000000,64.820000000,8,9,7,6,64.700000000,64.830000000,7,8,6,8,64.690000000,64.840000000,4,10,3,9,64.680000000,64.850000000,4,8,2,5,64.670000000,64.860000000,6,4,4,3,MCLN5
2025-06-11T00:00:20.840345769Z,2025-06-11T00:00:20.838651951Z,10,1,42026514,C,A,1,64.780000000,1,130,12622,79322567,64.760000000,64.770000000,5,2,5,2,64.750000000,64.780000000,5,2,5,2,64.740000000,64.790000000,9,6,8,4,64.730000000,64.800000000,7,8,7,7,64.720000000,64.810000000,9,4,6,4,64.710000000,64.820000000,8,9,7,6,64.700000000,64.830000000,7,8,6,8,64.690000000,64.840000000,4,10,3,9,64.680000000,64.850000000,4,8,2,5,64.670000000,64.860000000,6,4,4,3,MCLN5
2025-06-11T00:00:20.840359331Z,2025-06-11T00:00:20.838799903Z,10,1,42026514,M,A,2,64.790000000,1,130,13982,79322568,64.760000000,64.770000000,5,2,5,2,64.750000000,64.780000000,5,2,5,2,64.740000000,64.790000000,9,7,8,5,64.730000000,64.800000000,7,8,7,7,64.720000000,64.810000000,9,4,6,4,64.710000000,64.820000000,8,9,7,6,64.700000000,64.830000000,7,8,6,8,64.690000000,64.840000000,4,10,3,9,64.680000000,64.850000000,4,8,2,5,64.670000000,64.860000000,6,4,4,3,MCLN5
2025-06-11T00:00:20.840376810Z,2025-06-11T00:00:20.838848763Z,10,1,42026514,T,B,0,64.770000000,2,0,11600,79322570,64.760000000,64.770000000,5,2,5,2,64.750000000,64.780000000,5,2,5,2,64.740000000,64.790000000,9,7,8,5,64.730000000,64.800000000,7,8,7,7,64.720000000,64.810000000,9,4,6,4,64.710000000,64.820000000,8,9,7,6,64.700000000,64.830000000,7,8,6,8,64.690000000,64.840000000,4,10,3,9,64.680000000,64.850000000,4,8,2,5,64.670000000,64.860000000,6,4,4,3,MCLN5
2025-06-11T00:00:20.840395947Z,2025-06-11T00:00:20.838848763Z,10,1,42026514,C,A,0,64.770000000,1,130,11646,79322571,64.760000000,64.780000000,5,2,5,2,64.750000000,64.790000000,5,7,5,5,64.740000000,64.800000000,9,8,8,7,64.730000000,64.810000000,7,4,7,4,64.720000000,64.820000000,9,9,6,6,64.710000000,64.830000000,8,8,7,8,64.700000000,64.840000000,7,10,6,9,64.690000000,64.850000000,4,8,3,5,64.680000000,64.860000000,4,4,2,3,64.670000000,64.870000000,6,4,4,3,MCLN5
2025-06-11T00:00:20.840415899Z,2025-06-11T00:00:20.838865987Z,10,1,42025623,M,B,2,63.650000000,1,130,14402,79322573,63.670000000,63.690000000,3,2,3,2,63.660000000,63.700000000,3,2,3,2,63.650000000,63.710000000,3,2,3,2,63.640000000,63.720000000,3,2,3,2,63.630000000,63.730000000,7,2,7,2,63.620000000,63.740000000,3,3,3,3,63.610000000,63.750000000,2,2,2,2,63.600000000,63.760000000,7,7,7,7,63.590000000,63.770000000,1,1,1,1,63.580000000,63.780000000,6,3,4,3,MCLQ5
2025-06-11T00:00:20.840496878Z,2025-06-11T00:00:20.839282453Z,10,1,42025611,M,A,0,2.080000000,1,130,12441,79322581,2.070000000,2.080000000,1,6,1,3,2.060000000,2.090000000,23,27,3,6,2.050000000,2.100000000,23,27,3,6,2.040000000,2.110000000,23,22,3,3,2.030000000,2.120000000,2,2,1,1,2.020000000,2.130000000,2,2,2,2,2.010000000,2.140000000,2,2,1,1,2.000000000,2.150000000,2,2,2,1,1.990000000,2.160000000,2,2,1,1,1.980000000,2.170000000,2,2,2,1,MCLN5-MCLU5
2025-06-11T00:00:20.841179580Z,2025-06-11T00:00:20.840405163Z,10,1,42026514,A,A,0,64.780000000,1,130,13964,79322619,64.760000000,64.780000000,5,3,5,3,64.750000000,64.790000000,5,7,5,5,64.740000000,64.800000000,9,8,8,7,64.730000000,64.810000000,7,4,7,4,64.720000000,64.820000000,9,9,6,6,64.710000000,64.830000000,8,8,7,8,64.700000000,64.840000000,7,10,6,9,64.690000000,64.850000000,4,8,3,5,64.680000000,64.860000000,4,4,2,3,64.670000000,64.870000000,6,4,4,3,MCLN5
2025-06-11T00:00:20.841337166Z,2025-06-11T00:00:20.840511295Z,10,1,42026514,C,A,1,64.790000000,1,130,12527,79322628,64.760000000,64.780000000,5,3,5,3,64.750000000,64.790000000,5,6,5,4,64.740000000,64.800000000,9,8,8,7,64.730000000,64.810000000,7,4,7,4,64.720000000,64.820000000,9,9,6,6,64.710000000,64.830000000,8,8,7,8,64.700000000,64.840000000,7,10,6,9,64.690000000,64.850000000,4,8,3,5,64.680000000,64.860000000,4,4,2,3,64.670000000,64.870000000,6,4,4,3,MCLN5
2025-06-11T00:00:20.842895525Z,2025-06-11T00:00:20.842722979Z,10,1,42025623,C,A,0,63.690000000,1,130,13856,79322657,63.670000000,63.690000000,3,1,3,1,63.660000000,63.700000000,3,2,3,2,63.650000000,63.710000000,3,2,3,2,63.640000000,63.720000000,3,2,3,2,63.630000000,63.730000000,7,2,7,2,63.620000000,63.740000000,3,3,3,3,63.610000000,63.750000000,2,2,2,2,63.600000000,63.760000000,7,7,7,7,63.590000000,63.770000000,1,1,1,1,63.580000000,63.780000000,6,3,4,3,MCLQ5
2025-06-11T00:00:20.843086916Z,2025-06-11T00:00:20.842992267Z,10,1,42025623,M,B,2,62.270000000,1,130,11789,79322661,63.670000000,63.690000000,3,1,3,1,63.660000000,63.700000000,3,2,3,2,63.650000000,63.710000000,2,2,2,2,63.640000000,63.720000000,3,2,3,2,63.630000000,63.730000000,7,2,7,2,63.620000000,63.740000000,3,3,3,3,63.610000000,63.750000000,2,2,2,2,63.600000000,63.760000000,7,7,7,7,63.590000000,63.770000000,1,1,1,1,63.580000000,63.780000000,6,3,4,3,MCLQ5
2025-06-11T00:00:20.849617130Z,2025-06-11T00:00:20.849501105Z,10,1,42026514,A,A,0,64.780000000,1,130,15330,79322702,64.760000000,64.780000000,5,4,5,4,64.750000000,64.790000000,5,6,5,4,64.740000000,64.800000000,9,8,8,7,64.730000000,64.810000000,7,4,7,4,64.720000000,64.820000000,9,9,6,6,64.710000000,64.830000000,8,8,7,8,64.700000000,64.840000000,7,10,6,9,64.690000000,64.850000000,4,8,3,5,64.680000000,64.860000000,4,4,2,3,64.670000000,64.870000000,6,4,4,3,MCLN5
2025-06-11T00:00:20.849727117Z,2025-06-11T00:00:20.849627859Z,10,1,42025623,A,B,6,63.610000000,1,130,13583,79322704,63.670000000,63.690000000,3,1,3,1,63.660000000,63.700000000,3,2,3,2,63.650000000,63.710000000,2,2,2,2,63.640000000,63.720000000,3,2,3,2,63.630000000,63.730000000,7,2,7,2,63.620000000,63.740000000,3,3,3,3,63.610000000,63.750000000,3,2,3,2,63.600000000,63.760000000,7,7,7,7,63.590000000,63.770000000,1,1,1,1,63.580000000,63.780000000,6,3,4,3,MCLQ5
2025-06-11T00:00:20.849735703Z,2025-06-11T00:00:20.849629279Z,10,1,42025623,C,A,7,63.760000000,1,130,11168,79322705,63.670000000,63.690000000,3,1,3,1,63.660000000,63.700000000,3,2,3,2,63.650000000,63.710000000,2,2,2,2,63.640000000,63.720000000,3,2,3,2,63.630000000,63.730000000,7,2,7,2,63.620000000,63.740000000,3,3,3,3,63.610000000,63.750000000,3,2,3,2,63.600000000,63.760000000,7,6,7,6,63.590000000,63.770000000,1,1,1,1,63.580000000,63.780000000,6,3,4,3,MCLQ5
2025-06-11T00:00:20.849853992Z,2025-06-11T00:00:20.849758375Z,10,1,42025623,A,A,6,63.750000000,1,130,13289,79322706,63.670000000,63.690000000,3,1,3,1,63.660000000,63.700000000,3,2,3,2,63.650000000,63.710000000,2,2,2,2,63.640000000,63.720000000,3,2,3,2,63.630000000,63.730000000,7,2,7,2,63.620000000,63.740000000,3,3,3,3,63.610000000,63.750000000,3,3,3,3,63.600000000,63.760000000,7,6,7,6,63.590000000,63.770000000,1,1,1,1,63.580000000,63.780000000,6,3,4,3,MCLQ5
2025-06-11T00:00:20.852569151Z,2025-06-11T00:00:20.852467315Z,10,1,42026514,A,B,5,64.710000000,1,130,14922,79322712,64.760000000,64.780000000,5,4,5,4,64.750000000,64.790000000,5,6,5,4,64.740000000,64.800000000,9,8,8,7,64.730000000,64.810000000,7,4,7,4,64.720000000,64.820000000,9,9,6,6,64.710000000,64.830000000,9,8,8,8,64.700000000,64.840000000,7,10,6,9,64.690000000,64.850000000,4,8,3,5,64.680000000,64.860000000,4,4,2,3,64.670000000,64.870000000,6,4,4,3,MCLN5
2025-06-11T00:00:20.852579212Z,2025-06-11T00:00:20.852468601Z,10,1,42026514,C,A,6,64.840000000,1,130,13324,79322713,64.760000000,64.780000000,5,4,5,4,64.750000000,64.790000000,5,6,5,4,64.740000000,64.800000000,9,8,8,7,64.730000000,64.810000000,7,4,7,4,64.720000000,64.820000000,9,9,6,6,64.710000000,64.830000000,9,8,8,8,64.700000000,64.840000000,7,9,6,8,64.690000000,64.850000000,4,8,3,5,64.680000000,64.860000000,4,4,2,3,64.670000000,64.870000000,6,4,4,3,MCLN5
2025-06-11T00:00:20.852693254Z,2025-06-11T00:00:20.852597889Z,10,1,42026514,A,A,5,64.830000000,1,130,14735,79322714,64.760000000,64.780000000,5,4,5,4,64.750000000,64.790000000,5,6,5,4,64.740000000,64.800000000,9,8,8,7,64.730000000,64.810000000,7,4,7,4,64.720000000,64.820000000,9,9,6,6,64.710000000,64.830000000,9,9,8,9,64.700000000,64.840000000,7,9,6,8,64.690000000,64.850000000,4,8,3,5,64.680000000,64.860000000,4,4,2,3,64.670000000,64.870000000,6,4,4,3,MCLN5
2025-06-11T00:00:20.926755810Z,2025-06-11T00:00:20.926621905Z,10,1,42026514,A,A,0,64.770000000,1,130,15601,79322978,64.760000000,64.770000000,5,1,5,1,64.750000000,64.780000000,5,4,5,4,64.740000000,64.790000000,9,6,8,4,64.730000000,64.800000000,7,8,7,7,64.720000000,64.810000000,9,4,6,4,64.710000000,64.820000000,9,9,8,6,64.700000000,64.830000000,7,9,6,9,64.690000000,64.840000000,4,9,3,8,64.680000000,64.850000000,4,8,2,5,64.670000000,64.860000000,6,4,4,3,MCLN5
2025-06-11T00:00:20.926821870Z,2025-06-11T00:00:20.926654755Z,10,1,42026514,A,A,0,64.770000000,1,130,14030,79322983,64.760000000,64.770000000,5,2,5,2,64.750000000,64.780000000,5,4,5,4,64.740000000,64.790000000,9,6,8,4,64.730000000,64.800000000,7,8,7,7,64.720000000,64.810000000,9,4,6,4,64.710000000,64.820000000,9,9,8,6,64.700000000,64.830000000,7,9,6,9,64.690000000,64.840000000,4,9,3,8,64.680000000,64.850000000,4,8,2,5,64.670000000,64.860000000,6,4,4,3,MCLN5
2025-06-11T00:00:20.926863962Z,2025-06-11T00:00:20.926658135Z,10,1,42026514,A,A,0,64.770000000,2,130,16955,79322985,64.760000000,64.770000000,5,4,5,3,64.750000000,64.780000000,5,4,5,4,64.740000000,64.790000000,9,6,8,4,64.730000000,64.800000000,7,8,7,7,64.720000000,64.810000000,9,4,6,4,64.710000000,64.820000000,9,9,8,6,64.700000000,64.830000000,7,9,6,9,64.690000000,64.840000000,4,9,3,8,64.680000000,64.850000000,4,8,2,5,64.670000000,64.860000000,6,4,4,3,MCLN5
2025-06-11T00:00:20.927588701Z,2025-06-11T00:00:20.927117705Z,10,1,42022708,M,A,0,2.820000000,1,130,15543,79323028,2.810000000,2.820000000,1,1,1,1,2.800000000,2.830000000,12,12,3,3,2.790000000,2.840000000,2,2,2,2,2.780000000,2.870000000,1,1,1,1,,,0,0,0,0,,,0,0,0,0,,,0,0,0,0,,,0,0,0,0,,,0,0,0,0,,,0,0,0,0,MCLN5-MCLV5
2025-06-11T00:00:20.937269577Z,2025-06-11T00:00:20.937167211Z,10,1,42026514,M,A,4,64.810000000,1,130,14533,79323170,64.760000000,64.770000000,5,4,5,3,64.750000000,64.780000000,5,4,5,4,64.740000000,64.790000000,9,6,8,4,64.730000000,64.800000000,7,8,7,7,64.720000000,64.810000000,9,5,6,5,64.710000000,64.820000000,9,9,8,6,64.700000000,64.830000000,7,9,6,9,64.690000000,64.840000000,4,9,3,8,64.680000000,64.850000000,4,8,2,5,64.670000000,64.860000000,6,4,4,3,MCLN5
2025-06-11T00:00:20.937416257Z,2025-06-11T00:00:20.937306385Z,10,1,42026514,C,A,0,64.770000000,2,130,16535,79323171,64.760000000,64.770000000,5,2,5,2,64.750000000,64.780000000,5,4,5,4,64.740000000,64.790000000,9,6,8,4,64.730000000,64.800000000,7,8,7,7,64.720000000,64.810000000,9,5,6,5,64.710000000,64.820000000,9,9,8,6,64.700000000,64.830000000,7,9,6,9,64.690000000,64.840000000,4,9,3,8,64.680000000,64.850000000,4,8,2,5,64.670000000,64.860000000,6,4,4,3,MCLN5
2025-06-11T00:00:21.015916176Z,2025-06-11T00:00:21.015816917Z,10,1,42022708,M,A,0,2.850000000,1,130,14924,79323361,2.810000000,2.830000000,1,12,1,3,2.800000000,2.840000000,12,2,3,2,2.790000000,2.850000000,2,1,2,1,2.780000000,2.870000000,1,1,1,1,,,0,0,0,0,,,0,0,0,0,,,0,0,0,0,,,0,0,0,0,,,0,0,0,0,,,0,0,0,0,MCLN5-MCLV5
2025-06-11T00:00:21.254410590Z,2025-06-11T00:00:21.251982525Z,10,1,42026514,M,A,4,64.810000000,1,130,15183,79323632,64.760000000,64.770000000,5,2,5,2,64.750000000,64.780000000,5,4,5,4,64.740000000,64.790000000,9,6,8,4,64.730000000,64.800000000,7,8,7,7,64.720000000,64.810000000,9,6,6,6,64.710000000,64.820000000,9,9,8,6,64.700000000,64.830000000,7,9,6,9,64.690000000,64.840000000,4,8,3,7,64.680000000,64.850000000,4,8,2,5,64.670000000,64.860000000,6,4,4,3,MCLN5
2025-06-11T00:00:21.254422233Z,2025-06-11T00:00:21.251983407Z,10,1,42026514,M,A,4,64.810000000,1,130,14657,79323633,64.760000000,64.770000000,5,2,5,2,64.750000000,64.780000000,5,4,5,4,64.740000000,64.790000000,9,6,8,4,64.730000000,64.800000000,7,8,7,7,64.720000000,64.810000000,9,7,6,7,64.710000000,64.820000000,9,9,8,6,64.700000000,64.830000000,7,9,6,9,64.690000000,64.840000000,4,7,3,6,64.680000000,64.850000000,4,8,2,5,64.670000000,64.860000000,6,4,4,3,MCLN5
2025-06-11T00:00:21.254428399Z,2025-06-11T00:00:21.251984327Z,10,1,42026514,M,A,4,64.810000000,1,130,11729,79323634,64.760000000,64.770000000,5,2,5,2,64.750000000,64.780000000,5,4,5,4,64.740000000,64.790000000,9,6,8,4,64.730000000,64.800000000,7,8,7,7,64.720000000,64.810000000,9,8,6,8,64.710000000,64.820000000,9,9,8,6,64.700000000,64.830000000,7,9,6,9,64.690000000,64.840000000,4,6,3,5,64.680000000,64.850000000,4,8,2,5,64.670000000,64.860000000,6,4,4,3,MCLN5
2025-06-11T00:00:21.254441908Z,2025-06-11T00:00:21.251985211Z,10,1,42025623,M,A,4,63.730000000,1,130,11455,79323635,63.670000000,63.690000000,3,1,3,1,63.660000000,63.700000000,3,2,3,2,63.650000000,63.710000000,2,2,2,2,63.640000000,63.720000000,3,2,3,2,63.630000000,63.730000000,7,3,7,3,63.620000000,63.740000000,3,3,3,3,63.610000000,63.750000000,3,3,3,3,63.600000000,63.760000000,7,5,7,5,63.590000000,63.770000000,1,1,1,1,63.580000000,63.780000000,6,3,4,3,MCLQ5
2025-06-11T00:00:21.254455186Z,2025-06-11T00:00:21.251986229Z,10,1,42025623,M,A,4,63.730000000,1,130,13025,79323636,63.670000000,63.690000000,3,1,3,1,63.660000000,63.700000000,3,2,3,2,63.650000000,63.710000000,2,2,2,2,63.640000000,63.720000000,3,2,3,2,63.630000000,63.730000000,7,4,7,4,63.620000000,63.740000000,3,3,3,3,63.610000000,63.750000000,3,3,3,3,63.600000000,63.760000000,7,4,7,4,63.590000000,63.770000000,1,1,1,1,63.580000000,63.780000000,6,3,4,3,MCLQ5
2025-06-11T00:00:21.254464325Z,2025-06-11T00:00:21.251987189Z,10,1,42025623,M,A,5,63.740000000,1,130,11334,79323637,63.670000000,63.690000000,3,1,3,1,63.660000000,63.700000000,3,2,3,2,63.650000000,63.710000000,2,2,2,2,63.640000000,63.720000000,3,2,3,2,63.630000000,63.730000000,7,4,7,4,63.620000000,63.740000000,3,4,3,4,63.610000000,63.750000000,3,3,3,3,63.600000000,63.760000000,7,3,7,3,63.590000000,63.770000000,1,1,1,1,63.580000000,63.780000000,6,3,4,3,MCLQ5
2025-06-11T00:00:21.294935998Z,2025-06-11T00:00:21.294803869Z,10,1,42025623,C,B,7,63.600000000,1,130,15238,79323645,63.670000000,63.690000000,3,1,3,1,63.660000000,63.700000000,3,2,3,2,63.650000000,63.710000000,2,2,2,2,63.640000000,63.720000000,3,2,3,2,63.630000000,63.730000000,7,4,7,4,63.620000000,63.740000000,3,4,3,4,63.610000000,63.750000000,3,3,3,3,63.600000000,63.760000000,6,3,6,3,63.590000000,63.770000000,1,1,1,1,63.580000000,63.780000000,6,3,4,3,MCLQ5
2025-06-11T00:00:21.294944491Z,2025-06-11T00:00:21.294804157Z,10,1,42025623,A,B,5,63.620000000,1,130,11484,79323646,63.670000000,63.690000000,3,1,3,1,63.660000000,63.700000000,3,2,3,2,63.650000000,63.710000000,2,2,2,2,63.640000000,63.720000000,3,2,3,2,63.630000000,63.730000000,7,4,7,4,63.620000000,63.740000000,4,4,4,4,63.610000000,63.750000000,3,3,3,3,63.600000000,63.760000000,6,3,6,3,63.590000000,63.770000000,1,1,1,1,63.580000000,63.780000000,6,3,4,3,MCLQ5
2025-06-11T00:00:21.294955120Z,2025-06-11T00:00:21.294804405Z,10,1,42025623,A,A,7,63.760000000,1,130,11740,79323647,63.670000000,63.690000000,3,1,3,1,63.660000000,63.700000000,3,2,3,2,63.650000000,63.710000000,2,2,2,2,63.640000000,63.720000000,3,2,3,2,63.630000000,63.730000000,7,4,7,4,63.620000000,63.740000000,4,4,4,4,63.610000000,63.750000000,3,3,3,3,63.600000000,63.760000000,6,4,6,4,63.590000000,63.770000000,1,1,1,1,63.580000000,63.780000000,6,3,4,3,MCLQ5
2025-06-11T00:00:21.408709526Z,2025-06-11T00:00:21.408576885Z,10,1,42026514,C,A,0,64.770000000,1,130,19671,79323731,64.760000000,64.770000000,5,1,5,1,64.750000000,64.780000000,5,4,5,4,64.740000000,64.790000000,9,6,8,4,64.730000000,64.800000000,7,8,7,7,64.720000000,64.810000000,9,8,6,8,64.710000000,64.820000000,9,9,8,6,64.700000000,64.830000000,7,9,6,9,64.690000000,64.840000000,4,6,3,5,64.680000000,64.850000000,4,8,2,5,64.670000000,64.860000000,6,4,4,3,MCLN5
2025-06-11T00:00:21.408958199Z,2025-06-11T00:00:21.408719303Z,10,1,42026514,T,B,0,64.770000000,1,0,14740,79323735,64.760000000,64.770000000,5,1,5,1,64.750000000,64.780000000,5,4,5,4,64.740000000,64.790000000,9,6,8,4,64.730000000,64.800000000,7,8,7,7,64.720000000,64.810000000,9,8,6,8,64.710000000,64.820000000,9,9,8,6,64.700000000,64.830000000,7,9,6,9,64.690000000,64.840000000,4,6,3,5,64.680000000,64.850000000,4,8,2,5,64.670000000,64.860000000,6,4,4,3,MCLN5
2025-06-11T00:00:21.408967353Z,2025-06-11T00:00:21.408719303Z,10,1,42026514,C,A,0,64.770000000,1,130,11995,79323736,64.760000000,64.780000000,5,4,5,4,64.750000000,64.790000000,5,6,5,4,64.740000000,64.800000000,9,8,8,7,64.730000000,64.810000000,7,8,7,8,64.720000000,64.820000000,9,9,6,6,64.710000000,64.830000000,9,9,8,9,64.700000000,64.840000000,7,6,6,5,64.690000000,64.850000000,4,8,3,5,64.680000000,64.860000000,4,4,2,3,64.670000000,64.870000000,6,4,4,3,MCLN5
2025-06-11T00:00:21.416738114Z,2025-06-11T00:00:21.408995235Z,10,1,42026514,M,A,3,64.820000000,1,130,11827,79323749,64.760000000,64.780000000,5,4,5,4,64.750000000,64.790000000,5,6,5,4,64.740000000,64.800000000,9,8,8,7,64.730000000,64.810000000,7,7,7,7,64.720000000,64.820000000,9,10,6,7,64.710000000,64.830000000,9,9,8,9,64.700000000,64.840000000,7,6,6,5,64.690000000,64.850000000,4,8,3,5,64.680000000,64.860000000,4,4,2,3,64.670000000,64.870000000,6,4,4,3,MCLN5
2025-06-11T00:00:21.416747943Z,2025-06-11T00:00:21.408995925Z,10,1,42026514,M,B,3,64.730000000,1,130,11405,79323750,64.760000000,64.780000000,5,4,5,4,64.750000000,64.790000000,5,6,5,4,64.740000000,64.800000000,9,8,8,7,64.730000000,64.810000000,8,7,8,7,64.720000000,64.820000000,8,10,5,7,64.710000000,64.830000000,9,9,8,9,64.700000000,64.840000000,7,6,6,5,64.690000000,64.850000000,4,8,3,5,64.680000000,64.860000000,4,4,2,3,64.670000000,64.870000000,6,4,4,3,MCLN5
2025-06-11T00:00:21.416864097Z,2025-06-11T00:00:21.409031463Z,10,1,42026514,A,B,0,64.760000000,1,130,13538,79323756,64.760000000,64.780000000,6,4,6,4,64.750000000,64.790000000,5,6,5,4,64.740000000,64.800000000,9,8,8,7,64.730000000,64.810000000,8,7,8,7,64.720000000,64.820000000,8,10,5,7,64.710000000,64.830000000,9,9,8,9,64.700000000,64.840000000,7,6,6,5,64.690000000,64.850000000,4,8,3,5,64.680000000,64.860000000,4,4,2,3,64.670000000,64.870000000,6,4,4,3,MCLN5
2025-06-11T00:00:21.417323145Z,2025-06-11T00:00:21.416994983Z,10,1,42026514,A,B,0,64.770000000,2,130,15367,79323785,64.770000000,64.780000000,2,4,1,4,64.760000000,64.790000000,6,6,6,4,64.750000000,64.800000000,5,8,5,7,64.740000000,64.810000000,9,7,8,7,64.730000000,64.820000000,8,10,8,7,64.720000000,64.830000000,8,9,5,9,64.710000000,64.840000000,9,6,8,5,64.700000000,64.850000000,7,8,6,5,64.690000000,64.860000000,4,4,3,3,64.680000000,64.870000000,4,4,2,3,MCLN5
2025-06-11T00:00:21.417687734Z,2025-06-11T00:00:21.417067171Z,10,1,42026514,M,A,1,64.790000000,1,130,11376,79323805,64.770000000,64.780000000,2,4,1,4,64.760000000,64.790000000,6,7,6,5,64.750000000,64.800000000,5,8,5,7,64.740000000,64.810000000,9,7,8,7,64.730000000,64.820000000,8,10,8,7,64.720000000,64.830000000,8,9,5,9,64.710000000,64.840000000,9,6,8,5,64.700000000,64.850000000,7,8,6,5,64.690000000,64.860000000,4,4,3,3,64.680000000,64.870000000,4,4,2,3,MCLN5
2025-06-11T00:00:21.417727975Z,2025-06-11T00:00:21.417130989Z,10,1,42025623,C,A,0,63.690000000,1,130,13771,79323806,63.670000000,63.700000000,3,2,3,2,63.660000000,63.710000000,3,2,3,2,63.650000000,63.720000000,2,2,2,2,63.640000000,63.730000000,3,4,3,4,63.630000000,63.740000000,7,4,7,4,63.620000000,63.750000000,4,3,4,3,63.610000000,63.760000000,3,4,3,4,63.600000000,63.770000000,6,1,6,1,63.590000000,63.780000000,1,3,1,3,63.580000000,63.790000000,6,1,4,1,MCLQ5
2025-06-11T00:00:21.418015000Z,2025-06-11T00:00:21.417330393Z,10,1,42026514,C,A,5,64.830000000,1,130,11185,79323821,64.770000000,64.780000000,2,4,1,4,64.760000000,64.790000000,6,7,6,5,64.750000000,64.800000000,5,8,5,7,64.740000000,64.810000000,9,7,8,7,64.730000000,64.820000000,8,10,8,7,64.720000000,64.830000000,8,8,5,8,64.710000000,64.840000000,9,6,8,5,64.700000000,64.850000000,7,8,6,5,64.690000000,64.860000000,4,4,3,3,64.680000000,64.870000000,4,4,2,3,MCLN5
2025-06-11T00:00:21.418085115Z,2025-06-11T00:00:21.417336247Z,10,1,42025623,C,A,5,63.750000000,1,130,11293,79323824,63.670000000,63.700000000,3,2,3,2,63.660000000,63.710000000,3,2,3,2,63.650000000,63.720000000,2,2,2,2,63.640000000,63.730000000,3,4,3,4,63.630000000,63.740000000,7,4,7,4,63.620000000,63.750000000,4,2,4,2,63.610000000,63.760000000,3,4,3,4,63.600000000,63.770000000,6,1,6,1,63.590000000,63.780000000,1,3,1,3,63.580000000,63.790000000,6,1,4,1,MCLQ5
2025-06-11T00:00:21.418129526Z,2025-06-11T00:00:21.417344733Z,10,1,42025623,C,B,6,63.610000000,1,130,10636,79323826,63.670000000,63.700000000,3,2,3,2,63.660000000,63.710000000,3,2,3,2,63.650000000,63.720000000,2,2,2,2,63.640000000,63.730000000,3,4,3,4,63.630000000,63.740000000,7,4,7,4,63.620000000,63.750000000,4,2,4,2,63.610000000,63.760000000,2,4,2,4,63.600000000,63.770000000,6,1,6,1,63.590000000,63.780000000,1,3,1,3,63.580000000,63.790000000,6,1,4,1,MCLQ5
2025-06-11T00:00:21.418162041Z,2025-06-11T00:00:21.417496349Z,10,1,42025623,A,A,6,63.760000000,1,130,11262,79323828,63.670000000,63.700000000,3,2,3,2,63.660000000,63.710000000,3,2,3,2,63.650000000,63.720000000,2,2,2,2,63.640000000,63.730000000,3,4,3,4,63.630000000,63.740000000,7,4,7,4,63.620000000,63.750000000,4,2,4,2,63.610000000,63.760000000,2,5,2,5,63.600000000,63.770000000,6,1,6,1,63.590000000,63.780000000,1,3,1,3,63.580000000,63.790000000,6,1,4,1,MCLQ5
2025-06-11T00:00:21.418176417Z,2025-06-11T00:00:21.417516413Z,10,1,42025623,A,B,5,63.620000000,1,130,14976,79323829,63.670000000,63.700000000,3,2,3,2,63.660000000,63.710000000,3,2,3,2,63.650000000,63.720000000,2,2,2,2,63.640000000,63.730000000,3,4,3,4,63.630000000,63.740000000,7,4,7,4,63.620000000,63.750000000,5,2,5,2,63.610000000,63.760000000,2,5,2,5,63.600000000,63.770000000,6,1,6,1,63.590000000,63.780000000,1,3,1,3,63.580000000,63.790000000,6,1,4,1,MCLQ5
2025-06-11T00:00:21.418210269Z,2025-06-11T00:00:21.417580537Z,10,1,42026514,M,A,0,64.780000000,1,130,13212,79323831,64.770000000,64.780000000,2,5,1,5,64.760000000,64.790000000,6,7,6,5,64.750000000,64.800000000,5,8,5,7,64.740000000,64.810000000,9,7,8,7,64.730000000,64.820000000,8,10,8,7,64.720000000,64.830000000,8,8,5,8,64.710000000,64.840000000,9,6,8,5,64.700000000,64.850000000,7,8,6,5,64.690000000,64.860000000,4,4,3,3,64.680000000,64.870000000,4,4,2,3,MCLN5
2025-06-11T00:00:21.418390893Z,2025-06-11T00:00:21.417908997Z,10,1,42026514,M,A,0,66.720000000,2,130,13537,79323841,64.770000000,64.780000000,2,4,1,4,64.760000000,64.790000000,6,7,6,5,64.750000000,64.800000000,5,8,5,7,64.740000000,64.810000000,9,7,8,7,64.730000000,64.820000000,8,10,8,7,64.720000000,64.830000000,8,8,5,8,64.710000000,64.840000000,9,6,8,5,64.700000000,64.850000000,7,8,6,5,64.690000000,64.860000000,4,4,3,3,64.680000000,64.870000000,4,4,2,3,MCLN5
2025-06-11T00:00:21.418827616Z,2025-06-11T00:00:21.418602431Z,10,1,42026514,M,A,1,66.730000000,2,130,11654,79323864,64.770000000,64.780000000,2,4,1,4,64.760000000,64.790000000,6,6,6,4,64.750000000,64.800000000,5,8,5,7,64.740000000,64.810000000,9,7,8,7,64.730000000,64.820000000,8,10,8,7,64.720000000,64.830000000,8,8,5,8,64.710000000,64.840000000,9,6,8,5,64.700000000,64.850000000,7,8,6,5,64.690000000,64.860000000,4,4,3,3,64.680000000,64.870000000,4,4,2,3,MCLN5
2025-06-11T00:00:21.428065411Z,2025-06-11T00:00:21.427969947Z,10,1,42026514,C,B,6,64.710000000,1,130,15351,79323908,64.770000000,64.780000000,2,4,1,4,64.760000000,64.790000000,6,6,6,4,64.750000000,64.800000000,5,8,5,7,64.740000000,64.810000000,9,7,8,7,64.730000000,64.820000000,8,10,8,7,64.720000000,64.830000000,8,8,5,8,64.710000000,64.840000000,8,6,7,5,64.700000000,64.850000000,7,8,6,5,64.690000000,64.860000000,4,4,3,3,64.680000000,64.870000000,4,4,2,3,MCLN5
2025-06-11T00:00:21.428086983Z,2025-06-11T00:00:21.427972137Z,10,1,42026514,A,A,6,64.840000000,1,130,11269,79323909,64.770000000,64.780000000,2,4,1,4,64.760000000,64.790000000,6,6,6,4,64.750000000,64.800000000,5,8,5,7,64.740000000,64.810000000,9,7,8,7,64.730000000,64.820000000,8,10,8,7,64.720000000,64.830000000,8,8,5,8,64.710000000,64.840000000,8,7,7,6,64.700000000,64.850000000,7,8,6,5,64.690000000,64.860000000,4,4,3,3,64.680000000,64.870000000,4,4,2,3,MCLN5
2025-06-11T00:00:21.428190642Z,2025-06-11T00:00:21.428091783Z,10,1,42026514,A,B,5,64.720000000,1,130,14948,79323910,64.770000000,64.780000000,2,4,1,4,64.760000000,64.790000000,6,6,6,4,64.750000000,64.800000000,5,8,5,7,64.740000000,64.810000000,9,7,8,7,64.730000000,64.820000000,8,10,8,7,64.720000000,64.830000000,9,8,6,8,64.710000000,64.840000000,8,7,7,6,64.700000000,64.850000000,7,8,6,5,64.690000000,64.860000000,4,4,3,3,64.680000000,64.870000000,4,4,2,3,MCLN5
2025-06-11T00:00:21.544957075Z,2025-06-11T00:00:21.544860657Z,10,1,42025623,M,A,3,63.740000000,1,130,14932,79324013,63.670000000,63.700000000,3,2,3,2,63.660000000,63.710000000,3,2,3,2,63.650000000,63.720000000,2,2,2,2,63.640000000,63.730000000,3,3,3,3,63.630000000,63.740000000,7,5,7,5,63.620000000,63.750000000,5,2,5,2,63.610000000,63.760000000,2,5,2,5,63.600000000,63.770000000,6,1,6,1,63.590000000,63.780000000,1,3,1,3,63.580000000,63.790000000,6,1,4,1,MCLQ5
2025-06-11T00:00:21.544967665Z,2025-06-11T00:00:21.544861213Z,10,1,42025623,M,B,3,63.640000000,1,130,12083,79324014,63.670000000,63.700000000,3,2,3,2,63.660000000,63.710000000,3,2,3,2,63.650000000,63.720000000,2,2,2,2,63.640000000,63.730000000,4,3,4,3,63.630000000,63.740000000,6,5,6,5,63.620000000,63.750000000,5,2,5,2,63.610000000,63.760000000,2,5,2,5,63.600000000,63.770000000,6,1,6,1,63.590000000,63.780000000,1,3,1,3,63.580000000,63.790000000,6,1,4,1,MCLQ5
2025-06-11T00:00:21.544979354Z,2025-06-11T00:00:21.544862117Z,10,1,42025623,M,A,3,63.740000000,1,130,12117,79324015,63.670000000,63.700000000,3,2,3,2,63.660000000,63.710000000,3,2,3,2,63.650000000,63.720000000,2,2,2,2,63.640000000,63.730000000,4,2,4,2,63.630000000,63.740000000,6,6,6,6,63.620000000,63.750000000,5,2,5,2,63.610000000,63.760000000,2,5,2,5,63.600000000,63.770000000,6,1,6,1,63.590000000,63.780000000,1,3,1,3,63.580000000,63.790000000,6,1,4,1,MCLQ5
2025-06-11T00:00:21.544990220Z,2025-06-11T00:00:21.544862693Z,10,1,42025623,M,B,3,63.640000000,1,130,11888,79324016,63.670000000,63.700000000,3,2,3,2,63.660000000,63.710000000,3,2,3,2,63.650000000,63.720000000,2,2,2,2,63.640000000,63.730000000,5,2,5,2,63.630000000,63.740000000,5,6,5,6,63.620000000,63.750000000,5,2,5,2,63.610000000,63.760000000,2,5,2,5,63.600000000,63.770000000,6,1,6,1,63.590000000,63.780000000,1,3,1,3,63.580000000,63.790000000,6,1,4,1,MCLQ5
2025-06-11T00:00:21.558589119Z,2025-06-11T00:00:21.558466347Z,10,1,42418117,M,B,0,3.250000000,1,130,15804,79324028,3.250000000,3.270000000,1,1,1,1,3.240000000,3.280000000,11,11,2,2,3.230000000,3.290000000,1,1,1,1,,,0,0,0,0,,,0,0,0,0,,,0,0,0,0,,,0,0,0,0,,,0,0,0,0,,,0,0,0,0,,,0,0,0,0,MCLN5-MCLX5
2025-06-11T00:00:21.585221766Z,2025-06-11T00:00:21.585101731Z,10,1,42026514,A,B,4,64.730000000,1,130,15351,79324042,64.770000000,64.780000000,2,4,1,4,64.760000000,64.790000000,6,6,6,4,64.750000000,64.800000000,5,8,5,7,64.740000000,64.810000000,9,7,8,7,64.730000000,64.820000000,9,10,9,7,64.720000000,64.830000000,9,8,6,8,64.710000000,64.840000000,8,7,7,6,64.700000000,64.850000000,7,8,6,5,64.690000000,64.860000000,4,4,3,3,64.680000000,64.870000000,4,4,2,3,MCLN5
2025-06-11T00:00:21.793415661Z,2025-06-11T00:00:21.793311281Z,10,1,42022708,M,A,0,2.820000000,1,130,15823,79324107,2.810000000,2.820000000,1,1,1,1,2.800000000,2.830000000,12,12,3,3,2.790000000,2.840000000,2,2,2,2,2.780000000,2.870000000,1,1,1,1,,,0,0,0,0,,,0,0,0,0,,,0,0,0,0,,,0,0,0,0,,,0,0,0,0,,,0,0,0,0,MCLN5-MCLV5
2025-06-11T00:00:21.793423893Z,2025-06-11T00:00:21.793312433Z,10,1,42418117,M,B,0,3.220000000,1,130,11627,79324108,3.240000000,3.270000000,11,1,2,1,3.230000000,3.280000000,1,11,1,2,3.220000000,3.290000000,1,1,1,1,,,0,0,0,0,,,0,0,0,0,,,0,0,0,0,,,0,0,0,0,,,0,0,0,0,,,0,0,0,0,,,0,0,0,0,MCLN5-MCLX5
2025-06-11T00:00:22.133022679Z,2025-06-11T00:00:22.132899493Z,10,1,42026514,C,A,0,64.780000000,1,130,17876,79324223,64.770000000,64.780000000,2,3,1,3,64.760000000,64.790000000,6,6,6,4,64.750000000,64.800000000,5,8,5,7,64.740000000,64.810000000,9,7,8,7,64.730000000,64.820000000,9,10,9,7,64.720000000,64.830000000,9,8,6,8,64.710000000,64.840000000,8,7,7,6,64.700000000,64.850000000,7,8,6,5,64.690000000,64.860000000,4,4,3,3,64.680000000,64.870000000,4,4,2,3,MCLN5
2025-06-11T00:00:22.133662935Z,2025-06-11T00:00:22.133060767Z,10,1,42026514,C,A,0,64.780000000,1,130,15663,79324256,64.770000000,64.780000000,2,2,1,2,64.760000000,64.790000000,6,6,6,4,64.750000000,64.800000000,5,8,5,7,64.740000000,64.810000000,9,7,8,7,64.730000000,64.820000000,9,10,9,7,64.720000000,64.830000000,9,8,6,8,64.710000000,64.840000000,8,7,7,6,64.700000000,64.850000000,7,8,6,5,64.690000000,64.860000000,4,4,3,3,64.680000000,64.870000000,4,4,2,3,MCLN5
2025-06-11T00:00:22.133864778Z,2025-06-11T00:00:22.133624223Z,10,1,42026514,A,B,0,64.770000000,1,130,13064,79324266,64.770000000,64.780000000,3,2,2,2,64.760000000,64.790000000,6,6,6,4,64.750000000,64.800000000,5,8,5,7,64.740000000,64.810000000,9,7,8,7,64.730000000,64.820000000,9,10,9,7,64.720000000,64.830000000,9,8,6,8,64.710000000,64.840000000,8,7,7,6,64.700000000,64.850000000,7,8,6,5,64.690000000,64.860000000,4,4,3,3,64.680000000,64.870000000,4,4,2,3,MCLN5
2025-06-11T00:00:22.134020351Z,2025-06-11T00:00:22.133633533Z,10,1,42026514,C,A,0,64.780000000,1,130,15550,79324272,64.770000000,64.780000000,3,1,2,1,64.760000000,64.790000000,6,6,6,4,64.750000000,64.800000000,5,8,5,7,64.740000000,64.810000000,9,7,8,7,64.730000000,64.820000000,9,10,9,7,64.720000000,64.830000000,9,8,6,8,64.710000000,64.840000000,8,7,7,6,64.700000000,64.850000000,7,8,6,5,64.690000000,64.860000000,4,4,3,3,64.680000000,64.870000000,4,4,2,3,MCLN5
2025-06-11T00:00:22.134200276Z,2025-06-11T00:00:22.133691573Z,10,1,42026514,M,A,3,64.820000000,1,130,11601,79324280,64.770000000,64.780000000,3,1,2,1,64.760000000,64.790000000,6,6,6,4,64.750000000,64.800000000,5,8,5,7,64.740000000,64.810000000,9,6,8,6,64.730000000,64.820000000,9,11,9,8,64.720000000,64.830000000,9,8,6,8,64.710000000,64.840000000,8,7,7,6,64.700000000,64.850000000,7,8,6,5,64.690000000,64.860000000,4,4,3,3,64.680000000,64.870000000,4,4,2,3,MCLN5
2025-06-11T00:00:22.134212679Z,2025-06-11T00:00:22.133692015Z,10,1,42026514,M,B,3,64.740000000,1,130,14733,79324281,64.770000000,64.780000000,3,1,2,1,64.760000000,64.790000000,6,6,6,4,64.750000000,64.800000000,5,8,5,7,64.740000000,64.810000000,10,6,9,6,64.730000000,64.820000000,8,11,8,8,64.720000000,64.830000000,9,8,6,8,64.710000000,64.840000000,8,7,7,6,64.700000000,64.850000000,7,8,6,5,64.690000000,64.860000000,4,4,3,3,64.680000000,64.870000000,4,4,2,3,MCLN5
2025-06-11T00:00:22.134220757Z,2025-06-11T00:00:22.133692573Z,10,1,42026514,M,A,3,64.820000000,1,130,11323,79324282,64.770000000,64.780000000,3,1,2,1,64.760000000,64.790000000,6,6,6,4,64.750000000,64.800000000,5,8,5,7,64.740000000,64.810000000,10,5,9,5,64.730000000,64.820000000,8,12,8,9,64.720000000,64.830000000,9,8,6,8,64.710000000,64.840000000,8,7,7,6,64.700000000,64.850000000,7,8,6,5,64.690000000,64.860000000,4,4,3,3,64.680000000,64.870000000,4,4,2,3,MCLN5
2025-06-11T00:00:22.134228959Z,2025-06-11T00:00:22.133693071Z,10,1,42026514,M,B,3,64.740000000,1,130,11457,79324283,64.770000000,64.780000000,3,1,2,1,64.760000000,64.790000000,6,6,6,4,64.750000000,64.800000000,5,8,5,7,64.740000000,64.810000000,11,5,10,5,64.730000000,64.820000000,7,12,7,9,64.720000000,64.830000000,9,8,6,8,64.710000000,64.840000000,8,7,7,6,64.700000000,64.850000000,7,8,6,5,64.690000000,64.860000000,4,4,3,3,64.680000000,64.870000000,4,4,2,3,MCLN5
2025-06-11T00:00:22.134299128Z,2025-06-11T00:00:22.133761651Z,10,1,42022708,M,A,0,2.850000000,1,130,11661,79324287,2.810000000,2.830000000,1,12,1,3,2.800000000,2.840000000,12,2,3,2,2.790000000,2.850000000,2,1,2,1,2.780000000,2.870000000,1,1,1,1,,,0,0,0,0,,,0,0,0,0,,,0,0,0,0,,,0,0,0,0,,,0,0,0,0,,,0,0,0,0,MCLN5-MCLV5
2025-06-11T00:00:22.134421932Z,2025-06-11T00:00:22.134037447Z,10,1,42025623,M,A,4,63.750000000,1,130,11987,79324295,63.670000000,63.700000000,3,2,3,2,63.660000000,63.710000000,3,2,3,2,63.650000000,63.720000000,2,2,2,2,63.640000000,63.730000000,5,2,5,2,63.630000000,63.740000000,5,5,5,5,63.620000000,63.750000000,5,3,5,3,63.610000000,63.760000000,2,5,2,5,63.600000000,63.770000000,6,1,6,1,63.590000000,63.780000000,1,3,1,3,63.580000000,63.790000000,6,1,4,1,MCLQ5
2025-06-11T00:00:22.134421932Z,2025-06-11T00:00:22.134037907Z,10,1,42025623,M,B,3,63.640000000,1,130,11987,79324295,63.670000000,63.700000000,3,2,3,2,63.660000000,63.710000000,3,2,3,2,63.650000000,63.720000000,2,2,2,2,63.640000000,63.730000000,6,2,6,2,63.630000000,63.740000000,4,5,4,5,63.620000000,63.750000000,5,3,5,3,63.610000000,63.760000000,2,5,2,5,63.600000000,63.770000000,6,1,6,1,63.590000000,63.780000000,1,3,1,3,63.580000000,63.790000000,6,1,4,1,MCLQ5
2025-06-11T00:00:22.134664584Z,2025-06-11T00:00:22.134216113Z,10,1,42026514,M,B,2,62.780000000,2,130,11646,79324311,64.770000000,64.780000000,3,1,2,1,64.760000000,64.790000000,6,6,6,4,64.750000000,64.800000000,4,8,4,7,64.740000000,64.810000000,11,5,10,5,64.730000000,64.820000000,7,12,7,9,64.720000000,64.830000000,9,8,6,8,64.710000000,64.840000000,8,7,7,6,64.700000000,64.850000000,7,8,6,5,64.690000000,64.860000000,4,4,3,3,64.680000000,64.870000000,4,4,2,3,MCLN5
2025-06-11T00:00:22.135231568Z,2025-06-11T00:00:22.134533553Z,10,1,42284507,A,A,0,1.000000000,4,130,11390,79324351,0.980000000,1.000000000,23,16,7,6,0.970000000,1.010000000,18,25,5,8,0.960000000,1.020000000,23,21,8,6,0.950000000,1.030000000,8,17,5,5,0.940000000,1.040000000,6,17,4,5,0.930000000,1.050000000,3,6,2,3,0.920000000,1.060000000,3,4,2,2,0.910000000,1.070000000,3,2,2,1,0.900000000,1.080000000,2,2,1,1,0.890000000,1.090000000,2,4,1,2,MCLQ5-MCLU5
2025-06-11T00:00:22.136952174Z,2025-06-11T00:00:22.136735751Z,10,1,42026514,C,B,0,64.770000000,1,130,14139,79324458,64.770000000,64.780000000,2,1,1,1,64.760000000,64.790000000,6,6,6,4,64.750000000,64.800000000,4,8,4,7,64.740000000,64.810000000,11,5,10,5,64.730000000,64.820000000,7,12,7,9,64.720000000,64.830000000,9,8,6,8,64.710000000,64.840000000,8,7,7,6,64.700000000,64.850000000,7,8,6,5,64.690000000,64.860000000,4,4,3,3,64.680000000,64.870000000,4,4,2,3,MCLN5
2025-06-11T00:00:22.233759021Z,2025-06-11T00:00:22.233623213Z,10,1,42026514,A,A,0,64.780000000,1,130,18441,79324526,64.770000000,64.780000000,2,2,1,2,64.760000000,64.790000000,6,6,6,4,64.750000000,64.800000000,4,8,4,7,64.740000000,64.810000000,11,5,10,5,64.730000000,64.820000000,7,12,7,9,64.720000000,64.830000000,9,8,6,8,64.710000000,64.840000000,8,7,7,6,64.700000000,64.850000000,7,8,6,5,64.690000000,64.860000000,4,4,3,3,64.680000000,64.870000000,4,4,2,3,MCLN5
2025-06-11T00:00:22.233774219Z,2025-06-11T00:00:22.233639051Z,10,1,42026514,A,A,0,64.780000000,1,130,11957,79324527,64.770000000,64.780000000,2,3,1,3,64.760000000,64.790000000,6,6,6,4,64.750000000,64.800000000,4,8,4,7,64.740000000,64.810000000,11,5,10,5,64.730000000,64.820000000,7,12,7,9,64.720000000,64.830000000,9,8,6,8,64.710000000,64.840000000,8,7,7,6,64.700000000,64.850000000,7,8,6,5,64.690000000,64.860000000,4,4,3,3,64.680000000,64.870000000,4,4,2,3,MCLN5
2025-06-11T00:00:22.498006411Z,2025-06-11T00:00:22.497871133Z,10,1,42026514,A,B,0,64.770000000,1,130,14428,79324619,64.770000000,64.780000000,3,3,2,3,64.760000000,64.790000000,6,6,6,4,64.750000000,64.800000000,4,8,4,7,64.740000000,64.810000000,11,5,10,5,64.730000000,64.820000000,7,12,7,9,64.720000000,64.830000000,9,8,6,8,64.710000000,64.840000000,8,7,7,6,64.700000000,64.850000000,7,8,6,5,64.690000000,64.860000000,4,4,3,3,64.680000000,64.870000000,4,4,2,3,MCLN5
2025-06-11T00:00:22.498031761Z,2025-06-11T00:00:22.497878333Z,10,1,42026514,C,A,0,64.780000000,1,130,13514,79324621,64.770000000,64.780000000,3,2,2,2,64.760000000,64.790000000,6,6,6,4,64.750000000,64.800000000,4,8,4,7,64.740000000,64.810000000,11,5,10,5,64.730000000,64.820000000,7,12,7,9,64.720000000,64.830000000,9,8,6,8,64.710000000,64.840000000,8,7,7,6,64.700000000,64.850000000,7,8,6,5,64.690000000,64.860000000,4,4,3,3,64.680000000,64.870000000,4,4,2,3,MCLN5
2025-06-11T00:00:22.498120652Z,2025-06-11T00:00:22.498018987Z,10,1,42025623,M,B,3,63.630000000,1,130,14977,79324623,63.670000000,63.700000000,3,2,3,2,63.660000000,63.710000000,3,2,3,2,63.650000000,63.720000000,2,2,2,2,63.640000000,63.730000000,5,2,5,2,63.630000000,63.740000000,5,5,5,5,63.620000000,63.750000000,5,3,5,3,63.610000000,63.760000000,2,5,2,5,63.600000000,63.770000000,6,1,6,1,63.590000000,63.780000000,1,3,1,3,63.580000000,63.790000000,6,1,4,1,MCLQ5
2025-06-11T00:00:22.498130037Z,2025-06-11T00:00:22.498019485Z,10,1,42025623,M,A,4,63.740000000,1,130,11457,79324624,63.670000000,63.700000000,3,2,3,2,63.660000000,63.710000000,3,2,3,2,63.650000000,63.720000000,2,2,2,2,63.640000000,63.730000000,5,2,5,2,63.630000000,63.740000000,5,6,5,6,63.620000000,63.750000000,5,2,5,2,63.610000000,63.760000000,2,5,2,5,63.600000000,63.770000000,6,1,6,1,63.590000000,63.780000000,1,3,1,3,63.580000000,63.790000000,6,1,4,1,MCLQ5
2025-06-11T00:00:22.632263766Z,2025-06-11T00:00:22.632106261Z,10,1,42026514,C,A,0,64.780000000,1,130,16013,79324659,64.770000000,64.780000000,3,1,2,1,64.760000000,64.790000000,6,6,6,4,64.750000000,64.800000000,4,8,4,7,64.740000000,64.810000000,11,5,10,5,64.730000000,64.820000000,7,12,7,9,64.720000000,64.830000000,9,8,6,8,64.710000000,64.840000000,8,7,7,6,64.700000000,64.850000000,7,8,6,5,64.690000000,64.860000000,4,4,3,3,64.680000000,64.870000000,4,4,2,3,MCLN5
2025-06-11T00:00:22.906845923Z,2025-06-11T00:00:22.906751385Z,10,1,42025623,M,A,4,63.750000000,1,130,14955,79324703,63.670000000,63.700000000,3,2,3,2,63.660000000,63.710000000,3,2,3,2,63.650000000,63.720000000,2,2,2,2,63.640000000,63.730000000,5,2,5,2,63.630000000,63.740000000,5,5,5,5,63.620000000,63.750000000,5,3,5,3,63.610000000,63.760000000,2,5,2,5,63.600000000,63.770000000,6,1,6,1,63.590000000,63.780000000,1,3,1,3,63.580000000,63.790000000,6,1,4,1,MCLQ5
2025-06-11T00:00:22.906854747Z,2025-06-11T00:00:22.906751827Z,10,1,42025623,M,B,3,63.640000000,1,130,11554,79324704,63.670000000,63.700000000,3,2,3,2,63.660000000,63.710000000,3,2,3,2,63.650000000,63.720000000,2,2,2,2,63.640000000,63.730000000,6,2,6,2,63.630000000,63.740000000,4,5,4,5,63.620000000,63.750000000,5,3,5,3,63.610000000,63.760000000,2,5,2,5,63.600000000,63.770000000,6,1,6,1,63.590000000,63.780000000,1,3,1,3,63.580000000,63.790000000,6,1,4,1,MCLQ5
2025-06-11T00:00:22.907200659Z,2025-06-11T00:00:22.907103153Z,10,1,42418117,M,B,0,3.250000000,1,130,11168,79324713,3.250000000,3.270000000,1,1,1,1,3.240000000,3.280000000,11,11,2,2,3.230000000,3.290000000,1,1,1,1,,,0,0,0,0,,,0,0,0,0,,,0,0,0,0,,,0,0,0,0,,,0,0,0,0,,,0,0,0,0,,,0,0,0,0,MCLN5-MCLX5
2025-06-11T00:00:22.907844032Z,2025-06-11T00:00:22.907646967Z,10,1,42025611,C,B,0,2.070000000,1,130,11700,79324730,2.060000000,2.080000000,23,6,3,3,2.050000000,2.090000000,23,27,3,6,2.040000000,2.100000000,23,27,3,6,2.030000000,2.110000000,2,22,1,3,2.020000000,2.120000000,2,2,2,1,2.010000000,2.130000000,2,2,1,2,2.000000000,2.140000000,2,2,2,1,1.990000000,2.150000000,2,2,1,1,1.980000000,2.160000000,2,2,2,1,1.970000000,2.170000000,2,2,1,1,MCLN5-MCLU5
2025-06-11T00:00:22.907853133Z,2025-06-11T00:00:22.907665323Z,10,1,42418117,M,B,0,3.220000000,1,130,11691,79324731,3.240000000,3.270000000,11,1,2,1,3.230000000,3.280000000,1,11,1,2,3.220000000,3.290000000,1,1,1,1,,,0,0,0,0,,,0,0,0,0,,,0,0,0,0,,,0,0,0,0,,,0,0,0,0,,,0,0,0,0,,,0,0,0,0,MCLN5-MCLX5
2025-06-11T00:00:22.907954626Z,2025-06-11T00:00:22.907847465Z,10,1,42022708,M,A,0,2.820000000,1,130,12010,79324739,2.810000000,2.820000000,1,1,1,1,2.800000000,2.830000000,12,12,3,3,2.790000000,2.840000000,2,2,2,2,2.780000000,2.870000000,1,1,1,1,,,0,0,0,0,,,0,0,0,0,,,0,0,0,0,,,0,0,0,0,,,0,0,0,0,,,0,0,0,0,MCLN5-MCLV5
2025-06-11T00:00:22.907970208Z,2025-06-11T00:00:22.907872691Z,10,1,42022708,C,B,0,2.810000000,1,130,11721,79324740,2.800000000,2.820000000,12,1,3,1,2.790000000,2.830000000,2,12,2,3,2.780000000,2.840000000,1,2,1,2,,2.870000000,0,1,0,1,,,0,0,0,0,,,0,0,0,0,,,0,0,0,0,,,0,0,0,0,,,0,0,0,0,,,0,0,0,0,MCLN5-MCLV5
2025-06-11T00:00:22.907990029Z,2025-06-11T00:00:22.907884769Z,10,1,42025611,A,B,0,2.060000000,3,130,12408,79324741,2.060000000,2.080000000,26,6,4,3,2.050000000,2.090000000,23,27,3,6,2.040000000,2.100000000,23,27,3,6,2.030000000,2.110000000,2,22,1,3,2.020000000,2.120000000,2,2,2,1,2.010000000,2.130000000,2,2,1,2,2.000000000,2.140000000,2,2,2,1,1.990000000,2.150000000,2,2,1,1,1.980000000,2.160000000,2,2,2,1,1.970000000,2.170000000,2,2,1,1,MCLN5-MCLU5
2025-06-11T00:00:22.931355176Z,2025-06-11T00:00:22.931244145Z,10,1,42025611,A,B,0,2.070000000,1,130,14912,79324849,2.070000000,2.080000000,1,6,1,3,2.060000000,2.090000000,26,27,4,6,2.050000000,2.100000000,23,27,3,6,2.040000000,2.110000000,23,22,3,3,2.030000000,2.120000000,2,2,1,1,2.020000000,2.130000000,2,2,2,2,2.010000000,2.140000000,2,2,1,1,2.000000000,2.150000000,2,2,2,1,1.990000000,2.160000000,2,2,1,1,1.980000000,2.170000000,2,2,2,1,MCLN5-MCLU5
2025-06-11T00:00:22.931372731Z,2025-06-11T00:00:22.931244377Z,10,1,42022708,A,B,0,2.810000000,1,130,11751,79324850,2.810000000,2.820000000,1,1,1,1,2.800000000,2.830000000,12,12,3,3,2.790000000,2.840000000,2,2,2,2,2.780000000,2.870000000,1,1,1,1,,,0,0,0,0,,,0,0,0,0,,,0,0,0,0,,,0,0,0,0,,,0,0,0,0,,,0,0,0,0,MCLN5-MCLV5
2025-06-11T00:00:22.971785306Z,2025-06-11T00:00:22.971565337Z,10,1,42022708,M,A,0,2.850000000,1,130,11503,79325167,2.810000000,2.830000000,1,12,1,3,2.800000000,2.840000000,12,2,3,2,2.790000000,2.850000000,2,1,2,1,2.780000000,2.870000000,1,1,1,1,,,0,0,0,0,,,0,0,0,0,,,0,0,0,0,,,0,0,0,0,,,0,0,0,0,,,0,0,0,0,MCLN5-MCLV5
2025-06-11T00:00:22.972245291Z,2025-06-11T00:00:22.971885273Z,10,1,42418117,M,A,0,3.300000000,1,130,11573,79325204,3.240000000,3.280000000,11,11,2,2,3.230000000,3.290000000,1,1,1,1,3.220000000,3.300000000,1,1,1,1,,,0,0,0,0,,,0,0,0,0,,,0,0,0,0,,,0,0,0,0,,,0,0,0,0,,,0,0,0,0,,,0,0,0,0,MCLN5-MCLX5
2025-06-11T00:00:23.572912788Z,2025-06-11T00:00:23.572799387Z,10,1,42418117,M,A,0,3.270000000,1,130,15105,79326370,3.240000000,3.270000000,11,1,2,1,3.230000000,3.280000000,1,11,1,2,3.220000000,3.290000000,1,1,1,1,,,0,0,0,0,,,0,0,0,0,,,0,0,0,0,,,0,0,0,0,,,0,0,0,0,,,0,0,0,0,,,0,0,0,0,MCLN5-MCLX5
2025-06-11T00:00:23.932599943Z,2025-06-11T00:00:23.932484425Z,10,1,42418117,M,B,0,3.250000000,1,130,15830,79326491,3.250000000,3.270000000,1,1,1,1,3.240000000,3.280000000,11,11,2,2,3.230000000,3.290000000,1,1,1,1,,,0,0,0,0,,,0,0,0,0,,,0,0,0,0,,,0,0,0,0,,,0,0,0,0,,,0,0,0,0,,,0,0,0,0,MCLN5-MCLX5
2025-06-11T00:00:25.001594283Z,2025-06-11T00:00:25.001239983Z,10,1,42418117,M,B,0,3.220000000,1,130,15248,79327251,3.240000000,3.270000000,11,1,2,1,3.230000000,3.280000000,1,11,1,2,3.220000000,3.290000000,1,1,1,1,,,0,0,0,0,,,0,0,0,0,,,0,0,0,0,,,0,0,0,0,,,0,0,0,0,,,0,0,0,0,,,0,0,0,0,MCLN5-MCLX5
2025-06-11T00:00:25.001699616Z,2025-06-11T00:00:25.001318085Z,10,1,42022708,M,A,0,2.820000000,1,130,11764,79327261,2.810000000,2.820000000,1,1,1,1,2.800000000,2.830000000,12,12,3,3,2.790000000,2.840000000,2,2,2,2,2.780000000,2.870000000,1,1,1,1,,,0,0,0,0,,,0,0,0,0,,,0,0,0,0,,,0,0,0,0,,,0,0,0,0,,,0,0,0,0,MCLN5-MCLV5
2025-06-11T00:00:25.001980689Z,2025-06-11T00:00:25.001585817Z,10,1,42022708,C,B,0,2.810000000,1,130,11434,79327279,2.800000000,2.820000000,12,1,3,1,2.790000000,2.830000000,2,12,2,3,2.780000000,2.840000000,1,2,1,2,,2.870000000,0,1,0,1,,,0,0,0,0,,,0,0,0,0,,,0,0,0,0,,,0,0,0,0,,,0,0,0,0,,,0,0,0,0,MCLN5-MCLV5
2025-06-11T00:00:25.132127363Z,2025-06-11T00:00:25.132021259Z,10,1,42025611,A,B,1,2.060000000,1,130,15356,79327366,2.070000000,2.080000000,1,6,1,3,2.060000000,2.090000000,27,27,5,6,2.050000000,2.100000000,23,27,3,6,2.040000000,2.110000000,23,22,3,3,2.030000000,2.120000000,2,2,1,1,2.020000000,2.130000000,2,2,2,2,2.010000000,2.140000000,2,2,1,1,2.000000000,2.150000000,2,2,2,1,1.990000000,2.160000000,2,2,1,1,1.980000000,2.170000000,2,2,2,1,MCLN5-MCLU5
2025-06-11T00:00:25.272735513Z,2025-06-11T00:00:25.272536179Z,10,1,42026514,C,A,0,64.780000000,1,130,15322,79327774,64.770000000,64.790000000,3,6,2,4,64.760000000,64.800000000,6,8,6,7,64.750000000,64.810000000,4,5,4,5,64.740000000,64.820000000,11,12,10,9,64.730000000,64.830000000,7,8,7,8,64.720000000,64.840000000,9,7,6,6,64.710000000,64.850000000,8,8,7,5,64.700000000,64.860000000,7,4,6,3,64.690000000,64.870000000,4,4,3,3,64.680000000,64.880000000,4,4,2,3,MCLN5
2025-06-11T00:00:25.272840593Z,2025-06-11T00:00:25.272740959Z,10,1,42026514,A,A,1,64.800000000,1,130,14985,79327779,64.770000000,64.790000000,3,6,2,4,64.760000000,64.800000000,6,9,6,8,64.750000000,64.810000000,4,5,4,5,64.740000000,64.820000000,11,12,10,9,64.730000000,64.830000000,7,8,7,8,64.720000000,64.840000000,9,7,6,6,64.710000000,64.850000000,8,8,7,5,64.700000000,64.860000000,7,4,6,3,64.690000000,64.870000000,4,4,3,3,64.680000000,64.880000000,4,4,2,3,MCLN5
2025-06-11T00:00:25.272907851Z,2025-06-11T00:00:25.272769277Z,10,1,42025623,C,A,0,63.700000000,1,130,13770,79327783,63.670000000,63.700000000,3,1,3,1,63.660000000,63.710000000,3,2,3,2,63.650000000,63.720000000,2,2,2,2,63.640000000,63.730000000,6,2,6,2,63.630000000,63.740000000,4,5,4,5,63.620000000,63.750000000,5,3,5,3,63.610000000,63.760000000,2,5,2,5,63.600000000,63.770000000,6,1,6,1,63.590000000,63.780000000,1,3,1,3,63.580000000,63.790000000,6,1,4,1,MCLQ5
2025-06-11T00:00:25.273020941Z,2025-06-11T00:00:25.272790165Z,10,1,42026514,A,B,0,64.770000000,1,130,13278,79327788,64.770000000,64.790000000,4,6,3,4,64.760000000,64.800000000,6,9,6,8,64.750000000,64.810000000,4,5,4,5,64.740000000,64.820000000,11,12,10,9,64.730000000,64.830000000,7,8,7,8,64.720000000,64.840000000,9,7,6,6,64.710000000,64.850000000,8,8,7,5,64.700000000,64.860000000,7,4,6,3,64.690000000,64.870000000,4,4,3,3,64.680000000,64.880000000,4,4,2,3,MCLN5
2025-06-11T00:00:25.273063916Z,2025-06-11T00:00:25.272866213Z,10,1,42025623,C,A,0,63.700000000,1,130,15347,79327791,63.670000000,63.710000000,3,2,3,2,63.660000000,63.720000000,3,2,3,2,63.650000000,63.730000000,2,2,2,2,63.640000000,63.740000000,6,5,6,5,63.630000000,63.750000000,4,3,4,3,63.620000000,63.760000000,5,5,5,5,63.610000000,63.770000000,2,1,2,1,63.600000000,63.780000000,6,3,6,3,63.590000000,63.790000000,1,1,1,1,63.580000000,63.800000000,6,3,4,3,MCLQ5
2025-06-11T00:00:25.273900063Z,2025-06-11T00:00:25.273031921Z,10,1,42026514,C,B,0,64.770000000,1,130,13315,79327835,64.770000000,64.790000000,3,6,2,4,64.760000000,64.800000000,6,9,6,8,64.750000000,64.810000000,4,5,4,5,64.740000000,64.820000000,11,12,10,9,64.730000000,64.830000000,7,8,7,8,64.720000000,64.840000000,9,7,6,6,64.710000000,64.850000000,8,8,7,5,64.700000000,64.860000000,7,4,6,3,64.690000000,64.870000000,4,4,3,3,64.680000000,64.880000000,4,4,2,3,MCLN5
2025-06-11T00:00:25.273924061Z,2025-06-11T00:00:25.273062485Z,10,1,42025623,A,B,0,63.680000000,1,130,12563,79327836,63.680000000,63.710000000,1,2,1,2,63.670000000,63.720000000,3,2,3,2,63.660000000,63.730000000,3,2,3,2,63.650000000,63.740000000,2,5,2,5,63.640000000,63.750000000,6,3,6,3,63.630000000,63.760000000,4,5,4,5,63.620000000,63.770000000,5,1,5,1,63.610000000,63.780000000,2,3,2,3,63.600000000,63.790000000,6,1,6,1,63.590000000,63.800000000,1,3,1,3,MCLQ5
2025-06-11T00:00:25.273934974Z,2025-06-11T00:00:25.273072257Z,10,1,42025623,C,A,5,63.760000000,1,130,11619,79327837,63.680000000,63.710000000,1,2,1,2,63.670000000,63.720000000,3,2,3,2,63.660000000,63.730000000,3,2,3,2,63.650000000,63.740000000,2,5,2,5,63.640000000,63.750000000,6,3,6,3,63.630000000,63.760000000,4,4,4,4,63.620000000,63.770000000,5,1,5,1,63.610000000,63.780000000,2,3,2,3,63.600000000,63.790000000,6,1,6,1,63.590000000,63.800000000,1,3,1,3,MCLQ5
2025-06-11T00:00:25.274014565Z,2025-06-11T00:00:25.273192313Z,10,1,42025623,M,B,3,63.650000000,1,130,11968,79327842,63.680000000,63.710000000,1,2,1,2,63.670000000,63.720000000,3,2,3,2,63.660000000,63.730000000,3,2,3,2,63.650000000,63.740000000,3,5,3,5,63.640000000,63.750000000,6,3,6,3,63.630000000,63.760000000,4,4,4,4,63.620000000,63.770000000,5,1,5,1,63.610000000,63.780000000,2,3,2,3,63.600000000,63.790000000,6,1,6,1,63.590000000,63.800000000,1,3,1,3,MCLQ5
2025-06-11T00:00:25.274396026Z,2025-06-11T00:00:25.273537147Z,10,1,42026514,A,A,0,64.790000000,1,130,11638,79327873,64.770000000,64.790000000,3,7,2,5,64.760000000,64.800000000,6,9,6,8,64.750000000,64.810000000,4,5,4,5,64.740000000,64.820000000,11,12,10,9,64.730000000,64.830000000,7,8,7,8,64.720000000,64.840000000,9,7,6,6,64.710000000,64.850000000,8,8,7,5,64.700000000,64.860000000,7,4,6,3,64.690000000,64.870000000,4,4,3,3,64.680000000,64.880000000,4,4,2,3,MCLN5
2025-06-11T00:00:25.274708018Z,2025-06-11T00:00:25.273585913Z,10,1,42025623,A,B,0,63.690000000,1,130,13185,79327901,63.690000000,63.710000000,1,2,1,2,63.680000000,63.720000000,1,2,1,2,63.670000000,63.730000000,3,2,3,2,63.660000000,63.740000000,3,5,3,5,63.650000000,63.750000000,3,3,3,3,63.640000000,63.760000000,6,4,6,4,63.630000000,63.770000000,4,1,4,1,63.620000000,63.780000000,5,3,5,3,63.610000000,63.790000000,2,1,2,1,63.600000000,63.800000000,6,3,6,3,MCLQ5
2025-06-11T00:00:25.274865372Z,2025-06-11T00:00:25.273690855Z,10,1,42025623,A,B,1,63.680000000,1,130,15947,79327917,63.690000000,63.710000000,1,2,1,2,63.680000000,63.720000000,2,2,2,2,63.670000000,63.730000000,3,2,3,2,63.660000000,63.740000000,3,5,3,5,63.650000000,63.750000000,3,3,3,3,63.640000000,63.760000000,6,4,6,4,63.630000000,63.770000000,4,1,4,1,63.620000000,63.780000000,5,3,5,3,63.610000000,63.790000000,2,1,2,1,63.600000000,63.800000000,6,3,6,3,MCLQ5
2025-06-11T00:00:25.275189513Z,2025-06-11T00:00:25.273905483Z,10,1,42026514,A,B,0,64.770000000,1,130,13681,79327942,64.770000000,64.790000000,4,7,3,5,64.760000000,64.800000000,6,9,6,8,64.750000000,64.810000000,4,5,4,5,64.740000000,64.820000000,11,12,10,9,64.730000000,64.830000000,7,8,7,8,64.720000000,64.840000000,9,7,6,6,64.710000000,64.850000000,8,8,7,5,64.700000000,64.860000000,7,4,6,3,64.690000000,64.870000000,4,4,3,3,64.680000000,64.880000000,4,4,2,3,MCLN5
2025-06-11T00:00:25.275224155Z,2025-06-11T00:00:25.273909283Z,10,1,42026514,A,B,0,64.770000000,1,130,13809,79327944,64.770000000,64.790000000,5,7,4,5,64.760000000,64.800000000,6,9,6,8,64.750000000,64.810000000,4,5,4,5,64.740000000,64.820000000,11,12,10,9,64.730000000,64.830000000,7,8,7,8,64.720000000,64.840000000,9,7,6,6,64.710000000,64.850000000,8,8,7,5,64.700000000,64.860000000,7,4,6,3,64.690000000,64.870000000,4,4,3,3,64.680000000,64.880000000,4,4,2,3,MCLN5
2025-06-11T00:00:25.275504668Z,2025-06-11T00:00:25.274188171Z,10,1,42025623,C,B,0,63.690000000,1,130,14029,79327967,63.680000000,63.710000000,2,2,2,2,63.670000000,63.720000000,3,2,3,2,63.660000000,63.730000000,3,2,3,2,63.650000000,63.740000000,3,5,3,5,63.640000000,63.750000000,6,3,6,3,63.630000000,63.760000000,4,4,4,4,63.620000000,63.770000000,5,1,5,1,63.610000000,63.780000000,2,3,2,3,63.600000000,63.790000000,6,1,6,1,63.590000000,63.800000000,1,3,1,3,MCLQ5
2025-06-11T00:00:25.275741169Z,2025-06-11T00:00:25.274537153Z,10,1,42026514,C,B,1,64.760000000,1,130,11699,79327983,64.770000000,64.790000000,5,7,4,5,64.760000000,64.800000000,5,9,5,8,64.750000000,64.810000000,4,5,4,5,64.740000000,64.820000000,11,12,10,9,64.730000000,64.830000000,7,8,7,8,64.720000000,64.840000000,9,7,6,6,64.710000000,64.850000000,8,8,7,5,64.700000000,64.860000000,7,4,6,3,64.690000000,64.870000000,4,4,3,3,64.680000000,64.880000000,4,4,2,3,MCLN5
2025-06-11T00:00:25.275916387Z,2025-06-11T00:00:25.274671375Z,10,1,42026514,C,B,0,64.770000000,1,130,13232,79327999,64.770000000,64.790000000,4,7,3,5,64.760000000,64.800000000,5,9,5,8,64.750000000,64.810000000,4,5,4,5,64.740000000,64.820000000,11,12,10,9,64.730000000,64.830000000,7,8,7,8,64.720000000,64.840000000,9,7,6,6,64.710000000,64.850000000,8,8,7,5,64.700000000,64.860000000,7,4,6,3,64.690000000,64.870000000,4,4,3,3,64.680000000,64.880000000,4,4,2,3,MCLN5
2025-06-11T00:00:25.275958386Z,2025-06-11T00:00:25.274719275Z,10,1,42025623,M,A,3,63.750000000,1,130,11523,79328002,63.680000000,63.710000000,2,2,2,2,63.670000000,63.720000000,3,2,3,2,63.660000000,63.730000000,3,2,3,2,63.650000000,63.740000000,3,4,3,4,63.640000000,63.750000000,6,4,6,4,63.630000000,63.760000000,4,4,4,4,63.620000000,63.770000000,5,1,5,1,63.610000000,63.780000000,2,3,2,3,63.600000000,63.790000000,6,1,6,1,63.590000000,63.800000000,1,3,1,3,MCLQ5
2025-06-11T00:00:25.275968531Z,2025-06-11T00:00:25.274719737Z,10,1,42025623,M,B,3,63.650000000,1,130,11473,79328003,63.680000000,63.710000000,2,2,2,2,63.670000000,63.720000000,3,2,3,2,63.660000000,63.730000000,3,2,3,2,63.650000000,63.740000000,4,4,4,4,63.640000000,63.750000000,5,4,5,4,63.630000000,63.760000000,4,4,4,4,63.620000000,63.770000000,5,1,5,1,63.610000000,63.780000000,2,3,2,3,63.600000000,63.790000000,6,1,6,1,63.590000000,63.800000000,1,3,1,3,MCLQ5
2025-06-11T00:00:25.275978461Z,2025-06-11T00:00:25.274720255Z,10,1,42025623,M,A,3,63.750000000,1,130,11694,79328004,63.680000000,63.710000000,2,2,2,2,63.670000000,63.720000000,3,2,3,2,63.660000000,63.730000000,3,2,3,2,63.650000000,63.740000000,4,3,4,3,63.640000000,63.750000000,5,5,5,5,63.630000000,63.760000000,4,4,4,4,63.620000000,63.770000000,5,1,5,1,63.610000000,63.780000000,2,3,2,3,63.600000000,63.790000000,6,1,6,1,63.590000000,63.800000000,1,3,1,3,MCLQ5
2025-06-11T00:00:25.275992799Z,2025-06-11T00:00:25.274720775Z,10,1,42025623,M,B,3,63.650000000,1,130,14880,79328005,63.680000000,63.710000000,2,2,2,2,63.670000000,63.720000000,3,2,3,2,63.660000000,63.730000000,3,2,3,2,63.650000000,63.740000000,5,3,5,3,63.640000000,63.750000000,4,5,4,5,63.630000000,63.760000000,4,4,4,4,63.620000000,63.770000000,5,1,5,1,63.610000000,63.780000000,2,3,2,3,63.600000000,63.790000000,6,1,6,1,63.590000000,63.800000000,1,3,1,3,MCLQ5
2025-06-11T00:00:25.284150926Z,2025-06-11T00:00:25.274946287Z,10,1,42026514,M,B,1,64.760000000,1,130,11814,79328041,64.770000000,64.790000000,4,7,3,5,64.760000000,64.800000000,6,9,6,8,64.750000000,64.810000000,4,5,4,5,64.740000000,64.820000000,11,12,10,9,64.730000000,64.830000000,7,8,7,8,64.720000000,64.840000000,9,7,6,6,64.710000000,64.850000000,8,8,7,5,64.700000000,64.860000000,7,4,6,3,64.690000000,64.870000000,4,4,3,3,64.680000000,64.880000000,4,4,2,3,MCLN5
2025-06-11T00:00:25.284629004Z,2025-06-11T00:00:25.275200773Z,10,1,42026514,T,A,0,64.770000000,4,0,11598,79328079,64.770000000,64.790000000,4,7,3,5,64.760000000,64.800000000,6,9,6,8,64.750000000,64.810000000,4,5,4,5,64.740000000,64.820000000,11,12,10,9,64.730000000,64.830000000,7,8,7,8,64.720000000,64.840000000,9,7,6,6,64.710000000,64.850000000,8,8,7,5,64.700000000,64.860000000,7,4,6,3,64.690000000,64.870000000,4,4,3,3,64.680000000,64.880000000,4,4,2,3,MCLN5
2025-06-11T00:00:25.284651605Z,2025-06-11T00:00:25.275200773Z,10,1,42026514,C,B,0,64.770000000,1,130,12073,79328080,64.760000000,64.790000000,6,7,6,5,64.750000000,64.800000000,4,9,4,8,64.740000000,64.810000000,11,5,10,5,64.730000000,64.820000000,7,12,7,9,64.720000000,64.830000000,9,8,6,8,64.710000000,64.840000000,8,7,7,6,64.700000000,64.850000000,7,8,6,5,64.690000000,64.860000000,4,4,3,3,64.680000000,64.870000000,4,4,2,3,64.670000000,64.880000000,6,4,4,3,MCLN5
2025-06-11T00:00:25.284701038Z,2025-06-11T00:00:25.275220989Z,10,1,42026514,A,B,0,64.780000000,1,130,15658,79328084,64.780000000,64.790000000,1,7,1,5,64.760000000,64.800000000,6,9,6,8,64.750000000,64.810000000,4,5,4,5,64.740000000,64.820000000,11,12,10,9,64.730000000,64.830000000,7,8,7,8,64.720000000,64.840000000,9,7,6,6,64.710000000,64.850000000,8,8,7,5,64.700000000,64.860000000,7,4,6,3,64.690000000,64.870000000,4,4,3,3,64.680000000,64.880000000,4,4,2,3,MCLN5
2025-06-11T00:00:25.284751363Z,2025-06-11T00:00:25.275235061Z,10,1,42026514,A,B,0,64.780000000,1,130,13465,79328087,64.780000000,64.790000000,2,7,2,5,64.760000000,64.800000000,6,9,6,8,64.750000000,64.810000000,4,5,4,5,64.740000000,64.820000000,11,12,10,9,64.730000000,64.830000000,7,8,7,8,64.720000000,64.840000000,9,7,6,6,64.710000000,64.850000000,8,8,7,5,64.700000000,64.860000000,7,4,6,3,64.690000000,64.870000000,4,4,3,3,64.680000000,64.880000000,4,4,2,3,MCLN5
2025-06-11T00:00:25.284840915Z,2025-06-11T00:00:25.275264629Z,10,1,42025623,A,B,0,63.690000000,1,130,13293,79328093,63.690000000,63.710000000,1,2,1,2,63.680000000,63.720000000,2,2,2,2,63.670000000,63.730000000,3,2,3,2,63.660000000,63.740000000,3,3,3,3,63.650000000,63.750000000,5,5,5,5,63.640000000,63.760000000,4,4,4,4,63.630000000,63.770000000,4,1,4,1,63.620000000,63.780000000,5,3,5,3,63.610000000,63.790000000,2,1,2,1,63.600000000,63.800000000,6,3,6,3,MCLQ5
2025-06-11T00:00:25.284989822Z,2025-06-11T00:00:25.275346859Z,10,1,42026514,M,B,1,64.770000000,1,130,12805,79328104,64.780000000,64.790000000,2,7,2,5,64.770000000,64.800000000,1,9,1,8,64.760000000,64.810000000,6,5,6,5,64.750000000,64.820000000,4,12,4,9,64.740000000,64.830000000,11,8,10,8,64.730000000,64.840000000,7,7,7,6,64.720000000,64.850000000,9,8,6,5,64.710000000,64.860000000,8,4,7,3,64.700000000,64.870000000,7,4,6,3,64.690000000,64.880000000,4,4,3,3,MCLN5
2025-06-11T00:00:25.285027006Z,2025-06-11T00:00:25.275356035Z,10,1,42022708,M,A,0,2.850000000,1,130,11719,79328107,2.800000000,2.830000000,12,12,3,3,2.790000000,2.840000000,2,2,2,2,2.780000000,2.850000000,1,1,1,1,,2.870000000,0,1,0,1,,,0,0,0,0,,,0,0,0,0,,,0,0,0,0,,,0,0,0,0,,,0,0,0,0,,,0,0,0,0,MCLN5-MCLV5
2025-06-11T00:00:25.285241183Z,2025-06-11T00:00:25.275433659Z,10,1,42418117,M,A,0,3.300000000,1,130,11661,79328126,3.240000000,3.280000000,11,11,2,2,3.230000000,3.290000000,1,1,1,1,3.220000000,3.300000000,1,1,1,1,,,0,0,0,0,,,0,0,0,0,,,0,0,0,0,,,0,0,0,0,,,0,0,0,0,,,0,0,0,0,,,0,0,0,0,MCLN5-MCLX5
2025-06-11T00:00:25.285516195Z,2025-06-11T00:00:25.275652319Z,10,1,42025623,M,A,1,63.720000000,1,130,11957,79328149,63.690000000,63.710000000,1,2,1,2,63.680000000,63.720000000,2,3,2,3,63.670000000,63.730000000,3,2,3,2,63.660000000,63.740000000,3,3,3,3,63.650000000,63.750000000,5,5,5,5,63.640000000,63.760000000,4,4,4,4,63.630000000,63.770000000,4,1,4,1,63.620000000,63.780000000,5,3,5,3,63.610000000,63.790000000,2,1,2,1,63.600000000,63.800000000,6,3,6,3,MCLQ5
2025-06-11T00:00:25.285915536Z,2025-06-11T00:00:25.275991509Z,10,1,42026514,C,B,1,64.770000000,1,130,14882,79328180,64.780000000,64.790000000,2,7,2,5,64.760000000,64.800000000,6,9,6,8,64.750000000,64.810000000,4,5,4,5,64.740000000,64.820000000,11,12,10,9,64.730000000,64.830000000,7,8,7,8,64.720000000,64.840000000,9,7,6,6,64.710000000,64.850000000,8,8,7,5,64.700000000,64.860000000,7,4,6,3,64.690000000,64.870000000,4,4,3,3,64.680000000,64.880000000,4,4,2,3,MCLN5
2025-06-11T00:00:25.285957267Z,2025-06-11T00:00:25.276187801Z,10,1,42026514,T,A,0,64.780000000,1,0,11652,79328184,64.780000000,64.790000000,2,7,2,5,64.760000000,64.800000000,6,9,6,8,64.750000000,64.810000000,4,5,4,5,64.740000000,64.820000000,11,12,10,9,64.730000000,64.830000000,7,8,7,8,64.720000000,64.840000000,9,7,6,6,64.710000000,64.850000000,8,8,7,5,64.700000000,64.860000000,7,4,6,3,64.690000000,64.870000000,4,4,3,3,64.680000000,64.880000000,4,4,2,3,MCLN5
2025-06-11T00:00:25.285981703Z,2025-06-11T00:00:25.276187801Z,10,1,42026514,C,B,0,64.780000000,1,130,17686,79328185,64.780000000,64.790000000,1,7,1,5,64.760000000,64.800000000,6,9,6,8,64.750000000,64.810000000,4,5,4,5,64.740000000,64.820000000,11,12,10,9,64.730000000,64.830000000,7,8,7,8,64.720000000,64.840000000,9,7,6,6,64.710000000,64.850000000,8,8,7,5,64.700000000,64.860000000,7,4,6,3,64.690000000,64.870000000,4,4,3,3,64.680000000,64.880000000,4,4,2,3,MCLN5
2025-06-11T00:00:25.286311489Z,2025-06-11T00:00:25.276279477Z,10,1,42022708,A,B,0,2.810000000,1,130,11631,79328204,2.810000000,2.830000000,1,12,1,3,2.800000000,2.840000000,12,2,3,2,2.790000000,2.850000000,2,1,2,1,2.780000000,2.870000000,1,1,1,1,,,0,0,0,0,,,0,0,0,0,,,0,0,0,0,,,0,0,0,0,,,0,0,0,0,,,0,0,0,0,MCLN5-MCLV5
2025-06-11T00:00:25.286401025Z,2025-06-11T00:00:25.276413967Z,10,1,42026514,C,B,0,64.780000000,1,130,11670,79328213,64.760000000,64.790000000,6,7,6,5,64.750000000,64.800000000,4,9,4,8,64.740000000,64.810000000,11,5,10,5,64.730000000,64.820000000,7,12,7,9,64.720000000,64.830000000,9,8,6,8,64.710000000,64.840000000,8,7,7,6,64.700000000,64.850000000,7,8,6,5,64.690000000,64.860000000,4,4,3,3,64.680000000,64.870000000,4,4,2,3,64.670000000,64.880000000,6,4,4,3,MCLN5
2025-06-11T00:00:25.286433994Z,2025-06-11T00:00:25.276446931Z,10,1,42025623,C,B,0,63.690000000,1,130,11906,79328216,63.680000000,63.710000000,2,2,2,2,63.670000000,63.720000000,3,3,3,3,63.660000000,63.730000000,3,2,3,2,63.650000000,63.740000000,5,3,5,3,63.640000000,63.750000000,4,5,4,5,63.630000000,63.760000000,4,4,4,4,63.620000000,63.770000000,5,1,5,1,63.610000000,63.780000000,2,3,2,3,63.600000000,63.790000000,6,1,6,1,63.590000000,63.800000000,1,3,1,3,MCLQ5
2025-06-11T00:00:25.286586464Z,2025-06-11T00:00:25.276726241Z,10,1,42026514,A,B,0,64.770000000,1,130,15097,79328226,64.770000000,64.790000000,1,7,1,5,64.760000000,64.800000000,6,9,6,8,64.750000000,64.810000000,4,5,4,5,64.740000000,64.820000000,11,12,10,9,64.730000000,64.830000000,7,8,7,8,64.720000000,64.840000000,9,7,6,6,64.710000000,64.850000000,8,8,7,5,64.700000000,64.860000000,7,4,6,3,64.690000000,64.870000000,4,4,3,3,64.680000000,64.880000000,4,4,2,3,MCLN5
2025-06-11T00:00:25.287790095Z,2025-06-11T00:00:25.284649155Z,10,1,42026514,A,B,1,64.760000000,1,130,12166,79328314,64.770000000,64.790000000,1,7,1,5,64.760000000,64.800000000,7,9,7,8,64.750000000,64.810000000,4,5,4,5,64.740000000,64.820000000,11,12,10,9,64.730000000,64.830000000,7,8,7,8,64.720000000,64.840000000,9,7,6,6,64.710000000,64.850000000,8,8,7,5,64.700000000,64.860000000,7,4,6,3,64.690000000,64.870000000,4,4,3,3,64.680000000,64.880000000,4,4,2,3,MCLN5
2025-06-11T00:00:25.287886028Z,2025-06-11T00:00:25.284663861Z,10,1,42026514,A,B,0,64.770000000,1,130,13988,79328319,64.770000000,64.790000000,2,7,2,5,64.760000000,64.800000000,7,9,7,8,64.750000000,64.810000000,4,5,4,5,64.740000000,64.820000000,11,12,10,9,64.730000000,64.830000000,7,8,7,8,64.720000000,64.840000000,9,7,6,6,64.710000000,64.850000000,8,8,7,5,64.700000000,64.860000000,7,4,6,3,64.690000000,64.870000000,4,4,3,3,64.680000000,64.880000000,4,4,2,3,MCLN5
2025-06-11T00:00:25.287903615Z,2025-06-11T00:00:25.284664495Z,10,1,42026514,A,B,0,64.770000000,1,130,14302,79328320,64.770000000,64.790000000,3,7,3,5,64.760000000,64.800000000,7,9,7,8,64.750000000,64.810000000,4,5,4,5,64.740000000,64.820000000,11,12,10,9,64.730000000,64.830000000,7,8,7,8,64.720000000,64.840000000,9,7,6,6,64.710000000,64.850000000,8,8,7,5,64.700000000,64.860000000,7,4,6,3,64.690000000,64.870000000,4,4,3,3,64.680000000,64.880000000,4,4,2,3,MCLN5
2025-06-11T00:00:25.287950806Z,2025-06-11T00:00:25.284711917Z,10,1,42026514,M,A,3,64.830000000,1,130,11694,79328323,64.770000000,64.790000000,3,7,3,5,64.760000000,64.800000000,7,9,7,8,64.750000000,64.810000000,4,5,4,5,64.740000000,64.820000000,11,11,10,8,64.730000000,64.830000000,7,9,7,9,64.720000000,64.840000000,9,7,6,6,64.710000000,64.850000000,8,8,7,5,64.700000000,64.860000000,7,4,6,3,64.690000000,64.870000000,4,4,3,3,64.680000000,64.880000000,4,4,2,3,MCLN5
2025-06-11T00:00:25.287963684Z,2025-06-11T00:00:25.284712417Z,10,1,42026514,M,B,3,64.740000000,1,130,14950,79328324,64.770000000,64.790000000,3,7,3,5,64.760000000,64.800000000,7,9,7,8,64.750000000,64.810000000,4,5,4,5,64.740000000,64.820000000,12,11,11,8,64.730000000,64.830000000,6,9,6,9,64.720000000,64.840000000,9,7,6,6,64.710000000,64.850000000,8,8,7,5,64.700000000,64.860000000,7,4,6,3,64.690000000,64.870000000,4,4,3,3,64.680000000,64.880000000,4,4,2,3,MCLN5
2025-06-11T00:00:25.287985763Z,2025-06-11T00:00:25.284712665Z,10,1,42026514,A,A,0,64.780000000,1,130,11403,79328325,64.770000000,64.780000000,3,1,3,1,64.760000000,64.790000000,7,7,7,5,64.750000000,64.800000000,4,9,4,8,64.740000000,64.810000000,12,5,11,5,64.730000000,64.820000000,6,11,6,8,64.720000000,64.830000000,9,9,6,9,64.710000000,64.840000000,8,7,7,6,64.700000000,64.850000000,7,8,6,5,64.690000000,64.860000000,4,4,3,3,64.680000000,64.870000000,4,4,2,3,MCLN5
2025-06-11T00:00:25.288017196Z,2025-06-11T00:00:25.284714181Z,10,1,42026514,C,A,6,64.840000000,1,130,14016,79328328,64.770000000,64.780000000,3,1,3,1,64.760000000,64.790000000,7,7,7,5,64.750000000,64.800000000,4,9,4,8,64.740000000,64.810000000,12,5,11,5,64.730000000,64.820000000,6,11,6,8,64.720000000,64.830000000,9,9,6,9,64.710000000,64.840000000,8,6,7,5,64.700000000,64.850000000,7,8,6,5,64.690000000,64.860000000,4,4,3,3,64.680000000,64.870000000,4,4,2,3,MCLN5
2025-06-11T00:00:25.288026342Z,2025-06-11T00:00:25.284818127Z,10,1,42025623,M,A,1,65.090000000,1,130,11435,79328329,63.680000000,63.710000000,2,2,2,2,63.670000000,63.720000000,3,2,3,2,63.660000000,63.730000000,3,2,3,2,63.650000000,63.740000000,5,3,5,3,63.640000000,63.750000000,4,5,4,5,63.630000000,63.760000000,4,4,4,4,63.620000000,63.770000000,5,1,5,1,63.610000000,63.780000000,2,3,2,3,63.600000000,63.790000000,6,1,6,1,63.590000000,63.800000000,1,3,1,3,MCLQ5
2025-06-11T00:00:25.288066476Z,2025-06-11T00:00:25.285024767Z,10,1,42025623,A,B,0,63.690000000,1,130,16576,79328332,63.690000000,63.710000000,1,2,1,2,63.680000000,63.720000000,2,2,2,2,63.670000000,63.730000000,3,2,3,2,63.660000000,63.740000000,3,3,3,3,63.650000000,63.750000000,5,5,5,5,63.640000000,63.760000000,4,4,4,4,63.630000000,63.770000000,4,1,4,1,63.620000000,63.780000000,5,3,5,3,63.610000000,63.790000000,2,1,2,1,63.600000000,63.800000000,6,3,6,3,MCLQ5
2025-06-11T00:00:25.288521822Z,2025-06-11T00:00:25.285473585Z,10,1,42026514,M,B,2,64.750000000,1,130,11588,79328363,64.770000000,64.780000000,3,1,3,1,64.760000000,64.790000000,7,7,7,5,64.750000000,64.800000000,5,9,5,8,64.740000000,64.810000000,12,5,11,5,64.730000000,64.820000000,6,11,6,8,64.720000000,64.830000000,9,9,6,9,64.710000000,64.840000000,8,6,7,5,64.700000000,64.850000000,7,8,6,5,64.690000000,64.860000000,4,4,3,3,64.680000000,64.870000000,4,4,2,3,MCLN5
2025-06-11T00:00:25.288567524Z,2025-06-11T00:00:25.285524173Z,10,1,42026514,C,B,0,64.770000000,1,130,19923,79328365,64.770000000,64.780000000,2,1,2,1,64.760000000,64.790000000,7,7,7,5,64.750000000,64.800000000,5,9,5,8,64.740000000,64.810000000,12,5,11,5,64.730000000,64.820000000,6,11,6,8,64.720000000,64.830000000,9,9,6,9,64.710000000,64.840000000,8,6,7,5,64.700000000,64.850000000,7,8,6,5,64.690000000,64.860000000,4,4,3,3,64.680000000,64.870000000,4,4,2,3,MCLN5
2025-06-11T00:00:25.288871989Z,2025-06-11T00:00:25.285947343Z,10,1,42025623,C,B,0,63.690000000,1,130,13436,79328385,63.680000000,63.710000000,2,2,2,2,63.670000000,63.720000000,3,2,3,2,63.660000000,63.730000000,3,2,3,2,63.650000000,63.740000000,5,3,5,3,63.640000000,63.750000000,4,5,4,5,63.630000000,63.760000000,4,4,4,4,63.620000000,63.770000000,5,1,5,1,63.610000000,63.780000000,2,3,2,3,63.600000000,63.790000000,6,1,6,1,63.590000000,63.800000000,1,3,1,3,MCLQ5
2025-06-11T00:00:25.289617540Z,2025-06-11T00:00:25.286371223Z,10,1,42026514,A,B,0,64.770000000,2,130,13612,79328426,64.770000000,64.780000000,4,1,3,1,64.760000000,64.790000000,7,7,7,5,64.750000000,64.800000000,5,9,5,8,64.740000000,64.810000000,12,5,11,5,64.730000000,64.820000000,6,11,6,8,64.720000000,64.830000000,9,9,6,9,64.710000000,64.840000000,8,6,7,5,64.700000000,64.850000000,7,8,6,5,64.690000000,64.860000000,4,4,3,3,64.680000000,64.870000000,4,4,2,3,MCLN5
2025-06-11T00:00:25.289691417Z,2025-06-11T00:00:25.286411387Z,10,1,42026514,A,B,0,64.770000000,1,130,14173,79328429,64.770000000,64.780000000,5,1,4,1,64.760000000,64.790000000,7,7,7,5,64.750000000,64.800000000,5,9,5,8,64.740000000,64.810000000,12,5,11,5,64.730000000,64.820000000,6,11,6,8,64.720000000,64.830000000,9,9,6,9,64.710000000,64.840000000,8,6,7,5,64.700000000,64.850000000,7,8,6,5,64.690000000,64.860000000,4,4,3,3,64.680000000,64.870000000,4,4,2,3,MCLN5
2025-06-11T00:00:25.289751572Z,2025-06-11T00:00:25.286578477Z,10,1,42026514,C,B,1,64.760000000,1,130,12394,79328435,64.770000000,64.780000000,5,1,4,1,64.760000000,64.790000000,6,7,6,5,64.750000000,64.800000000,5,9,5,8,64.740000000,64.810000000,12,5,11,5,64.730000000,64.820000000,6,11,6,8,64.720000000,64.830000000,9,9,6,9,64.710000000,64.840000000,8,6,7,5,64.700000000,64.850000000,7,8,6,5,64.690000000,64.860000000,4,4,3,3,64.680000000,64.870000000,4,4,2,3,MCLN5
2025-06-11T00:00:25.289770832Z,2025-06-11T00:00:25.286608177Z,10,1,42025623,A,B,0,63.690000000,1,130,13643,79328436,63.690000000,63.710000000,1,2,1,2,63.680000000,63.720000000,2,2,2,2,63.670000000,63.730000000,3,2,3,2,63.660000000,63.740000000,3,3,3,3,63.650000000,63.750000000,5,5,5,5,63.640000000,63.760000000,4,4,4,4,63.630000000,63.770000000,4,1,4,1,63.620000000,63.780000000,5,3,5,3,63.610000000,63.790000000,2,1,2,1,63.600000000,63.800000000,6,3,6,3,MCLQ5
2025-06-11T00:00:25.289800030Z,2025-06-11T00:00:25.286628145Z,10,1,42026514,T,B,0,64.780000000,1,0,11620,79328438,64.770000000,64.780000000,5,1,4,1,64.760000000,64.790000000,6,7,6,5,64.750000000,64.800000000,5,9,5,8,64.740000000,64.810000000,12,5,11,5,64.730000000,64.820000000,6,11,6,8,64.720000000,64.830000000,9,9,6,9,64.710000000,64.840000000,8,6,7,5,64.700000000,64.850000000,7,8,6,5,64.690000000,64.860000000,4,4,3,3,64.680000000,64.870000000,4,4,2,3,MCLN5
2025-06-11T00:00:25.289821763Z,2025-06-11T00:00:25.286628145Z,10,1,42026514,C,A,0,64.780000000,1,130,11748,79328439,64.770000000,64.790000000,5,7,4,5,64.760000000,64.800000000,6,9,6,8,64.750000000,64.810000000,5,5,5,5,64.740000000,64.820000000,12,11,11,8,64.730000000,64.830000000,6,9,6,9,64.720000000,64.840000000,9,6,6,5,64.710000000,64.850000000,8,8,7,5,64.700000000,64.860000000,7,4,6,3,64.690000000,64.870000000,4,4,3,3,64.680000000,64.880000000,4,4,2,3,MCLN5
2025-06-11T00:00:25.289890841Z,2025-06-11T00:00:25.286817565Z,10,1,42026514,M,B,3,64.730000000,1,130,11687,79328445,64.770000000,64.790000000,5,7,4,5,64.760000000,64.800000000,6,9,6,8,64.750000000,64.810000000,5,5,5,5,64.740000000,64.820000000,11,11,10,8,64.730000000,64.830000000,7,9,7,9,64.720000000,64.840000000,9,6,6,5,64.710000000,64.850000000,8,8,7,5,64.700000000,64.860000000,7,4,6,3,64.690000000,64.870000000,4,4,3,3,64.680000000,64.880000000,4,4,2,3,MCLN5
2025-06-11T00:00:25.289900425Z,2025-06-11T00:00:25.286818063Z,10,1,42026514,M,A,3,64.820000000,1,130,11376,79328446,64.770000000,64.790000000,5,7,4,5,64.760000000,64.800000000,6,9,6,8,64.750000000,64.810000000,5,5,5,5,64.740000000,64.820000000,11,12,10,9,64.730000000,64.830000000,7,8,7,8,64.720000000,64.840000000,9,6,6,5,64.710000000,64.850000000,8,8,7,5,64.700000000,64.860000000,7,4,6,3,64.690000000,64.870000000,4,4,3,3,64.680000000,64.880000000,4,4,2,3,MCLN5
2025-06-11T00:00:25.290379025Z,2025-06-11T00:00:25.287273485Z,10,1,42026514,M,A,1,66.740000000,2,130,15024,79328474,64.770000000,64.790000000,5,7,4,5,64.760000000,64.800000000,6,7,6,7,64.750000000,64.810000000,5,5,5,5,64.740000000,64.820000000,11,12,10,9,64.730000000,64.830000000,7,8,7,8,64.720000000,64.840000000,9,6,6,5,64.710000000,64.850000000,8,8,7,5,64.700000000,64.860000000,7,4,6,3,64.690000000,64.870000000,4,4,3,3,64.680000000,64.880000000,4,4,2,3,MCLN5
2025-06-11T00:00:25.290557583Z,2025-06-11T00:00:25.287449887Z,10,1,42026514,A,B,0,64.770000000,1,130,14035,79328485,64.770000000,64.790000000,6,7,5,5,64.760000000,64.800000000,6,7,6,7,64.750000000,64.810000000,5,5,5,5,64.740000000,64.820000000,11,12,10,9,64.730000000,64.830000000,7,8,7,8,64.720000000,64.840000000,9,6,6,5,64.710000000,64.850000000,8,8,7,5,64.700000000,64.860000000,7,4,6,3,64.690000000,64.870000000,4,4,3,3,64.680000000,64.880000000,4,4,2,3,MCLN5
2025-06-11T00:00:25.291301268Z,2025-06-11T00:00:25.287696541Z,10,1,42026514,A,A,0,64.780000000,1,130,11583,79328523,64.770000000,64.780000000,6,1,5,1,64.760000000,64.790000000,6,7,6,5,64.750000000,64.800000000,5,7,5,7,64.740000000,64.810000000,11,5,10,5,64.730000000,64.820000000,7,12,7,9,64.720000000,64.830000000,9,8,6,8,64.710000000,64.840000000,8,6,7,5,64.700000000,64.850000000,7,8,6,5,64.690000000,64.860000000,4,4,3,3,64.680000000,64.870000000,4,4,2,3,MCLN5
2025-06-11T00:00:25.291365054Z,2025-06-11T00:00:25.287747263Z,10,1,42026514,A,A,0,64.780000000,1,130,13643,79328527,64.770000000,64.780000000,6,2,5,2,64.760000000,64.790000000,6,7,6,5,64.750000000,64.800000000,5,7,5,7,64.740000000,64.810000000,11,5,10,5,64.730000000,64.820000000,7,12,7,9,64.720000000,64.830000000,9,8,6,8,64.710000000,64.840000000,8,6,7,5,64.700000000,64.850000000,7,8,6,5,64.690000000,64.860000000,4,4,3,3,64.680000000,64.870000000,4,4,2,3,MCLN5
2025-06-11T00:00:25.291409020Z,2025-06-11T00:00:25.287752045Z,10,1,42026514,C,B,0,64.770000000,1,130,13445,79328529,64.770000000,64.780000000,5,2,4,2,64.760000000,64.790000000,6,7,6,5,64.750000000,64.800000000,5,7,5,7,64.740000000,64.810000000,11,5,10,5,64.730000000,64.820000000,7,12,7,9,64.720000000,64.830000000,9,8,6,8,64.710000000,64.840000000,8,6,7,5,64.700000000,64.850000000,7,8,6,5,64.690000000,64.860000000,4,4,3,3,64.680000000,64.870000000,4,4,2,3,MCLN5
2025-06-11T00:00:25.291701597Z,2025-06-11T00:00:25.287811811Z,10,1,42025623,M,B,4,63.640000000,1,130,14149,79328544,63.690000000,63.710000000,1,2,1,2,63.680000000,63.720000000,2,2,2,2,63.670000000,63.730000000,3,2,3,2,63.660000000,63.740000000,3,3,3,3,63.650000000,63.750000000,4,5,4,5,63.640000000,63.760000000,5,4,5,4,63.630000000,63.770000000,4,1,4,1,63.620000000,63.780000000,5,3,5,3,63.610000000,63.790000000,2,1,2,1,63.600000000,63.800000000,6,3,6,3,MCLQ5
2025-06-11T00:00:25.291710568Z,2025-06-11T00:00:25.287812293Z,10,1,42025623,M,A,3,63.740000000,1,130,12304,79328545,63.690000000,63.710000000,1,2,1,2,63.680000000,63.720000000,2,2,2,2,63.670000000,63.730000000,3,2,3,2,63.660000000,63.740000000,3,4,3,4,63.650000000,63.750000000,4,4,4,4,63.640000000,63.760000000,5,4,5,4,63.630000000,63.770000000,4,1,4,1,63.620000000,63.780000000,5,3,5,3,63.610000000,63.790000000,2,1,2,1,63.600000000,63.800000000,6,3,6,3,MCLQ5
2025-06-11T00:00:25.291719645Z,2025-06-11T00:00:25.287812753Z,10,1,42025623,M,B,4,63.640000000,1,130,11348,79328546,63.690000000,63.710000000,1,2,1,2,63.680000000,63.720000000,2,2,2,2,63.670000000,63.730000000,3,2,3,2,63.660000000,63.740000000,3,4,3,4,63.650000000,63.750000000,3,4,3,4,63.640000000,63.760000000,6,4,6,4,63.630000000,63.770000000,4,1,4,1,63.620000000,63.780000000,5,3,5,3,63.610000000,63.790000000,2,1,2,1,63.600000000,63.800000000,6,3,6,3,MCLQ5
2025-06-11T00:00:25.291729467Z,2025-06-11T00:00:25.287813329Z,10,1,42025623,M,A,3,63.740000000,1,130,11469,79328547,63.690000000,63.710000000,1,2,1,2,63.680000000,63.720000000,2,2,2,2,63.670000000,63.730000000,3,2,3,2,63.660000000,63.740000000,3,5,3,5,63.650000000,63.750000000,3,3,3,3,63.640000000,63.760000000,6,4,6,4,63.630000000,63.770000000,4,1,4,1,63.620000000,63.780000000,5,3,5,3,63.610000000,63.790000000,2,1,2,1,63.600000000,63.800000000,6,3,6,3,MCLQ5
2025-06-11T00:00:25.291835853Z,2025-06-11T00:00:25.287906981Z,10,1,42025623,A,B,0,63.690000000,1,130,12950,79328553,63.690000000,63.710000000,2,2,2,2,63.680000000,63.720000000,2,2,2,2,63.670000000,63.730000000,3,2,3,2,63.660000000,63.740000000,3,5,3,5,63.650000000,63.750000000,3,3,3,3,63.640000000,63.760000000,6,4,6,4,63.630000000,63.770000000,4,1,4,1,63.620000000,63.780000000,5,3,5,3,63.610000000,63.790000000,2,1,2,1,63.600000000,63.800000000,6,3,6,3,MCLQ5
2025-06-11T00:00:25.291877038Z,2025-06-11T00:00:25.287998197Z,10,1,42026514,A,A,0,64.780000000,1,130,13808,79328556,64.770000000,64.780000000,5,3,4,3,64.760000000,64.790000000,6,7,6,5,64.750000000,64.800000000,5,7,5,7,64.740000000,64.810000000,11,5,10,5,64.730000000,64.820000000,7,12,7,9,64.720000000,64.830000000,9,8,6,8,64.710000000,64.840000000,8,6,7,5,64.700000000,64.850000000,7,8,6,5,64.690000000,64.860000000,4,4,3,3,64.680000000,64.870000000,4,4,2,3,MCLN5
2025-06-11T00:00:25.291924268Z,2025-06-11T00:00:25.288133475Z,10,1,42026514,T,B,0,64.780000000,1,0,11278,79328559,64.770000000,64.780000000,5,3,4,3,64.760000000,64.790000000,6,7,6,5,64.750000000,64.800000000,5,7,5,7,64.740000000,64.810000000,11,5,10,5,64.730000000,64.820000000,7,12,7,9,64.720000000,64.830000000,9,8,6,8,64.710000000,64.840000000,8,6,7,5,64.700000000,64.850000000,7,8,6,5,64.690000000,64.860000000,4,4,3,3,64.680000000,64.870000000,4,4,2,3,MCLN5
2025-06-11T00:00:25.291943144Z,2025-06-11T00:00:25.288133475Z,10,1,42026514,C,A,0,64.780000000,1,130,13630,79328560,64.770000000,64.780000000,5,2,4,2,64.760000000,64.790000000,6,7,6,5,64.750000000,64.800000000,5,7,5,7,64.740000000,64.810000000,11,5,10,5,64.730000000,64.820000000,7,12,7,9,64.720000000,64.830000000,9,8,6,8,64.710000000,64.840000000,8,6,7,5,64.700000000,64.850000000,7,8,6,5,64.690000000,64.860000000,4,4,3,3,64.680000000,64.870000000,4,4,2,3,MCLN5
2025-06-11T00:00:25.292136378Z,2025-06-11T00:00:25.288484147Z,10,1,42026514,C,A,1,64.790000000,1,130,12208,79328575,64.770000000,64.780000000,5,2,4,2,64.760000000,64.790000000,6,6,6,4,64.750000000,64.800000000,5,7,5,7,64.740000000,64.810000000,11,5,10,5,64.730000000,64.820000000,7,12,7,9,64.720000000,64.830000000,9,8,6,8,64.710000000,64.840000000,8,6,7,5,64.700000000,64.850000000,7,8,6,5,64.690000000,64.860000000,4,4,3,3,64.680000000,64.870000000,4,4,2,3,MCLN5
2025-06-11T00:00:25.292225937Z,2025-06-11T00:00:25.288693417Z,10,1,42026514,M,A,4,64.830000000,1,130,12027,79328581,64.770000000,64.780000000,5,2,4,2,64.760000000,64.790000000,6,6,6,4,64.750000000,64.800000000,5,7,5,7,64.740000000,64.810000000,11,5,10,5,64.730000000,64.820000000,7,11,7,8,64.720000000,64.830000000,9,9,6,9,64.710000000,64.840000000,8,6,7,5,64.700000000,64.850000000,7,8,6,5,64.690000000,64.860000000,4,4,3,3,64.680000000,64.870000000,4,4,2,3,MCLN5
2025-06-11T00:00:25.292248078Z,2025-06-11T00:00:25.288693973Z,10,1,42026514,C,A,0,64.780000000,1,130,11101,79328582,64.770000000,64.780000000,5,1,4,1,64.760000000,64.790000000,6,6,6,4,64.750000000,64.800000000,5,7,5,7,64.740000000,64.810000000,11,5,10,5,64.730000000,64.820000000,7,11,7,8,64.720000000,64.830000000,9,9,6,9,64.710000000,64.840000000,8,6,7,5,64.700000000,64.850000000,7,8,6,5,64.690000000,64.860000000,4,4,3,3,64.680000000,64.870000000,4,4,2,3,MCLN5
2025-06-11T00:00:25.292267883Z,2025-06-11T00:00:25.288694799Z,10,1,42026514,A,B,0,64.770000000,1,130,13306,79328584,64.770000000,64.780000000,6,1,5,1,64.760000000,64.790000000,6,6,6,4,64.750000000,64.800000000,5,7,5,7,64.740000000,64.810000000,11,5,10,5,64.730000000,64.820000000,7,11,7,8,64.720000000,64.830000000,9,9,6,9,64.710000000,64.840000000,8,6,7,5,64.700000000,64.850000000,7,8,6,5,64.690000000,64.860000000,4,4,3,3,64.680000000,64.870000000,4,4,2,3,MCLN5
2025-06-11T00:00:25.292277690Z,2025-06-11T00:00:25.288715093Z,10,1,42025623,M,A,3,63.750000000,1,130,10907,79328585,63.690000000,63.710000000,2,2,2,2,63.680000000,63.720000000,2,2,2,2,63.670000000,63.730000000,3,2,3,2,63.660000000,63.740000000,3,4,3,4,63.650000000,63.750000000,3,4,3,4,63.640000000,63.760000000,6,4,6,4,63.630000000,63.770000000,4,1,4,1,63.620000000,63.780000000,5,3,5,3,63.610000000,63.790000000,2,1,2,1,63.600000000,63.800000000,6,3,6,3,MCLQ5
2025-06-11T00:00:25.292301766Z,2025-06-11T00:00:25.288715869Z,10,1,42025623,M,A,3,63.750000000,1,130,14916,79328587,63.690000000,63.710000000,2,2,2,2,63.680000000,63.720000000,2,2,2,2,63.670000000,63.730000000,3,2,3,2,63.660000000,63.740000000,3,3,3,3,63.650000000,63.750000000,3,5,3,5,63.640000000,63.760000000,6,4,6,4,63.630000000,63.770000000,4,1,4,1,63.620000000,63.780000000,5,3,5,3,63.610000000,63.790000000,2,1,2,1,63.600000000,63.800000000,6,3,6,3,MCLQ5
2025-06-11T00:00:25.292976779Z,2025-06-11T00:00:25.289492447Z,10,1,42026514,A,B,0,64.770000000,1,130,13189,79328630,64.770000000,64.780000000,7,1,6,1,64.760000000,64.790000000,6,6,6,4,64.750000000,64.800000000,5,7,5,7,64.740000000,64.810000000,11,5,10,5,64.730000000,64.820000000,7,11,7,8,64.720000000,64.830000000,9,9,6,9,64.710000000,64.840000000,8,6,7,5,64.700000000,64.850000000,7,8,6,5,64.690000000,64.860000000,4,4,3,3,64.680000000,64.870000000,4,4,2,3,MCLN5
2025-06-11T00:00:25.293039691Z,2025-06-11T00:00:25.289626073Z,10,1,42026514,C,B,0,64.770000000,1,130,13443,79328633,64.770000000,64.780000000,6,1,5,1,64.760000000,64.790000000,6,6,6,4,64.750000000,64.800000000,5,7,5,7,64.740000000,64.810000000,11,5,10,5,64.730000000,64.820000000,7,11,7,8,64.720000000,64.830000000,9,9,6,9,64.710000000,64.840000000,8,6,7,5,64.700000000,64.850000000,7,8,6,5,64.690000000,64.860000000,4,4,3,3,64.680000000,64.870000000,4,4,2,3,MCLN5
2025-06-11T00:00:25.293052270Z,2025-06-11T00:00:25.289672555Z,10,1,42026514,T,B,0,64.780000000,1,0,11132,79328634,64.770000000,64.780000000,6,1,5,1,64.760000000,64.790000000,6,6,6,4,64.750000000,64.800000000,5,7,5,7,64.740000000,64.810000000,11,5,10,5,64.730000000,64.820000000,7,11,7,8,64.720000000,64.830000000,9,9,6,9,64.710000000,64.840000000,8,6,7,5,64.700000000,64.850000000,7,8,6,5,64.690000000,64.860000000,4,4,3,3,64.680000000,64.870000000,4,4,2,3,MCLN5
2025-06-11T00:00:25.293052270Z,2025-06-11T00:00:25.289672555Z,10,1,42026514,C,A,0,64.780000000,1,130,11132,79328634,64.770000000,64.790000000,6,6,5,4,64.760000000,64.800000000,6,7,6,7,64.750000000,64.810000000,5,5,5,5,64.740000000,64.820000000,11,11,10,8,64.730000000,64.830000000,7,9,7,9,64.720000000,64.840000000,9,6,6,5,64.710000000,64.850000000,8,8,7,5,64.700000000,64.860000000,7,4,6,3,64.690000000,64.870000000,4,4,3,3,64.680000000,64.880000000,4,4,2,3,MCLN5
2025-06-11T00:00:25.293365175Z,2025-06-11T00:00:25.289762715Z,10,1,42026514,C,B,0,64.770000000,1,130,13262,79328652,64.770000000,64.790000000,5,6,4,4,64.760000000,64.800000000,6,7,6,7,64.750000000,64.810000000,5,5,5,5,64.740000000,64.820000000,11,11,10,8,64.730000000,64.830000000,7,9,7,9,64.720000000,64.840000000,9,6,6,5,64.710000000,64.850000000,8,8,7,5,64.700000000,64.860000000,7,4,6,3,64.690000000,64.870000000,4,4,3,3,64.680000000,64.880000000,4,4,2,3,MCLN5
2025-06-11T00:00:25.294223508Z,2025-06-11T00:00:25.290758477Z,10,1,42026514,M,A,1,64.800000000,1,130,11773,79328706,64.770000000,64.790000000,5,6,4,4,64.760000000,64.800000000,6,8,6,8,64.750000000,64.810000000,5,5,5,5,64.740000000,64.820000000,11,11,10,8,64.730000000,64.830000000,7,9,7,9,64.720000000,64.840000000,9,6,6,5,64.710000000,64.850000000,8,8,7,5,64.700000000,64.860000000,7,4,6,3,64.690000000,64.870000000,4,4,3,3,64.680000000,64.880000000,4,4,2,3,MCLN5
2025-06-11T00:00:25.294492509Z,2025-06-11T00:00:25.291312181Z,10,1,42026514,A,A,0,64.780000000,1,130,11284,79328721,64.770000000,64.780000000,5,1,4,1,64.760000000,64.790000000,6,6,6,4,64.750000000,64.800000000,5,8,5,8,64.740000000,64.810000000,11,5,10,5,64.730000000,64.820000000,7,11,7,8,64.720000000,64.830000000,9,9,6,9,64.710000000,64.840000000,8,6,7,5,64.700000000,64.850000000,7,8,6,5,64.690000000,64.860000000,4,4,3,3,64.680000000,64.870000000,4,4,2,3,MCLN5
2025-06-11T00:00:25.294555681Z,2025-06-11T00:00:25.291333549Z,10,1,42026514,T,B,0,64.780000000,1,0,11215,79328726,64.770000000,64.780000000,5,1,4,1,64.760000000,64.790000000,6,6,6,4,64.750000000,64.800000000,5,8,5,8,64.740000000,64.810000000,11,5,10,5,64.730000000,64.820000000,7,11,7,8,64.720000000,64.830000000,9,9,6,9,64.710000000,64.840000000,8,6,7,5,64.700000000,64.850000000,7,8,6,5,64.690000000,64.860000000,4,4,3,3,64.680000000,64.870000000,4,4,2,3,MCLN5
2025-06-11T00:00:25.294577069Z,2025-06-11T00:00:25.291333549Z,10,1,42026514,C,A,0,64.780000000,1,130,11091,79328727,64.770000000,64.790000000,5,6,4,4,64.760000000,64.800000000,6,8,6,8,64.750000000,64.810000000,5,5,5,5,64.740000000,64.820000000,11,11,10,8,64.730000000,64.830000000,7,9,7,9,64.720000000,64.840000000,9,6,6,5,64.710000000,64.850000000,8,8,7,5,64.700000000,64.860000000,7,4,6,3,64.690000000,64.870000000,4,4,3,3,64.680000000,64.880000000,4,4,2,3,MCLN5
2025-06-11T00:00:25.294603870Z,2025-06-11T00:00:25.291334433Z,10,1,42026514,A,B,0,64.780000000,1,130,14241,79328730,64.780000000,64.790000000,1,6,1,4,64.770000000,64.800000000,5,8,4,8,64.760000000,64.810000000,6,5,6,5,64.750000000,64.820000000,5,11,5,8,64.740000000,64.830000000,11,9,10,9,64.730000000,64.840000000,7,6,7,5,64.720000000,64.850000000,9,8,6,5,64.710000000,64.860000000,8,4,7,3,64.700000000,64.870000000,7,4,6,3,64.690000000,64.880000000,4,4,3,3,MCLN5
2025-06-11T00:00:25.294677579Z,2025-06-11T00:00:25.291453333Z,10,1,42026514,M,A,1,64.800000000,1,130,11609,79328734,64.780000000,64.790000000,1,6,1,4,64.770000000,64.800000000,5,9,4,9,64.760000000,64.810000000,6,5,6,5,64.750000000,64.820000000,5,11,5,8,64.740000000,64.830000000,11,9,10,9,64.730000000,64.840000000,7,6,7,5,64.720000000,64.850000000,9,8,6,5,64.710000000,64.860000000,8,4,7,3,64.700000000,64.870000000,7,4,6,3,64.690000000,64.880000000,4,4,3,3,MCLN5
2025-06-11T00:00:25.294719448Z,2025-06-11T00:00:25.291812839Z,10,1,42026514,T,A,0,64.780000000,1,0,15570,79328737,64.780000000,64.790000000,1,6,1,4,64.770000000,64.800000000,5,9,4,9,64.760000000,64.810000000,6,5,6,5,64.750000000,64.820000000,5,11,5,8,64.740000000,64.830000000,11,9,10,9,64.730000000,64.840000000,7,6,7,5,64.720000000,64.850000000,9,8,6,5,64.710000000,64.860000000,8,4,7,3,64.700000000,64.870000000,7,4,6,3,64.690000000,64.880000000,4,4,3,3,MCLN5
2025-06-11T00:00:25.294730446Z,2025-06-11T00:00:25.291812839Z,10,1,42026514,C,B,0,64.780000000,1,130,11769,79328738,64.770000000,64.790000000,5,6,4,4,64.760000000,64.800000000,6,9,6,9,64.750000000,64.810000000,5,5,5,5,64.740000000,64.820000000,11,11,10,8,64.730000000,64.830000000,7,9,7,9,64.720000000,64.840000000,9,6,6,5,64.710000000,64.850000000,8,8,7,5,64.700000000,64.860000000,7,4,6,3,64.690000000,64.870000000,4,4,3,3,64.680000000,64.880000000,4,4,2,3,MCLN5
2025-06-11T00:00:25.295138279Z,2025-06-11T00:00:25.292185723Z,10,1,42026514,A,A,0,64.780000000,1,130,11760,79328774,64.770000000,64.780000000,5,1,4,1,64.760000000,64.790000000,6,6,6,4,64.750000000,64.800000000,5,9,5,9,64.740000000,64.810000000,11,5,10,5,64.730000000,64.820000000,7,11,7,8,64.720000000,64.830000000,9,9,6,9,64.710000000,64.840000000,8,6,7,5,64.700000000,64.850000000,7,8,6,5,64.690000000,64.860000000,4,4,3,3,64.680000000,64.870000000,4,4,2,3,MCLN5
2025-06-11T00:00:25.296242259Z,2025-06-11T00:00:25.294563231Z,10,1,42026514,A,B,0,64.770000000,1,130,13410,79328846,64.770000000,64.780000000,6,1,5,1,64.760000000,64.790000000,6,6,6,4,64.750000000,64.800000000,5,9,5,9,64.740000000,64.810000000,11,5,10,5,64.730000000,64.820000000,7,11,7,8,64.720000000,64.830000000,9,9,6,9,64.710000000,64.840000000,8,6,7,5,64.700000000,64.850000000,7,8,6,5,64.690000000,64.860000000,4,4,3,3,64.680000000,64.870000000,4,4,2,3,MCLN5
2025-06-11T00:00:25.296285234Z,2025-06-11T00:00:25.294566783Z,10,1,42026514,C,A,0,64.780000000,1,130,11624,79328848,64.770000000,64.790000000,6,6,5,4,64.760000000,64.800000000,6,9,6,9,64.750000000,64.810000000,5,5,5,5,64.740000000,64.820000000,11,11,10,8,64.730000000,64.830000000,7,9,7,9,64.720000000,64.840000000,9,6,6,5,64.710000000,64.850000000,8,8,7,5,64.700000000,64.860000000,7,4,6,3,64.690000000,64.870000000,4,4,3,3,64.680000000,64.880000000,4,4,2,3,MCLN5
2025-06-11T00:00:25.296311445Z,2025-06-11T00:00:25.294673645Z,10,1,42026514,C,B,0,64.770000000,1,130,11715,79328851,64.770000000,64.790000000,5,6,4,4,64.760000000,64.800000000,6,9,6,9,64.750000000,64.810000000,5,5,5,5,64.740000000,64.820000000,11,11,10,8,64.730000000,64.830000000,7,9,7,9,64.720000000,64.840000000,9,6,6,5,64.710000000,64.850000000,8,8,7,5,64.700000000,64.860000000,7,4,6,3,64.690000000,64.870000000,4,4,3,3,64.680000000,64.880000000,4,4,2,3,MCLN5
2025-06-11T00:00:25.296349059Z,2025-06-11T00:00:25.294707283Z,10,1,42026514,M,A,1,66.730000000,2,130,11732,79328854,64.770000000,64.790000000,5,6,4,4,64.760000000,64.800000000,6,8,6,8,64.750000000,64.810000000,5,5,5,5,64.740000000,64.820000000,11,11,10,8,64.730000000,64.830000000,7,9,7,9,64.720000000,64.840000000,9,6,6,5,64.710000000,64.850000000,8,8,7,5,64.700000000,64.860000000,7,4,6,3,64.690000000,64.870000000,4,4,3,3,64.680000000,64.880000000,4,4,2,3,MCLN5
2025-06-11T00:00:25.296371292Z,2025-06-11T00:00:25.294723525Z,10,1,42025623,M,B,0,63.690000000,1,130,15678,79328855,63.690000000,63.710000000,3,2,3,2,63.680000000,63.720000000,2,2,2,2,63.670000000,63.730000000,3,2,3,2,63.660000000,63.740000000,3,3,3,3,63.650000000,63.750000000,3,5,3,5,63.640000000,63.760000000,6,4,6,4,63.630000000,63.770000000,4,1,4,1,63.620000000,63.780000000,5,3,5,3,63.610000000,63.790000000,2,1,2,1,63.600000000,63.800000000,6,3,6,3,MCLQ5
2025-06-11T00:00:25.296379601Z,2025-06-11T00:00:25.294735947Z,10,1,42026514,M,A,1,66.750000000,2,130,11521,79328856,64.770000000,64.790000000,5,6,4,4,64.760000000,64.800000000,6,7,6,7,64.750000000,64.810000000,5,5,5,5,64.740000000,64.820000000,11,11,10,8,64.730000000,64.830000000,7,9,7,9,64.720000000,64.840000000,9,6,6,5,64.710000000,64.850000000,8,8,7,5,64.700000000,64.860000000,7,4,6,3,64.690000000,64.870000000,4,4,3,3,64.680000000,64.880000000,4,4,2,3,MCLN5
2025-06-11T00:00:25.296389377Z,2025-06-11T00:00:25.294748887Z,10,1,42026514,M,B,1,64.760000000,1,130,11604,79328857,64.770000000,64.790000000,5,6,4,4,64.760000000,64.800000000,7,7,7,7,64.750000000,64.810000000,5,5,5,5,64.740000000,64.820000000,11,11,10,8,64.730000000,64.830000000,7,9,7,9,64.720000000,64.840000000,9,6,6,5,64.710000000,64.850000000,8,8,7,5,64.700000000,64.860000000,7,4,6,3,64.690000000,64.870000000,4,4,3,3,64.680000000,64.880000000,4,4,2,3,MCLN5
2025-06-11T00:00:25.296406817Z,2025-06-11T00:00:25.294823265Z,10,1,42025623,C,B,0,63.690000000,1,130,12791,79328858,63.690000000,63.710000000,2,2,2,2,63.680000000,63.720000000,2,2,2,2,63.670000000,63.730000000,3,2,3,2,63.660000000,63.740000000,3,3,3,3,63.650000000,63.750000000,3,5,3,5,63.640000000,63.760000000,6,4,6,4,63.630000000,63.770000000,4,1,4,1,63.620000000,63.780000000,5,3,5,3,63.610000000,63.790000000,2,1,2,1,63.600000000,63.800000000,6,3,6,3,MCLQ5
2025-06-11T00:00:25.297223343Z,2025-06-11T00:00:25.296430791Z,10,1,42025623,M,B,0,63.690000000,1,130,13363,79328913,63.690000000,63.710000000,3,2,3,2,63.680000000,63.720000000,2,2,2,2,63.670000000,63.730000000,3,2,3,2,63.660000000,63.740000000,3,3,3,3,63.650000000,63.750000000,3,5,3,5,63.640000000,63.760000000,6,4,6,4,63.630000000,63.770000000,4,1,4,1,63.620000000,63.780000000,5,3,5,3,63.610000000,63.790000000,2,1,2,1,63.600000000,63.800000000,6,3,6,3,MCLQ5
2025-06-11T00:00:25.297268791Z,2025-06-11T00:00:25.296546253Z,10,1,42025623,C,B,0,63.690000000,1,130,12967,79328917,63.690000000,63.710000000,2,2,2,2,63.680000000,63.720000000,2,2,2,2,63.670000000,63.730000000,3,2,3,2,63.660000000,63.740000000,3,3,3,3,63.650000000,63.750000000,3,5,3,5,63.640000000,63.760000000,6,4,6,4,63.630000000,63.770000000,4,1,4,1,63.620000000,63.780000000,5,3,5,3,63.610000000,63.790000000,2,1,2,1,63.600000000,63.800000000,6,3,6,3,MCLQ5
2025-06-11T00:00:25.297617183Z,2025-06-11T00:00:25.296894909Z,10,1,42026514,A,B,0,64.780000000,1,130,11337,79328936,64.780000000,64.790000000,1,6,1,4,64.770000000,64.800000000,5,7,4,7,64.760000000,64.810000000,7,5,7,5,64.750000000,64.820000000,5,11,5,8,64.740000000,64.830000000,11,9,10,9,64.730000000,64.840000000,7,6,7,5,64.720000000,64.850000000,9,8,6,5,64.710000000,64.860000000,8,4,7,3,64.700000000,64.870000000,7,4,6,3,64.690000000,64.880000000,4,4,3,3,MCLN5
2025-06-11T00:00:25.297834031Z,2025-06-11T00:00:25.297002061Z,10,1,42025623,C,B,0,63.690000000,1,130,11676,79328952,63.690000000,63.710000000,1,2,1,2,63.680000000,63.720000000,2,2,2,2,63.670000000,63.730000000,3,2,3,2,63.660000000,63.740000000,3,3,3,3,63.650000000,63.750000000,3,5,3,5,63.640000000,63.760000000,6,4,6,4,63.630000000,63.770000000,4,1,4,1,63.620000000,63.780000000,5,3,5,3,63.610000000,63.790000000,2,1,2,1,63.600000000,63.800000000,6,3,6,3,MCLQ5
2025-06-11T00:00:25.298783245Z,2025-06-11T00:00:25.298343679Z,10,1,42026514,T,A,0,64.780000000,1,0,14690,79329015,64.780000000,64.790000000,1,6,1,4,64.770000000,64.800000000,5,7,4,7,64.760000000,64.810000000,7,5,7,5,64.750000000,64.820000000,5,11,5,8,64.740000000,64.830000000,11,9,10,9,64.730000000,64.840000000,7,6,7,5,64.720000000,64.850000000,9,8,6,5,64.710000000,64.860000000,8,4,7,3,64.700000000,64.870000000,7,4,6,3,64.690000000,64.880000000,4,4,3,3,MCLN5
2025-06-11T00:00:25.298798712Z,2025-06-11T00:00:25.298343679Z,10,1,42026514,C,B,0,64.780000000,1,130,11524,79329016,64.770000000,64.790000000,5,6,4,4,64.760000000,64.800000000,7,7,7,7,64.750000000,64.810000000,5,5,5,5,64.740000000,64.820000000,11,11,10,8,64.730000000,64.830000000,7,9,7,9,64.720000000,64.840000000,9,6,6,5,64.710000000,64.850000000,8,8,7,5,64.700000000,64.860000000,7,4,6,3,64.690000000,64.870000000,4,4,3,3,64.680000000,64.880000000,4,4,2,3,MCLN5
2025-06-11T00:00:25.299949553Z,2025-06-11T00:00:25.299771041Z,10,1,42026514,M,B,0,64.770000000,1,130,13394,79329090,64.770000000,64.790000000,6,6,5,4,64.760000000,64.800000000,7,7,7,7,64.750000000,64.810000000,5,5,5,5,64.740000000,64.820000000,11,11,10,8,64.730000000,64.830000000,7,9,7,9,64.720000000,64.840000000,9,6,6,5,64.710000000,64.850000000,8,8,7,5,64.700000000,64.860000000,7,4,6,3,64.690000000,64.870000000,4,4,3,3,64.680000000,64.880000000,4,4,2,3,MCLN5
2025-06-11T00:00:25.299992782Z,2025-06-11T00:00:25.299881051Z,10,1,42025623,A,B,0,63.690000000,1,130,12933,79329093,63.690000000,63.710000000,2,2,2,2,63.680000000,63.720000000,2,2,2,2,63.670000000,63.730000000,3,2,3,2,63.660000000,63.740000000,3,3,3,3,63.650000000,63.750000000,3,5,3,5,63.640000000,63.760000000,6,4,6,4,63.630000000,63.770000000,4,1,4,1,63.620000000,63.780000000,5,3,5,3,63.610000000,63.790000000,2,1,2,1,63.600000000,63.800000000,6,3,6,3,MCLQ5
2025-06-11T00:00:25.300319702Z,2025-06-11T00:00:25.299959517Z,10,1,42025623,C,B,7,63.620000000,1,130,14759,79329115,63.690000000,63.710000000,2,2,2,2,63.680000000,63.720000000,2,2,2,2,63.670000000,63.730000000,3,2,3,2,63.660000000,63.740000000,3,3,3,3,63.650000000,63.750000000,3,5,3,5,63.640000000,63.760000000,6,4,6,4,63.630000000,63.770000000,4,1,4,1,63.620000000,63.780000000,4,3,4,3,63.610000000,63.790000000,2,1,2,1,63.600000000,63.800000000,6,3,6,3,MCLQ5
2025-06-11T00:00:25.300327858Z,2025-06-11T00:00:25.299962763Z,10,1,42025623,A,A,6,63.770000000,1,130,11374,79329116,63.690000000,63.710000000,2,2,2,2,63.680000000,63.720000000,2,2,2,2,63.670000000,63.730000000,3,2,3,2,63.660000000,63.740000000,3,3,3,3,63.650000000,63.750000000,3,5,3,5,63.640000000,63.760000000,6,4,6,4,63.630000000,63.770000000,4,2,4,2,63.620000000,63.780000000,4,3,4,3,63.610000000,63.790000000,2,1,2,1,63.600000000,63.800000000,6,3,6,3,MCLQ5
2025-06-11T00:00:25.300494045Z,2025-06-11T00:00:25.300223411Z,10,1,42025623,A,B,6,63.630000000,1,130,11414,79329128,63.690000000,63.710000000,2,2,2,2,63.680000000,63.720000000,2,2,2,2,63.670000000,63.730000000,3,2,3,2,63.660000000,63.740000000,3,3,3,3,63.650000000,63.750000000,3,5,3,5,63.640000000,63.760000000,6,4,6,4,63.630000000,63.770000000,5,2,5,2,63.620000000,63.780000000,4,3,4,3,63.610000000,63.790000000,2,1,2,1,63.600000000,63.800000000,6,3,6,3,MCLQ5
2025-06-11T00:00:25.308810133Z,2025-06-11T00:00:25.308668445Z,10,1,42026514,A,B,0,64.780000000,1,130,19588,79329247,64.780000000,64.790000000,1,6,1,4,64.770000000,64.800000000,6,7,5,7,64.760000000,64.810000000,7,5,7,5,64.750000000,64.820000000,5,11,5,8,64.740000000,64.830000000,11,9,10,9,64.730000000,64.840000000,7,6,7,5,64.720000000,64.850000000,9,8,6,5,64.710000000,64.860000000,8,4,7,3,64.700000000,64.870000000,7,4,6,3,64.690000000,64.880000000,4,4,3,3,MCLN5
2025-06-11T00:00:25.319685709Z,2025-06-11T00:00:25.319587021Z,10,1,42026514,C,B,6,64.720000000,1,130,15478,79329285,64.780000000,64.790000000,1,6,1,4,64.770000000,64.800000000,6,7,5,7,64.760000000,64.810000000,7,5,7,5,64.750000000,64.820000000,5,11,5,8,64.740000000,64.830000000,11,9,10,9,64.730000000,64.840000000,7,6,7,5,64.720000000,64.850000000,8,8,5,5,64.710000000,64.860000000,8,4,7,3,64.700000000,64.870000000,7,4,6,3,64.690000000,64.880000000,4,4,3,3,MCLN5
2025-06-11T00:00:25.319693895Z,2025-06-11T00:00:25.319589171Z,10,1,42026514,A,A,6,64.850000000,1,130,11233,79329286,64.780000000,64.790000000,1,6,1,4,64.770000000,64.800000000,6,7,5,7,64.760000000,64.810000000,7,5,7,5,64.750000000,64.820000000,5,11,5,8,64.740000000,64.830000000,11,9,10,9,64.730000000,64.840000000,7,6,7,5,64.720000000,64.850000000,8,9,5,6,64.710000000,64.860000000,8,4,7,3,64.700000000,64.870000000,7,4,6,3,64.690000000,64.880000000,4,4,3,3,MCLN5
2025-06-11T00:00:25.319809258Z,2025-06-11T00:00:25.319716443Z,10,1,42026514,A,B,5,64.730000000,1,130,14582,79329287,64.780000000,64.790000000,1,6,1,4,64.770000000,64.800000000,6,7,5,7,64.760000000,64.810000000,7,5,7,5,64.750000000,64.820000000,5,11,5,8,64.740000000,64.830000000,11,9,10,9,64.730000000,64.840000000,8,6,8,5,64.720000000,64.850000000,8,9,5,6,64.710000000,64.860000000,8,4,7,3,64.700000000,64.870000000,7,4,6,3,64.690000000,64.880000000,4,4,3,3,MCLN5
2025-06-11T00:00:25.341717427Z,2025-06-11T00:00:25.341481983Z,10,1,42418117,M,A,0,3.290000000,10,130,11753,79329353,3.240000000,3.280000000,11,1,2,1,3.230000000,3.290000000,1,11,1,2,3.220000000,3.300000000,1,1,1,1,,,0,0,0,0,,,0,0,0,0,,,0,0,0,0,,,0,0,0,0,,,0,0,0,0,,,0,0,0,0,,,0,0,0,0,MCLN5-MCLX5
2025-06-11T00:00:25.442480741Z,2025-06-11T00:00:25.442386501Z,10,1,42418117,M,A,0,3.280000000,10,130,14672,79329583,3.240000000,3.280000000,11,11,2,2,3.230000000,3.290000000,1,1,1,1,3.220000000,3.300000000,1,1,1,1,,,0,0,0,0,,,0,0,0,0,,,0,0,0,0,,,0,0,0,0,,,0,0,0,0,,,0,0,0,0,,,0,0,0,0,MCLN5-MCLX5
2025-06-11T00:00:25.591952432Z,2025-06-11T00:00:25.591843079Z,10,1,42026514,M,B,4,64.740000000,1,130,16770,79329691,64.780000000,64.790000000,1,6,1,4,64.770000000,64.800000000,6,7,5,7,64.760000000,64.810000000,7,5,7,5,64.750000000,64.820000000,5,11,5,8,64.740000000,64.830000000,12,9,11,9,64.730000000,64.840000000,7,6,7,5,64.720000000,64.850000000,8,9,5,6,64.710000000,64.860000000,8,4,7,3,64.700000000,64.870000000,7,4,6,3,64.690000000,64.880000000,4,4,3,3,MCLN5
2025-06-11T00:00:25.591961164Z,2025-06-11T00:00:25.591844039Z,10,1,42025623,M,B,4,63.650000000,1,130,11934,79329692,63.690000000,63.710000000,2,2,2,2,63.680000000,63.720000000,2,2,2,2,63.670000000,63.730000000,3,2,3,2,63.660000000,63.740000000,3,3,3,3,63.650000000,63.750000000,4,5,4,5,63.640000000,63.760000000,5,4,5,4,63.630000000,63.770000000,5,2,5,2,63.620000000,63.780000000,4,3,4,3,63.610000000,63.790000000,2,1,2,1,63.600000000,63.800000000,6,3,6,3,MCLQ5
2025-06-11T00:00:25.591972622Z,2025-06-11T00:00:25.591844615Z,10,1,42025623,M,B,4,63.650000000,1,130,12064,79329693,63.690000000,63.710000000,2,2,2,2,63.680000000,63.720000000,2,2,2,2,63.670000000,63.730000000,3,2,3,2,63.660000000,63.740000000,3,3,3,3,63.650000000,63.750000000,5,5,5,5,63.640000000,63.760000000,4,4,4,4,63.630000000,63.770000000,5,2,5,2,63.620000000,63.780000000,4,3,4,3,63.610000000,63.790000000,2,1,2,1,63.600000000,63.800000000,6,3,6,3,MCLQ5
2025-06-11T00:00:25.603013823Z,2025-06-11T00:00:25.602894073Z,10,1,42418117,M,B,0,3.250000000,1,130,15327,79329694,3.250000000,3.280000000,1,11,1,2,3.240000000,3.290000000,11,1,2,1,3.230000000,3.300000000,1,1,1,1,,,0,0,0,0,,,0,0,0,0,,,0,0,0,0,,,0,0,0,0,,,0,0,0,0,,,0,0,0,0,,,0,0,0,0,MCLN5-MCLX5
2025-06-11T00:00:26.015757821Z,2025-06-11T00:00:26.015630973Z,10,1,42026514,C,A,0,64.790000000,1,130,13675,79329793,64.780000000,64.790000000,1,5,1,3,64.770000000,64.800000000,6,7,5,7,64.760000000,64.810000000,7,5,7,5,64.750000000,64.820000000,5,11,5,8,64.740000000,64.830000000,12,9,11,9,64.730000000,64.840000000,7,6,7,5,64.720000000,64.850000000,8,9,5,6,64.710000000,64.860000000,8,4,7,3,64.700000000,64.870000000,7,4,6,3,64.690000000,64.880000000,4,4,3,3,MCLN5
2025-06-11T00:00:26.015941439Z,2025-06-11T00:00:26.015773259Z,10,1,42026514,A,B,0,64.780000000,1,130,13574,79329800,64.780000000,64.790000000,2,5,2,3,64.770000000,64.800000000,6,7,5,7,64.760000000,64.810000000,7,5,7,5,64.750000000,64.820000000,5,11,5,8,64.740000000,64.830000000,12,9,11,9,64.730000000,64.840000000,7,6,7,5,64.720000000,64.850000000,8,9,5,6,64.710000000,64.860000000,8,4,7,3,64.700000000,64.870000000,7,4,6,3,64.690000000,64.880000000,4,4,3,3,MCLN5
2025-06-11T00:00:26.015962075Z,2025-06-11T00:00:26.015783855Z,10,1,42026514,A,B,0,64.780000000,1,130,17188,79329801,64.780000000,64.790000000,3,5,3,3,64.770000000,64.800000000,6,7,5,7,64.760000000,64.810000000,7,5,7,5,64.750000000,64.820000000,5,11,5,8,64.740000000,64.830000000,12,9,11,9,64.730000000,64.840000000,7,6,7,5,64.720000000,64.850000000,8,9,5,6,64.710000000,64.860000000,8,4,7,3,64.700000000,64.870000000,7,4,6,3,64.690000000,64.880000000,4,4,3,3,MCLN5
2025-06-11T00:00:26.015978455Z,2025-06-11T00:00:26.015793763Z,10,1,42026514,C,A,0,64.790000000,2,130,12795,79329802,64.780000000,64.790000000,3,3,3,2,64.770000000,64.800000000,6,7,5,7,64.760000000,64.810000000,7,5,7,5,64.750000000,64.820000000,5,11,5,8,64.740000000,64.830000000,12,9,11,9,64.730000000,64.840000000,7,6,7,5,64.720000000,64.850000000,8,9,5,6,64.710000000,64.860000000,8,4,7,3,64.700000000,64.870000000,7,4,6,3,64.690000000,64.880000000,4,4,3,3,MCLN5
2025-06-11T00:00:26.016281308Z,2025-06-11T00:00:26.015970971Z,10,1,42025623,M,A,4,63.760000000,1,130,11396,79329812,63.690000000,63.710000000,2,2,2,2,63.680000000,63.720000000,2,2,2,2,63.670000000,63.730000000,3,2,3,2,63.660000000,63.740000000,3,3,3,3,63.650000000,63.750000000,5,4,5,4,63.640000000,63.760000000,4,5,4,5,63.630000000,63.770000000,5,2,5,2,63.620000000,63.780000000,4,3,4,3,63.610000000,63.790000000,2,1,2,1,63.600000000,63.800000000,6,3,6,3,MCLQ5
2025-06-11T00:00:26.016292927Z,2025-06-11T00:00:26.015971469Z,10,1,42025623,M,B,4,63.650000000,1,130,11514,79329813,63.690000000,63.710000000,2,2,2,2,63.680000000,63.720000000,2,2,2,2,63.670000000,63.730000000,3,2,3,2,63.660000000,63.740000000,3,3,3,3,63.650000000,63.750000000,6,4,6,4,63.640000000,63.760000000,3,5,3,5,63.630000000,63.770000000,5,2,5,2,63.620000000,63.780000000,4,3,4,3,63.610000000,63.790000000,2,1,2,1,63.600000000,63.800000000,6,3,6,3,MCLQ5
2025-06-11T00:00:26.016304884Z,2025-06-11T00:00:26.015985965Z,10,1,42026514,M,A,3,64.830000000,1,130,11724,79329814,64.780000000,64.790000000,3,3,3,2,64.770000000,64.800000000,6,7,5,7,64.760000000,64.810000000,7,5,7,5,64.750000000,64.820000000,5,10,5,7,64.740000000,64.830000000,12,10,11,10,64.730000000,64.840000000,7,6,7,5,64.720000000,64.850000000,8,9,5,6,64.710000000,64.860000000,8,4,7,3,64.700000000,64.870000000,7,4,6,3,64.690000000,64.880000000,4,4,3,3,MCLN5
2025-06-11T00:00:26.016314331Z,2025-06-11T00:00:26.015986445Z,10,1,42026514,M,B,3,64.750000000,1,130,11492,79329815,64.780000000,64.790000000,3,3,3,2,64.770000000,64.800000000,6,7,5,7,64.760000000,64.810000000,7,5,7,5,64.750000000,64.820000000,6,10,6,7,64.740000000,64.830000000,11,10,10,10,64.730000000,64.840000000,7,6,7,5,64.720000000,64.850000000,8,9,5,6,64.710000000,64.860000000,8,4,7,3,64.700000000,64.870000000,7,4,6,3,64.690000000,64.880000000,4,4,3,3,MCLN5
2025-06-11T00:00:26.016324091Z,2025-06-11T00:00:26.015986945Z,10,1,42026514,M,A,3,64.830000000,1,130,11737,79329816,64.780000000,64.790000000,3,3,3,2,64.770000000,64.800000000,6,7,5,7,64.760000000,64.810000000,7,5,7,5,64.750000000,64.820000000,6,9,6,6,64.740000000,64.830000000,11,11,10,11,64.730000000,64.840000000,7,6,7,5,64.720000000,64.850000000,8,9,5,6,64.710000000,64.860000000,8,4,7,3,64.700000000,64.870000000,7,4,6,3,64.690000000,64.880000000,4,4,3,3,MCLN5
2025-06-11T00:00:26.016334141Z,2025-06-11T00:00:26.015987423Z,10,1,42026514,M,B,3,64.750000000,1,130,12374,79329817,64.780000000,64.790000000,3,3,3,2,64.770000000,64.800000000,6,7,5,7,64.760000000,64.810000000,7,5,7,5,64.750000000,64.820000000,7,9,7,6,64.740000000,64.830000000,10,11,9,11,64.730000000,64.840000000,7,6,7,5,64.720000000,64.850000000,8,9,5,6,64.710000000,64.860000000,8,4,7,3,64.700000000,64.870000000,7,4,6,3,64.690000000,64.880000000,4,4,3,3,MCLN5
2025-06-11T00:00:26.025588202Z,2025-06-11T00:00:26.016458339Z,10,1,42026514,A,B,0,64.780000000,1,130,13805,79329874,64.780000000,64.790000000,4,3,4,2,64.770000000,64.800000000,6,7,5,7,64.760000000,64.810000000,7,5,7,5,64.750000000,64.820000000,7,9,7,6,64.740000000,64.830000000,10,11,9,11,64.730000000,64.840000000,7,6,7,5,64.720000000,64.850000000,8,9,5,6,64.710000000,64.860000000,8,4,7,3,64.700000000,64.870000000,7,4,6,3,64.690000000,64.880000000,4,4,3,3,MCLN5
2025-06-11T00:00:26.025614013Z,2025-06-11T00:00:26.016524635Z,10,1,42026514,M,B,3,64.750000000,1,130,11483,79329877,64.780000000,64.790000000,4,3,4,2,64.770000000,64.800000000,6,7,5,7,64.760000000,64.810000000,7,5,7,5,64.750000000,64.820000000,8,9,8,6,64.740000000,64.830000000,10,11,9,11,64.730000000,64.840000000,7,6,7,5,64.720000000,64.850000000,8,9,5,6,64.710000000,64.860000000,8,4,7,3,64.700000000,64.870000000,7,4,6,3,64.690000000,64.880000000,4,4,3,3,MCLN5
2025-06-11T00:00:26.025895133Z,2025-06-11T00:00:26.017169457Z,10,1,42025623,M,B,0,63.690000000,1,130,11696,79329896,63.690000000,63.710000000,3,2,3,2,63.680000000,63.720000000,2,2,2,2,63.670000000,63.730000000,3,2,3,2,63.660000000,63.740000000,3,3,3,3,63.650000000,63.750000000,6,4,6,4,63.640000000,63.760000000,3,5,3,5,63.630000000,63.770000000,5,2,5,2,63.620000000,63.780000000,4,3,4,3,63.610000000,63.790000000,2,1,2,1,63.600000000,63.800000000,6,3,6,3,MCLQ5
2025-06-11T00:00:26.025958405Z,2025-06-11T00:00:26.017430373Z,10,1,42026514,A,B,0,64.780000000,1,130,13850,79329901,64.780000000,64.790000000,5,3,5,2,64.770000000,64.800000000,6,7,5,7,64.760000000,64.810000000,7,5,7,5,64.750000000,64.820000000,8,9,8,6,64.740000000,64.830000000,10,11,9,11,64.730000000,64.840000000,7,6,7,5,64.720000000,64.850000000,8,9,5,6,64.710000000,64.860000000,8,4,7,3,64.700000000,64.870000000,7,4,6,3,64.690000000,64.880000000,4,4,3,3,MCLN5
2025-06-11T00:00:26.026345471Z,2025-06-11T00:00:26.025915689Z,10,1,42026514,C,A,0,64.790000000,1,130,17523,79329924,64.780000000,64.790000000,5,2,5,1,64.770000000,64.800000000,6,7,5,7,64.760000000,64.810000000,7,5,7,5,64.750000000,64.820000000,8,9,8,6,64.740000000,64.830000000,10,11,9,11,64.730000000,64.840000000,7,6,7,5,64.720000000,64.850000000,8,9,5,6,64.710000000,64.860000000,8,4,7,3,64.700000000,64.870000000,7,4,6,3,64.690000000,64.880000000,4,4,3,3,MCLN5
2025-06-11T00:00:26.026791080Z,2025-06-11T00:00:26.026326511Z,10,1,42025611,A,B,0,2.070000000,2,130,11405,79329963,2.070000000,2.080000000,3,6,2,3,2.060000000,2.090000000,27,27,5,6,2.050000000,2.100000000,23,27,3,6,2.040000000,2.110000000,23,22,3,3,2.030000000,2.120000000,2,2,1,1,2.020000000,2.130000000,2,2,2,2,2.010000000,2.140000000,2,2,1,1,2.000000000,2.150000000,2,2,2,1,1.990000000,2.160000000,2,2,1,1,1.980000000,2.170000000,2,2,2,1,MCLN5-MCLU5
2025-06-11T00:00:26.026846021Z,2025-06-11T00:00:26.026373435Z,10,1,42025623,C,A,0,63.710000000,1,130,18657,79329966,63.690000000,63.710000000,3,1,3,1,63.680000000,63.720000000,2,2,2,2,63.670000000,63.730000000,3,2,3,2,63.660000000,63.740000000,3,3,3,3,63.650000000,63.750000000,6,4,6,4,63.640000000,63.760000000,3,5,3,5,63.630000000,63.770000000,5,2,5,2,63.620000000,63.780000000,4,3,4,3,63.610000000,63.790000000,2,1,2,1,63.600000000,63.800000000,6,3,6,3,MCLQ5
2025-06-11T00:00:26.026864674Z,2025-06-11T00:00:26.026378195Z,10,1,42026514,C,A,0,64.790000000,2,130,10806,79329967,64.780000000,64.800000000,5,7,5,7,64.770000000,64.810000000,6,5,5,5,64.760000000,64.820000000,7,9,7,6,64.750000000,64.830000000,8,11,8,11,64.740000000,64.840000000,10,6,9,5,64.730000000,64.850000000,7,9,7,6,64.720000000,64.860000000,8,4,5,3,64.710000000,64.870000000,8,4,7,3,64.700000000,64.880000000,7,4,6,3,64.690000000,64.890000000,4,3,3,2,MCLN5
2025-06-11T00:00:26.027277337Z,2025-06-11T00:00:26.026876491Z,10,1,42026514,C,B,0,64.780000000,1,130,13887,79329996,64.780000000,64.800000000,4,7,4,7,64.770000000,64.810000000,6,5,5,5,64.760000000,64.820000000,7,9,7,6,64.750000000,64.830000000,8,11,8,11,64.740000000,64.840000000,10,6,9,5,64.730000000,64.850000000,7,9,7,6,64.720000000,64.860000000,8,4,5,3,64.710000000,64.870000000,8,4,7,3,64.700000000,64.880000000,7,4,6,3,64.690000000,64.890000000,4,3,3,2,MCLN5
2025-06-11T00:00:26.027359225Z,2025-06-11T00:00:26.027074761Z,10,1,42026514,M,A,1,66.760000000,2,130,11620,79330002,64.780000000,64.800000000,4,7,4,7,64.770000000,64.810000000,6,4,5,4,64.760000000,64.820000000,7,9,7,6,64.750000000,64.830000000,8,11,8,11,64.740000000,64.840000000,10,6,9,5,64.730000000,64.850000000,7,9,7,6,64.720000000,64.860000000,8,4,5,3,64.710000000,64.870000000,8,4,7,3,64.700000000,64.880000000,7,4,6,3,64.690000000,64.890000000,4,3,3,2,MCLN5
2025-06-11T00:00:26.027480140Z,2025-06-11T00:00:26.027302789Z,10,1,42026514,A,A,0,64.790000000,2,130,11305,79330010,64.780000000,64.790000000,4,2,4,1,64.770000000,64.800000000,6,7,5,7,64.760000000,64.810000000,7,4,7,4,64.750000000,64.820000000,8,9,8,6,64.740000000,64.830000000,10,11,9,11,64.730000000,64.840000000,7,6,7,5,64.720000000,64.850000000,8,9,5,6,64.710000000,64.860000000,8,4,7,3,64.700000000,64.870000000,7,4,6,3,64.690000000,64.880000000,4,4,3,3,MCLN5
2025-06-11T00:00:26.027771135Z,2025-06-11T00:00:26.027675925Z,10,1,42026514,M,B,1,62.830000000,2,130,12730,79330019,64.780000000,64.790000000,4,2,4,1,64.770000000,64.800000000,5,7,4,7,64.760000000,64.810000000,7,4,7,4,64.750000000,64.820000000,8,9,8,6,64.740000000,64.830000000,10,11,9,11,64.730000000,64.840000000,7,6,7,5,64.720000000,64.850000000,8,9,5,6,64.710000000,64.860000000,8,4,7,3,64.700000000,64.870000000,7,4,6,3,64.690000000,64.880000000,4,4,3,3,MCLN5
2025-06-11T00:00:26.101139181Z,2025-06-11T00:00:26.101011709Z,10,1,42026514,M,B,1,64.770000000,1,130,16503,79330133,64.780000000,64.790000000,4,2,4,1,64.770000000,64.800000000,6,7,5,7,64.760000000,64.810000000,7,4,7,4,64.750000000,64.820000000,8,9,8,6,64.740000000,64.830000000,10,11,9,11,64.730000000,64.840000000,7,6,7,5,64.720000000,64.850000000,8,9,5,6,64.710000000,64.860000000,8,4,7,3,64.700000000,64.870000000,7,4,6,3,64.690000000,64.880000000,4,4,3,3,MCLN5
2025-06-11T00:00:26.102300013Z,2025-06-11T00:00:26.102171989Z,10,1,42026514,C,A,0,64.790000000,2,130,15583,79330134,64.780000000,64.800000000,4,7,4,7,64.770000000,64.810000000,6,4,5,4,64.760000000,64.820000000,7,9,7,6,64.750000000,64.830000000,8,11,8,11,64.740000000,64.840000000,10,6,9,5,64.730000000,64.850000000,7,9,7,6,64.720000000,64.860000000,8,4,5,3,64.710000000,64.870000000,8,4,7,3,64.700000000,64.880000000,7,4,6,3,64.690000000,64.890000000,4,3,3,2,MCLN5
2025-06-11T00:00:26.102328182Z,2025-06-11T00:00:26.102193955Z,10,1,42025623,C,A,0,63.710000000,1,130,11492,79330137,63.690000000,63.720000000,3,2,3,2,63.680000000,63.730000000,2,2,2,2,63.670000000,63.740000000,3,3,3,3,63.660000000,63.750000000,3,4,3,4,63.650000000,63.760000000,6,5,6,5,63.640000000,63.770000000,3,2,3,2,63.630000000,63.780000000,5,3,5,3,63.620000000,63.790000000,4,1,4,1,63.610000000,63.800000000,2,3,2,3,63.600000000,63.810000000,6,4,6,2,MCLQ5
2025-06-11T00:00:26.102445403Z,2025-06-11T00:00:26.102335107Z,10,1,42025623,M,A,3,63.760000000,1,130,15413,79330139,63.690000000,63.720000000,3,2,3,2,63.680000000,63.730000000,2,2,2,2,63.670000000,63.740000000,3,3,3,3,63.660000000,63.750000000,3,3,3,3,63.650000000,63.760000000,6,6,6,6,63.640000000,63.770000000,3,2,3,2,63.630000000,63.780000000,5,3,5,3,63.620000000,63.790000000,4,1,4,1,63.610000000,63.800000000,2,3,2,3,63.600000000,63.810000000,6,4,6,2,MCLQ5
2025-06-11T00:00:26.102454719Z,2025-06-11T00:00:26.102335625Z,10,1,42025623,M,B,3,63.660000000,1,130,11645,79330140,63.690000000,63.720000000,3,2,3,2,63.680000000,63.730000000,2,2,2,2,63.670000000,63.740000000,3,3,3,3,63.660000000,63.750000000,4,3,4,3,63.650000000,63.760000000,5,6,5,6,63.640000000,63.770000000,3,2,3,2,63.630000000,63.780000000,5,3,5,3,63.620000000,63.790000000,4,1,4,1,63.610000000,63.800000000,2,3,2,3,63.600000000,63.810000000,6,4,6,2,MCLQ5
2025-06-11T00:00:26.102466722Z,2025-06-11T00:00:26.102336105Z,10,1,42025623,M,A,3,63.760000000,1,130,11823,79330141,63.690000000,63.720000000,3,2,3,2,63.680000000,63.730000000,2,2,2,2,63.670000000,63.740000000,3,3,3,3,63.660000000,63.750000000,4,2,4,2,63.650000000,63.760000000,5,7,5,7,63.640000000,63.770000000,3,2,3,2,63.630000000,63.780000000,5,3,5,3,63.620000000,63.790000000,4,1,4,1,63.610000000,63.800000000,2,3,2,3,63.600000000,63.810000000,6,4,6,2,MCLQ5
2025-06-11T00:00:26.102478679Z,2025-06-11T00:00:26.102336643Z,10,1,42025623,M,B,3,63.660000000,1,130,11483,79330142,63.690000000,63.720000000,3,2,3,2,63.680000000,63.730000000,2,2,2,2,63.670000000,63.740000000,3,3,3,3,63.660000000,63.750000000,5,2,5,2,63.650000000,63.760000000,4,7,4,7,63.640000000,63.770000000,3,2,3,2,63.630000000,63.780000000,5,3,5,3,63.620000000,63.790000000,4,1,4,1,63.610000000,63.800000000,2,3,2,3,63.600000000,63.810000000,6,4,6,2,MCLQ5
2025-06-11T00:00:26.102489146Z,2025-06-11T00:00:26.102336821Z,10,1,42025623,C,A,5,63.770000000,1,130,11380,79330143,63.690000000,63.720000000,3,2,3,2,63.680000000,63.730000000,2,2,2,2,63.670000000,63.740000000,3,3,3,3,63.660000000,63.750000000,5,2,5,2,63.650000000,63.760000000,4,7,4,7,63.640000000,63.770000000,3,1,3,1,63.630000000,63.780000000,5,3,5,3,63.620000000,63.790000000,4,1,4,1,63.610000000,63.800000000,2,3,2,3,63.600000000,63.810000000,6,4,6,2,MCLQ5
2025-06-11T00:00:26.112110220Z,2025-06-11T00:00:26.111999729Z,10,1,42026514,M,A,4,66.770000000,2,130,15929,79330145,64.780000000,64.800000000,4,7,4,7,64.770000000,64.810000000,6,4,5,4,64.760000000,64.820000000,7,9,7,6,64.750000000,64.830000000,8,11,8,11,64.740000000,64.840000000,10,5,9,4,64.730000000,64.850000000,7,9,7,6,64.720000000,64.860000000,8,4,5,3,64.710000000,64.870000000,8,4,7,3,64.700000000,64.880000000,7,4,6,3,64.690000000,64.890000000,4,3,3,2,MCLN5
2025-06-11T00:00:26.113721315Z,2025-06-11T00:00:26.113621403Z,10,1,42025623,C,B,6,63.630000000,1,130,15070,79330146,63.690000000,63.720000000,3,2,3,2,63.680000000,63.730000000,2,2,2,2,63.670000000,63.740000000,3,3,3,3,63.660000000,63.750000000,5,2,5,2,63.650000000,63.760000000,4,7,4,7,63.640000000,63.770000000,3,1,3,1,63.630000000,63.780000000,4,3,4,3,63.620000000,63.790000000,4,1,4,1,63.610000000,63.800000000,2,3,2,3,63.600000000,63.810000000,6,4,6,2,MCLQ5
2025-06-11T00:00:26.113731276Z,2025-06-11T00:00:26.113625533Z,10,1,42025623,A,A,6,63.780000000,1,130,11697,79330147,63.690000000,63.720000000,3,2,3,2,63.680000000,63.730000000,2,2,2,2,63.670000000,63.740000000,3,3,3,3,63.660000000,63.750000000,5,2,5,2,63.650000000,63.760000000,4,7,4,7,63.640000000,63.770000000,3,1,3,1,63.630000000,63.780000000,4,4,4,4,63.620000000,63.790000000,4,1,4,1,63.610000000,63.800000000,2,3,2,3,63.600000000,63.810000000,6,4,6,2,MCLQ5
2025-06-11T00:00:26.113844980Z,2025-06-11T00:00:26.113745565Z,10,1,42025623,A,B,5,63.640000000,1,130,14858,79330148,63.690000000,63.720000000,3,2,3,2,63.680000000,63.730000000,2,2,2,2,63.670000000,63.740000000,3,3,3,3,63.660000000,63.750000000,5,2,5,2,63.650000000,63.760000000,4,7,4,7,63.640000000,63.770000000,4,1,4,1,63.630000000,63.780000000,4,4,4,4,63.620000000,63.790000000,4,1,4,1,63.610000000,63.800000000,2,3,2,3,63.600000000,63.810000000,6,4,6,2,MCLQ5
2025-06-11T00:00:26.423912731Z,2025-06-11T00:00:26.423742659Z,10,1,42026514,A,A,0,64.790000000,2,130,16773,79330188,64.780000000,64.790000000,4,2,4,1,64.770000000,64.800000000,6,7,5,7,64.760000000,64.810000000,7,4,7,4,64.750000000,64.820000000,8,9,8,6,64.740000000,64.830000000,10,11,9,11,64.730000000,64.840000000,7,5,7,4,64.720000000,64.850000000,8,9,5,6,64.710000000,64.860000000,8,4,7,3,64.700000000,64.870000000,7,4,6,3,64.690000000,64.880000000,4,4,3,3,MCLN5
2025-06-11T00:00:26.424039206Z,2025-06-11T00:00:26.423934765Z,10,1,42025623,C,B,5,63.640000000,1,130,15257,79330191,63.690000000,63.720000000,3,2,3,2,63.680000000,63.730000000,2,2,2,2,63.670000000,63.740000000,3,3,3,3,63.660000000,63.750000000,5,2,5,2,63.650000000,63.760000000,4,7,4,7,63.640000000,63.770000000,3,1,3,1,63.630000000,63.780000000,4,4,4,4,63.620000000,63.790000000,4,1,4,1,63.610000000,63.800000000,2,3,2,3,63.600000000,63.810000000,6,4,6,2,MCLQ5
2025-06-11T00:00:26.424048498Z,2025-06-11T00:00:26.423936285Z,10,1,42025623,M,B,3,63.650000000,1,130,12102,79330192,63.690000000,63.720000000,3,2,3,2,63.680000000,63.730000000,2,2,2,2,63.670000000,63.740000000,3,3,3,3,63.660000000,63.750000000,4,2,4,2,63.650000000,63.760000000,5,7,5,7,63.640000000,63.770000000,3,1,3,1,63.630000000,63.780000000,4,4,4,4,63.620000000,63.790000000,4,1,4,1,63.610000000,63.800000000,2,3,2,3,63.600000000,63.810000000,6,4,6,2,MCLQ5
2025-06-11T00:00:26.424061031Z,2025-06-11T00:00:26.423936841Z,10,1,42025623,M,A,3,63.750000000,1,130,11760,79330193,63.690000000,63.720000000,3,2,3,2,63.680000000,63.730000000,2,2,2,2,63.670000000,63.740000000,3,3,3,3,63.660000000,63.750000000,4,3,4,3,63.650000000,63.760000000,5,6,5,6,63.640000000,63.770000000,3,1,3,1,63.630000000,63.780000000,4,4,4,4,63.620000000,63.790000000,4,1,4,1,63.610000000,63.800000000,2,3,2,3,63.600000000,63.810000000,6,4,6,2,MCLQ5
2025-06-11T00:00:26.424070877Z,2025-06-11T00:00:26.423937551Z,10,1,42025623,M,B,3,63.650000000,1,130,11521,79330194,63.690000000,63.720000000,3,2,3,2,63.680000000,63.730000000,2,2,2,2,63.670000000,63.740000000,3,3,3,3,63.660000000,63.750000000,3,3,3,3,63.650000000,63.760000000,6,6,6,6,63.640000000,63.770000000,3,1,3,1,63.630000000,63.780000000,4,4,4,4,63.620000000,63.790000000,4,1,4,1,63.610000000,63.800000000,2,3,2,3,63.600000000,63.810000000,6,4,6,2,MCLQ5
2025-06-11T00:00:26.424081045Z,2025-06-11T00:00:26.423937551Z,10,1,42025623,M,A,3,63.750000000,1,130,11430,79330195,63.690000000,63.720000000,3,2,3,2,63.680000000,63.730000000,2,2,2,2,63.670000000,63.740000000,3,3,3,3,63.660000000,63.750000000,3,4,3,4,63.650000000,63.760000000,6,5,6,5,63.640000000,63.770000000,3,1,3,1,63.630000000,63.780000000,4,4,4,4,63.620000000,63.790000000,4,1,4,1,63.610000000,63.800000000,2,3,2,3,63.600000000,63.810000000,6,4,6,2,MCLQ5
2025-06-11T00:00:26.424090990Z,2025-06-11T00:00:26.423941025Z,10,1,42025623,C,A,6,63.780000000,1,130,11508,79330196,63.690000000,63.720000000,3,2,3,2,63.680000000,63.730000000,2,2,2,2,63.670000000,63.740000000,3,3,3,3,63.660000000,63.750000000,3,4,3,4,63.650000000,63.760000000,6,5,6,5,63.640000000,63.770000000,3,1,3,1,63.630000000,63.780000000,4,3,4,3,63.620000000,63.790000000,4,1,4,1,63.610000000,63.800000000,2,3,2,3,63.600000000,63.810000000,6,4,6,2,MCLQ5
2025-06-11T00:00:26.424166181Z,2025-06-11T00:00:26.424058447Z,10,1,42025623,A,B,6,63.630000000,1,130,14914,79330197,63.690000000,63.720000000,3,2,3,2,63.680000000,63.730000000,2,2,2,2,63.670000000,63.740000000,3,3,3,3,63.660000000,63.750000000,3,4,3,4,63.650000000,63.760000000,6,5,6,5,63.640000000,63.770000000,3,1,3,1,63.630000000,63.780000000,5,3,5,3,63.620000000,63.790000000,4,1,4,1,63.610000000,63.800000000,2,3,2,3,63.600000000,63.810000000,6,4,6,2,MCLQ5
2025-06-11T00:00:26.424204832Z,2025-06-11T00:00:26.424112301Z,10,1,42025623,A,A,5,63.770000000,1,130,11636,79330198,63.690000000,63.720000000,3,2,3,2,63.680000000,63.730000000,2,2,2,2,63.670000000,63.740000000,3,3,3,3,63.660000000,63.750000000,3,4,3,4,63.650000000,63.760000000,6,5,6,5,63.640000000,63.770000000,3,2,3,2,63.630000000,63.780000000,5,3,5,3,63.620000000,63.790000000,4,1,4,1,63.610000000,63.800000000,2,3,2,3,63.600000000,63.810000000,6,4,6,2,MCLQ5
2025-06-11T00:00:26.430757148Z,2025-06-11T00:00:26.430649131Z,10,1,42026514,M,A,5,64.840000000,1,130,15542,79330199,64.780000000,64.790000000,4,2,4,1,64.770000000,64.800000000,6,7,5,7,64.760000000,64.810000000,7,4,7,4,64.750000000,64.820000000,8,9,8,6,64.740000000,64.830000000,10,11,9,11,64.730000000,64.840000000,7,6,7,5,64.720000000,64.850000000,8,9,5,6,64.710000000,64.860000000,8,4,7,3,64.700000000,64.870000000,7,4,6,3,64.690000000,64.880000000,4,4,3,3,MCLN5
2025-06-11T00:00:26.436434681Z,2025-06-11T00:00:26.436313785Z,10,1,42026514,C,A,0,64.790000000,2,130,15151,79330200,64.780000000,64.800000000,4,7,4,7,64.770000000,64.810000000,6,4,5,4,64.760000000,64.820000000,7,9,7,6,64.750000000,64.830000000,8,11,8,11,64.740000000,64.840000000,10,6,9,5,64.730000000,64.850000000,7,9,7,6,64.720000000,64.860000000,8,4,5,3,64.710000000,64.870000000,8,4,7,3,64.700000000,64.880000000,7,4,6,3,64.690000000,64.890000000,4,3,3,2,MCLN5
2025-06-11T00:00:26.436555289Z,2025-06-11T00:00:26.436455551Z,10,1,42025623,C,A,5,63.770000000,1,130,15191,79330203,63.690000000,63.720000000,3,2,3,2,63.680000000,63.730000000,2,2,2,2,63.670000000,63.740000000,3,3,3,3,63.660000000,63.750000000,3,4,3,4,63.650000000,63.760000000,6,5,6,5,63.640000000,63.770000000,3,1,3,1,63.630000000,63.780000000,5,3,5,3,63.620000000,63.790000000,4,1,4,1,63.610000000,63.800000000,2,3,2,3,63.600000000,63.810000000,6,4,6,2,MCLQ5
2025-06-11T00:00:26.436565587Z,2025-06-11T00:00:26.436459715Z,10,1,42025623,C,B,6,63.630000000,1,130,11575,79330204,63.690000000,63.720000000,3,2,3,2,63.680000000,63.730000000,2,2,2,2,63.670000000,63.740000000,3,3,3,3,63.660000000,63.750000000,3,4,3,4,63.650000000,63.760000000,6,5,6,5,63.640000000,63.770000000,3,1,3,1,63.630000000,63.780000000,4,3,4,3,63.620000000,63.790000000,4,1,4,1,63.610000000,63.800000000,2,3,2,3,63.600000000,63.810000000,6,4,6,2,MCLQ5
2025-06-11T00:00:26.436671995Z,2025-06-11T00:00:26.436572243Z,10,1,42025623,A,A,6,63.780000000,1,130,15181,79330205,63.690000000,63.720000000,3,2,3,2,63.680000000,63.730000000,2,2,2,2,63.670000000,63.740000000,3,3,3,3,63.660000000,63.750000000,3,4,3,4,63.650000000,63.760000000,6,5,6,5,63.640000000,63.770000000,3,1,3,1,63.630000000,63.780000000,4,4,4,4,63.620000000,63.790000000,4,1,4,1,63.610000000,63.800000000,2,3,2,3,63.600000000,63.810000000,6,4,6,2,MCLQ5
2025-06-11T00:00:26.436680727Z,2025-06-11T00:00:26.436580423Z,10,1,42025623,A,B,5,63.640000000,1,130,11549,79330206,63.690000000,63.720000000,3,2,3,2,63.680000000,63.730000000,2,2,2,2,63.670000000,63.740000000,3,3,3,3,63.660000000,63.750000000,3,4,3,4,63.650000000,63.760000000,6,5,6,5,63.640000000,63.770000000,4,1,4,1,63.630000000,63.780000000,4,4,4,4,63.620000000,63.790000000,4,1,4,1,63.610000000,63.800000000,2,3,2,3,63.600000000,63.810000000,6,4,6,2,MCLQ5
2025-06-11T00:00:26.450184981Z,2025-06-11T00:00:26.450063907Z,10,1,42026514,M,A,4,66.770000000,2,130,16846,79330207,64.780000000,64.800000000,4,7,4,7,64.770000000,64.810000000,6,4,5,4,64.760000000,64.820000000,7,9,7,6,64.750000000,64.830000000,8,11,8,11,64.740000000,64.840000000,10,5,9,4,64.730000000,64.850000000,7,9,7,6,64.720000000,64.860000000,8,4,5,3,64.710000000,64.870000000,8,4,7,3,64.700000000,64.880000000,7,4,6,3,64.690000000,64.890000000,4,3,3,2,MCLN5
2025-06-11T00:00:26.725897015Z,2025-06-11T00:00:26.725753197Z,10,1,42026514,A,A,0,64.790000000,2,130,16205,79330238,64.780000000,64.790000000,4,2,4,1,64.770000000,64.800000000,6,7,5,7,64.760000000,64.810000000,7,4,7,4,64.750000000,64.820000000,8,9,8,6,64.740000000,64.830000000,10,11,9,11,64.730000000,64.840000000,7,5,7,4,64.720000000,64.850000000,8,9,5,6,64.710000000,64.860000000,8,4,7,3,64.700000000,64.870000000,7,4,6,3,64.690000000,64.880000000,4,4,3,3,MCLN5
2025-06-11T00:00:26.726014252Z,2025-06-11T00:00:26.725918521Z,10,1,42025623,C,B,5,63.640000000,1,130,14856,79330241,63.690000000,63.720000000,3,2,3,2,63.680000000,63.730000000,2,2,2,2,63.670000000,63.740000000,3,3,3,3,63.660000000,63.750000000,3,4,3,4,63.650000000,63.760000000,6,5,6,5,63.640000000,63.770000000,3,1,3,1,63.630000000,63.780000000,4,4,4,4,63.620000000,63.790000000,4,1,4,1,63.610000000,63.800000000,2,3,2,3,63.600000000,63.810000000,6,4,6,2,MCLQ5
2025-06-11T00:00:26.726022615Z,2025-06-11T00:00:26.725924107Z,10,1,42025623,C,A,6,63.780000000,1,130,11655,79330242,63.690000000,63.720000000,3,2,3,2,63.680000000,63.730000000,2,2,2,2,63.670000000,63.740000000,3,3,3,3,63.660000000,63.750000000,3,4,3,4,63.650000000,63.760000000,6,5,6,5,63.640000000,63.770000000,3,1,3,1,63.630000000,63.780000000,4,3,4,3,63.620000000,63.790000000,4,1,4,1,63.610000000,63.800000000,2,3,2,3,63.600000000,63.810000000,6,4,6,2,MCLQ5
2025-06-11T00:00:26.726135306Z,2025-06-11T00:00:26.726036921Z,10,1,42025623,A,B,6,63.630000000,1,130,15332,79330243,63.690000000,63.720000000,3,2,3,2,63.680000000,63.730000000,2,2,2,2,63.670000000,63.740000000,3,3,3,3,63.660000000,63.750000000,3,4,3,4,63.650000000,63.760000000,6,5,6,5,63.640000000,63.770000000,3,1,3,1,63.630000000,63.780000000,5,3,5,3,63.620000000,63.790000000,4,1,4,1,63.610000000,63.800000000,2,3,2,3,63.600000000,63.810000000,6,4,6,2,MCLQ5
2025-06-11T00:00:26.726143692Z,2025-06-11T00:00:26.726047633Z,10,1,42025623,A,A,5,63.770000000,1,130,11557,79330244,63.690000000,63.720000000,3,2,3,2,63.680000000,63.730000000,2,2,2,2,63.670000000,63.740000000,3,3,3,3,63.660000000,63.750000000,3,4,3,4,63.650000000,63.760000000,6,5,6,5,63.640000000,63.770000000,3,2,3,2,63.630000000,63.780000000,5,3,5,3,63.620000000,63.790000000,4,1,4,1,63.610000000,63.800000000,2,3,2,3,63.600000000,63.810000000,6,4,6,2,MCLQ5
2025-06-11T00:00:26.729129841Z,2025-06-11T00:00:26.729022427Z,10,1,42026514,M,A,5,64.840000000,1,130,15170,79330245,64.780000000,64.790000000,4,2,4,1,64.770000000,64.800000000,6,7,5,7,64.760000000,64.810000000,7,4,7,4,64.750000000,64.820000000,8,9,8,6,64.740000000,64.830000000,10,11,9,11,64.730000000,64.840000000,7,6,7,5,64.720000000,64.850000000,8,9,5,6,64.710000000,64.860000000,8,4,7,3,64.700000000,64.870000000,7,4,6,3,64.690000000,64.880000000,4,4,3,3,MCLN5
2025-06-11T00:00:26.742624488Z,2025-06-11T00:00:26.742500941Z,10,1,42026514,C,A,0,64.790000000,2,130,15686,79330246,64.780000000,64.800000000,4,7,4,7,64.770000000,64.810000000,6,4,5,4,64.760000000,64.820000000,7,9,7,6,64.750000000,64.830000000,8,11,8,11,64.740000000,64.840000000,10,6,9,5,64.730000000,64.850000000,7,9,7,6,64.720000000,64.860000000,8,4,5,3,64.710000000,64.870000000,8,4,7,3,64.700000000,64.880000000,7,4,6,3,64.690000000,64.890000000,4,3,3,2,MCLN5
2025-06-11T00:00:26.742750172Z,2025-06-11T00:00:26.742644475Z,10,1,42025623,M,A,3,63.760000000,1,130,15622,79330249,63.690000000,63.720000000,3,2,3,2,63.680000000,63.730000000,2,2,2,2,63.670000000,63.740000000,3,3,3,3,63.660000000,63.750000000,3,3,3,3,63.650000000,63.760000000,6,6,6,6,63.640000000,63.770000000,3,2,3,2,63.630000000,63.780000000,5,3,5,3,63.620000000,63.790000000,4,1,4,1,63.610000000,63.800000000,2,3,2,3,63.600000000,63.810000000,6,4,6,2,MCLQ5
2025-06-11T00:00:26.742758789Z,2025-06-11T00:00:26.742644935Z,10,1,42025623,M,B,3,63.660000000,1,130,11759,79330250,63.690000000,63.720000000,3,2,3,2,63.680000000,63.730000000,2,2,2,2,63.670000000,63.740000000,3,3,3,3,63.660000000,63.750000000,4,3,4,3,63.650000000,63.760000000,5,6,5,6,63.640000000,63.770000000,3,2,3,2,63.630000000,63.780000000,5,3,5,3,63.620000000,63.790000000,4,1,4,1,63.610000000,63.800000000,2,3,2,3,63.600000000,63.810000000,6,4,6,2,MCLQ5
2025-06-11T00:00:26.742767359Z,2025-06-11T00:00:26.742645415Z,10,1,42025623,M,A,3,63.760000000,1,130,12122,79330251,63.690000000,63.720000000,3,2,3,2,63.680000000,63.730000000,2,2,2,2,63.670000000,63.740000000,3,3,3,3,63.660000000,63.750000000,4,2,4,2,63.650000000,63.760000000,5,7,5,7,63.640000000,63.770000000,3,2,3,2,63.630000000,63.780000000,5,3,5,3,63.620000000,63.790000000,4,1,4,1,63.610000000,63.800000000,2,3,2,3,63.600000000,63.810000000,6,4,6,2,MCLQ5
2025-06-11T00:00:26.742777204Z,2025-06-11T00:00:26.742645595Z,10,1,42025623,C,A,5,63.770000000,1,130,11658,79330252,63.690000000,63.720000000,3,2,3,2,63.680000000,63.730000000,2,2,2,2,63.670000000,63.740000000,3,3,3,3,63.660000000,63.750000000,4,2,4,2,63.650000000,63.760000000,5,7,5,7,63.640000000,63.770000000,3,1,3,1,63.630000000,63.780000000,5,3,5,3,63.620000000,63.790000000,4,1,4,1,63.610000000,63.800000000,2,3,2,3,63.600000000,63.810000000,6,4,6,2,MCLQ5
2025-06-11T00:00:26.742788716Z,2025-06-11T00:00:26.742645991Z,10,1,42025623,M,B,3,63.660000000,1,130,11649,79330253,63.690000000,63.720000000,3,2,3,2,63.680000000,63.730000000,2,2,2,2,63.670000000,63.740000000,3,3,3,3,63.660000000,63.750000000,5,2,5,2,63.650000000,63.760000000,4,7,4,7,63.640000000,63.770000000,3,1,3,1,63.630000000,63.780000000,5,3,5,3,63.620000000,63.790000000,4,1,4,1,63.610000000,63.800000000,2,3,2,3,63.600000000,63.810000000,6,4,6,2,MCLQ5
2025-06-11T00:00:26.742799398Z,2025-06-11T00:00:26.742650291Z,10,1,42025623,C,B,6,63.630000000,1,130,11379,79330254,63.690000000,63.720000000,3,2,3,2,63.680000000,63.730000000,2,2,2,2,63.670000000,63.740000000,3,3,3,3,63.660000000,63.750000000,5,2,5,2,63.650000000,63.760000000,4,7,4,7,63.640000000,63.770000000,3,1,3,1,63.630000000,63.780000000,4,3,4,3,63.620000000,63.790000000,4,1,4,1,63.610000000,63.800000000,2,3,2,3,63.600000000,63.810000000,6,4,6,2,MCLQ5
2025-06-11T00:00:26.742899579Z,2025-06-11T00:00:26.742795533Z,10,1,42025623,A,A,6,63.780000000,1,130,14948,79330255,63.690000000,63.720000000,3,2,3,2,63.680000000,63.730000000,2,2,2,2,63.670000000,63.740000000,3,3,3,3,63.660000000,63.750000000,5,2,5,2,63.650000000,63.760000000,4,7,4,7,63.640000000,63.770000000,3,1,3,1,63.630000000,63.780000000,4,4,4,4,63.620000000,63.790000000,4,1,4,1,63.610000000,63.800000000,2,3,2,3,63.600000000,63.810000000,6,4,6,2,MCLQ5
2025-06-11T00:00:26.742907573Z,2025-06-11T00:00:26.742815461Z,10,1,42025623,A,B,5,63.640000000,1,130,11455,79330256,63.690000000,63.720000000,3,2,3,2,63.680000000,63.730000000,2,2,2,2,63.670000000,63.740000000,3,3,3,3,63.660000000,63.750000000,5,2,5,2,63.650000000,63.760000000,4,7,4,7,63.640000000,63.770000000,4,1,4,1,63.630000000,63.780000000,4,4,4,4,63.620000000,63.790000000,4,1,4,1,63.610000000,63.800000000,2,3,2,3,63.600000000,63.810000000,6,4,6,2,MCLQ5
2025-06-11T00:00:26.747663662Z,2025-06-11T00:00:26.747556213Z,10,1,42026514,M,A,4,66.770000000,2,130,15885,79330257,64.780000000,64.800000000,4,7,4,7,64.770000000,64.810000000,6,4,5,4,64.760000000,64.820000000,7,9,7,6,64.750000000,64.830000000,8,11,8,11,64.740000000,64.840000000,10,5,9,4,64.730000000,64.850000000,7,9,7,6,64.720000000,64.860000000,8,4,5,3,64.710000000,64.870000000,8,4,7,3,64.700000000,64.880000000,7,4,6,3,64.690000000,64.890000000,4,3,3,2,MCLN5
2025-06-11T00:00:26.887582543Z,2025-06-11T00:00:26.887471753Z,10,1,42025611,M,A,1,2.120000000,20,130,11339,79330264,2.070000000,2.080000000,3,6,2,3,2.060000000,2.090000000,27,7,5,5,2.050000000,2.100000000,23,27,3,6,2.040000000,2.110000000,23,22,3,3,2.030000000,2.120000000,2,22,1,2,2.020000000,2.130000000,2,2,2,2,2.010000000,2.140000000,2,2,1,1,2.000000000,2.150000000,2,2,2,1,1.990000000,2.160000000,2,2,1,1,1.980000000,2.170000000,2,2,2,1,MCLN5-MCLU5
2025-06-11T00:00:26.935645887Z,2025-06-11T00:00:26.935435109Z,10,1,42026514,A,A,0,64.790000000,2,130,15844,79330265,64.780000000,64.790000000,4,2,4,1,64.770000000,64.800000000,6,7,5,7,64.760000000,64.810000000,7,4,7,4,64.750000000,64.820000000,8,9,8,6,64.740000000,64.830000000,10,11,9,11,64.730000000,64.840000000,7,5,7,4,64.720000000,64.850000000,8,9,5,6,64.710000000,64.860000000,8,4,7,3,64.700000000,64.870000000,7,4,6,3,64.690000000,64.880000000,4,4,3,3,MCLN5
2025-06-11T00:00:26.935792882Z,2025-06-11T00:00:26.935666267Z,10,1,42025623,C,B,5,63.640000000,1,130,15668,79330268,63.690000000,63.720000000,3,2,3,2,63.680000000,63.730000000,2,2,2,2,63.670000000,63.740000000,3,3,3,3,63.660000000,63.750000000,5,2,5,2,63.650000000,63.760000000,4,7,4,7,63.640000000,63.770000000,3,1,3,1,63.630000000,63.780000000,4,4,4,4,63.620000000,63.790000000,4,1,4,1,63.610000000,63.800000000,2,3,2,3,63.600000000,63.810000000,6,4,6,2,MCLQ5
2025-06-11T00:00:26.935801076Z,2025-06-11T00:00:26.935671471Z,10,1,42025623,C,A,6,63.780000000,1,130,11685,79330269,63.690000000,63.720000000,3,2,3,2,63.680000000,63.730000000,2,2,2,2,63.670000000,63.740000000,3,3,3,3,63.660000000,63.750000000,5,2,5,2,63.650000000,63.760000000,4,7,4,7,63.640000000,63.770000000,3,1,3,1,63.630000000,63.780000000,4,3,4,3,63.620000000,63.790000000,4,1,4,1,63.610000000,63.800000000,2,3,2,3,63.600000000,63.810000000,6,4,6,2,MCLQ5
2025-06-11T00:00:26.935916855Z,2025-06-11T00:00:26.935802945Z,10,1,42026514,M,B,1,62.830000000,2,130,15720,79330270,64.780000000,64.790000000,4,2,4,1,64.770000000,64.800000000,5,7,4,7,64.760000000,64.810000000,7,4,7,4,64.750000000,64.820000000,8,9,8,6,64.740000000,64.830000000,10,11,9,11,64.730000000,64.840000000,7,5,7,4,64.720000000,64.850000000,8,9,5,6,64.710000000,64.860000000,8,4,7,3,64.700000000,64.870000000,7,4,6,3,64.690000000,64.880000000,4,4,3,3,MCLN5
2025-06-11T00:00:26.935924872Z,2025-06-11T00:00:26.935814947Z,10,1,42025623,A,B,6,63.630000000,1,130,11663,79330271,63.690000000,63.720000000,3,2,3,2,63.680000000,63.730000000,2,2,2,2,63.670000000,63.740000000,3,3,3,3,63.660000000,63.750000000,5,2,5,2,63.650000000,63.760000000,4,7,4,7,63.640000000,63.770000000,3,1,3,1,63.630000000,63.780000000,5,3,5,3,63.620000000,63.790000000,4,1,4,1,63.610000000,63.800000000,2,3,2,3,63.600000000,63.810000000,6,4,6,2,MCLQ5
2025-06-11T00:00:26.935933973Z,2025-06-11T00:00:26.935830537Z,10,1,42025623,A,A,5,63.770000000,1,130,11368,79330272,63.690000000,63.720000000,3,2,3,2,63.680000000,63.730000000,2,2,2,2,63.670000000,63.740000000,3,3,3,3,63.660000000,63.750000000,5,2,5,2,63.650000000,63.760000000,4,7,4,7,63.640000000,63.770000000,3,2,3,2,63.630000000,63.780000000,5,3,5,3,63.620000000,63.790000000,4,1,4,1,63.610000000,63.800000000,2,3,2,3,63.600000000,63.810000000,6,4,6,2,MCLQ5
2025-06-11T00:00:26.936168162Z,2025-06-11T00:00:26.936048965Z,10,1,42026514,M,B,1,64.770000000,1,130,15378,79330273,64.780000000,64.790000000,4,2,4,1,64.770000000,64.800000000,6,7,5,7,64.760000000,64.810000000,7,4,7,4,64.750000000,64.820000000,8,9,8,6,64.740000000,64.830000000,10,11,9,11,64.730000000,64.840000000,7,5,7,4,64.720000000,64.850000000,8,9,5,6,64.710000000,64.860000000,8,4,7,3,64.700000000,64.870000000,7,4,6,3,64.690000000,64.880000000,4,4,3,3,MCLN5
2025-06-11T00:00:26.946481068Z,2025-06-11T00:00:26.946347351Z,10,1,42026514,M,A,5,64.840000000,1,130,16084,79330274,64.780000000,64.790000000,4,2,4,1,64.770000000,64.800000000,6,7,5,7,64.760000000,64.810000000,7,4,7,4,64.750000000,64.820000000,8,9,8,6,64.740000000,64.830000000,10,11,9,11,64.730000000,64.840000000,7,6,7,5,64.720000000,64.850000000,8,9,5,6,64.710000000,64.860000000,8,4,7,3,64.700000000,64.870000000,7,4,6,3,64.690000000,64.880000000,4,4,3,3,MCLN5
2025-06-11T00:00:27.285735342Z,2025-06-11T00:00:27.285628603Z,10,1,42025623,M,B,3,63.650000000,1,130,14779,79330298,63.690000000,63.720000000,3,2,3,2,63.680000000,63.730000000,2,2,2,2,63.670000000,63.740000000,3,3,3,3,63.660000000,63.750000000,4,2,4,2,63.650000000,63.760000000,5,7,5,7,63.640000000,63.770000000,3,2,3,2,63.630000000,63.780000000,5,3,5,3,63.620000000,63.790000000,4,1,4,1,63.610000000,63.800000000,2,3,2,3,63.600000000,63.810000000,6,4,6,2,MCLQ5
2025-06-11T00:00:27.285762374Z,2025-06-11T00:00:27.285629083Z,10,1,42025623,M,A,3,63.750000000,1,130,10983,79330299,63.690000000,63.720000000,3,2,3,2,63.680000000,63.730000000,2,2,2,2,63.670000000,63.740000000,3,3,3,3,63.660000000,63.750000000,4,3,4,3,63.650000000,63.760000000,5,6,5,6,63.640000000,63.770000000,3,2,3,2,63.630000000,63.780000000,5,3,5,3,63.620000000,63.790000000,4,1,4,1,63.610000000,63.800000000,2,3,2,3,63.600000000,63.810000000,6,4,6,2,MCLQ5
2025-06-11T00:00:27.285774008Z,2025-06-11T00:00:27.285629697Z,10,1,42025623,M,B,3,63.650000000,1,130,11357,79330300,63.690000000,63.720000000,3,2,3,2,63.680000000,63.730000000,2,2,2,2,63.670000000,63.740000000,3,3,3,3,63.660000000,63.750000000,3,3,3,3,63.650000000,63.760000000,6,6,6,6,63.640000000,63.770000000,3,2,3,2,63.630000000,63.780000000,5,3,5,3,63.620000000,63.790000000,4,1,4,1,63.610000000,63.800000000,2,3,2,3,63.600000000,63.810000000,6,4,6,2,MCLQ5
2025-06-11T00:00:27.285785128Z,2025-06-11T00:00:27.285630291Z,10,1,42025623,M,A,3,63.750000000,1,130,11366,79330301,63.690000000,63.720000000,3,2,3,2,63.680000000,63.730000000,2,2,2,2,63.670000000,63.740000000,3,3,3,3,63.660000000,63.750000000,3,4,3,4,63.650000000,63.760000000,6,5,6,5,63.640000000,63.770000000,3,2,3,2,63.630000000,63.780000000,5,3,5,3,63.620000000,63.790000000,4,1,4,1,63.610000000,63.800000000,2,3,2,3,63.600000000,63.810000000,6,4,6,2,MCLQ5
2025-06-11T00:00:28.983669429Z,2025-06-11T00:00:28.983527553Z,10,1,42026514,C,A,0,64.790000000,2,130,18783,79330373,64.780000000,64.800000000,4,7,4,7,64.770000000,64.810000000,6,4,5,4,64.760000000,64.820000000,7,9,7,6,64.750000000,64.830000000,8,11,8,11,64.740000000,64.840000000,10,6,9,5,64.730000000,64.850000000,7,9,7,6,64.720000000,64.860000000,8,4,5,3,64.710000000,64.870000000,8,4,7,3,64.700000000,64.880000000,7,4,6,3,64.690000000,64.890000000,4,3,3,2,MCLN5
2025-06-11T00:00:28.983808334Z,2025-06-11T00:00:28.983693935Z,10,1,42025623,C,A,5,63.770000000,1,130,15003,79330376,63.690000000,63.720000000,3,2,3,2,63.680000000,63.730000000,2,2,2,2,63.670000000,63.740000000,3,3,3,3,63.660000000,63.750000000,3,4,3,4,63.650000000,63.760000000,6,5,6,5,63.640000000,63.770000000,3,1,3,1,63.630000000,63.780000000,5,3,5,3,63.620000000,63.790000000,4,1,4,1,63.610000000,63.800000000,2,3,2,3,63.600000000,63.810000000,6,4,6,2,MCLQ5
2025-06-11T00:00:28.983816736Z,2025-06-11T00:00:28.983695355Z,10,1,42025623,M,A,3,63.760000000,1,130,11796,79330377,63.690000000,63.720000000,3,2,3,2,63.680000000,63.730000000,2,2,2,2,63.670000000,63.740000000,3,3,3,3,63.660000000,63.750000000,3,3,3,3,63.650000000,63.760000000,6,6,6,6,63.640000000,63.770000000,3,1,3,1,63.630000000,63.780000000,5,3,5,3,63.620000000,63.790000000,4,1,4,1,63.610000000,63.800000000,2,3,2,3,63.600000000,63.810000000,6,4,6,2,MCLQ5
2025-06-11T00:00:28.983825084Z,2025-06-11T00:00:28.983695855Z,10,1,42025623,M,B,3,63.660000000,1,130,11478,79330378,63.690000000,63.720000000,3,2,3,2,63.680000000,63.730000000,2,2,2,2,63.670000000,63.740000000,3,3,3,3,63.660000000,63.750000000,4,3,4,3,63.650000000,63.760000000,5,6,5,6,63.640000000,63.770000000,3,1,3,1,63.630000000,63.780000000,5,3,5,3,63.620000000,63.790000000,4,1,4,1,63.610000000,63.800000000,2,3,2,3,63.600000000,63.810000000,6,4,6,2,MCLQ5
2025-06-11T00:00:28.983835382Z,2025-06-11T00:00:28.983696373Z,10,1,42025623,M,A,3,63.760000000,1,130,11777,79330379,63.690000000,63.720000000,3,2,3,2,63.680000000,63.730000000,2,2,2,2,63.670000000,63.740000000,3,3,3,3,63.660000000,63.750000000,4,2,4,2,63.650000000,63.760000000,5,7,5,7,63.640000000,63.770000000,3,1,3,1,63.630000000,63.780000000,5,3,5,3,63.620000000,63.790000000,4,1,4,1,63.610000000,63.800000000,2,3,2,3,63.600000000,63.810000000,6,4,6,2,MCLQ5
2025-06-11T00:00:28.983847116Z,2025-06-11T00:00:28.983696929Z,10,1,42025623,M,B,3,63.660000000,1,130,12134,79330380,63.690000000,63.720000000,3,2,3,2,63.680000000,63.730000000,2,2,2,2,63.670000000,63.740000000,3,3,3,3,63.660000000,63.750000000,5,2,5,2,63.650000000,63.760000000,4,7,4,7,63.640000000,63.770000000,3,1,3,1,63.630000000,63.780000000,5,3,5,3,63.620000000,63.790000000,4,1,4,1,63.610000000,63.800000000,2,3,2,3,63.600000000,63.810000000,6,4,6,2,MCLQ5
2025-06-11T00:00:28.983857069Z,2025-06-11T00:00:28.983700847Z,10,1,42025623,C,B,6,63.630000000,1,130,11364,79330381,63.690000000,63.720000000,3,2,3,2,63.680000000,63.730000000,2,2,2,2,63.670000000,63.740000000,3,3,3,3,63.660000000,63.750000000,5,2,5,2,63.650000000,63.760000000,4,7,4,7,63.640000000,63.770000000,3,1,3,1,63.630000000,63.780000000,4,3,4,3,63.620000000,63.790000000,4,1,4,1,63.610000000,63.800000000,2,3,2,3,63.600000000,63.810000000,6,4,6,2,MCLQ5
2025-06-11T00:00:28.983938849Z,2025-06-11T00:00:28.983836929Z,10,1,42025623,A,A,6,63.780000000,1,130,14685,79330382,63.690000000,63.720000000,3,2,3,2,63.680000000,63.730000000,2,2,2,2,63.670000000,63.740000000,3,3,3,3,63.660000000,63.750000000,5,2,5,2,63.650000000,63.760000000,4,7,4,7,63.640000000,63.770000000,3,1,3,1,63.630000000,63.780000000,4,4,4,4,63.620000000,63.790000000,4,1,4,1,63.610000000,63.800000000,2,3,2,3,63.600000000,63.810000000,6,4,6,2,MCLQ5
2025-06-11T00:00:28.983974874Z,2025-06-11T00:00:28.983883717Z,10,1,42025623,A,B,5,63.640000000,1,130,11325,79330383,63.690000000,63.720000000,3,2,3,2,63.680000000,63.730000000,2,2,2,2,63.670000000,63.740000000,3,3,3,3,63.660000000,63.750000000,5,2,5,2,63.650000000,63.760000000,4,7,4,7,63.640000000,63.770000000,4,1,4,1,63.630000000,63.780000000,4,4,4,4,63.620000000,63.790000000,4,1,4,1,63.610000000,63.800000000,2,3,2,3,63.600000000,63.810000000,6,4,6,2,MCLQ5
2025-06-11T00:00:28.994779175Z,2025-06-11T00:00:28.994656341Z,10,1,42026514,M,A,4,66.770000000,2,130,15155,79330384,64.780000000,64.800000000,4,7,4,7,64.770000000,64.810000000,6,4,5,4,64.760000000,64.820000000,7,9,7,6,64.750000000,64.830000000,8,11,8,11,64.740000000,64.840000000,10,5,9,4,64.730000000,64.850000000,7,9,7,6,64.720000000,64.860000000,8,4,5,3,64.710000000,64.870000000,8,4,7,3,64.700000000,64.880000000,7,4,6,3,64.690000000,64.890000000,4,3,3,2,MCLN5
2025-06-11T00:00:29.091485360Z,2025-06-11T00:00:29.091307747Z,10,1,42026514,A,A,0,64.790000000,2,130,14978,79330385,64.780000000,64.790000000,4,2,4,1,64.770000000,64.800000000,6,7,5,7,64.760000000,64.810000000,7,4,7,4,64.750000000,64.820000000,8,9,8,6,64.740000000,64.830000000,10,11,9,11,64.730000000,64.840000000,7,5,7,4,64.720000000,64.850000000,8,9,5,6,64.710000000,64.860000000,8,4,7,3,64.700000000,64.870000000,7,4,6,3,64.690000000,64.880000000,4,4,3,3,MCLN5
2025-06-11T00:00:29.091607236Z,2025-06-11T00:00:29.091506305Z,10,1,42025623,C,B,5,63.640000000,1,130,15060,79330388,63.690000000,63.720000000,3,2,3,2,63.680000000,63.730000000,2,2,2,2,63.670000000,63.740000000,3,3,3,3,63.660000000,63.750000000,5,2,5,2,63.650000000,63.760000000,4,7,4,7,63.640000000,63.770000000,3,1,3,1,63.630000000,63.780000000,4,4,4,4,63.620000000,63.790000000,4,1,4,1,63.610000000,63.800000000,2,3,2,3,63.600000000,63.810000000,6,4,6,2,MCLQ5
2025-06-11T00:00:29.091615238Z,2025-06-11T00:00:29.091511393Z,10,1,42025623,C,A,6,63.780000000,1,130,11383,79330389,63.690000000,63.720000000,3,2,3,2,63.680000000,63.730000000,2,2,2,2,63.670000000,63.740000000,3,3,3,3,63.660000000,63.750000000,5,2,5,2,63.650000000,63.760000000,4,7,4,7,63.640000000,63.770000000,3,1,3,1,63.630000000,63.780000000,4,3,4,3,63.620000000,63.790000000,4,1,4,1,63.610000000,63.800000000,2,3,2,3,63.600000000,63.810000000,6,4,6,2,MCLQ5
2025-06-11T00:00:29.091744792Z,2025-06-11T00:00:29.091645497Z,10,1,42025623,A,B,6,63.630000000,1,130,15244,79330390,63.690000000,63.720000000,3,2,3,2,63.680000000,63.730000000,2,2,2,2,63.670000000,63.740000000,3,3,3,3,63.660000000,63.750000000,5,2,5,2,63.650000000,63.760000000,4,7,4,7,63.640000000,63.770000000,3,1,3,1,63.630000000,63.780000000,5,3,5,3,63.620000000,63.790000000,4,1,4,1,63.610000000,63.800000000,2,3,2,3,63.600000000,63.810000000,6,4,6,2,MCLQ5
2025-06-11T00:00:29.091754438Z,2025-06-11T00:00:29.091655539Z,10,1,42025623,A,A,5,63.770000000,1,130,12408,79330391,63.690000000,63.720000000,3,2,3,2,63.680000000,63.730000000,2,2,2,2,63.670000000,63.740000000,3,3,3,3,63.660000000,63.750000000,5,2,5,2,63.650000000,63.760000000,4,7,4,7,63.640000000,63.770000000,3,2,3,2,63.630000000,63.780000000,5,3,5,3,63.620000000,63.790000000,4,1,4,1,63.610000000,63.800000000,2,3,2,3,63.600000000,63.810000000,6,4,6,2,MCLQ5
2025-06-11T00:00:29.091767393Z,2025-06-11T00:00:29.091664793Z,10,1,42026514,M,B,1,62.840000000,2,130,12796,79330392,64.780000000,64.790000000,4,2,4,1,64.770000000,64.800000000,5,7,4,7,64.760000000,64.810000000,7,4,7,4,64.750000000,64.820000000,8,9,8,6,64.740000000,64.830000000,10,11,9,11,64.730000000,64.840000000,7,5,7,4,64.720000000,64.850000000,8,9,5,6,64.710000000,64.860000000,8,4,7,3,64.700000000,64.870000000,7,4,6,3,64.690000000,64.880000000,4,4,3,3,MCLN5
2025-06-11T00:00:29.094413828Z,2025-06-11T00:00:29.094307769Z,10,1,42026514,M,A,5,64.840000000,1,130,14122,79330393,64.780000000,64.790000000,4,2,4,1,64.770000000,64.800000000,5,7,4,7,64.760000000,64.810000000,7,4,7,4,64.750000000,64.820000000,8,9,8,6,64.740000000,64.830000000,10,11,9,11,64.730000000,64.840000000,7,6,7,5,64.720000000,64.850000000,8,9,5,6,64.710000000,64.860000000,8,4,7,3,64.700000000,64.870000000,7,4,6,3,64.690000000,64.880000000,4,4,3,3,MCLN5
2025-06-11T00:00:29.209426137Z,2025-06-11T00:00:29.209271073Z,10,1,42026514,C,A,0,64.790000000,2,130,14564,79330403,64.780000000,64.800000000,4,7,4,7,64.770000000,64.810000000,5,4,4,4,64.760000000,64.820000000,7,9,7,6,64.750000000,64.830000000,8,11,8,11,64.740000000,64.840000000,10,6,9,5,64.730000000,64.850000000,7,9,7,6,64.720000000,64.860000000,8,4,5,3,64.710000000,64.870000000,8,4,7,3,64.700000000,64.880000000,7,4,6,3,64.690000000,64.890000000,4,3,3,2,MCLN5
2025-06-11T00:00:29.209538428Z,2025-06-11T00:00:29.209446535Z,10,1,42025623,C,A,5,63.770000000,1,130,14642,79330407,63.690000000,63.720000000,3,2,3,2,63.680000000,63.730000000,2,2,2,2,63.670000000,63.740000000,3,3,3,3,63.660000000,63.750000000,5,2,5,2,63.650000000,63.760000000,4,7,4,7,63.640000000,63.770000000,3,1,3,1,63.630000000,63.780000000,5,3,5,3,63.620000000,63.790000000,4,1,4,1,63.610000000,63.800000000,2,3,2,3,63.600000000,63.810000000,6,4,6,2,MCLQ5
2025-06-11T00:00:29.209548427Z,2025-06-11T00:00:29.209451545Z,10,1,42025623,C,B,6,63.630000000,1,130,12586,79330408,63.690000000,63.720000000,3,2,3,2,63.680000000,63.730000000,2,2,2,2,63.670000000,63.740000000,3,3,3,3,63.660000000,63.750000000,5,2,5,2,63.650000000,63.760000000,4,7,4,7,63.640000000,63.770000000,3,1,3,1,63.630000000,63.780000000,4,3,4,3,63.620000000,63.790000000,4,1,4,1,63.610000000,63.800000000,2,3,2,3,63.600000000,63.810000000,6,4,6,2,MCLQ5
2025-06-11T00:00:29.209660595Z,2025-06-11T00:00:29.209565091Z,10,1,42025623,A,A,6,63.780000000,1,130,15297,79330409,63.690000000,63.720000000,3,2,3,2,63.680000000,63.730000000,2,2,2,2,63.670000000,63.740000000,3,3,3,3,63.660000000,63.750000000,5,2,5,2,63.650000000,63.760000000,4,7,4,7,63.640000000,63.770000000,3,1,3,1,63.630000000,63.780000000,4,4,4,4,63.620000000,63.790000000,4,1,4,1,63.610000000,63.800000000,2,3,2,3,63.600000000,63.810000000,6,4,6,2,MCLQ5
2025-06-11T00:00:29.209668559Z,2025-06-11T00:00:29.209569755Z,10,1,42025623,A,B,5,63.640000000,1,130,11372,79330410,63.690000000,63.720000000,3,2,3,2,63.680000000,63.730000000,2,2,2,2,63.670000000,63.740000000,3,3,3,3,63.660000000,63.750000000,5,2,5,2,63.650000000,63.760000000,4,7,4,7,63.640000000,63.770000000,4,1,4,1,63.630000000,63.780000000,4,4,4,4,63.620000000,63.790000000,4,1,4,1,63.610000000,63.800000000,2,3,2,3,63.600000000,63.810000000,6,4,6,2,MCLQ5
2025-06-11T00:00:29.209712095Z,2025-06-11T00:00:29.209603909Z,10,1,42026514,M,B,1,64.770000000,1,130,11945,79330411,64.780000000,64.800000000,4,7,4,7,64.770000000,64.810000000,6,4,5,4,64.760000000,64.820000000,7,9,7,6,64.750000000,64.830000000,8,11,8,11,64.740000000,64.840000000,10,6,9,5,64.730000000,64.850000000,7,9,7,6,64.720000000,64.860000000,8,4,5,3,64.710000000,64.870000000,8,4,7,3,64.700000000,64.880000000,7,4,6,3,64.690000000,64.890000000,4,3,3,2,MCLN5
2025-06-11T00:00:29.224428572Z,2025-06-11T00:00:29.221314011Z,10,1,42026514,M,A,4,66.770000000,2,130,15879,79330431,64.780000000,64.800000000,4,7,4,7,64.770000000,64.810000000,6,4,5,4,64.760000000,64.820000000,7,9,7,6,64.750000000,64.830000000,8,11,8,11,64.740000000,64.840000000,10,5,9,4,64.730000000,64.850000000,7,9,7,6,64.720000000,64.860000000,8,4,5,3,64.710000000,64.870000000,8,4,7,3,64.700000000,64.880000000,7,4,6,3,64.690000000,64.890000000,4,3,3,2,MCLN5
2025-06-11T00:00:29.252584004Z,2025-06-11T00:00:29.252376219Z,10,1,42418117,M,A,0,3.290000000,10,130,11716,79330480,3.250000000,3.280000000,1,1,1,1,3.240000000,3.290000000,11,11,2,2,3.230000000,3.300000000,1,1,1,1,,,0,0,0,0,,,0,0,0,0,,,0,0,0,0,,,0,0,0,0,,,0,0,0,0,,,0,0,0,0,,,0,0,0,0,MCLN5-MCLX5
2025-06-11T00:00:29.252609531Z,2025-06-11T00:00:29.252408973Z,10,1,42022708,M,A,0,2.840000000,10,130,15085,79330482,2.810000000,2.830000000,1,2,1,2,2.800000000,2.840000000,12,12,3,3,2.790000000,2.850000000,2,1,2,1,2.780000000,2.870000000,1,1,1,1,,,0,0,0,0,,,0,0,0,0,,,0,0,0,0,,,0,0,0,0,,,0,0,0,0,,,0,0,0,0,MCLN5-MCLV5
2025-06-11T00:00:29.355771301Z,2025-06-11T00:00:29.355678057Z,10,1,42022708,M,A,0,2.830000000,10,130,14959,79330562,2.810000000,2.830000000,1,12,1,3,2.800000000,2.840000000,12,2,3,2,2.790000000,2.850000000,2,1,2,1,2.780000000,2.870000000,1,1,1,1,,,0,0,0,0,,,0,0,0,0,,,0,0,0,0,,,0,0,0,0,,,0,0,0,0,,,0,0,0,0,MCLN5-MCLV5
2025-06-11T00:00:29.410301066Z,2025-06-11T00:00:29.410202129Z,10,1,42418117,M,A,0,3.280000000,10,130,15821,79330570,3.250000000,3.280000000,1,11,1,2,3.240000000,3.290000000,11,1,2,1,3.230000000,3.300000000,1,1,1,1,,,0,0,0,0,,,0,0,0,0,,,0,0,0,0,,,0,0,0,0,,,0,0,0,0,,,0,0,0,0,,,0,0,0,0,MCLN5-MCLX5
2025-06-11T00:00:29.668282733Z,2025-06-11T00:00:29.660038529Z,10,1,42026514,A,B,0,64.790000000,2,130,11878,79330634,64.790000000,64.800000000,2,7,1,7,64.780000000,64.810000000,4,4,4,4,64.770000000,64.820000000,6,9,5,6,64.760000000,64.830000000,7,11,7,11,64.750000000,64.840000000,8,5,8,4,64.740000000,64.850000000,10,9,9,6,64.730000000,64.860000000,7,4,7,3,64.720000000,64.870000000,8,4,5,3,64.710000000,64.880000000,8,4,7,3,64.700000000,64.890000000,7,3,6,2,MCLN5
2025-06-11T00:00:29.668377269Z,2025-06-11T00:00:29.660051451Z,10,1,42026514,C,A,0,64.800000000,1,130,13512,79330639,64.790000000,64.800000000,2,6,1,6,64.780000000,64.810000000,4,4,4,4,64.770000000,64.820000000,6,9,5,6,64.760000000,64.830000000,7,11,7,11,64.750000000,64.840000000,8,5,8,4,64.740000000,64.850000000,10,9,9,6,64.730000000,64.860000000,7,4,7,3,64.720000000,64.870000000,8,4,5,3,64.710000000,64.880000000,8,4,7,3,64.700000000,64.890000000,7,3,6,2,MCLN5
2025-06-11T00:00:29.668590686Z,2025-06-11T00:00:29.660580329Z,10,1,42026514,A,B,0,64.790000000,1,130,12150,79330651,64.790000000,64.800000000,3,6,2,6,64.780000000,64.810000000,4,4,4,4,64.770000000,64.820000000,6,9,5,6,64.760000000,64.830000000,7,11,7,11,64.750000000,64.840000000,8,5,8,4,64.740000000,64.850000000,10,9,9,6,64.730000000,64.860000000,7,4,7,3,64.720000000,64.870000000,8,4,5,3,64.710000000,64.880000000,8,4,7,3,64.700000000,64.890000000,7,3,6,2,MCLN5
2025-06-11T00:00:29.668958062Z,2025-06-11T00:00:29.668292647Z,10,1,42026514,C,A,5,64.850000000,1,130,16065,79330675,64.790000000,64.800000000,3,6,2,6,64.780000000,64.810000000,4,4,4,4,64.770000000,64.820000000,6,9,5,6,64.760000000,64.830000000,7,11,7,11,64.750000000,64.840000000,8,5,8,4,64.740000000,64.850000000,10,8,9,5,64.730000000,64.860000000,7,4,7,3,64.720000000,64.870000000,8,4,5,3,64.710000000,64.880000000,8,4,7,3,64.700000000,64.890000000,7,3,6,2,MCLN5
2025-06-11T00:00:29.669010636Z,2025-06-11T00:00:29.668321197Z,10,1,42026514,M,A,3,64.840000000,1,130,11519,79330678,64.790000000,64.800000000,3,6,2,6,64.780000000,64.810000000,4,4,4,4,64.770000000,64.820000000,6,9,5,6,64.760000000,64.830000000,7,10,7,10,64.750000000,64.840000000,8,6,8,5,64.740000000,64.850000000,10,8,9,5,64.730000000,64.860000000,7,4,7,3,64.720000000,64.870000000,8,4,5,3,64.710000000,64.880000000,8,4,7,3,64.700000000,64.890000000,7,3,6,2,MCLN5
2025-06-11T00:00:29.669019330Z,2025-06-11T00:00:29.668321657Z,10,1,42026514,M,B,4,64.750000000,1,130,11400,79330679,64.790000000,64.800000000,3,6,2,6,64.780000000,64.810000000,4,4,4,4,64.770000000,64.820000000,6,9,5,6,64.760000000,64.830000000,7,10,7,10,64.750000000,64.840000000,9,6,9,5,64.740000000,64.850000000,9,8,8,5,64.730000000,64.860000000,7,4,7,3,64.720000000,64.870000000,8,4,5,3,64.710000000,64.880000000,8,4,7,3,64.700000000,64.890000000,7,3,6,2,MCLN5
2025-06-11T00:00:29.669150029Z,2025-06-11T00:00:29.668599391Z,10,1,42418117,M,A,0,3.290000000,10,130,11819,79330690,3.250000000,3.280000000,1,1,1,1,3.240000000,3.290000000,11,11,2,2,3.230000000,3.300000000,1,1,1,1,,,0,0,0,0,,,0,0,0,0,,,0,0,0,0,,,0,0,0,0,,,0,0,0,0,,,0,0,0,0,,,0,0,0,0,MCLN5-MCLX5
2025-06-11T00:00:29.669600060Z,2025-06-11T00:00:29.668842319Z,10,1,42022708,M,A,0,2.840000000,10,130,11647,79330712,2.810000000,2.830000000,1,2,1,2,2.800000000,2.840000000,12,12,3,3,2.790000000,2.850000000,2,1,2,1,2.780000000,2.870000000,1,1,1,1,,,0,0,0,0,,,0,0,0,0,,,0,0,0,0,,,0,0,0,0,,,0,0,0,0,,,0,0,0,0,MCLN5-MCLV5
2025-06-11T00:00:29.682688526Z,2025-06-11T00:00:29.682577717Z,10,1,42026514,C,B,6,64.730000000,1,130,15346,79330821,64.790000000,64.800000000,3,6,2,6,64.780000000,64.810000000,4,4,4,4,64.770000000,64.820000000,6,9,5,6,64.760000000,64.830000000,7,10,7,10,64.750000000,64.840000000,9,6,9,5,64.740000000,64.850000000,9,8,8,5,64.730000000,64.860000000,6,4,6,3,64.720000000,64.870000000,8,4,5,3,64.710000000,64.880000000,8,4,7,3,64.700000000,64.890000000,7,3,6,2,MCLN5
2025-06-11T00:00:29.682697319Z,2025-06-11T00:00:29.682581231Z,10,1,42026514,A,A,6,64.860000000,1,130,11747,79330822,64.790000000,64.800000000,3,6,2,6,64.780000000,64.810000000,4,4,4,4,64.770000000,64.820000000,6,9,5,6,64.760000000,64.830000000,7,10,7,10,64.750000000,64.840000000,9,6,9,5,64.740000000,64.850000000,9,8,8,5,64.730000000,64.860000000,6,5,6,4,64.720000000,64.870000000,8,4,5,3,64.710000000,64.880000000,8,4,7,3,64.700000000,64.890000000,7,3,6,2,MCLN5
2025-06-11T00:00:29.682816545Z,2025-06-11T00:00:29.682705643Z,10,1,42026514,C,B,0,64.790000000,1,130,17330,79330823,64.790000000,64.800000000,2,6,1,6,64.780000000,64.810000000,4,4,4,4,64.770000000,64.820000000,6,9,5,6,64.760000000,64.830000000,7,10,7,10,64.750000000,64.840000000,9,6,9,5,64.740000000,64.850000000,9,8,8,5,64.730000000,64.860000000,6,5,6,4,64.720000000,64.870000000,8,4,5,3,64.710000000,64.880000000,8,4,7,3,64.700000000,64.890000000,7,3,6,2,MCLN5
2025-06-11T00:00:29.682823733Z,2025-06-11T00:00:29.682714493Z,10,1,42026514,A,B,5,64.740000000,1,130,11305,79330824,64.790000000,64.800000000,2,6,1,6,64.780000000,64.810000000,4,4,4,4,64.770000000,64.820000000,6,9,5,6,64.760000000,64.830000000,7,10,7,10,64.750000000,64.840000000,9,6,9,5,64.740000000,64.850000000,10,8,9,5,64.730000000,64.860000000,6,5,6,4,64.720000000,64.870000000,8,4,5,3,64.710000000,64.880000000,8,4,7,3,64.700000000,64.890000000,7,3,6,2,MCLN5
2025-06-11T00:00:29.682995779Z,2025-06-11T00:00:29.682860619Z,10,1,42026514,C,B,0,64.790000000,2,130,11432,79330831,64.780000000,64.800000000,4,6,4,6,64.770000000,64.810000000,6,4,5,4,64.760000000,64.820000000,7,9,7,6,64.750000000,64.830000000,9,10,9,10,64.740000000,64.840000000,10,6,9,5,64.730000000,64.850000000,6,8,6,5,64.720000000,64.860000000,8,5,5,4,64.710000000,64.870000000,8,4,7,3,64.700000000,64.880000000,7,4,6,3,64.690000000,64.890000000,4,3,3,2,MCLN5
2025-06-11T00:00:29.683099308Z,2025-06-11T00:00:29.683004227Z,10,1,42026514,C,B,4,64.740000000,1,130,17572,79330834,64.780000000,64.800000000,4,6,4,6,64.770000000,64.810000000,6,4,5,4,64.760000000,64.820000000,7,9,7,6,64.750000000,64.830000000,9,10,9,10,64.740000000,64.840000000,9,6,8,5,64.730000000,64.850000000,6,8,6,5,64.720000000,64.860000000,8,5,5,4,64.710000000,64.870000000,8,4,7,3,64.700000000,64.880000000,7,4,6,3,64.690000000,64.890000000,4,3,3,2,MCLN5
2025-06-11T00:00:29.683116295Z,2025-06-11T00:00:29.683009333Z,10,1,42026514,A,B,0,64.780000000,1,130,13978,79330835,64.780000000,64.800000000,5,6,5,6,64.770000000,64.810000000,6,4,5,4,64.760000000,64.820000000,7,9,7,6,64.750000000,64.830000000,9,10,9,10,64.740000000,64.840000000,9,6,8,5,64.730000000,64.850000000,6,8,6,5,64.720000000,64.860000000,8,5,5,4,64.710000000,64.870000000,8,4,7,3,64.700000000,64.880000000,7,4,6,3,64.690000000,64.890000000,4,3,3,2,MCLN5
2025-06-11T00:00:29.683952118Z,2025-06-11T00:00:29.683767663Z,10,1,42026514,M,A,1,66.780000000,2,130,12290,79330843,64.780000000,64.800000000,5,6,5,6,64.770000000,64.810000000,6,3,5,3,64.760000000,64.820000000,7,9,7,6,64.750000000,64.830000000,9,10,9,10,64.740000000,64.840000000,9,6,8,5,64.730000000,64.850000000,6,8,6,5,64.720000000,64.860000000,8,5,5,4,64.710000000,64.870000000,8,4,7,3,64.700000000,64.880000000,7,4,6,3,64.690000000,64.890000000,4,3,3,2,MCLN5
2025-06-11T00:00:29.683970711Z,2025-06-11T00:00:29.683796711Z,10,1,42026514,M,B,0,64.780000000,1,130,13389,79330844,64.780000000,64.800000000,6,6,6,6,64.770000000,64.810000000,6,3,5,3,64.760000000,64.820000000,7,9,7,6,64.750000000,64.830000000,9,10,9,10,64.740000000,64.840000000,9,6,8,5,64.730000000,64.850000000,6,8,6,5,64.720000000,64.860000000,8,5,5,4,64.710000000,64.870000000,8,4,7,3,64.700000000,64.880000000,7,4,6,3,64.690000000,64.890000000,4,3,3,2,MCLN5
2025-06-11T00:00:29.696201005Z,2025-06-11T00:00:29.696089677Z,10,1,42026514,A,B,5,64.730000000,1,130,15776,79330846,64.780000000,64.800000000,6,6,6,6,64.770000000,64.810000000,6,3,5,3,64.760000000,64.820000000,7,9,7,6,64.750000000,64.830000000,9,10,9,10,64.740000000,64.840000000,9,6,8,5,64.730000000,64.850000000,7,8,7,5,64.720000000,64.860000000,8,5,5,4,64.710000000,64.870000000,8,4,7,3,64.700000000,64.880000000,7,4,6,3,64.690000000,64.890000000,4,3,3,2,MCLN5
2025-06-11T00:00:29.696210497Z,2025-06-11T00:00:29.696091001Z,10,1,42026514,C,A,6,64.860000000,1,130,12637,79330847,64.780000000,64.800000000,6,6,6,6,64.770000000,64.810000000,6,3,5,3,64.760000000,64.820000000,7,9,7,6,64.750000000,64.830000000,9,10,9,10,64.740000000,64.840000000,9,6,8,5,64.730000000,64.850000000,7,8,7,5,64.720000000,64.860000000,8,4,5,3,64.710000000,64.870000000,8,4,7,3,64.700000000,64.880000000,7,4,6,3,64.690000000,64.890000000,4,3,3,2,MCLN5
2025-06-11T00:00:29.696334830Z,2025-06-11T00:00:29.696239547Z,10,1,42026514,A,A,5,64.850000000,1,130,14846,79330848,64.780000000,64.800000000,6,6,6,6,64.770000000,64.810000000,6,3,5,3,64.760000000,64.820000000,7,9,7,6,64.750000000,64.830000000,9,10,9,10,64.740000000,64.840000000,9,6,8,5,64.730000000,64.850000000,7,9,7,6,64.720000000,64.860000000,8,4,5,3,64.710000000,64.870000000,8,4,7,3,64.700000000,64.880000000,7,4,6,3,64.690000000,64.890000000,4,3,3,2,MCLN5
2025-06-11T00:00:29.771012678Z,2025-06-11T00:00:29.770913145Z,10,1,42022708,M,A,0,2.830000000,10,130,15529,79330879,2.810000000,2.830000000,1,12,1,3,2.800000000,2.840000000,12,2,3,2,2.790000000,2.850000000,2,1,2,1,2.780000000,2.870000000,1,1,1,1,,,0,0,0,0,,,0,0,0,0,,,0,0,0,0,,,0,0,0,0,,,0,0,0,0,,,0,0,0,0,MCLN5-MCLV5
2025-06-11T00:00:29.897904005Z,2025-06-11T00:00:29.897802503Z,10,1,42418117,M,B,0,3.250000000,10,130,15143,79330938,3.250000000,3.280000000,11,1,2,1,3.240000000,3.290000000,1,11,1,2,3.230000000,3.300000000,1,1,1,1,,,0,0,0,0,,,0,0,0,0,,,0,0,0,0,,,0,0,0,0,,,0,0,0,0,,,0,0,0,0,,,0,0,0,0,MCLN5-MCLX5
2025-06-11T00:00:30.026855198Z,2025-06-11T00:00:30.026750279Z,10,1,42418117,M,B,0,3.240000000,10,130,14691,79330978,3.250000000,3.280000000,1,1,1,1,3.240000000,3.290000000,11,11,2,2,3.230000000,3.300000000,1,1,1,1,,,0,0,0,0,,,0,0,0,0,,,0,0,0,0,,,0,0,0,0,,,0,0,0,0,,,0,0,0,0,,,0,0,0,0,MCLN5-MCLX5
2025-06-11T00:00:30.825071888Z,2025-06-11T00:00:30.824966475Z,10,1,42022708,M,A,0,2.840000000,10,130,14833,79331082,2.810000000,2.830000000,1,2,1,2,2.800000000,2.840000000,12,12,3,3,2.790000000,2.850000000,2,1,2,1,2.780000000,2.870000000,1,1,1,1,,,0,0,0,0,,,0,0,0,0,,,0,0,0,0,,,0,0,0,0,,,0,0,0,0,,,0,0,0,0,MCLN5-MCLV5
2025-06-11T00:00:31.004448529Z,2025-06-11T00:00:31.004264809Z,10,1,42026514,A,B,0,64.790000000,2,130,11536,79331093,64.790000000,64.800000000,2,6,1,6,64.780000000,64.810000000,6,3,6,3,64.770000000,64.820000000,6,9,5,6,64.760000000,64.830000000,7,10,7,10,64.750000000,64.840000000,9,6,9,5,64.740000000,64.850000000,9,9,8,6,64.730000000,64.860000000,7,4,7,3,64.720000000,64.870000000,8,4,5,3,64.710000000,64.880000000,8,4,7,3,64.700000000,64.890000000,7,3,6,2,MCLN5
2025-06-11T00:00:31.004583390Z,2025-06-11T00:00:31.004450137Z,10,1,42026514,A,B,0,64.790000000,1,130,13557,79331100,64.790000000,64.800000000,3,6,2,6,64.780000000,64.810000000,6,3,6,3,64.770000000,64.820000000,6,9,5,6,64.760000000,64.830000000,7,10,7,10,64.750000000,64.840000000,9,6,9,5,64.740000000,64.850000000,9,9,8,6,64.730000000,64.860000000,7,4,7,3,64.720000000,64.870000000,8,4,5,3,64.710000000,64.880000000,8,4,7,3,64.700000000,64.890000000,7,3,6,2,MCLN5
2025-06-11T00:00:31.004735576Z,2025-06-11T00:00:31.004452173Z,10,1,42026514,T,A,0,64.790000000,2,0,15216,79331101,64.790000000,64.800000000,3,6,2,6,64.780000000,64.810000000,6,3,6,3,64.770000000,64.820000000,6,9,5,6,64.760000000,64.830000000,7,10,7,10,64.750000000,64.840000000,9,6,9,5,64.740000000,64.850000000,9,9,8,6,64.730000000,64.860000000,7,4,7,3,64.720000000,64.870000000,8,4,5,3,64.710000000,64.880000000,8,4,7,3,64.700000000,64.890000000,7,3,6,2,MCLN5
2025-06-11T00:00:31.004754829Z,2025-06-11T00:00:31.004452173Z,10,1,42026514,C,B,0,64.790000000,2,130,16143,79331102,64.790000000,64.800000000,1,6,1,6,64.780000000,64.810000000,6,3,6,3,64.770000000,64.820000000,6,9,5,6,64.760000000,64.830000000,7,10,7,10,64.750000000,64.840000000,9,6,9,5,64.740000000,64.850000000,9,9,8,6,64.730000000,64.860000000,7,4,7,3,64.720000000,64.870000000,8,4,5,3,64.710000000,64.880000000,8,4,7,3,64.700000000,64.890000000,7,3,6,2,MCLN5
2025-06-11T00:00:31.004754829Z,2025-06-11T00:00:31.004458797Z,10,1,42026514,C,A,5,64.850000000,1,130,16143,79331102,64.790000000,64.800000000,1,6,1,6,64.780000000,64.810000000,6,3,6,3,64.770000000,64.820000000,6,9,5,6,64.760000000,64.830000000,7,10,7,10,64.750000000,64.840000000,9,6,9,5,64.740000000,64.850000000,9,8,8,5,64.730000000,64.860000000,7,4,7,3,64.720000000,64.870000000,8,4,5,3,64.710000000,64.880000000,8,4,7,3,64.700000000,64.890000000,7,3,6,2,MCLN5
2025-06-11T00:00:31.004769612Z,2025-06-11T00:00:31.004462271Z,10,1,42026514,A,B,0,64.790000000,1,130,15754,79331103,64.790000000,64.800000000,2,6,2,6,64.780000000,64.810000000,6,3,6,3,64.770000000,64.820000000,6,9,5,6,64.760000000,64.830000000,7,10,7,10,64.750000000,64.840000000,9,6,9,5,64.740000000,64.850000000,9,8,8,5,64.730000000,64.860000000,7,4,7,3,64.720000000,64.870000000,8,4,5,3,64.710000000,64.880000000,8,4,7,3,64.700000000,64.890000000,7,3,6,2,MCLN5
2025-06-11T00:00:31.013090931Z,2025-06-11T00:00:31.004689973Z,10,1,42026514,M,B,3,64.760000000,1,130,11602,79331119,64.790000000,64.800000000,2,6,2,6,64.780000000,64.810000000,6,3,6,3,64.770000000,64.820000000,6,9,5,6,64.760000000,64.830000000,8,10,8,10,64.750000000,64.840000000,9,6,9,5,64.740000000,64.850000000,9,8,8,5,64.730000000,64.860000000,7,4,7,3,64.720000000,64.870000000,8,4,5,3,64.710000000,64.880000000,8,4,7,3,64.700000000,64.890000000,7,3,6,2,MCLN5
2025-06-11T00:00:31.013160930Z,2025-06-11T00:00:31.004747935Z,10,1,42026514,C,B,0,64.790000000,1,130,14094,79331124,64.790000000,64.800000000,1,6,1,6,64.780000000,64.810000000,6,3,6,3,64.770000000,64.820000000,6,9,5,6,64.760000000,64.830000000,8,10,8,10,64.750000000,64.840000000,9,6,9,5,64.740000000,64.850000000,9,8,8,5,64.730000000,64.860000000,7,4,7,3,64.720000000,64.870000000,8,4,5,3,64.710000000,64.880000000,8,4,7,3,64.700000000,64.890000000,7,3,6,2,MCLN5
2025-06-11T00:00:31.013216147Z,2025-06-11T00:00:31.004872213Z,10,1,42026514,C,B,1,64.780000000,1,130,16333,79331127,64.790000000,64.800000000,1,6,1,6,64.780000000,64.810000000,5,3,5,3,64.770000000,64.820000000,6,9,5,6,64.760000000,64.830000000,8,10,8,10,64.750000000,64.840000000,9,6,9,5,64.740000000,64.850000000,9,8,8,5,64.730000000,64.860000000,7,4,7,3,64.720000000,64.870000000,8,4,5,3,64.710000000,64.880000000,8,4,7,3,64.700000000,64.890000000,7,3,6,2,MCLN5
