ts_recv,ts_event,rtype,publisher_id,instrument_id,action,side,depth,price,size,flags,ts_in_delta,sequence,bid_px_00,ask_px_00,bid_sz_00,ask_sz_00,bid_ct_00,ask_ct_00,bid_px_01,ask_px_01,bid_sz_01,ask_sz_01,bid_ct_01,ask_ct_01,bid_px_02,ask_px_02,bid_sz_02,ask_sz_02,bid_ct_02,ask_ct_02,bid_px_03,ask_px_03,bid_sz_03,ask_sz_03,bid_ct_03,ask_ct_03,bid_px_04,ask_px_04,bid_sz_04,ask_sz_04,bid_ct_04,ask_ct_04,bid_px_05,ask_px_05,bid_sz_05,ask_sz_05,bid_ct_05,ask_ct_05,bid_px_06,ask_px_06,bid_sz_06,ask_sz_06,bid_ct_06,ask_ct_06,bid_px_07,ask_px_07,bid_sz_07,ask_sz_07,bid_ct_07,ask_ct_07,bid_px_08,ask_px_08,bid_sz_08,ask_sz_08,bid_ct_08,ask_ct_08,bid_px_09,ask_px_09,bid_sz_09,ask_sz_09,bid_ct_09,ask_ct_09,symbol
2025-06-11T00:00:17.620581397Z,2025-06-11T00:00:17.616527159Z,10,1,42026514,M,A,3,64.820000000,1,130,15415,79309993,64.760000000,64.780000000,5,5,5,5,64.750000000,64.790000000,4,6,4,4,64.740000000,64.800000000,9,5,8,5,64.730000000,64.810000000,7,7,7,7,64.720000000,64.820000000,10,10,7,7,64.710000000,64.830000000,8,8,7,8,64.700000000,64.840000000,7,7,6,6,64.690000000,64.850000000,4,8,3,5,64.680000000,64.860000000,4,4,2,3,64.670000000,64.870000000,6,4,4,3,MCLN5
2025-06-11T00:00:17.620590459Z,2025-06-11T00:00:17.616527735Z,10,1,42026514,M,B,3,64.730000000,1,130,11980,79309994,64.760000000,64.780000000,5,5,5,5,64.750000000,64.790000000,4,6,4,4,64.740000000,64.800000000,9,5,8,5,64.730000000,64.810000000,8,7,8,7,64.720000000,64.820000000,9,10,6,7,64.710000000,64.830000000,8,8,7,8,64.700000000,64.840000000,7,7,6,6,64.690000000,64.850000000,4,8,3,5,64.680000000,64.860000000,4,4,2,3,64.670000000,64.870000000,6,4,4,3,MCLN5
2025-06-11T00:00:17.620599713Z,2025-06-11T00:00:17.616529887Z,10,1,42026514,C,B,4,64.720000000,1,130,12158,79309995,64.760000000,64.780000000,5,5,5,5,64.750000000,64.790000000,4,6,4,4,64.740000000,64.800000000,9,5,8,5,64.730000000,64.810000000,8,7,8,7,64.720000000,64.820000000,8,10,5,7,64.710000000,64.830000000,8,8,7,8,64.700000000,64.840000000,7,7,6,6,64.690000000,64.850000000,4,8,3,5,64.680000000,64.860000000,4,4,2,3,64.670000000,64.870000000,6,4,4,3,MCLN5
2025-06-11T00:00:17.620722103Z,2025-06-11T00:00:17.616595241Z,10,1,42026514,A,A,0,64.770000000,2,130,11752,79310001,64.760000000,64.770000000,5,2,5,1,64.750000000,64.780000000,4,5,4,5,64.740000000,64.790000000,9,6,8,4,64.730000000,64.800000000,8,5,8,5,64.720000000,64.810000000,8,7,5,7,64.710000000,64.820000000,8,10,7,7,64.700000000,64.830000000,7,8,6,8,64.690000000,64.840000000,4,7,3,6,64.680000000,64.850000000,4,8,2,5,64.670000000,64.860000000,6,4,4,3,MCLN5
2025-06-11T00:00:17.620849016Z,2025-06-11T00:00:17.620743583Z,10,1,42025623,C,B,5,63.620000000,1,130,11454,79310005,63.670000000,63.700000000,2,3,2,3,63.660000000,63.710000000,3,2,3,2,63.650000000,63.720000000,3,2,3,2,63.640000000,63.730000000,5,2,5,2,63.630000000,63.740000000,5,7,5,7,63.620000000,63.750000000,3,2,3,2,63.610000000,63.760000000,2,4,2,4,63.600000000,63.770000000,7,1,7,1,63.590000000,63.780000000,1,3,1,3,63.580000000,63.790000000,6,1,4,1,MCLQ5
2025-06-11T00:00:17.620862908Z,2025-06-11T00:00:17.620744561Z,10,1,42025623,M,B,3,63.630000000,1,130,12256,79310006,63.670000000,63.700000000,2,3,2,3,63.660000000,63.710000000,3,2,3,2,63.650000000,63.720000000,3,2,3,2,63.640000000,63.730000000,4,2,4,2,63.630000000,63.740000000,6,7,6,7,63.620000000,63.750000000,3,2,3,2,63.610000000,63.760000000,2,4,2,4,63.600000000,63.770000000,7,1,7,1,63.590000000,63.780000000,1,3,1,3,63.580000000,63.790000000,6,1,4,1,MCLQ5
2025-06-11T00:00:17.620885932Z,2025-06-11T00:00:17.620745003Z,10,1,42025623,M,A,3,63.730000000,1,130,11530,79310007,63.670000000,63.700000000,2,3,2,3,63.660000000,63.710000000,3,2,3,2,63.650000000,63.720000000,3,2,3,2,63.640000000,63.730000000,4,3,4,3,63.630000000,63.740000000,6,6,6,6,63.620000000,63.750000000,3,2,3,2,63.610000000,63.760000000,2,4,2,4,63.600000000,63.770000000,7,1,7,1,63.590000000,63.780000000,1,3,1,3,63.580000000,63.790000000,6,1,4,1,MCLQ5
2025-06-11T00:00:17.620898826Z,2025-06-11T00:00:17.620745713Z,10,1,42025623,M,B,3,63.630000000,1,130,11828,79310008,63.670000000,63.700000000,2,3,2,3,63.660000000,63.710000000,3,2,3,2,63.650000000,63.720000000,3,2,3,2,63.640000000,63.730000000,3,3,3,3,63.630000000,63.740000000,7,6,7,6,63.620000000,63.750000000,3,2,3,2,63.610000000,63.760000000,2,4,2,4,63.600000000,63.770000000,7,1,7,1,63.590000000,63.780000000,1,3,1,3,63.580000000,63.790000000,6,1,4,1,MCLQ5
2025-06-11T00:00:17.620909838Z,2025-06-11T00:00:17.620746251Z,10,1,42025623,M,A,3,63.730000000,1,130,11710,79310009,63.670000000,63.700000000,2,3,2,3,63.660000000,63.710000000,3,2,3,2,63.650000000,63.720000000,3,2,3,2,63.640000000,63.730000000,3,4,3,4,63.630000000,63.740000000,7,5,7,5,63.620000000,63.750000000,3,2,3,2,63.610000000,63.760000000,2,4,2,4,63.600000000,63.770000000,7,1,7,1,63.590000000,63.780000000,1,3,1,3,63.580000000,63.790000000,6,1,4,1,MCLQ5
2025-06-11T00:00:17.620920582Z,2025-06-11T00:00:17.620751665Z,10,1,42025623,C,A,6,63.760000000,1,130,11512,79310010,63.670000000,63.700000000,2,3,2,3,63.660000000,63.710000000,3,2,3,2,63.650000000,63.720000000,3,2,3,2,63.640000000,63.730000000,3,4,3,4,63.630000000,63.740000000,7,5,7,5,63.620000000,63.750000000,3,2,3,2,63.610000000,63.760000000,2,3,2,3,63.600000000,63.770000000,7,1,7,1,63.590000000,63.780000000,1,3,1,3,63.580000000,63.790000000,6,1,4,1,MCLQ5
2025-06-11T00:00:17.620973272Z,2025-06-11T00:00:17.620877995Z,10,1,42025623,A,B,6,63.610000000,1,130,12222,79310013,63.670000000,63.700000000,2,3,2,3,63.660000000,63.710000000,3,2,3,2,63.650000000,63.720000000,3,2,3,2,63.640000000,63.730000000,3,4,3,4,63.630000000,63.740000000,7,5,7,5,63.620000000,63.750000000,3,2,3,2,63.610000000,63.760000000,3,3,3,3,63.600000000,63.770000000,7,1,7,1,63.590000000,63.780000000,1,3,1,3,63.580000000,63.790000000,6,1,4,1,MCLQ5
2025-06-11T00:00:17.621029632Z,2025-06-11T00:00:17.620937667Z,10,1,42025623,A,A,5,63.750000000,1,130,11415,79310014,63.670000000,63.700000000,2,3,2,3,63.660000000,63.710000000,3,2,3,2,63.650000000,63.720000000,3,2,3,2,63.640000000,63.730000000,3,4,3,4,63.630000000,63.740000000,7,5,7,5,63.620000000,63.750000000,3,3,3,3,63.610000000,63.760000000,3,3,3,3,63.600000000,63.770000000,7,1,7,1,63.590000000,63.780000000,1,3,1,3,63.580000000,63.790000000,6,1,4,1,MCLQ5
2025-06-11T00:00:17.621155386Z,2025-06-11T00:00:17.621045565Z,10,1,42025623,M,B,2,62.280000000,1,130,15059,79310015,63.670000000,63.700000000,2,3,2,3,63.660000000,63.710000000,3,2,3,2,63.650000000,63.720000000,2,2,2,2,63.640000000,63.730000000,3,4,3,4,63.630000000,63.740000000,7,5,7,5,63.620000000,63.750000000,3,3,3,3,63.610000000,63.760000000,3,3,3,3,63.600000000,63.770000000,7,1,7,1,63.590000000,63.780000000,1,3,1,3,63.580000000,63.790000000,6,1,4,1,MCLQ5
2025-06-11T00:00:17.621786004Z,2025-06-11T00:00:17.621683247Z,10,1,42026514,M,B,1,64.750000000,1,130,16225,79310017,64.760000000,64.770000000,5,2,5,1,64.750000000,64.780000000,5,5,5,5,64.740000000,64.790000000,9,6,8,4,64.730000000,64.800000000,8,5,8,5,64.720000000,64.810000000,8,7,5,7,64.710000000,64.820000000,8,10,7,7,64.700000000,64.830000000,7,8,6,8,64.690000000,64.840000000,4,7,3,6,64.680000000,64.850000000,4,8,2,5,64.670000000,64.860000000,6,4,4,3,MCLN5
2025-06-11T00:00:17.621835791Z,2025-06-11T00:00:17.621737425Z,10,1,42026514,M,A,1,66.730000000,2,130,12691,79310018,64.760000000,64.770000000,5,2,5,1,64.750000000,64.780000000,5,4,5,4,64.740000000,64.790000000,9,6,8,4,64.730000000,64.800000000,8,5,8,5,64.720000000,64.810000000,8,7,5,7,64.710000000,64.820000000,8,10,7,7,64.700000000,64.830000000,7,8,6,8,64.690000000,64.840000000,4,7,3,6,64.680000000,64.850000000,4,8,2,5,64.670000000,64.860000000,6,4,4,3,MCLN5
2025-06-11T00:00:17.621910605Z,2025-06-11T00:00:17.621798211Z,10,1,42026514,C,A,1,64.780000000,1,130,16412,79310019,64.760000000,64.770000000,5,2,5,1,64.750000000,64.780000000,5,3,5,3,64.740000000,64.790000000,9,6,8,4,64.730000000,64.800000000,8,5,8,5,64.720000000,64.810000000,8,7,5,7,64.710000000,64.820000000,8,10,7,7,64.700000000,64.830000000,7,8,6,8,64.690000000,64.840000000,4,7,3,6,64.680000000,64.850000000,4,8,2,5,64.670000000,64.860000000,6,4,4,3,MCLN5
2025-06-11T00:00:17.628419108Z,2025-06-11T00:00:17.628277731Z,10,1,42026514,C,A,0,64.770000000,2,130,11335,79310022,64.760000000,64.780000000,5,3,5,3,64.750000000,64.790000000,5,6,5,4,64.740000000,64.800000000,9,5,8,5,64.730000000,64.810000000,8,7,8,7,64.720000000,64.820000000,8,10,5,7,64.710000000,64.830000000,8,8,7,8,64.700000000,64.840000000,7,7,6,6,64.690000000,64.850000000,4,8,3,5,64.680000000,64.860000000,4,4,2,3,64.670000000,64.870000000,6,4,4,3,MCLN5
2025-06-11T00:00:17.628546113Z,2025-06-11T00:00:17.628429155Z,10,1,42026514,A,A,0,64.780000000,1,130,13779,79310026,64.760000000,64.780000000,5,4,5,4,64.750000000,64.790000000,5,6,5,4,64.740000000,64.800000000,9,5,8,5,64.730000000,64.810000000,8,7,8,7,64.720000000,64.820000000,8,10,5,7,64.710000000,64.830000000,8,8,7,8,64.700000000,64.840000000,7,7,6,6,64.690000000,64.850000000,4,8,3,5,64.680000000,64.860000000,4,4,2,3,64.670000000,64.870000000,6,4,4,3,MCLN5
2025-06-11T00:00:17.628554899Z,2025-06-11T00:00:17.628441001Z,10,1,42025623,C,A,5,63.750000000,1,130,11321,79310027,63.670000000,63.700000000,2,3,2,3,63.660000000,63.710000000,3,2,3,2,63.650000000,63.720000000,2,2,2,2,63.640000000,63.730000000,3,4,3,4,63.630000000,63.740000000,7,5,7,5,63.620000000,63.750000000,3,2,3,2,63.610000000,63.760000000,3,3,3,3,63.600000000,63.770000000,7,1,7,1,63.590000000,63.780000000,1,3,1,3,63.580000000,63.790000000,6,1,4,1,MCLQ5
2025-06-11T00:00:17.628568484Z,2025-06-11T00:00:17.628445647Z,10,1,42025623,C,B,6,63.610000000,1,130,12372,79310028,63.670000000,63.700000000,2,3,2,3,63.660000000,63.710000000,3,2,3,2,63.650000000,63.720000000,2,2,2,2,63.640000000,63.730000000,3,4,3,4,63.630000000,63.740000000,7,5,7,5,63.620000000,63.750000000,3,2,3,2,63.610000000,63.760000000,2,3,2,3,63.600000000,63.770000000,7,1,7,1,63.590000000,63.780000000,1,3,1,3,63.580000000,63.790000000,6,1,4,1,MCLQ5
2025-06-11T00:00:17.628679101Z,2025-06-11T00:00:17.628585245Z,10,1,42025623,A,A,6,63.760000000,1,130,14782,79310030,63.670000000,63.700000000,2,3,2,3,63.660000000,63.710000000,3,2,3,2,63.650000000,63.720000000,2,2,2,2,63.640000000,63.730000000,3,4,3,4,63.630000000,63.740000000,7,5,7,5,63.620000000,63.750000000,3,2,3,2,63.610000000,63.760000000,2,4,2,4,63.600000000,63.770000000,7,1,7,1,63.590000000,63.780000000,1,3,1,3,63.580000000,63.790000000,6,1,4,1,MCLQ5
2025-06-11T00:00:17.628696265Z,2025-06-11T00:00:17.628595613Z,10,1,42025623,A,B,5,63.620000000,1,130,11265,79310031,63.670000000,63.700000000,2,3,2,3,63.660000000,63.710000000,3,2,3,2,63.650000000,63.720000000,2,2,2,2,63.640000000,63.730000000,3,4,3,4,63.630000000,63.740000000,7,5,7,5,63.620000000,63.750000000,4,2,4,2,63.610000000,63.760000000,2,4,2,4,63.600000000,63.770000000,7,1,7,1,63.590000000,63.780000000,1,3,1,3,63.580000000,63.790000000,6,1,4,1,MCLQ5
2025-06-11T00:00:17.638967901Z,2025-06-11T00:00:17.638858827Z,10,1,42026514,A,B,5,64.710000000,1,130,15978,79310032,64.760000000,64.780000000,5,4,5,4,64.750000000,64.790000000,5,6,5,4,64.740000000,64.800000000,9,5,8,5,64.730000000,64.810000000,8,7,8,7,64.720000000,64.820000000,8,10,5,7,64.710000000,64.830000000,9,8,8,8,64.700000000,64.840000000,7,7,6,6,64.690000000,64.850000000,4,8,3,5,64.680000000,64.860000000,4,4,2,3,64.670000000,64.870000000,6,4,4,3,MCLN5
2025-06-11T00:00:17.638977340Z,2025-06-11T00:00:17.638860765Z,10,1,42026514,C,A,6,64.840000000,1,130,12584,79310033,64.760000000,64.780000000,5,4,5,4,64.750000000,64.790000000,5,6,5,4,64.740000000,64.800000000,9,5,8,5,64.730000000,64.810000000,8,7,8,7,64.720000000,64.820000000,8,10,5,7,64.710000000,64.830000000,9,8,8,8,64.700000000,64.840000000,7,6,6,5,64.690000000,64.850000000,4,8,3,5,64.680000000,64.860000000,4,4,2,3,64.670000000,64.870000000,6,4,4,3,MCLN5
2025-06-11T00:00:17.639102356Z,2025-06-11T00:00:17.639005259Z,10,1,42026514,A,A,5,64.830000000,1,130,14755,79310034,64.760000000,64.780000000,5,4,5,4,64.750000000,64.790000000,5,6,5,4,64.740000000,64.800000000,9,5,8,5,64.730000000,64.810000000,8,7,8,7,64.720000000,64.820000000,8,10,5,7,64.710000000,64.830000000,9,9,8,9,64.700000000,64.840000000,7,6,6,5,64.690000000,64.850000000,4,8,3,5,64.680000000,64.860000000,4,4,2,3,64.670000000,64.870000000,6,4,4,3,MCLN5
2025-06-11T00:00:18.005283107Z,2025-06-11T00:00:18.005185211Z,10,1,42025623,M,A,3,63.740000000,1,130,15105,79310063,63.670000000,63.700000000,2,3,2,3,63.660000000,63.710000000,3,2,3,2,63.650000000,63.720000000,2,2,2,2,63.640000000,63.730000000,3,3,3,3,63.630000000,63.740000000,7,6,7,6,63.620000000,63.750000000,4,2,4,2,63.610000000,63.760000000,2,4,2,4,63.600000000,63.770000000,7,1,7,1,63.590000000,63.780000000,1,3,1,3,63.580000000,63.790000000,6,1,4,1,MCLQ5
2025-06-11T00:00:18.005291670Z,2025-06-11T00:00:18.005185691Z,10,1,42025623,M,B,3,63.640000000,1,130,11479,79310064,63.670000000,63.700000000,2,3,2,3,63.660000000,63.710000000,3,2,3,2,63.650000000,63.720000000,2,2,2,2,63.640000000,63.730000000,4,3,4,3,63.630000000,63.740000000,6,6,6,6,63.620000000,63.750000000,4,2,4,2,63.610000000,63.760000000,2,4,2,4,63.600000000,63.770000000,7,1,7,1,63.590000000,63.780000000,1,3,1,3,63.580000000,63.790000000,6,1,4,1,MCLQ5
2025-06-11T00:00:18.005303304Z,2025-06-11T00:00:18.005186229Z,10,1,42025623,M,A,3,63.740000000,1,130,11501,79310065,63.670000000,63.700000000,2,3,2,3,63.660000000,63.710000000,3,2,3,2,63.650000000,63.720000000,2,2,2,2,63.640000000,63.730000000,4,2,4,2,63.630000000,63.740000000,6,7,6,7,63.620000000,63.750000000,4,2,4,2,63.610000000,63.760000000,2,4,2,4,63.600000000,63.770000000,7,1,7,1,63.590000000,63.780000000,1,3,1,3,63.580000000,63.790000000,6,1,4,1,MCLQ5
2025-06-11T00:00:18.005314086Z,2025-06-11T00:00:18.005186805Z,10,1,42025623,M,B,3,63.640000000,1,130,11326,79310066,63.670000000,63.700000000,2,3,2,3,63.660000000,63.710000000,3,2,3,2,63.650000000,63.720000000,2,2,2,2,63.640000000,63.730000000,5,2,5,2,63.630000000,63.740000000,5,7,5,7,63.620000000,63.750000000,4,2,4,2,63.610000000,63.760000000,2,4,2,4,63.600000000,63.770000000,7,1,7,1,63.590000000,63.780000000,1,3,1,3,63.580000000,63.790000000,6,1,4,1,MCLQ5
2025-06-11T00:00:18.706516958Z,2025-06-11T00:00:18.706370555Z,10,1,42026514,A,A,0,64.770000000,2,130,14483,79310097,64.760000000,64.770000000,5,2,5,1,64.750000000,64.780000000,5,4,5,4,64.740000000,64.790000000,9,6,8,4,64.730000000,64.800000000,8,5,8,5,64.720000000,64.810000000,8,7,5,7,64.710000000,64.820000000,9,10,8,7,64.700000000,64.830000000,7,9,6,9,64.690000000,64.840000000,4,6,3,5,64.680000000,64.850000000,4,8,2,5,64.670000000,64.860000000,6,4,4,3,MCLN5
2025-06-11T00:00:18.706624641Z,2025-06-11T00:00:18.706526355Z,10,1,42026514,M,B,3,64.720000000,1,130,15212,79310100,64.760000000,64.770000000,5,2,5,1,64.750000000,64.780000000,5,4,5,4,64.740000000,64.790000000,9,6,8,4,64.730000000,64.800000000,7,5,7,5,64.720000000,64.810000000,9,7,6,7,64.710000000,64.820000000,9,10,8,7,64.700000000,64.830000000,7,9,6,9,64.690000000,64.840000000,4,6,3,5,64.680000000,64.850000000,4,8,2,5,64.670000000,64.860000000,6,4,4,3,MCLN5
2025-06-11T00:00:18.706633081Z,2025-06-11T00:00:18.706526817Z,10,1,42026514,M,A,4,64.810000000,1,130,11512,79310101,64.760000000,64.770000000,5,2,5,1,64.750000000,64.780000000,5,4,5,4,64.740000000,64.790000000,9,6,8,4,64.730000000,64.800000000,7,5,7,5,64.720000000,64.810000000,9,8,6,8,64.710000000,64.820000000,9,9,8,6,64.700000000,64.830000000,7,9,6,9,64.690000000,64.840000000,4,6,3,5,64.680000000,64.850000000,4,8,2,5,64.670000000,64.860000000,6,4,4,3,MCLN5
2025-06-11T00:00:18.706645760Z,2025-06-11T00:00:18.706534955Z,10,1,42026514,C,A,1,64.780000000,1,130,13062,79310102,64.760000000,64.770000000,5,2,5,1,64.750000000,64.780000000,5,3,5,3,64.740000000,64.790000000,9,6,8,4,64.730000000,64.800000000,7,5,7,5,64.720000000,64.810000000,9,8,6,8,64.710000000,64.820000000,9,9,8,6,64.700000000,64.830000000,7,9,6,9,64.690000000,64.840000000,4,6,3,5,64.680000000,64.850000000,4,8,2,5,64.670000000,64.860000000,6,4,4,3,MCLN5
2025-06-11T00:00:18.706656227Z,2025-06-11T00:00:18.706538239Z,10,1,42025623,C,B,5,63.620000000,1,130,11312,79310103,63.670000000,63.700000000,2,3,2,3,63.660000000,63.710000000,3,2,3,2,63.650000000,63.720000000,2,2,2,2,63.640000000,63.730000000,5,2,5,2,63.630000000,63.740000000,5,7,5,7,63.620000000,63.750000000,3,2,3,2,63.610000000,63.760000000,2,4,2,4,63.600000000,63.770000000,7,1,7,1,63.590000000,63.780000000,1,3,1,3,63.580000000,63.790000000,6,1,4,1,MCLQ5
2025-06-11T00:00:18.706666718Z,2025-06-11T00:00:18.706541867Z,10,1,42025623,M,B,3,63.630000000,1,130,11469,79310104,63.670000000,63.700000000,2,3,2,3,63.660000000,63.710000000,3,2,3,2,63.650000000,63.720000000,2,2,2,2,63.640000000,63.730000000,4,2,4,2,63.630000000,63.740000000,6,7,6,7,63.620000000,63.750000000,3,2,3,2,63.610000000,63.760000000,2,4,2,4,63.600000000,63.770000000,7,1,7,1,63.590000000,63.780000000,1,3,1,3,63.580000000,63.790000000,6,1,4,1,MCLQ5
2025-06-11T00:00:18.706686884Z,2025-06-11T00:00:18.706542329Z,10,1,42025623,M,A,3,63.730000000,1,130,11748,79310105,63.670000000,63.700000000,2,3,2,3,63.660000000,63.710000000,3,2,3,2,63.650000000,63.720000000,2,2,2,2,63.640000000,63.730000000,4,3,4,3,63.630000000,63.740000000,6,6,6,6,63.620000000,63.750000000,3,2,3,2,63.610000000,63.760000000,2,4,2,4,63.600000000,63.770000000,7,1,7,1,63.590000000,63.780000000,1,3,1,3,63.580000000,63.790000000,6,1,4,1,MCLQ5
2025-06-11T00:00:18.706698726Z,2025-06-11T00:00:18.706542751Z,10,1,42025623,M,B,3,63.630000000,1,130,12058,79310106,63.670000000,63.700000000,2,3,2,3,63.660000000,63.710000000,3,2,3,2,63.650000000,63.720000000,2,2,2,2,63.640000000,63.730000000,3,3,3,3,63.630000000,63.740000000,7,6,7,6,63.620000000,63.750000000,3,2,3,2,63.610000000,63.760000000,2,4,2,4,63.600000000,63.770000000,7,1,7,1,63.590000000,63.780000000,1,3,1,3,63.580000000,63.790000000,6,1,4,1,MCLQ5
2025-06-11T00:00:18.706709063Z,2025-06-11T00:00:18.706543231Z,10,1,42025623,M,A,3,63.730000000,1,130,11368,79310107,63.670000000,63.700000000,2,3,2,3,63.660000000,63.710000000,3,2,3,2,63.650000000,63.720000000,2,2,2,2,63.640000000,63.730000000,3,4,3,4,63.630000000,63.740000000,7,5,7,5,63.620000000,63.750000000,3,2,3,2,63.610000000,63.760000000,2,4,2,4,63.600000000,63.770000000,7,1,7,1,63.590000000,63.780000000,1,3,1,3,63.580000000,63.790000000,6,1,4,1,MCLQ5
2025-06-11T00:00:18.706723477Z,2025-06-11T00:00:18.706546055Z,10,1,42025623,C,A,6,63.760000000,1,130,14684,79310108,63.670000000,63.700000000,2,3,2,3,63.660000000,63.710000000,3,2,3,2,63.650000000,63.720000000,2,2,2,2,63.640000000,63.730000000,3,4,3,4,63.630000000,63.740000000,7,5,7,5,63.620000000,63.750000000,3,2,3,2,63.610000000,63.760000000,2,3,2,3,63.600000000,63.770000000,7,1,7,1,63.590000000,63.780000000,1,3,1,3,63.580000000,63.790000000,6,1,4,1,MCLQ5
2025-06-11T00:00:18.706790628Z,2025-06-11T00:00:18.706685037Z,10,1,42025623,A,B,6,63.610000000,1,130,12364,79310109,63.670000000,63.700000000,2,3,2,3,63.660000000,63.710000000,3,2,3,2,63.650000000,63.720000000,2,2,2,2,63.640000000,63.730000000,3,4,3,4,63.630000000,63.740000000,7,5,7,5,63.620000000,63.750000000,3,2,3,2,63.610000000,63.760000000,3,3,3,3,63.600000000,63.770000000,7,1,7,1,63.590000000,63.780000000,1,3,1,3,63.580000000,63.790000000,6,1,4,1,MCLQ5
2025-06-11T00:00:18.706859022Z,2025-06-11T00:00:18.706766403Z,10,1,42025623,A,A,5,63.750000000,1,130,14635,79310110,63.670000000,63.700000000,2,3,2,3,63.660000000,63.710000000,3,2,3,2,63.650000000,63.720000000,2,2,2,2,63.640000000,63.730000000,3,4,3,4,63.630000000,63.740000000,7,5,7,5,63.620000000,63.750000000,3,3,3,3,63.610000000,63.760000000,3,3,3,3,63.600000000,63.770000000,7,1,7,1,63.590000000,63.780000000,1,3,1,3,63.580000000,63.790000000,6,1,4,1,MCLQ5
2025-06-11T00:00:18.722534851Z,2025-06-11T00:00:18.722409699Z,10,1,42026514,C,A,0,64.770000000,2,130,15734,79310111,64.760000000,64.780000000,5,3,5,3,64.750000000,64.790000000,5,6,5,4,64.740000000,64.800000000,9,5,8,5,64.730000000,64.810000000,7,8,7,8,64.720000000,64.820000000,9,9,6,6,64.710000000,64.830000000,9,9,8,9,64.700000000,64.840000000,7,6,6,5,64.690000000,64.850000000,4,8,3,5,64.680000000,64.860000000,4,4,2,3,64.670000000,64.870000000,6,4,4,3,MCLN5
2025-06-11T00:00:18.722655214Z,2025-06-11T00:00:18.722544879Z,10,1,42026514,A,A,0,64.780000000,1,130,16635,79310114,64.760000000,64.780000000,5,4,5,4,64.750000000,64.790000000,5,6,5,4,64.740000000,64.800000000,9,5,8,5,64.730000000,64.810000000,7,8,7,8,64.720000000,64.820000000,9,9,6,6,64.710000000,64.830000000,9,9,8,9,64.700000000,64.840000000,7,6,6,5,64.690000000,64.850000000,4,8,3,5,64.680000000,64.860000000,4,4,2,3,64.670000000,64.870000000,6,4,4,3,MCLN5
2025-06-11T00:00:18.722665335Z,2025-06-11T00:00:18.722555535Z,10,1,42025623,C,A,5,63.750000000,1,130,10725,79310115,63.670000000,63.700000000,2,3,2,3,63.660000000,63.710000000,3,2,3,2,63.650000000,63.720000000,2,2,2,2,63.640000000,63.730000000,3,4,3,4,63.630000000,63.740000000,7,5,7,5,63.620000000,63.750000000,3,2,3,2,63.610000000,63.760000000,3,3,3,3,63.600000000,63.770000000,7,1,7,1,63.590000000,63.780000000,1,3,1,3,63.580000000,63.790000000,6,1,4,1,MCLQ5
2025-06-11T00:00:18.722672063Z,2025-06-11T00:00:18.722560411Z,10,1,42025623,C,B,6,63.610000000,1,130,11249,79310116,63.670000000,63.700000000,2,3,2,3,63.660000000,63.710000000,3,2,3,2,63.650000000,63.720000000,2,2,2,2,63.640000000,63.730000000,3,4,3,4,63.630000000,63.740000000,7,5,7,5,63.620000000,63.750000000,3,2,3,2,63.610000000,63.760000000,2,3,2,3,63.600000000,63.770000000,7,1,7,1,63.590000000,63.780000000,1,3,1,3,63.580000000,63.790000000,6,1,4,1,MCLQ5
2025-06-11T00:00:18.722791473Z,2025-06-11T00:00:18.722677487Z,10,1,42026514,A,A,0,64.770000000,2,130,15100,79310117,64.760000000,64.770000000,5,2,5,1,64.750000000,64.780000000,5,4,5,4,64.740000000,64.790000000,9,6,8,4,64.730000000,64.800000000,7,5,7,5,64.720000000,64.810000000,9,8,6,8,64.710000000,64.820000000,9,9,8,6,64.700000000,64.830000000,7,9,6,9,64.690000000,64.840000000,4,6,3,5,64.680000000,64.850000000,4,8,2,5,64.670000000,64.860000000,6,4,4,3,MCLN5
2025-06-11T00:00:18.722809090Z,2025-06-11T00:00:18.722708687Z,10,1,42025623,A,A,6,63.760000000,1,130,11918,79310119,63.670000000,63.700000000,2,3,2,3,63.660000000,63.710000000,3,2,3,2,63.650000000,63.720000000,2,2,2,2,63.640000000,63.730000000,3,4,3,4,63.630000000,63.740000000,7,5,7,5,63.620000000,63.750000000,3,2,3,2,63.610000000,63.760000000,2,4,2,4,63.600000000,63.770000000,7,1,7,1,63.590000000,63.780000000,1,3,1,3,63.580000000,63.790000000,6,1,4,1,MCLQ5
2025-06-11T00:00:18.722819403Z,2025-06-11T00:00:18.722716635Z,10,1,42025623,A,B,5,63.620000000,1,130,11455,79310120,63.670000000,63.700000000,2,3,2,3,63.660000000,63.710000000,3,2,3,2,63.650000000,63.720000000,2,2,2,2,63.640000000,63.730000000,3,4,3,4,63.630000000,63.740000000,7,5,7,5,63.620000000,63.750000000,4,2,4,2,63.610000000,63.760000000,2,4,2,4,63.600000000,63.770000000,7,1,7,1,63.590000000,63.780000000,1,3,1,3,63.580000000,63.790000000,6,1,4,1,MCLQ5
2025-06-11T00:00:18.722894640Z,2025-06-11T00:00:18.722800113Z,10,1,42026514,C,A,1,64.780000000,1,130,16001,79310121,64.760000000,64.770000000,5,2,5,1,64.750000000,64.780000000,5,3,5,3,64.740000000,64.790000000,9,6,8,4,64.730000000,64.800000000,7,5,7,5,64.720000000,64.810000000,9,8,6,8,64.710000000,64.820000000,9,9,8,6,64.700000000,64.830000000,7,9,6,9,64.690000000,64.840000000,4,6,3,5,64.680000000,64.850000000,4,8,2,5,64.670000000,64.860000000,6,4,4,3,MCLN5
2025-06-11T00:00:18.722914431Z,2025-06-11T00:00:18.722828815Z,10,1,42025623,C,A,6,63.760000000,1,130,11364,79310122,63.670000000,63.700000000,2,3,2,3,63.660000000,63.710000000,3,2,3,2,63.650000000,63.720000000,2,2,2,2,63.640000000,63.730000000,3,4,3,4,63.630000000,63.740000000,7,5,7,5,63.620000000,63.750000000,4,2,4,2,63.610000000,63.760000000,2,3,2,3,63.600000000,63.770000000,7,1,7,1,63.590000000,63.780000000,1,3,1,3,63.580000000,63.790000000,6,1,4,1,MCLQ5
2025-06-11T00:00:18.723037112Z,2025-06-11T00:00:18.722945681Z,10,1,42025623,A,A,5,63.750000000,1,130,14885,79310123,63.670000000,63.700000000,2,3,2,3,63.660000000,63.710000000,3,2,3,2,63.650000000,63.720000000,2,2,2,2,63.640000000,63.730000000,3,4,3,4,63.630000000,63.740000000,7,5,7,5,63.620000000,63.750000000,4,3,4,3,63.610000000,63.760000000,2,3,2,3,63.600000000,63.770000000,7,1,7,1,63.590000000,63.780000000,1,3,1,3,63.580000000,63.790000000,6,1,4,1,MCLQ5
2025-06-11T00:00:18.723136723Z,2025-06-11T00:00:18.723044249Z,10,1,42025623,C,B,5,63.620000000,1,130,14883,79310124,63.670000000,63.700000000,2,3,2,3,63.660000000,63.710000000,3,2,3,2,63.650000000,63.720000000,2,2,2,2,63.640000000,63.730000000,3,4,3,4,63.630000000,63.740000000,7,5,7,5,63.620000000,63.750000000,3,3,3,3,63.610000000,63.760000000,2,3,2,3,63.600000000,63.770000000,7,1,7,1,63.590000000,63.780000000,1,3,1,3,63.580000000,63.790000000,6,1,4,1,MCLQ5
2025-06-11T00:00:18.723268759Z,2025-06-11T00:00:18.723173747Z,10,1,42025623,A,B,6,63.610000000,1,130,14516,79310125,63.670000000,63.700000000,2,3,2,3,63.660000000,63.710000000,3,2,3,2,63.650000000,63.720000000,2,2,2,2,63.640000000,63.730000000,3,4,3,4,63.630000000,63.740000000,7,5,7,5,63.620000000,63.750000000,3,3,3,3,63.610000000,63.760000000,3,3,3,3,63.600000000,63.770000000,7,1,7,1,63.590000000,63.780000000,1,3,1,3,63.580000000,63.790000000,6,1,4,1,MCLQ5
2025-06-11T00:00:18.735705350Z,2025-06-11T00:00:18.735588149Z,10,1,42026514,C,A,0,64.770000000,2,130,14864,79310143,64.760000000,64.780000000,5,3,5,3,64.750000000,64.790000000,5,6,5,4,64.740000000,64.800000000,9,5,8,5,64.730000000,64.810000000,7,8,7,8,64.720000000,64.820000000,9,9,6,6,64.710000000,64.830000000,9,9,8,9,64.700000000,64.840000000,7,6,6,5,64.690000000,64.850000000,4,8,3,5,64.680000000,64.860000000,4,4,2,3,64.670000000,64.870000000,6,4,4,3,MCLN5
2025-06-11T00:00:18.735822057Z,2025-06-11T00:00:18.735714517Z,10,1,42026514,A,A,0,64.780000000,1,130,16427,79310146,64.760000000,64.780000000,5,4,5,4,64.750000000,64.790000000,5,6,5,4,64.740000000,64.800000000,9,5,8,5,64.730000000,64.810000000,7,8,7,8,64.720000000,64.820000000,9,9,6,6,64.710000000,64.830000000,9,9,8,9,64.700000000,64.840000000,7,6,6,5,64.690000000,64.850000000,4,8,3,5,64.680000000,64.860000000,4,4,2,3,64.670000000,64.870000000,6,4,4,3,MCLN5
2025-06-11T00:00:18.735829591Z,2025-06-11T00:00:18.735725885Z,10,1,42025623,C,A,5,63.750000000,1,130,11763,79310147,63.670000000,63.700000000,2,3,2,3,63.660000000,63.710000000,3,2,3,2,63.650000000,63.720000000,2,2,2,2,63.640000000,63.730000000,3,4,3,4,63.630000000,63.740000000,7,5,7,5,63.620000000,63.750000000,3,2,3,2,63.610000000,63.760000000,3,3,3,3,63.600000000,63.770000000,7,1,7,1,63.590000000,63.780000000,1,3,1,3,63.580000000,63.790000000,6,1,4,1,MCLQ5
2025-06-11T00:00:18.735839712Z,2025-06-11T00:00:18.735730089Z,10,1,42025623,C,B,6,63.610000000,1,130,11355,79310148,63.670000000,63.700000000,2,3,2,3,63.660000000,63.710000000,3,2,3,2,63.650000000,63.720000000,2,2,2,2,63.640000000,63.730000000,3,4,3,4,63.630000000,63.740000000,7,5,7,5,63.620000000,63.750000000,3,2,3,2,63.610000000,63.760000000,2,3,2,3,63.600000000,63.770000000,7,1,7,1,63.590000000,63.780000000,1,3,1,3,63.580000000,63.790000000,6,1,4,1,MCLQ5
2025-06-11T00:00:18.735945069Z,2025-06-11T00:00:18.735853519Z,10,1,42025623,A,A,6,63.760000000,1,130,14512,79310149,63.670000000,63.700000000,2,3,2,3,63.660000000,63.710000000,3,2,3,2,63.650000000,63.720000000,2,2,2,2,63.640000000,63.730000000,3,4,3,4,63.630000000,63.740000000,7,5,7,5,63.620000000,63.750000000,3,2,3,2,63.610000000,63.760000000,2,4,2,4,63.600000000,63.770000000,7,1,7,1,63.590000000,63.780000000,1,3,1,3,63.580000000,63.790000000,6,1,4,1,MCLQ5
2025-06-11T00:00:18.735953278Z,2025-06-11T00:00:18.735858185Z,10,1,42025623,A,B,5,63.620000000,1,130,11239,79310150,63.670000000,63.700000000,2,3,2,3,63.660000000,63.710000000,3,2,3,2,63.650000000,63.720000000,2,2,2,2,63.640000000,63.730000000,3,4,3,4,63.630000000,63.740000000,7,5,7,5,63.620000000,63.750000000,4,2,4,2,63.610000000,63.760000000,2,4,2,4,63.600000000,63.770000000,7,1,7,1,63.590000000,63.780000000,1,3,1,3,63.580000000,63.790000000,6,1,4,1,MCLQ5
2025-06-11T00:00:18.874134333Z,2025-06-11T00:00:18.873989723Z,10,1,42026514,A,A,0,64.770000000,2,130,14692,79310170,64.760000000,64.770000000,5,2,5,1,64.750000000,64.780000000,5,4,5,4,64.740000000,64.790000000,9,6,8,4,64.730000000,64.800000000,7,5,7,5,64.720000000,64.810000000,9,8,6,8,64.710000000,64.820000000,9,9,8,6,64.700000000,64.830000000,7,9,6,9,64.690000000,64.840000000,4,6,3,5,64.680000000,64.850000000,4,8,2,5,64.670000000,64.860000000,6,4,4,3,MCLN5
2025-06-11T00:00:18.874241095Z,2025-06-11T00:00:18.874144641Z,10,1,42026514,C,A,1,64.780000000,1,130,16486,79310174,64.760000000,64.770000000,5,2,5,1,64.750000000,64.780000000,5,3,5,3,64.740000000,64.790000000,9,6,8,4,64.730000000,64.800000000,7,5,7,5,64.720000000,64.810000000,9,8,6,8,64.710000000,64.820000000,9,9,8,6,64.700000000,64.830000000,7,9,6,9,64.690000000,64.840000000,4,6,3,5,64.680000000,64.850000000,4,8,2,5,64.670000000,64.860000000,6,4,4,3,MCLN5
2025-06-11T00:00:18.874250348Z,2025-06-11T00:00:18.874155431Z,10,1,42025623,C,B,5,63.620000000,1,130,13379,79310175,63.670000000,63.700000000,2,3,2,3,63.660000000,63.710000000,3,2,3,2,63.650000000,63.720000000,2,2,2,2,63.640000000,63.730000000,3,4,3,4,63.630000000,63.740000000,7,5,7,5,63.620000000,63.750000000,3,2,3,2,63.610000000,63.760000000,2,4,2,4,63.600000000,63.770000000,7,1,7,1,63.590000000,63.780000000,1,3,1,3,63.580000000,63.790000000,6,1,4,1,MCLQ5
2025-06-11T00:00:18.874258343Z,2025-06-11T00:00:18.874160959Z,10,1,42025623,C,A,6,63.760000000,1,130,11258,79310176,63.670000000,63.700000000,2,3,2,3,63.660000000,63.710000000,3,2,3,2,63.650000000,63.720000000,2,2,2,2,63.640000000,63.730000000,3,4,3,4,63.630000000,63.740000000,7,5,7,5,63.620000000,63.750000000,3,2,3,2,63.610000000,63.760000000,2,3,2,3,63.600000000,63.770000000,7,1,7,1,63.590000000,63.780000000,1,3,1,3,63.580000000,63.790000000,6,1,4,1,MCLQ5
2025-06-11T00:00:18.874372538Z,2025-06-11T00:00:18.874274445Z,10,1,42025623,A,B,6,63.610000000,1,130,15568,79310177,63.670000000,63.700000000,2,3,2,3,63.660000000,63.710000000,3,2,3,2,63.650000000,63.720000000,2,2,2,2,63.640000000,63.730000000,3,4,3,4,63.630000000,63.740000000,7,5,7,5,63.620000000,63.750000000,3,2,3,2,63.610000000,63.760000000,3,3,3,3,63.600000000,63.770000000,7,1,7,1,63.590000000,63.780000000,1,3,1,3,63.580000000,63.790000000,6,1,4,1,MCLQ5
2025-06-11T00:00:18.874381347Z,2025-06-11T00:00:18.874289305Z,10,1,42025623,A,A,5,63.750000000,1,130,11371,79310178,63.670000000,63.700000000,2,3,2,3,63.660000000,63.710000000,3,2,3,2,63.650000000,63.720000000,2,2,2,2,63.640000000,63.730000000,3,4,3,4,63.630000000,63.740000000,7,5,7,5,63.620000000,63.750000000,3,3,3,3,63.610000000,63.760000000,3,3,3,3,63.600000000,63.770000000,7,1,7,1,63.590000000,63.780000000,1,3,1,3,63.580000000,63.790000000,6,1,4,1,MCLQ5
2025-06-11T00:00:18.890885243Z,2025-06-11T00:00:18.890762137Z,10,1,42026514,C,A,0,64.770000000,2,130,15334,79310179,64.760000000,64.780000000,5,3,5,3,64.750000000,64.790000000,5,6,5,4,64.740000000,64.800000000,9,5,8,5,64.730000000,64.810000000,7,8,7,8,64.720000000,64.820000000,9,9,6,6,64.710000000,64.830000000,9,9,8,9,64.700000000,64.840000000,7,6,6,5,64.690000000,64.850000000,4,8,3,5,64.680000000,64.860000000,4,4,2,3,64.670000000,64.870000000,6,4,4,3,MCLN5
2025-06-11T00:00:18.891001643Z,2025-06-11T00:00:18.890906881Z,10,1,42025623,C,A,5,63.750000000,1,130,15724,79310182,63.670000000,63.700000000,2,3,2,3,63.660000000,63.710000000,3,2,3,2,63.650000000,63.720000000,2,2,2,2,63.640000000,63.730000000,3,4,3,4,63.630000000,63.740000000,7,5,7,5,63.620000000,63.750000000,3,2,3,2,63.610000000,63.760000000,3,3,3,3,63.600000000,63.770000000,7,1,7,1,63.590000000,63.780000000,1,3,1,3,63.580000000,63.790000000,6,1,4,1,MCLQ5
2025-06-11T00:00:18.891010167Z,2025-06-11T00:00:18.890911335Z,10,1,42025623,C,B,6,63.610000000,1,130,11405,79310183,63.670000000,63.700000000,2,3,2,3,63.660000000,63.710000000,3,2,3,2,63.650000000,63.720000000,2,2,2,2,63.640000000,63.730000000,3,4,3,4,63.630000000,63.740000000,7,5,7,5,63.620000000,63.750000000,3,2,3,2,63.610000000,63.760000000,2,3,2,3,63.600000000,63.770000000,7,1,7,1,63.590000000,63.780000000,1,3,1,3,63.580000000,63.790000000,6,1,4,1,MCLQ5
2025-06-11T00:00:18.891134576Z,2025-06-11T00:00:18.891037665Z,10,1,42025623,A,A,6,63.760000000,1,130,15080,79310184,63.670000000,63.700000000,2,3,2,3,63.660000000,63.710000000,3,2,3,2,63.650000000,63.720000000,2,2,2,2,63.640000000,63.730000000,3,4,3,4,63.630000000,63.740000000,7,5,7,5,63.620000000,63.750000000,3,2,3,2,63.610000000,63.760000000,2,4,2,4,63.600000000,63.770000000,7,1,7,1,63.590000000,63.780000000,1,3,1,3,63.580000000,63.790000000,6,1,4,1,MCLQ5
2025-06-11T00:00:18.891143585Z,2025-06-11T00:00:18.891045747Z,10,1,42025623,A,B,5,63.620000000,1,130,11388,79310185,63.670000000,63.700000000,2,3,2,3,63.660000000,63.710000000,3,2,3,2,63.650000000,63.720000000,2,2,2,2,63.640000000,63.730000000,3,4,3,4,63.630000000,63.740000000,7,5,7,5,63.620000000,63.750000000,4,2,4,2,63.610000000,63.760000000,2,4,2,4,63.600000000,63.770000000,7,1,7,1,63.590000000,63.780000000,1,3,1,3,63.580000000,63.790000000,6,1,4,1,MCLQ5
2025-06-11T00:00:18.892000651Z,2025-06-11T00:00:18.891885635Z,10,1,42026514,M,B,1,62.770000000,2,130,16671,79310186,64.760000000,64.780000000,5,3,5,3,64.750000000,64.790000000,4,6,4,4,64.740000000,64.800000000,9,5,8,5,64.730000000,64.810000000,7,8,7,8,64.720000000,64.820000000,9,9,6,6,64.710000000,64.830000000,9,9,8,9,64.700000000,64.840000000,7,6,6,5,64.690000000,64.850000000,4,8,3,5,64.680000000,64.860000000,4,4,2,3,64.670000000,64.870000000,6,4,4,3,MCLN5
2025-06-11T00:00:19.025853838Z,2025-06-11T00:00:19.025720785Z,10,1,42026514,A,A,0,64.770000000,2,130,15019,79310195,64.760000000,64.770000000,5,2,5,1,64.750000000,64.780000000,4,3,4,3,64.740000000,64.790000000,9,6,8,4,64.730000000,64.800000000,7,5,7,5,64.720000000,64.810000000,9,8,6,8,64.710000000,64.820000000,9,9,8,6,64.700000000,64.830000000,7,9,6,9,64.690000000,64.840000000,4,6,3,5,64.680000000,64.850000000,4,8,2,5,64.670000000,64.860000000,6,4,4,3,MCLN5
2025-06-11T00:00:19.025966489Z,2025-06-11T00:00:19.025875837Z,10,1,42025623,C,B,5,63.620000000,1,130,15122,79310198,63.670000000,63.700000000,2,3,2,3,63.660000000,63.710000000,3,2,3,2,63.650000000,63.720000000,2,2,2,2,63.640000000,63.730000000,3,4,3,4,63.630000000,63.740000000,7,5,7,5,63.620000000,63.750000000,3,2,3,2,63.610000000,63.760000000,2,4,2,4,63.600000000,63.770000000,7,1,7,1,63.590000000,63.780000000,1,3,1,3,63.580000000,63.790000000,6,1,4,1,MCLQ5
2025-06-11T00:00:19.025974753Z,2025-06-11T00:00:19.025880695Z,10,1,42025623,C,A,6,63.760000000,1,130,11263,79310199,63.670000000,63.700000000,2,3,2,3,63.660000000,63.710000000,3,2,3,2,63.650000000,63.720000000,2,2,2,2,63.640000000,63.730000000,3,4,3,4,63.630000000,63.740000000,7,5,7,5,63.620000000,63.750000000,3,2,3,2,63.610000000,63.760000000,2,3,2,3,63.600000000,63.770000000,7,1,7,1,63.590000000,63.780000000,1,3,1,3,63.580000000,63.790000000,6,1,4,1,MCLQ5
2025-06-11T00:00:19.205686063Z,2025-06-11T00:00:19.205265447Z,10,1,42026514,C,A,0,64.770000000,2,130,11765,79310246,64.760000000,64.780000000,5,3,5,3,64.750000000,64.790000000,4,6,4,4,64.740000000,64.800000000,9,5,8,5,64.730000000,64.810000000,7,8,7,8,64.720000000,64.820000000,9,9,6,6,64.710000000,64.830000000,9,9,8,9,64.700000000,64.840000000,7,6,6,5,64.690000000,64.850000000,4,8,3,5,64.680000000,64.860000000,4,4,2,3,64.670000000,64.870000000,6,4,4,3,MCLN5
2025-06-11T00:00:19.205720199Z,2025-06-11T00:00:19.205266215Z,10,1,42025611,A,B,0,2.070000000,2,130,11086,79310249,2.070000000,2.080000000,3,6,2,3,2.060000000,2.090000000,23,27,3,6,2.050000000,2.100000000,23,27,3,6,2.040000000,2.110000000,23,22,3,3,2.030000000,2.120000000,2,2,1,1,2.020000000,2.130000000,2,2,2,2,2.010000000,2.140000000,2,2,1,1,2.000000000,2.150000000,2,2,2,1,1.990000000,2.160000000,2,2,1,1,1.980000000,2.170000000,2,2,2,1,MCLN5-MCLU5
2025-06-11T00:00:19.205928946Z,2025-06-11T00:00:19.205695507Z,10,1,42026514,M,A,3,64.820000000,1,130,11727,79310260,64.760000000,64.780000000,5,3,5,3,64.750000000,64.790000000,4,6,4,4,64.740000000,64.800000000,9,5,8,5,64.730000000,64.810000000,7,7,7,7,64.720000000,64.820000000,9,10,6,7,64.710000000,64.830000000,9,9,8,9,64.700000000,64.840000000,7,6,6,5,64.690000000,64.850000000,4,8,3,5,64.680000000,64.860000000,4,4,2,3,64.670000000,64.870000000,6,4,4,3,MCLN5
2025-06-11T00:00:19.205938266Z,2025-06-11T00:00:19.205696063Z,10,1,42026514,M,B,3,64.730000000,1,130,12337,79310261,64.760000000,64.780000000,5,3,5,3,64.750000000,64.790000000,4,6,4,4,64.740000000,64.800000000,9,5,8,5,64.730000000,64.810000000,8,7,8,7,64.720000000,64.820000000,8,10,5,7,64.710000000,64.830000000,9,9,8,9,64.700000000,64.840000000,7,6,6,5,64.690000000,64.850000000,4,8,3,5,64.680000000,64.860000000,4,4,2,3,64.670000000,64.870000000,6,4,4,3,MCLN5
2025-06-11T00:00:19.205958259Z,2025-06-11T00:00:19.205697139Z,10,1,42026514,A,A,0,64.780000000,1,130,13028,79310262,64.760000000,64.780000000,5,4,5,4,64.750000000,64.790000000,4,6,4,4,64.740000000,64.800000000,9,5,8,5,64.730000000,64.810000000,8,7,8,7,64.720000000,64.820000000,8,10,5,7,64.710000000,64.830000000,9,9,8,9,64.700000000,64.840000000,7,6,6,5,64.690000000,64.850000000,4,8,3,5,64.680000000,64.860000000,4,4,2,3,64.670000000,64.870000000,6,4,4,3,MCLN5
2025-06-11T00:00:19.205969248Z,2025-06-11T00:00:19.205712077Z,10,1,42025623,M,A,3,63.740000000,1,130,11523,79310263,63.670000000,63.700000000,2,3,2,3,63.660000000,63.710000000,3,2,3,2,63.650000000,63.720000000,2,2,2,2,63.640000000,63.730000000,3,3,3,3,63.630000000,63.740000000,7,6,7,6,63.620000000,63.750000000,3,2,3,2,63.610000000,63.760000000,2,3,2,3,63.600000000,63.770000000,7,1,7,1,63.590000000,63.780000000,1,3,1,3,63.580000000,63.790000000,6,1,4,1,MCLQ5
2025-06-11T00:00:19.205982081Z,2025-06-11T00:00:19.205712729Z,10,1,42025623,M,B,3,63.640000000,1,130,11351,79310264,63.670000000,63.700000000,2,3,2,3,63.660000000,63.710000000,3,2,3,2,63.650000000,63.720000000,2,2,2,2,63.640000000,63.730000000,4,3,4,3,63.630000000,63.740000000,6,6,6,6,63.620000000,63.750000000,3,2,3,2,63.610000000,63.760000000,2,3,2,3,63.600000000,63.770000000,7,1,7,1,63.590000000,63.780000000,1,3,1,3,63.580000000,63.790000000,6,1,4,1,MCLQ5
2025-06-11T00:00:19.205992948Z,2025-06-11T00:00:19.205713209Z,10,1,42025623,M,A,3,63.740000000,1,130,11451,79310265,63.670000000,63.700000000,2,3,2,3,63.660000000,63.710000000,3,2,3,2,63.650000000,63.720000000,2,2,2,2,63.640000000,63.730000000,4,2,4,2,63.630000000,63.740000000,6,7,6,7,63.620000000,63.750000000,3,2,3,2,63.610000000,63.760000000,2,3,2,3,63.600000000,63.770000000,7,1,7,1,63.590000000,63.780000000,1,3,1,3,63.580000000,63.790000000,6,1,4,1,MCLQ5
2025-06-11T00:00:19.206004498Z,2025-06-11T00:00:19.205713689Z,10,1,42025623,M,B,3,63.640000000,1,130,11657,79310266,63.670000000,63.700000000,2,3,2,3,63.660000000,63.710000000,3,2,3,2,63.650000000,63.720000000,2,2,2,2,63.640000000,63.730000000,5,2,5,2,63.630000000,63.740000000,5,7,5,7,63.620000000,63.750000000,3,2,3,2,63.610000000,63.760000000,2,3,2,3,63.600000000,63.770000000,7,1,7,1,63.590000000,63.780000000,1,3,1,3,63.580000000,63.790000000,6,1,4,1,MCLQ5
2025-06-11T00:00:19.206102074Z,2025-06-11T00:00:19.205987795Z,10,1,42026514,A,A,0,64.770000000,2,130,11430,79310268,64.760000000,64.770000000,5,2,5,1,64.750000000,64.780000000,4,4,4,4,64.740000000,64.790000000,9,6,8,4,64.730000000,64.800000000,8,5,8,5,64.720000000,64.810000000,8,7,5,7,64.710000000,64.820000000,9,10,8,7,64.700000000,64.830000000,7,9,6,9,64.690000000,64.840000000,4,6,3,5,64.680000000,64.850000000,4,8,2,5,64.670000000,64.860000000,6,4,4,3,MCLN5
2025-06-11T00:00:19.206214919Z,2025-06-11T00:00:19.206110651Z,10,1,42026514,C,A,1,64.780000000,1,130,12581,79310272,64.760000000,64.770000000,5,2,5,1,64.750000000,64.780000000,4,3,4,3,64.740000000,64.790000000,9,6,8,4,64.730000000,64.800000000,8,5,8,5,64.720000000,64.810000000,8,7,5,7,64.710000000,64.820000000,9,10,8,7,64.700000000,64.830000000,7,9,6,9,64.690000000,64.840000000,4,6,3,5,64.680000000,64.850000000,4,8,2,5,64.670000000,64.860000000,6,4,4,3,MCLN5
2025-06-11T00:00:19.211166975Z,2025-06-11T00:00:19.210886113Z,10,1,42026514,A,B,0,64.760000000,1,130,12121,79310418,64.760000000,64.770000000,6,2,6,1,64.750000000,64.780000000,4,3,4,3,64.740000000,64.790000000,9,6,8,4,64.730000000,64.800000000,8,5,8,5,64.720000000,64.810000000,8,7,5,7,64.710000000,64.820000000,9,10,8,7,64.700000000,64.830000000,7,9,6,9,64.690000000,64.840000000,4,6,3,5,64.680000000,64.850000000,4,8,2,5,64.670000000,64.860000000,6,4,4,3,MCLN5
2025-06-11T00:00:19.211363496Z,2025-06-11T00:00:19.211048595Z,10,1,42026514,C,A,0,64.770000000,2,130,11337,79310426,64.760000000,64.780000000,6,3,6,3,64.750000000,64.790000000,4,6,4,4,64.740000000,64.800000000,9,5,8,5,64.730000000,64.810000000,8,7,8,7,64.720000000,64.820000000,8,10,5,7,64.710000000,64.830000000,9,9,8,9,64.700000000,64.840000000,7,6,6,5,64.690000000,64.850000000,4,8,3,5,64.680000000,64.860000000,4,4,2,3,64.670000000,64.870000000,6,4,4,3,MCLN5
2025-06-11T00:00:19.211540173Z,2025-06-11T00:00:19.211168417Z,10,1,42026514,A,B,0,64.770000000,2,130,16674,79310444,64.770000000,64.780000000,2,3,1,3,64.760000000,64.790000000,6,6,6,4,64.750000000,64.800000000,4,5,4,5,64.740000000,64.810000000,9,7,8,7,64.730000000,64.820000000,8,10,8,7,64.720000000,64.830000000,8,9,5,9,64.710000000,64.840000000,9,6,8,5,64.700000000,64.850000000,7,8,6,5,64.690000000,64.860000000,4,4,3,3,64.680000000,64.870000000,4,4,2,3,MCLN5
2025-06-11T00:00:19.212130158Z,2025-06-11T00:00:19.211372139Z,10,1,42026514,A,A,0,64.780000000,1,130,13779,79310474,64.770000000,64.780000000,2,4,1,4,64.760000000,64.790000000,6,6,6,4,64.750000000,64.800000000,4,5,4,5,64.740000000,64.810000000,9,7,8,7,64.730000000,64.820000000,8,10,8,7,64.720000000,64.830000000,8,9,5,9,64.710000000,64.840000000,9,6,8,5,64.700000000,64.850000000,7,8,6,5,64.690000000,64.860000000,4,4,3,3,64.680000000,64.870000000,4,4,2,3,MCLN5
2025-06-11T00:00:19.212300829Z,2025-06-11T00:00:19.211547503Z,10,1,42026514,C,A,5,64.830000000,1,130,12042,79310482,64.770000000,64.780000000,2,4,1,4,64.760000000,64.790000000,6,6,6,4,64.750000000,64.800000000,4,5,4,5,64.740000000,64.810000000,9,7,8,7,64.730000000,64.820000000,8,10,8,7,64.720000000,64.830000000,8,8,5,8,64.710000000,64.840000000,9,6,8,5,64.700000000,64.850000000,7,8,6,5,64.690000000,64.860000000,4,4,3,3,64.680000000,64.870000000,4,4,2,3,MCLN5
2025-06-11T00:00:19.212430223Z,2025-06-11T00:00:19.211701367Z,10,1,42025623,M,B,2,63.650000000,1,130,11529,79310489,63.670000000,63.700000000,2,3,2,3,63.660000000,63.710000000,3,2,3,2,63.650000000,63.720000000,3,2,3,2,63.640000000,63.730000000,5,2,5,2,63.630000000,63.740000000,5,7,5,7,63.620000000,63.750000000,3,2,3,2,63.610000000,63.760000000,2,3,2,3,63.600000000,63.770000000,7,1,7,1,63.590000000,63.780000000,1,3,1,3,63.580000000,63.790000000,6,1,4,1,MCLQ5
2025-06-11T00:00:19.212589797Z,2025-06-11T00:00:19.211729703Z,10,1,42026514,A,B,0,64.770000000,1,130,16861,79310496,64.770000000,64.780000000,3,4,2,4,64.760000000,64.790000000,6,6,6,4,64.750000000,64.800000000,4,5,4,5,64.740000000,64.810000000,9,7,8,7,64.730000000,64.820000000,8,10,8,7,64.720000000,64.830000000,8,8,5,8,64.710000000,64.840000000,9,6,8,5,64.700000000,64.850000000,7,8,6,5,64.690000000,64.860000000,4,4,3,3,64.680000000,64.870000000,4,4,2,3,MCLN5
2025-06-11T00:00:19.212686299Z,2025-06-11T00:00:19.211732547Z,10,1,42026514,C,A,0,64.780000000,1,130,17088,79310500,64.770000000,64.780000000,3,3,2,3,64.760000000,64.790000000,6,6,6,4,64.750000000,64.800000000,4,5,4,5,64.740000000,64.810000000,9,7,8,7,64.730000000,64.820000000,8,10,8,7,64.720000000,64.830000000,8,8,5,8,64.710000000,64.840000000,9,6,8,5,64.700000000,64.850000000,7,8,6,5,64.690000000,64.860000000,4,4,3,3,64.680000000,64.870000000,4,4,2,3,MCLN5
2025-06-11T00:00:19.213178814Z,2025-06-11T00:00:19.212250807Z,10,1,42026514,M,A,0,64.780000000,1,130,12496,79310530,64.770000000,64.780000000,3,4,2,4,64.760000000,64.790000000,6,6,6,4,64.750000000,64.800000000,4,5,4,5,64.740000000,64.810000000,9,7,8,7,64.730000000,64.820000000,8,10,8,7,64.720000000,64.830000000,8,8,5,8,64.710000000,64.840000000,9,6,8,5,64.700000000,64.850000000,7,8,6,5,64.690000000,64.860000000,4,4,3,3,64.680000000,64.870000000,4,4,2,3,MCLN5
2025-06-11T00:00:19.213644320Z,2025-06-11T00:00:19.212671461Z,10,1,42026514,A,A,0,64.780000000,1,130,13634,79310550,64.770000000,64.780000000,3,5,2,5,64.760000000,64.790000000,6,6,6,4,64.750000000,64.800000000,4,5,4,5,64.740000000,64.810000000,9,7,8,7,64.730000000,64.820000000,8,10,8,7,64.720000000,64.830000000,8,8,5,8,64.710000000,64.840000000,9,6,8,5,64.700000000,64.850000000,7,8,6,5,64.690000000,64.860000000,4,4,3,3,64.680000000,64.870000000,4,4,2,3,MCLN5
2025-06-11T00:00:19.213712077Z,2025-06-11T00:00:19.212694233Z,10,1,42026514,M,A,3,64.820000000,1,130,11359,79310554,64.770000000,64.780000000,3,5,2,5,64.760000000,64.790000000,6,6,6,4,64.750000000,64.800000000,4,5,4,5,64.740000000,64.810000000,9,6,8,6,64.730000000,64.820000000,8,11,8,8,64.720000000,64.830000000,8,8,5,8,64.710000000,64.840000000,9,6,8,5,64.700000000,64.850000000,7,8,6,5,64.690000000,64.860000000,4,4,3,3,64.680000000,64.870000000,4,4,2,3,MCLN5
2025-06-11T00:00:19.213719788Z,2025-06-11T00:00:19.212694693Z,10,1,42026514,M,B,3,64.740000000,1,130,11264,79310555,64.770000000,64.780000000,3,5,2,5,64.760000000,64.790000000,6,6,6,4,64.750000000,64.800000000,4,5,4,5,64.740000000,64.810000000,10,6,9,6,64.730000000,64.820000000,7,11,7,8,64.720000000,64.830000000,8,8,5,8,64.710000000,64.840000000,9,6,8,5,64.700000000,64.850000000,7,8,6,5,64.690000000,64.860000000,4,4,3,3,64.680000000,64.870000000,4,4,2,3,MCLN5
2025-06-11T00:00:19.213728089Z,2025-06-11T00:00:19.212695229Z,10,1,42026514,M,A,3,64.820000000,1,130,11396,79310556,64.770000000,64.780000000,3,5,2,5,64.760000000,64.790000000,6,6,6,4,64.750000000,64.800000000,4,5,4,5,64.740000000,64.810000000,10,5,9,5,64.730000000,64.820000000,7,12,7,9,64.720000000,64.830000000,8,8,5,8,64.710000000,64.840000000,9,6,8,5,64.700000000,64.850000000,7,8,6,5,64.690000000,64.860000000,4,4,3,3,64.680000000,64.870000000,4,4,2,3,MCLN5
2025-06-11T00:00:19.213737527Z,2025-06-11T00:00:19.212695729Z,10,1,42026514,M,B,3,64.740000000,1,130,11213,79310557,64.770000000,64.780000000,3,5,2,5,64.760000000,64.790000000,6,6,6,4,64.750000000,64.800000000,4,5,4,5,64.740000000,64.810000000,11,5,10,5,64.730000000,64.820000000,6,12,6,9,64.720000000,64.830000000,8,8,5,8,64.710000000,64.840000000,9,6,8,5,64.700000000,64.850000000,7,8,6,5,64.690000000,64.860000000,4,4,3,3,64.680000000,64.870000000,4,4,2,3,MCLN5
2025-06-11T00:00:19.213784942Z,2025-06-11T00:00:19.212841547Z,10,1,42025623,M,A,2,63.720000000,1,130,11902,79310560,63.670000000,63.700000000,2,3,2,3,63.660000000,63.710000000,3,2,3,2,63.650000000,63.720000000,3,3,3,3,63.640000000,63.730000000,5,2,5,2,63.630000000,63.740000000,5,7,5,7,63.620000000,63.750000000,3,2,3,2,63.610000000,63.760000000,2,3,2,3,63.600000000,63.770000000,7,1,7,1,63.590000000,63.780000000,1,3,1,3,63.580000000,63.790000000,6,1,4,1,MCLQ5
2025-06-11T00:00:19.216510399Z,2025-06-11T00:00:19.215777479Z,10,1,42026514,A,B,0,64.770000000,1,130,11435,79310754,64.770000000,64.780000000,4,5,3,5,64.760000000,64.790000000,6,6,6,4,64.750000000,64.800000000,4,5,4,5,64.740000000,64.810000000,11,5,10,5,64.730000000,64.820000000,6,12,6,9,64.720000000,64.830000000,8,8,5,8,64.710000000,64.840000000,9,6,8,5,64.700000000,64.850000000,7,8,6,5,64.690000000,64.860000000,4,4,3,3,64.680000000,64.870000000,4,4,2,3,MCLN5
2025-06-11T00:00:19.216727532Z,2025-06-11T00:00:19.215809735Z,10,1,42026514,M,B,3,64.730000000,1,130,11842,79310767,64.770000000,64.780000000,4,5,3,5,64.760000000,64.790000000,6,6,6,4,64.750000000,64.800000000,4,5,4,5,64.740000000,64.810000000,10,5,9,5,64.730000000,64.820000000,7,12,7,9,64.720000000,64.830000000,8,8,5,8,64.710000000,64.840000000,9,6,8,5,64.700000000,64.850000000,7,8,6,5,64.690000000,64.860000000,4,4,3,3,64.680000000,64.870000000,4,4,2,3,MCLN5
2025-06-11T00:00:19.216751715Z,2025-06-11T00:00:19.215810371Z,10,1,42026514,M,A,3,64.810000000,1,130,11676,79310770,64.770000000,64.780000000,4,5,3,5,64.760000000,64.790000000,6,6,6,4,64.750000000,64.800000000,4,5,4,5,64.740000000,64.810000000,10,6,9,6,64.730000000,64.820000000,7,11,7,8,64.720000000,64.830000000,8,8,5,8,64.710000000,64.840000000,9,6,8,5,64.700000000,64.850000000,7,8,6,5,64.690000000,64.860000000,4,4,3,3,64.680000000,64.870000000,4,4,2,3,MCLN5
2025-06-11T00:00:19.216759695Z,2025-06-11T00:00:19.215810733Z,10,1,42026514,M,B,3,64.730000000,1,130,11581,79310771,64.770000000,64.780000000,4,5,3,5,64.760000000,64.790000000,6,6,6,4,64.750000000,64.800000000,4,5,4,5,64.740000000,64.810000000,9,6,8,6,64.730000000,64.820000000,8,11,8,8,64.720000000,64.830000000,8,8,5,8,64.710000000,64.840000000,9,6,8,5,64.700000000,64.850000000,7,8,6,5,64.690000000,64.860000000,4,4,3,3,64.680000000,64.870000000,4,4,2,3,MCLN5
2025-06-11T00:00:19.216767935Z,2025-06-11T00:00:19.215811233Z,10,1,42026514,M,A,3,64.810000000,1,130,11422,79310772,64.770000000,64.780000000,4,5,3,5,64.760000000,64.790000000,6,6,6,4,64.750000000,64.800000000,4,5,4,5,64.740000000,64.810000000,9,7,8,7,64.730000000,64.820000000,8,10,8,7,64.720000000,64.830000000,8,8,5,8,64.710000000,64.840000000,9,6,8,5,64.700000000,64.850000000,7,8,6,5,64.690000000,64.860000000,4,4,3,3,64.680000000,64.870000000,4,4,2,3,MCLN5
2025-06-11T00:00:19.217220892Z,2025-06-11T00:00:19.216443575Z,10,1,42026514,M,B,1,64.760000000,1,130,11885,79310807,64.770000000,64.780000000,4,5,3,5,64.760000000,64.790000000,7,6,7,4,64.750000000,64.800000000,4,5,4,5,64.740000000,64.810000000,9,7,8,7,64.730000000,64.820000000,8,10,8,7,64.720000000,64.830000000,8,8,5,8,64.710000000,64.840000000,9,6,8,5,64.700000000,64.850000000,7,8,6,5,64.690000000,64.860000000,4,4,3,3,64.680000000,64.870000000,4,4,2,3,MCLN5
2025-06-11T00:00:19.217332930Z,2025-06-11T00:00:19.216557081Z,10,1,42025623,A,B,0,63.680000000,1,130,17799,79310816,63.680000000,63.700000000,1,3,1,3,63.670000000,63.710000000,2,2,2,2,63.660000000,63.720000000,3,3,3,3,63.650000000,63.730000000,3,2,3,2,63.640000000,63.740000000,5,7,5,7,63.630000000,63.750000000,5,2,5,2,63.620000000,63.760000000,3,3,3,3,63.610000000,63.770000000,2,1,2,1,63.600000000,63.780000000,7,3,7,3,63.590000000,63.790000000,1,1,1,1,MCLQ5
2025-06-11T00:00:19.217395649Z,2025-06-11T00:00:19.216752047Z,10,1,42418117,M,A,0,3.300000000,1,130,11796,79310823,3.250000000,3.280000000,1,11,1,2,3.240000000,3.290000000,11,1,2,1,3.230000000,3.300000000,1,1,1,1,,,0,0,0,0,,,0,0,0,0,,,0,0,0,0,,,0,0,0,0,,,0,0,0,0,,,0,0,0,0,,,0,0,0,0,MCLN5-MCLX5
2025-06-11T00:00:19.217432012Z,2025-06-11T00:00:19.216809627Z,10,1,42025611,M,A,0,2.110000000,1,130,15037,79310825,2.070000000,2.080000000,3,5,2,2,2.060000000,2.090000000,23,27,3,6,2.050000000,2.100000000,23,27,3,6,2.040000000,2.110000000,23,23,3,4,2.030000000,2.120000000,2,2,1,1,2.020000000,2.130000000,2,2,2,2,2.010000000,2.140000000,2,2,1,1,2.000000000,2.150000000,2,2,2,1,1.990000000,2.160000000,2,2,1,1,1.980000000,2.170000000,2,2,2,1,MCLN5-MCLU5
2025-06-11T00:00:19.217541139Z,2025-06-11T00:00:19.216871831Z,10,1,42026514,C,A,0,64.780000000,1,130,12712,79310833,64.770000000,64.780000000,4,4,3,4,64.760000000,64.790000000,7,6,7,4,64.750000000,64.800000000,4,5,4,5,64.740000000,64.810000000,9,7,8,7,64.730000000,64.820000000,8,10,8,7,64.720000000,64.830000000,8,8,5,8,64.710000000,64.840000000,9,6,8,5,64.700000000,64.850000000,7,8,6,5,64.690000000,64.860000000,4,4,3,3,64.680000000,64.870000000,4,4,2,3,MCLN5
2025-06-11T00:00:19.217561306Z,2025-06-11T00:00:19.216875519Z,10,1,42026514,C,A,0,64.780000000,1,130,16372,79310834,64.770000000,64.780000000,4,3,3,3,64.760000000,64.790000000,7,6,7,4,64.750000000,64.800000000,4,5,4,5,64.740000000,64.810000000,9,7,8,7,64.730000000,64.820000000,8,10,8,7,64.720000000,64.830000000,8,8,5,8,64.710000000,64.840000000,9,6,8,5,64.700000000,64.850000000,7,8,6,5,64.690000000,64.860000000,4,4,3,3,64.680000000,64.870000000,4,4,2,3,MCLN5
2025-06-11T00:00:19.218182562Z,2025-06-11T00:00:19.217414765Z,10,1,42418117,M,A,0,3.780000000,10,130,12313,79310887,3.250000000,3.280000000,1,1,1,1,3.240000000,3.290000000,11,1,2,1,3.230000000,3.300000000,1,1,1,1,,3.780000000,0,10,0,1,,,0,0,0,0,,,0,0,0,0,,,0,0,0,0,,,0,0,0,0,,,0,0,0,0,,,0,0,0,0,MCLN5-MCLX5
2025-06-11T00:00:19.218635466Z,2025-06-11T00:00:19.217716997Z,10,1,42026514,M,A,0,66.730000000,2,130,11720,79310910,64.770000000,64.780000000,4,2,3,2,64.760000000,64.790000000,7,6,7,4,64.750000000,64.800000000,4,5,4,5,64.740000000,64.810000000,9,7,8,7,64.730000000,64.820000000,8,10,8,7,64.720000000,64.830000000,8,8,5,8,64.710000000,64.840000000,9,6,8,5,64.700000000,64.850000000,7,8,6,5,64.690000000,64.860000000,4,4,3,3,64.680000000,64.870000000,4,4,2,3,MCLN5
2025-06-11T00:00:19.218695029Z,2025-06-11T00:00:19.217816813Z,10,1,42026514,M,B,1,62.770000000,2,130,15402,79310915,64.770000000,64.780000000,4,2,3,2,64.760000000,64.790000000,6,6,6,4,64.750000000,64.800000000,4,5,4,5,64.740000000,64.810000000,9,7,8,7,64.730000000,64.820000000,8,10,8,7,64.720000000,64.830000000,8,8,5,8,64.710000000,64.840000000,9,6,8,5,64.700000000,64.850000000,7,8,6,5,64.690000000,64.860000000,4,4,3,3,64.680000000,64.870000000,4,4,2,3,MCLN5
2025-06-11T00:00:19.219048221Z,2025-06-11T00:00:19.217949883Z,10,1,42026514,C,A,0,64.780000000,1,130,11570,79310936,64.770000000,64.780000000,4,1,3,1,64.760000000,64.790000000,6,6,6,4,64.750000000,64.800000000,4,5,4,5,64.740000000,64.810000000,9,7,8,7,64.730000000,64.820000000,8,10,8,7,64.720000000,64.830000000,8,8,5,8,64.710000000,64.840000000,9,6,8,5,64.700000000,64.850000000,7,8,6,5,64.690000000,64.860000000,4,4,3,3,64.680000000,64.870000000,4,4,2,3,MCLN5
2025-06-11T00:00:19.219639381Z,2025-06-11T00:00:19.218041215Z,10,1,42026514,C,A,0,64.780000000,1,130,14792,79310965,64.770000000,64.790000000,4,6,3,4,64.760000000,64.800000000,6,5,6,5,64.750000000,64.810000000,4,7,4,7,64.740000000,64.820000000,9,10,8,7,64.730000000,64.830000000,8,8,8,8,64.720000000,64.840000000,8,6,5,5,64.710000000,64.850000000,9,8,8,5,64.700000000,64.860000000,7,4,6,3,64.690000000,64.870000000,4,4,3,3,64.680000000,64.880000000,4,4,2,3,MCLN5
2025-06-11T00:00:19.219731659Z,2025-06-11T00:00:19.218045439Z,10,1,42026514,A,B,0,64.780000000,1,130,14582,79310970,64.780000000,64.790000000,1,6,1,4,64.770000000,64.800000000,4,5,3,5,64.760000000,64.810000000,6,7,6,7,64.750000000,64.820000000,4,10,4,7,64.740000000,64.830000000,9,8,8,8,64.730000000,64.840000000,8,6,8,5,64.720000000,64.850000000,8,8,5,5,64.710000000,64.860000000,9,4,8,3,64.700000000,64.870000000,7,4,6,3,64.690000000,64.880000000,4,4,3,3,MCLN5
2025-06-11T00:00:19.220700041Z,2025-06-11T00:00:19.218228905Z,10,1,42025623,A,B,0,63.680000000,1,130,12809,79311015,63.680000000,63.700000000,2,3,2,3,63.670000000,63.710000000,2,2,2,2,63.660000000,63.720000000,3,3,3,3,63.650000000,63.730000000,3,2,3,2,63.640000000,63.740000000,5,7,5,7,63.630000000,63.750000000,5,2,5,2,63.620000000,63.760000000,3,3,3,3,63.610000000,63.770000000,2,1,2,1,63.600000000,63.780000000,7,3,7,3,63.590000000,63.790000000,1,1,1,1,MCLQ5
2025-06-11T00:00:19.220796359Z,2025-06-11T00:00:19.218406709Z,10,1,42026514,A,B,2,64.760000000,1,130,11403,79311022,64.780000000,64.790000000,1,6,1,4,64.770000000,64.800000000,4,5,3,5,64.760000000,64.810000000,7,7,7,7,64.750000000,64.820000000,4,10,4,7,64.740000000,64.830000000,9,8,8,8,64.730000000,64.840000000,8,6,8,5,64.720000000,64.850000000,8,8,5,5,64.710000000,64.860000000,9,4,8,3,64.700000000,64.870000000,7,4,6,3,64.690000000,64.880000000,4,4,3,3,MCLN5
2025-06-11T00:00:19.220953783Z,2025-06-11T00:00:19.218659541Z,10,1,42025623,M,A,4,63.750000000,1,130,11625,79311032,63.680000000,63.700000000,2,3,2,3,63.670000000,63.710000000,2,2,2,2,63.660000000,63.720000000,3,3,3,3,63.650000000,63.730000000,3,2,3,2,63.640000000,63.740000000,5,6,5,6,63.630000000,63.750000000,5,3,5,3,63.620000000,63.760000000,3,3,3,3,63.610000000,63.770000000,2,1,2,1,63.600000000,63.780000000,7,3,7,3,63.590000000,63.790000000,1,1,1,1,MCLQ5
2025-06-11T00:00:19.220964903Z,2025-06-11T00:00:19.218660271Z,10,1,42025623,M,B,4,63.640000000,1,130,11497,79311033,63.680000000,63.700000000,2,3,2,3,63.670000000,63.710000000,2,2,2,2,63.660000000,63.720000000,3,3,3,3,63.650000000,63.730000000,3,2,3,2,63.640000000,63.740000000,6,6,6,6,63.630000000,63.750000000,4,3,4,3,63.620000000,63.760000000,3,3,3,3,63.610000000,63.770000000,2,1,2,1,63.600000000,63.780000000,7,3,7,3,63.590000000,63.790000000,1,1,1,1,MCLQ5
2025-06-11T00:00:19.221202548Z,2025-06-11T00:00:19.219734425Z,10,1,42026514,T,A,0,64.780000000,1,0,11674,79311052,64.780000000,64.790000000,1,6,1,4,64.770000000,64.800000000,4,5,3,5,64.760000000,64.810000000,7,7,7,7,64.750000000,64.820000000,4,10,4,7,64.740000000,64.830000000,9,8,8,8,64.730000000,64.840000000,8,6,8,5,64.720000000,64.850000000,8,8,5,5,64.710000000,64.860000000,9,4,8,3,64.700000000,64.870000000,7,4,6,3,64.690000000,64.880000000,4,4,3,3,MCLN5
2025-06-11T00:00:19.221224650Z,2025-06-11T00:00:19.219734425Z,10,1,42026514,C,B,0,64.780000000,1,130,15427,79311053,64.770000000,64.790000000,4,6,3,4,64.760000000,64.800000000,7,5,7,5,64.750000000,64.810000000,4,7,4,7,64.740000000,64.820000000,9,10,8,7,64.730000000,64.830000000,8,8,8,8,64.720000000,64.840000000,8,6,5,5,64.710000000,64.850000000,9,8,8,5,64.700000000,64.860000000,7,4,6,3,64.690000000,64.870000000,4,4,3,3,64.680000000,64.880000000,4,4,2,3,MCLN5
2025-06-11T00:00:19.221246076Z,2025-06-11T00:00:19.219755045Z,10,1,42026514,M,B,1,64.760000000,1,130,14879,79311055,64.770000000,64.790000000,4,6,3,4,64.760000000,64.800000000,8,5,8,5,64.750000000,64.810000000,4,7,4,7,64.740000000,64.820000000,9,10,8,7,64.730000000,64.830000000,8,8,8,8,64.720000000,64.840000000,8,6,5,5,64.710000000,64.850000000,9,8,8,5,64.700000000,64.860000000,7,4,6,3,64.690000000,64.870000000,4,4,3,3,64.680000000,64.880000000,4,4,2,3,MCLN5
2025-06-11T00:00:19.221258102Z,2025-06-11T00:00:19.219794269Z,10,1,42026514,M,A,1,66.740000000,2,130,12165,79311056,64.770000000,64.790000000,4,6,3,4,64.760000000,64.800000000,8,4,8,4,64.750000000,64.810000000,4,7,4,7,64.740000000,64.820000000,9,10,8,7,64.730000000,64.830000000,8,8,8,8,64.720000000,64.840000000,8,6,5,5,64.710000000,64.850000000,9,8,8,5,64.700000000,64.860000000,7,4,6,3,64.690000000,64.870000000,4,4,3,3,64.680000000,64.880000000,4,4,2,3,MCLN5
2025-06-11T00:00:19.221318310Z,2025-06-11T00:00:19.220180441Z,10,1,42025611,M,A,1,2.120000000,20,130,15859,79311059,2.070000000,2.080000000,3,5,2,2,2.060000000,2.090000000,23,7,3,5,2.050000000,2.100000000,23,27,3,6,2.040000000,2.110000000,23,23,3,4,2.030000000,2.120000000,2,22,1,2,2.020000000,2.130000000,2,2,2,2,2.010000000,2.140000000,2,2,1,1,2.000000000,2.150000000,2,2,2,1,1.990000000,2.160000000,2,2,1,1,1.980000000,2.170000000,2,2,2,1,MCLN5-MCLU5
2025-06-11T00:00:19.221325490Z,2025-06-11T00:00:19.220187583Z,10,1,42284507,C,A,0,1.000000000,4,130,11420,79311060,0.980000000,1.000000000,23,12,7,5,0.970000000,1.010000000,18,25,5,8,0.960000000,1.020000000,23,21,8,6,0.950000000,1.030000000,8,17,5,5,0.940000000,1.040000000,6,17,4,5,0.930000000,1.050000000,3,6,2,3,0.920000000,1.060000000,3,4,2,2,0.910000000,1.070000000,3,2,2,1,0.900000000,1.080000000,2,2,1,1,0.890000000,1.090000000,2,4,1,2,MCLQ5-MCLU5
2025-06-11T00:00:19.221730189Z,2025-06-11T00:00:19.220853891Z,10,1,42025623,M,B,1,63.670000000,1,130,11931,79311087,63.680000000,63.700000000,2,3,2,3,63.670000000,63.710000000,3,2,3,2,63.660000000,63.720000000,3,3,3,3,63.650000000,63.730000000,3,2,3,2,63.640000000,63.740000000,6,6,6,6,63.630000000,63.750000000,4,3,4,3,63.620000000,63.760000000,3,3,3,3,63.610000000,63.770000000,2,1,2,1,63.600000000,63.780000000,7,3,7,3,63.590000000,63.790000000,1,1,1,1,MCLQ5
2025-06-11T00:00:19.222087798Z,2025-06-11T00:00:19.221214067Z,10,1,42026514,A,A,0,64.780000000,1,130,11374,79311111,64.770000000,64.780000000,4,1,3,1,64.760000000,64.790000000,8,6,8,4,64.750000000,64.800000000,4,4,4,4,64.740000000,64.810000000,9,7,8,7,64.730000000,64.820000000,8,10,8,7,64.720000000,64.830000000,8,8,5,8,64.710000000,64.840000000,9,6,8,5,64.700000000,64.850000000,7,8,6,5,64.690000000,64.860000000,4,4,3,3,64.680000000,64.870000000,4,4,2,3,MCLN5
2025-06-11T00:00:19.223236849Z,2025-06-11T00:00:19.222288737Z,10,1,42026514,M,B,1,62.780000000,2,130,12082,79311190,64.770000000,64.780000000,4,1,3,1,64.760000000,64.790000000,7,6,7,4,64.750000000,64.800000000,4,4,4,4,64.740000000,64.810000000,9,7,8,7,64.730000000,64.820000000,8,10,8,7,64.720000000,64.830000000,8,8,5,8,64.710000000,64.840000000,9,6,8,5,64.700000000,64.850000000,7,8,6,5,64.690000000,64.860000000,4,4,3,3,64.680000000,64.870000000,4,4,2,3,MCLN5
2025-06-11T00:00:19.224585424Z,2025-06-11T00:00:19.223111327Z,10,1,42026514,M,A,3,64.820000000,1,130,12298,79311278,64.770000000,64.780000000,4,1,3,1,64.760000000,64.790000000,7,6,7,4,64.750000000,64.800000000,4,4,4,4,64.740000000,64.810000000,9,6,8,6,64.730000000,64.820000000,8,11,8,8,64.720000000,64.830000000,8,8,5,8,64.710000000,64.840000000,9,6,8,5,64.700000000,64.850000000,7,8,6,5,64.690000000,64.860000000,4,4,3,3,64.680000000,64.870000000,4,4,2,3,MCLN5
2025-06-11T00:00:19.224585424Z,2025-06-11T00:00:19.223112383Z,10,1,42026514,M,A,3,64.820000000,1,130,12298,79311278,64.770000000,64.780000000,4,1,3,1,64.760000000,64.790000000,7,6,7,4,64.750000000,64.800000000,4,4,4,4,64.740000000,64.810000000,9,5,8,5,64.730000000,64.820000000,8,12,8,9,64.720000000,64.830000000,8,8,5,8,64.710000000,64.840000000,9,6,8,5,64.700000000,64.850000000,7,8,6,5,64.690000000,64.860000000,4,4,3,3,64.680000000,64.870000000,4,4,2,3,MCLN5
2025-06-11T00:00:19.224618032Z,2025-06-11T00:00:19.223119485Z,10,1,42026514,A,A,0,64.780000000,1,130,15143,79311280,64.770000000,64.780000000,4,2,3,2,64.760000000,64.790000000,7,6,7,4,64.750000000,64.800000000,4,4,4,4,64.740000000,64.810000000,9,5,8,5,64.730000000,64.820000000,8,12,8,9,64.720000000,64.830000000,8,8,5,8,64.710000000,64.840000000,9,6,8,5,64.700000000,64.850000000,7,8,6,5,64.690000000,64.860000000,4,4,3,3,64.680000000,64.870000000,4,4,2,3,MCLN5
2025-06-11T00:00:19.225682263Z,2025-06-11T00:00:19.224646375Z,10,1,42026514,A,A,0,64.780000000,1,130,16674,79311357,64.770000000,64.780000000,4,3,3,3,64.760000000,64.790000000,7,6,7,4,64.750000000,64.800000000,4,4,4,4,64.740000000,64.810000000,9,5,8,5,64.730000000,64.820000000,8,12,8,9,64.720000000,64.830000000,8,8,5,8,64.710000000,64.840000000,9,6,8,5,64.700000000,64.850000000,7,8,6,5,64.690000000,64.860000000,4,4,3,3,64.680000000,64.870000000,4,4,2,3,MCLN5
2025-06-11T00:00:19.230655300Z,2025-06-11T00:00:19.230501501Z,10,1,42026514,A,A,0,64.780000000,1,130,12538,79311505,64.770000000,64.780000000,4,4,3,4,64.760000000,64.790000000,7,6,7,4,64.750000000,64.800000000,4,4,4,4,64.740000000,64.810000000,9,5,8,5,64.730000000,64.820000000,8,12,8,9,64.720000000,64.830000000,8,8,5,8,64.710000000,64.840000000,9,6,8,5,64.700000000,64.850000000,7,8,6,5,64.690000000,64.860000000,4,4,3,3,64.680000000,64.870000000,4,4,2,3,MCLN5
2025-06-11T00:00:19.236372229Z,2025-06-11T00:00:19.236275761Z,10,1,42026514,C,B,6,64.710000000,1,130,11360,79311580,64.770000000,64.780000000,4,4,3,4,64.760000000,64.790000000,7,6,7,4,64.750000000,64.800000000,4,4,4,4,64.740000000,64.810000000,9,5,8,5,64.730000000,64.820000000,8,12,8,9,64.720000000,64.830000000,8,8,5,8,64.710000000,64.840000000,8,6,7,5,64.700000000,64.850000000,7,8,6,5,64.690000000,64.860000000,4,4,3,3,64.680000000,64.870000000,4,4,2,3,MCLN5
2025-06-11T00:00:19.236381813Z,2025-06-11T00:00:19.236278681Z,10,1,42026514,A,A,6,64.840000000,1,130,11272,79311581,64.770000000,64.780000000,4,4,3,4,64.760000000,64.790000000,7,6,7,4,64.750000000,64.800000000,4,4,4,4,64.740000000,64.810000000,9,5,8,5,64.730000000,64.820000000,8,12,8,9,64.720000000,64.830000000,8,8,5,8,64.710000000,64.840000000,8,7,7,6,64.700000000,64.850000000,7,8,6,5,64.690000000,64.860000000,4,4,3,3,64.680000000,64.870000000,4,4,2,3,MCLN5
2025-06-11T00:00:19.236521259Z,2025-06-11T00:00:19.236431427Z,10,1,42026514,A,B,5,64.720000000,1,130,11396,79311584,64.770000000,64.780000000,4,4,3,4,64.760000000,64.790000000,7,6,7,4,64.750000000,64.800000000,4,4,4,4,64.740000000,64.810000000,9,5,8,5,64.730000000,64.820000000,8,12,8,9,64.720000000,64.830000000,9,8,6,8,64.710000000,64.840000000,8,7,7,6,64.700000000,64.850000000,7,8,6,5,64.690000000,64.860000000,4,4,3,3,64.680000000,64.870000000,4,4,2,3,MCLN5
2025-06-11T00:00:19.319538038Z,2025-06-11T00:00:19.319436097Z,10,1,42418117,M,A,0,3.280000000,10,130,15117,79312173,3.250000000,3.280000000,1,11,1,2,3.240000000,3.290000000,11,1,2,1,3.230000000,3.300000000,1,1,1,1,,,0,0,0,0,,,0,0,0,0,,,0,0,0,0,,,0,0,0,0,,,0,0,0,0,,,0,0,0,0,,,0,0,0,0,MCLN5-MCLX5
2025-06-11T00:00:19.523687374Z,2025-06-11T00:00:19.523580053Z,10,1,42026514,M,B,3,64.740000000,1,130,14816,79312887,64.770000000,64.780000000,4,4,3,4,64.760000000,64.790000000,7,6,7,4,64.750000000,64.800000000,4,4,4,4,64.740000000,64.810000000,10,5,9,5,64.730000000,64.820000000,7,12,7,9,64.720000000,64.830000000,9,8,6,8,64.710000000,64.840000000,8,7,7,6,64.700000000,64.850000000,7,8,6,5,64.690000000,64.860000000,4,4,3,3,64.680000000,64.870000000,4,4,2,3,MCLN5
2025-06-11T00:00:19.523696912Z,2025-06-11T00:00:19.523581033Z,10,1,42026514,M,B,3,64.740000000,1,130,12657,79312888,64.770000000,64.780000000,4,4,3,4,64.760000000,64.790000000,7,6,7,4,64.750000000,64.800000000,4,4,4,4,64.740000000,64.810000000,11,5,10,5,64.730000000,64.820000000,6,12,6,9,64.720000000,64.830000000,9,8,6,8,64.710000000,64.840000000,8,7,7,6,64.700000000,64.850000000,7,8,6,5,64.690000000,64.860000000,4,4,3,3,64.680000000,64.870000000,4,4,2,3,MCLN5
2025-06-11T00:00:19.653582021Z,2025-06-11T00:00:19.653449485Z,10,1,42026514,C,A,0,64.780000000,1,130,17277,79313130,64.770000000,64.780000000,4,3,3,3,64.760000000,64.790000000,7,6,7,4,64.750000000,64.800000000,4,4,4,4,64.740000000,64.810000000,11,5,10,5,64.730000000,64.820000000,6,12,6,9,64.720000000,64.830000000,9,8,6,8,64.710000000,64.840000000,8,7,7,6,64.700000000,64.850000000,7,8,6,5,64.690000000,64.860000000,4,4,3,3,64.680000000,64.870000000,4,4,2,3,MCLN5
2025-06-11T00:00:19.653771108Z,2025-06-11T00:00:19.653654531Z,10,1,42026514,C,A,0,64.780000000,1,130,17352,79313131,64.770000000,64.780000000,4,2,3,2,64.760000000,64.790000000,7,6,7,4,64.750000000,64.800000000,4,4,4,4,64.740000000,64.810000000,11,5,10,5,64.730000000,64.820000000,6,12,6,9,64.720000000,64.830000000,9,8,6,8,64.710000000,64.840000000,8,7,7,6,64.700000000,64.850000000,7,8,6,5,64.690000000,64.860000000,4,4,3,3,64.680000000,64.870000000,4,4,2,3,MCLN5
2025-06-11T00:00:19.710677281Z,2025-06-11T00:00:19.710561449Z,10,1,42025623,A,B,6,63.620000000,1,130,15196,79313165,63.680000000,63.700000000,2,3,2,3,63.670000000,63.710000000,3,2,3,2,63.660000000,63.720000000,3,3,3,3,63.650000000,63.730000000,3,2,3,2,63.640000000,63.740000000,6,6,6,6,63.630000000,63.750000000,4,3,4,3,63.620000000,63.760000000,4,3,4,3,63.610000000,63.770000000,2,1,2,1,63.600000000,63.780000000,7,3,7,3,63.590000000,63.790000000,1,1,1,1,MCLQ5
2025-06-11T00:00:19.710686189Z,2025-06-11T00:00:19.710563561Z,10,1,42025623,A,A,6,63.760000000,1,130,11350,79313166,63.680000000,63.700000000,2,3,2,3,63.670000000,63.710000000,3,2,3,2,63.660000000,63.720000000,3,3,3,3,63.650000000,63.730000000,3,2,3,2,63.640000000,63.740000000,6,6,6,6,63.630000000,63.750000000,4,3,4,3,63.620000000,63.760000000,4,4,4,4,63.610000000,63.770000000,2,1,2,1,63.600000000,63.780000000,7,3,7,3,63.590000000,63.790000000,1,1,1,1,MCLQ5
2025-06-11T00:00:19.743532503Z,2025-06-11T00:00:19.743406723Z,10,1,42026514,C,A,0,64.780000000,1,130,14515,79313187,64.770000000,64.780000000,4,1,3,1,64.760000000,64.790000000,7,6,7,4,64.750000000,64.800000000,4,4,4,4,64.740000000,64.810000000,11,5,10,5,64.730000000,64.820000000,6,12,6,9,64.720000000,64.830000000,9,8,6,8,64.710000000,64.840000000,8,7,7,6,64.700000000,64.850000000,7,8,6,5,64.690000000,64.860000000,4,4,3,3,64.680000000,64.870000000,4,4,2,3,MCLN5
2025-06-11T00:00:19.748120547Z,2025-06-11T00:00:19.747284599Z,10,1,42025623,A,B,0,63.690000000,1,130,13720,79313282,63.690000000,63.700000000,1,3,1,3,63.680000000,63.710000000,2,2,2,2,63.670000000,63.720000000,3,3,3,3,63.660000000,63.730000000,3,2,3,2,63.650000000,63.740000000,3,6,3,6,63.640000000,63.750000000,6,3,6,3,63.630000000,63.760000000,4,4,4,4,63.620000000,63.770000000,4,1,4,1,63.610000000,63.780000000,2,3,2,3,63.600000000,63.790000000,7,1,7,1,MCLQ5
2025-06-11T00:00:19.749133033Z,2025-06-11T00:00:19.747290561Z,10,1,42025623,C,A,0,63.700000000,1,130,13953,79313334,63.690000000,63.700000000,1,2,1,2,63.680000000,63.710000000,2,2,2,2,63.670000000,63.720000000,3,3,3,3,63.660000000,63.730000000,3,2,3,2,63.650000000,63.740000000,3,6,3,6,63.640000000,63.750000000,6,3,6,3,63.630000000,63.760000000,4,4,4,4,63.620000000,63.770000000,4,1,4,1,63.610000000,63.780000000,2,3,2,3,63.600000000,63.790000000,7,1,7,1,MCLQ5
2025-06-11T00:00:19.749483583Z,2025-06-11T00:00:19.747292525Z,10,1,42025623,A,B,0,63.690000000,1,130,12156,79313352,63.690000000,63.700000000,2,2,2,2,63.680000000,63.710000000,2,2,2,2,63.670000000,63.720000000,3,3,3,3,63.660000000,63.730000000,3,2,3,2,63.650000000,63.740000000,3,6,3,6,63.640000000,63.750000000,6,3,6,3,63.630000000,63.760000000,4,4,4,4,63.620000000,63.770000000,4,1,4,1,63.610000000,63.780000000,2,3,2,3,63.600000000,63.790000000,7,1,7,1,MCLQ5
2025-06-11T00:00:19.749699011Z,2025-06-11T00:00:19.747305667Z,10,1,42463766,A,B,0,1.080000000,7,130,12180,79313365,1.080000000,1.090000000,10,29,2,12,1.070000000,1.100000000,61,56,19,14,1.060000000,1.110000000,52,57,14,13,1.050000000,1.120000000,56,54,13,12,1.040000000,1.130000000,52,40,11,10,1.030000000,1.140000000,39,38,9,8,1.020000000,1.150000000,38,41,8,10,1.010000000,1.160000000,35,36,8,7,1.000000000,1.170000000,40,38,9,9,0.990000000,1.180000000,35,37,8,9,MCLN5-MCLQ5
2025-06-11T00:00:19.750130329Z,2025-06-11T00:00:19.747375745Z,10,1,42463766,A,B,0,1.080000000,5,130,11432,79313394,1.080000000,1.090000000,15,29,3,12,1.070000000,1.100000000,61,56,19,14,1.060000000,1.110000000,52,57,14,13,1.050000000,1.120000000,56,54,13,12,1.040000000,1.130000000,52,40,11,10,1.030000000,1.140000000,39,38,9,8,1.020000000,1.150000000,38,41,8,10,1.010000000,1.160000000,35,36,8,7,1.000000000,1.170000000,40,38,9,9,0.990000000,1.180000000,35,37,8,9,MCLN5-MCLQ5
2025-06-11T00:00:19.750486884Z,2025-06-11T00:00:19.747944231Z,10,1,42418117,M,B,0,3.250000000,10,130,11402,79313426,3.250000000,3.280000000,11,11,2,2,3.240000000,3.290000000,1,1,1,1,3.230000000,3.300000000,1,1,1,1,,,0,0,0,0,,,0,0,0,0,,,0,0,0,0,,,0,0,0,0,,,0,0,0,0,,,0,0,0,0,,,0,0,0,0,MCLN5-MCLX5
2025-06-11T00:00:19.750514208Z,2025-06-11T00:00:19.747997815Z,10,1,42022708,M,A,0,2.840000000,10,130,11731,79313429,2.810000000,2.830000000,1,2,1,2,2.800000000,2.840000000,12,12,3,3,2.790000000,2.850000000,2,1,2,1,2.780000000,2.870000000,1,1,1,1,,,0,0,0,0,,,0,0,0,0,,,0,0,0,0,,,0,0,0,0,,,0,0,0,0,,,0,0,0,0,MCLN5-MCLV5
2025-06-11T00:00:19.750622875Z,2025-06-11T00:00:19.748129561Z,10,1,42025623,C,A,6,63.760000000,1,130,11818,79313437,63.690000000,63.700000000,2,2,2,2,63.680000000,63.710000000,2,2,2,2,63.670000000,63.720000000,3,3,3,3,63.660000000,63.730000000,3,2,3,2,63.650000000,63.740000000,3,6,3,6,63.640000000,63.750000000,6,3,6,3,63.630000000,63.760000000,4,3,4,3,63.620000000,63.770000000,4,1,4,1,63.610000000,63.780000000,2,3,2,3,63.600000000,63.790000000,7,1,7,1,MCLQ5
2025-06-11T00:00:19.750718109Z,2025-06-11T00:00:19.748210849Z,10,1,42025623,M,B,5,63.630000000,1,130,11692,79313445,63.690000000,63.700000000,2,2,2,2,63.680000000,63.710000000,2,2,2,2,63.670000000,63.720000000,3,3,3,3,63.660000000,63.730000000,3,2,3,2,63.650000000,63.740000000,3,6,3,6,63.640000000,63.750000000,5,3,5,3,63.630000000,63.760000000,5,3,5,3,63.620000000,63.770000000,4,1,4,1,63.610000000,63.780000000,2,3,2,3,63.600000000,63.790000000,7,1,7,1,MCLQ5
2025-06-11T00:00:19.750729475Z,2025-06-11T00:00:19.748211291Z,10,1,42025623,M,A,4,63.740000000,1,130,11802,79313446,63.690000000,63.700000000,2,2,2,2,63.680000000,63.710000000,2,2,2,2,63.670000000,63.720000000,3,3,3,3,63.660000000,63.730000000,3,2,3,2,63.650000000,63.740000000,3,7,3,7,63.640000000,63.750000000,5,2,5,2,63.630000000,63.760000000,5,3,5,3,63.620000000,63.770000000,4,1,4,1,63.610000000,63.780000000,2,3,2,3,63.600000000,63.790000000,7,1,7,1,MCLQ5
2025-06-11T00:00:19.751233456Z,2025-06-11T00:00:19.748482113Z,10,1,42026514,C,A,0,64.780000000,1,130,11484,79313485,64.770000000,64.790000000,4,6,3,4,64.760000000,64.800000000,7,4,7,4,64.750000000,64.810000000,4,5,4,5,64.740000000,64.820000000,11,12,10,9,64.730000000,64.830000000,6,8,6,8,64.720000000,64.840000000,9,7,6,6,64.710000000,64.850000000,8,8,7,5,64.700000000,64.860000000,7,4,6,3,64.690000000,64.870000000,4,4,3,3,64.680000000,64.880000000,4,4,2,3,MCLN5
2025-06-11T00:00:19.751655627Z,2025-06-11T00:00:19.749040925Z,10,1,42025623,M,A,4,63.750000000,1,130,10977,79313525,63.690000000,63.700000000,2,2,2,2,63.680000000,63.710000000,2,2,2,2,63.670000000,63.720000000,3,3,3,3,63.660000000,63.730000000,3,2,3,2,63.650000000,63.740000000,3,6,3,6,63.640000000,63.750000000,5,3,5,3,63.630000000,63.760000000,5,3,5,3,63.620000000,63.770000000,4,1,4,1,63.610000000,63.780000000,2,3,2,3,63.600000000,63.790000000,7,1,7,1,MCLQ5
2025-06-11T00:00:19.751670303Z,2025-06-11T00:00:19.749041385Z,10,1,42025623,M,B,5,63.640000000,1,130,15265,79313526,63.690000000,63.700000000,2,2,2,2,63.680000000,63.710000000,2,2,2,2,63.670000000,63.720000000,3,3,3,3,63.660000000,63.730000000,3,2,3,2,63.650000000,63.740000000,3,6,3,6,63.640000000,63.750000000,6,3,6,3,63.630000000,63.760000000,4,3,4,3,63.620000000,63.770000000,4,1,4,1,63.610000000,63.780000000,2,3,2,3,63.600000000,63.790000000,7,1,7,1,MCLQ5
2025-06-11T00:00:19.751795380Z,2025-06-11T00:00:19.749051063Z,10,1,42026514,A,B,0,64.780000000,1,130,14981,79313531,64.780000000,64.790000000,1,6,1,4,64.770000000,64.800000000,4,4,3,4,64.760000000,64.810000000,7,5,7,5,64.750000000,64.820000000,4,12,4,9,64.740000000,64.830000000,11,8,10,8,64.730000000,64.840000000,6,7,6,6,64.720000000,64.850000000,9,8,6,5,64.710000000,64.860000000,8,4,7,3,64.700000000,64.870000000,7,4,6,3,64.690000000,64.880000000,4,4,3,3,MCLN5
2025-06-11T00:00:19.751819801Z,2025-06-11T00:00:19.749052329Z,10,1,42025623,C,A,0,63.700000000,1,130,14232,79313532,63.690000000,63.700000000,2,1,2,1,63.680000000,63.710000000,2,2,2,2,63.670000000,63.720000000,3,3,3,3,63.660000000,63.730000000,3,2,3,2,63.650000000,63.740000000,3,6,3,6,63.640000000,63.750000000,6,3,6,3,63.630000000,63.760000000,4,3,4,3,63.620000000,63.770000000,4,1,4,1,63.610000000,63.780000000,2,3,2,3,63.600000000,63.790000000,7,1,7,1,MCLQ5
2025-06-11T00:00:19.752486436Z,2025-06-11T00:00:19.749265995Z,10,1,42026514,M,B,2,64.760000000,1,130,11731,79313568,64.780000000,64.790000000,1,6,1,4,64.770000000,64.800000000,4,4,3,4,64.760000000,64.810000000,8,5,8,5,64.750000000,64.820000000,4,12,4,9,64.740000000,64.830000000,11,8,10,8,64.730000000,64.840000000,6,7,6,6,64.720000000,64.850000000,9,8,6,5,64.710000000,64.860000000,8,4,7,3,64.700000000,64.870000000,7,4,6,3,64.690000000,64.880000000,4,4,3,3,MCLN5
2025-06-11T00:00:19.754292462Z,2025-06-11T00:00:19.751258581Z,10,1,42025623,M,A,4,63.750000000,1,130,14591,79313704,63.690000000,63.700000000,2,1,2,1,63.680000000,63.710000000,2,2,2,2,63.670000000,63.720000000,3,3,3,3,63.660000000,63.730000000,3,2,3,2,63.650000000,63.740000000,3,5,3,5,63.640000000,63.750000000,6,4,6,4,63.630000000,63.760000000,4,3,4,3,63.620000000,63.770000000,4,1,4,1,63.610000000,63.780000000,2,3,2,3,63.600000000,63.790000000,7,1,7,1,MCLQ5
2025-06-11T00:00:19.754302108Z,2025-06-11T00:00:19.751259117Z,10,1,42025623,M,B,4,63.650000000,1,130,11464,79313705,63.690000000,63.700000000,2,1,2,1,63.680000000,63.710000000,2,2,2,2,63.670000000,63.720000000,3,3,3,3,63.660000000,63.730000000,3,2,3,2,63.650000000,63.740000000,4,5,4,5,63.640000000,63.750000000,5,4,5,4,63.630000000,63.760000000,4,3,4,3,63.620000000,63.770000000,4,1,4,1,63.610000000,63.780000000,2,3,2,3,63.600000000,63.790000000,7,1,7,1,MCLQ5
2025-06-11T00:00:19.754314095Z,2025-06-11T00:00:19.751259599Z,10,1,42025623,M,A,4,63.750000000,1,130,11711,79313706,63.690000000,63.700000000,2,1,2,1,63.680000000,63.710000000,2,2,2,2,63.670000000,63.720000000,3,3,3,3,63.660000000,63.730000000,3,2,3,2,63.650000000,63.740000000,4,4,4,4,63.640000000,63.750000000,5,5,5,5,63.630000000,63.760000000,4,3,4,3,63.620000000,63.770000000,4,1,4,1,63.610000000,63.780000000,2,3,2,3,63.600000000,63.790000000,7,1,7,1,MCLQ5
2025-06-11T00:00:19.754324985Z,2025-06-11T00:00:19.751260231Z,10,1,42025623,M,B,4,63.650000000,1,130,10890,79313707,63.690000000,63.700000000,2,1,2,1,63.680000000,63.710000000,2,2,2,2,63.670000000,63.720000000,3,3,3,3,63.660000000,63.730000000,3,2,3,2,63.650000000,63.740000000,5,4,5,4,63.640000000,63.750000000,4,5,4,5,63.630000000,63.760000000,4,3,4,3,63.620000000,63.770000000,4,1,4,1,63.610000000,63.780000000,2,3,2,3,63.600000000,63.790000000,7,1,7,1,MCLQ5
2025-06-11T00:00:19.754377306Z,2025-06-11T00:00:19.751426823Z,10,1,42026514,M,A,1,66.750000000,2,130,12780,79313712,64.780000000,64.790000000,1,6,1,4,64.770000000,64.800000000,4,3,3,3,64.760000000,64.810000000,8,5,8,5,64.750000000,64.820000000,4,12,4,9,64.740000000,64.830000000,11,8,10,8,64.730000000,64.840000000,6,7,6,6,64.720000000,64.850000000,9,8,6,5,64.710000000,64.860000000,8,4,7,3,64.700000000,64.870000000,7,4,6,3,64.690000000,64.880000000,4,4,3,3,MCLN5
2025-06-11T00:00:19.754721836Z,2025-06-11T00:00:19.751457809Z,10,1,42026514,M,A,2,66.760000000,2,130,15557,79313730,64.780000000,64.790000000,1,6,1,4,64.770000000,64.800000000,4,3,3,3,64.760000000,64.810000000,8,4,8,4,64.750000000,64.820000000,4,12,4,9,64.740000000,64.830000000,11,8,10,8,64.730000000,64.840000000,6,7,6,6,64.720000000,64.850000000,9,8,6,5,64.710000000,64.860000000,8,4,7,3,64.700000000,64.870000000,7,4,6,3,64.690000000,64.880000000,4,4,3,3,MCLN5
2025-06-11T00:00:19.755119953Z,2025-06-11T00:00:19.751803375Z,10,1,42026514,C,A,5,64.840000000,1,130,12146,79313754,64.780000000,64.790000000,1,6,1,4,64.770000000,64.800000000,4,3,3,3,64.760000000,64.810000000,8,4,8,4,64.750000000,64.820000000,4,12,4,9,64.740000000,64.830000000,11,8,10,8,64.730000000,64.840000000,6,6,6,5,64.720000000,64.850000000,9,8,6,5,64.710000000,64.860000000,8,4,7,3,64.700000000,64.870000000,7,4,6,3,64.690000000,64.880000000,4,4,3,3,MCLN5
2025-06-11T00:00:19.755144451Z,2025-06-11T00:00:19.751807887Z,10,1,42026514,A,B,0,64.780000000,1,130,13973,79313755,64.780000000,64.790000000,2,6,2,4,64.770000000,64.800000000,4,3,3,3,64.760000000,64.810000000,8,4,8,4,64.750000000,64.820000000,4,12,4,9,64.740000000,64.830000000,11,8,10,8,64.730000000,64.840000000,6,6,6,5,64.720000000,64.850000000,9,8,6,5,64.710000000,64.860000000,8,4,7,3,64.700000000,64.870000000,7,4,6,3,64.690000000,64.880000000,4,4,3,3,MCLN5
2025-06-11T00:00:19.755588517Z,2025-06-11T00:00:19.751928689Z,10,1,42026514,C,A,0,64.790000000,1,130,17835,79313783,64.780000000,64.790000000,2,5,2,3,64.770000000,64.800000000,4,3,3,3,64.760000000,64.810000000,8,4,8,4,64.750000000,64.820000000,4,12,4,9,64.740000000,64.830000000,11,8,10,8,64.730000000,64.840000000,6,6,6,5,64.720000000,64.850000000,9,8,6,5,64.710000000,64.860000000,8,4,7,3,64.700000000,64.870000000,7,4,6,3,64.690000000,64.880000000,4,4,3,3,MCLN5
2025-06-11T00:00:19.755703565Z,2025-06-11T00:00:19.751988801Z,10,1,42026514,M,B,1,64.770000000,1,130,13155,79313791,64.780000000,64.790000000,2,5,2,3,64.770000000,64.800000000,5,3,4,3,64.760000000,64.810000000,8,4,8,4,64.750000000,64.820000000,4,12,4,9,64.740000000,64.830000000,11,8,10,8,64.730000000,64.840000000,6,6,6,5,64.720000000,64.850000000,9,8,6,5,64.710000000,64.860000000,8,4,7,3,64.700000000,64.870000000,7,4,6,3,64.690000000,64.880000000,4,4,3,3,MCLN5
2025-06-11T00:00:19.755712005Z,2025-06-11T00:00:19.752004237Z,10,1,42026514,M,B,3,64.750000000,1,130,11649,79313792,64.780000000,64.790000000,2,5,2,3,64.770000000,64.800000000,5,3,4,3,64.760000000,64.810000000,8,4,8,4,64.750000000,64.820000000,5,12,5,9,64.740000000,64.830000000,11,8,10,8,64.730000000,64.840000000,6,6,6,5,64.720000000,64.850000000,9,8,6,5,64.710000000,64.860000000,8,4,7,3,64.700000000,64.870000000,7,4,6,3,64.690000000,64.880000000,4,4,3,3,MCLN5
2025-06-11T00:00:19.756411999Z,2025-06-11T00:00:19.753183373Z,10,1,42026514,M,A,4,66.770000000,2,130,11447,79313841,64.780000000,64.790000000,2,5,2,3,64.770000000,64.800000000,5,3,4,3,64.760000000,64.810000000,8,4,8,4,64.750000000,64.820000000,5,12,5,9,64.740000000,64.830000000,11,7,10,7,64.730000000,64.840000000,6,6,6,5,64.720000000,64.850000000,9,8,6,5,64.710000000,64.860000000,8,4,7,3,64.700000000,64.870000000,7,4,6,3,64.690000000,64.880000000,4,4,3,3,MCLN5
2025-06-11T00:00:19.757970681Z,2025-06-11T00:00:19.755450907Z,10,1,42022708,M,A,0,2.830000000,10,130,11420,79313959,2.810000000,2.830000000,1,12,1,3,2.800000000,2.840000000,12,2,3,2,2.790000000,2.850000000,2,1,2,1,2.780000000,2.870000000,1,1,1,1,,,0,0,0,0,,,0,0,0,0,,,0,0,0,0,,,0,0,0,0,,,0,0,0,0,,,0,0,0,0,MCLN5-MCLV5
2025-06-11T00:00:19.758012550Z,2025-06-11T00:00:19.755734573Z,10,1,42026514,M,A,0,66.780000000,2,130,13182,79313962,64.780000000,64.790000000,2,4,2,2,64.770000000,64.800000000,5,3,4,3,64.760000000,64.810000000,8,4,8,4,64.750000000,64.820000000,5,12,5,9,64.740000000,64.830000000,11,7,10,7,64.730000000,64.840000000,6,6,6,5,64.720000000,64.850000000,9,8,6,5,64.710000000,64.860000000,8,4,7,3,64.700000000,64.870000000,7,4,6,3,64.690000000,64.880000000,4,4,3,3,MCLN5
2025-06-11T00:00:19.759892853Z,2025-06-11T00:00:19.758842839Z,10,1,42026514,M,A,3,64.830000000,1,130,11853,79314086,64.780000000,64.790000000,2,4,2,2,64.770000000,64.800000000,5,3,4,3,64.760000000,64.810000000,8,4,8,4,64.750000000,64.820000000,5,11,5,8,64.740000000,64.830000000,11,8,10,8,64.730000000,64.840000000,6,6,6,5,64.720000000,64.850000000,9,8,6,5,64.710000000,64.860000000,8,4,7,3,64.700000000,64.870000000,7,4,6,3,64.690000000,64.880000000,4,4,3,3,MCLN5
2025-06-11T00:00:19.759905908Z,2025-06-11T00:00:19.758843377Z,10,1,42026514,M,B,4,64.740000000,1,130,14992,79314087,64.780000000,64.790000000,2,4,2,2,64.770000000,64.800000000,5,3,4,3,64.760000000,64.810000000,8,4,8,4,64.750000000,64.820000000,5,11,5,8,64.740000000,64.830000000,12,8,11,8,64.730000000,64.840000000,5,6,5,5,64.720000000,64.850000000,9,8,6,5,64.710000000,64.860000000,8,4,7,3,64.700000000,64.870000000,7,4,6,3,64.690000000,64.880000000,4,4,3,3,MCLN5
2025-06-11T00:00:19.759923948Z,2025-06-11T00:00:19.758869045Z,10,1,42022708,M,A,0,2.840000000,10,130,11773,79314089,2.810000000,2.830000000,1,2,1,2,2.800000000,2.840000000,12,12,3,3,2.790000000,2.850000000,2,1,2,1,2.780000000,2.870000000,1,1,1,1,,,0,0,0,0,,,0,0,0,0,,,0,0,0,0,,,0,0,0,0,,,0,0,0,0,,,0,0,0,0,MCLN5-MCLV5
2025-06-11T00:00:19.760156117Z,2025-06-11T00:00:19.759113031Z,10,1,42026514,A,B,0,64.780000000,1,130,11651,79314102,64.780000000,64.790000000,3,4,3,2,64.770000000,64.800000000,5,3,4,3,64.760000000,64.810000000,8,4,8,4,64.750000000,64.820000000,5,11,5,8,64.740000000,64.830000000,12,8,11,8,64.730000000,64.840000000,5,6,5,5,64.720000000,64.850000000,9,8,6,5,64.710000000,64.860000000,8,4,7,3,64.700000000,64.870000000,7,4,6,3,64.690000000,64.880000000,4,4,3,3,MCLN5
2025-06-11T00:00:19.761120321Z,2025-06-11T00:00:19.759632905Z,10,1,42026514,A,B,0,64.780000000,1,130,16512,79314170,64.780000000,64.790000000,4,4,4,2,64.770000000,64.800000000,5,3,4,3,64.760000000,64.810000000,8,4,8,4,64.750000000,64.820000000,5,11,5,8,64.740000000,64.830000000,12,8,11,8,64.730000000,64.840000000,5,6,5,5,64.720000000,64.850000000,9,8,6,5,64.710000000,64.860000000,8,4,7,3,64.700000000,64.870000000,7,4,6,3,64.690000000,64.880000000,4,4,3,3,MCLN5
2025-06-11T00:00:19.761142576Z,2025-06-11T00:00:19.759635535Z,10,1,42025623,T,B,0,63.700000000,1,0,11457,79314172,63.690000000,63.700000000,2,1,2,1,63.680000000,63.710000000,2,2,2,2,63.670000000,63.720000000,3,3,3,3,63.660000000,63.730000000,3,2,3,2,63.650000000,63.740000000,5,4,5,4,63.640000000,63.750000000,4,5,4,5,63.630000000,63.760000000,4,3,4,3,63.620000000,63.770000000,4,1,4,1,63.610000000,63.780000000,2,3,2,3,63.600000000,63.790000000,7,1,7,1,MCLQ5
2025-06-11T00:00:19.761142576Z,2025-06-11T00:00:19.759635535Z,10,1,42025623,C,A,0,63.700000000,1,130,11457,79314172,63.690000000,63.710000000,2,2,2,2,63.680000000,63.720000000,2,3,2,3,63.670000000,63.730000000,3,2,3,2,63.660000000,63.740000000,3,4,3,4,63.650000000,63.750000000,5,5,5,5,63.640000000,63.760000000,4,3,4,3,63.630000000,63.770000000,4,1,4,1,63.620000000,63.780000000,4,3,4,3,63.610000000,63.790000000,2,1,2,1,63.600000000,63.800000000,7,3,7,3,MCLQ5
2025-06-11T00:00:19.761382748Z,2025-06-11T00:00:19.759669901Z,10,1,42026514,C,A,0,64.790000000,2,130,13273,79314185,64.780000000,64.790000000,4,2,4,1,64.770000000,64.800000000,5,3,4,3,64.760000000,64.810000000,8,4,8,4,64.750000000,64.820000000,5,11,5,8,64.740000000,64.830000000,12,8,11,8,64.730000000,64.840000000,5,6,5,5,64.720000000,64.850000000,9,8,6,5,64.710000000,64.860000000,8,4,7,3,64.700000000,64.870000000,7,4,6,3,64.690000000,64.880000000,4,4,3,3,MCLN5
2025-06-11T00:00:19.761402761Z,2025-06-11T00:00:19.759673627Z,10,1,42025623,C,A,0,63.710000000,1,130,13838,79314186,63.690000000,63.710000000,2,1,2,1,63.680000000,63.720000000,2,3,2,3,63.670000000,63.730000000,3,2,3,2,63.660000000,63.740000000,3,4,3,4,63.650000000,63.750000000,5,5,5,5,63.640000000,63.760000000,4,3,4,3,63.630000000,63.770000000,4,1,4,1,63.620000000,63.780000000,4,3,4,3,63.610000000,63.790000000,2,1,2,1,63.600000000,63.800000000,7,3,7,3,MCLQ5
2025-06-11T00:00:19.761532478Z,2025-06-11T00:00:19.759740879Z,10,1,42025623,C,A,0,63.710000000,1,130,15050,79314192,63.690000000,63.720000000,2,3,2,3,63.680000000,63.730000000,2,2,2,2,63.670000000,63.740000000,3,4,3,4,63.660000000,63.750000000,3,5,3,5,63.650000000,63.760000000,5,3,5,3,63.640000000,63.770000000,4,1,4,1,63.630000000,63.780000000,4,3,4,3,63.620000000,63.790000000,4,1,4,1,63.610000000,63.800000000,2,3,2,3,63.600000000,63.810000000,7,4,7,2,MCLQ5
2025-06-11T00:00:19.761870848Z,2025-06-11T00:00:19.759771081Z,10,1,42026514,C,A,0,64.790000000,2,130,11325,79314216,64.780000000,64.800000000,4,3,4,3,64.770000000,64.810000000,5,4,4,4,64.760000000,64.820000000,8,11,8,8,64.750000000,64.830000000,5,8,5,8,64.740000000,64.840000000,12,6,11,5,64.730000000,64.850000000,5,8,5,5,64.720000000,64.860000000,9,4,6,3,64.710000000,64.870000000,8,4,7,3,64.700000000,64.880000000,7,4,6,3,64.690000000,64.890000000,4,3,3,2,MCLN5
2025-06-11T00:00:19.762248392Z,2025-06-11T00:00:19.759903017Z,10,1,42025623,C,B,7,63.620000000,1,130,12173,79314239,63.690000000,63.720000000,2,3,2,3,63.680000000,63.730000000,2,2,2,2,63.670000000,63.740000000,3,4,3,4,63.660000000,63.750000000,3,5,3,5,63.650000000,63.760000000,5,3,5,3,63.640000000,63.770000000,4,1,4,1,63.630000000,63.780000000,4,3,4,3,63.620000000,63.790000000,3,1,3,1,63.610000000,63.800000000,2,3,2,3,63.600000000,63.810000000,7,4,7,2,MCLQ5
2025-06-11T00:00:19.762258998Z,2025-06-11T00:00:19.759906473Z,10,1,42025623,A,A,5,63.770000000,1,130,11571,79314240,63.690000000,63.720000000,2,3,2,3,63.680000000,63.730000000,2,2,2,2,63.670000000,63.740000000,3,4,3,4,63.660000000,63.750000000,3,5,3,5,63.650000000,63.760000000,5,3,5,3,63.640000000,63.770000000,4,2,4,2,63.630000000,63.780000000,4,3,4,3,63.620000000,63.790000000,3,1,3,1,63.610000000,63.800000000,2,3,2,3,63.600000000,63.810000000,7,4,7,2,MCLQ5
2025-06-11T00:00:19.762747336Z,2025-06-11T00:00:19.760280665Z,10,1,42025623,M,B,0,63.690000000,1,130,12991,79314271,63.690000000,63.720000000,3,3,3,3,63.680000000,63.730000000,2,2,2,2,63.670000000,63.740000000,3,4,3,4,63.660000000,63.750000000,3,5,3,5,63.650000000,63.760000000,5,3,5,3,63.640000000,63.770000000,4,2,4,2,63.630000000,63.780000000,4,3,4,3,63.620000000,63.790000000,3,1,3,1,63.610000000,63.800000000,2,3,2,3,63.600000000,63.810000000,7,4,7,2,MCLQ5
2025-06-11T00:00:19.763253529Z,2025-06-11T00:00:19.760607549Z,10,1,42026514,A,B,1,64.770000000,1,130,11950,79314303,64.780000000,64.800000000,4,3,4,3,64.770000000,64.810000000,6,4,5,4,64.760000000,64.820000000,8,11,8,8,64.750000000,64.830000000,5,8,5,8,64.740000000,64.840000000,12,6,11,5,64.730000000,64.850000000,5,8,5,5,64.720000000,64.860000000,9,4,6,3,64.710000000,64.870000000,8,4,7,3,64.700000000,64.880000000,7,4,6,3,64.690000000,64.890000000,4,3,3,2,MCLN5
2025-06-11T00:00:19.763361972Z,2025-06-11T00:00:19.760620239Z,10,1,42026514,A,B,0,64.790000000,2,130,15449,79314306,64.790000000,64.800000000,2,3,1,3,64.780000000,64.810000000,4,4,4,4,64.770000000,64.820000000,6,11,5,8,64.760000000,64.830000000,8,8,8,8,64.750000000,64.840000000,5,6,5,5,64.740000000,64.850000000,12,8,11,5,64.730000000,64.860000000,5,4,5,3,64.720000000,64.870000000,9,4,6,3,64.710000000,64.880000000,8,4,7,3,64.700000000,64.890000000,7,3,6,2,MCLN5
2025-06-11T00:00:19.764135185Z,2025-06-11T00:00:19.760982643Z,10,1,42025623,A,B,6,63.630000000,1,130,11908,79314357,63.690000000,63.720000000,3,3,3,3,63.680000000,63.730000000,2,2,2,2,63.670000000,63.740000000,3,4,3,4,63.660000000,63.750000000,3,5,3,5,63.650000000,63.760000000,5,3,5,3,63.640000000,63.770000000,4,2,4,2,63.630000000,63.780000000,5,3,5,3,63.620000000,63.790000000,3,1,3,1,63.610000000,63.800000000,2,3,2,3,63.600000000,63.810000000,7,4,7,2,MCLQ5
2025-06-11T00:00:19.764318120Z,2025-06-11T00:00:19.761387803Z,10,1,42025623,M,A,0,65.090000000,1,130,13567,79314373,63.690000000,63.720000000,3,2,3,2,63.680000000,63.730000000,2,2,2,2,63.670000000,63.740000000,3,4,3,4,63.660000000,63.750000000,3,5,3,5,63.650000000,63.760000000,5,3,5,3,63.640000000,63.770000000,4,2,4,2,63.630000000,63.780000000,5,3,5,3,63.620000000,63.790000000,3,1,3,1,63.610000000,63.800000000,2,3,2,3,63.600000000,63.810000000,7,4,7,2,MCLQ5
2025-06-11T00:00:19.764649095Z,2025-06-11T00:00:19.761893049Z,10,1,42025623,C,A,5,63.770000000,1,130,11533,79314405,63.690000000,63.720000000,3,2,3,2,63.680000000,63.730000000,2,2,2,2,63.670000000,63.740000000,3,4,3,4,63.660000000,63.750000000,3,5,3,5,63.650000000,63.760000000,5,3,5,3,63.640000000,63.770000000,4,1,4,1,63.630000000,63.780000000,5,3,5,3,63.620000000,63.790000000,3,1,3,1,63.610000000,63.800000000,2,3,2,3,63.600000000,63.810000000,7,4,7,2,MCLQ5
2025-06-11T00:00:19.764671274Z,2025-06-11T00:00:19.761909943Z,10,1,42026514,A,A,0,64.800000000,1,130,13214,79314406,64.790000000,64.800000000,2,4,1,4,64.780000000,64.810000000,4,4,4,4,64.770000000,64.820000000,6,11,5,8,64.760000000,64.830000000,8,8,8,8,64.750000000,64.840000000,5,6,5,5,64.740000000,64.850000000,12,8,11,5,64.730000000,64.860000000,5,4,5,3,64.720000000,64.870000000,9,4,6,3,64.710000000,64.880000000,8,4,7,3,64.700000000,64.890000000,7,3,6,2,MCLN5
2025-06-11T00:00:19.765643619Z,2025-06-11T00:00:19.763069283Z,10,1,42025623,M,A,3,63.760000000,1,130,11931,79314481,63.690000000,63.720000000,3,2,3,2,63.680000000,63.730000000,2,2,2,2,63.670000000,63.740000000,3,4,3,4,63.660000000,63.750000000,3,4,3,4,63.650000000,63.760000000,5,4,5,4,63.640000000,63.770000000,4,1,4,1,63.630000000,63.780000000,5,3,5,3,63.620000000,63.790000000,3,1,3,1,63.610000000,63.800000000,2,3,2,3,63.600000000,63.810000000,7,4,7,2,MCLQ5
2025-06-11T00:00:19.765656564Z,2025-06-11T00:00:19.763070185Z,10,1,42025623,M,A,3,63.760000000,1,130,13018,79314482,63.690000000,63.720000000,3,2,3,2,63.680000000,63.730000000,2,2,2,2,63.670000000,63.740000000,3,4,3,4,63.660000000,63.750000000,3,3,3,3,63.650000000,63.760000000,5,5,5,5,63.640000000,63.770000000,4,1,4,1,63.630000000,63.780000000,5,3,5,3,63.620000000,63.790000000,3,1,3,1,63.610000000,63.800000000,2,3,2,3,63.600000000,63.810000000,7,4,7,2,MCLQ5
2025-06-11T00:00:19.765665987Z,2025-06-11T00:00:19.763071011Z,10,1,42025623,M,A,3,63.760000000,1,130,11562,79314483,63.690000000,63.720000000,3,2,3,2,63.680000000,63.730000000,2,2,2,2,63.670000000,63.740000000,3,4,3,4,63.660000000,63.750000000,3,2,3,2,63.650000000,63.760000000,5,6,5,6,63.640000000,63.770000000,4,1,4,1,63.630000000,63.780000000,5,3,5,3,63.620000000,63.790000000,3,1,3,1,63.610000000,63.800000000,2,3,2,3,63.600000000,63.810000000,7,4,7,2,MCLQ5
2025-06-11T00:00:19.765925936Z,2025-06-11T00:00:19.763226929Z,10,1,42026514,C,A,0,64.800000000,1,130,13097,79314495,64.790000000,64.800000000,2,3,1,3,64.780000000,64.810000000,4,4,4,4,64.770000000,64.820000000,6,11,5,8,64.760000000,64.830000000,8,8,8,8,64.750000000,64.840000000,5,6,5,5,64.740000000,64.850000000,12,8,11,5,64.730000000,64.860000000,5,4,5,3,64.720000000,64.870000000,9,4,6,3,64.710000000,64.880000000,8,4,7,3,64.700000000,64.890000000,7,3,6,2,MCLN5
2025-06-11T00:00:19.766140435Z,2025-06-11T00:00:19.763364587Z,10,1,42026514,T,A,0,64.790000000,2,0,11263,79314508,64.790000000,64.800000000,2,3,1,3,64.780000000,64.810000000,4,4,4,4,64.770000000,64.820000000,6,11,5,8,64.760000000,64.830000000,8,8,8,8,64.750000000,64.840000000,5,6,5,5,64.740000000,64.850000000,12,8,11,5,64.730000000,64.860000000,5,4,5,3,64.720000000,64.870000000,9,4,6,3,64.710000000,64.880000000,8,4,7,3,64.700000000,64.890000000,7,3,6,2,MCLN5
2025-06-11T00:00:19.766161930Z,2025-06-11T00:00:19.763364587Z,10,1,42026514,C,B,0,64.790000000,2,130,15439,79314509,64.780000000,64.800000000,4,3,4,3,64.770000000,64.810000000,6,4,5,4,64.760000000,64.820000000,8,11,8,8,64.750000000,64.830000000,5,8,5,8,64.740000000,64.840000000,12,6,11,5,64.730000000,64.850000000,5,8,5,5,64.720000000,64.860000000,9,4,6,3,64.710000000,64.870000000,8,4,7,3,64.700000000,64.880000000,7,4,6,3,64.690000000,64.890000000,4,3,3,2,MCLN5
2025-06-11T00:00:19.766247987Z,2025-06-11T00:00:19.763427253Z,10,1,42026514,M,B,3,64.750000000,1,130,12323,79314515,64.780000000,64.800000000,4,3,4,3,64.770000000,64.810000000,6,4,5,4,64.760000000,64.820000000,8,11,8,8,64.750000000,64.830000000,6,8,6,8,64.740000000,64.840000000,12,6,11,5,64.730000000,64.850000000,5,8,5,5,64.720000000,64.860000000,9,4,6,3,64.710000000,64.870000000,8,4,7,3,64.700000000,64.880000000,7,4,6,3,64.690000000,64.890000000,4,3,3,2,MCLN5
2025-06-11T00:00:19.766335227Z,2025-06-11T00:00:19.763522325Z,10,1,42026514,M,B,2,64.760000000,1,130,11665,79314520,64.780000000,64.800000000,4,3,4,3,64.770000000,64.810000000,6,4,5,4,64.760000000,64.820000000,9,11,9,8,64.750000000,64.830000000,6,8,6,8,64.740000000,64.840000000,12,6,11,5,64.730000000,64.850000000,5,8,5,5,64.720000000,64.860000000,9,4,6,3,64.710000000,64.870000000,8,4,7,3,64.700000000,64.880000000,7,4,6,3,64.690000000,64.890000000,4,3,3,2,MCLN5
2025-06-11T00:00:19.767152298Z,2025-06-11T00:00:19.764022157Z,10,1,42026514,A,A,0,64.800000000,1,130,13461,79314568,64.780000000,64.800000000,4,4,4,4,64.770000000,64.810000000,6,4,5,4,64.760000000,64.820000000,9,11,9,8,64.750000000,64.830000000,6,8,6,8,64.740000000,64.840000000,12,6,11,5,64.730000000,64.850000000,5,8,5,5,64.720000000,64.860000000,9,4,6,3,64.710000000,64.870000000,8,4,7,3,64.700000000,64.880000000,7,4,6,3,64.690000000,64.890000000,4,3,3,2,MCLN5
2025-06-11T00:00:19.768897609Z,2025-06-11T00:00:19.765694269Z,10,1,42026514,C,A,0,64.800000000,1,130,16745,79314698,64.780000000,64.800000000,4,3,4,3,64.770000000,64.810000000,6,4,5,4,64.760000000,64.820000000,9,11,9,8,64.750000000,64.830000000,6,8,6,8,64.740000000,64.840000000,12,6,11,5,64.730000000,64.850000000,5,8,5,5,64.720000000,64.860000000,9,4,6,3,64.710000000,64.870000000,8,4,7,3,64.700000000,64.880000000,7,4,6,3,64.690000000,64.890000000,4,3,3,2,MCLN5
2025-06-11T00:00:19.769197137Z,2025-06-11T00:00:19.766004411Z,10,1,42026514,A,B,0,64.790000000,1,130,11468,79314720,64.790000000,64.800000000,1,3,1,3,64.780000000,64.810000000,4,4,4,4,64.770000000,64.820000000,6,11,5,8,64.760000000,64.830000000,9,8,9,8,64.750000000,64.840000000,6,6,6,5,64.740000000,64.850000000,12,8,11,5,64.730000000,64.860000000,5,4,5,3,64.720000000,64.870000000,9,4,6,3,64.710000000,64.880000000,8,4,7,3,64.700000000,64.890000000,7,3,6,2,MCLN5
2025-06-11T00:00:19.769577929Z,2025-06-11T00:00:19.766370577Z,10,1,42026514,M,B,1,64.780000000,1,130,13308,79314742,64.790000000,64.800000000,1,3,1,3,64.780000000,64.810000000,5,4,5,4,64.770000000,64.820000000,6,11,5,8,64.760000000,64.830000000,9,8,9,8,64.750000000,64.840000000,6,6,6,5,64.740000000,64.850000000,12,8,11,5,64.730000000,64.860000000,5,4,5,3,64.720000000,64.870000000,9,4,6,3,64.710000000,64.880000000,8,4,7,3,64.700000000,64.890000000,7,3,6,2,MCLN5
2025-06-11T00:00:19.769796498Z,2025-06-11T00:00:19.766509695Z,10,1,42026514,C,B,0,64.790000000,1,130,13342,79314757,64.780000000,64.800000000,5,3,5,3,64.770000000,64.810000000,6,4,5,4,64.760000000,64.820000000,9,11,9,8,64.750000000,64.830000000,6,8,6,8,64.740000000,64.840000000,12,6,11,5,64.730000000,64.850000000,5,8,5,5,64.720000000,64.860000000,9,4,6,3,64.710000000,64.870000000,8,4,7,3,64.700000000,64.880000000,7,4,6,3,64.690000000,64.890000000,4,3,3,2,MCLN5
2025-06-11T00:00:19.770059847Z,2025-06-11T00:00:19.767315579Z,10,1,42026514,C,B,0,64.780000000,1,130,14067,79314779,64.780000000,64.800000000,4,3,4,3,64.770000000,64.810000000,6,4,5,4,64.760000000,64.820000000,9,11,9,8,64.750000000,64.830000000,6,8,6,8,64.740000000,64.840000000,12,6,11,5,64.730000000,64.850000000,5,8,5,5,64.720000000,64.860000000,9,4,6,3,64.710000000,64.870000000,8,4,7,3,64.700000000,64.880000000,7,4,6,3,64.690000000,64.890000000,4,3,3,2,MCLN5
2025-06-11T00:00:19.771370700Z,2025-06-11T00:00:19.768906401Z,10,1,42026514,C,B,0,64.780000000,1,130,12987,79314888,64.780000000,64.800000000,3,3,3,3,64.770000000,64.810000000,6,4,5,4,64.760000000,64.820000000,9,11,9,8,64.750000000,64.830000000,6,8,6,8,64.740000000,64.840000000,12,6,11,5,64.730000000,64.850000000,5,8,5,5,64.720000000,64.860000000,9,4,6,3,64.710000000,64.870000000,8,4,7,3,64.700000000,64.880000000,7,4,6,3,64.690000000,64.890000000,4,3,3,2,MCLN5
2025-06-11T00:00:19.771402409Z,2025-06-11T00:00:19.768995755Z,10,1,42026514,M,B,0,64.780000000,1,130,13547,79314891,64.780000000,64.800000000,4,3,4,3,64.770000000,64.810000000,6,4,5,4,64.760000000,64.820000000,9,11,9,8,64.750000000,64.830000000,6,8,6,8,64.740000000,64.840000000,12,6,11,5,64.730000000,64.850000000,5,8,5,5,64.720000000,64.860000000,9,4,6,3,64.710000000,64.870000000,8,4,7,3,64.700000000,64.880000000,7,4,6,3,64.690000000,64.890000000,4,3,3,2,MCLN5
2025-06-11T00:00:19.771418152Z,2025-06-11T00:00:19.769034325Z,10,1,42026514,M,A,1,66.790000000,2,130,12808,79314892,64.780000000,64.800000000,4,3,4,3,64.770000000,64.810000000,6,3,5,3,64.760000000,64.820000000,9,11,9,8,64.750000000,64.830000000,6,8,6,8,64.740000000,64.840000000,12,6,11,5,64.730000000,64.850000000,5,8,5,5,64.720000000,64.860000000,9,4,6,3,64.710000000,64.870000000,8,4,7,3,64.700000000,64.880000000,7,4,6,3,64.690000000,64.890000000,4,3,3,2,MCLN5
2025-06-11T00:00:19.772085747Z,2025-06-11T00:00:19.769950165Z,10,1,42026514,C,B,0,64.780000000,1,130,12983,79314942,64.780000000,64.800000000,3,3,3,3,64.770000000,64.810000000,6,3,5,3,64.760000000,64.820000000,9,11,9,8,64.750000000,64.830000000,6,8,6,8,64.740000000,64.840000000,12,6,11,5,64.730000000,64.850000000,5,8,5,5,64.720000000,64.860000000,9,4,6,3,64.710000000,64.870000000,8,4,7,3,64.700000000,64.880000000,7,4,6,3,64.690000000,64.890000000,4,3,3,2,MCLN5
2025-06-11T00:00:19.773490706Z,2025-06-11T00:00:19.772095285Z,10,1,42025623,C,B,6,63.630000000,1,130,11599,79315050,63.690000000,63.720000000,3,2,3,2,63.680000000,63.730000000,2,2,2,2,63.670000000,63.740000000,3,4,3,4,63.660000000,63.750000000,3,2,3,2,63.650000000,63.760000000,5,6,5,6,63.640000000,63.770000000,4,1,4,1,63.630000000,63.780000000,4,3,4,3,63.620000000,63.790000000,3,1,3,1,63.610000000,63.800000000,2,3,2,3,63.600000000,63.810000000,7,4,7,2,MCLQ5
2025-06-11T00:00:19.773500982Z,2025-06-11T00:00:19.772097417Z,10,1,42025623,A,A,6,63.780000000,1,130,11277,79315051,63.690000000,63.720000000,3,2,3,2,63.680000000,63.730000000,2,2,2,2,63.670000000,63.740000000,3,4,3,4,63.660000000,63.750000000,3,2,3,2,63.650000000,63.760000000,5,6,5,6,63.640000000,63.770000000,4,1,4,1,63.630000000,63.780000000,4,4,4,4,63.620000000,63.790000000,3,1,3,1,63.610000000,63.800000000,2,3,2,3,63.600000000,63.810000000,7,4,7,2,MCLQ5
2025-06-11T00:00:19.773633570Z,2025-06-11T00:00:19.772227913Z,10,1,42025623,A,B,5,63.640000000,1,130,11462,79315063,63.690000000,63.720000000,3,2,3,2,63.680000000,63.730000000,2,2,2,2,63.670000000,63.740000000,3,4,3,4,63.660000000,63.750000000,3,2,3,2,63.650000000,63.760000000,5,6,5,6,63.640000000,63.770000000,5,1,5,1,63.630000000,63.780000000,4,4,4,4,63.620000000,63.790000000,3,1,3,1,63.610000000,63.800000000,2,3,2,3,63.600000000,63.810000000,7,4,7,2,MCLQ5
2025-06-11T00:00:19.773719765Z,2025-06-11T00:00:19.772622723Z,10,1,42026514,M,A,4,66.800000000,2,130,15836,79315072,64.780000000,64.800000000,3,3,3,3,64.770000000,64.810000000,6,3,5,3,64.760000000,64.820000000,9,11,9,8,64.750000000,64.830000000,6,8,6,8,64.740000000,64.840000000,12,5,11,4,64.730000000,64.850000000,5,8,5,5,64.720000000,64.860000000,9,4,6,3,64.710000000,64.870000000,8,4,7,3,64.700000000,64.880000000,7,4,6,3,64.690000000,64.890000000,4,3,3,2,MCLN5
2025-06-11T00:00:19.775903205Z,2025-06-11T00:00:19.775769043Z,10,1,42026514,A,A,0,64.790000000,2,130,14987,79315130,64.780000000,64.790000000,3,2,3,1,64.770000000,64.800000000,6,3,5,3,64.760000000,64.810000000,9,3,9,3,64.750000000,64.820000000,6,11,6,8,64.740000000,64.830000000,12,8,11,8,64.730000000,64.840000000,5,5,5,4,64.720000000,64.850000000,9,8,6,5,64.710000000,64.860000000,8,4,7,3,64.700000000,64.870000000,7,4,6,3,64.690000000,64.880000000,4,4,3,3,MCLN5
2025-06-11T00:00:19.776010543Z,2025-06-11T00:00:19.775910561Z,10,1,42026514,M,A,3,64.830000000,1,130,15233,79315134,64.780000000,64.790000000,3,2,3,1,64.770000000,64.800000000,6,3,5,3,64.760000000,64.810000000,9,3,9,3,64.750000000,64.820000000,6,10,6,7,64.740000000,64.830000000,12,9,11,9,64.730000000,64.840000000,5,5,5,4,64.720000000,64.850000000,9,8,6,5,64.710000000,64.860000000,8,4,7,3,64.700000000,64.870000000,7,4,6,3,64.690000000,64.880000000,4,4,3,3,MCLN5
2025-06-11T00:00:19.776018514Z,2025-06-11T00:00:19.775911019Z,10,1,42026514,M,B,3,64.750000000,1,130,11479,79315135,64.780000000,64.790000000,3,2,3,1,64.770000000,64.800000000,6,3,5,3,64.760000000,64.810000000,9,3,9,3,64.750000000,64.820000000,7,10,7,7,64.740000000,64.830000000,11,9,10,9,64.730000000,64.840000000,5,5,5,4,64.720000000,64.850000000,9,8,6,5,64.710000000,64.860000000,8,4,7,3,64.700000000,64.870000000,7,4,6,3,64.690000000,64.880000000,4,4,3,3,MCLN5
2025-06-11T00:00:19.776027714Z,2025-06-11T00:00:19.775911501Z,10,1,42026514,M,A,3,64.830000000,1,130,11945,79315136,64.780000000,64.790000000,3,2,3,1,64.770000000,64.800000000,6,3,5,3,64.760000000,64.810000000,9,3,9,3,64.750000000,64.820000000,7,9,7,6,64.740000000,64.830000000,11,10,10,10,64.730000000,64.840000000,5,5,5,4,64.720000000,64.850000000,9,8,6,5,64.710000000,64.860000000,8,4,7,3,64.700000000,64.870000000,7,4,6,3,64.690000000,64.880000000,4,4,3,3,MCLN5
2025-06-11T00:00:19.776038289Z,2025-06-11T00:00:19.775911999Z,10,1,42026514,M,B,3,64.750000000,1,130,11650,79315137,64.780000000,64.790000000,3,2,3,1,64.770000000,64.800000000,6,3,5,3,64.760000000,64.810000000,9,3,9,3,64.750000000,64.820000000,8,9,8,6,64.740000000,64.830000000,10,10,9,10,64.730000000,64.840000000,5,5,5,4,64.720000000,64.850000000,9,8,6,5,64.710000000,64.860000000,8,4,7,3,64.700000000,64.870000000,7,4,6,3,64.690000000,64.880000000,4,4,3,3,MCLN5
2025-06-11T00:00:19.776049363Z,2025-06-11T00:00:19.775924729Z,10,1,42025623,C,B,5,63.640000000,1,130,11259,79315138,63.690000000,63.720000000,3,2,3,2,63.680000000,63.730000000,2,2,2,2,63.670000000,63.740000000,3,4,3,4,63.660000000,63.750000000,3,2,3,2,63.650000000,63.760000000,5,6,5,6,63.640000000,63.770000000,4,1,4,1,63.630000000,63.780000000,4,4,4,4,63.620000000,63.790000000,3,1,3,1,63.610000000,63.800000000,2,3,2,3,63.600000000,63.810000000,7,4,7,2,MCLQ5
2025-06-11T00:00:19.776059508Z,2025-06-11T00:00:19.775929201Z,10,1,42025623,C,A,6,63.780000000,1,130,11290,79315139,63.690000000,63.720000000,3,2,3,2,63.680000000,63.730000000,2,2,2,2,63.670000000,63.740000000,3,4,3,4,63.660000000,63.750000000,3,2,3,2,63.650000000,63.760000000,5,6,5,6,63.640000000,63.770000000,4,1,4,1,63.630000000,63.780000000,4,3,4,3,63.620000000,63.790000000,3,1,3,1,63.610000000,63.800000000,2,3,2,3,63.600000000,63.810000000,7,4,7,2,MCLQ5
2025-06-11T00:00:19.776193640Z,2025-06-11T00:00:19.776077053Z,10,1,42025623,M,B,2,62.300000000,1,130,15116,79315140,63.690000000,63.720000000,3,2,3,2,63.680000000,63.730000000,2,2,2,2,63.670000000,63.740000000,2,4,2,4,63.660000000,63.750000000,3,2,3,2,63.650000000,63.760000000,5,6,5,6,63.640000000,63.770000000,4,1,4,1,63.630000000,63.780000000,4,3,4,3,63.620000000,63.790000000,3,1,3,1,63.610000000,63.800000000,2,3,2,3,63.600000000,63.810000000,7,4,7,2,MCLQ5
2025-06-11T00:00:19.776213522Z,2025-06-11T00:00:19.776082777Z,10,1,42025623,A,B,6,63.630000000,1,130,13178,79315141,63.690000000,63.720000000,3,2,3,2,63.680000000,63.730000000,2,2,2,2,63.670000000,63.740000000,2,4,2,4,63.660000000,63.750000000,3,2,3,2,63.650000000,63.760000000,5,6,5,6,63.640000000,63.770000000,4,1,4,1,63.630000000,63.780000000,5,3,5,3,63.620000000,63.790000000,3,1,3,1,63.610000000,63.800000000,2,3,2,3,63.600000000,63.810000000,7,4,7,2,MCLQ5
2025-06-11T00:00:19.776221186Z,2025-06-11T00:00:19.776090493Z,10,1,42025623,A,A,5,63.770000000,1,130,11227,79315142,63.690000000,63.720000000,3,2,3,2,63.680000000,63.730000000,2,2,2,2,63.670000000,63.740000000,2,4,2,4,63.660000000,63.750000000,3,2,3,2,63.650000000,63.760000000,5,6,5,6,63.640000000,63.770000000,4,2,4,2,63.630000000,63.780000000,5,3,5,3,63.620000000,63.790000000,3,1,3,1,63.610000000,63.800000000,2,3,2,3,63.600000000,63.810000000,7,4,7,2,MCLQ5
2025-06-11T00:00:19.786876803Z,2025-06-11T00:00:19.786763301Z,10,1,42026514,C,A,0,64.790000000,2,130,14603,79315190,64.780000000,64.800000000,3,3,3,3,64.770000000,64.810000000,6,3,5,3,64.760000000,64.820000000,9,9,9,6,64.750000000,64.830000000,8,10,8,10,64.740000000,64.840000000,10,5,9,4,64.730000000,64.850000000,5,8,5,5,64.720000000,64.860000000,9,4,6,3,64.710000000,64.870000000,8,4,7,3,64.700000000,64.880000000,7,4,6,3,64.690000000,64.890000000,4,3,3,2,MCLN5
2025-06-11T00:00:19.786990714Z,2025-06-11T00:00:19.786897657Z,10,1,42025623,C,A,5,63.770000000,1,130,15253,79315193,63.690000000,63.720000000,3,2,3,2,63.680000000,63.730000000,2,2,2,2,63.670000000,63.740000000,2,4,2,4,63.660000000,63.750000000,3,2,3,2,63.650000000,63.760000000,5,6,5,6,63.640000000,63.770000000,4,1,4,1,63.630000000,63.780000000,5,3,5,3,63.620000000,63.790000000,3,1,3,1,63.610000000,63.800000000,2,3,2,3,63.600000000,63.810000000,7,4,7,2,MCLQ5
2025-06-11T00:00:19.786998609Z,2025-06-11T00:00:19.786902015Z,10,1,42025623,C,B,6,63.630000000,1,130,11248,79315194,63.690000000,63.720000000,3,2,3,2,63.680000000,63.730000000,2,2,2,2,63.670000000,63.740000000,2,4,2,4,63.660000000,63.750000000,3,2,3,2,63.650000000,63.760000000,5,6,5,6,63.640000000,63.770000000,4,1,4,1,63.630000000,63.780000000,4,3,4,3,63.620000000,63.790000000,3,1,3,1,63.610000000,63.800000000,2,3,2,3,63.600000000,63.810000000,7,4,7,2,MCLQ5
2025-06-11T00:00:19.787110247Z,2025-06-11T00:00:19.787008839Z,10,1,42025623,A,A,6,63.780000000,1,130,14828,79315195,63.690000000,63.720000000,3,2,3,2,63.680000000,63.730000000,2,2,2,2,63.670000000,63.740000000,2,4,2,4,63.660000000,63.750000000,3,2,3,2,63.650000000,63.760000000,5,6,5,6,63.640000000,63.770000000,4,1,4,1,63.630000000,63.780000000,4,4,4,4,63.620000000,63.790000000,3,1,3,1,63.610000000,63.800000000,2,3,2,3,63.600000000,63.810000000,7,4,7,2,MCLQ5
2025-06-11T00:00:19.787119186Z,2025-06-11T00:00:19.787019205Z,10,1,42025623,A,B,5,63.640000000,1,130,11741,79315196,63.690000000,63.720000000,3,2,3,2,63.680000000,63.730000000,2,2,2,2,63.670000000,63.740000000,2,4,2,4,63.660000000,63.750000000,3,2,3,2,63.650000000,63.760000000,5,6,5,6,63.640000000,63.770000000,5,1,5,1,63.630000000,63.780000000,4,4,4,4,63.620000000,63.790000000,3,1,3,1,63.610000000,63.800000000,2,3,2,3,63.600000000,63.810000000,7,4,7,2,MCLQ5
2025-06-11T00:00:19.797018346Z,2025-06-11T00:00:19.796910687Z,10,1,42026514,C,B,6,64.720000000,1,130,15245,79315213,64.780000000,64.800000000,3,3,3,3,64.770000000,64.810000000,6,3,5,3,64.760000000,64.820000000,9,9,9,6,64.750000000,64.830000000,8,10,8,10,64.740000000,64.840000000,10,5,9,4,64.730000000,64.850000000,5,8,5,5,64.720000000,64.860000000,8,4,5,3,64.710000000,64.870000000,8,4,7,3,64.700000000,64.880000000,7,4,6,3,64.690000000,64.890000000,4,3,3,2,MCLN5
2025-06-11T00:00:19.797027224Z,2025-06-11T00:00:19.796912875Z,10,1,42026514,A,A,5,64.850000000,1,130,12064,79315214,64.780000000,64.800000000,3,3,3,3,64.770000000,64.810000000,6,3,5,3,64.760000000,64.820000000,9,9,9,6,64.750000000,64.830000000,8,10,8,10,64.740000000,64.840000000,10,5,9,4,64.730000000,64.850000000,5,9,5,6,64.720000000,64.860000000,8,4,5,3,64.710000000,64.870000000,8,4,7,3,64.700000000,64.880000000,7,4,6,3,64.690000000,64.890000000,4,3,3,2,MCLN5
2025-06-11T00:00:19.797133509Z,2025-06-11T00:00:19.797034925Z,10,1,42026514,A,B,5,64.730000000,1,130,14882,79315215,64.780000000,64.800000000,3,3,3,3,64.770000000,64.810000000,6,3,5,3,64.760000000,64.820000000,9,9,9,6,64.750000000,64.830000000,8,10,8,10,64.740000000,64.840000000,10,5,9,4,64.730000000,64.850000000,6,9,6,6,64.720000000,64.860000000,8,4,5,3,64.710000000,64.870000000,8,4,7,3,64.700000000,64.880000000,7,4,6,3,64.690000000,64.890000000,4,3,3,2,MCLN5
2025-06-11T00:00:19.858184882Z,2025-06-11T00:00:19.857324039Z,10,1,42026514,A,A,0,64.790000000,1,130,15510,79315438,64.780000000,64.790000000,3,1,3,1,64.770000000,64.800000000,6,3,5,3,64.760000000,64.810000000,9,3,9,3,64.750000000,64.820000000,8,9,8,6,64.740000000,64.830000000,10,10,9,10,64.730000000,64.840000000,6,5,6,4,64.720000000,64.850000000,8,9,5,6,64.710000000,64.860000000,8,4,7,3,64.700000000,64.870000000,7,4,6,3,64.690000000,64.880000000,4,4,3,3,MCLN5
2025-06-11T00:00:19.858762964Z,2025-06-11T00:00:19.858206029Z,10,1,42025623,C,B,5,63.640000000,1,130,11741,79315484,63.690000000,63.720000000,3,2,3,2,63.680000000,63.730000000,2,2,2,2,63.670000000,63.740000000,2,4,2,4,63.660000000,63.750000000,3,2,3,2,63.650000000,63.760000000,5,6,5,6,63.640000000,63.770000000,4,1,4,1,63.630000000,63.780000000,4,4,4,4,63.620000000,63.790000000,3,1,3,1,63.610000000,63.800000000,2,3,2,3,63.600000000,63.810000000,7,4,7,2,MCLQ5
2025-06-11T00:00:19.858791877Z,2025-06-11T00:00:19.858211271Z,10,1,42025623,C,A,6,63.780000000,1,130,11731,79315487,63.690000000,63.720000000,3,2,3,2,63.680000000,63.730000000,2,2,2,2,63.670000000,63.740000000,2,4,2,4,63.660000000,63.750000000,3,2,3,2,63.650000000,63.760000000,5,6,5,6,63.640000000,63.770000000,4,1,4,1,63.630000000,63.780000000,4,3,4,3,63.620000000,63.790000000,3,1,3,1,63.610000000,63.800000000,2,3,2,3,63.600000000,63.810000000,7,4,7,2,MCLQ5
2025-06-11T00:00:19.858962902Z,2025-06-11T00:00:19.858367705Z,10,1,42026514,M,A,2,64.810000000,1,130,11679,79315503,64.780000000,64.790000000,3,1,3,1,64.770000000,64.800000000,6,3,5,3,64.760000000,64.810000000,9,4,9,4,64.750000000,64.820000000,8,9,8,6,64.740000000,64.830000000,10,10,9,10,64.730000000,64.840000000,6,5,6,4,64.720000000,64.850000000,8,9,5,6,64.710000000,64.860000000,8,4,7,3,64.700000000,64.870000000,7,4,6,3,64.690000000,64.880000000,4,4,3,3,MCLN5
2025-06-11T00:00:19.859468035Z,2025-06-11T00:00:19.858972959Z,10,1,42025623,A,B,6,63.630000000,1,130,22662,79315519,63.690000000,63.720000000,3,2,3,2,63.680000000,63.730000000,2,2,2,2,63.670000000,63.740000000,2,4,2,4,63.660000000,63.750000000,3,2,3,2,63.650000000,63.760000000,5,6,5,6,63.640000000,63.770000000,4,1,4,1,63.630000000,63.780000000,5,3,5,3,63.620000000,63.790000000,3,1,3,1,63.610000000,63.800000000,2,3,2,3,63.600000000,63.810000000,7,4,7,2,MCLQ5
2025-06-11T00:00:19.859468035Z,2025-06-11T00:00:19.858984171Z,10,1,42025623,A,A,5,63.770000000,1,130,22662,79315519,63.690000000,63.720000000,3,2,3,2,63.680000000,63.730000000,2,2,2,2,63.670000000,63.740000000,2,4,2,4,63.660000000,63.750000000,3,2,3,2,63.650000000,63.760000000,5,6,5,6,63.640000000,63.770000000,4,2,4,2,63.630000000,63.780000000,5,3,5,3,63.620000000,63.790000000,3,1,3,1,63.610000000,63.800000000,2,3,2,3,63.600000000,63.810000000,7,4,7,2,MCLQ5
2025-06-11T00:00:19.868417014Z,2025-06-11T00:00:19.866416491Z,10,1,42026514,A,A,0,64.790000000,2,130,14335,79315987,64.780000000,64.790000000,3,3,3,2,64.770000000,64.800000000,6,3,5,3,64.760000000,64.810000000,9,4,9,4,64.750000000,64.820000000,8,9,8,6,64.740000000,64.830000000,10,10,9,10,64.730000000,64.840000000,6,5,6,4,64.720000000,64.850000000,8,9,5,6,64.710000000,64.860000000,8,4,7,3,64.700000000,64.870000000,7,4,6,3,64.690000000,64.880000000,4,4,3,3,MCLN5
2025-06-11T00:00:19.869241495Z,2025-06-11T00:00:19.867319003Z,10,1,42418117,M,A,0,3.290000000,10,130,11475,79316057,3.250000000,3.280000000,11,1,2,1,3.240000000,3.290000000,1,11,1,2,3.230000000,3.300000000,1,1,1,1,,,0,0,0,0,,,0,0,0,0,,,0,0,0,0,,,0,0,0,0,,,0,0,0,0,,,0,0,0,0,,,0,0,0,0,MCLN5-MCLX5
2025-06-11T00:00:19.869692633Z,2025-06-11T00:00:19.868330933Z,10,1,42026514,M,A,5,64.840000000,1,130,11234,79316093,64.780000000,64.790000000,3,3,3,2,64.770000000,64.800000000,6,3,5,3,64.760000000,64.810000000,9,4,9,4,64.750000000,64.820000000,8,9,8,6,64.740000000,64.830000000,10,10,9,10,64.730000000,64.840000000,6,6,6,5,64.720000000,64.850000000,8,9,5,6,64.710000000,64.860000000,8,4,7,3,64.700000000,64.870000000,7,4,6,3,64.690000000,64.880000000,4,4,3,3,MCLN5
2025-06-11T00:00:19.869703093Z,2025-06-11T00:00:19.868455285Z,10,1,42418117,M,B,0,3.240000000,10,130,11654,79316094,3.250000000,3.280000000,1,1,1,1,3.240000000,3.290000000,11,11,2,2,3.230000000,3.300000000,1,1,1,1,,,0,0,0,0,,,0,0,0,0,,,0,0,0,0,,,0,0,0,0,,,0,0,0,0,,,0,0,0,0,,,0,0,0,0,MCLN5-MCLX5
2025-06-11T00:00:19.955139868Z,2025-06-11T00:00:19.955016577Z,10,1,42026514,A,B,0,64.780000000,1,130,16902,79316426,64.780000000,64.790000000,4,3,4,2,64.770000000,64.800000000,6,3,5,3,64.760000000,64.810000000,9,4,9,4,64.750000000,64.820000000,8,9,8,6,64.740000000,64.830000000,10,10,9,10,64.730000000,64.840000000,6,6,6,5,64.720000000,64.850000000,8,9,5,6,64.710000000,64.860000000,8,4,7,3,64.700000000,64.870000000,7,4,6,3,64.690000000,64.880000000,4,4,3,3,MCLN5
2025-06-11T00:00:19.955191406Z,2025-06-11T00:00:19.955020379Z,10,1,42026514,C,A,0,64.790000000,2,130,11543,79316428,64.780000000,64.790000000,4,1,4,1,64.770000000,64.800000000,6,3,5,3,64.760000000,64.810000000,9,4,9,4,64.750000000,64.820000000,8,9,8,6,64.740000000,64.830000000,10,10,9,10,64.730000000,64.840000000,6,6,6,5,64.720000000,64.850000000,8,9,5,6,64.710000000,64.860000000,8,4,7,3,64.700000000,64.870000000,7,4,6,3,64.690000000,64.880000000,4,4,3,3,MCLN5
2025-06-11T00:00:19.955330315Z,2025-06-11T00:00:19.955200275Z,10,1,42026514,C,B,0,64.780000000,1,130,13313,79316435,64.780000000,64.790000000,3,1,3,1,64.770000000,64.800000000,6,3,5,3,64.760000000,64.810000000,9,4,9,4,64.750000000,64.820000000,8,9,8,6,64.740000000,64.830000000,10,10,9,10,64.730000000,64.840000000,6,6,6,5,64.720000000,64.850000000,8,9,5,6,64.710000000,64.860000000,8,4,7,3,64.700000000,64.870000000,7,4,6,3,64.690000000,64.880000000,4,4,3,3,MCLN5
2025-06-11T00:00:19.955469676Z,2025-06-11T00:00:19.955358725Z,10,1,42026514,M,B,0,64.780000000,1,130,17374,79316438,64.780000000,64.790000000,4,1,4,1,64.770000000,64.800000000,6,3,5,3,64.760000000,64.810000000,9,4,9,4,64.750000000,64.820000000,8,9,8,6,64.740000000,64.830000000,10,10,9,10,64.730000000,64.840000000,6,6,6,5,64.720000000,64.850000000,8,9,5,6,64.710000000,64.860000000,8,4,7,3,64.700000000,64.870000000,7,4,6,3,64.690000000,64.880000000,4,4,3,3,MCLN5
2025-06-11T00:00:19.955547563Z,2025-06-11T00:00:19.955450037Z,10,1,42026514,C,B,0,64.780000000,1,130,13397,79316439,64.780000000,64.790000000,3,1,3,1,64.770000000,64.800000000,6,3,5,3,64.760000000,64.810000000,9,4,9,4,64.750000000,64.820000000,8,9,8,6,64.740000000,64.830000000,10,10,9,10,64.730000000,64.840000000,6,6,6,5,64.720000000,64.850000000,8,9,5,6,64.710000000,64.860000000,8,4,7,3,64.700000000,64.870000000,7,4,6,3,64.690000000,64.880000000,4,4,3,3,MCLN5
2025-06-11T00:00:20.007480651Z,2025-06-11T00:00:20.007341445Z,10,1,42026514,A,A,0,64.790000000,2,130,19150,79316513,64.780000000,64.790000000,3,3,3,2,64.770000000,64.800000000,6,3,5,3,64.760000000,64.810000000,9,4,9,4,64.750000000,64.820000000,8,9,8,6,64.740000000,64.830000000,10,10,9,10,64.730000000,64.840000000,6,6,6,5,64.720000000,64.850000000,8,9,5,6,64.710000000,64.860000000,8,4,7,3,64.700000000,64.870000000,7,4,6,3,64.690000000,64.880000000,4,4,3,3,MCLN5
2025-06-11T00:00:20.009717818Z,2025-06-11T00:00:20.009612589Z,10,1,42026514,A,B,0,64.780000000,1,130,13674,79316518,64.780000000,64.790000000,4,3,4,2,64.770000000,64.800000000,6,3,5,3,64.760000000,64.810000000,9,4,9,4,64.750000000,64.820000000,8,9,8,6,64.740000000,64.830000000,10,10,9,10,64.730000000,64.840000000,6,6,6,5,64.720000000,64.850000000,8,9,5,6,64.710000000,64.860000000,8,4,7,3,64.700000000,64.870000000,7,4,6,3,64.690000000,64.880000000,4,4,3,3,MCLN5
2025-06-11T00:00:20.009948351Z,2025-06-11T00:00:20.009848469Z,10,1,42026514,C,B,0,64.780000000,1,130,16657,79316521,64.780000000,64.790000000,3,3,3,2,64.770000000,64.800000000,6,3,5,3,64.760000000,64.810000000,9,4,9,4,64.750000000,64.820000000,8,9,8,6,64.740000000,64.830000000,10,10,9,10,64.730000000,64.840000000,6,6,6,5,64.720000000,64.850000000,8,9,5,6,64.710000000,64.860000000,8,4,7,3,64.700000000,64.870000000,7,4,6,3,64.690000000,64.880000000,4,4,3,3,MCLN5
2025-06-11T00:00:20.010076593Z,2025-06-11T00:00:20.009974129Z,10,1,42026514,A,B,0,64.780000000,1,130,16423,79316522,64.780000000,64.790000000,4,3,4,2,64.770000000,64.800000000,6,3,5,3,64.760000000,64.810000000,9,4,9,4,64.750000000,64.820000000,8,9,8,6,64.740000000,64.830000000,10,10,9,10,64.730000000,64.840000000,6,6,6,5,64.720000000,64.850000000,8,9,5,6,64.710000000,64.860000000,8,4,7,3,64.700000000,64.870000000,7,4,6,3,64.690000000,64.880000000,4,4,3,3,MCLN5
2025-06-11T00:00:20.010233587Z,2025-06-11T00:00:20.010136111Z,10,1,42026514,C,B,0,64.780000000,1,130,15483,79316523,64.780000000,64.790000000,3,3,3,2,64.770000000,64.800000000,6,3,5,3,64.760000000,64.810000000,9,4,9,4,64.750000000,64.820000000,8,9,8,6,64.740000000,64.830000000,10,10,9,10,64.730000000,64.840000000,6,6,6,5,64.720000000,64.850000000,8,9,5,6,64.710000000,64.860000000,8,4,7,3,64.700000000,64.870000000,7,4,6,3,64.690000000,64.880000000,4,4,3,3,MCLN5
2025-06-11T00:00:20.019158106Z,2025-06-11T00:00:20.019035377Z,10,1,42026514,C,A,0,64.790000000,2,130,15109,79316533,64.780000000,64.790000000,3,1,3,1,64.770000000,64.800000000,6,3,5,3,64.760000000,64.810000000,9,4,9,4,64.750000000,64.820000000,8,9,8,6,64.740000000,64.830000000,10,10,9,10,64.730000000,64.840000000,6,6,6,5,64.720000000,64.850000000,8,9,5,6,64.710000000,64.860000000,8,4,7,3,64.700000000,64.870000000,7,4,6,3,64.690000000,64.880000000,4,4,3,3,MCLN5
2025-06-11T00:00:20.019280903Z,2025-06-11T00:00:20.019177415Z,10,1,42025623,M,A,3,63.750000000,1,130,14738,79316535,63.690000000,63.720000000,3,2,3,2,63.680000000,63.730000000,2,2,2,2,63.670000000,63.740000000,2,4,2,4,63.660000000,63.750000000,3,3,3,3,63.650000000,63.760000000,5,5,5,5,63.640000000,63.770000000,4,2,4,2,63.630000000,63.780000000,5,3,5,3,63.620000000,63.790000000,3,1,3,1,63.610000000,63.800000000,2,3,2,3,63.600000000,63.810000000,7,4,7,2,MCLQ5
2025-06-11T00:00:20.019289442Z,2025-06-11T00:00:20.019178125Z,10,1,42025623,M,A,3,63.750000000,1,130,11642,79316536,63.690000000,63.720000000,3,2,3,2,63.680000000,63.730000000,2,2,2,2,63.670000000,63.740000000,2,4,2,4,63.660000000,63.750000000,3,4,3,4,63.650000000,63.760000000,5,4,5,4,63.640000000,63.770000000,4,2,4,2,63.630000000,63.780000000,5,3,5,3,63.620000000,63.790000000,3,1,3,1,63.610000000,63.800000000,2,3,2,3,63.600000000,63.810000000,7,4,7,2,MCLQ5
2025-06-11T00:00:20.019300900Z,2025-06-11T00:00:20.019178873Z,10,1,42025623,M,B,4,63.650000000,1,130,12542,79316537,63.690000000,63.720000000,3,2,3,2,63.680000000,63.730000000,2,2,2,2,63.670000000,63.740000000,2,4,2,4,63.660000000,63.750000000,3,4,3,4,63.650000000,63.760000000,6,4,6,4,63.640000000,63.770000000,3,2,3,2,63.630000000,63.780000000,5,3,5,3,63.620000000,63.790000000,3,1,3,1,63.610000000,63.800000000,2,3,2,3,63.600000000,63.810000000,7,4,7,2,MCLQ5
2025-06-11T00:00:20.300301025Z,2025-06-11T00:00:20.300203585Z,10,1,42022708,M,A,0,2.830000000,10,130,14914,79316794,2.810000000,2.830000000,1,12,1,3,2.800000000,2.840000000,12,2,3,2,2.790000000,2.850000000,2,1,2,1,2.780000000,2.870000000,1,1,1,1,,,0,0,0,0,,,0,0,0,0,,,0,0,0,0,,,0,0,0,0,,,0,0,0,0,,,0,0,0,0,MCLN5-MCLV5
2025-06-11T00:00:20.321710868Z,2025-06-11T00:00:20.319211819Z,10,1,42026514,A,A,0,64.790000000,2,130,18060,79316808,64.780000000,64.790000000,3,3,3,2,64.770000000,64.800000000,6,3,5,3,64.760000000,64.810000000,9,4,9,4,64.750000000,64.820000000,8,9,8,6,64.740000000,64.830000000,10,10,9,10,64.730000000,64.840000000,6,6,6,5,64.720000000,64.850000000,8,9,5,6,64.710000000,64.860000000,8,4,7,3,64.700000000,64.870000000,7,4,6,3,64.690000000,64.880000000,4,4,3,3,MCLN5
2025-06-11T00:00:20.329583536Z,2025-06-11T00:00:20.329424481Z,10,1,42026514,C,A,0,64.790000000,2,130,12978,79317061,64.780000000,64.790000000,3,1,3,1,64.770000000,64.800000000,6,3,5,3,64.760000000,64.810000000,9,4,9,4,64.750000000,64.820000000,8,9,8,6,64.740000000,64.830000000,10,10,9,10,64.730000000,64.840000000,6,6,6,5,64.720000000,64.850000000,8,9,5,6,64.710000000,64.860000000,8,4,7,3,64.700000000,64.870000000,7,4,6,3,64.690000000,64.880000000,4,4,3,3,MCLN5
2025-06-11T00:00:20.484791861Z,2025-06-11T00:00:20.484631589Z,10,1,42026514,A,A,0,64.790000000,2,130,18405,79317185,64.780000000,64.790000000,3,3,3,2,64.770000000,64.800000000,6,3,5,3,64.760000000,64.810000000,9,4,9,4,64.750000000,64.820000000,8,9,8,6,64.740000000,64.830000000,10,10,9,10,64.730000000,64.840000000,6,6,6,5,64.720000000,64.850000000,8,9,5,6,64.710000000,64.860000000,8,4,7,3,64.700000000,64.870000000,7,4,6,3,64.690000000,64.880000000,4,4,3,3,MCLN5
2025-06-11T00:00:20.501668763Z,2025-06-11T00:00:20.501582461Z,10,1,42418117,M,A,0,3.280000000,10,130,11355,79317195,3.250000000,3.280000000,1,11,1,2,3.240000000,3.290000000,11,1,2,1,3.230000000,3.300000000,1,1,1,1,,,0,0,0,0,,,0,0,0,0,,,0,0,0,0,,,0,0,0,0,,,0,0,0,0,,,0,0,0,0,,,0,0,0,0,MCLN5-MCLX5
2025-06-11T00:00:20.722599713Z,2025-06-11T00:00:20.722298071Z,10,1,42026514,A,A,0,64.790000000,2,130,13158,79317301,64.780000000,64.790000000,3,5,3,3,64.770000000,64.800000000,6,3,5,3,64.760000000,64.810000000,9,4,9,4,64.750000000,64.820000000,8,9,8,6,64.740000000,64.830000000,10,10,9,10,64.730000000,64.840000000,6,6,6,5,64.720000000,64.850000000,8,9,5,6,64.710000000,64.860000000,8,4,7,3,64.700000000,64.870000000,7,4,6,3,64.690000000,64.880000000,4,4,3,3,MCLN5
2025-06-11T00:00:20.722828112Z,2025-06-11T00:00:20.722622403Z,10,1,42026514,M,B,3,64.740000000,1,130,14949,79317307,64.780000000,64.790000000,3,5,3,3,64.770000000,64.800000000,6,3,5,3,64.760000000,64.810000000,9,4,9,4,64.750000000,64.820000000,7,9,7,6,64.740000000,64.830000000,11,10,10,10,64.730000000,64.840000000,6,6,6,5,64.720000000,64.850000000,8,9,5,6,64.710000000,64.860000000,8,4,7,3,64.700000000,64.870000000,7,4,6,3,64.690000000,64.880000000,4,4,3,3,MCLN5
2025-06-11T00:00:20.722836383Z,2025-06-11T00:00:20.722622901Z,10,1,42026514,M,A,3,64.820000000,1,130,11609,79317308,64.780000000,64.790000000,3,5,3,3,64.770000000,64.800000000,6,3,5,3,64.760000000,64.810000000,9,4,9,4,64.750000000,64.820000000,7,10,7,7,64.740000000,64.830000000,11,9,10,9,64.730000000,64.840000000,6,6,6,5,64.720000000,64.850000000,8,9,5,6,64.710000000,64.860000000,8,4,7,3,64.700000000,64.870000000,7,4,6,3,64.690000000,64.880000000,4,4,3,3,MCLN5
2025-06-11T00:00:20.722844647Z,2025-06-11T00:00:20.722623383Z,10,1,42026514,M,B,3,64.740000000,1,130,11383,79317309,64.780000000,64.790000000,3,5,3,3,64.770000000,64.800000000,6,3,5,3,64.760000000,64.810000000,9,4,9,4,64.750000000,64.820000000,6,10,6,7,64.740000000,64.830000000,12,9,11,9,64.730000000,64.840000000,6,6,6,5,64.720000000,64.850000000,8,9,5,6,64.710000000,64.860000000,8,4,7,3,64.700000000,64.870000000,7,4,6,3,64.690000000,64.880000000,4,4,3,3,MCLN5
2025-06-11T00:00:20.722853739Z,2025-06-11T00:00:20.722623861Z,10,1,42026514,M,A,3,64.820000000,1,130,11698,79317310,64.780000000,64.790000000,3,5,3,3,64.770000000,64.800000000,6,3,5,3,64.760000000,64.810000000,9,4,9,4,64.750000000,64.820000000,6,11,6,8,64.740000000,64.830000000,12,8,11,8,64.730000000,64.840000000,6,6,6,5,64.720000000,64.850000000,8,9,5,6,64.710000000,64.860000000,8,4,7,3,64.700000000,64.870000000,7,4,6,3,64.690000000,64.880000000,4,4,3,3,MCLN5
2025-06-11T00:00:20.723439062Z,2025-06-11T00:00:20.722771061Z,10,1,42025623,M,B,2,63.670000000,1,130,13054,79317345,63.690000000,63.720000000,3,2,3,2,63.680000000,63.730000000,2,2,2,2,63.670000000,63.740000000,3,4,3,4,63.660000000,63.750000000,3,4,3,4,63.650000000,63.760000000,6,4,6,4,63.640000000,63.770000000,3,2,3,2,63.630000000,63.780000000,5,3,5,3,63.620000000,63.790000000,3,1,3,1,63.610000000,63.800000000,2,3,2,3,63.600000000,63.810000000,7,4,7,2,MCLQ5
2025-06-11T00:00:20.751857912Z,2025-06-11T00:00:20.751703337Z,10,1,42026514,C,A,0,64.790000000,2,130,13498,79317380,64.780000000,64.790000000,3,3,3,2,64.770000000,64.800000000,6,3,5,3,64.760000000,64.810000000,9,4,9,4,64.750000000,64.820000000,6,11,6,8,64.740000000,64.830000000,12,8,11,8,64.730000000,64.840000000,6,6,6,5,64.720000000,64.850000000,8,9,5,6,64.710000000,64.860000000,8,4,7,3,64.700000000,64.870000000,7,4,6,3,64.690000000,64.880000000,4,4,3,3,MCLN5
2025-06-11T00:00:20.752118635Z,2025-06-11T00:00:20.751729429Z,10,1,42026514,A,B,0,64.780000000,1,130,13131,79317393,64.780000000,64.790000000,4,3,4,2,64.770000000,64.800000000,6,3,5,3,64.760000000,64.810000000,9,4,9,4,64.750000000,64.820000000,6,11,6,8,64.740000000,64.830000000,12,8,11,8,64.730000000,64.840000000,6,6,6,5,64.720000000,64.850000000,8,9,5,6,64.710000000,64.860000000,8,4,7,3,64.700000000,64.870000000,7,4,6,3,64.690000000,64.880000000,4,4,3,3,MCLN5
2025-06-11T00:00:20.752139892Z,2025-06-11T00:00:20.751729605Z,10,1,42026514,C,A,0,64.790000000,1,130,13583,79317394,64.780000000,64.790000000,4,2,4,1,64.770000000,64.800000000,6,3,5,3,64.760000000,64.810000000,9,4,9,4,64.750000000,64.820000000,6,11,6,8,64.740000000,64.830000000,12,8,11,8,64.730000000,64.840000000,6,6,6,5,64.720000000,64.850000000,8,9,5,6,64.710000000,64.860000000,8,4,7,3,64.700000000,64.870000000,7,4,6,3,64.690000000,64.880000000,4,4,3,3,MCLN5
2025-06-11T00:00:20.752193841Z,2025-06-11T00:00:20.751733327Z,10,1,42026514,C,A,0,64.790000000,2,130,15737,79317396,64.780000000,64.800000000,4,3,4,3,64.770000000,64.810000000,6,4,5,4,64.760000000,64.820000000,9,11,9,8,64.750000000,64.830000000,6,8,6,8,64.740000000,64.840000000,12,6,11,5,64.730000000,64.850000000,6,9,6,6,64.720000000,64.860000000,8,4,5,3,64.710000000,64.870000000,8,4,7,3,64.700000000,64.880000000,7,4,6,3,64.690000000,64.890000000,4,3,3,2,MCLN5
2025-06-11T00:00:20.752635141Z,2025-06-11T00:00:20.751782669Z,10,1,42026514,A,B,0,64.790000000,2,130,15484,79317422,64.790000000,64.800000000,2,3,1,3,64.780000000,64.810000000,4,4,4,4,64.770000000,64.820000000,6,11,5,8,64.760000000,64.830000000,9,8,9,8,64.750000000,64.840000000,6,6,6,5,64.740000000,64.850000000,12,9,11,6,64.730000000,64.860000000,6,4,6,3,64.720000000,64.870000000,8,4,5,3,64.710000000,64.880000000,8,4,7,3,64.700000000,64.890000000,7,3,6,2,MCLN5
2025-06-11T00:00:20.752650785Z,2025-06-11T00:00:20.751783167Z,10,1,42026514,A,B,0,64.790000000,2,130,13628,79317423,64.790000000,64.800000000,4,3,2,3,64.780000000,64.810000000,4,4,4,4,64.770000000,64.820000000,6,11,5,8,64.760000000,64.830000000,9,8,9,8,64.750000000,64.840000000,6,6,6,5,64.740000000,64.850000000,12,9,11,6,64.730000000,64.860000000,6,4,6,3,64.720000000,64.870000000,8,4,5,3,64.710000000,64.880000000,8,4,7,3,64.700000000,64.890000000,7,3,6,2,MCLN5
2025-06-11T00:00:20.752687347Z,2025-06-11T00:00:20.751786161Z,10,1,42026514,A,B,1,64.780000000,1,130,13136,79317425,64.790000000,64.800000000,4,3,2,3,64.780000000,64.810000000,5,4,5,4,64.770000000,64.820000000,6,11,5,8,64.760000000,64.830000000,9,8,9,8,64.750000000,64.840000000,6,6,6,5,64.740000000,64.850000000,12,9,11,6,64.730000000,64.860000000,6,4,6,3,64.720000000,64.870000000,8,4,5,3,64.710000000,64.880000000,8,4,7,3,64.700000000,64.890000000,7,3,6,2,MCLN5
2025-06-11T00:00:20.752702468Z,2025-06-11T00:00:20.751787027Z,10,1,42025623,C,A,2,63.740000000,1,130,14998,79317426,63.690000000,63.720000000,3,2,3,2,63.680000000,63.730000000,2,2,2,2,63.670000000,63.740000000,3,3,3,3,63.660000000,63.750000000,3,4,3,4,63.650000000,63.760000000,6,4,6,4,63.640000000,63.770000000,3,2,3,2,63.630000000,63.780000000,5,3,5,3,63.620000000,63.790000000,3,1,3,1,63.610000000,63.800000000,2,3,2,3,63.600000000,63.810000000,7,4,7,2,MCLQ5
2025-06-11T00:00:20.752940843Z,2025-06-11T00:00:20.751800235Z,10,1,42026514,C,A,0,64.800000000,1,130,13846,79317436,64.790000000,64.800000000,4,2,2,2,64.780000000,64.810000000,5,4,5,4,64.770000000,64.820000000,6,11,5,8,64.760000000,64.830000000,9,8,9,8,64.750000000,64.840000000,6,6,6,5,64.740000000,64.850000000,12,9,11,6,64.730000000,64.860000000,6,4,6,3,64.720000000,64.870000000,8,4,5,3,64.710000000,64.880000000,8,4,7,3,64.700000000,64.890000000,7,3,6,2,MCLN5
2025-06-11T00:00:20.753371308Z,2025-06-11T00:00:20.752201095Z,10,1,42026514,M,A,3,64.840000000,1,130,11749,79317462,64.790000000,64.800000000,4,2,2,2,64.780000000,64.810000000,5,4,5,4,64.770000000,64.820000000,6,11,5,8,64.760000000,64.830000000,9,7,9,7,64.750000000,64.840000000,6,7,6,6,64.740000000,64.850000000,12,9,11,6,64.730000000,64.860000000,6,4,6,3,64.720000000,64.870000000,8,4,5,3,64.710000000,64.880000000,8,4,7,3,64.700000000,64.890000000,7,3,6,2,MCLN5
2025-06-11T00:00:20.753371308Z,2025-06-11T00:00:20.752201941Z,10,1,42026514,M,B,4,64.750000000,1,130,11749,79317462,64.790000000,64.800000000,4,2,2,2,64.780000000,64.810000000,5,4,5,4,64.770000000,64.820000000,6,11,5,8,64.760000000,64.830000000,9,7,9,7,64.750000000,64.840000000,7,7,7,6,64.740000000,64.850000000,11,9,10,6,64.730000000,64.860000000,6,4,6,3,64.720000000,64.870000000,8,4,5,3,64.710000000,64.880000000,8,4,7,3,64.700000000,64.890000000,7,3,6,2,MCLN5
2025-06-11T00:00:20.753382912Z,2025-06-11T00:00:20.752205031Z,10,1,42026514,C,B,1,64.780000000,1,130,11136,79317463,64.790000000,64.800000000,4,2,2,2,64.780000000,64.810000000,4,4,4,4,64.770000000,64.820000000,6,11,5,8,64.760000000,64.830000000,9,7,9,7,64.750000000,64.840000000,7,7,7,6,64.740000000,64.850000000,11,9,10,6,64.730000000,64.860000000,6,4,6,3,64.720000000,64.870000000,8,4,5,3,64.710000000,64.880000000,8,4,7,3,64.700000000,64.890000000,7,3,6,2,MCLN5
2025-06-11T00:00:20.753399185Z,2025-06-11T00:00:20.752214361Z,10,1,42025623,M,A,3,63.760000000,1,130,11444,79317465,63.690000000,63.720000000,3,2,3,2,63.680000000,63.730000000,2,2,2,2,63.670000000,63.740000000,3,3,3,3,63.660000000,63.750000000,3,3,3,3,63.650000000,63.760000000,6,5,6,5,63.640000000,63.770000000,3,2,3,2,63.630000000,63.780000000,5,3,5,3,63.620000000,63.790000000,3,1,3,1,63.610000000,63.800000000,2,3,2,3,63.600000000,63.810000000,7,4,7,2,MCLQ5
2025-06-11T00:00:20.753414559Z,2025-06-11T00:00:20.752214631Z,10,1,42025623,C,A,5,63.770000000,1,130,14869,79317466,63.690000000,63.720000000,3,2,3,2,63.680000000,63.730000000,2,2,2,2,63.670000000,63.740000000,3,3,3,3,63.660000000,63.750000000,3,3,3,3,63.650000000,63.760000000,6,5,6,5,63.640000000,63.770000000,3,1,3,1,63.630000000,63.780000000,5,3,5,3,63.620000000,63.790000000,3,1,3,1,63.610000000,63.800000000,2,3,2,3,63.600000000,63.810000000,7,4,7,2,MCLQ5
2025-06-11T00:00:20.753422684Z,2025-06-11T00:00:20.752214823Z,10,1,42025623,M,B,3,63.660000000,1,130,11303,79317467,63.690000000,63.720000000,3,2,3,2,63.680000000,63.730000000,2,2,2,2,63.670000000,63.740000000,3,3,3,3,63.660000000,63.750000000,4,3,4,3,63.650000000,63.760000000,5,5,5,5,63.640000000,63.770000000,3,1,3,1,63.630000000,63.780000000,5,3,5,3,63.620000000,63.790000000,3,1,3,1,63.610000000,63.800000000,2,3,2,3,63.600000000,63.810000000,7,4,7,2,MCLQ5
2025-06-11T00:00:20.753433105Z,2025-06-11T00:00:20.752215379Z,10,1,42025623,M,A,3,63.760000000,1,130,11492,79317468,63.690000000,63.720000000,3,2,3,2,63.680000000,63.730000000,2,2,2,2,63.670000000,63.740000000,3,3,3,3,63.660000000,63.750000000,4,2,4,2,63.650000000,63.760000000,5,6,5,6,63.640000000,63.770000000,3,1,3,1,63.630000000,63.780000000,5,3,5,3,63.620000000,63.790000000,3,1,3,1,63.610000000,63.800000000,2,3,2,3,63.600000000,63.810000000,7,4,7,2,MCLQ5
2025-06-11T00:00:20.753446637Z,2025-06-11T00:00:20.752215897Z,10,1,42025623,M,B,3,63.660000000,1,130,11465,79317469,63.690000000,63.720000000,3,2,3,2,63.680000000,63.730000000,2,2,2,2,63.670000000,63.740000000,3,3,3,3,63.660000000,63.750000000,5,2,5,2,63.650000000,63.760000000,4,6,4,6,63.640000000,63.770000000,3,1,3,1,63.630000000,63.780000000,5,3,5,3,63.620000000,63.790000000,3,1,3,1,63.610000000,63.800000000,2,3,2,3,63.600000000,63.810000000,7,4,7,2,MCLQ5
2025-06-11T00:00:20.753457166Z,2025-06-11T00:00:20.752220333Z,10,1,42025623,C,B,6,63.630000000,1,130,11214,79317470,63.690000000,63.720000000,3,2,3,2,63.680000000,63.730000000,2,2,2,2,63.670000000,63.740000000,3,3,3,3,63.660000000,63.750000000,5,2,5,2,63.650000000,63.760000000,4,6,4,6,63.640000000,63.770000000,3,1,3,1,63.630000000,63.780000000,4,3,4,3,63.620000000,63.790000000,3,1,3,1,63.610000000,63.800000000,2,3,2,3,63.600000000,63.810000000,7,4,7,2,MCLQ5
2025-06-11T00:00:20.753505209Z,2025-06-11T00:00:20.752300431Z,10,1,42026514,A,B,0,64.790000000,1,130,13982,79317473,64.790000000,64.800000000,5,2,3,2,64.780000000,64.810000000,4,4,4,4,64.770000000,64.820000000,6,11,5,8,64.760000000,64.830000000,9,7,9,7,64.750000000,64.840000000,7,7,7,6,64.740000000,64.850000000,11,9,10,6,64.730000000,64.860000000,6,4,6,3,64.720000000,64.870000000,8,4,5,3,64.710000000,64.880000000,8,4,7,3,64.700000000,64.890000000,7,3,6,2,MCLN5
2025-06-11T00:00:20.753524339Z,2025-06-11T00:00:20.752323451Z,10,1,42026514,M,B,1,64.780000000,1,130,17269,79317474,64.790000000,64.800000000,5,2,3,2,64.780000000,64.810000000,5,4,5,4,64.770000000,64.820000000,6,11,5,8,64.760000000,64.830000000,9,7,9,7,64.750000000,64.840000000,7,7,7,6,64.740000000,64.850000000,11,9,10,6,64.730000000,64.860000000,6,4,6,3,64.720000000,64.870000000,8,4,5,3,64.710000000,64.880000000,8,4,7,3,64.700000000,64.890000000,7,3,6,2,MCLN5
2025-06-11T00:00:20.753666266Z,2025-06-11T00:00:20.752369125Z,10,1,42026514,M,A,1,66.790000000,2,130,12555,79317481,64.790000000,64.800000000,5,2,3,2,64.780000000,64.810000000,5,3,5,3,64.770000000,64.820000000,6,11,5,8,64.760000000,64.830000000,9,7,9,7,64.750000000,64.840000000,7,7,7,6,64.740000000,64.850000000,11,9,10,6,64.730000000,64.860000000,6,4,6,3,64.720000000,64.870000000,8,4,5,3,64.710000000,64.880000000,8,4,7,3,64.700000000,64.890000000,7,3,6,2,MCLN5
2025-06-11T00:00:20.753854677Z,2025-06-11T00:00:20.752642329Z,10,1,42026514,C,A,5,64.850000000,1,130,11339,79317492,64.790000000,64.800000000,5,2,3,2,64.780000000,64.810000000,5,3,5,3,64.770000000,64.820000000,6,11,5,8,64.760000000,64.830000000,9,7,9,7,64.750000000,64.840000000,7,7,7,6,64.740000000,64.850000000,11,8,10,5,64.730000000,64.860000000,6,4,6,3,64.720000000,64.870000000,8,4,5,3,64.710000000,64.880000000,8,4,7,3,64.700000000,64.890000000,7,3,6,2,MCLN5
2025-06-11T00:00:20.753962375Z,2025-06-11T00:00:20.752724905Z,10,1,42025623,A,A,6,63.780000000,1,130,11373,79317499,63.690000000,63.720000000,3,2,3,2,63.680000000,63.730000000,2,2,2,2,63.670000000,63.740000000,3,3,3,3,63.660000000,63.750000000,5,2,5,2,63.650000000,63.760000000,4,6,4,6,63.640000000,63.770000000,3,1,3,1,63.630000000,63.780000000,4,4,4,4,63.620000000,63.790000000,3,1,3,1,63.610000000,63.800000000,2,3,2,3,63.600000000,63.810000000,7,4,7,2,MCLQ5
2025-06-11T00:00:20.753998984Z,2025-06-11T00:00:20.752753301Z,10,1,42025623,A,B,5,63.640000000,1,130,11311,79317501,63.690000000,63.720000000,3,2,3,2,63.680000000,63.730000000,2,2,2,2,63.670000000,63.740000000,3,3,3,3,63.660000000,63.750000000,5,2,5,2,63.650000000,63.760000000,4,6,4,6,63.640000000,63.770000000,4,1,4,1,63.630000000,63.780000000,4,4,4,4,63.620000000,63.790000000,3,1,3,1,63.610000000,63.800000000,2,3,2,3,63.600000000,63.810000000,7,4,7,2,MCLQ5
2025-06-11T00:00:20.754024795Z,2025-06-11T00:00:20.752796941Z,10,1,42026514,T,A,0,64.790000000,2,0,15795,79317503,64.790000000,64.800000000,5,2,3,2,64.780000000,64.810000000,5,3,5,3,64.770000000,64.820000000,6,11,5,8,64.760000000,64.830000000,9,7,9,7,64.750000000,64.840000000,7,7,7,6,64.740000000,64.850000000,11,8,10,5,64.730000000,64.860000000,6,4,6,3,64.720000000,64.870000000,8,4,5,3,64.710000000,64.880000000,8,4,7,3,64.700000000,64.890000000,7,3,6,2,MCLN5
2025-06-11T00:00:20.754037274Z,2025-06-11T00:00:20.752796941Z,10,1,42026514,C,B,0,64.790000000,2,130,14399,79317504,64.790000000,64.800000000,3,2,2,2,64.780000000,64.810000000,5,3,5,3,64.770000000,64.820000000,6,11,5,8,64.760000000,64.830000000,9,7,9,7,64.750000000,64.840000000,7,7,7,6,64.740000000,64.850000000,11,8,10,5,64.730000000,64.860000000,6,4,6,3,64.720000000,64.870000000,8,4,5,3,64.710000000,64.880000000,8,4,7,3,64.700000000,64.890000000,7,3,6,2,MCLN5
2025-06-11T00:00:20.754052472Z,2025-06-11T00:00:20.752850429Z,10,1,42418117,M,A,0,3.290000000,10,130,11452,79317506,3.250000000,3.280000000,1,1,1,1,3.240000000,3.290000000,11,11,2,2,3.230000000,3.300000000,1,1,1,1,,,0,0,0,0,,,0,0,0,0,,,0,0,0,0,,,0,0,0,0,,,0,0,0,0,,,0,0,0,0,,,0,0,0,0,MCLN5-MCLX5
2025-06-11T00:00:20.754248417Z,2025-06-11T00:00:20.752920181Z,10,1,42026514,C,B,0,64.790000000,2,130,13889,79317517,64.790000000,64.800000000,1,2,1,2,64.780000000,64.810000000,5,3,5,3,64.770000000,64.820000000,6,11,5,8,64.760000000,64.830000000,9,7,9,7,64.750000000,64.840000000,7,7,7,6,64.740000000,64.850000000,11,8,10,5,64.730000000,64.860000000,6,4,6,3,64.720000000,64.870000000,8,4,5,3,64.710000000,64.880000000,8,4,7,3,64.700000000,64.890000000,7,3,6,2,MCLN5
2025-06-11T00:00:20.754286347Z,2025-06-11T00:00:20.752949785Z,10,1,42026514,A,A,0,64.800000000,1,130,13754,79317519,64.790000000,64.800000000,1,3,1,3,64.780000000,64.810000000,5,3,5,3,64.770000000,64.820000000,6,11,5,8,64.760000000,64.830000000,9,7,9,7,64.750000000,64.840000000,7,7,7,6,64.740000000,64.850000000,11,8,10,5,64.730000000,64.860000000,6,4,6,3,64.720000000,64.870000000,8,4,5,3,64.710000000,64.880000000,8,4,7,3,64.700000000,64.890000000,7,3,6,2,MCLN5
2025-06-11T00:00:20.754296184Z,2025-06-11T00:00:20.752949977Z,10,1,42025623,M,A,4,63.770000000,1,130,11000,79317520,63.690000000,63.720000000,3,2,3,2,63.680000000,63.730000000,2,2,2,2,63.670000000,63.740000000,3,3,3,3,63.660000000,63.750000000,5,2,5,2,63.650000000,63.760000000,4,5,4,5,63.640000000,63.770000000,4,2,4,2,63.630000000,63.780000000,4,4,4,4,63.620000000,63.790000000,3,1,3,1,63.610000000,63.800000000,2,3,2,3,63.600000000,63.810000000,7,4,7,2,MCLQ5
2025-06-11T00:00:20.754304778Z,2025-06-11T00:00:20.752950457Z,10,1,42025623,M,B,3,63.660000000,1,130,11662,79317521,63.690000000,63.720000000,3,2,3,2,63.680000000,63.730000000,2,2,2,2,63.670000000,63.740000000,3,3,3,3,63.660000000,63.750000000,6,2,6,2,63.650000000,63.760000000,3,5,3,5,63.640000000,63.770000000,4,2,4,2,63.630000000,63.780000000,4,4,4,4,63.620000000,63.790000000,3,1,3,1,63.610000000,63.800000000,2,3,2,3,63.600000000,63.810000000,7,4,7,2,MCLQ5
2025-06-11T00:00:20.754338691Z,2025-06-11T00:00:20.752967563Z,10,1,42025623,C,A,0,63.720000000,1,130,17864,79317522,63.690000000,63.720000000,3,1,3,1,63.680000000,63.730000000,2,2,2,2,63.670000000,63.740000000,3,3,3,3,63.660000000,63.750000000,6,2,6,2,63.650000000,63.760000000,3,5,3,5,63.640000000,63.770000000,4,2,4,2,63.630000000,63.780000000,4,4,4,4,63.620000000,63.790000000,3,1,3,1,63.610000000,63.800000000,2,3,2,3,63.600000000,63.810000000,7,4,7,2,MCLQ5
2025-06-11T00:00:20.754353889Z,2025-06-11T00:00:20.752975263Z,10,1,42026514,C,A,0,64.800000000,1,130,13817,79317523,64.790000000,64.800000000,1,2,1,2,64.780000000,64.810000000,5,3,5,3,64.770000000,64.820000000,6,11,5,8,64.760000000,64.830000000,9,7,9,7,64.750000000,64.840000000,7,7,7,6,64.740000000,64.850000000,11,8,10,5,64.730000000,64.860000000,6,4,6,3,64.720000000,64.870000000,8,4,5,3,64.710000000,64.880000000,8,4,7,3,64.700000000,64.890000000,7,3,6,2,MCLN5
2025-06-11T00:00:20.754424541Z,2025-06-11T00:00:20.753123249Z,10,1,42026514,M,A,2,64.840000000,1,130,12015,79317529,64.790000000,64.800000000,1,2,1,2,64.780000000,64.810000000,5,3,5,3,64.770000000,64.820000000,6,10,5,7,64.760000000,64.830000000,9,7,9,7,64.750000000,64.840000000,7,8,7,7,64.740000000,64.850000000,11,8,10,5,64.730000000,64.860000000,6,4,6,3,64.720000000,64.870000000,8,4,5,3,64.710000000,64.880000000,8,4,7,3,64.700000000,64.890000000,7,3,6,2,MCLN5
2025-06-11T00:00:20.754437596Z,2025-06-11T00:00:20.753123711Z,10,1,42026514,M,B,3,64.760000000,1,130,15282,79317530,64.790000000,64.800000000,1,2,1,2,64.780000000,64.810000000,5,3,5,3,64.770000000,64.820000000,6,10,5,7,64.760000000,64.830000000,10,7,10,7,64.750000000,64.840000000,7,8,7,7,64.740000000,64.850000000,10,8,9,5,64.730000000,64.860000000,6,4,6,3,64.720000000,64.870000000,8,4,5,3,64.710000000,64.880000000,8,4,7,3,64.700000000,64.890000000,7,3,6,2,MCLN5
2025-06-11T00:00:20.754446028Z,2025-06-11T00:00:20.753124171Z,10,1,42026514,M,A,2,64.840000000,1,130,11667,79317531,64.790000000,64.800000000,1,2,1,2,64.780000000,64.810000000,5,3,5,3,64.770000000,64.820000000,6,9,5,6,64.760000000,64.830000000,10,7,10,7,64.750000000,64.840000000,7,9,7,8,64.740000000,64.850000000,10,8,9,5,64.730000000,64.860000000,6,4,6,3,64.720000000,64.870000000,8,4,5,3,64.710000000,64.880000000,8,4,7,3,64.700000000,64.890000000,7,3,6,2,MCLN5
2025-06-11T00:00:20.754454484Z,2025-06-11T00:00:20.753124651Z,10,1,42026514,M,B,3,64.760000000,1,130,11358,79317532,64.790000000,64.800000000,1,2,1,2,64.780000000,64.810000000,5,3,5,3,64.770000000,64.820000000,6,9,5,6,64.760000000,64.830000000,11,7,11,7,64.750000000,64.840000000,7,9,7,8,64.740000000,64.850000000,9,8,8,5,64.730000000,64.860000000,6,4,6,3,64.720000000,64.870000000,8,4,5,3,64.710000000,64.880000000,8,4,7,3,64.700000000,64.890000000,7,3,6,2,MCLN5
2025-06-11T00:00:20.755329343Z,2025-06-11T00:00:20.753381975Z,10,1,42026514,C,B,1,64.780000000,1,130,11647,79317580,64.790000000,64.800000000,1,2,1,2,64.780000000,64.810000000,4,3,4,3,64.770000000,64.820000000,6,9,5,6,64.760000000,64.830000000,11,7,11,7,64.750000000,64.840000000,7,9,7,8,64.740000000,64.850000000,9,8,8,5,64.730000000,64.860000000,6,4,6,3,64.720000000,64.870000000,8,4,5,3,64.710000000,64.880000000,8,4,7,3,64.700000000,64.890000000,7,3,6,2,MCLN5
2025-06-11T00:00:20.755370767Z,2025-06-11T00:00:20.753404055Z,10,1,42026514,A,A,0,64.800000000,1,130,14294,79317583,64.790000000,64.800000000,1,3,1,3,64.780000000,64.810000000,4,3,4,3,64.770000000,64.820000000,6,9,5,6,64.760000000,64.830000000,11,7,11,7,64.750000000,64.840000000,7,9,7,8,64.740000000,64.850000000,9,8,8,5,64.730000000,64.860000000,6,4,6,3,64.720000000,64.870000000,8,4,5,3,64.710000000,64.880000000,8,4,7,3,64.700000000,64.890000000,7,3,6,2,MCLN5
2025-06-11T00:00:20.755477606Z,2025-06-11T00:00:20.753801249Z,10,1,42026514,C,A,0,64.800000000,1,130,14017,79317590,64.790000000,64.800000000,1,2,1,2,64.780000000,64.810000000,4,3,4,3,64.770000000,64.820000000,6,9,5,6,64.760000000,64.830000000,11,7,11,7,64.750000000,64.840000000,7,9,7,8,64.740000000,64.850000000,9,8,8,5,64.730000000,64.860000000,6,4,6,3,64.720000000,64.870000000,8,4,5,3,64.710000000,64.880000000,8,4,7,3,64.700000000,64.890000000,7,3,6,2,MCLN5
2025-06-11T00:00:20.755796501Z,2025-06-11T00:00:20.753953419Z,10,1,42026514,A,A,0,64.800000000,1,130,13479,79317610,64.790000000,64.800000000,1,3,1,3,64.780000000,64.810000000,4,3,4,3,64.770000000,64.820000000,6,9,5,6,64.760000000,64.830000000,11,7,11,7,64.750000000,64.840000000,7,9,7,8,64.740000000,64.850000000,9,8,8,5,64.730000000,64.860000000,6,4,6,3,64.720000000,64.870000000,8,4,5,3,64.710000000,64.880000000,8,4,7,3,64.700000000,64.890000000,7,3,6,2,MCLN5
2025-06-11T00:00:20.755864012Z,2025-06-11T00:00:20.754073473Z,10,1,42025623,A,B,0,63.700000000,1,130,14260,79317614,63.700000000,63.720000000,1,1,1,1,63.690000000,63.730000000,3,2,3,2,63.680000000,63.740000000,2,3,2,3,63.670000000,63.750000000,3,2,3,2,63.660000000,63.760000000,6,5,6,5,63.650000000,63.770000000,3,2,3,2,63.640000000,63.780000000,4,4,4,4,63.630000000,63.790000000,4,1,4,1,63.620000000,63.800000000,3,3,3,3,63.610000000,63.810000000,2,4,2,2,MCLQ5
2025-06-11T00:00:20.755900183Z,2025-06-11T00:00:20.754233345Z,10,1,42022708,M,A,0,2.840000000,10,130,11843,79317618,2.810000000,2.830000000,1,2,1,2,2.800000000,2.840000000,12,12,3,3,2.790000000,2.850000000,2,1,2,1,2.780000000,2.870000000,1,1,1,1,,,0,0,0,0,,,0,0,0,0,,,0,0,0,0,,,0,0,0,0,,,0,0,0,0,,,0,0,0,0,MCLN5-MCLV5
2025-06-11T00:00:20.755965260Z,2025-06-11T00:00:20.754271013Z,10,1,42026514,C,A,0,64.800000000,1,130,13378,79317620,64.790000000,64.800000000,1,2,1,2,64.780000000,64.810000000,4,3,4,3,64.770000000,64.820000000,6,9,5,6,64.760000000,64.830000000,11,7,11,7,64.750000000,64.840000000,7,9,7,8,64.740000000,64.850000000,9,8,8,5,64.730000000,64.860000000,6,4,6,3,64.720000000,64.870000000,8,4,5,3,64.710000000,64.880000000,8,4,7,3,64.700000000,64.890000000,7,3,6,2,MCLN5
2025-06-11T00:00:20.756114298Z,2025-06-11T00:00:20.754445591Z,10,1,42026514,A,B,0,64.790000000,1,130,11457,79317633,64.790000000,64.800000000,2,2,2,2,64.780000000,64.810000000,4,3,4,3,64.770000000,64.820000000,6,9,5,6,64.760000000,64.830000000,11,7,11,7,64.750000000,64.840000000,7,9,7,8,64.740000000,64.850000000,9,8,8,5,64.730000000,64.860000000,6,4,6,3,64.720000000,64.870000000,8,4,5,3,64.710000000,64.880000000,8,4,7,3,64.700000000,64.890000000,7,3,6,2,MCLN5
2025-06-11T00:00:20.756404348Z,2025-06-11T00:00:20.754562091Z,10,1,42026514,T,B,0,64.800000000,1,0,11528,79317648,64.790000000,64.800000000,2,2,2,2,64.780000000,64.810000000,4,3,4,3,64.770000000,64.820000000,6,9,5,6,64.760000000,64.830000000,11,7,11,7,64.750000000,64.840000000,7,9,7,8,64.740000000,64.850000000,9,8,8,5,64.730000000,64.860000000,6,4,6,3,64.720000000,64.870000000,8,4,5,3,64.710000000,64.880000000,8,4,7,3,64.700000000,64.890000000,7,3,6,2,MCLN5
2025-06-11T00:00:20.756422104Z,2025-06-11T00:00:20.754562091Z,10,1,42026514,C,A,0,64.800000000,1,130,15179,79317649,64.790000000,64.800000000,2,1,2,1,64.780000000,64.810000000,4,3,4,3,64.770000000,64.820000000,6,9,5,6,64.760000000,64.830000000,11,7,11,7,64.750000000,64.840000000,7,9,7,8,64.740000000,64.850000000,9,8,8,5,64.730000000,64.860000000,6,4,6,3,64.720000000,64.870000000,8,4,5,3,64.710000000,64.880000000,8,4,7,3,64.700000000,64.890000000,7,3,6,2,MCLN5
2025-06-11T00:00:20.757324202Z,2025-06-11T00:00:20.754729873Z,10,1,42026514,C,B,0,64.790000000,1,130,13770,79317702,64.790000000,64.800000000,1,1,1,1,64.780000000,64.810000000,4,3,4,3,64.770000000,64.820000000,6,9,5,6,64.760000000,64.830000000,11,7,11,7,64.750000000,64.840000000,7,9,7,8,64.740000000,64.850000000,9,8,8,5,64.730000000,64.860000000,6,4,6,3,64.720000000,64.870000000,8,4,5,3,64.710000000,64.880000000,8,4,7,3,64.700000000,64.890000000,7,3,6,2,MCLN5
2025-06-11T00:00:20.757376071Z,2025-06-11T00:00:20.754730469Z,10,1,42025611,C,A,0,2.080000000,2,130,11542,79317706,2.070000000,2.080000000,3,3,2,1,2.060000000,2.090000000,23,7,3,5,2.050000000,2.100000000,23,27,3,6,2.040000000,2.110000000,23,23,3,4,2.030000000,2.120000000,2,22,1,2,2.020000000,2.130000000,2,2,2,2,2.010000000,2.140000000,2,2,1,1,2.000000000,2.150000000,2,2,2,1,1.990000000,2.160000000,2,2,1,1,1.980000000,2.170000000,2,2,2,1,MCLN5-MCLU5
2025-06-11T00:00:20.757634136Z,2025-06-11T00:00:20.754732023Z,10,1,42026514,T,A,0,64.790000000,1,0,11527,79317721,64.790000000,64.800000000,1,1,1,1,64.780000000,64.810000000,4,3,4,3,64.770000000,64.820000000,6,9,5,6,64.760000000,64.830000000,11,7,11,7,64.750000000,64.840000000,7,9,7,8,64.740000000,64.850000000,9,8,8,5,64.730000000,64.860000000,6,4,6,3,64.720000000,64.870000000,8,4,5,3,64.710000000,64.880000000,8,4,7,3,64.700000000,64.890000000,7,3,6,2,MCLN5
2025-06-11T00:00:20.757634136Z,2025-06-11T00:00:20.754732023Z,10,1,42026514,C,B,0,64.790000000,1,130,11527,79317721,64.780000000,64.800000000,4,1,4,1,64.770000000,64.810000000,6,3,5,3,64.760000000,64.820000000,11,9,11,6,64.750000000,64.830000000,7,7,7,7,64.740000000,64.840000000,9,9,8,8,64.730000000,64.850000000,6,8,6,5,64.720000000,64.860000000,8,4,5,3,64.710000000,64.870000000,8,4,7,3,64.700000000,64.880000000,7,4,6,3,64.690000000,64.890000000,4,3,3,2,MCLN5
2025-06-11T00:00:20.757778896Z,2025-06-11T00:00:20.754732837Z,10,1,42026514,A,A,0,64.790000000,2,130,11976,79317730,64.780000000,64.790000000,4,2,4,1,64.770000000,64.800000000,6,1,5,1,64.760000000,64.810000000,11,3,11,3,64.750000000,64.820000000,7,9,7,6,64.740000000,64.830000000,9,7,8,7,64.730000000,64.840000000,6,9,6,8,64.720000000,64.850000000,8,8,5,5,64.710000000,64.860000000,8,4,7,3,64.700000000,64.870000000,7,4,6,3,64.690000000,64.880000000,4,4,3,3,MCLN5
2025-06-11T00:00:20.758212294Z,2025-06-11T00:00:20.754757615Z,10,1,42463766,C,B,0,1.080000000,7,130,11872,79317755,1.080000000,1.090000000,8,29,2,12,1.070000000,1.100000000,61,56,19,14,1.060000000,1.110000000,52,57,14,13,1.050000000,1.120000000,56,54,13,12,1.040000000,1.130000000,52,40,11,10,1.030000000,1.140000000,39,38,9,8,1.020000000,1.150000000,38,41,8,10,1.010000000,1.160000000,35,36,8,7,1.000000000,1.170000000,40,38,9,9,0.990000000,1.180000000,35,37,8,9,MCLN5-MCLQ5
2025-06-11T00:00:20.758222016Z,2025-06-11T00:00:20.754758613Z,10,1,42463766,C,B,0,1.080000000,5,130,12464,79317756,1.080000000,1.090000000,3,29,1,12,1.070000000,1.100000000,61,56,19,14,1.060000000,1.110000000,52,57,14,13,1.050000000,1.120000000,56,54,13,12,1.040000000,1.130000000,52,40,11,10,1.030000000,1.140000000,39,38,9,8,1.020000000,1.150000000,38,41,8,10,1.010000000,1.160000000,35,36,8,7,1.000000000,1.170000000,40,38,9,9,0.990000000,1.180000000,35,37,8,9,MCLN5-MCLQ5
2025-06-11T00:00:20.758435491Z,2025-06-11T00:00:20.754847083Z,10,1,42026514,T,B,0,64.790000000,1,0,12541,79317771,64.780000000,64.790000000,4,2,4,1,64.770000000,64.800000000,6,1,5,1,64.760000000,64.810000000,11,3,11,3,64.750000000,64.820000000,7,9,7,6,64.740000000,64.830000000,9,7,8,7,64.730000000,64.840000000,6,9,6,8,64.720000000,64.850000000,8,8,5,5,64.710000000,64.860000000,8,4,7,3,64.700000000,64.870000000,7,4,6,3,64.690000000,64.880000000,4,4,3,3,MCLN5
2025-06-11T00:00:20.758435491Z,2025-06-11T00:00:20.754847083Z,10,1,42026514,M,A,0,64.790000000,1,130,12541,79317771,64.780000000,64.790000000,4,1,4,1,64.770000000,64.800000000,6,1,5,1,64.760000000,64.810000000,11,3,11,3,64.750000000,64.820000000,7,9,7,6,64.740000000,64.830000000,9,7,8,7,64.730000000,64.840000000,6,9,6,8,64.720000000,64.850000000,8,8,5,5,64.710000000,64.860000000,8,4,7,3,64.700000000,64.870000000,7,4,6,3,64.690000000,64.880000000,4,4,3,3,MCLN5
2025-06-11T00:00:20.758656343Z,2025-06-11T00:00:20.754931039Z,10,1,42026514,T,B,0,64.790000000,1,0,11387,79317786,64.780000000,64.790000000,4,1,4,1,64.770000000,64.800000000,6,1,5,1,64.760000000,64.810000000,11,3,11,3,64.750000000,64.820000000,7,9,7,6,64.740000000,64.830000000,9,7,8,7,64.730000000,64.840000000,6,9,6,8,64.720000000,64.850000000,8,8,5,5,64.710000000,64.860000000,8,4,7,3,64.700000000,64.870000000,7,4,6,3,64.690000000,64.880000000,4,4,3,3,MCLN5
2025-06-11T00:00:20.758673569Z,2025-06-11T00:00:20.754931039Z,10,1,42026514,C,A,0,64.790000000,1,130,11324,79317787,64.780000000,64.800000000,4,1,4,1,64.770000000,64.810000000,6,3,5,3,64.760000000,64.820000000,11,9,11,6,64.750000000,64.830000000,7,7,7,7,64.740000000,64.840000000,9,9,8,8,64.730000000,64.850000000,6,8,6,5,64.720000000,64.860000000,8,4,5,3,64.710000000,64.870000000,8,4,7,3,64.700000000,64.880000000,7,4,6,3,64.690000000,64.890000000,4,3,3,2,MCLN5
2025-06-11T00:00:20.759275542Z,2025-06-11T00:00:20.755276857Z,10,1,42025623,A,A,0,63.720000000,1,130,13268,79317829,63.700000000,63.720000000,1,2,1,2,63.690000000,63.730000000,3,2,3,2,63.680000000,63.740000000,2,3,2,3,63.670000000,63.750000000,3,2,3,2,63.660000000,63.760000000,6,5,6,5,63.650000000,63.770000000,3,2,3,2,63.640000000,63.780000000,4,4,4,4,63.630000000,63.790000000,4,1,4,1,63.620000000,63.800000000,3,3,3,3,63.610000000,63.810000000,2,4,2,2,MCLQ5
2025-06-11T00:00:20.759300723Z,2025-06-11T00:00:20.755295729Z,10,1,42026514,A,A,0,64.800000000,1,130,14195,79317830,64.780000000,64.800000000,4,2,4,2,64.770000000,64.810000000,6,3,5,3,64.760000000,64.820000000,11,9,11,6,64.750000000,64.830000000,7,7,7,7,64.740000000,64.840000000,9,9,8,8,64.730000000,64.850000000,6,8,6,5,64.720000000,64.860000000,8,4,5,3,64.710000000,64.870000000,8,4,7,3,64.700000000,64.880000000,7,4,6,3,64.690000000,64.890000000,4,3,3,2,MCLN5
2025-06-11T00:00:20.759379915Z,2025-06-11T00:00:20.755387079Z,10,1,42026514,M,B,2,64.750000000,1,130,10644,79317835,64.780000000,64.800000000,4,2,4,2,64.770000000,64.810000000,6,3,5,3,64.760000000,64.820000000,10,9,10,6,64.750000000,64.830000000,8,7,8,7,64.740000000,64.840000000,9,9,8,8,64.730000000,64.850000000,6,8,6,5,64.720000000,64.860000000,8,4,5,3,64.710000000,64.870000000,8,4,7,3,64.700000000,64.880000000,7,4,6,3,64.690000000,64.890000000,4,3,3,2,MCLN5
2025-06-11T00:00:20.759388240Z,2025-06-11T00:00:20.755387941Z,10,1,42026514,M,B,2,64.750000000,1,130,11437,79317836,64.780000000,64.800000000,4,2,4,2,64.770000000,64.810000000,6,3,5,3,64.760000000,64.820000000,9,9,9,6,64.750000000,64.830000000,9,7,9,7,64.740000000,64.840000000,9,9,8,8,64.730000000,64.850000000,6,8,6,5,64.720000000,64.860000000,8,4,5,3,64.710000000,64.870000000,8,4,7,3,64.700000000,64.880000000,7,4,6,3,64.690000000,64.890000000,4,3,3,2,MCLN5
2025-06-11T00:00:20.759469444Z,2025-06-11T00:00:20.755395545Z,10,1,42025623,C,B,0,63.700000000,1,130,15015,79317840,63.690000000,63.720000000,3,2,3,2,63.680000000,63.730000000,2,2,2,2,63.670000000,63.740000000,3,3,3,3,63.660000000,63.750000000,6,2,6,2,63.650000000,63.760000000,3,5,3,5,63.640000000,63.770000000,4,2,4,2,63.630000000,63.780000000,4,4,4,4,63.620000000,63.790000000,3,1,3,1,63.610000000,63.800000000,2,3,2,3,63.600000000,63.810000000,7,4,7,2,MCLQ5
2025-06-11T00:00:20.759905353Z,2025-06-11T00:00:20.755592949Z,10,1,42026514,C,B,0,64.780000000,1,130,13213,79317863,64.780000000,64.800000000,3,2,3,2,64.770000000,64.810000000,6,3,5,3,64.760000000,64.820000000,9,9,9,6,64.750000000,64.830000000,9,7,9,7,64.740000000,64.840000000,9,9,8,8,64.730000000,64.850000000,6,8,6,5,64.720000000,64.860000000,8,4,5,3,64.710000000,64.870000000,8,4,7,3,64.700000000,64.880000000,7,4,6,3,64.690000000,64.890000000,4,3,3,2,MCLN5
2025-06-11T00:00:20.760549671Z,2025-06-11T00:00:20.755695629Z,10,1,42026514,M,B,3,64.740000000,1,130,15348,79317902,64.780000000,64.800000000,3,2,3,2,64.770000000,64.810000000,6,3,5,3,64.760000000,64.820000000,9,9,9,6,64.750000000,64.830000000,8,7,8,7,64.740000000,64.840000000,10,9,9,8,64.730000000,64.850000000,6,8,6,5,64.720000000,64.860000000,8,4,5,3,64.710000000,64.870000000,8,4,7,3,64.700000000,64.880000000,7,4,6,3,64.690000000,64.890000000,4,3,3,2,MCLN5
2025-06-11T00:00:20.760566828Z,2025-06-11T00:00:20.755696185Z,10,1,42026514,M,A,3,64.830000000,1,130,10983,79317903,64.780000000,64.800000000,3,2,3,2,64.770000000,64.810000000,6,3,5,3,64.760000000,64.820000000,9,9,9,6,64.750000000,64.830000000,8,8,8,8,64.740000000,64.840000000,10,8,9,7,64.730000000,64.850000000,6,8,6,5,64.720000000,64.860000000,8,4,5,3,64.710000000,64.870000000,8,4,7,3,64.700000000,64.880000000,7,4,6,3,64.690000000,64.890000000,4,3,3,2,MCLN5
2025-06-11T00:00:20.760594236Z,2025-06-11T00:00:20.755829907Z,10,1,42025623,A,A,0,63.710000000,1,130,11323,79317905,63.690000000,63.710000000,3,1,3,1,63.680000000,63.720000000,2,2,2,2,63.670000000,63.730000000,3,2,3,2,63.660000000,63.740000000,6,3,6,3,63.650000000,63.750000000,3,2,3,2,63.640000000,63.760000000,4,5,4,5,63.630000000,63.770000000,4,2,4,2,63.620000000,63.780000000,3,4,3,4,63.610000000,63.790000000,2,1,2,1,63.600000000,63.800000000,7,3,7,3,MCLQ5
2025-06-11T00:00:20.760784329Z,2025-06-11T00:00:20.756003735Z,10,1,42026514,M,A,3,64.840000000,1,130,11493,79317917,64.780000000,64.800000000,3,2,3,2,64.770000000,64.810000000,6,3,5,3,64.760000000,64.820000000,9,9,9,6,64.750000000,64.830000000,8,7,8,7,64.740000000,64.840000000,10,9,9,8,64.730000000,64.850000000,6,8,6,5,64.720000000,64.860000000,8,4,5,3,64.710000000,64.870000000,8,4,7,3,64.700000000,64.880000000,7,4,6,3,64.690000000,64.890000000,4,3,3,2,MCLN5
2025-06-11T00:00:20.761331385Z,2025-06-11T00:00:20.756198377Z,10,1,42026514,T,B,0,64.800000000,1,0,11740,79317955,64.780000000,64.800000000,3,2,3,2,64.770000000,64.810000000,6,3,5,3,64.760000000,64.820000000,9,9,9,6,64.750000000,64.830000000,8,7,8,7,64.740000000,64.840000000,10,9,9,8,64.730000000,64.850000000,6,8,6,5,64.720000000,64.860000000,8,4,5,3,64.710000000,64.870000000,8,4,7,3,64.700000000,64.880000000,7,4,6,3,64.690000000,64.890000000,4,3,3,2,MCLN5
2025-06-11T00:00:20.761331385Z,2025-06-11T00:00:20.756198377Z,10,1,42026514,C,A,0,64.800000000,1,130,11740,79317955,64.780000000,64.800000000,3,1,3,1,64.770000000,64.810000000,6,3,5,3,64.760000000,64.820000000,9,9,9,6,64.750000000,64.830000000,8,7,8,7,64.740000000,64.840000000,10,9,9,8,64.730000000,64.850000000,6,8,6,5,64.720000000,64.860000000,8,4,5,3,64.710000000,64.870000000,8,4,7,3,64.700000000,64.880000000,7,4,6,3,64.690000000,64.890000000,4,3,3,2,MCLN5
2025-06-11T00:00:20.761674164Z,2025-06-11T00:00:20.756416269Z,10,1,42026514,A,A,0,64.800000000,1,130,14731,79317979,64.780000000,64.800000000,3,2,3,2,64.770000000,64.810000000,6,3,5,3,64.760000000,64.820000000,9,9,9,6,64.750000000,64.830000000,8,7,8,7,64.740000000,64.840000000,10,9,9,8,64.730000000,64.850000000,6,8,6,5,64.720000000,64.860000000,8,4,5,3,64.710000000,64.870000000,8,4,7,3,64.700000000,64.880000000,7,4,6,3,64.690000000,64.890000000,4,3,3,2,MCLN5
2025-06-11T00:00:20.762547763Z,2025-06-11T00:00:20.756630683Z,10,1,42026514,M,B,0,64.780000000,1,130,12097,79318038,64.780000000,64.800000000,4,2,4,2,64.770000000,64.810000000,6,3,5,3,64.760000000,64.820000000,9,9,9,6,64.750000000,64.830000000,8,7,8,7,64.740000000,64.840000000,10,9,9,8,64.730000000,64.850000000,6,8,6,5,64.720000000,64.860000000,8,4,5,3,64.710000000,64.870000000,8,4,7,3,64.700000000,64.880000000,7,4,6,3,64.690000000,64.890000000,4,3,3,2,MCLN5
2025-06-11T00:00:20.764296200Z,2025-06-11T00:00:20.757788067Z,10,1,42026514,C,A,0,64.800000000,1,130,15472,79318164,64.780000000,64.800000000,4,1,4,1,64.770000000,64.810000000,6,3,5,3,64.760000000,64.820000000,9,9,9,6,64.750000000,64.830000000,8,7,8,7,64.740000000,64.840000000,10,9,9,8,64.730000000,64.850000000,6,8,6,5,64.720000000,64.860000000,8,4,5,3,64.710000000,64.870000000,8,4,7,3,64.700000000,64.880000000,7,4,6,3,64.690000000,64.890000000,4,3,3,2,MCLN5
2025-06-11T00:00:20.764306967Z,2025-06-11T00:00:20.757931581Z,10,1,42026514,M,A,1,64.810000000,1,130,11655,79318165,64.780000000,64.800000000,4,1,4,1,64.770000000,64.810000000,6,4,5,4,64.760000000,64.820000000,9,9,9,6,64.750000000,64.830000000,8,7,8,7,64.740000000,64.840000000,10,9,9,8,64.730000000,64.850000000,6,8,6,5,64.720000000,64.860000000,8,4,5,3,64.710000000,64.870000000,8,4,7,3,64.700000000,64.880000000,7,4,6,3,64.690000000,64.890000000,4,3,3,2,MCLN5
2025-06-11T00:00:20.765035614Z,2025-06-11T00:00:20.758303775Z,10,1,42025623,C,A,0,63.710000000,1,130,15218,79318209,63.690000000,63.720000000,3,2,3,2,63.680000000,63.730000000,2,2,2,2,63.670000000,63.740000000,3,3,3,3,63.660000000,63.750000000,6,2,6,2,63.650000000,63.760000000,3,5,3,5,63.640000000,63.770000000,4,2,4,2,63.630000000,63.780000000,4,4,4,4,63.620000000,63.790000000,3,1,3,1,63.610000000,63.800000000,2,3,2,3,63.600000000,63.810000000,7,4,7,2,MCLQ5
2025-06-11T00:00:20.765431790Z,2025-06-11T00:00:20.758500069Z,10,1,42026514,C,A,0,64.800000000,1,130,11844,79318240,64.780000000,64.810000000,4,4,4,4,64.770000000,64.820000000,6,9,5,6,64.760000000,64.830000000,9,7,9,7,64.750000000,64.840000000,8,9,8,8,64.740000000,64.850000000,10,8,9,5,64.730000000,64.860000000,6,4,6,3,64.720000000,64.870000000,8,4,5,3,64.710000000,64.880000000,8,4,7,3,64.700000000,64.890000000,7,3,6,2,64.690000000,64.900000000,4,5,3,4,MCLN5
2025-06-11T00:00:20.765844307Z,2025-06-11T00:00:20.758815797Z,10,1,42026514,C,A,0,64.810000000,1,130,17982,79318266,64.780000000,64.810000000,4,3,4,3,64.770000000,64.820000000,6,9,5,6,64.760000000,64.830000000,9,7,9,7,64.750000000,64.840000000,8,9,8,8,64.740000000,64.850000000,10,8,9,5,64.730000000,64.860000000,6,4,6,3,64.720000000,64.870000000,8,4,5,3,64.710000000,64.880000000,8,4,7,3,64.700000000,64.890000000,7,3,6,2,64.690000000,64.900000000,4,5,3,4,MCLN5
2025-06-11T00:00:20.766208604Z,2025-06-11T00:00:20.759165759Z,10,1,42025623,M,B,3,63.650000000,1,130,13612,79318290,63.690000000,63.720000000,3,2,3,2,63.680000000,63.730000000,2,2,2,2,63.670000000,63.740000000,3,3,3,3,63.660000000,63.750000000,5,2,5,2,63.650000000,63.760000000,4,5,4,5,63.640000000,63.770000000,4,2,4,2,63.630000000,63.780000000,4,4,4,4,63.620000000,63.790000000,3,1,3,1,63.610000000,63.800000000,2,3,2,3,63.600000000,63.810000000,7,4,7,2,MCLQ5
2025-06-11T00:00:20.766217505Z,2025-06-11T00:00:20.759166239Z,10,1,42025623,M,A,4,63.760000000,1,130,11766,79318291,63.690000000,63.720000000,3,2,3,2,63.680000000,63.730000000,2,2,2,2,63.670000000,63.740000000,3,3,3,3,63.660000000,63.750000000,5,2,5,2,63.650000000,63.760000000,4,6,4,6,63.640000000,63.770000000,4,1,4,1,63.630000000,63.780000000,4,4,4,4,63.620000000,63.790000000,3,1,3,1,63.610000000,63.800000000,2,3,2,3,63.600000000,63.810000000,7,4,7,2,MCLQ5
2025-06-11T00:00:20.766937214Z,2025-06-11T00:00:20.759787333Z,10,1,42026514,C,B,0,64.780000000,1,130,12736,79318343,64.780000000,64.810000000,3,3,3,3,64.770000000,64.820000000,6,9,5,6,64.760000000,64.830000000,9,7,9,7,64.750000000,64.840000000,8,9,8,8,64.740000000,64.850000000,10,8,9,5,64.730000000,64.860000000,6,4,6,3,64.720000000,64.870000000,8,4,5,3,64.710000000,64.880000000,8,4,7,3,64.700000000,64.890000000,7,3,6,2,64.690000000,64.900000000,4,5,3,4,MCLN5
2025-06-11T00:00:20.767017765Z,2025-06-11T00:00:20.759811735Z,10,1,42026514,A,A,0,64.800000000,1,130,11864,79318347,64.780000000,64.800000000,3,1,3,1,64.770000000,64.810000000,6,3,5,3,64.760000000,64.820000000,9,9,9,6,64.750000000,64.830000000,8,7,8,7,64.740000000,64.840000000,10,9,9,8,64.730000000,64.850000000,6,8,6,5,64.720000000,64.860000000,8,4,5,3,64.710000000,64.870000000,8,4,7,3,64.700000000,64.880000000,7,4,6,3,64.690000000,64.890000000,4,3,3,2,MCLN5
2025-06-11T00:00:20.767841309Z,2025-06-11T00:00:20.760602047Z,10,1,42025623,C,B,5,63.640000000,1,130,11168,79318402,63.690000000,63.720000000,3,2,3,2,63.680000000,63.730000000,2,2,2,2,63.670000000,63.740000000,3,3,3,3,63.660000000,63.750000000,5,2,5,2,63.650000000,63.760000000,4,6,4,6,63.640000000,63.770000000,3,1,3,1,63.630000000,63.780000000,4,4,4,4,63.620000000,63.790000000,3,1,3,1,63.610000000,63.800000000,2,3,2,3,63.600000000,63.810000000,7,4,7,2,MCLQ5
2025-06-11T00:00:20.768011089Z,2025-06-11T00:00:20.760750939Z,10,1,42025623,M,B,2,62.300000000,1,130,14786,79318409,63.690000000,63.720000000,3,2,3,2,63.680000000,63.730000000,2,2,2,2,63.670000000,63.740000000,2,3,2,3,63.660000000,63.750000000,5,2,5,2,63.650000000,63.760000000,4,6,4,6,63.640000000,63.770000000,3,1,3,1,63.630000000,63.780000000,4,4,4,4,63.620000000,63.790000000,3,1,3,1,63.610000000,63.800000000,2,3,2,3,63.600000000,63.810000000,7,4,7,2,MCLQ5
2025-06-11T00:00:20.768149361Z,2025-06-11T00:00:20.760894027Z,10,1,42026514,M,B,0,62.840000000,2,130,14577,79318415,64.780000000,64.800000000,2,1,2,1,64.770000000,64.810000000,6,3,5,3,64.760000000,64.820000000,9,9,9,6,64.750000000,64.830000000,8,7,8,7,64.740000000,64.840000000,10,9,9,8,64.730000000,64.850000000,6,8,6,5,64.720000000,64.860000000,8,4,5,3,64.710000000,64.870000000,8,4,7,3,64.700000000,64.880000000,7,4,6,3,64.690000000,64.890000000,4,3,3,2,MCLN5
2025-06-11T00:00:20.769305016Z,2025-06-11T00:00:20.761137033Z,10,1,42025623,C,B,0,63.690000000,1,130,15324,79318498,63.690000000,63.720000000,2,2,2,2,63.680000000,63.730000000,2,2,2,2,63.670000000,63.740000000,2,3,2,3,63.660000000,63.750000000,5,2,5,2,63.650000000,63.760000000,4,6,4,6,63.640000000,63.770000000,3,1,3,1,63.630000000,63.780000000,4,4,4,4,63.620000000,63.790000000,3,1,3,1,63.610000000,63.800000000,2,3,2,3,63.600000000,63.810000000,7,4,7,2,MCLQ5
2025-06-11T00:00:20.769886923Z,2025-06-11T00:00:20.761344173Z,10,1,42026514,A,A,0,64.800000000,1,130,17563,79318528,64.780000000,64.800000000,2,2,2,2,64.770000000,64.810000000,6,3,5,3,64.760000000,64.820000000,9,9,9,6,64.750000000,64.830000000,8,7,8,7,64.740000000,64.840000000,10,9,9,8,64.730000000,64.850000000,6,8,6,5,64.720000000,64.860000000,8,4,5,3,64.710000000,64.870000000,8,4,7,3,64.700000000,64.880000000,7,4,6,3,64.690000000,64.890000000,4,3,3,2,MCLN5
2025-06-11T00:00:20.769910661Z,2025-06-11T00:00:20.761372741Z,10,1,42025623,A,A,0,63.710000000,1,130,15437,79318529,63.690000000,63.710000000,2,1,2,1,63.680000000,63.720000000,2,2,2,2,63.670000000,63.730000000,2,2,2,2,63.660000000,63.740000000,5,3,5,3,63.650000000,63.750000000,4,2,4,2,63.640000000,63.760000000,3,6,3,6,63.630000000,63.770000000,4,1,4,1,63.620000000,63.780000000,3,4,3,4,63.610000000,63.790000000,2,1,2,1,63.600000000,63.800000000,7,3,7,3,MCLQ5
2025-06-11T00:00:20.770377703Z,2025-06-11T00:00:20.761685341Z,10,1,42026514,A,A,0,64.800000000,1,130,16630,79318563,64.780000000,64.800000000,2,3,2,3,64.770000000,64.810000000,6,3,5,3,64.760000000,64.820000000,9,9,9,6,64.750000000,64.830000000,8,7,8,7,64.740000000,64.840000000,10,9,9,8,64.730000000,64.850000000,6,8,6,5,64.720000000,64.860000000,8,4,5,3,64.710000000,64.870000000,8,4,7,3,64.700000000,64.880000000,7,4,6,3,64.690000000,64.890000000,4,3,3,2,MCLN5
2025-06-11T00:00:20.770693196Z,2025-06-11T00:00:20.761795101Z,10,1,42026514,A,B,0,64.780000000,1,130,16386,79318582,64.780000000,64.800000000,3,3,3,3,64.770000000,64.810000000,6,3,5,3,64.760000000,64.820000000,9,9,9,6,64.750000000,64.830000000,8,7,8,7,64.740000000,64.840000000,10,9,9,8,64.730000000,64.850000000,6,8,6,5,64.720000000,64.860000000,8,4,5,3,64.710000000,64.870000000,8,4,7,3,64.700000000,64.880000000,7,4,6,3,64.690000000,64.890000000,4,3,3,2,MCLN5
2025-06-11T00:00:20.771820100Z,2025-06-11T00:00:20.762832625Z,10,1,42418117,M,B,0,3.250000000,10,130,11847,79318658,3.250000000,3.280000000,11,1,2,1,3.240000000,3.290000000,1,11,1,2,3.230000000,3.300000000,1,1,1,1,,,0,0,0,0,,,0,0,0,0,,,0,0,0,0,,,0,0,0,0,,,0,0,0,0,,,0,0,0,0,,,0,0,0,0,MCLN5-MCLX5
2025-06-11T00:00:20.772528005Z,2025-06-11T00:00:20.763158011Z,10,1,42025623,A,A,0,63.710000000,1,130,13606,79318696,63.690000000,63.710000000,2,2,2,2,63.680000000,63.720000000,2,2,2,2,63.670000000,63.730000000,2,2,2,2,63.660000000,63.740000000,5,3,5,3,63.650000000,63.750000000,4,2,4,2,63.640000000,63.760000000,3,6,3,6,63.630000000,63.770000000,4,1,4,1,63.620000000,63.780000000,3,4,3,4,63.610000000,63.790000000,2,1,2,1,63.600000000,63.800000000,7,3,7,3,MCLQ5
2025-06-11T00:00:20.772620989Z,2025-06-11T00:00:20.763181589Z,10,1,42418117,M,B,0,3.240000000,10,130,11952,79318701,3.250000000,3.280000000,1,1,1,1,3.240000000,3.290000000,11,11,2,2,3.230000000,3.300000000,1,1,1,1,,,0,0,0,0,,,0,0,0,0,,,0,0,0,0,,,0,0,0,0,,,0,0,0,0,,,0,0,0,0,,,0,0,0,0,MCLN5-MCLX5
2025-06-11T00:00:20.773756963Z,2025-06-11T00:00:20.763651699Z,10,1,42025623,M,B,3,63.650000000,1,130,12104,79318787,63.690000000,63.710000000,2,2,2,2,63.680000000,63.720000000,2,2,2,2,63.670000000,63.730000000,2,2,2,2,63.660000000,63.740000000,4,3,4,3,63.650000000,63.750000000,5,2,5,2,63.640000000,63.760000000,3,6,3,6,63.630000000,63.770000000,4,1,4,1,63.620000000,63.780000000,3,4,3,4,63.610000000,63.790000000,2,1,2,1,63.600000000,63.800000000,7,3,7,3,MCLQ5
2025-06-11T00:00:20.773768621Z,2025-06-11T00:00:20.763652197Z,10,1,42025623,M,A,4,63.750000000,1,130,13354,79318788,63.690000000,63.710000000,2,2,2,2,63.680000000,63.720000000,2,2,2,2,63.670000000,63.730000000,2,2,2,2,63.660000000,63.740000000,4,3,4,3,63.650000000,63.750000000,5,3,5,3,63.640000000,63.760000000,3,5,3,5,63.630000000,63.770000000,4,1,4,1,63.620000000,63.780000000,3,4,3,4,63.610000000,63.790000000,2,1,2,1,63.600000000,63.800000000,7,3,7,3,MCLQ5
2025-06-11T00:00:20.773777905Z,2025-06-11T00:00:20.763652717Z,10,1,42025623,M,B,3,63.650000000,1,130,11423,79318789,63.690000000,63.710000000,2,2,2,2,63.680000000,63.720000000,2,2,2,2,63.670000000,63.730000000,2,2,2,2,63.660000000,63.740000000,3,3,3,3,63.650000000,63.750000000,6,3,6,3,63.640000000,63.760000000,3,5,3,5,63.630000000,63.770000000,4,1,4,1,63.620000000,63.780000000,3,4,3,4,63.610000000,63.790000000,2,1,2,1,63.600000000,63.800000000,7,3,7,3,MCLQ5
2025-06-11T00:00:20.773788239Z,2025-06-11T00:00:20.763653253Z,10,1,42025623,M,A,4,63.750000000,1,130,11885,79318790,63.690000000,63.710000000,2,2,2,2,63.680000000,63.720000000,2,2,2,2,63.670000000,63.730000000,2,2,2,2,63.660000000,63.740000000,3,3,3,3,63.650000000,63.750000000,6,4,6,4,63.640000000,63.760000000,3,4,3,4,63.630000000,63.770000000,4,1,4,1,63.620000000,63.780000000,3,4,3,4,63.610000000,63.790000000,2,1,2,1,63.600000000,63.800000000,7,3,7,3,MCLQ5
2025-06-11T00:00:20.774941886Z,2025-06-11T00:00:20.765434473Z,10,1,42026514,A,A,0,64.790000000,2,130,13743,79318869,64.780000000,64.790000000,3,2,3,1,64.770000000,64.800000000,6,3,5,3,64.760000000,64.810000000,9,3,9,3,64.750000000,64.820000000,8,9,8,6,64.740000000,64.830000000,10,7,9,7,64.730000000,64.840000000,6,9,6,8,64.720000000,64.850000000,8,8,5,5,64.710000000,64.860000000,8,4,7,3,64.700000000,64.870000000,7,4,6,3,64.690000000,64.880000000,4,4,3,3,MCLN5
2025-06-11T00:00:20.775086439Z,2025-06-11T00:00:20.765445571Z,10,1,42026514,A,A,1,64.800000000,1,130,12107,79318878,64.780000000,64.790000000,3,2,3,1,64.770000000,64.800000000,6,4,5,4,64.760000000,64.810000000,9,3,9,3,64.750000000,64.820000000,8,9,8,6,64.740000000,64.830000000,10,7,9,7,64.730000000,64.840000000,6,9,6,8,64.720000000,64.850000000,8,8,5,5,64.710000000,64.860000000,8,4,7,3,64.700000000,64.870000000,7,4,6,3,64.690000000,64.880000000,4,4,3,3,MCLN5
2025-06-11T00:00:20.775150334Z,2025-06-11T00:00:20.765476253Z,10,1,42025623,C,A,0,63.710000000,1,130,14049,79318882,63.690000000,63.710000000,2,1,2,1,63.680000000,63.720000000,2,2,2,2,63.670000000,63.730000000,2,2,2,2,63.660000000,63.740000000,3,3,3,3,63.650000000,63.750000000,6,4,6,4,63.640000000,63.760000000,3,4,3,4,63.630000000,63.770000000,4,1,4,1,63.620000000,63.780000000,3,4,3,4,63.610000000,63.790000000,2,1,2,1,63.600000000,63.800000000,7,3,7,3,MCLQ5
2025-06-11T00:00:20.775221669Z,2025-06-11T00:00:20.765571115Z,10,1,42022708,M,B,0,2.810000000,1,130,12235,79318885,2.810000000,2.830000000,2,2,2,2,2.800000000,2.840000000,12,12,3,3,2.790000000,2.850000000,2,1,2,1,,2.870000000,0,1,0,1,,,0,0,0,0,,,0,0,0,0,,,0,0,0,0,,,0,0,0,0,,,0,0,0,0,,,0,0,0,0,MCLN5-MCLV5
2025-06-11T00:00:20.775325651Z,2025-06-11T00:00:20.765655149Z,10,1,42026514,C,B,0,64.780000000,1,130,14156,79318892,64.780000000,64.790000000,2,2,2,1,64.770000000,64.800000000,6,4,5,4,64.760000000,64.810000000,9,3,9,3,64.750000000,64.820000000,8,9,8,6,64.740000000,64.830000000,10,7,9,7,64.730000000,64.840000000,6,9,6,8,64.720000000,64.850000000,8,8,5,5,64.710000000,64.860000000,8,4,7,3,64.700000000,64.870000000,7,4,6,3,64.690000000,64.880000000,4,4,3,3,MCLN5
2025-06-11T00:00:20.775643816Z,2025-06-11T00:00:20.766101605Z,10,1,42025623,M,A,4,63.760000000,1,130,11608,79318914,63.690000000,63.710000000,2,1,2,1,63.680000000,63.720000000,2,2,2,2,63.670000000,63.730000000,2,2,2,2,63.660000000,63.740000000,3,3,3,3,63.650000000,63.750000000,6,3,6,3,63.640000000,63.760000000,3,5,3,5,63.630000000,63.770000000,4,1,4,1,63.620000000,63.780000000,3,4,3,4,63.610000000,63.790000000,2,1,2,1,63.600000000,63.800000000,7,3,7,3,MCLQ5
2025-06-11T00:00:20.775655989Z,2025-06-11T00:00:20.766102393Z,10,1,42025623,M,A,4,63.760000000,1,130,12271,79318915,63.690000000,63.710000000,2,1,2,1,63.680000000,63.720000000,2,2,2,2,63.670000000,63.730000000,2,2,2,2,63.660000000,63.740000000,3,3,3,3,63.650000000,63.750000000,6,2,6,2,63.640000000,63.760000000,3,6,3,6,63.630000000,63.770000000,4,1,4,1,63.620000000,63.780000000,3,4,3,4,63.610000000,63.790000000,2,1,2,1,63.600000000,63.800000000,7,3,7,3,MCLQ5
2025-06-11T00:00:20.775881039Z,2025-06-11T00:00:20.766328119Z,10,1,42026514,A,B,0,64.780000000,1,130,13103,79318928,64.780000000,64.790000000,3,2,3,1,64.770000000,64.800000000,6,4,5,4,64.760000000,64.810000000,9,3,9,3,64.750000000,64.820000000,8,9,8,6,64.740000000,64.830000000,10,7,9,7,64.730000000,64.840000000,6,9,6,8,64.720000000,64.850000000,8,8,5,5,64.710000000,64.860000000,8,4,7,3,64.700000000,64.870000000,7,4,6,3,64.690000000,64.880000000,4,4,3,3,MCLN5
2025-06-11T00:00:20.775898303Z,2025-06-11T00:00:20.766329557Z,10,1,42025623,A,B,0,63.690000000,1,130,13384,79318929,63.690000000,63.710000000,3,1,3,1,63.680000000,63.720000000,2,2,2,2,63.670000000,63.730000000,2,2,2,2,63.660000000,63.740000000,3,3,3,3,63.650000000,63.750000000,6,2,6,2,63.640000000,63.760000000,3,6,3,6,63.630000000,63.770000000,4,1,4,1,63.620000000,63.780000000,3,4,3,4,63.610000000,63.790000000,2,1,2,1,63.600000000,63.800000000,7,3,7,3,MCLQ5
2025-06-11T00:00:20.776248608Z,2025-06-11T00:00:20.766708319Z,10,1,42025623,C,A,0,63.710000000,1,130,18421,79318951,63.690000000,63.720000000,3,2,3,2,63.680000000,63.730000000,2,2,2,2,63.670000000,63.740000000,2,3,2,3,63.660000000,63.750000000,3,2,3,2,63.650000000,63.760000000,6,6,6,6,63.640000000,63.770000000,3,1,3,1,63.630000000,63.780000000,4,4,4,4,63.620000000,63.790000000,3,1,3,1,63.610000000,63.800000000,2,3,2,3,63.600000000,63.810000000,7,4,7,2,MCLQ5
2025-06-11T00:00:20.776762050Z,2025-06-11T00:00:20.767005061Z,10,1,42026514,C,B,0,64.780000000,1,130,13286,79318979,64.780000000,64.790000000,2,2,2,1,64.770000000,64.800000000,6,4,5,4,64.760000000,64.810000000,9,3,9,3,64.750000000,64.820000000,8,9,8,6,64.740000000,64.830000000,10,7,9,7,64.730000000,64.840000000,6,9,6,8,64.720000000,64.850000000,8,8,5,5,64.710000000,64.860000000,8,4,7,3,64.700000000,64.870000000,7,4,6,3,64.690000000,64.880000000,4,4,3,3,MCLN5
2025-06-11T00:00:20.776843469Z,2025-06-11T00:00:20.767053847Z,10,1,42025623,A,A,0,63.710000000,1,130,15344,79318984,63.690000000,63.710000000,3,1,3,1,63.680000000,63.720000000,2,2,2,2,63.670000000,63.730000000,2,2,2,2,63.660000000,63.740000000,3,3,3,3,63.650000000,63.750000000,6,2,6,2,63.640000000,63.760000000,3,6,3,6,63.630000000,63.770000000,4,1,4,1,63.620000000,63.780000000,3,4,3,4,63.610000000,63.790000000,2,1,2,1,63.600000000,63.800000000,7,3,7,3,MCLQ5
2025-06-11T00:00:20.777095820Z,2025-06-11T00:00:20.767190665Z,10,1,42026514,M,B,2,62.830000000,2,130,11609,79319001,64.780000000,64.790000000,2,2,2,1,64.770000000,64.800000000,6,4,5,4,64.760000000,64.810000000,8,3,8,3,64.750000000,64.820000000,8,9,8,6,64.740000000,64.830000000,10,7,9,7,64.730000000,64.840000000,6,9,6,8,64.720000000,64.850000000,8,8,5,5,64.710000000,64.860000000,8,4,7,3,64.700000000,64.870000000,7,4,6,3,64.690000000,64.880000000,4,4,3,3,MCLN5
2025-06-11T00:00:20.777134487Z,2025-06-11T00:00:20.767204405Z,10,1,42026514,M,B,2,62.820000000,2,130,11751,79319004,64.780000000,64.790000000,2,2,2,1,64.770000000,64.800000000,6,4,5,4,64.760000000,64.810000000,7,3,7,3,64.750000000,64.820000000,8,9,8,6,64.740000000,64.830000000,10,7,9,7,64.730000000,64.840000000,6,9,6,8,64.720000000,64.850000000,8,8,5,5,64.710000000,64.860000000,8,4,7,3,64.700000000,64.870000000,7,4,6,3,64.690000000,64.880000000,4,4,3,3,MCLN5
2025-06-11T00:00:20.779247413Z,2025-06-11T00:00:20.769221141Z,10,1,42026514,A,A,1,64.800000000,1,130,12749,79319137,64.780000000,64.790000000,2,2,2,1,64.770000000,64.800000000,6,5,5,5,64.760000000,64.810000000,7,3,7,3,64.750000000,64.820000000,8,9,8,6,64.740000000,64.830000000,10,7,9,7,64.730000000,64.840000000,6,9,6,8,64.720000000,64.850000000,8,8,5,5,64.710000000,64.860000000,8,4,7,3,64.700000000,64.870000000,7,4,6,3,64.690000000,64.880000000,4,4,3,3,MCLN5
2025-06-11T00:00:20.779347540Z,2025-06-11T00:00:20.769294059Z,10,1,42026514,A,A,0,64.790000000,2,130,12227,79319142,64.780000000,64.790000000,2,4,2,2,64.770000000,64.800000000,6,5,5,5,64.760000000,64.810000000,7,3,7,3,64.750000000,64.820000000,8,9,8,6,64.740000000,64.830000000,10,7,9,7,64.730000000,64.840000000,6,9,6,8,64.720000000,64.850000000,8,8,5,5,64.710000000,64.860000000,8,4,7,3,64.700000000,64.870000000,7,4,6,3,64.690000000,64.880000000,4,4,3,3,MCLN5
2025-06-11T00:00:20.780269536Z,2025-06-11T00:00:20.769919089Z,10,1,42026514,A,A,0,64.790000000,1,130,13180,79319205,64.780000000,64.790000000,2,5,2,3,64.770000000,64.800000000,6,5,5,5,64.760000000,64.810000000,7,3,7,3,64.750000000,64.820000000,8,9,8,6,64.740000000,64.830000000,10,7,9,7,64.730000000,64.840000000,6,9,6,8,64.720000000,64.850000000,8,8,5,5,64.710000000,64.860000000,8,4,7,3,64.700000000,64.870000000,7,4,6,3,64.690000000,64.880000000,4,4,3,3,MCLN5
2025-06-11T00:00:20.781327193Z,2025-06-11T00:00:20.770204811Z,10,1,42025623,A,A,0,63.710000000,1,130,12997,79319277,63.690000000,63.710000000,3,2,3,2,63.680000000,63.720000000,2,2,2,2,63.670000000,63.730000000,2,2,2,2,63.660000000,63.740000000,3,3,3,3,63.650000000,63.750000000,6,2,6,2,63.640000000,63.760000000,3,6,3,6,63.630000000,63.770000000,4,1,4,1,63.620000000,63.780000000,3,4,3,4,63.610000000,63.790000000,2,1,2,1,63.600000000,63.800000000,7,3,7,3,MCLQ5
2025-06-11T00:00:20.781446420Z,2025-06-11T00:00:20.770207785Z,10,1,42026514,C,B,0,64.780000000,1,130,13393,79319285,64.780000000,64.790000000,1,5,1,3,64.770000000,64.800000000,6,5,5,5,64.760000000,64.810000000,7,3,7,3,64.750000000,64.820000000,8,9,8,6,64.740000000,64.830000000,10,7,9,7,64.730000000,64.840000000,6,9,6,8,64.720000000,64.850000000,8,8,5,5,64.710000000,64.860000000,8,4,7,3,64.700000000,64.870000000,7,4,6,3,64.690000000,64.880000000,4,4,3,3,MCLN5
2025-06-11T00:00:20.781475541Z,2025-06-11T00:00:20.770208501Z,10,1,42025623,C,B,0,63.690000000,1,130,13343,79319287,63.690000000,63.710000000,2,2,2,2,63.680000000,63.720000000,2,2,2,2,63.670000000,63.730000000,2,2,2,2,63.660000000,63.740000000,3,3,3,3,63.650000000,63.750000000,6,2,6,2,63.640000000,63.760000000,3,6,3,6,63.630000000,63.770000000,4,1,4,1,63.620000000,63.780000000,3,4,3,4,63.610000000,63.790000000,2,1,2,1,63.600000000,63.800000000,7,3,7,3,MCLQ5
2025-06-11T00:00:20.781977402Z,2025-06-11T00:00:20.770689435Z,10,1,42026514,M,A,1,64.800000000,1,130,11538,79319316,64.780000000,64.790000000,1,5,1,3,64.770000000,64.800000000,6,6,5,6,64.760000000,64.810000000,7,3,7,3,64.750000000,64.820000000,8,9,8,6,64.740000000,64.830000000,10,7,9,7,64.730000000,64.840000000,6,9,6,8,64.720000000,64.850000000,8,8,5,5,64.710000000,64.860000000,8,4,7,3,64.700000000,64.870000000,7,4,6,3,64.690000000,64.880000000,4,4,3,3,MCLN5
2025-06-11T00:00:20.783908159Z,2025-06-11T00:00:20.772783355Z,10,1,42026514,C,B,0,64.780000000,1,130,11403,79319437,64.770000000,64.790000000,6,5,5,3,64.760000000,64.800000000,7,6,7,6,64.750000000,64.810000000,8,3,8,3,64.740000000,64.820000000,10,9,9,6,64.730000000,64.830000000,6,7,6,7,64.720000000,64.840000000,8,9,5,8,64.710000000,64.850000000,8,8,7,5,64.700000000,64.860000000,7,4,6,3,64.690000000,64.870000000,4,4,3,3,64.680000000,64.880000000,4,4,2,3,MCLN5
2025-06-11T00:00:20.784270859Z,2025-06-11T00:00:20.772847171Z,10,1,42026514,M,B,2,64.740000000,1,130,11319,79319461,64.770000000,64.790000000,6,5,5,3,64.760000000,64.800000000,7,6,7,6,64.750000000,64.810000000,7,3,7,3,64.740000000,64.820000000,11,9,10,6,64.730000000,64.830000000,6,7,6,7,64.720000000,64.840000000,8,9,5,8,64.710000000,64.850000000,8,8,7,5,64.700000000,64.860000000,7,4,6,3,64.690000000,64.870000000,4,4,3,3,64.680000000,64.880000000,4,4,2,3,MCLN5
2025-06-11T00:00:20.784281119Z,2025-06-11T00:00:20.772847843Z,10,1,42026514,M,B,2,64.740000000,1,130,11378,79319462,64.770000000,64.790000000,6,5,5,3,64.760000000,64.800000000,7,6,7,6,64.750000000,64.810000000,6,3,6,3,64.740000000,64.820000000,12,9,11,6,64.730000000,64.830000000,6,7,6,7,64.720000000,64.840000000,8,9,5,8,64.710000000,64.850000000,8,8,7,5,64.700000000,64.860000000,7,4,6,3,64.690000000,64.870000000,4,4,3,3,64.680000000,64.880000000,4,4,2,3,MCLN5
2025-06-11T00:00:20.787344809Z,2025-06-11T00:00:20.774844169Z,10,1,42025623,M,A,1,63.720000000,1,130,12272,79319660,63.690000000,63.710000000,2,2,2,2,63.680000000,63.720000000,2,3,2,3,63.670000000,63.730000000,2,2,2,2,63.660000000,63.740000000,3,3,3,3,63.650000000,63.750000000,6,2,6,2,63.640000000,63.760000000,3,6,3,6,63.630000000,63.770000000,4,1,4,1,63.620000000,63.780000000,3,4,3,4,63.610000000,63.790000000,2,1,2,1,63.600000000,63.800000000,7,3,7,3,MCLQ5
2025-06-11T00:00:20.787437195Z,2025-06-11T00:00:20.774953375Z,10,1,42026514,A,A,0,64.790000000,1,130,13378,79319666,64.770000000,64.790000000,6,6,5,4,64.760000000,64.800000000,7,6,7,6,64.750000000,64.810000000,6,3,6,3,64.740000000,64.820000000,12,9,11,6,64.730000000,64.830000000,6,7,6,7,64.720000000,64.840000000,8,9,5,8,64.710000000,64.850000000,8,8,7,5,64.700000000,64.860000000,7,4,6,3,64.690000000,64.870000000,4,4,3,3,64.680000000,64.880000000,4,4,2,3,MCLN5
2025-06-11T00:00:20.787503447Z,2025-06-11T00:00:20.775084947Z,10,1,42025623,M,B,2,63.670000000,1,130,11549,79319669,63.690000000,63.710000000,2,2,2,2,63.680000000,63.720000000,2,3,2,3,63.670000000,63.730000000,3,2,3,2,63.660000000,63.740000000,3,3,3,3,63.650000000,63.750000000,6,2,6,2,63.640000000,63.760000000,3,6,3,6,63.630000000,63.770000000,4,1,4,1,63.620000000,63.780000000,3,4,3,4,63.610000000,63.790000000,2,1,2,1,63.600000000,63.800000000,7,3,7,3,MCLQ5
2025-06-11T00:00:20.788025091Z,2025-06-11T00:00:20.775353063Z,10,1,42418117,M,A,0,3.280000000,10,130,11336,79319700,3.250000000,3.280000000,1,11,1,2,3.240000000,3.290000000,11,1,2,1,3.230000000,3.300000000,1,1,1,1,,,0,0,0,0,,,0,0,0,0,,,0,0,0,0,,,0,0,0,0,,,0,0,0,0,,,0,0,0,0,,,0,0,0,0,MCLN5-MCLX5
2025-06-11T00:00:20.788122845Z,2025-06-11T00:00:20.775736393Z,10,1,42026514,A,B,0,64.780000000,1,130,15164,79319706,64.780000000,64.790000000,1,6,1,4,64.770000000,64.800000000,6,6,5,6,64.760000000,64.810000000,7,3,7,3,64.750000000,64.820000000,6,9,6,6,64.740000000,64.830000000,12,7,11,7,64.730000000,64.840000000,6,9,6,8,64.720000000,64.850000000,8,8,5,5,64.710000000,64.860000000,8,4,7,3,64.700000000,64.870000000,7,4,6,3,64.690000000,64.880000000,4,4,3,3,MCLN5
2025-06-11T00:00:20.788244628Z,2025-06-11T00:00:20.776165187Z,10,1,42026514,C,A,1,64.800000000,1,130,10710,79319716,64.780000000,64.790000000,1,6,1,4,64.770000000,64.800000000,6,5,5,5,64.760000000,64.810000000,7,3,7,3,64.750000000,64.820000000,6,9,6,6,64.740000000,64.830000000,12,7,11,7,64.730000000,64.840000000,6,9,6,8,64.720000000,64.850000000,8,8,5,5,64.710000000,64.860000000,8,4,7,3,64.700000000,64.870000000,7,4,6,3,64.690000000,64.880000000,4,4,3,3,MCLN5
2025-06-11T00:00:20.788317330Z,2025-06-11T00:00:20.776428867Z,10,1,42026514,C,B,0,64.780000000,1,130,11857,79319723,64.770000000,64.790000000,6,6,5,4,64.760000000,64.800000000,7,5,7,5,64.750000000,64.810000000,6,3,6,3,64.740000000,64.820000000,12,9,11,6,64.730000000,64.830000000,6,7,6,7,64.720000000,64.840000000,8,9,5,8,64.710000000,64.850000000,8,8,7,5,64.700000000,64.860000000,7,4,6,3,64.690000000,64.870000000,4,4,3,3,64.680000000,64.880000000,4,4,2,3,MCLN5
2025-06-11T00:00:20.790585867Z,2025-06-11T00:00:20.780316427Z,10,1,42026514,A,A,0,64.780000000,1,130,11370,79319873,64.770000000,64.780000000,6,1,5,1,64.760000000,64.790000000,7,6,7,4,64.750000000,64.800000000,6,5,6,5,64.740000000,64.810000000,12,3,11,3,64.730000000,64.820000000,6,9,6,6,64.720000000,64.830000000,8,7,5,7,64.710000000,64.840000000,8,9,7,8,64.700000000,64.850000000,7,8,6,5,64.690000000,64.860000000,4,4,3,3,64.680000000,64.870000000,4,4,2,3,MCLN5
2025-06-11T00:00:20.792052732Z,2025-06-11T00:00:20.781453555Z,10,1,42026514,M,B,3,64.730000000,1,130,11680,79319975,64.770000000,64.780000000,6,1,5,1,64.760000000,64.790000000,7,6,7,4,64.750000000,64.800000000,6,5,6,5,64.740000000,64.810000000,11,3,10,3,64.730000000,64.820000000,7,9,7,6,64.720000000,64.830000000,8,7,5,7,64.710000000,64.840000000,8,9,7,8,64.700000000,64.850000000,7,8,6,5,64.690000000,64.860000000,4,4,3,3,64.680000000,64.870000000,4,4,2,3,MCLN5
2025-06-11T00:00:20.793043077Z,2025-06-11T00:00:20.782849007Z,10,1,42025623,C,B,0,63.690000000,1,130,13443,79320045,63.690000000,63.710000000,1,2,1,2,63.680000000,63.720000000,2,3,2,3,63.670000000,63.730000000,3,2,3,2,63.660000000,63.740000000,3,3,3,3,63.650000000,63.750000000,6,2,6,2,63.640000000,63.760000000,3,6,3,6,63.630000000,63.770000000,4,1,4,1,63.620000000,63.780000000,3,4,3,4,63.610000000,63.790000000,2,1,2,1,63.600000000,63.800000000,7,3,7,3,MCLQ5
2025-06-11T00:00:20.793660286Z,2025-06-11T00:00:20.783462477Z,10,1,42025623,M,B,4,63.640000000,1,130,11429,79320081,63.690000000,63.710000000,1,2,1,2,63.680000000,63.720000000,2,3,2,3,63.670000000,63.730000000,3,2,3,2,63.660000000,63.740000000,3,3,3,3,63.650000000,63.750000000,5,2,5,2,63.640000000,63.760000000,4,6,4,6,63.630000000,63.770000000,4,1,4,1,63.620000000,63.780000000,3,4,3,4,63.610000000,63.790000000,2,1,2,1,63.600000000,63.800000000,7,3,7,3,MCLQ5
2025-06-11T00:00:20.794413470Z,2025-06-11T00:00:20.783917305Z,10,1,42026514,C,B,4,64.730000000,1,130,11750,79320124,64.770000000,64.780000000,6,1,5,1,64.760000000,64.790000000,7,6,7,4,64.750000000,64.800000000,6,5,6,5,64.740000000,64.810000000,11,3,10,3,64.730000000,64.820000000,6,9,6,6,64.720000000,64.830000000,8,7,5,7,64.710000000,64.840000000,8,9,7,8,64.700000000,64.850000000,7,8,6,5,64.690000000,64.860000000,4,4,3,3,64.680000000,64.870000000,4,4,2,3,MCLN5
2025-06-11T00:00:20.794421610Z,2025-06-11T00:00:20.783921951Z,10,1,42026514,C,B,0,64.770000000,1,130,11359,79320125,64.770000000,64.780000000,5,1,4,1,64.760000000,64.790000000,7,6,7,4,64.750000000,64.800000000,6,5,6,5,64.740000000,64.810000000,11,3,10,3,64.730000000,64.820000000,6,9,6,6,64.720000000,64.830000000,8,7,5,7,64.710000000,64.840000000,8,9,7,8,64.700000000,64.850000000,7,8,6,5,64.690000000,64.860000000,4,4,3,3,64.680000000,64.870000000,4,4,2,3,MCLN5
2025-06-11T00:00:20.794542256Z,2025-06-11T00:00:20.784189665Z,10,1,42026514,M,B,1,64.760000000,1,130,11139,79320134,64.770000000,64.780000000,5,1,4,1,64.760000000,64.790000000,8,6,8,4,64.750000000,64.800000000,6,5,6,5,64.740000000,64.810000000,11,3,10,3,64.730000000,64.820000000,6,9,6,6,64.720000000,64.830000000,8,7,5,7,64.710000000,64.840000000,8,9,7,8,64.700000000,64.850000000,7,8,6,5,64.690000000,64.860000000,4,4,3,3,64.680000000,64.870000000,4,4,2,3,MCLN5
2025-06-11T00:00:20.794549998Z,2025-06-11T00:00:20.784229559Z,10,1,42025623,C,A,1,63.720000000,1,130,11634,79320135,63.690000000,63.710000000,1,2,1,2,63.680000000,63.720000000,2,2,2,2,63.670000000,63.730000000,3,2,3,2,63.660000000,63.740000000,3,3,3,3,63.650000000,63.750000000,5,2,5,2,63.640000000,63.760000000,4,6,4,6,63.630000000,63.770000000,4,1,4,1,63.620000000,63.780000000,3,4,3,4,63.610000000,63.790000000,2,1,2,1,63.600000000,63.800000000,7,3,7,3,MCLQ5
2025-06-11T00:00:20.794894244Z,2025-06-11T00:00:20.784369829Z,10,1,42022708,M,B,0,2.780000000,1,130,15004,79320154,2.810000000,2.830000000,1,2,1,2,2.800000000,2.840000000,12,12,3,3,2.790000000,2.850000000,2,1,2,1,2.780000000,2.870000000,1,1,1,1,,,0,0,0,0,,,0,0,0,0,,,0,0,0,0,,,0,0,0,0,,,0,0,0,0,,,0,0,0,0,MCLN5-MCLV5
2025-06-11T00:00:20.795888628Z,2025-06-11T00:00:20.787356871Z,10,1,42025623,A,B,6,63.630000000,1,130,11440,79320223,63.690000000,63.710000000,1,2,1,2,63.680000000,63.720000000,2,2,2,2,63.670000000,63.730000000,3,2,3,2,63.660000000,63.740000000,3,3,3,3,63.650000000,63.750000000,5,2,5,2,63.640000000,63.760000000,4,6,4,6,63.630000000,63.770000000,5,1,5,1,63.620000000,63.780000000,3,4,3,4,63.610000000,63.790000000,2,1,2,1,63.600000000,63.800000000,7,3,7,3,MCLQ5
2025-06-11T00:00:20.795899902Z,2025-06-11T00:00:20.787358157Z,10,1,42025623,C,A,7,63.780000000,1,130,11641,79320224,63.690000000,63.710000000,1,2,1,2,63.680000000,63.720000000,2,2,2,2,63.670000000,63.730000000,3,2,3,2,63.660000000,63.740000000,3,3,3,3,63.650000000,63.750000000,5,2,5,2,63.640000000,63.760000000,4,6,4,6,63.630000000,63.770000000,5,1,5,1,63.620000000,63.780000000,3,3,3,3,63.610000000,63.790000000,2,1,2,1,63.600000000,63.800000000,7,3,7,3,MCLQ5
2025-06-11T00:00:20.795913879Z,2025-06-11T00:00:20.787488751Z,10,1,42025623,A,A,6,63.770000000,1,130,15266,79320225,63.690000000,63.710000000,1,2,1,2,63.680000000,63.720000000,2,2,2,2,63.670000000,63.730000000,3,2,3,2,63.660000000,63.740000000,3,3,3,3,63.650000000,63.750000000,5,2,5,2,63.640000000,63.760000000,4,6,4,6,63.630000000,63.770000000,5,2,5,2,63.620000000,63.780000000,3,3,3,3,63.610000000,63.790000000,2,1,2,1,63.600000000,63.800000000,7,3,7,3,MCLQ5
2025-06-11T00:00:20.796124814Z,2025-06-11T00:00:20.787554047Z,10,1,42026514,A,B,0,64.770000000,1,130,15981,79320236,64.770000000,64.780000000,6,1,5,1,64.760000000,64.790000000,8,6,8,4,64.750000000,64.800000000,6,5,6,5,64.740000000,64.810000000,11,3,10,3,64.730000000,64.820000000,6,9,6,6,64.720000000,64.830000000,8,7,5,7,64.710000000,64.840000000,8,9,7,8,64.700000000,64.850000000,7,8,6,5,64.690000000,64.860000000,4,4,3,3,64.680000000,64.870000000,4,4,2,3,MCLN5
2025-06-11T00:00:20.796338745Z,2025-06-11T00:00:20.787994169Z,10,1,42026514,C,B,0,64.770000000,1,130,13578,79320252,64.770000000,64.780000000,5,1,4,1,64.760000000,64.790000000,8,6,8,4,64.750000000,64.800000000,6,5,6,5,64.740000000,64.810000000,11,3,10,3,64.730000000,64.820000000,6,9,6,6,64.720000000,64.830000000,8,7,5,7,64.710000000,64.840000000,8,9,7,8,64.700000000,64.850000000,7,8,6,5,64.690000000,64.860000000,4,4,3,3,64.680000000,64.870000000,4,4,2,3,MCLN5
2025-06-11T00:00:20.796743152Z,2025-06-11T00:00:20.788480193Z,10,1,42026514,M,A,2,64.800000000,1,130,11788,79320283,64.770000000,64.780000000,5,1,4,1,64.760000000,64.790000000,8,6,8,4,64.750000000,64.800000000,6,6,6,6,64.740000000,64.810000000,11,3,10,3,64.730000000,64.820000000,6,9,6,6,64.720000000,64.830000000,8,7,5,7,64.710000000,64.840000000,8,9,7,8,64.700000000,64.850000000,7,8,6,5,64.690000000,64.860000000,4,4,3,3,64.680000000,64.870000000,4,4,2,3,MCLN5
2025-06-11T00:00:20.796785175Z,2025-06-11T00:00:20.788586769Z,10,1,42026514,C,A,2,64.800000000,1,130,14757,79320287,64.770000000,64.780000000,5,1,4,1,64.760000000,64.790000000,8,6,8,4,64.750000000,64.800000000,6,5,6,5,64.740000000,64.810000000,11,3,10,3,64.730000000,64.820000000,6,9,6,6,64.720000000,64.830000000,8,7,5,7,64.710000000,64.840000000,8,9,7,8,64.700000000,64.850000000,7,8,6,5,64.690000000,64.860000000,4,4,3,3,64.680000000,64.870000000,4,4,2,3,MCLN5
2025-06-11T00:00:20.796973409Z,2025-06-11T00:00:20.788820171Z,10,1,42026514,A,B,0,64.770000000,1,130,13912,79320301,64.770000000,64.780000000,6,1,5,1,64.760000000,64.790000000,8,6,8,4,64.750000000,64.800000000,6,5,6,5,64.740000000,64.810000000,11,3,10,3,64.730000000,64.820000000,6,9,6,6,64.720000000,64.830000000,8,7,5,7,64.710000000,64.840000000,8,9,7,8,64.700000000,64.850000000,7,8,6,5,64.690000000,64.860000000,4,4,3,3,64.680000000,64.870000000,4,4,2,3,MCLN5
2025-06-11T00:00:20.797331094Z,2025-06-11T00:00:20.790262029Z,10,1,42026514,C,B,0,64.770000000,1,130,12029,79320329,64.770000000,64.780000000,5,1,4,1,64.760000000,64.790000000,8,6,8,4,64.750000000,64.800000000,6,5,6,5,64.740000000,64.810000000,11,3,10,3,64.730000000,64.820000000,6,9,6,6,64.720000000,64.830000000,8,7,5,7,64.710000000,64.840000000,8,9,7,8,64.700000000,64.850000000,7,8,6,5,64.690000000,64.860000000,4,4,3,3,64.680000000,64.870000000,4,4,2,3,MCLN5
2025-06-11T00:00:20.797423734Z,2025-06-11T00:00:20.790332951Z,10,1,42026514,A,A,2,64.800000000,1,130,11386,79320334,64.770000000,64.780000000,5,1,4,1,64.760000000,64.790000000,8,6,8,4,64.750000000,64.800000000,6,6,6,6,64.740000000,64.810000000,11,3,10,3,64.730000000,64.820000000,6,9,6,6,64.720000000,64.830000000,8,7,5,7,64.710000000,64.840000000,8,9,7,8,64.700000000,64.850000000,7,8,6,5,64.690000000,64.860000000,4,4,3,3,64.680000000,64.870000000,4,4,2,3,MCLN5
2025-06-11T00:00:20.797979667Z,2025-06-11T00:00:20.790448761Z,10,1,42026514,A,A,0,64.780000000,1,130,10923,79320357,64.770000000,64.780000000,5,2,4,2,64.760000000,64.790000000,8,6,8,4,64.750000000,64.800000000,6,6,6,6,64.740000000,64.810000000,11,3,10,3,64.730000000,64.820000000,6,9,6,6,64.720000000,64.830000000,8,7,5,7,64.710000000,64.840000000,8,9,7,8,64.700000000,64.850000000,7,8,6,5,64.690000000,64.860000000,4,4,3,3,64.680000000,64.870000000,4,4,2,3,MCLN5
2025-06-11T00:00:20.798167840Z,2025-06-11T00:00:20.790517607Z,10,1,42026514,M,A,2,64.800000000,1,130,11440,79320368,64.770000000,64.780000000,5,2,4,2,64.760000000,64.790000000,8,6,8,4,64.750000000,64.800000000,6,7,6,7,64.740000000,64.810000000,11,3,10,3,64.730000000,64.820000000,6,9,6,6,64.720000000,64.830000000,8,7,5,7,64.710000000,64.840000000,8,9,7,8,64.700000000,64.850000000,7,8,6,5,64.690000000,64.860000000,4,4,3,3,64.680000000,64.870000000,4,4,2,3,MCLN5
2025-06-11T00:00:20.798311057Z,2025-06-11T00:00:20.790598781Z,10,1,42026514,A,A,0,64.780000000,1,130,13522,79320377,64.770000000,64.780000000,5,3,4,3,64.760000000,64.790000000,8,6,8,4,64.750000000,64.800000000,6,7,6,7,64.740000000,64.810000000,11,3,10,3,64.730000000,64.820000000,6,9,6,6,64.720000000,64.830000000,8,7,5,7,64.710000000,64.840000000,8,9,7,8,64.700000000,64.850000000,7,8,6,5,64.690000000,64.860000000,4,4,3,3,64.680000000,64.870000000,4,4,2,3,MCLN5
2025-06-11T00:00:20.798523013Z,2025-06-11T00:00:20.790778907Z,10,1,42026514,M,A,3,64.810000000,1,130,11764,79320392,64.770000000,64.780000000,5,3,4,3,64.760000000,64.790000000,8,6,8,4,64.750000000,64.800000000,6,7,6,7,64.740000000,64.810000000,11,4,10,4,64.730000000,64.820000000,6,9,6,6,64.720000000,64.830000000,8,7,5,7,64.710000000,64.840000000,8,9,7,8,64.700000000,64.850000000,7,8,6,5,64.690000000,64.860000000,4,4,3,3,64.680000000,64.870000000,4,4,2,3,MCLN5
2025-06-11T00:00:20.799254464Z,2025-06-11T00:00:20.791591167Z,10,1,42026514,C,A,0,64.780000000,1,130,13956,79320446,64.770000000,64.780000000,5,2,4,2,64.760000000,64.790000000,8,6,8,4,64.750000000,64.800000000,6,7,6,7,64.740000000,64.810000000,11,4,10,4,64.730000000,64.820000000,6,9,6,6,64.720000000,64.830000000,8,7,5,7,64.710000000,64.840000000,8,9,7,8,64.700000000,64.850000000,7,8,6,5,64.690000000,64.860000000,4,4,3,3,64.680000000,64.870000000,4,4,2,3,MCLN5
2025-06-11T00:00:20.800008870Z,2025-06-11T00:00:20.792341585Z,10,1,42026514,A,A,0,64.780000000,1,130,13745,79320498,64.770000000,64.780000000,5,3,4,3,64.760000000,64.790000000,8,6,8,4,64.750000000,64.800000000,6,7,6,7,64.740000000,64.810000000,11,4,10,4,64.730000000,64.820000000,6,9,6,6,64.720000000,64.830000000,8,7,5,7,64.710000000,64.840000000,8,9,7,8,64.700000000,64.850000000,7,8,6,5,64.690000000,64.860000000,4,4,3,3,64.680000000,64.870000000,4,4,2,3,MCLN5
2025-06-11T00:00:20.800197657Z,2025-06-11T00:00:20.792483909Z,10,1,42026514,C,A,0,64.780000000,1,130,13473,79320510,64.770000000,64.780000000,5,2,4,2,64.760000000,64.790000000,8,6,8,4,64.750000000,64.800000000,6,7,6,7,64.740000000,64.810000000,11,4,10,4,64.730000000,64.820000000,6,9,6,6,64.720000000,64.830000000,8,7,5,7,64.710000000,64.840000000,8,9,7,8,64.700000000,64.850000000,7,8,6,5,64.690000000,64.860000000,4,4,3,3,64.680000000,64.870000000,4,4,2,3,MCLN5
2025-06-11T00:00:20.800245071Z,2025-06-11T00:00:20.792657065Z,10,1,42026514,C,A,0,64.780000000,1,130,15112,79320513,64.770000000,64.780000000,5,1,4,1,64.760000000,64.790000000,8,6,8,4,64.750000000,64.800000000,6,7,6,7,64.740000000,64.810000000,11,4,10,4,64.730000000,64.820000000,6,9,6,6,64.720000000,64.830000000,8,7,5,7,64.710000000,64.840000000,8,9,7,8,64.700000000,64.850000000,7,8,6,5,64.690000000,64.860000000,4,4,3,3,64.680000000,64.870000000,4,4,2,3,MCLN5
2025-06-11T00:00:20.800668954Z,2025-06-11T00:00:20.793072861Z,10,1,42025623,C,B,0,63.690000000,1,130,18188,79320540,63.680000000,63.710000000,2,2,2,2,63.670000000,63.720000000,3,2,3,2,63.660000000,63.730000000,3,2,3,2,63.650000000,63.740000000,5,3,5,3,63.640000000,63.750000000,4,2,4,2,63.630000000,63.760000000,5,6,5,6,63.620000000,63.770000000,3,2,3,2,63.610000000,63.780000000,2,3,2,3,63.600000000,63.790000000,7,1,7,1,63.590000000,63.800000000,1,3,1,3,MCLQ5
2025-06-11T00:00:20.800721643Z,2025-06-11T00:00:20.793112489Z,10,1,42026514,T,B,0,64.780000000,1,0,12167,79320546,64.770000000,64.780000000,5,1,4,1,64.760000000,64.790000000,8,6,8,4,64.750000000,64.800000000,6,7,6,7,64.740000000,64.810000000,11,4,10,4,64.730000000,64.820000000,6,9,6,6,64.720000000,64.830000000,8,7,5,7,64.710000000,64.840000000,8,9,7,8,64.700000000,64.850000000,7,8,6,5,64.690000000,64.860000000,4,4,3,3,64.680000000,64.870000000,4,4,2,3,MCLN5
2025-06-11T00:00:20.800740312Z,2025-06-11T00:00:20.793112489Z,10,1,42026514,C,A,0,64.780000000,1,130,11453,79320547,64.770000000,64.790000000,5,6,4,4,64.760000000,64.800000000,8,7,8,7,64.750000000,64.810000000,6,4,6,4,64.740000000,64.820000000,11,9,10,6,64.730000000,64.830000000,6,7,6,7,64.720000000,64.840000000,8,9,5,8,64.710000000,64.850000000,8,8,7,5,64.700000000,64.860000000,7,4,6,3,64.690000000,64.870000000,4,4,3,3,64.680000000,64.880000000,4,4,2,3,MCLN5
2025-06-11T00:00:20.801088382Z,2025-06-11T00:00:20.794032493Z,10,1,42022708,M,A,0,2.830000000,10,130,11588,79320571,2.810000000,2.830000000,1,12,1,3,2.800000000,2.840000000,12,2,3,2,2.790000000,2.850000000,2,1,2,1,2.780000000,2.870000000,1,1,1,1,,,0,0,0,0,,,0,0,0,0,,,0,0,0,0,,,0,0,0,0,,,0,0,0,0,,,0,0,0,0,MCLN5-MCLV5
2025-06-11T00:00:20.802895507Z,2025-06-11T00:00:20.796106519Z,10,1,42026514,A,B,0,64.770000000,1,130,15560,79320677,64.770000000,64.790000000,6,6,5,4,64.760000000,64.800000000,8,7,8,7,64.750000000,64.810000000,6,4,6,4,64.740000000,64.820000000,11,9,10,6,64.730000000,64.830000000,6,7,6,7,64.720000000,64.840000000,8,9,5,8,64.710000000,64.850000000,8,8,7,5,64.700000000,64.860000000,7,4,6,3,64.690000000,64.870000000,4,4,3,3,64.680000000,64.880000000,4,4,2,3,MCLN5
2025-06-11T00:00:20.803277966Z,2025-06-11T00:00:20.796627085Z,10,1,42418117,M,A,0,3.290000000,10,130,11428,79320704,3.250000000,3.280000000,1,1,1,1,3.240000000,3.290000000,11,11,2,2,3.230000000,3.300000000,1,1,1,1,,,0,0,0,0,,,0,0,0,0,,,0,0,0,0,,,0,0,0,0,,,0,0,0,0,,,0,0,0,0,,,0,0,0,0,MCLN5-MCLX5
2025-06-11T00:00:20.803349793Z,2025-06-11T00:00:20.796815525Z,10,1,42026514,A,A,0,64.780000000,1,130,11653,79320708,64.770000000,64.780000000,6,1,5,1,64.760000000,64.790000000,8,6,8,4,64.750000000,64.800000000,6,7,6,7,64.740000000,64.810000000,11,4,10,4,64.730000000,64.820000000,6,9,6,6,64.720000000,64.830000000,8,7,5,7,64.710000000,64.840000000,8,9,7,8,64.700000000,64.850000000,7,8,6,5,64.690000000,64.860000000,4,4,3,3,64.680000000,64.870000000,4,4,2,3,MCLN5
2025-06-11T00:00:20.804109098Z,2025-06-11T00:00:20.797318601Z,10,1,42026514,C,B,0,64.770000000,1,130,17192,79320759,64.770000000,64.780000000,5,1,4,1,64.760000000,64.790000000,8,6,8,4,64.750000000,64.800000000,6,7,6,7,64.740000000,64.810000000,11,4,10,4,64.730000000,64.820000000,6,9,6,6,64.720000000,64.830000000,8,7,5,7,64.710000000,64.840000000,8,9,7,8,64.700000000,64.850000000,7,8,6,5,64.690000000,64.860000000,4,4,3,3,64.680000000,64.870000000,4,4,2,3,MCLN5
2025-06-11T00:00:20.804260194Z,2025-06-11T00:00:20.797541061Z,10,1,42026514,M,A,2,64.800000000,1,130,11896,79320769,64.770000000,64.780000000,5,1,4,1,64.760000000,64.790000000,8,6,8,4,64.750000000,64.800000000,6,8,6,8,64.740000000,64.810000000,11,4,10,4,64.730000000,64.820000000,6,9,6,6,64.720000000,64.830000000,8,7,5,7,64.710000000,64.840000000,8,9,7,8,64.700000000,64.850000000,7,8,6,5,64.690000000,64.860000000,4,4,3,3,64.680000000,64.870000000,4,4,2,3,MCLN5
2025-06-11T00:00:20.805489751Z,2025-06-11T00:00:20.798920461Z,10,1,42026514,A,A,0,64.780000000,1,130,15511,79320846,64.770000000,64.780000000,5,2,4,2,64.760000000,64.790000000,8,6,8,4,64.750000000,64.800000000,6,8,6,8,64.740000000,64.810000000,11,4,10,4,64.730000000,64.820000000,6,9,6,6,64.720000000,64.830000000,8,7,5,7,64.710000000,64.840000000,8,9,7,8,64.700000000,64.850000000,7,8,6,5,64.690000000,64.860000000,4,4,3,3,64.680000000,64.870000000,4,4,2,3,MCLN5
2025-06-11T00:00:20.805506370Z,2025-06-11T00:00:20.798924089Z,10,1,42026514,C,B,0,64.770000000,2,130,12579,79320847,64.770000000,64.780000000,3,2,3,2,64.760000000,64.790000000,8,6,8,4,64.750000000,64.800000000,6,8,6,8,64.740000000,64.810000000,11,4,10,4,64.730000000,64.820000000,6,9,6,6,64.720000000,64.830000000,8,7,5,7,64.710000000,64.840000000,8,9,7,8,64.700000000,64.850000000,7,8,6,5,64.690000000,64.860000000,4,4,3,3,64.680000000,64.870000000,4,4,2,3,MCLN5
2025-06-11T00:00:20.805672356Z,2025-06-11T00:00:20.799100051Z,10,1,42026514,C,A,0,64.780000000,1,130,11479,79320854,64.770000000,64.780000000,3,1,3,1,64.760000000,64.790000000,8,6,8,4,64.750000000,64.800000000,6,8,6,8,64.740000000,64.810000000,11,4,10,4,64.730000000,64.820000000,6,9,6,6,64.720000000,64.830000000,8,7,5,7,64.710000000,64.840000000,8,9,7,8,64.700000000,64.850000000,7,8,6,5,64.690000000,64.860000000,4,4,3,3,64.680000000,64.870000000,4,4,2,3,MCLN5
2025-06-11T00:00:20.806767106Z,2025-06-11T00:00:20.800285485Z,10,1,42026514,A,B,0,64.770000000,2,130,17578,79320922,64.770000000,64.780000000,5,1,4,1,64.760000000,64.790000000,8,6,8,4,64.750000000,64.800000000,6,8,6,8,64.740000000,64.810000000,11,4,10,4,64.730000000,64.820000000,6,9,6,6,64.720000000,64.830000000,8,7,5,7,64.710000000,64.840000000,8,9,7,8,64.700000000,64.850000000,7,8,6,5,64.690000000,64.860000000,4,4,3,3,64.680000000,64.870000000,4,4,2,3,MCLN5
