ts_recv,ts_event,rtype,publisher_id,instrument_id,action,side,depth,price,size,flags,ts_in_delta,sequence,bid_px_00,ask_px_00,bid_sz_00,ask_sz_00,bid_ct_00,ask_ct_00,bid_px_01,ask_px_01,bid_sz_01,ask_sz_01,bid_ct_01,ask_ct_01,bid_px_02,ask_px_02,bid_sz_02,ask_sz_02,bid_ct_02,ask_ct_02,bid_px_03,ask_px_03,bid_sz_03,ask_sz_03,bid_ct_03,ask_ct_03,bid_px_04,ask_px_04,bid_sz_04,ask_sz_04,bid_ct_04,ask_ct_04,bid_px_05,ask_px_05,bid_sz_05,ask_sz_05,bid_ct_05,ask_ct_05,bid_px_06,ask_px_06,bid_sz_06,ask_sz_06,bid_ct_06,ask_ct_06,bid_px_07,ask_px_07,bid_sz_07,ask_sz_07,bid_ct_07,ask_ct_07,bid_px_08,ask_px_08,bid_sz_08,ask_sz_08,bid_ct_08,ask_ct_08,bid_px_09,ask_px_09,bid_sz_09,ask_sz_09,bid_ct_09,ask_ct_09,symbol
2025-06-11T00:00:00.000000000Z,2025-06-10T23:52:40.065054761Z,10,1,42026412,A,N,0,61.700000000,1,168,0,79270849,61.000000000,61.700000000,1,1,1,1,60.700000000,62.200000000,8,9,1,1,60.360000000,89.000000000,2,1,1,1,60.350000000,,1,0,1,0,59.310000000,,1,0,1,0,59.000000000,,1,0,1,0,58.800000000,,1,0,1,0,58.000000000,,1,0,1,0,57.050000000,,1,0,1,0,57.000000000,,1,0,1,0,MCLX5
2025-06-11T00:00:00.000000000Z,2025-06-10T23:59:47.508458409Z,10,1,42175560,A,N,0,4.030000000,10,168,0,79277197,3.220000000,4.030000000,10,10,1,1,,,0,0,0,0,,,0,0,0,0,,,0,0,0,0,,,0,0,0,0,,,0,0,0,0,,,0,0,0,0,,,0,0,0,0,,,0,0,0,0,,,0,0,0,0,MCLN5-MCLZ5
2025-06-11T00:00:00.000000000Z,2025-06-10T23:59:06.049919041Z,10,1,42405621,A,N,0,3.790000000,10,168,0,79276599,3.000000000,3.790000000,10,10,1,1,,,0,0,0,0,,,0,0,0,0,,,0,0,0,0,,,0,0,0,0,,,0,0,0,0,,,0,0,0,0,,,0,0,0,0,,,0,0,0,0,,,0,0,0,0,MCLN5-MCLK6
2025-06-11T00:00:00.000000000Z,2025-06-10T23:59:56.185568279Z,10,1,42026514,A,N,0,64.830000000,1,168,0,79277611,64.790000000,64.800000000,6,8,2,5,64.780000000,64.810000000,5,3,5,3,64.770000000,64.820000000,9,9,5,6,64.760000000,64.830000000,8,10,8,10,64.750000000,64.840000000,9,6,9,5,64.740000000,64.850000000,10,8,9,5,64.730000000,64.860000000,5,5,5,4,64.720000000,64.870000000,8,4,5,3,64.710000000,64.880000000,8,4,7,3,64.700000000,64.890000000,7,3,6,2,MCLN5
2025-06-11T00:00:00.000000000Z,2025-06-10T23:49:45.751977669Z,10,1,42026513,A,N,0,62.400000000,1,168,0,79265548,62.600000000,62.830000000,1,1,1,1,62.510000000,63.170000000,1,1,1,1,62.500000000,63.310000000,2,1,2,1,62.400000000,63.500000000,1,2,1,2,62.310000000,63.540000000,1,1,1,1,62.210000000,63.790000000,1,1,1,1,62.080000000,64.000000000,1,2,1,2,62.050000000,64.280000000,1,1,1,1,62.040000000,64.500000000,1,3,1,3,62.030000000,64.550000000,2,1,2,1,MCLU5
2025-06-11T00:00:00.000000000Z,2025-06-10T23:18:40.705384631Z,10,1,42026512,A,N,0,61.580000000,1,168,0,79175419,60.100000000,61.580000000,1,1,1,1,60.000000000,63.000000000,1,2,1,2,59.800000000,63.750000000,2,1,1,1,59.750000000,64.000000000,1,1,1,1,59.700000000,64.700000000,1,1,1,1,59.500000000,65.000000000,1,1,1,1,59.400000000,66.000000000,1,2,1,1,59.000000000,66.590000000,6,6,4,6,58.850000000,66.640000000,2,2,1,1,58.800000000,67.000000000,1,2,1,1,MCLZ5
2025-06-11T00:00:00.000000000Z,2025-06-08T20:04:25.625079513Z,10,1,42000225,A,N,0,55.000000000,1,168,0,114308,55.000000000,,1,0,1,0,,,0,0,0,0,,,0,0,0,0,,,0,0,0,0,,,0,0,0,0,,,0,0,0,0,,,0,0,0,0,,,0,0,0,0,,,0,0,0,0,,,0,0,0,0,MCLZ7
2025-06-11T00:00:00.000000000Z,2025-06-08T20:04:25.625079513Z,10,1,42025624,A,N,0,53.660000000,2,168,0,114301,58.080000000,,1,0,1,0,53.660000000,,2,0,1,0,,,0,0,0,0,,,0,0,0,0,,,0,0,0,0,,,0,0,0,0,,,0,0,0,0,,,0,0,0,0,,,0,0,0,0,,,0,0,0,0,MCLU6
2025-06-11T00:00:00.000000000Z,2025-06-10T23:59:55.590356549Z,10,1,42025623,A,N,0,62.500000000,1,168,0,79277610,63.700000000,63.720000000,2,2,2,2,63.690000000,63.730000000,3,2,3,2,63.680000000,63.740000000,1,3,1,3,63.670000000,63.750000000,3,2,3,2,63.660000000,63.760000000,5,6,5,6,63.650000000,63.770000000,4,1,4,1,63.640000000,63.780000000,5,5,5,5,63.630000000,63.790000000,4,1,4,1,63.620000000,63.800000000,3,3,3,3,63.610000000,63.810000000,2,4,2,2,MCLQ5
2025-06-11T00:00:00.000000000Z,2025-06-10T17:20:11.604183789Z,10,1,42026453,A,N,0,59.000000000,1,168,0,70390632,59.000000000,63.490000000,1,1,1,1,56.940000000,64.940000000,1,1,1,1,56.490000000,,1,0,1,0,55.940000000,,1,0,1,0,,,0,0,0,0,,,0,0,0,0,,,0,0,0,0,,,0,0,0,0,,,0,0,0,0,,,0,0,0,0,MCLZ6
2025-06-11T00:00:00.000000000Z,2025-06-09T19:43:44.055500243Z,10,1,42026516,A,N,0,58.310000000,1,168,0,35081403,58.310000000,,1,0,1,0,57.570000000,,2,0,1,0,,,0,0,0,0,,,0,0,0,0,,,0,0,0,0,,,0,0,0,0,,,0,0,0,0,,,0,0,0,0,,,0,0,0,0,,,0,0,0,0,MCLG6
2025-06-11T00:00:00.000000000Z,2025-06-08T20:04:25.625079513Z,10,1,42026451,A,N,0,48.000000000,1,168,0,114250,55.550000000,,1,0,1,0,52.000000000,,1,0,1,0,48.000000000,,1,0,1,0,,,0,0,0,0,,,0,0,0,0,,,0,0,0,0,,,0,0,0,0,,,0,0,0,0,,,0,0,0,0,,,0,0,0,0,MCLH6
2025-06-11T00:00:00.000000000Z,2025-06-08T20:04:25.625079513Z,10,1,42026450,A,N,0,53.530000000,3,168,0,114250,56.560000000,,2,0,1,0,55.000000000,,2,0,1,0,54.540000000,,4,0,1,0,53.530000000,,3,0,1,0,,,0,0,0,0,,,0,0,0,0,,,0,0,0,0,,,0,0,0,0,,,0,0,0,0,,,0,0,0,0,MCLJ6
2025-06-11T00:00:00.000000000Z,2025-06-10T13:50:49.281479785Z,10,1,42024019,A,N,0,62.250000000,1,168,0,55219793,57.000000000,62.250000000,1,1,1,1,,,0,0,0,0,,,0,0,0,0,,,0,0,0,0,,,0,0,0,0,,,0,0,0,0,,,0,0,0,0,,,0,0,0,0,,,0,0,0,0,,,0,0,0,0,MCLF6
2025-06-11T00:00:00.000000000Z,2025-06-10T22:27:30.808863639Z,10,1,42026448,A,N,0,61.010000000,1,168,0,79010697,61.010000000,,1,0,1,0,50.000000000,,1,0,1,0,,,0,0,0,0,,,0,0,0,0,,,0,0,0,0,,,0,0,0,0,,,0,0,0,0,,,0,0,0,0,,,0,0,0,0,,,0,0,0,0,MCLM6
2025-06-11T00:00:00.000000000Z,2025-06-08T20:04:25.625079513Z,10,1,42002137,A,N,0,50.000000000,1,168,0,114309,50.000000000,,1,0,1,0,,,0,0,0,0,,,0,0,0,0,,,0,0,0,0,,,0,0,0,0,,,0,0,0,0,,,0,0,0,0,,,0,0,0,0,,,0,0,0,0,,,0,0,0,0,MCLZ8
2025-06-11T00:00:00.000000000Z,2025-06-08T20:04:25.625079513Z,10,1,42002712,A,N,0,75.500000000,1,168,0,114251,,75.500000000,0,1,0,1,,,0,0,0,0,,,0,0,0,0,,,0,0,0,0,,,0,0,0,0,,,0,0,0,0,,,0,0,0,0,,,0,0,0,0,,,0,0,0,0,,,0,0,0,0,MCLM7
2025-06-11T00:00:00.000000000Z,2025-06-10T23:52:25.132298439Z,10,1,42025611,A,N,0,2.070000000,20,168,0,79270534,2.070000000,2.090000000,26,6,5,4,2.060000000,2.100000000,23,27,3,6,2.050000000,2.110000000,23,23,3,4,2.040000000,2.120000000,2,22,1,2,2.030000000,2.130000000,2,2,1,2,2.020000000,2.140000000,2,2,2,1,2.010000000,2.150000000,2,2,1,1,2.000000000,2.160000000,2,2,2,1,1.990000000,2.170000000,2,2,1,1,1.980000000,2.180000000,2,2,2,2,MCLN5-MCLU5
2025-06-11T00:00:00.000000000Z,2025-06-10T23:48:14.439939243Z,10,1,42186877,A,N,0,3.190000000,10,168,0,79262569,3.190000000,4.050000000,10,10,1,1,,,0,0,0,0,,,0,0,0,0,,,0,0,0,0,,,0,0,0,0,,,0,0,0,0,,,0,0,0,0,,,0,0,0,0,,,0,0,0,0,,,0,0,0,0,MCLN5-MCLH6
2025-06-11T00:00:00.000000000Z,2025-06-10T22:57:30.028437513Z,10,1,42024057,A,N,0,61.000000000,1,168,0,79083200,61.000000000,67.500000000,1,5,1,1,59.590000000,70.800000000,6,1,1,1,,,0,0,0,0,,,0,0,0,0,,,0,0,0,0,,,0,0,0,0,,,0,0,0,0,,,0,0,0,0,,,0,0,0,0,,,0,0,0,0,MCLK6
2025-06-11T00:00:00.000000000Z,2025-06-10T23:48:08.528653345Z,10,1,42463766,A,N,0,1.080000000,5,168,0,79260816,1.080000000,1.090000000,15,29,3,12,1.070000000,1.100000000,61,56,19,14,1.060000000,1.110000000,52,57,14,13,1.050000000,1.120000000,56,54,13,12,1.040000000,1.130000000,52,40,11,10,1.030000000,1.140000000,39,38,9,8,1.020000000,1.150000000,38,41,8,10,1.010000000,1.160000000,35,36,8,7,1.000000000,1.170000000,40,38,9,9,0.990000000,1.180000000,35,37,8,9,MCLN5-MCLQ5
2025-06-11T00:00:00.000000000Z,2025-06-10T21:55:00.842453655Z,10,1,42473994,A,N,0,0.200000000,4,168,0,78830516,,0.200000000,0,4,0,1,,,0,0,0,0,,,0,0,0,0,,,0,0,0,0,,,0,0,0,0,,,0,0,0,0,,,0,0,0,0,,,0,0,0,0,,,0,0,0,0,,,0,0,0,0,MCLJ6-MCLK6
2025-06-11T00:00:00.000000000Z,2025-06-08T20:04:25.625079513Z,10,1,42026750,A,N,0,57.120000000,1,168,0,114283,57.120000000,,1,0,1,0,,,0,0,0,0,,,0,0,0,0,,,0,0,0,0,,,0,0,0,0,,,0,0,0,0,,,0,0,0,0,,,0,0,0,0,,,0,0,0,0,,,0,0,0,0,MCLN6
2025-06-11T00:00:00.000000000Z,2025-06-10T23:48:25.284358361Z,10,1,42279938,A,N,0,3.390000000,10,168,0,79262902,3.390000000,3.890000000,10,10,1,1,,,0,0,0,0,,,0,0,0,0,,,0,0,0,0,,,0,0,0,0,,,0,0,0,0,,,0,0,0,0,,,0,0,0,0,,,0,0,0,0,,,0,0,0,0,MCLN5-MCLG6
2025-06-11T00:00:00.000000000Z,2025-06-10T23:44:19.414596105Z,10,1,42284507,A,N,0,0.990000000,2,168,0,79247788,0.990000000,1.010000000,22,18,6,8,0.980000000,1.020000000,19,18,6,5,0.970000000,1.030000000,21,23,6,7,0.960000000,1.040000000,17,15,6,4,0.950000000,1.050000000,10,8,6,4,0.940000000,1.060000000,4,4,3,2,0.930000000,1.070000000,3,2,2,1,0.920000000,1.080000000,3,2,2,1,0.910000000,1.090000000,3,4,2,2,0.900000000,1.100000000,2,2,1,1,MCLQ5-MCLU5
2025-06-11T00:00:00.000000000Z,2025-06-10T23:57:50.271732561Z,10,1,42175405,A,N,0,4.120000000,10,168,0,79275924,3.050000000,4.120000000,10,10,1,1,,,0,0,0,0,,,0,0,0,0,,,0,0,0,0,,,0,0,0,0,,,0,0,0,0,,,0,0,0,0,,,0,0,0,0,,,0,0,0,0,,,0,0,0,0,MCLN5-MCLJ6
2025-06-11T00:00:00.000000000Z,2025-06-10T23:59:53.596736745Z,10,1,42545016,A,N,0,3.090000000,10,168,0,79277222,3.090000000,4.140000000,10,10,1,1,,,0,0,0,0,,,0,0,0,0,,,0,0,0,0,,,0,0,0,0,,,0,0,0,0,,,0,0,0,0,,,0,0,0,0,,,0,0,0,0,,,0,0,0,0,MCLN5-MCLF6
2025-06-11T00:00:00.000000000Z,2025-06-10T23:29:57.293799239Z,10,1,42064377,A,N,0,0.800000000,2,168,0,79213019,0.730000000,0.750000000,21,13,5,4,0.720000000,0.760000000,15,15,4,4,0.710000000,0.770000000,16,16,4,4,0.700000000,0.780000000,12,12,3,3,0.690000000,0.790000000,6,5,3,3,0.680000000,0.800000000,6,6,4,4,0.670000000,0.810000000,2,2,2,1,0.660000000,0.820000000,2,1,1,1,0.600000000,0.830000000,10,1,1,1,0.560000000,0.840000000,10,1,1,1,MCLU5-MCLV5
2025-06-11T00:00:00.000000000Z,2025-06-10T23:59:38.061413877Z,10,1,42418117,A,N,0,3.290000000,10,168,0,79277055,3.260000000,3.280000000,1,1,1,1,3.250000000,3.290000000,11,11,2,2,3.240000000,3.300000000,1,1,1,1,,,0,0,0,0,,,0,0,0,0,,,0,0,0,0,,,0,0,0,0,,,0,0,0,0,,,0,0,0,0,,,0,0,0,0,MCLN5-MCLX5
2025-06-11T00:00:00.000000000Z,2025-06-10T23:59:43.795274733Z,10,1,42022708,A,N,0,2.810000000,10,168,0,79277174,2.810000000,2.830000000,12,1,3,1,2.800000000,2.840000000,2,12,2,3,2.790000000,2.850000000,2,1,2,1,,2.870000000,0,1,0,1,,,0,0,0,0,,,0,0,0,0,,,0,0,0,0,,,0,0,0,0,,,0,0,0,0,,,0,0,0,0,MCLN5-MCLV5
2025-06-11T00:00:00.000000000Z,2025-06-10T23:59:19.147507219Z,10,1,42023923,A,N,0,59.900000000,1,168,0,79276633,61.510000000,63.000000000,1,1,1,1,61.500000000,63.080000000,2,1,2,1,61.460000000,63.330000000,1,1,1,1,61.000000000,63.500000000,2,1,2,1,60.500000000,63.550000000,1,1,1,1,60.250000000,63.660000000,1,1,1,1,60.000000000,64.000000000,3,1,3,1,59.900000000,64.800000000,1,1,1,1,59.500000000,65.000000000,1,1,1,1,59.000000000,66.750000000,2,1,2,1,MCLV5
2025-06-11T00:00:00.025381190Z,2025-06-11T00:00:00.024536663Z,10,1,42418117,M,B,0,3.230000000,1,130,12211,79278062,3.250000000,3.280000000,11,1,2,1,3.240000000,3.290000000,1,11,1,2,3.230000000,3.300000000,1,1,1,1,,,0,0,0,0,,,0,0,0,0,,,0,0,0,0,,,0,0,0,0,,,0,0,0,0,,,0,0,0,0,,,0,0,0,0,MCLN5-MCLX5
2025-06-11T00:00:00.025662178Z,2025-06-11T00:00:00.025389701Z,10,1,42418117,M,B,0,2.750000000,10,130,11720,79278085,3.250000000,3.280000000,1,1,1,1,3.240000000,3.290000000,1,11,1,2,3.230000000,3.300000000,1,1,1,1,2.750000000,,10,0,1,0,,,0,0,0,0,,,0,0,0,0,,,0,0,0,0,,,0,0,0,0,,,0,0,0,0,,,0,0,0,0,MCLN5-MCLX5
2025-06-11T00:00:00.030833918Z,2025-06-11T00:00:00.028704199Z,10,1,42026514,A,B,0,64.790000000,2,130,13251,79278097,64.790000000,64.800000000,8,8,3,5,64.780000000,64.810000000,5,3,5,3,64.770000000,64.820000000,9,9,5,6,64.760000000,64.830000000,8,10,8,10,64.750000000,64.840000000,9,6,9,5,64.740000000,64.850000000,10,8,9,5,64.730000000,64.860000000,5,5,5,4,64.720000000,64.870000000,8,4,5,3,64.710000000,64.880000000,8,4,7,3,64.700000000,64.890000000,7,3,6,2,MCLN5
2025-06-11T00:00:00.031246803Z,2025-06-11T00:00:00.030848729Z,10,1,42025623,M,A,4,63.770000000,1,130,11397,79278120,63.700000000,63.720000000,2,2,2,2,63.690000000,63.730000000,3,2,3,2,63.680000000,63.740000000,1,3,1,3,63.670000000,63.750000000,3,2,3,2,63.660000000,63.760000000,5,5,5,5,63.650000000,63.770000000,4,2,4,2,63.640000000,63.780000000,5,5,5,5,63.630000000,63.790000000,4,1,4,1,63.620000000,63.800000000,3,3,3,3,63.610000000,63.810000000,2,4,2,2,MCLQ5
2025-06-11T00:00:00.031259920Z,2025-06-11T00:00:00.030849247Z,10,1,42025623,M,B,4,63.660000000,1,130,11936,79278121,63.700000000,63.720000000,2,2,2,2,63.690000000,63.730000000,3,2,3,2,63.680000000,63.740000000,1,3,1,3,63.670000000,63.750000000,3,2,3,2,63.660000000,63.760000000,6,5,6,5,63.650000000,63.770000000,3,2,3,2,63.640000000,63.780000000,5,5,5,5,63.630000000,63.790000000,4,1,4,1,63.620000000,63.800000000,3,3,3,3,63.610000000,63.810000000,2,4,2,2,MCLQ5
2025-06-11T00:00:00.031270656Z,2025-06-11T00:00:00.030850437Z,10,1,42026514,M,A,3,64.840000000,1,130,11576,79278122,64.790000000,64.800000000,8,8,3,5,64.780000000,64.810000000,5,3,5,3,64.770000000,64.820000000,9,9,5,6,64.760000000,64.830000000,8,9,8,9,64.750000000,64.840000000,9,7,9,6,64.740000000,64.850000000,10,8,9,5,64.730000000,64.860000000,5,5,5,4,64.720000000,64.870000000,8,4,5,3,64.710000000,64.880000000,8,4,7,3,64.700000000,64.890000000,7,3,6,2,MCLN5
2025-06-11T00:00:00.031280732Z,2025-06-11T00:00:00.030850975Z,10,1,42026514,M,B,3,64.760000000,1,130,11538,79278123,64.790000000,64.800000000,8,8,3,5,64.780000000,64.810000000,5,3,5,3,64.770000000,64.820000000,9,9,5,6,64.760000000,64.830000000,9,9,9,9,64.750000000,64.840000000,8,7,8,6,64.740000000,64.850000000,10,8,9,5,64.730000000,64.860000000,5,5,5,4,64.720000000,64.870000000,8,4,5,3,64.710000000,64.880000000,8,4,7,3,64.700000000,64.890000000,7,3,6,2,MCLN5
2025-06-11T00:00:00.031295016Z,2025-06-11T00:00:00.030851417Z,10,1,42026514,M,A,3,64.840000000,1,130,15325,79278124,64.790000000,64.800000000,8,8,3,5,64.780000000,64.810000000,5,3,5,3,64.770000000,64.820000000,9,9,5,6,64.760000000,64.830000000,9,8,9,8,64.750000000,64.840000000,8,8,8,7,64.740000000,64.850000000,10,8,9,5,64.730000000,64.860000000,5,5,5,4,64.720000000,64.870000000,8,4,5,3,64.710000000,64.880000000,8,4,7,3,64.700000000,64.890000000,7,3,6,2,MCLN5
2025-06-11T00:00:00.031304462Z,2025-06-11T00:00:00.030851897Z,10,1,42026514,M,B,3,64.760000000,1,130,11361,79278125,64.790000000,64.800000000,8,8,3,5,64.780000000,64.810000000,5,3,5,3,64.770000000,64.820000000,9,9,5,6,64.760000000,64.830000000,10,8,10,8,64.750000000,64.840000000,7,8,7,7,64.740000000,64.850000000,10,8,9,5,64.730000000,64.860000000,5,5,5,4,64.720000000,64.870000000,8,4,5,3,64.710000000,64.880000000,8,4,7,3,64.700000000,64.890000000,7,3,6,2,MCLN5
2025-06-11T00:00:00.050636646Z,2025-06-11T00:00:00.045773265Z,10,1,42025623,A,A,0,63.720000000,1,130,15204,79278406,63.700000000,63.720000000,2,3,2,3,63.690000000,63.730000000,3,2,3,2,63.680000000,63.740000000,1,3,1,3,63.670000000,63.750000000,3,2,3,2,63.660000000,63.760000000,6,5,6,5,63.650000000,63.770000000,3,2,3,2,63.640000000,63.780000000,5,5,5,5,63.630000000,63.790000000,4,1,4,1,63.620000000,63.800000000,3,3,3,3,63.610000000,63.810000000,2,4,2,2,MCLQ5
2025-06-11T00:00:00.057954762Z,2025-06-11T00:00:00.057799211Z,10,1,42418117,M,B,0,3.250000000,10,130,11444,79278585,3.250000000,3.280000000,11,1,2,1,3.240000000,3.290000000,1,11,1,2,3.230000000,3.300000000,1,1,1,1,,,0,0,0,0,,,0,0,0,0,,,0,0,0,0,,,0,0,0,0,,,0,0,0,0,,,0,0,0,0,,,0,0,0,0,MCLN5-MCLX5
2025-06-11T00:00:00.059368637Z,2025-06-11T00:00:00.058413373Z,10,1,42025623,M,B,4,63.650000000,1,130,11670,79278659,63.700000000,63.720000000,2,3,2,3,63.690000000,63.730000000,3,2,3,2,63.680000000,63.740000000,1,3,1,3,63.670000000,63.750000000,3,2,3,2,63.660000000,63.760000000,5,5,5,5,63.650000000,63.770000000,4,2,4,2,63.640000000,63.780000000,5,5,5,5,63.630000000,63.790000000,4,1,4,1,63.620000000,63.800000000,3,3,3,3,63.610000000,63.810000000,2,4,2,2,MCLQ5
2025-06-11T00:00:00.059380863Z,2025-06-11T00:00:00.058413871Z,10,1,42025623,M,A,4,63.760000000,1,130,14992,79278660,63.700000000,63.720000000,2,3,2,3,63.690000000,63.730000000,3,2,3,2,63.680000000,63.740000000,1,3,1,3,63.670000000,63.750000000,3,2,3,2,63.660000000,63.760000000,5,6,5,6,63.650000000,63.770000000,4,1,4,1,63.640000000,63.780000000,5,5,5,5,63.630000000,63.790000000,4,1,4,1,63.620000000,63.800000000,3,3,3,3,63.610000000,63.810000000,2,4,2,2,MCLQ5
2025-06-11T00:00:00.059707646Z,2025-06-11T00:00:00.058492837Z,10,1,42026514,C,A,0,64.800000000,1,130,14156,79278676,64.790000000,64.800000000,8,7,3,4,64.780000000,64.810000000,5,3,5,3,64.770000000,64.820000000,9,9,5,6,64.760000000,64.830000000,10,8,10,8,64.750000000,64.840000000,7,8,7,7,64.740000000,64.850000000,10,8,9,5,64.730000000,64.860000000,5,5,5,4,64.720000000,64.870000000,8,4,5,3,64.710000000,64.880000000,8,4,7,3,64.700000000,64.890000000,7,3,6,2,MCLN5
2025-06-11T00:00:00.059746006Z,2025-06-11T00:00:00.058495123Z,10,1,42025623,A,B,0,63.710000000,1,130,16648,79278678,63.710000000,63.720000000,1,3,1,3,63.700000000,63.730000000,2,2,2,2,63.690000000,63.740000000,3,3,3,3,63.680000000,63.750000000,1,2,1,2,63.670000000,63.760000000,3,6,3,6,63.660000000,63.770000000,5,1,5,1,63.650000000,63.780000000,4,5,4,5,63.640000000,63.790000000,5,1,5,1,63.630000000,63.800000000,4,3,4,3,63.620000000,63.810000000,3,4,3,2,MCLQ5
2025-06-11T00:00:00.060572406Z,2025-06-11T00:00:00.059757525Z,10,1,42025623,C,A,6,63.780000000,1,130,11787,79278731,63.710000000,63.720000000,1,3,1,3,63.700000000,63.730000000,2,2,2,2,63.690000000,63.740000000,3,3,3,3,63.680000000,63.750000000,1,2,1,2,63.670000000,63.760000000,3,6,3,6,63.660000000,63.770000000,5,1,5,1,63.650000000,63.780000000,4,4,4,4,63.640000000,63.790000000,5,1,5,1,63.630000000,63.800000000,4,3,4,3,63.620000000,63.810000000,3,4,3,2,MCLQ5
2025-06-11T00:00:00.060721152Z,2025-06-11T00:00:00.060054439Z,10,1,42026514,M,A,0,66.800000000,3,130,13235,79278740,64.790000000,64.800000000,8,6,3,3,64.780000000,64.810000000,5,3,5,3,64.770000000,64.820000000,9,9,5,6,64.760000000,64.830000000,10,8,10,8,64.750000000,64.840000000,7,8,7,7,64.740000000,64.850000000,10,8,9,5,64.730000000,64.860000000,5,5,5,4,64.720000000,64.870000000,8,4,5,3,64.710000000,64.880000000,8,4,7,3,64.700000000,64.890000000,7,3,6,2,MCLN5
2025-06-11T00:00:00.068153166Z,2025-06-11T00:00:00.067693319Z,10,1,42025623,M,A,4,63.770000000,1,130,11494,79278849,63.710000000,63.720000000,1,3,1,3,63.700000000,63.730000000,2,2,2,2,63.690000000,63.740000000,3,3,3,3,63.680000000,63.750000000,1,2,1,2,63.670000000,63.760000000,3,5,3,5,63.660000000,63.770000000,5,2,5,2,63.650000000,63.780000000,4,4,4,4,63.640000000,63.790000000,5,1,5,1,63.630000000,63.800000000,4,3,4,3,63.620000000,63.810000000,3,4,3,2,MCLQ5
2025-06-11T00:00:00.069225168Z,2025-06-11T00:00:00.068636823Z,10,1,42418117,M,A,1,3.300000000,10,130,13354,79278925,3.250000000,3.280000000,11,1,2,1,3.240000000,3.290000000,1,1,1,1,3.230000000,3.300000000,1,11,1,2,,,0,0,0,0,,,0,0,0,0,,,0,0,0,0,,,0,0,0,0,,,0,0,0,0,,,0,0,0,0,,,0,0,0,0,MCLN5-MCLX5
2025-06-11T00:00:00.071617716Z,2025-06-11T00:00:00.071520191Z,10,1,42025623,C,B,7,63.640000000,1,130,11492,79279067,63.710000000,63.720000000,1,3,1,3,63.700000000,63.730000000,2,2,2,2,63.690000000,63.740000000,3,3,3,3,63.680000000,63.750000000,1,2,1,2,63.670000000,63.760000000,3,5,3,5,63.660000000,63.770000000,5,2,5,2,63.650000000,63.780000000,4,4,4,4,63.640000000,63.790000000,4,1,4,1,63.630000000,63.800000000,4,3,4,3,63.620000000,63.810000000,3,4,3,2,MCLQ5
2025-06-11T00:00:00.071631562Z,2025-06-11T00:00:00.071523897Z,10,1,42025623,A,A,7,63.790000000,1,130,14682,79279068,63.710000000,63.720000000,1,3,1,3,63.700000000,63.730000000,2,2,2,2,63.690000000,63.740000000,3,3,3,3,63.680000000,63.750000000,1,2,1,2,63.670000000,63.760000000,3,5,3,5,63.660000000,63.770000000,5,2,5,2,63.650000000,63.780000000,4,4,4,4,63.640000000,63.790000000,4,2,4,2,63.630000000,63.800000000,4,3,4,3,63.620000000,63.810000000,3,4,3,2,MCLQ5
2025-06-11T00:00:00.071741465Z,2025-06-11T00:00:00.071642337Z,10,1,42025623,A,B,6,63.650000000,1,130,15149,79279069,63.710000000,63.720000000,1,3,1,3,63.700000000,63.730000000,2,2,2,2,63.690000000,63.740000000,3,3,3,3,63.680000000,63.750000000,1,2,1,2,63.670000000,63.760000000,3,5,3,5,63.660000000,63.770000000,5,2,5,2,63.650000000,63.780000000,5,4,5,4,63.640000000,63.790000000,4,2,4,2,63.630000000,63.800000000,4,3,4,3,63.620000000,63.810000000,3,4,3,2,MCLQ5
2025-06-11T00:00:00.089291875Z,2025-06-11T00:00:00.089008831Z,10,1,42025623,A,B,0,63.710000000,1,130,13371,79279146,63.710000000,63.720000000,2,3,2,3,63.700000000,63.730000000,2,2,2,2,63.690000000,63.740000000,3,3,3,3,63.680000000,63.750000000,1,2,1,2,63.670000000,63.760000000,3,5,3,5,63.660000000,63.770000000,5,2,5,2,63.650000000,63.780000000,5,4,5,4,63.640000000,63.790000000,4,2,4,2,63.630000000,63.800000000,4,3,4,3,63.620000000,63.810000000,3,4,3,2,MCLQ5
2025-06-11T00:00:00.089380873Z,2025-06-11T00:00:00.089010445Z,10,1,42026514,T,B,0,64.800000000,1,0,11983,79279148,64.790000000,64.800000000,8,6,3,3,64.780000000,64.810000000,5,3,5,3,64.770000000,64.820000000,9,9,5,6,64.760000000,64.830000000,10,8,10,8,64.750000000,64.840000000,7,8,7,7,64.740000000,64.850000000,10,8,9,5,64.730000000,64.860000000,5,5,5,4,64.720000000,64.870000000,8,4,5,3,64.710000000,64.880000000,8,4,7,3,64.700000000,64.890000000,7,3,6,2,MCLN5
2025-06-11T00:00:00.089380873Z,2025-06-11T00:00:00.089010445Z,10,1,42026514,M,A,0,64.800000000,3,130,11983,79279148,64.790000000,64.800000000,8,5,3,3,64.780000000,64.810000000,5,3,5,3,64.770000000,64.820000000,9,9,5,6,64.760000000,64.830000000,10,8,10,8,64.750000000,64.840000000,7,8,7,7,64.740000000,64.850000000,10,8,9,5,64.730000000,64.860000000,5,5,5,4,64.720000000,64.870000000,8,4,5,3,64.710000000,64.880000000,8,4,7,3,64.700000000,64.890000000,7,3,6,2,MCLN5
2025-06-11T00:00:00.089449122Z,2025-06-11T00:00:00.089015129Z,10,1,42026514,T,B,0,64.800000000,1,0,11708,79279152,64.790000000,64.800000000,8,5,3,3,64.780000000,64.810000000,5,3,5,3,64.770000000,64.820000000,9,9,5,6,64.760000000,64.830000000,10,8,10,8,64.750000000,64.840000000,7,8,7,7,64.740000000,64.850000000,10,8,9,5,64.730000000,64.860000000,5,5,5,4,64.720000000,64.870000000,8,4,5,3,64.710000000,64.880000000,8,4,7,3,64.700000000,64.890000000,7,3,6,2,MCLN5
2025-06-11T00:00:00.089460557Z,2025-06-11T00:00:00.089015129Z,10,1,42026514,M,A,0,64.800000000,2,130,13563,79279153,64.790000000,64.800000000,8,4,3,3,64.780000000,64.810000000,5,3,5,3,64.770000000,64.820000000,9,9,5,6,64.760000000,64.830000000,10,8,10,8,64.750000000,64.840000000,7,8,7,7,64.740000000,64.850000000,10,8,9,5,64.730000000,64.860000000,5,5,5,4,64.720000000,64.870000000,8,4,5,3,64.710000000,64.880000000,8,4,7,3,64.700000000,64.890000000,7,3,6,2,MCLN5
2025-06-11T00:00:00.089567710Z,2025-06-11T00:00:00.089023367Z,10,1,42026514,A,B,0,64.790000000,1,130,13614,79279159,64.790000000,64.800000000,9,4,4,3,64.780000000,64.810000000,5,3,5,3,64.770000000,64.820000000,9,9,5,6,64.760000000,64.830000000,10,8,10,8,64.750000000,64.840000000,7,8,7,7,64.740000000,64.850000000,10,8,9,5,64.730000000,64.860000000,5,5,5,4,64.720000000,64.870000000,8,4,5,3,64.710000000,64.880000000,8,4,7,3,64.700000000,64.890000000,7,3,6,2,MCLN5
2025-06-11T00:00:00.089604173Z,2025-06-11T00:00:00.089031737Z,10,1,42026514,T,B,0,64.800000000,1,0,11609,79279162,64.790000000,64.800000000,9,4,4,3,64.780000000,64.810000000,5,3,5,3,64.770000000,64.820000000,9,9,5,6,64.760000000,64.830000000,10,8,10,8,64.750000000,64.840000000,7,8,7,7,64.740000000,64.850000000,10,8,9,5,64.730000000,64.860000000,5,5,5,4,64.720000000,64.870000000,8,4,5,3,64.710000000,64.880000000,8,4,7,3,64.700000000,64.890000000,7,3,6,2,MCLN5
2025-06-11T00:00:00.089604173Z,2025-06-11T00:00:00.089031737Z,10,1,42026514,M,A,0,64.800000000,1,130,11609,79279162,64.790000000,64.800000000,9,3,4,3,64.780000000,64.810000000,5,3,5,3,64.770000000,64.820000000,9,9,5,6,64.760000000,64.830000000,10,8,10,8,64.750000000,64.840000000,7,8,7,7,64.740000000,64.850000000,10,8,9,5,64.730000000,64.860000000,5,5,5,4,64.720000000,64.870000000,8,4,5,3,64.710000000,64.880000000,8,4,7,3,64.700000000,64.890000000,7,3,6,2,MCLN5
2025-06-11T00:00:00.100450611Z,2025-06-11T00:00:00.100278215Z,10,1,42025623,C,B,0,63.710000000,1,130,14811,79279244,63.710000000,63.720000000,1,3,1,3,63.700000000,63.730000000,2,2,2,2,63.690000000,63.740000000,3,3,3,3,63.680000000,63.750000000,1,2,1,2,63.670000000,63.760000000,3,5,3,5,63.660000000,63.770000000,5,2,5,2,63.650000000,63.780000000,5,4,5,4,63.640000000,63.790000000,4,2,4,2,63.630000000,63.800000000,4,3,4,3,63.620000000,63.810000000,3,4,3,2,MCLQ5
2025-06-11T00:00:00.100713538Z,2025-06-11T00:00:00.100600089Z,10,1,42026514,M,B,0,64.790000000,2,130,13756,79279249,64.790000000,64.800000000,11,3,5,3,64.780000000,64.810000000,5,3,5,3,64.770000000,64.820000000,9,9,5,6,64.760000000,64.830000000,10,8,10,8,64.750000000,64.840000000,7,8,7,7,64.740000000,64.850000000,10,8,9,5,64.730000000,64.860000000,5,5,5,4,64.720000000,64.870000000,8,4,5,3,64.710000000,64.880000000,8,4,7,3,64.700000000,64.890000000,7,3,6,2,MCLN5
2025-06-11T00:00:00.100725188Z,2025-06-11T00:00:00.100619079Z,10,1,42025623,M,A,2,65.100000000,1,130,10939,79279250,63.710000000,63.720000000,1,3,1,3,63.700000000,63.730000000,2,2,2,2,63.690000000,63.740000000,3,2,3,2,63.680000000,63.750000000,1,2,1,2,63.670000000,63.760000000,3,5,3,5,63.660000000,63.770000000,5,2,5,2,63.650000000,63.780000000,5,4,5,4,63.640000000,63.790000000,4,2,4,2,63.630000000,63.800000000,4,3,4,3,63.620000000,63.810000000,3,4,3,2,MCLQ5
2025-06-11T00:00:00.121592469Z,2025-06-11T00:00:00.121356069Z,10,1,42025611,A,A,0,2.090000000,1,130,11618,79279294,2.070000000,2.090000000,26,7,5,5,2.060000000,2.100000000,23,27,3,6,2.050000000,2.110000000,23,23,3,4,2.040000000,2.120000000,2,22,1,2,2.030000000,2.130000000,2,2,1,2,2.020000000,2.140000000,2,2,2,1,2.010000000,2.150000000,2,2,1,1,2.000000000,2.160000000,2,2,2,1,1.990000000,2.170000000,2,2,1,1,1.980000000,2.180000000,2,2,2,2,MCLN5-MCLU5
2025-06-11T00:00:00.121611415Z,2025-06-11T00:00:00.121356439Z,10,1,42022708,A,A,0,2.830000000,1,130,11427,79279296,2.810000000,2.830000000,12,2,3,2,2.800000000,2.840000000,2,12,2,3,2.790000000,2.850000000,2,1,2,1,,2.870000000,0,1,0,1,,,0,0,0,0,,,0,0,0,0,,,0,0,0,0,,,0,0,0,0,,,0,0,0,0,,,0,0,0,0,MCLN5-MCLV5
2025-06-11T00:00:00.122221904Z,2025-06-11T00:00:00.121370999Z,10,1,42026514,A,A,0,64.800000000,1,130,13401,79279353,64.790000000,64.800000000,11,4,5,4,64.780000000,64.810000000,5,3,5,3,64.770000000,64.820000000,9,9,5,6,64.760000000,64.830000000,10,8,10,8,64.750000000,64.840000000,7,8,7,7,64.740000000,64.850000000,10,8,9,5,64.730000000,64.860000000,5,5,5,4,64.720000000,64.870000000,8,4,5,3,64.710000000,64.880000000,8,4,7,3,64.700000000,64.890000000,7,3,6,2,MCLN5
2025-06-11T00:00:00.122310772Z,2025-06-11T00:00:00.121377025Z,10,1,42026514,C,B,0,64.790000000,1,130,12648,79279357,64.790000000,64.800000000,10,4,4,4,64.780000000,64.810000000,5,3,5,3,64.770000000,64.820000000,9,9,5,6,64.760000000,64.830000000,10,8,10,8,64.750000000,64.840000000,7,8,7,7,64.740000000,64.850000000,10,8,9,5,64.730000000,64.860000000,5,5,5,4,64.720000000,64.870000000,8,4,5,3,64.710000000,64.880000000,8,4,7,3,64.700000000,64.890000000,7,3,6,2,MCLN5
2025-06-11T00:00:00.122445073Z,2025-06-11T00:00:00.121420551Z,10,1,42025611,M,B,0,2.040000000,20,130,11624,79279368,2.070000000,2.090000000,6,7,4,5,2.060000000,2.100000000,23,27,3,6,2.050000000,2.110000000,23,23,3,4,2.040000000,2.120000000,22,22,2,2,2.030000000,2.130000000,2,2,1,2,2.020000000,2.140000000,2,2,2,1,2.010000000,2.150000000,2,2,1,1,2.000000000,2.160000000,2,2,2,1,1.990000000,2.170000000,2,2,1,1,1.980000000,2.180000000,2,2,2,2,MCLN5-MCLU5
2025-06-11T00:00:00.122618033Z,2025-06-11T00:00:00.121471677Z,10,1,42284507,C,B,0,0.990000000,10,130,11718,79279382,0.990000000,1.010000000,12,18,5,8,0.980000000,1.020000000,19,18,6,5,0.970000000,1.030000000,21,23,6,7,0.960000000,1.040000000,17,15,6,4,0.950000000,1.050000000,10,8,6,4,0.940000000,1.060000000,4,4,3,2,0.930000000,1.070000000,3,2,2,1,0.920000000,1.080000000,3,2,2,1,0.910000000,1.090000000,3,4,2,2,0.900000000,1.100000000,2,2,1,1,MCLQ5-MCLU5
2025-06-11T00:00:00.122680767Z,2025-06-11T00:00:00.121503607Z,10,1,42022708,M,B,0,2.780000000,1,130,12030,79279387,2.810000000,2.830000000,11,2,2,2,2.800000000,2.840000000,2,12,2,3,2.790000000,2.850000000,2,1,2,1,2.780000000,2.870000000,1,1,1,1,,,0,0,0,0,,,0,0,0,0,,,0,0,0,0,,,0,0,0,0,,,0,0,0,0,,,0,0,0,0,MCLN5-MCLV5
2025-06-11T00:00:00.122712069Z,2025-06-11T00:00:00.121526319Z,10,1,42022708,M,B,0,2.800000000,10,130,11841,79279390,2.810000000,2.830000000,1,2,1,2,2.800000000,2.840000000,12,12,3,3,2.790000000,2.850000000,2,1,2,1,2.780000000,2.870000000,1,1,1,1,,,0,0,0,0,,,0,0,0,0,,,0,0,0,0,,,0,0,0,0,,,0,0,0,0,,,0,0,0,0,MCLN5-MCLV5
2025-06-11T00:00:00.123721814Z,2025-06-11T00:00:00.122269479Z,10,1,42025623,C,B,0,63.710000000,1,130,14116,79279469,63.700000000,63.720000000,2,3,2,3,63.690000000,63.730000000,3,2,3,2,63.680000000,63.740000000,1,2,1,2,63.670000000,63.750000000,3,2,3,2,63.660000000,63.760000000,5,5,5,5,63.650000000,63.770000000,5,2,5,2,63.640000000,63.780000000,4,4,4,4,63.630000000,63.790000000,4,2,4,2,63.620000000,63.800000000,3,3,3,3,63.610000000,63.810000000,2,4,2,2,MCLQ5
2025-06-11T00:00:00.123873831Z,2025-06-11T00:00:00.122353285Z,10,1,42026514,M,B,0,64.790000000,1,130,13325,79279479,64.790000000,64.800000000,9,4,4,4,64.780000000,64.810000000,5,3,5,3,64.770000000,64.820000000,9,9,5,6,64.760000000,64.830000000,10,8,10,8,64.750000000,64.840000000,7,8,7,7,64.740000000,64.850000000,10,8,9,5,64.730000000,64.860000000,5,5,5,4,64.720000000,64.870000000,8,4,5,3,64.710000000,64.880000000,8,4,7,3,64.700000000,64.890000000,7,3,6,2,MCLN5
2025-06-11T00:00:00.123920270Z,2025-06-11T00:00:00.122416411Z,10,1,42026514,A,A,0,64.800000000,1,130,13342,79279482,64.790000000,64.800000000,9,5,4,5,64.780000000,64.810000000,5,3,5,3,64.770000000,64.820000000,9,9,5,6,64.760000000,64.830000000,10,8,10,8,64.750000000,64.840000000,7,8,7,7,64.740000000,64.850000000,10,8,9,5,64.730000000,64.860000000,5,5,5,4,64.720000000,64.870000000,8,4,5,3,64.710000000,64.880000000,8,4,7,3,64.700000000,64.890000000,7,3,6,2,MCLN5
2025-06-11T00:00:00.124105240Z,2025-06-11T00:00:00.122626697Z,10,1,42026514,C,A,0,64.800000000,1,130,12318,79279494,64.790000000,64.800000000,9,4,4,4,64.780000000,64.810000000,5,3,5,3,64.770000000,64.820000000,9,9,5,6,64.760000000,64.830000000,10,8,10,8,64.750000000,64.840000000,7,8,7,7,64.740000000,64.850000000,10,8,9,5,64.730000000,64.860000000,5,5,5,4,64.720000000,64.870000000,8,4,5,3,64.710000000,64.880000000,8,4,7,3,64.700000000,64.890000000,7,3,6,2,MCLN5
2025-06-11T00:00:00.124160656Z,2025-06-11T00:00:00.122631689Z,10,1,42025611,M,B,0,2.040000000,1,130,17661,79279497,2.070000000,2.090000000,5,7,3,5,2.060000000,2.100000000,23,27,3,6,2.050000000,2.110000000,23,23,3,4,2.040000000,2.120000000,23,22,3,2,2.030000000,2.130000000,2,2,1,2,2.020000000,2.140000000,2,2,2,1,2.010000000,2.150000000,2,2,1,1,2.000000000,2.160000000,2,2,2,1,1.990000000,2.170000000,2,2,1,1,1.980000000,2.180000000,2,2,2,2,MCLN5-MCLU5
2025-06-11T00:00:00.124275820Z,2025-06-11T00:00:00.122849407Z,10,1,42026514,C,B,0,64.790000000,1,130,13482,79279506,64.790000000,64.800000000,8,4,3,4,64.780000000,64.810000000,5,3,5,3,64.770000000,64.820000000,9,9,5,6,64.760000000,64.830000000,10,8,10,8,64.750000000,64.840000000,7,8,7,7,64.740000000,64.850000000,10,8,9,5,64.730000000,64.860000000,5,5,5,4,64.720000000,64.870000000,8,4,5,3,64.710000000,64.880000000,8,4,7,3,64.700000000,64.890000000,7,3,6,2,MCLN5
2025-06-11T00:00:00.124362092Z,2025-06-11T00:00:00.122877285Z,10,1,42284507,M,B,0,0.960000000,3,130,15481,79279514,0.990000000,1.010000000,9,18,4,8,0.980000000,1.020000000,19,18,6,5,0.970000000,1.030000000,21,23,6,7,0.960000000,1.040000000,20,15,7,4,0.950000000,1.050000000,10,8,6,4,0.940000000,1.060000000,4,4,3,2,0.930000000,1.070000000,3,2,2,1,0.920000000,1.080000000,3,2,2,1,0.910000000,1.090000000,3,4,2,2,0.900000000,1.100000000,2,2,1,1,MCLQ5-MCLU5
2025-06-11T00:00:00.124371745Z,2025-06-11T00:00:00.122877651Z,10,1,42284507,A,A,0,1.000000000,1,130,12495,79279515,0.990000000,1.000000000,9,1,4,1,0.980000000,1.010000000,19,18,6,8,0.970000000,1.020000000,21,18,6,5,0.960000000,1.030000000,20,23,7,7,0.950000000,1.040000000,10,15,6,4,0.940000000,1.050000000,4,8,3,4,0.930000000,1.060000000,3,4,2,2,0.920000000,1.070000000,3,2,2,1,0.910000000,1.080000000,3,2,2,1,0.900000000,1.090000000,2,4,1,2,MCLQ5-MCLU5
2025-06-11T00:00:00.124388533Z,2025-06-11T00:00:00.122878669Z,10,1,42284507,M,A,0,1.000000000,3,130,11945,79279517,0.990000000,1.000000000,9,4,4,2,0.980000000,1.010000000,19,18,6,8,0.970000000,1.020000000,21,18,6,5,0.960000000,1.030000000,20,20,7,6,0.950000000,1.040000000,10,15,6,4,0.940000000,1.050000000,4,8,3,4,0.930000000,1.060000000,3,4,2,2,0.920000000,1.070000000,3,2,2,1,0.910000000,1.080000000,3,2,2,1,0.900000000,1.090000000,2,4,1,2,MCLQ5-MCLU5
2025-06-11T00:00:00.124405912Z,2025-06-11T00:00:00.122880051Z,10,1,42025611,M,A,0,2.080000000,1,130,11823,79279519,2.070000000,2.080000000,5,1,3,1,2.060000000,2.090000000,23,7,3,5,2.050000000,2.100000000,23,27,3,6,2.040000000,2.110000000,23,22,3,3,2.030000000,2.120000000,2,22,1,2,2.020000000,2.130000000,2,2,2,2,2.010000000,2.140000000,2,2,1,1,2.000000000,2.150000000,2,2,2,1,1.990000000,2.160000000,2,2,1,1,1.980000000,2.170000000,2,2,2,1,MCLN5-MCLU5
2025-06-11T00:00:00.124759603Z,2025-06-11T00:00:00.123352829Z,10,1,42418117,M,A,1,3.290000000,10,130,11535,79279547,3.250000000,3.280000000,11,1,2,1,3.240000000,3.290000000,1,11,1,2,3.230000000,3.300000000,1,1,1,1,,,0,0,0,0,,,0,0,0,0,,,0,0,0,0,,,0,0,0,0,,,0,0,0,0,,,0,0,0,0,,,0,0,0,0,MCLN5-MCLX5
2025-06-11T00:00:00.124857395Z,2025-06-11T00:00:00.123732033Z,10,1,42025623,C,B,5,63.650000000,1,130,11782,79279557,63.700000000,63.720000000,2,3,2,3,63.690000000,63.730000000,3,2,3,2,63.680000000,63.740000000,1,2,1,2,63.670000000,63.750000000,3,2,3,2,63.660000000,63.760000000,5,5,5,5,63.650000000,63.770000000,4,2,4,2,63.640000000,63.780000000,4,4,4,4,63.630000000,63.790000000,4,2,4,2,63.620000000,63.800000000,3,3,3,3,63.610000000,63.810000000,2,4,2,2,MCLQ5
2025-06-11T00:00:00.125007485Z,2025-06-11T00:00:00.123858151Z,10,1,42025623,M,A,2,63.740000000,1,130,11700,79279567,63.700000000,63.720000000,2,3,2,3,63.690000000,63.730000000,3,2,3,2,63.680000000,63.740000000,1,3,1,3,63.670000000,63.750000000,3,2,3,2,63.660000000,63.760000000,5,5,5,5,63.650000000,63.770000000,4,2,4,2,63.640000000,63.780000000,4,4,4,4,63.630000000,63.790000000,4,2,4,2,63.620000000,63.800000000,3,3,3,3,63.610000000,63.810000000,2,4,2,2,MCLQ5
2025-06-11T00:00:00.125159410Z,2025-06-11T00:00:00.124041887Z,10,1,42418117,M,A,0,3.270000000,1,130,12074,79279581,3.250000000,3.270000000,11,1,2,1,3.240000000,3.280000000,1,1,1,1,3.230000000,3.290000000,1,11,1,2,,,0,0,0,0,,,0,0,0,0,,,0,0,0,0,,,0,0,0,0,,,0,0,0,0,,,0,0,0,0,,,0,0,0,0,MCLN5-MCLX5
2025-06-11T00:00:00.125215687Z,2025-06-11T00:00:00.124071243Z,10,1,42022708,M,A,0,2.820000000,1,130,14723,79279586,2.810000000,2.820000000,1,1,1,1,2.800000000,2.830000000,12,2,3,2,2.790000000,2.840000000,2,12,2,3,2.780000000,2.870000000,1,1,1,1,,,0,0,0,0,,,0,0,0,0,,,0,0,0,0,,,0,0,0,0,,,0,0,0,0,,,0,0,0,0,MCLN5-MCLV5
2025-06-11T00:00:00.125393669Z,2025-06-11T00:00:00.124098487Z,10,1,42064377,C,B,0,0.730000000,10,130,11763,79279602,0.730000000,0.750000000,11,13,4,4,0.720000000,0.760000000,15,15,4,4,0.710000000,0.770000000,16,16,4,4,0.700000000,0.780000000,12,12,3,3,0.690000000,0.790000000,6,5,3,3,0.680000000,0.800000000,6,6,4,4,0.670000000,0.810000000,2,2,2,1,0.660000000,0.820000000,2,1,1,1,0.600000000,0.830000000,10,1,1,1,0.560000000,0.840000000,10,1,1,1,MCLU5-MCLV5
2025-06-11T00:00:00.125461602Z,2025-06-11T00:00:00.124101271Z,10,1,42418117,M,B,0,3.220000000,1,130,12056,79279608,3.250000000,3.270000000,10,1,1,1,3.240000000,3.280000000,1,1,1,1,3.230000000,3.290000000,1,11,1,2,3.220000000,,1,0,1,0,,,0,0,0,0,,,0,0,0,0,,,0,0,0,0,,,0,0,0,0,,,0,0,0,0,,,0,0,0,0,MCLN5-MCLX5
2025-06-11T00:00:00.125920451Z,2025-06-11T00:00:00.124397553Z,10,1,42284507,A,A,0,1.000000000,3,130,11237,79279642,0.990000000,1.000000000,9,7,4,3,0.980000000,1.010000000,19,18,6,8,0.970000000,1.020000000,21,18,6,5,0.960000000,1.030000000,20,20,7,6,0.950000000,1.040000000,10,15,6,4,0.940000000,1.050000000,4,8,3,4,0.930000000,1.060000000,3,4,2,2,0.920000000,1.070000000,3,2,2,1,0.910000000,1.080000000,3,2,2,1,0.900000000,1.090000000,2,4,1,2,MCLQ5-MCLU5
2025-06-11T00:00:00.125928722Z,2025-06-11T00:00:00.124397731Z,10,1,42284507,C,A,1,1.010000000,3,130,11375,79279643,0.990000000,1.000000000,9,7,4,3,0.980000000,1.010000000,19,15,6,7,0.970000000,1.020000000,21,18,6,5,0.960000000,1.030000000,20,20,7,6,0.950000000,1.040000000,10,15,6,4,0.940000000,1.050000000,4,8,3,4,0.930000000,1.060000000,3,4,2,2,0.920000000,1.070000000,3,2,2,1,0.910000000,1.080000000,3,2,2,1,0.900000000,1.090000000,2,4,1,2,MCLQ5-MCLU5
2025-06-11T00:00:00.125987456Z,2025-06-11T00:00:00.124534211Z,10,1,42284507,M,A,0,1.000000000,1,130,12467,79279648,0.990000000,1.000000000,9,8,4,4,0.980000000,1.010000000,19,15,6,7,0.970000000,1.020000000,21,18,6,5,0.960000000,1.030000000,20,20,7,6,0.950000000,1.040000000,10,15,6,4,0.940000000,1.050000000,4,8,3,4,0.930000000,1.060000000,3,4,2,2,0.920000000,1.070000000,3,2,2,1,0.910000000,1.080000000,3,2,2,1,0.900000000,1.090000000,2,4,1,2,MCLQ5-MCLU5
2025-06-11T00:00:00.126129190Z,2025-06-11T00:00:00.124993091Z,10,1,42284507,A,A,1,1.010000000,10,130,11212,79279661,0.990000000,1.000000000,9,8,4,4,0.980000000,1.010000000,19,25,6,8,0.970000000,1.020000000,21,18,6,5,0.960000000,1.030000000,20,20,7,6,0.950000000,1.040000000,10,15,6,4,0.940000000,1.050000000,4,8,3,4,0.930000000,1.060000000,3,4,2,2,0.920000000,1.070000000,3,2,2,1,0.910000000,1.080000000,3,2,2,1,0.900000000,1.090000000,2,4,1,2,MCLQ5-MCLU5
2025-06-11T00:00:00.126668597Z,2025-06-11T00:00:00.125599495Z,10,1,42064377,M,A,0,0.750000000,2,130,15197,79279700,0.730000000,0.750000000,11,15,4,5,0.720000000,0.760000000,15,15,4,4,0.710000000,0.770000000,16,16,4,4,0.700000000,0.780000000,12,12,3,3,0.690000000,0.790000000,6,5,3,3,0.680000000,0.800000000,6,6,4,4,0.670000000,0.810000000,2,2,2,1,0.660000000,0.820000000,2,1,1,1,0.600000000,0.830000000,10,1,1,1,0.560000000,0.880000000,10,10,1,1,MCLU5-MCLV5
2025-06-11T00:00:00.126761950Z,2025-06-11T00:00:00.126083679Z,10,1,42284507,M,B,0,0.880000000,2,130,15064,79279708,0.990000000,1.000000000,7,8,3,4,0.980000000,1.010000000,19,25,6,8,0.970000000,1.020000000,21,18,6,5,0.960000000,1.030000000,20,20,7,6,0.950000000,1.040000000,10,15,6,4,0.940000000,1.050000000,4,8,3,4,0.930000000,1.060000000,3,4,2,2,0.920000000,1.070000000,3,2,2,1,0.910000000,1.080000000,3,2,2,1,0.900000000,1.090000000,2,4,1,2,MCLQ5-MCLU5
2025-06-11T00:00:00.126937898Z,2025-06-11T00:00:00.126250443Z,10,1,42284507,M,A,0,1.100000000,2,130,11315,79279721,0.990000000,1.000000000,7,7,3,3,0.980000000,1.010000000,19,25,6,8,0.970000000,1.020000000,21,18,6,5,0.960000000,1.030000000,20,20,7,6,0.950000000,1.040000000,10,15,6,4,0.940000000,1.050000000,4,8,3,4,0.930000000,1.060000000,3,4,2,2,0.920000000,1.070000000,3,2,2,1,0.910000000,1.080000000,3,2,2,1,0.900000000,1.090000000,2,4,1,2,MCLQ5-MCLU5
2025-06-11T00:00:00.127193690Z,2025-06-11T00:00:00.126781549Z,10,1,42284507,M,B,2,0.960000000,3,130,11485,79279744,0.990000000,1.000000000,7,7,3,3,0.980000000,1.010000000,19,25,6,8,0.970000000,1.020000000,18,18,5,5,0.960000000,1.030000000,23,20,8,6,0.950000000,1.040000000,10,15,6,4,0.940000000,1.050000000,4,8,3,4,0.930000000,1.060000000,3,4,2,2,0.920000000,1.070000000,3,2,2,1,0.910000000,1.080000000,3,2,2,1,0.900000000,1.090000000,2,4,1,2,MCLQ5-MCLU5
2025-06-11T00:00:00.127193690Z,2025-06-11T00:00:00.126782067Z,10,1,42284507,M,A,2,1.020000000,3,130,11485,79279744,0.990000000,1.000000000,7,7,3,3,0.980000000,1.010000000,19,25,6,8,0.970000000,1.020000000,18,21,5,6,0.960000000,1.030000000,23,17,8,5,0.950000000,1.040000000,10,15,6,4,0.940000000,1.050000000,4,8,3,4,0.930000000,1.060000000,3,4,2,2,0.920000000,1.070000000,3,2,2,1,0.910000000,1.080000000,3,2,2,1,0.900000000,1.090000000,2,4,1,2,MCLQ5-MCLU5
2025-06-11T00:00:00.128477188Z,2025-06-11T00:00:00.128356455Z,10,1,42284507,A,A,0,1.000000000,3,130,11351,79279777,0.990000000,1.000000000,7,10,3,4,0.980000000,1.010000000,19,25,6,8,0.970000000,1.020000000,18,21,5,6,0.960000000,1.030000000,23,17,8,5,0.950000000,1.040000000,10,15,6,4,0.940000000,1.050000000,4,8,3,4,0.930000000,1.060000000,3,4,2,2,0.920000000,1.070000000,3,2,2,1,0.910000000,1.080000000,3,2,2,1,0.900000000,1.090000000,2,4,1,2,MCLQ5-MCLU5
2025-06-11T00:00:00.129626440Z,2025-06-11T00:00:00.129457047Z,10,1,42026514,C,A,0,64.800000000,1,130,12467,79279818,64.790000000,64.800000000,8,3,3,3,64.780000000,64.810000000,5,3,5,3,64.770000000,64.820000000,9,9,5,6,64.760000000,64.830000000,10,8,10,8,64.750000000,64.840000000,7,8,7,7,64.740000000,64.850000000,10,8,9,5,64.730000000,64.860000000,5,5,5,4,64.720000000,64.870000000,8,4,5,3,64.710000000,64.880000000,8,4,7,3,64.700000000,64.890000000,7,3,6,2,MCLN5
2025-06-11T00:00:00.137314674Z,2025-06-11T00:00:00.136988911Z,10,1,42025623,A,B,6,63.640000000,1,130,15609,79280013,63.700000000,63.720000000,2,3,2,3,63.690000000,63.730000000,3,2,3,2,63.680000000,63.740000000,1,3,1,3,63.670000000,63.750000000,3,2,3,2,63.660000000,63.760000000,5,5,5,5,63.650000000,63.770000000,4,2,4,2,63.640000000,63.780000000,5,4,5,4,63.630000000,63.790000000,4,2,4,2,63.620000000,63.800000000,3,3,3,3,63.610000000,63.810000000,2,4,2,2,MCLQ5
2025-06-11T00:00:00.137314674Z,2025-06-11T00:00:00.136990697Z,10,1,42025623,C,A,7,63.790000000,1,130,15609,79280013,63.700000000,63.720000000,2,3,2,3,63.690000000,63.730000000,3,2,3,2,63.680000000,63.740000000,1,3,1,3,63.670000000,63.750000000,3,2,3,2,63.660000000,63.760000000,5,5,5,5,63.650000000,63.770000000,4,2,4,2,63.640000000,63.780000000,5,4,5,4,63.630000000,63.790000000,4,1,4,1,63.620000000,63.800000000,3,3,3,3,63.610000000,63.810000000,2,4,2,2,MCLQ5
2025-06-11T00:00:00.137510297Z,2025-06-11T00:00:00.137319139Z,10,1,42025623,A,A,6,63.780000000,1,130,11918,79280033,63.700000000,63.720000000,2,3,2,3,63.690000000,63.730000000,3,2,3,2,63.680000000,63.740000000,1,3,1,3,63.670000000,63.750000000,3,2,3,2,63.660000000,63.760000000,5,5,5,5,63.650000000,63.770000000,4,2,4,2,63.640000000,63.780000000,5,5,5,5,63.630000000,63.790000000,4,1,4,1,63.620000000,63.800000000,3,3,3,3,63.610000000,63.810000000,2,4,2,2,MCLQ5
2025-06-11T00:00:00.139632530Z,2025-06-11T00:00:00.139531763Z,10,1,42026514,A,A,0,64.800000000,1,130,11579,79280121,64.790000000,64.800000000,8,4,3,4,64.780000000,64.810000000,5,3,5,3,64.770000000,64.820000000,9,9,5,6,64.760000000,64.830000000,10,8,10,8,64.750000000,64.840000000,7,8,7,7,64.740000000,64.850000000,10,8,9,5,64.730000000,64.860000000,5,5,5,4,64.720000000,64.870000000,8,4,5,3,64.710000000,64.880000000,8,4,7,3,64.700000000,64.890000000,7,3,6,2,MCLN5
2025-06-11T00:00:00.139768866Z,2025-06-11T00:00:00.139661607Z,10,1,42026514,A,A,0,64.800000000,1,130,13183,79280129,64.790000000,64.800000000,8,5,3,5,64.780000000,64.810000000,5,3,5,3,64.770000000,64.820000000,9,9,5,6,64.760000000,64.830000000,10,8,10,8,64.750000000,64.840000000,7,8,7,7,64.740000000,64.850000000,10,8,9,5,64.730000000,64.860000000,5,5,5,4,64.720000000,64.870000000,8,4,5,3,64.710000000,64.880000000,8,4,7,3,64.700000000,64.890000000,7,3,6,2,MCLN5
2025-06-11T00:00:00.244758216Z,2025-06-11T00:00:00.244280967Z,10,1,42025611,C,B,0,2.070000000,2,130,11712,79281072,2.070000000,2.080000000,3,1,2,1,2.060000000,2.090000000,23,7,3,5,2.050000000,2.100000000,23,27,3,6,2.040000000,2.110000000,23,22,3,3,2.030000000,2.120000000,2,22,1,2,2.020000000,2.130000000,2,2,2,2,2.010000000,2.140000000,2,2,1,1,2.000000000,2.150000000,2,2,2,1,1.990000000,2.160000000,2,2,1,1,1.980000000,2.170000000,2,2,2,1,MCLN5-MCLU5
2025-06-11T00:00:00.245854724Z,2025-06-11T00:00:00.245751335Z,10,1,42025611,A,A,0,2.080000000,3,130,14823,79281157,2.070000000,2.080000000,3,4,2,2,2.060000000,2.090000000,23,7,3,5,2.050000000,2.100000000,23,27,3,6,2.040000000,2.110000000,23,22,3,3,2.030000000,2.120000000,2,22,1,2,2.020000000,2.130000000,2,2,2,2,2.010000000,2.140000000,2,2,1,1,2.000000000,2.150000000,2,2,2,1,1.990000000,2.160000000,2,2,1,1,1.980000000,2.170000000,2,2,2,1,MCLN5-MCLU5
2025-06-11T00:00:00.246534091Z,2025-06-11T00:00:00.246406735Z,10,1,42026514,A,A,0,64.800000000,1,130,13645,79281177,64.790000000,64.800000000,8,6,3,6,64.780000000,64.810000000,5,3,5,3,64.770000000,64.820000000,9,9,5,6,64.760000000,64.830000000,10,8,10,8,64.750000000,64.840000000,7,8,7,7,64.740000000,64.850000000,10,8,9,5,64.730000000,64.860000000,5,5,5,4,64.720000000,64.870000000,8,4,5,3,64.710000000,64.880000000,8,4,7,3,64.700000000,64.890000000,7,3,6,2,MCLN5
2025-06-11T00:00:00.313869400Z,2025-06-11T00:00:00.313529195Z,10,1,42026514,C,B,0,64.790000000,2,130,18119,79281535,64.790000000,64.800000000,6,6,2,6,64.780000000,64.810000000,5,3,5,3,64.770000000,64.820000000,9,9,5,6,64.760000000,64.830000000,10,8,10,8,64.750000000,64.840000000,7,8,7,7,64.740000000,64.850000000,10,8,9,5,64.730000000,64.860000000,5,5,5,4,64.720000000,64.870000000,8,4,5,3,64.710000000,64.880000000,8,4,7,3,64.700000000,64.890000000,7,3,6,2,MCLN5
2025-06-11T00:00:00.327044775Z,2025-06-11T00:00:00.326942739Z,10,1,42025623,M,A,4,63.760000000,1,130,14793,79281726,63.700000000,63.720000000,2,3,2,3,63.690000000,63.730000000,3,2,3,2,63.680000000,63.740000000,1,3,1,3,63.670000000,63.750000000,3,2,3,2,63.660000000,63.760000000,5,6,5,6,63.650000000,63.770000000,4,1,4,1,63.640000000,63.780000000,5,5,5,5,63.630000000,63.790000000,4,1,4,1,63.620000000,63.800000000,3,3,3,3,63.610000000,63.810000000,2,4,2,2,MCLQ5
2025-06-11T00:00:00.360484990Z,2025-06-11T00:00:00.360301435Z,10,1,42026514,A,A,0,64.800000000,1,130,15878,79281930,64.790000000,64.800000000,6,7,2,7,64.780000000,64.810000000,5,3,5,3,64.770000000,64.820000000,9,9,5,6,64.760000000,64.830000000,10,8,10,8,64.750000000,64.840000000,7,8,7,7,64.740000000,64.850000000,10,8,9,5,64.730000000,64.860000000,5,5,5,4,64.720000000,64.870000000,8,4,5,3,64.710000000,64.880000000,8,4,7,3,64.700000000,64.890000000,7,3,6,2,MCLN5
2025-06-11T00:00:00.360602565Z,2025-06-11T00:00:00.360494791Z,10,1,42026514,M,B,3,64.750000000,1,130,11863,79281933,64.790000000,64.800000000,6,7,2,7,64.780000000,64.810000000,5,3,5,3,64.770000000,64.820000000,9,9,5,6,64.760000000,64.830000000,9,8,9,8,64.750000000,64.840000000,8,8,8,7,64.740000000,64.850000000,10,8,9,5,64.730000000,64.860000000,5,5,5,4,64.720000000,64.870000000,8,4,5,3,64.710000000,64.880000000,8,4,7,3,64.700000000,64.890000000,7,3,6,2,MCLN5
2025-06-11T00:00:00.360611389Z,2025-06-11T00:00:00.360495291Z,10,1,42026514,M,A,3,64.830000000,1,130,11545,79281934,64.790000000,64.800000000,6,7,2,7,64.780000000,64.810000000,5,3,5,3,64.770000000,64.820000000,9,9,5,6,64.760000000,64.830000000,9,9,9,9,64.750000000,64.840000000,8,7,8,6,64.740000000,64.850000000,10,8,9,5,64.730000000,64.860000000,5,5,5,4,64.720000000,64.870000000,8,4,5,3,64.710000000,64.880000000,8,4,7,3,64.700000000,64.890000000,7,3,6,2,MCLN5
2025-06-11T00:00:00.360621181Z,2025-06-11T00:00:00.360495809Z,10,1,42026514,M,B,3,64.750000000,1,130,12400,79281935,64.790000000,64.800000000,6,7,2,7,64.780000000,64.810000000,5,3,5,3,64.770000000,64.820000000,9,9,5,6,64.760000000,64.830000000,8,9,8,9,64.750000000,64.840000000,9,7,9,6,64.740000000,64.850000000,10,8,9,5,64.730000000,64.860000000,5,5,5,4,64.720000000,64.870000000,8,4,5,3,64.710000000,64.880000000,8,4,7,3,64.700000000,64.890000000,7,3,6,2,MCLN5
2025-06-11T00:00:00.360630309Z,2025-06-11T00:00:00.360496289Z,10,1,42026514,M,A,3,64.830000000,1,130,12326,79281936,64.790000000,64.800000000,6,7,2,7,64.780000000,64.810000000,5,3,5,3,64.770000000,64.820000000,9,9,5,6,64.760000000,64.830000000,8,10,8,10,64.750000000,64.840000000,9,6,9,5,64.740000000,64.850000000,10,8,9,5,64.730000000,64.860000000,5,5,5,4,64.720000000,64.870000000,8,4,5,3,64.710000000,64.880000000,8,4,7,3,64.700000000,64.890000000,7,3,6,2,MCLN5
2025-06-11T00:00:00.365697923Z,2025-06-11T00:00:00.365422369Z,10,1,42026514,C,A,0,64.800000000,1,130,16667,79281967,64.790000000,64.800000000,6,6,2,6,64.780000000,64.810000000,5,3,5,3,64.770000000,64.820000000,9,9,5,6,64.760000000,64.830000000,8,10,8,10,64.750000000,64.840000000,9,6,9,5,64.740000000,64.850000000,10,8,9,5,64.730000000,64.860000000,5,5,5,4,64.720000000,64.870000000,8,4,5,3,64.710000000,64.880000000,8,4,7,3,64.700000000,64.890000000,7,3,6,2,MCLN5
2025-06-11T00:00:00.377662065Z,2025-06-11T00:00:00.376911659Z,10,1,42026514,C,A,0,64.800000000,1,130,17109,79282116,64.790000000,64.800000000,6,5,2,5,64.780000000,64.810000000,5,3,5,3,64.770000000,64.820000000,9,9,5,6,64.760000000,64.830000000,8,10,8,10,64.750000000,64.840000000,9,6,9,5,64.740000000,64.850000000,10,8,9,5,64.730000000,64.860000000,5,5,5,4,64.720000000,64.870000000,8,4,5,3,64.710000000,64.880000000,8,4,7,3,64.700000000,64.890000000,7,3,6,2,MCLN5
2025-06-11T00:00:00.378444524Z,2025-06-11T00:00:00.378125217Z,10,1,42026514,M,A,3,64.840000000,1,130,15059,79282174,64.790000000,64.800000000,6,5,2,5,64.780000000,64.810000000,5,3,5,3,64.770000000,64.820000000,9,9,5,6,64.760000000,64.830000000,8,9,8,9,64.750000000,64.840000000,9,7,9,6,64.740000000,64.850000000,10,8,9,5,64.730000000,64.860000000,5,5,5,4,64.720000000,64.870000000,8,4,5,3,64.710000000,64.880000000,8,4,7,3,64.700000000,64.890000000,7,3,6,2,MCLN5
2025-06-11T00:00:00.378453056Z,2025-06-11T00:00:00.378125719Z,10,1,42026514,M,B,3,64.760000000,1,130,11757,79282175,64.790000000,64.800000000,6,5,2,5,64.780000000,64.810000000,5,3,5,3,64.770000000,64.820000000,9,9,5,6,64.760000000,64.830000000,9,9,9,9,64.750000000,64.840000000,8,7,8,6,64.740000000,64.850000000,10,8,9,5,64.730000000,64.860000000,5,5,5,4,64.720000000,64.870000000,8,4,5,3,64.710000000,64.880000000,8,4,7,3,64.700000000,64.890000000,7,3,6,2,MCLN5
2025-06-11T00:00:00.378462187Z,2025-06-11T00:00:00.378126275Z,10,1,42026514,M,A,3,64.840000000,1,130,11659,79282176,64.790000000,64.800000000,6,5,2,5,64.780000000,64.810000000,5,3,5,3,64.770000000,64.820000000,9,9,5,6,64.760000000,64.830000000,9,8,9,8,64.750000000,64.840000000,8,8,8,7,64.740000000,64.850000000,10,8,9,5,64.730000000,64.860000000,5,5,5,4,64.720000000,64.870000000,8,4,5,3,64.710000000,64.880000000,8,4,7,3,64.700000000,64.890000000,7,3,6,2,MCLN5
2025-06-11T00:00:00.378470481Z,2025-06-11T00:00:00.378126773Z,10,1,42026514,M,B,3,64.760000000,1,130,11563,79282177,64.790000000,64.800000000,6,5,2,5,64.780000000,64.810000000,5,3,5,3,64.770000000,64.820000000,9,9,5,6,64.760000000,64.830000000,10,8,10,8,64.750000000,64.840000000,7,8,7,7,64.740000000,64.850000000,10,8,9,5,64.730000000,64.860000000,5,5,5,4,64.720000000,64.870000000,8,4,5,3,64.710000000,64.880000000,8,4,7,3,64.700000000,64.890000000,7,3,6,2,MCLN5
2025-06-11T00:00:00.378573879Z,2025-06-11T00:00:00.378164999Z,10,1,42025611,C,B,0,2.070000000,2,130,11775,79282185,2.070000000,2.080000000,1,4,1,2,2.060000000,2.090000000,23,7,3,5,2.050000000,2.100000000,23,27,3,6,2.040000000,2.110000000,23,22,3,3,2.030000000,2.120000000,2,22,1,2,2.020000000,2.130000000,2,2,2,2,2.010000000,2.140000000,2,2,1,1,2.000000000,2.150000000,2,2,2,1,1.990000000,2.160000000,2,2,1,1,1.980000000,2.170000000,2,2,2,1,MCLN5-MCLU5
2025-06-11T00:00:00.378857555Z,2025-06-11T00:00:00.378558503Z,10,1,42418117,M,B,0,3.240000000,10,130,15036,79282206,3.240000000,3.270000000,11,1,2,1,3.230000000,3.280000000,1,1,1,1,3.220000000,3.290000000,1,11,1,2,,,0,0,0,0,,,0,0,0,0,,,0,0,0,0,,,0,0,0,0,,,0,0,0,0,,,0,0,0,0,,,0,0,0,0,MCLN5-MCLX5
2025-06-11T00:00:00.379272975Z,2025-06-11T00:00:00.378894413Z,10,1,42418117,M,A,1,3.280000000,10,130,11346,79282243,3.240000000,3.270000000,11,1,2,1,3.230000000,3.280000000,1,11,1,2,3.220000000,3.290000000,1,1,1,1,,,0,0,0,0,,,0,0,0,0,,,0,0,0,0,,,0,0,0,0,,,0,0,0,0,,,0,0,0,0,,,0,0,0,0,MCLN5-MCLX5
2025-06-11T00:00:00.379920242Z,2025-06-11T00:00:00.379824057Z,10,1,42418117,M,A,1,3.290000000,10,130,15966,79282252,3.240000000,3.270000000,11,1,2,1,3.230000000,3.280000000,1,1,1,1,3.220000000,3.290000000,1,11,1,2,,,0,0,0,0,,,0,0,0,0,,,0,0,0,0,,,0,0,0,0,,,0,0,0,0,,,0,0,0,0,,,0,0,0,0,MCLN5-MCLX5
2025-06-11T00:00:00.562690256Z,2025-06-11T00:00:00.557038343Z,10,1,42022708,M,A,1,2.830000000,10,130,11559,79286972,2.810000000,2.820000000,1,1,1,1,2.800000000,2.830000000,12,12,3,3,2.790000000,2.840000000,2,2,2,2,2.780000000,2.870000000,1,1,1,1,,,0,0,0,0,,,0,0,0,0,,,0,0,0,0,,,0,0,0,0,,,0,0,0,0,,,0,0,0,0,MCLN5-MCLV5
2025-06-11T00:00:00.562962428Z,2025-06-11T00:00:00.557271057Z,10,1,42026514,A,A,0,64.800000000,1,130,13262,79286988,64.790000000,64.800000000,6,6,2,6,64.780000000,64.810000000,5,3,5,3,64.770000000,64.820000000,9,9,5,6,64.760000000,64.830000000,10,8,10,8,64.750000000,64.840000000,7,8,7,7,64.740000000,64.850000000,10,8,9,5,64.730000000,64.860000000,5,5,5,4,64.720000000,64.870000000,8,4,5,3,64.710000000,64.880000000,8,4,7,3,64.700000000,64.890000000,7,3,6,2,MCLN5
2025-06-11T00:00:00.563034371Z,2025-06-11T00:00:00.557312891Z,10,1,42025623,M,A,4,63.770000000,1,130,11905,79286993,63.700000000,63.720000000,2,3,2,3,63.690000000,63.730000000,3,2,3,2,63.680000000,63.740000000,1,3,1,3,63.670000000,63.750000000,3,2,3,2,63.660000000,63.760000000,5,5,5,5,63.650000000,63.770000000,4,2,4,2,63.640000000,63.780000000,5,5,5,5,63.630000000,63.790000000,4,1,4,1,63.620000000,63.800000000,3,3,3,3,63.610000000,63.810000000,2,4,2,2,MCLQ5
2025-06-11T00:00:00.563055996Z,2025-06-11T00:00:00.557313369Z,10,1,42025623,M,B,4,63.660000000,1,130,11807,79286995,63.700000000,63.720000000,2,3,2,3,63.690000000,63.730000000,3,2,3,2,63.680000000,63.740000000,1,3,1,3,63.670000000,63.750000000,3,2,3,2,63.660000000,63.760000000,6,5,6,5,63.650000000,63.770000000,3,2,3,2,63.640000000,63.780000000,5,5,5,5,63.630000000,63.790000000,4,1,4,1,63.620000000,63.800000000,3,3,3,3,63.610000000,63.810000000,2,4,2,2,MCLQ5
2025-06-11T00:00:00.563068053Z,2025-06-11T00:00:00.557314349Z,10,1,42026514,M,B,3,64.750000000,1,130,11389,79286996,64.790000000,64.800000000,6,6,2,6,64.780000000,64.810000000,5,3,5,3,64.770000000,64.820000000,9,9,5,6,64.760000000,64.830000000,9,8,9,8,64.750000000,64.840000000,8,8,8,7,64.740000000,64.850000000,10,8,9,5,64.730000000,64.860000000,5,5,5,4,64.720000000,64.870000000,8,4,5,3,64.710000000,64.880000000,8,4,7,3,64.700000000,64.890000000,7,3,6,2,MCLN5
2025-06-11T00:00:00.563156323Z,2025-06-11T00:00:00.557315407Z,10,1,42026514,M,B,3,64.750000000,1,130,13530,79286999,64.790000000,64.800000000,6,6,2,6,64.780000000,64.810000000,5,3,5,3,64.770000000,64.820000000,9,9,5,6,64.760000000,64.830000000,8,8,8,8,64.750000000,64.840000000,9,8,9,7,64.740000000,64.850000000,10,8,9,5,64.730000000,64.860000000,5,5,5,4,64.720000000,64.870000000,8,4,5,3,64.710000000,64.880000000,8,4,7,3,64.700000000,64.890000000,7,3,6,2,MCLN5
2025-06-11T00:00:00.564396715Z,2025-06-11T00:00:00.557925439Z,10,1,42026514,T,A,0,64.790000000,6,0,12704,79287066,64.790000000,64.800000000,6,6,2,6,64.780000000,64.810000000,5,3,5,3,64.770000000,64.820000000,9,9,5,6,64.760000000,64.830000000,8,8,8,8,64.750000000,64.840000000,9,8,9,7,64.740000000,64.850000000,10,8,9,5,64.730000000,64.860000000,5,5,5,4,64.720000000,64.870000000,8,4,5,3,64.710000000,64.880000000,8,4,7,3,64.700000000,64.890000000,7,3,6,2,MCLN5
2025-06-11T00:00:00.564427987Z,2025-06-11T00:00:00.557925439Z,10,1,42026514,C,B,0,64.790000000,3,130,15125,79287067,64.780000000,64.800000000,5,6,5,6,64.770000000,64.810000000,9,3,5,3,64.760000000,64.820000000,8,9,8,6,64.750000000,64.830000000,9,8,9,8,64.740000000,64.840000000,10,8,9,7,64.730000000,64.850000000,5,8,5,5,64.720000000,64.860000000,8,5,5,4,64.710000000,64.870000000,8,4,7,3,64.700000000,64.880000000,7,4,6,3,64.690000000,64.890000000,4,3,3,2,MCLN5
2025-06-11T00:00:00.565150391Z,2025-06-11T00:00:00.557994959Z,10,1,42026514,A,A,0,64.800000000,1,130,13119,79287106,64.780000000,64.800000000,5,7,5,7,64.770000000,64.810000000,9,3,5,3,64.760000000,64.820000000,8,9,8,6,64.750000000,64.830000000,9,8,9,8,64.740000000,64.840000000,10,8,9,7,64.730000000,64.850000000,5,8,5,5,64.720000000,64.860000000,8,5,5,4,64.710000000,64.870000000,8,4,7,3,64.700000000,64.880000000,7,4,6,3,64.690000000,64.890000000,4,3,3,2,MCLN5
2025-06-11T00:00:00.565254220Z,2025-06-11T00:00:00.557999567Z,10,1,42026514,A,B,0,64.790000000,2,130,15837,79287109,64.790000000,64.800000000,2,7,1,7,64.780000000,64.810000000,5,3,5,3,64.770000000,64.820000000,9,9,5,6,64.760000000,64.830000000,8,8,8,8,64.750000000,64.840000000,9,8,9,7,64.740000000,64.850000000,10,8,9,5,64.730000000,64.860000000,5,5,5,4,64.720000000,64.870000000,8,4,5,3,64.710000000,64.880000000,8,4,7,3,64.700000000,64.890000000,7,3,6,2,MCLN5
2025-06-11T00:00:00.565288893Z,2025-06-11T00:00:00.558010395Z,10,1,42025623,A,A,0,63.710000000,1,130,15822,79287110,63.700000000,63.710000000,2,1,2,1,63.690000000,63.720000000,3,3,3,3,63.680000000,63.730000000,1,2,1,2,63.670000000,63.740000000,3,3,3,3,63.660000000,63.750000000,6,2,6,2,63.650000000,63.760000000,3,5,3,5,63.640000000,63.770000000,5,2,5,2,63.630000000,63.780000000,4,5,4,5,63.620000000,63.790000000,3,1,3,1,63.610000000,63.800000000,2,3,2,3,MCLQ5
2025-06-11T00:00:00.565362056Z,2025-06-11T00:00:00.558016155Z,10,1,42025623,C,B,0,63.700000000,1,130,15286,79287113,63.700000000,63.710000000,1,1,1,1,63.690000000,63.720000000,3,3,3,3,63.680000000,63.730000000,1,2,1,2,63.670000000,63.740000000,3,3,3,3,63.660000000,63.750000000,6,2,6,2,63.650000000,63.760000000,3,5,3,5,63.640000000,63.770000000,5,2,5,2,63.630000000,63.780000000,4,5,4,5,63.620000000,63.790000000,3,1,3,1,63.610000000,63.800000000,2,3,2,3,MCLQ5
2025-06-11T00:00:00.565528419Z,2025-06-11T00:00:00.558211947Z,10,1,42026514,M,B,1,62.840000000,2,130,11574,79287122,64.790000000,64.800000000,2,7,1,7,64.780000000,64.810000000,4,3,4,3,64.770000000,64.820000000,9,9,5,6,64.760000000,64.830000000,8,8,8,8,64.750000000,64.840000000,9,8,9,7,64.740000000,64.850000000,10,8,9,5,64.730000000,64.860000000,5,5,5,4,64.720000000,64.870000000,8,4,5,3,64.710000000,64.880000000,8,4,7,3,64.700000000,64.890000000,7,3,6,2,MCLN5
2025-06-11T00:00:00.565674424Z,2025-06-11T00:00:00.559926413Z,10,1,42025623,C,A,0,63.710000000,1,130,16908,79287131,63.700000000,63.720000000,1,3,1,3,63.690000000,63.730000000,3,2,3,2,63.680000000,63.740000000,1,3,1,3,63.670000000,63.750000000,3,2,3,2,63.660000000,63.760000000,6,5,6,5,63.650000000,63.770000000,3,2,3,2,63.640000000,63.780000000,5,5,5,5,63.630000000,63.790000000,4,1,4,1,63.620000000,63.800000000,3,3,3,3,63.610000000,63.810000000,2,4,2,2,MCLQ5
2025-06-11T00:00:00.565786776Z,2025-06-11T00:00:00.563008223Z,10,1,42026514,A,B,0,64.790000000,2,130,13970,79287142,64.790000000,64.800000000,4,7,2,7,64.780000000,64.810000000,4,3,4,3,64.770000000,64.820000000,9,9,5,6,64.760000000,64.830000000,8,8,8,8,64.750000000,64.840000000,9,8,9,7,64.740000000,64.850000000,10,8,9,5,64.730000000,64.860000000,5,5,5,4,64.720000000,64.870000000,8,4,5,3,64.710000000,64.880000000,8,4,7,3,64.700000000,64.890000000,7,3,6,2,MCLN5
2025-06-11T00:00:00.566233875Z,2025-06-11T00:00:00.563827431Z,10,1,42418117,M,A,1,3.280000000,10,130,11337,79287178,3.240000000,3.270000000,11,1,2,1,3.230000000,3.280000000,1,11,1,2,3.220000000,3.290000000,1,1,1,1,,,0,0,0,0,,,0,0,0,0,,,0,0,0,0,,,0,0,0,0,,,0,0,0,0,,,0,0,0,0,,,0,0,0,0,MCLN5-MCLX5
2025-06-11T00:00:00.566383020Z,2025-06-11T00:00:00.564297425Z,10,1,42025623,M,B,4,63.650000000,1,130,11430,79287188,63.700000000,63.720000000,1,3,1,3,63.690000000,63.730000000,3,2,3,2,63.680000000,63.740000000,1,3,1,3,63.670000000,63.750000000,3,2,3,2,63.660000000,63.760000000,5,5,5,5,63.650000000,63.770000000,4,2,4,2,63.640000000,63.780000000,5,5,5,5,63.630000000,63.790000000,4,1,4,1,63.620000000,63.800000000,3,3,3,3,63.610000000,63.810000000,2,4,2,2,MCLQ5
2025-06-11T00:00:00.566534362Z,2025-06-11T00:00:00.564407321Z,10,1,42026514,C,B,5,64.740000000,1,130,11557,79287198,64.790000000,64.800000000,4,7,2,7,64.780000000,64.810000000,4,3,4,3,64.770000000,64.820000000,9,9,5,6,64.760000000,64.830000000,8,8,8,8,64.750000000,64.840000000,9,8,9,7,64.740000000,64.850000000,9,8,8,5,64.730000000,64.860000000,5,5,5,4,64.720000000,64.870000000,8,4,5,3,64.710000000,64.880000000,8,4,7,3,64.700000000,64.890000000,7,3,6,2,MCLN5
2025-06-11T00:00:00.566622439Z,2025-06-11T00:00:00.564419935Z,10,1,42026514,C,B,1,64.780000000,1,130,11877,79287203,64.790000000,64.800000000,4,7,2,7,64.780000000,64.810000000,3,3,3,3,64.770000000,64.820000000,9,9,5,6,64.760000000,64.830000000,8,8,8,8,64.750000000,64.840000000,9,8,9,7,64.740000000,64.850000000,9,8,8,5,64.730000000,64.860000000,5,5,5,4,64.720000000,64.870000000,8,4,5,3,64.710000000,64.880000000,8,4,7,3,64.700000000,64.890000000,7,3,6,2,MCLN5
2025-06-11T00:00:00.566997856Z,2025-06-11T00:00:00.565263855Z,10,1,42026514,T,A,0,64.790000000,2,0,15106,79287231,64.790000000,64.800000000,4,7,2,7,64.780000000,64.810000000,3,3,3,3,64.770000000,64.820000000,9,9,5,6,64.760000000,64.830000000,8,8,8,8,64.750000000,64.840000000,9,8,9,7,64.740000000,64.850000000,9,8,8,5,64.730000000,64.860000000,5,5,5,4,64.720000000,64.870000000,8,4,5,3,64.710000000,64.880000000,8,4,7,3,64.700000000,64.890000000,7,3,6,2,MCLN5
2025-06-11T00:00:00.567011257Z,2025-06-11T00:00:00.565263855Z,10,1,42026514,C,B,0,64.790000000,2,130,13852,79287232,64.790000000,64.800000000,2,7,1,7,64.780000000,64.810000000,3,3,3,3,64.770000000,64.820000000,9,9,5,6,64.760000000,64.830000000,8,8,8,8,64.750000000,64.840000000,9,8,9,7,64.740000000,64.850000000,9,8,8,5,64.730000000,64.860000000,5,5,5,4,64.720000000,64.870000000,8,4,5,3,64.710000000,64.880000000,8,4,7,3,64.700000000,64.890000000,7,3,6,2,MCLN5
2025-06-11T00:00:00.567018706Z,2025-06-11T00:00:00.565266235Z,10,1,42026514,M,B,4,64.740000000,1,130,11863,79287233,64.790000000,64.800000000,2,7,1,7,64.780000000,64.810000000,3,3,3,3,64.770000000,64.820000000,9,9,5,6,64.760000000,64.830000000,8,8,8,8,64.750000000,64.840000000,8,8,8,7,64.740000000,64.850000000,10,8,9,5,64.730000000,64.860000000,5,5,5,4,64.720000000,64.870000000,8,4,5,3,64.710000000,64.880000000,8,4,7,3,64.700000000,64.890000000,7,3,6,2,MCLN5
2025-06-11T00:00:00.567028221Z,2025-06-11T00:00:00.565266791Z,10,1,42026514,M,A,3,64.830000000,1,130,11653,79287234,64.790000000,64.800000000,2,7,1,7,64.780000000,64.810000000,3,3,3,3,64.770000000,64.820000000,9,9,5,6,64.760000000,64.830000000,8,9,8,9,64.750000000,64.840000000,8,7,8,6,64.740000000,64.850000000,10,8,9,5,64.730000000,64.860000000,5,5,5,4,64.720000000,64.870000000,8,4,5,3,64.710000000,64.880000000,8,4,7,3,64.700000000,64.890000000,7,3,6,2,MCLN5
2025-06-11T00:00:00.567129123Z,2025-06-11T00:00:00.565403183Z,10,1,42026514,C,A,0,64.800000000,1,130,12017,79287239,64.790000000,64.800000000,2,6,1,6,64.780000000,64.810000000,3,3,3,3,64.770000000,64.820000000,9,9,5,6,64.760000000,64.830000000,8,9,8,9,64.750000000,64.840000000,8,7,8,6,64.740000000,64.850000000,10,8,9,5,64.730000000,64.860000000,5,5,5,4,64.720000000,64.870000000,8,4,5,3,64.710000000,64.880000000,8,4,7,3,64.700000000,64.890000000,7,3,6,2,MCLN5
2025-06-11T00:00:00.567139030Z,2025-06-11T00:00:00.565403605Z,10,1,42026514,C,A,0,64.800000000,1,130,13206,79287240,64.790000000,64.800000000,2,5,1,5,64.780000000,64.810000000,3,3,3,3,64.770000000,64.820000000,9,9,5,6,64.760000000,64.830000000,8,9,8,9,64.750000000,64.840000000,8,7,8,6,64.740000000,64.850000000,10,8,9,5,64.730000000,64.860000000,5,5,5,4,64.720000000,64.870000000,8,4,5,3,64.710000000,64.880000000,8,4,7,3,64.700000000,64.890000000,7,3,6,2,MCLN5
2025-06-11T00:00:00.567822875Z,2025-06-11T00:00:00.565831209Z,10,1,42026514,M,A,3,64.840000000,1,130,11615,79287276,64.790000000,64.800000000,2,5,1,5,64.780000000,64.810000000,3,3,3,3,64.770000000,64.820000000,9,9,5,6,64.760000000,64.830000000,8,8,8,8,64.750000000,64.840000000,8,8,8,7,64.740000000,64.850000000,10,8,9,5,64.730000000,64.860000000,5,5,5,4,64.720000000,64.870000000,8,4,5,3,64.710000000,64.880000000,8,4,7,3,64.700000000,64.890000000,7,3,6,2,MCLN5
2025-06-11T00:00:00.567834625Z,2025-06-11T00:00:00.565831765Z,10,1,42026514,M,B,4,64.750000000,1,130,14706,79287277,64.790000000,64.800000000,2,5,1,5,64.780000000,64.810000000,3,3,3,3,64.770000000,64.820000000,9,9,5,6,64.760000000,64.830000000,8,8,8,8,64.750000000,64.840000000,9,8,9,7,64.740000000,64.850000000,9,8,8,5,64.730000000,64.860000000,5,5,5,4,64.720000000,64.870000000,8,4,5,3,64.710000000,64.880000000,8,4,7,3,64.700000000,64.890000000,7,3,6,2,MCLN5
2025-06-11T00:00:00.567846444Z,2025-06-11T00:00:00.565882163Z,10,1,42026514,M,B,1,64.780000000,1,130,12627,79287278,64.790000000,64.800000000,2,5,1,5,64.780000000,64.810000000,4,3,4,3,64.770000000,64.820000000,9,9,5,6,64.760000000,64.830000000,8,8,8,8,64.750000000,64.840000000,9,8,9,7,64.740000000,64.850000000,9,8,8,5,64.730000000,64.860000000,5,5,5,4,64.720000000,64.870000000,8,4,5,3,64.710000000,64.880000000,8,4,7,3,64.700000000,64.890000000,7,3,6,2,MCLN5
2025-06-11T00:00:00.569383200Z,2025-06-11T00:00:00.568153403Z,10,1,42026514,M,B,4,64.740000000,1,130,15042,79287346,64.790000000,64.800000000,2,5,1,5,64.780000000,64.810000000,4,3,4,3,64.770000000,64.820000000,9,9,5,6,64.760000000,64.830000000,8,8,8,8,64.750000000,64.840000000,8,8,8,7,64.740000000,64.850000000,10,8,9,5,64.730000000,64.860000000,5,5,5,4,64.720000000,64.870000000,8,4,5,3,64.710000000,64.880000000,8,4,7,3,64.700000000,64.890000000,7,3,6,2,MCLN5
2025-06-11T00:00:00.569391425Z,2025-06-11T00:00:00.568158547Z,10,1,42026514,A,A,0,64.800000000,1,130,11240,79287347,64.790000000,64.800000000,2,6,1,6,64.780000000,64.810000000,4,3,4,3,64.770000000,64.820000000,9,9,5,6,64.760000000,64.830000000,8,8,8,8,64.750000000,64.840000000,8,8,8,7,64.740000000,64.850000000,10,8,9,5,64.730000000,64.860000000,5,5,5,4,64.720000000,64.870000000,8,4,5,3,64.710000000,64.880000000,8,4,7,3,64.700000000,64.890000000,7,3,6,2,MCLN5
2025-06-11T00:00:00.569584459Z,2025-06-11T00:00:00.568671991Z,10,1,42026514,M,B,1,62.830000000,2,130,15411,79287359,64.790000000,64.800000000,2,6,1,6,64.780000000,64.810000000,3,3,3,3,64.770000000,64.820000000,9,9,5,6,64.760000000,64.830000000,8,8,8,8,64.750000000,64.840000000,8,8,8,7,64.740000000,64.850000000,10,8,9,5,64.730000000,64.860000000,5,5,5,4,64.720000000,64.870000000,8,4,5,3,64.710000000,64.880000000,8,4,7,3,64.700000000,64.890000000,7,3,6,2,MCLN5
2025-06-11T00:00:00.569609648Z,2025-06-11T00:00:00.569048141Z,10,1,42022708,M,A,1,2.840000000,10,130,11496,79287362,2.810000000,2.820000000,1,1,1,1,2.800000000,2.830000000,12,2,3,2,2.790000000,2.840000000,2,12,2,3,2.780000000,2.870000000,1,1,1,1,,,0,0,0,0,,,0,0,0,0,,,0,0,0,0,,,0,0,0,0,,,0,0,0,0,,,0,0,0,0,MCLN5-MCLV5
2025-06-11T00:00:00.570062737Z,2025-06-11T00:00:00.569331541Z,10,1,42026514,C,A,0,64.800000000,1,130,12687,79287388,64.790000000,64.800000000,2,5,1,5,64.780000000,64.810000000,3,3,3,3,64.770000000,64.820000000,9,9,5,6,64.760000000,64.830000000,8,8,8,8,64.750000000,64.840000000,8,8,8,7,64.740000000,64.850000000,10,8,9,5,64.730000000,64.860000000,5,5,5,4,64.720000000,64.870000000,8,4,5,3,64.710000000,64.880000000,8,4,7,3,64.700000000,64.890000000,7,3,6,2,MCLN5
2025-06-11T00:00:00.570594633Z,2025-06-11T00:00:00.569608699Z,10,1,42418117,M,A,1,3.290000000,10,130,15179,79287421,3.240000000,3.270000000,11,1,2,1,3.230000000,3.280000000,1,1,1,1,3.220000000,3.290000000,1,11,1,2,,,0,0,0,0,,,0,0,0,0,,,0,0,0,0,,,0,0,0,0,,,0,0,0,0,,,0,0,0,0,,,0,0,0,0,MCLN5-MCLX5
2025-06-11T00:00:00.576001061Z,2025-06-11T00:00:00.575897207Z,10,1,42026514,A,B,5,64.740000000,1,130,14907,79287480,64.790000000,64.800000000,2,5,1,5,64.780000000,64.810000000,3,3,3,3,64.770000000,64.820000000,9,9,5,6,64.760000000,64.830000000,8,8,8,8,64.750000000,64.840000000,8,8,8,7,64.740000000,64.850000000,11,8,10,5,64.730000000,64.860000000,5,5,5,4,64.720000000,64.870000000,8,4,5,3,64.710000000,64.880000000,8,4,7,3,64.700000000,64.890000000,7,3,6,2,MCLN5
2025-06-11T00:00:00.576131299Z,2025-06-11T00:00:00.576015399Z,10,1,42026514,A,B,0,64.790000000,2,130,16805,79287481,64.790000000,64.800000000,4,5,2,5,64.780000000,64.810000000,3,3,3,3,64.770000000,64.820000000,9,9,5,6,64.760000000,64.830000000,8,8,8,8,64.750000000,64.840000000,8,8,8,7,64.740000000,64.850000000,11,8,10,5,64.730000000,64.860000000,5,5,5,4,64.720000000,64.870000000,8,4,5,3,64.710000000,64.880000000,8,4,7,3,64.700000000,64.890000000,7,3,6,2,MCLN5
2025-06-11T00:00:00.596657008Z,2025-06-11T00:00:00.596537485Z,10,1,42026514,C,B,0,64.790000000,2,130,16584,79287508,64.790000000,64.800000000,2,5,1,5,64.780000000,64.810000000,3,3,3,3,64.770000000,64.820000000,9,9,5,6,64.760000000,64.830000000,8,8,8,8,64.750000000,64.840000000,8,8,8,7,64.740000000,64.850000000,11,8,10,5,64.730000000,64.860000000,5,5,5,4,64.720000000,64.870000000,8,4,5,3,64.710000000,64.880000000,8,4,7,3,64.700000000,64.890000000,7,3,6,2,MCLN5
2025-06-11T00:00:00.613674738Z,2025-06-11T00:00:00.613496921Z,10,1,42022708,M,A,0,2.850000000,1,130,11674,79287692,2.810000000,2.830000000,1,2,1,2,2.800000000,2.840000000,12,12,3,3,2.790000000,2.850000000,2,1,2,1,2.780000000,2.870000000,1,1,1,1,,,0,0,0,0,,,0,0,0,0,,,0,0,0,0,,,0,0,0,0,,,0,0,0,0,,,0,0,0,0,MCLN5-MCLV5
2025-06-11T00:00:00.658256689Z,2025-06-11T00:00:00.658126807Z,10,1,42025623,A,B,0,63.700000000,1,130,12673,79288046,63.700000000,63.720000000,2,3,2,3,63.690000000,63.730000000,3,2,3,2,63.680000000,63.740000000,1,3,1,3,63.670000000,63.750000000,3,2,3,2,63.660000000,63.760000000,5,5,5,5,63.650000000,63.770000000,4,2,4,2,63.640000000,63.780000000,5,5,5,5,63.630000000,63.790000000,4,1,4,1,63.620000000,63.800000000,3,3,3,3,63.610000000,63.810000000,2,4,2,2,MCLQ5
2025-06-11T00:00:00.670881582Z,2025-06-11T00:00:00.670714537Z,10,1,42026514,A,A,0,64.800000000,1,130,12487,79288063,64.790000000,64.800000000,2,6,1,6,64.780000000,64.810000000,3,3,3,3,64.770000000,64.820000000,9,9,5,6,64.760000000,64.830000000,8,8,8,8,64.750000000,64.840000000,8,8,8,7,64.740000000,64.850000000,11,8,10,5,64.730000000,64.860000000,5,5,5,4,64.720000000,64.870000000,8,4,5,3,64.710000000,64.880000000,8,4,7,3,64.700000000,64.890000000,7,3,6,2,MCLN5
2025-06-11T00:00:00.675272553Z,2025-06-11T00:00:00.675078025Z,10,1,42026514,M,A,3,64.830000000,1,130,11592,79288072,64.790000000,64.800000000,2,6,1,6,64.780000000,64.810000000,3,3,3,3,64.770000000,64.820000000,9,9,5,6,64.760000000,64.830000000,8,9,8,9,64.750000000,64.840000000,8,7,8,6,64.740000000,64.850000000,11,8,10,5,64.730000000,64.860000000,5,5,5,4,64.720000000,64.870000000,8,4,5,3,64.710000000,64.880000000,8,4,7,3,64.700000000,64.890000000,7,3,6,2,MCLN5
2025-06-11T00:00:00.675280386Z,2025-06-11T00:00:00.675078715Z,10,1,42026514,M,A,3,64.830000000,1,130,11357,79288073,64.790000000,64.800000000,2,6,1,6,64.780000000,64.810000000,3,3,3,3,64.770000000,64.820000000,9,9,5,6,64.760000000,64.830000000,8,10,8,10,64.750000000,64.840000000,8,6,8,5,64.740000000,64.850000000,11,8,10,5,64.730000000,64.860000000,5,5,5,4,64.720000000,64.870000000,8,4,5,3,64.710000000,64.880000000,8,4,7,3,64.700000000,64.890000000,7,3,6,2,MCLN5
2025-06-11T00:00:00.675296037Z,2025-06-11T00:00:00.675101293Z,10,1,42025623,M,A,4,63.760000000,1,130,11616,79288075,63.700000000,63.720000000,2,3,2,3,63.690000000,63.730000000,3,2,3,2,63.680000000,63.740000000,1,3,1,3,63.670000000,63.750000000,3,2,3,2,63.660000000,63.760000000,5,6,5,6,63.650000000,63.770000000,4,1,4,1,63.640000000,63.780000000,5,5,5,5,63.630000000,63.790000000,4,1,4,1,63.620000000,63.800000000,3,3,3,3,63.610000000,63.810000000,2,4,2,2,MCLQ5
2025-06-11T00:00:00.675995003Z,2025-06-11T00:00:00.675864153Z,10,1,42025611,M,A,0,2.110000000,1,130,11441,79288112,2.070000000,2.080000000,1,3,1,1,2.060000000,2.090000000,23,7,3,5,2.050000000,2.100000000,23,27,3,6,2.040000000,2.110000000,23,23,3,4,2.030000000,2.120000000,2,22,1,2,2.020000000,2.130000000,2,2,2,2,2.010000000,2.140000000,2,2,1,1,2.000000000,2.150000000,2,2,2,1,1.990000000,2.160000000,2,2,1,1,1.980000000,2.170000000,2,2,2,1,MCLN5-MCLU5
2025-06-11T00:00:00.676158993Z,2025-06-11T00:00:00.676051499Z,10,1,42025611,A,B,0,2.070000000,2,130,14513,79288115,2.070000000,2.080000000,3,3,2,1,2.060000000,2.090000000,23,7,3,5,2.050000000,2.100000000,23,27,3,6,2.040000000,2.110000000,23,23,3,4,2.030000000,2.120000000,2,22,1,2,2.020000000,2.130000000,2,2,2,2,2.010000000,2.140000000,2,2,1,1,2.000000000,2.150000000,2,2,2,1,1.990000000,2.160000000,2,2,1,1,1.980000000,2.170000000,2,2,2,1,MCLN5-MCLU5
2025-06-11T00:00:00.676820982Z,2025-06-11T00:00:00.676703501Z,10,1,42026514,M,B,1,64.780000000,1,130,15302,79288117,64.790000000,64.800000000,2,6,1,6,64.780000000,64.810000000,4,3,4,3,64.770000000,64.820000000,9,9,5,6,64.760000000,64.830000000,8,10,8,10,64.750000000,64.840000000,8,6,8,5,64.740000000,64.850000000,11,8,10,5,64.730000000,64.860000000,5,5,5,4,64.720000000,64.870000000,8,4,5,3,64.710000000,64.880000000,8,4,7,3,64.700000000,64.890000000,7,3,6,2,MCLN5
2025-06-11T00:00:00.705022938Z,2025-06-11T00:00:00.704913965Z,10,1,42026514,C,A,0,64.800000000,1,130,17366,79288132,64.790000000,64.800000000,2,5,1,5,64.780000000,64.810000000,4,3,4,3,64.770000000,64.820000000,9,9,5,6,64.760000000,64.830000000,8,10,8,10,64.750000000,64.840000000,8,6,8,5,64.740000000,64.850000000,11,8,10,5,64.730000000,64.860000000,5,5,5,4,64.720000000,64.870000000,8,4,5,3,64.710000000,64.880000000,8,4,7,3,64.700000000,64.890000000,7,3,6,2,MCLN5
2025-06-11T00:00:00.731455737Z,2025-06-11T00:00:00.731327237Z,10,1,42418117,M,B,0,3.250000000,1,130,15614,79288214,3.250000000,3.270000000,1,1,1,1,3.240000000,3.280000000,11,1,2,1,3.230000000,3.290000000,1,11,1,2,,,0,0,0,0,,,0,0,0,0,,,0,0,0,0,,,0,0,0,0,,,0,0,0,0,,,0,0,0,0,,,0,0,0,0,MCLN5-MCLX5
2025-06-11T00:00:00.731566984Z,2025-06-11T00:00:00.731462513Z,10,1,42418117,M,B,0,3.250000000,10,130,15145,79288215,3.250000000,3.270000000,11,1,2,1,3.240000000,3.280000000,1,1,1,1,3.230000000,3.290000000,1,11,1,2,,,0,0,0,0,,,0,0,0,0,,,0,0,0,0,,,0,0,0,0,,,0,0,0,0,,,0,0,0,0,,,0,0,0,0,MCLN5-MCLX5
2025-06-11T00:00:00.737437813Z,2025-06-11T00:00:00.737326759Z,10,1,42026514,C,A,0,64.800000000,1,130,17595,79288236,64.790000000,64.800000000,2,4,1,4,64.780000000,64.810000000,4,3,4,3,64.770000000,64.820000000,9,9,5,6,64.760000000,64.830000000,8,10,8,10,64.750000000,64.840000000,8,6,8,5,64.740000000,64.850000000,11,8,10,5,64.730000000,64.860000000,5,5,5,4,64.720000000,64.870000000,8,4,5,3,64.710000000,64.880000000,8,4,7,3,64.700000000,64.890000000,7,3,6,2,MCLN5
2025-06-11T00:00:00.850444494Z,2025-06-11T00:00:00.850337569Z,10,1,42026514,M,B,4,64.750000000,1,130,11552,79288419,64.790000000,64.800000000,2,4,1,4,64.780000000,64.810000000,4,3,4,3,64.770000000,64.820000000,9,9,5,6,64.760000000,64.830000000,8,10,8,10,64.750000000,64.840000000,9,6,9,5,64.740000000,64.850000000,10,8,9,5,64.730000000,64.860000000,5,5,5,4,64.720000000,64.870000000,8,4,5,3,64.710000000,64.880000000,8,4,7,3,64.700000000,64.890000000,7,3,6,2,MCLN5
2025-06-11T00:00:00.850481940Z,2025-06-11T00:00:00.850340775Z,10,1,42026514,A,A,0,64.800000000,1,130,16469,79288420,64.790000000,64.800000000,2,5,1,5,64.780000000,64.810000000,4,3,4,3,64.770000000,64.820000000,9,9,5,6,64.760000000,64.830000000,8,10,8,10,64.750000000,64.840000000,9,6,9,5,64.740000000,64.850000000,10,8,9,5,64.730000000,64.860000000,5,5,5,4,64.720000000,64.870000000,8,4,5,3,64.710000000,64.880000000,8,4,7,3,64.700000000,64.890000000,7,3,6,2,MCLN5
2025-06-11T00:00:01.000699560Z,2025-06-11T00:00:01.000580679Z,10,1,42026514,C,A,0,64.800000000,1,130,15054,79289140,64.790000000,64.800000000,2,4,1,4,64.780000000,64.810000000,4,3,4,3,64.770000000,64.820000000,9,9,5,6,64.760000000,64.830000000,8,10,8,10,64.750000000,64.840000000,9,6,9,5,64.740000000,64.850000000,10,8,9,5,64.730000000,64.860000000,5,5,5,4,64.720000000,64.870000000,8,4,5,3,64.710000000,64.880000000,8,4,7,3,64.700000000,64.890000000,7,3,6,2,MCLN5
2025-06-11T00:00:01.000823348Z,2025-06-11T00:00:01.000712885Z,10,1,42026514,C,A,0,64.800000000,1,130,14943,79289142,64.790000000,64.800000000,2,3,1,3,64.780000000,64.810000000,4,3,4,3,64.770000000,64.820000000,9,9,5,6,64.760000000,64.830000000,8,10,8,10,64.750000000,64.840000000,9,6,9,5,64.740000000,64.850000000,10,8,9,5,64.730000000,64.860000000,5,5,5,4,64.720000000,64.870000000,8,4,5,3,64.710000000,64.880000000,8,4,7,3,64.700000000,64.890000000,7,3,6,2,MCLN5
2025-06-11T00:00:01.000990710Z,2025-06-11T00:00:01.000842707Z,10,1,42026514,A,A,0,64.800000000,1,130,13585,79289155,64.790000000,64.800000000,2,4,1,4,64.780000000,64.810000000,4,3,4,3,64.770000000,64.820000000,9,9,5,6,64.760000000,64.830000000,8,10,8,10,64.750000000,64.840000000,9,6,9,5,64.740000000,64.850000000,10,8,9,5,64.730000000,64.860000000,5,5,5,4,64.720000000,64.870000000,8,4,5,3,64.710000000,64.880000000,8,4,7,3,64.700000000,64.890000000,7,3,6,2,MCLN5
2025-06-11T00:00:01.001008634Z,2025-06-11T00:00:01.000847105Z,10,1,42026514,A,A,0,64.800000000,1,130,13732,79289156,64.790000000,64.800000000,2,5,1,5,64.780000000,64.810000000,4,3,4,3,64.770000000,64.820000000,9,9,5,6,64.760000000,64.830000000,8,10,8,10,64.750000000,64.840000000,9,6,9,5,64.740000000,64.850000000,10,8,9,5,64.730000000,64.860000000,5,5,5,4,64.720000000,64.870000000,8,4,5,3,64.710000000,64.880000000,8,4,7,3,64.700000000,64.890000000,7,3,6,2,MCLN5
2025-06-11T00:00:01.038894439Z,2025-06-11T00:00:01.038775989Z,10,1,42026514,A,B,0,64.790000000,1,130,16425,79289848,64.790000000,64.800000000,3,5,2,5,64.780000000,64.810000000,4,3,4,3,64.770000000,64.820000000,9,9,5,6,64.760000000,64.830000000,8,10,8,10,64.750000000,64.840000000,9,6,9,5,64.740000000,64.850000000,10,8,9,5,64.730000000,64.860000000,5,5,5,4,64.720000000,64.870000000,8,4,5,3,64.710000000,64.880000000,8,4,7,3,64.700000000,64.890000000,7,3,6,2,MCLN5
2025-06-11T00:00:01.048278422Z,2025-06-11T00:00:01.039966105Z,10,1,42026514,C,B,0,64.790000000,2,130,13043,79289867,64.790000000,64.800000000,1,5,1,5,64.780000000,64.810000000,4,3,4,3,64.770000000,64.820000000,9,9,5,6,64.760000000,64.830000000,8,10,8,10,64.750000000,64.840000000,9,6,9,5,64.740000000,64.850000000,10,8,9,5,64.730000000,64.860000000,5,5,5,4,64.720000000,64.870000000,8,4,5,3,64.710000000,64.880000000,8,4,7,3,64.700000000,64.890000000,7,3,6,2,MCLN5
2025-06-11T00:00:01.048818551Z,2025-06-11T00:00:01.039993983Z,10,1,42026514,T,A,0,64.790000000,1,0,11430,79289897,64.790000000,64.800000000,1,5,1,5,64.780000000,64.810000000,4,3,4,3,64.770000000,64.820000000,9,9,5,6,64.760000000,64.830000000,8,10,8,10,64.750000000,64.840000000,9,6,9,5,64.740000000,64.850000000,10,8,9,5,64.730000000,64.860000000,5,5,5,4,64.720000000,64.870000000,8,4,5,3,64.710000000,64.880000000,8,4,7,3,64.700000000,64.890000000,7,3,6,2,MCLN5
2025-06-11T00:00:01.048848409Z,2025-06-11T00:00:01.039993983Z,10,1,42026514,A,N,0,64.790000000,1,130,11514,79289898,64.780000000,64.790000000,4,1,4,1,64.770000000,64.800000000,9,5,5,5,64.760000000,64.810000000,8,3,8,3,64.750000000,64.820000000,9,9,9,6,64.740000000,64.830000000,10,10,9,10,64.730000000,64.840000000,5,6,5,5,64.720000000,64.850000000,8,8,5,5,64.710000000,64.860000000,8,5,7,4,64.700000000,64.870000000,7,4,6,3,64.690000000,64.880000000,4,4,3,3,MCLN5
2025-06-11T00:00:01.048938391Z,2025-06-11T00:00:01.040001719Z,10,1,42026514,A,A,0,64.790000000,2,130,13144,79289904,64.780000000,64.790000000,4,3,4,2,64.770000000,64.800000000,9,5,5,5,64.760000000,64.810000000,8,3,8,3,64.750000000,64.820000000,9,9,9,6,64.740000000,64.830000000,10,10,9,10,64.730000000,64.840000000,5,6,5,5,64.720000000,64.850000000,8,8,5,5,64.710000000,64.860000000,8,5,7,4,64.700000000,64.870000000,7,4,6,3,64.690000000,64.880000000,4,4,3,3,MCLN5
2025-06-11T00:00:01.048978579Z,2025-06-11T00:00:01.040005001Z,10,1,42026514,A,A,1,64.800000000,1,130,15292,79289907,64.780000000,64.790000000,4,3,4,2,64.770000000,64.800000000,9,6,5,6,64.760000000,64.810000000,8,3,8,3,64.750000000,64.820000000,9,9,9,6,64.740000000,64.830000000,10,10,9,10,64.730000000,64.840000000,5,6,5,5,64.720000000,64.850000000,8,8,5,5,64.710000000,64.860000000,8,5,7,4,64.700000000,64.870000000,7,4,6,3,64.690000000,64.880000000,4,4,3,3,MCLN5
2025-06-11T00:00:01.049208252Z,2025-06-11T00:00:01.041111757Z,10,1,42026514,C,A,0,64.790000000,2,130,11487,79289924,64.780000000,64.790000000,4,1,4,1,64.770000000,64.800000000,9,6,5,6,64.760000000,64.810000000,8,3,8,3,64.750000000,64.820000000,9,9,9,6,64.740000000,64.830000000,10,10,9,10,64.730000000,64.840000000,5,6,5,5,64.720000000,64.850000000,8,8,5,5,64.710000000,64.860000000,8,5,7,4,64.700000000,64.870000000,7,4,6,3,64.690000000,64.880000000,4,4,3,3,MCLN5
2025-06-11T00:00:01.049246435Z,2025-06-11T00:00:01.041112063Z,10,1,42026514,C,A,0,64.790000000,1,130,11589,79289926,64.780000000,64.800000000,4,6,4,6,64.770000000,64.810000000,9,3,5,3,64.760000000,64.820000000,8,9,8,6,64.750000000,64.830000000,9,10,9,10,64.740000000,64.840000000,10,6,9,5,64.730000000,64.850000000,5,8,5,5,64.720000000,64.860000000,8,5,5,4,64.710000000,64.870000000,8,4,7,3,64.700000000,64.880000000,7,4,6,3,64.690000000,64.890000000,4,3,3,2,MCLN5
2025-06-11T00:00:01.049851894Z,2025-06-11T00:00:01.048827357Z,10,1,42026514,C,B,4,64.740000000,1,130,11494,79289969,64.780000000,64.800000000,4,6,4,6,64.770000000,64.810000000,9,3,5,3,64.760000000,64.820000000,8,9,8,6,64.750000000,64.830000000,9,10,9,10,64.740000000,64.840000000,9,6,8,5,64.730000000,64.850000000,5,8,5,5,64.720000000,64.860000000,8,5,5,4,64.710000000,64.870000000,8,4,7,3,64.700000000,64.880000000,7,4,6,3,64.690000000,64.890000000,4,3,3,2,MCLN5
2025-06-11T00:00:01.049915366Z,2025-06-11T00:00:01.048949059Z,10,1,42025623,M,B,4,63.650000000,1,130,11180,79289972,63.700000000,63.720000000,2,3,2,3,63.690000000,63.730000000,3,2,3,2,63.680000000,63.740000000,1,3,1,3,63.670000000,63.750000000,3,2,3,2,63.660000000,63.760000000,4,6,4,6,63.650000000,63.770000000,5,1,5,1,63.640000000,63.780000000,5,5,5,5,63.630000000,63.790000000,4,1,4,1,63.620000000,63.800000000,3,3,3,3,63.610000000,63.810000000,2,4,2,2,MCLQ5
2025-06-11T00:00:01.049922838Z,2025-06-11T00:00:01.048949541Z,10,1,42025623,M,A,3,63.750000000,1,130,11419,79289973,63.700000000,63.720000000,2,3,2,3,63.690000000,63.730000000,3,2,3,2,63.680000000,63.740000000,1,3,1,3,63.670000000,63.750000000,3,3,3,3,63.660000000,63.760000000,4,5,4,5,63.650000000,63.770000000,5,1,5,1,63.640000000,63.780000000,5,5,5,5,63.630000000,63.790000000,4,1,4,1,63.620000000,63.800000000,3,3,3,3,63.610000000,63.810000000,2,4,2,2,MCLQ5
2025-06-11T00:00:01.049931386Z,2025-06-11T00:00:01.048950019Z,10,1,42025623,M,B,4,63.650000000,1,130,11706,79289974,63.700000000,63.720000000,2,3,2,3,63.690000000,63.730000000,3,2,3,2,63.680000000,63.740000000,1,3,1,3,63.670000000,63.750000000,3,3,3,3,63.660000000,63.760000000,3,5,3,5,63.650000000,63.770000000,6,1,6,1,63.640000000,63.780000000,5,5,5,5,63.630000000,63.790000000,4,1,4,1,63.620000000,63.800000000,3,3,3,3,63.610000000,63.810000000,2,4,2,2,MCLQ5
2025-06-11T00:00:01.049939511Z,2025-06-11T00:00:01.048950559Z,10,1,42025623,M,A,3,63.750000000,1,130,11519,79289975,63.700000000,63.720000000,2,3,2,3,63.690000000,63.730000000,3,2,3,2,63.680000000,63.740000000,1,3,1,3,63.670000000,63.750000000,3,4,3,4,63.660000000,63.760000000,3,4,3,4,63.650000000,63.770000000,6,1,6,1,63.640000000,63.780000000,5,5,5,5,63.630000000,63.790000000,4,1,4,1,63.620000000,63.800000000,3,3,3,3,63.610000000,63.810000000,2,4,2,2,MCLQ5
2025-06-11T00:00:01.050118699Z,2025-06-11T00:00:01.049117763Z,10,1,42026514,M,A,1,64.810000000,1,130,12312,79289992,64.780000000,64.800000000,4,6,4,6,64.770000000,64.810000000,9,4,5,4,64.760000000,64.820000000,8,9,8,6,64.750000000,64.830000000,9,10,9,10,64.740000000,64.840000000,9,6,8,5,64.730000000,64.850000000,5,8,5,5,64.720000000,64.860000000,8,5,5,4,64.710000000,64.870000000,8,4,7,3,64.700000000,64.880000000,7,4,6,3,64.690000000,64.890000000,4,3,3,2,MCLN5
2025-06-11T00:00:01.050157581Z,2025-06-11T00:00:01.049175725Z,10,1,42026514,M,B,3,64.740000000,1,130,11493,79289994,64.780000000,64.800000000,4,6,4,6,64.770000000,64.810000000,9,4,5,4,64.760000000,64.820000000,8,9,8,6,64.750000000,64.830000000,8,10,8,10,64.740000000,64.840000000,10,6,9,5,64.730000000,64.850000000,5,8,5,5,64.720000000,64.860000000,8,5,5,4,64.710000000,64.870000000,8,4,7,3,64.700000000,64.880000000,7,4,6,3,64.690000000,64.890000000,4,3,3,2,MCLN5
2025-06-11T00:00:01.050167334Z,2025-06-11T00:00:01.049176169Z,10,1,42026514,M,A,3,64.830000000,1,130,11519,79289995,64.780000000,64.800000000,4,6,4,6,64.770000000,64.810000000,9,4,5,4,64.760000000,64.820000000,8,9,8,6,64.750000000,64.830000000,8,11,8,11,64.740000000,64.840000000,10,5,9,4,64.730000000,64.850000000,5,8,5,5,64.720000000,64.860000000,8,5,5,4,64.710000000,64.870000000,8,4,7,3,64.700000000,64.880000000,7,4,6,3,64.690000000,64.890000000,4,3,3,2,MCLN5
2025-06-11T00:00:01.050679624Z,2025-06-11T00:00:01.049484219Z,10,1,42026514,M,B,0,62.830000000,2,130,13730,79290022,64.780000000,64.800000000,3,6,3,6,64.770000000,64.810000000,9,4,5,4,64.760000000,64.820000000,8,9,8,6,64.750000000,64.830000000,8,11,8,11,64.740000000,64.840000000,10,5,9,4,64.730000000,64.850000000,5,8,5,5,64.720000000,64.860000000,8,5,5,4,64.710000000,64.870000000,8,4,7,3,64.700000000,64.880000000,7,4,6,3,64.690000000,64.890000000,4,3,3,2,MCLN5
2025-06-11T00:00:01.051070170Z,2025-06-11T00:00:01.049973815Z,10,1,42026514,C,A,1,64.810000000,1,130,12746,79290054,64.780000000,64.800000000,3,6,3,6,64.770000000,64.810000000,9,3,5,3,64.760000000,64.820000000,8,9,8,6,64.750000000,64.830000000,8,11,8,11,64.740000000,64.840000000,10,5,9,4,64.730000000,64.850000000,5,8,5,5,64.720000000,64.860000000,8,5,5,4,64.710000000,64.870000000,8,4,7,3,64.700000000,64.880000000,7,4,6,3,64.690000000,64.890000000,4,3,3,2,MCLN5
2025-06-11T00:00:01.051120264Z,2025-06-11T00:00:01.050253701Z,10,1,42026514,M,A,3,64.840000000,1,130,12452,79290059,64.780000000,64.800000000,3,6,3,6,64.770000000,64.810000000,9,3,5,3,64.760000000,64.820000000,8,9,8,6,64.750000000,64.830000000,8,10,8,10,64.740000000,64.840000000,10,6,9,5,64.730000000,64.850000000,5,8,5,5,64.720000000,64.860000000,8,5,5,4,64.710000000,64.870000000,8,4,7,3,64.700000000,64.880000000,7,4,6,3,64.690000000,64.890000000,4,3,3,2,MCLN5
2025-06-11T00:00:01.051253029Z,2025-06-11T00:00:01.050277489Z,10,1,42025623,M,A,3,63.760000000,1,130,11923,79290066,63.700000000,63.720000000,2,3,2,3,63.690000000,63.730000000,3,2,3,2,63.680000000,63.740000000,1,3,1,3,63.670000000,63.750000000,3,3,3,3,63.660000000,63.760000000,3,5,3,5,63.650000000,63.770000000,6,1,6,1,63.640000000,63.780000000,5,5,5,5,63.630000000,63.790000000,4,1,4,1,63.620000000,63.800000000,3,3,3,3,63.610000000,63.810000000,2,4,2,2,MCLQ5
2025-06-11T00:00:01.051253029Z,2025-06-11T00:00:01.050277989Z,10,1,42025623,M,B,4,63.660000000,1,130,11923,79290066,63.700000000,63.720000000,2,3,2,3,63.690000000,63.730000000,3,2,3,2,63.680000000,63.740000000,1,3,1,3,63.670000000,63.750000000,3,3,3,3,63.660000000,63.760000000,4,5,4,5,63.650000000,63.770000000,5,1,5,1,63.640000000,63.780000000,5,5,5,5,63.630000000,63.790000000,4,1,4,1,63.620000000,63.800000000,3,3,3,3,63.610000000,63.810000000,2,4,2,2,MCLQ5
2025-06-11T00:00:01.051261953Z,2025-06-11T00:00:01.050278449Z,10,1,42025623,M,A,3,63.760000000,1,130,12276,79290067,63.700000000,63.720000000,2,3,2,3,63.690000000,63.730000000,3,2,3,2,63.680000000,63.740000000,1,3,1,3,63.670000000,63.750000000,3,2,3,2,63.660000000,63.760000000,4,6,4,6,63.650000000,63.770000000,5,1,5,1,63.640000000,63.780000000,5,5,5,5,63.630000000,63.790000000,4,1,4,1,63.620000000,63.800000000,3,3,3,3,63.610000000,63.810000000,2,4,2,2,MCLQ5
2025-06-11T00:00:01.051269786Z,2025-06-11T00:00:01.050278851Z,10,1,42025623,M,B,4,63.660000000,1,130,11273,79290068,63.700000000,63.720000000,2,3,2,3,63.690000000,63.730000000,3,2,3,2,63.680000000,63.740000000,1,3,1,3,63.670000000,63.750000000,3,2,3,2,63.660000000,63.760000000,5,6,5,6,63.650000000,63.770000000,4,1,4,1,63.640000000,63.780000000,5,5,5,5,63.630000000,63.790000000,4,1,4,1,63.620000000,63.800000000,3,3,3,3,63.610000000,63.810000000,2,4,2,2,MCLQ5
2025-06-11T00:00:01.051867781Z,2025-06-11T00:00:01.051081107Z,10,1,42026514,A,B,0,64.780000000,1,130,13450,79290106,64.780000000,64.800000000,4,6,4,6,64.770000000,64.810000000,9,3,5,3,64.760000000,64.820000000,8,9,8,6,64.750000000,64.830000000,8,10,8,10,64.740000000,64.840000000,10,6,9,5,64.730000000,64.850000000,5,8,5,5,64.720000000,64.860000000,8,5,5,4,64.710000000,64.870000000,8,4,7,3,64.700000000,64.880000000,7,4,6,3,64.690000000,64.890000000,4,3,3,2,MCLN5
2025-06-11T00:00:01.052144446Z,2025-06-11T00:00:01.051630915Z,10,1,42026514,C,B,0,64.780000000,1,130,13131,79290122,64.780000000,64.800000000,3,6,3,6,64.770000000,64.810000000,9,3,5,3,64.760000000,64.820000000,8,9,8,6,64.750000000,64.830000000,8,10,8,10,64.740000000,64.840000000,10,6,9,5,64.730000000,64.850000000,5,8,5,5,64.720000000,64.860000000,8,5,5,4,64.710000000,64.870000000,8,4,7,3,64.700000000,64.880000000,7,4,6,3,64.690000000,64.890000000,4,3,3,2,MCLN5
2025-06-11T00:00:01.053502230Z,2025-06-11T00:00:01.052013283Z,10,1,42026514,M,B,0,64.780000000,1,130,13239,79290139,64.780000000,64.800000000,4,6,4,6,64.770000000,64.810000000,9,3,5,3,64.760000000,64.820000000,8,9,8,6,64.750000000,64.830000000,8,10,8,10,64.740000000,64.840000000,10,6,9,5,64.730000000,64.850000000,5,8,5,5,64.720000000,64.860000000,8,5,5,4,64.710000000,64.870000000,8,4,7,3,64.700000000,64.880000000,7,4,6,3,64.690000000,64.890000000,4,3,3,2,MCLN5
2025-06-11T00:00:01.053828320Z,2025-06-11T00:00:01.052274835Z,10,1,42026514,A,B,0,64.790000000,2,130,15617,79290157,64.790000000,64.800000000,2,6,1,6,64.780000000,64.810000000,4,3,4,3,64.770000000,64.820000000,9,9,5,6,64.760000000,64.830000000,8,10,8,10,64.750000000,64.840000000,8,6,8,5,64.740000000,64.850000000,10,8,9,5,64.730000000,64.860000000,5,5,5,4,64.720000000,64.870000000,8,4,5,3,64.710000000,64.880000000,8,4,7,3,64.700000000,64.890000000,7,3,6,2,MCLN5
2025-06-11T00:00:01.053839379Z,2025-06-11T00:00:01.052275009Z,10,1,42026514,A,B,1,64.780000000,1,130,12057,79290158,64.790000000,64.800000000,2,6,1,6,64.780000000,64.810000000,5,3,5,3,64.770000000,64.820000000,9,9,5,6,64.760000000,64.830000000,8,10,8,10,64.750000000,64.840000000,8,6,8,5,64.740000000,64.850000000,10,8,9,5,64.730000000,64.860000000,5,5,5,4,64.720000000,64.870000000,8,4,5,3,64.710000000,64.880000000,8,4,7,3,64.700000000,64.890000000,7,3,6,2,MCLN5
2025-06-11T00:00:01.054813835Z,2025-06-11T00:00:01.053560389Z,10,1,42026514,C,B,0,64.790000000,2,130,13000,79290213,64.780000000,64.800000000,5,6,5,6,64.770000000,64.810000000,9,3,5,3,64.760000000,64.820000000,8,9,8,6,64.750000000,64.830000000,8,10,8,10,64.740000000,64.840000000,10,6,9,5,64.730000000,64.850000000,5,8,5,5,64.720000000,64.860000000,8,5,5,4,64.710000000,64.870000000,8,4,7,3,64.700000000,64.880000000,7,4,6,3,64.690000000,64.890000000,4,3,3,2,MCLN5
2025-06-11T00:00:01.055593821Z,2025-06-11T00:00:01.053958599Z,10,1,42026514,A,B,0,64.790000000,2,130,15808,79290255,64.790000000,64.800000000,2,6,1,6,64.780000000,64.810000000,5,3,5,3,64.770000000,64.820000000,9,9,5,6,64.760000000,64.830000000,8,10,8,10,64.750000000,64.840000000,8,6,8,5,64.740000000,64.850000000,10,8,9,5,64.730000000,64.860000000,5,5,5,4,64.720000000,64.870000000,8,4,5,3,64.710000000,64.880000000,8,4,7,3,64.700000000,64.890000000,7,3,6,2,MCLN5
2025-06-11T00:00:01.055965560Z,2025-06-11T00:00:01.054427827Z,10,1,42026514,C,A,0,64.800000000,1,130,13120,79290274,64.790000000,64.800000000,2,5,1,5,64.780000000,64.810000000,5,3,5,3,64.770000000,64.820000000,9,9,5,6,64.760000000,64.830000000,8,10,8,10,64.750000000,64.840000000,8,6,8,5,64.740000000,64.850000000,10,8,9,5,64.730000000,64.860000000,5,5,5,4,64.720000000,64.870000000,8,4,5,3,64.710000000,64.880000000,8,4,7,3,64.700000000,64.890000000,7,3,6,2,MCLN5
2025-06-11T00:00:01.056336730Z,2025-06-11T00:00:01.054694581Z,10,1,42418117,M,A,0,3.300000000,1,130,12900,79290297,3.250000000,3.280000000,11,1,2,1,3.240000000,3.290000000,1,11,1,2,3.230000000,3.300000000,1,1,1,1,,,0,0,0,0,,,0,0,0,0,,,0,0,0,0,,,0,0,0,0,,,0,0,0,0,,,0,0,0,0,,,0,0,0,0,MCLN5-MCLX5
2025-06-11T00:00:01.056440650Z,2025-06-11T00:00:01.055092309Z,10,1,42026514,A,A,0,64.800000000,1,130,11737,79290303,64.790000000,64.800000000,2,6,1,6,64.780000000,64.810000000,5,3,5,3,64.770000000,64.820000000,9,9,5,6,64.760000000,64.830000000,8,10,8,10,64.750000000,64.840000000,8,6,8,5,64.740000000,64.850000000,10,8,9,5,64.730000000,64.860000000,5,5,5,4,64.720000000,64.870000000,8,4,5,3,64.710000000,64.880000000,8,4,7,3,64.700000000,64.890000000,7,3,6,2,MCLN5
2025-06-11T00:00:01.056621905Z,2025-06-11T00:00:01.055605597Z,10,1,42026514,C,A,0,64.800000000,1,130,12842,79290315,64.790000000,64.800000000,2,5,1,5,64.780000000,64.810000000,5,3,5,3,64.770000000,64.820000000,9,9,5,6,64.760000000,64.830000000,8,10,8,10,64.750000000,64.840000000,8,6,8,5,64.740000000,64.850000000,10,8,9,5,64.730000000,64.860000000,5,5,5,4,64.720000000,64.870000000,8,4,5,3,64.710000000,64.880000000,8,4,7,3,64.700000000,64.890000000,7,3,6,2,MCLN5
2025-06-11T00:00:01.056898193Z,2025-06-11T00:00:01.056053093Z,10,1,42026514,A,A,0,64.800000000,1,130,15084,79290332,64.790000000,64.800000000,2,6,1,6,64.780000000,64.810000000,5,3,5,3,64.770000000,64.820000000,9,9,5,6,64.760000000,64.830000000,8,10,8,10,64.750000000,64.840000000,8,6,8,5,64.740000000,64.850000000,10,8,9,5,64.730000000,64.860000000,5,5,5,4,64.720000000,64.870000000,8,4,5,3,64.710000000,64.880000000,8,4,7,3,64.700000000,64.890000000,7,3,6,2,MCLN5
2025-06-11T00:00:01.057167563Z,2025-06-11T00:00:01.056175123Z,10,1,42026514,T,B,0,64.800000000,1,0,11630,79290350,64.790000000,64.800000000,2,6,1,6,64.780000000,64.810000000,5,3,5,3,64.770000000,64.820000000,9,9,5,6,64.760000000,64.830000000,8,10,8,10,64.750000000,64.840000000,8,6,8,5,64.740000000,64.850000000,10,8,9,5,64.730000000,64.860000000,5,5,5,4,64.720000000,64.870000000,8,4,5,3,64.710000000,64.880000000,8,4,7,3,64.700000000,64.890000000,7,3,6,2,MCLN5
2025-06-11T00:00:01.057167563Z,2025-06-11T00:00:01.056175123Z,10,1,42026514,C,A,0,64.800000000,1,130,11630,79290350,64.790000000,64.800000000,2,5,1,5,64.780000000,64.810000000,5,3,5,3,64.770000000,64.820000000,9,9,5,6,64.760000000,64.830000000,8,10,8,10,64.750000000,64.840000000,8,6,8,5,64.740000000,64.850000000,10,8,9,5,64.730000000,64.860000000,5,5,5,4,64.720000000,64.870000000,8,4,5,3,64.710000000,64.880000000,8,4,7,3,64.700000000,64.890000000,7,3,6,2,MCLN5
2025-06-11T00:00:01.057823531Z,2025-06-11T00:00:01.057183999Z,10,1,42026514,C,A,0,64.800000000,1,130,16753,79290392,64.790000000,64.800000000,2,4,1,4,64.780000000,64.810000000,5,3,5,3,64.770000000,64.820000000,9,9,5,6,64.760000000,64.830000000,8,10,8,10,64.750000000,64.840000000,8,6,8,5,64.740000000,64.850000000,10,8,9,5,64.730000000,64.860000000,5,5,5,4,64.720000000,64.870000000,8,4,5,3,64.710000000,64.880000000,8,4,7,3,64.700000000,64.890000000,7,3,6,2,MCLN5
2025-06-11T00:00:01.057906762Z,2025-06-11T00:00:01.057390679Z,10,1,42026514,T,B,0,64.800000000,1,0,11499,79290398,64.790000000,64.800000000,2,4,1,4,64.780000000,64.810000000,5,3,5,3,64.770000000,64.820000000,9,9,5,6,64.760000000,64.830000000,8,10,8,10,64.750000000,64.840000000,8,6,8,5,64.740000000,64.850000000,10,8,9,5,64.730000000,64.860000000,5,5,5,4,64.720000000,64.870000000,8,4,5,3,64.710000000,64.880000000,8,4,7,3,64.700000000,64.890000000,7,3,6,2,MCLN5
2025-06-11T00:00:01.057924855Z,2025-06-11T00:00:01.057390679Z,10,1,42026514,C,A,0,64.800000000,1,130,16847,79290399,64.790000000,64.800000000,2,3,1,3,64.780000000,64.810000000,5,3,5,3,64.770000000,64.820000000,9,9,5,6,64.760000000,64.830000000,8,10,8,10,64.750000000,64.840000000,8,6,8,5,64.740000000,64.850000000,10,8,9,5,64.730000000,64.860000000,5,5,5,4,64.720000000,64.870000000,8,4,5,3,64.710000000,64.880000000,8,4,7,3,64.700000000,64.890000000,7,3,6,2,MCLN5
2025-06-11T00:00:01.057993565Z,2025-06-11T00:00:01.057500823Z,10,1,42026514,A,A,0,64.800000000,1,130,11819,79290404,64.790000000,64.800000000,2,4,1,4,64.780000000,64.810000000,5,3,5,3,64.770000000,64.820000000,9,9,5,6,64.760000000,64.830000000,8,10,8,10,64.750000000,64.840000000,8,6,8,5,64.740000000,64.850000000,10,8,9,5,64.730000000,64.860000000,5,5,5,4,64.720000000,64.870000000,8,4,5,3,64.710000000,64.880000000,8,4,7,3,64.700000000,64.890000000,7,3,6,2,MCLN5
2025-06-11T00:00:01.058219229Z,2025-06-11T00:00:01.057834717Z,10,1,42026514,A,B,0,64.790000000,1,130,11684,79290419,64.790000000,64.800000000,3,4,2,4,64.780000000,64.810000000,5,3,5,3,64.770000000,64.820000000,9,9,5,6,64.760000000,64.830000000,8,10,8,10,64.750000000,64.840000000,8,6,8,5,64.740000000,64.850000000,10,8,9,5,64.730000000,64.860000000,5,5,5,4,64.720000000,64.870000000,8,4,5,3,64.710000000,64.880000000,8,4,7,3,64.700000000,64.890000000,7,3,6,2,MCLN5
2025-06-11T00:00:01.058403278Z,2025-06-11T00:00:01.057919597Z,10,1,42026514,T,B,0,64.800000000,1,0,10946,79290433,64.790000000,64.800000000,3,4,2,4,64.780000000,64.810000000,5,3,5,3,64.770000000,64.820000000,9,9,5,6,64.760000000,64.830000000,8,10,8,10,64.750000000,64.840000000,8,6,8,5,64.740000000,64.850000000,10,8,9,5,64.730000000,64.860000000,5,5,5,4,64.720000000,64.870000000,8,4,5,3,64.710000000,64.880000000,8,4,7,3,64.700000000,64.890000000,7,3,6,2,MCLN5
2025-06-11T00:00:01.058403278Z,2025-06-11T00:00:01.057919597Z,10,1,42026514,C,A,0,64.800000000,1,130,10946,79290433,64.790000000,64.800000000,3,3,2,3,64.780000000,64.810000000,5,3,5,3,64.770000000,64.820000000,9,9,5,6,64.760000000,64.830000000,8,10,8,10,64.750000000,64.840000000,8,6,8,5,64.740000000,64.850000000,10,8,9,5,64.730000000,64.860000000,5,5,5,4,64.720000000,64.870000000,8,4,5,3,64.710000000,64.880000000,8,4,7,3,64.700000000,64.890000000,7,3,6,2,MCLN5
2025-06-11T00:00:01.058506976Z,2025-06-11T00:00:01.058410037Z,10,1,42026514,M,A,3,64.840000000,1,130,15440,79290437,64.790000000,64.800000000,3,3,2,3,64.780000000,64.810000000,5,3,5,3,64.770000000,64.820000000,9,9,5,6,64.760000000,64.830000000,8,9,8,9,64.750000000,64.840000000,8,7,8,6,64.740000000,64.850000000,10,8,9,5,64.730000000,64.860000000,5,5,5,4,64.720000000,64.870000000,8,4,5,3,64.710000000,64.880000000,8,4,7,3,64.700000000,64.890000000,7,3,6,2,MCLN5
2025-06-11T00:00:01.058515984Z,2025-06-11T00:00:01.058410537Z,10,1,42026514,M,B,3,64.760000000,1,130,11511,79290438,64.790000000,64.800000000,3,3,2,3,64.780000000,64.810000000,5,3,5,3,64.770000000,64.820000000,9,9,5,6,64.760000000,64.830000000,9,9,9,9,64.750000000,64.840000000,7,7,7,6,64.740000000,64.850000000,10,8,9,5,64.730000000,64.860000000,5,5,5,4,64.720000000,64.870000000,8,4,5,3,64.710000000,64.880000000,8,4,7,3,64.700000000,64.890000000,7,3,6,2,MCLN5
2025-06-11T00:00:01.058524132Z,2025-06-11T00:00:01.058411035Z,10,1,42026514,M,A,3,64.840000000,1,130,11195,79290439,64.790000000,64.800000000,3,3,2,3,64.780000000,64.810000000,5,3,5,3,64.770000000,64.820000000,9,9,5,6,64.760000000,64.830000000,9,8,9,8,64.750000000,64.840000000,7,8,7,7,64.740000000,64.850000000,10,8,9,5,64.730000000,64.860000000,5,5,5,4,64.720000000,64.870000000,8,4,5,3,64.710000000,64.880000000,8,4,7,3,64.700000000,64.890000000,7,3,6,2,MCLN5
2025-06-11T00:00:01.058551579Z,2025-06-11T00:00:01.058411537Z,10,1,42026514,M,B,3,64.760000000,1,130,11265,79290440,64.790000000,64.800000000,3,3,2,3,64.780000000,64.810000000,5,3,5,3,64.770000000,64.820000000,9,9,5,6,64.760000000,64.830000000,10,8,10,8,64.750000000,64.840000000,6,8,6,7,64.740000000,64.850000000,10,8,9,5,64.730000000,64.860000000,5,5,5,4,64.720000000,64.870000000,8,4,5,3,64.710000000,64.880000000,8,4,7,3,64.700000000,64.890000000,7,3,6,2,MCLN5
2025-06-11T00:00:01.065714953Z,2025-06-11T00:00:01.065621201Z,10,1,42026514,A,B,5,64.740000000,1,130,14880,79290494,64.790000000,64.800000000,3,3,2,3,64.780000000,64.810000000,5,3,5,3,64.770000000,64.820000000,9,9,5,6,64.760000000,64.830000000,10,8,10,8,64.750000000,64.840000000,6,8,6,7,64.740000000,64.850000000,11,8,10,5,64.730000000,64.860000000,5,5,5,4,64.720000000,64.870000000,8,4,5,3,64.710000000,64.880000000,8,4,7,3,64.700000000,64.890000000,7,3,6,2,MCLN5
2025-06-11T00:00:01.245812333Z,2025-06-11T00:00:01.245619249Z,10,1,42026514,M,B,4,64.750000000,1,130,11502,79290941,64.790000000,64.800000000,3,3,2,3,64.780000000,64.810000000,5,3,5,3,64.770000000,64.820000000,9,9,5,6,64.760000000,64.830000000,10,8,10,8,64.750000000,64.840000000,7,8,7,7,64.740000000,64.850000000,10,8,9,5,64.730000000,64.860000000,5,5,5,4,64.720000000,64.870000000,8,4,5,3,64.710000000,64.880000000,8,4,7,3,64.700000000,64.890000000,7,3,6,2,MCLN5
2025-06-11T00:00:01.245974265Z,2025-06-11T00:00:01.245625299Z,10,1,42026514,A,B,0,64.790000000,2,130,17206,79290947,64.790000000,64.800000000,5,3,3,3,64.780000000,64.810000000,5,3,5,3,64.770000000,64.820000000,9,9,5,6,64.760000000,64.830000000,10,8,10,8,64.750000000,64.840000000,7,8,7,7,64.740000000,64.850000000,10,8,9,5,64.730000000,64.860000000,5,5,5,4,64.720000000,64.870000000,8,4,5,3,64.710000000,64.880000000,8,4,7,3,64.700000000,64.890000000,7,3,6,2,MCLN5
2025-06-11T00:00:01.246478953Z,2025-06-11T00:00:01.245990063Z,10,1,42025623,M,A,4,63.770000000,1,130,13539,79290981,63.700000000,63.720000000,2,3,2,3,63.690000000,63.730000000,3,2,3,2,63.680000000,63.740000000,1,3,1,3,63.670000000,63.750000000,3,2,3,2,63.660000000,63.760000000,5,5,5,5,63.650000000,63.770000000,4,2,4,2,63.640000000,63.780000000,5,5,5,5,63.630000000,63.790000000,4,1,4,1,63.620000000,63.800000000,3,3,3,3,63.610000000,63.810000000,2,4,2,2,MCLQ5
2025-06-11T00:00:01.246489904Z,2025-06-11T00:00:01.245990581Z,10,1,42025623,M,B,4,63.660000000,1,130,11340,79290982,63.700000000,63.720000000,2,3,2,3,63.690000000,63.730000000,3,2,3,2,63.680000000,63.740000000,1,3,1,3,63.670000000,63.750000000,3,2,3,2,63.660000000,63.760000000,6,5,6,5,63.650000000,63.770000000,3,2,3,2,63.640000000,63.780000000,5,5,5,5,63.630000000,63.790000000,4,1,4,1,63.620000000,63.800000000,3,3,3,3,63.610000000,63.810000000,2,4,2,2,MCLQ5
2025-06-11T00:00:01.246894741Z,2025-06-11T00:00:01.246571471Z,10,1,42026514,M,B,3,64.750000000,1,130,11476,79291010,64.790000000,64.800000000,5,3,3,3,64.780000000,64.810000000,5,3,5,3,64.770000000,64.820000000,9,9,5,6,64.760000000,64.830000000,9,8,9,8,64.750000000,64.840000000,8,8,8,7,64.740000000,64.850000000,10,8,9,5,64.730000000,64.860000000,5,5,5,4,64.720000000,64.870000000,8,4,5,3,64.710000000,64.880000000,8,4,7,3,64.700000000,64.890000000,7,3,6,2,MCLN5
2025-06-11T00:00:01.246902498Z,2025-06-11T00:00:01.246572009Z,10,1,42026514,M,A,3,64.830000000,1,130,11747,79291011,64.790000000,64.800000000,5,3,3,3,64.780000000,64.810000000,5,3,5,3,64.770000000,64.820000000,9,9,5,6,64.760000000,64.830000000,9,9,9,9,64.750000000,64.840000000,8,7,8,6,64.740000000,64.850000000,10,8,9,5,64.730000000,64.860000000,5,5,5,4,64.720000000,64.870000000,8,4,5,3,64.710000000,64.880000000,8,4,7,3,64.700000000,64.890000000,7,3,6,2,MCLN5
2025-06-11T00:00:01.246911521Z,2025-06-11T00:00:01.246572545Z,10,1,42026514,M,B,3,64.750000000,1,130,11840,79291012,64.790000000,64.800000000,5,3,3,3,64.780000000,64.810000000,5,3,5,3,64.770000000,64.820000000,9,9,5,6,64.760000000,64.830000000,8,9,8,9,64.750000000,64.840000000,9,7,9,6,64.740000000,64.850000000,10,8,9,5,64.730000000,64.860000000,5,5,5,4,64.720000000,64.870000000,8,4,5,3,64.710000000,64.880000000,8,4,7,3,64.700000000,64.890000000,7,3,6,2,MCLN5
2025-06-11T00:00:01.246919953Z,2025-06-11T00:00:01.246573235Z,10,1,42026514,M,A,3,64.830000000,1,130,11512,79291013,64.790000000,64.800000000,5,3,3,3,64.780000000,64.810000000,5,3,5,3,64.770000000,64.820000000,9,9,5,6,64.760000000,64.830000000,8,10,8,10,64.750000000,64.840000000,9,6,9,5,64.740000000,64.850000000,10,8,9,5,64.730000000,64.860000000,5,5,5,4,64.720000000,64.870000000,8,4,5,3,64.710000000,64.880000000,8,4,7,3,64.700000000,64.890000000,7,3,6,2,MCLN5
2025-06-11T00:00:01.247506936Z,2025-06-11T00:00:01.247183463Z,10,1,42026514,C,B,0,64.790000000,2,130,13619,79291052,64.790000000,64.800000000,3,3,2,3,64.780000000,64.810000000,5,3,5,3,64.770000000,64.820000000,9,9,5,6,64.760000000,64.830000000,8,10,8,10,64.750000000,64.840000000,9,6,9,5,64.740000000,64.850000000,10,8,9,5,64.730000000,64.860000000,5,5,5,4,64.720000000,64.870000000,8,4,5,3,64.710000000,64.880000000,8,4,7,3,64.700000000,64.890000000,7,3,6,2,MCLN5
2025-06-11T00:00:01.248048439Z,2025-06-11T00:00:01.247357619Z,10,1,42026514,C,B,0,64.790000000,2,130,13570,79291080,64.790000000,64.800000000,1,3,1,3,64.780000000,64.810000000,5,3,5,3,64.770000000,64.820000000,9,9,5,6,64.760000000,64.830000000,8,10,8,10,64.750000000,64.840000000,9,6,9,5,64.740000000,64.850000000,10,8,9,5,64.730000000,64.860000000,5,5,5,4,64.720000000,64.870000000,8,4,5,3,64.710000000,64.880000000,8,4,7,3,64.700000000,64.890000000,7,3,6,2,MCLN5
2025-06-11T00:00:01.248288612Z,2025-06-11T00:00:01.247827825Z,10,1,42026514,M,A,3,64.840000000,1,130,11720,79291094,64.790000000,64.800000000,1,3,1,3,64.780000000,64.810000000,5,3,5,3,64.770000000,64.820000000,9,9,5,6,64.760000000,64.830000000,8,9,8,9,64.750000000,64.840000000,9,7,9,6,64.740000000,64.850000000,10,8,9,5,64.730000000,64.860000000,5,5,5,4,64.720000000,64.870000000,8,4,5,3,64.710000000,64.880000000,8,4,7,3,64.700000000,64.890000000,7,3,6,2,MCLN5
2025-06-11T00:00:01.248298134Z,2025-06-11T00:00:01.247828805Z,10,1,42026514,M,A,3,64.840000000,1,130,12694,79291095,64.790000000,64.800000000,1,3,1,3,64.780000000,64.810000000,5,3,5,3,64.770000000,64.820000000,9,9,5,6,64.760000000,64.830000000,8,8,8,8,64.750000000,64.840000000,9,8,9,7,64.740000000,64.850000000,10,8,9,5,64.730000000,64.860000000,5,5,5,4,64.720000000,64.870000000,8,4,5,3,64.710000000,64.880000000,8,4,7,3,64.700000000,64.890000000,7,3,6,2,MCLN5
2025-06-11T00:00:01.248349280Z,2025-06-11T00:00:01.247844279Z,10,1,42025623,M,B,4,63.650000000,1,130,13553,79291098,63.700000000,63.720000000,2,3,2,3,63.690000000,63.730000000,3,2,3,2,63.680000000,63.740000000,1,3,1,3,63.670000000,63.750000000,3,2,3,2,63.660000000,63.760000000,5,5,5,5,63.650000000,63.770000000,4,2,4,2,63.640000000,63.780000000,5,5,5,5,63.630000000,63.790000000,4,1,4,1,63.620000000,63.800000000,3,3,3,3,63.610000000,63.810000000,2,4,2,2,MCLQ5
2025-06-11T00:00:01.248356561Z,2025-06-11T00:00:01.247844759Z,10,1,42025623,M,A,4,63.760000000,1,130,11733,79291099,63.700000000,63.720000000,2,3,2,3,63.690000000,63.730000000,3,2,3,2,63.680000000,63.740000000,1,3,1,3,63.670000000,63.750000000,3,2,3,2,63.660000000,63.760000000,5,6,5,6,63.650000000,63.770000000,4,1,4,1,63.640000000,63.780000000,5,5,5,5,63.630000000,63.790000000,4,1,4,1,63.620000000,63.800000000,3,3,3,3,63.610000000,63.810000000,2,4,2,2,MCLQ5
2025-06-11T00:00:01.248647963Z,2025-06-11T00:00:01.248090929Z,10,1,42026514,M,B,4,64.740000000,1,130,15984,79291116,64.790000000,64.800000000,1,3,1,3,64.780000000,64.810000000,5,3,5,3,64.770000000,64.820000000,9,9,5,6,64.760000000,64.830000000,8,8,8,8,64.750000000,64.840000000,8,8,8,7,64.740000000,64.850000000,11,8,10,5,64.730000000,64.860000000,5,5,5,4,64.720000000,64.870000000,8,4,5,3,64.710000000,64.880000000,8,4,7,3,64.700000000,64.890000000,7,3,6,2,MCLN5
2025-06-11T00:00:01.587736844Z,2025-06-11T00:00:01.587617491Z,10,1,42026514,M,A,3,64.830000000,1,130,11861,79291608,64.790000000,64.800000000,1,3,1,3,64.780000000,64.810000000,5,3,5,3,64.770000000,64.820000000,9,9,5,6,64.760000000,64.830000000,8,9,8,9,64.750000000,64.840000000,8,7,8,6,64.740000000,64.850000000,11,8,10,5,64.730000000,64.860000000,5,5,5,4,64.720000000,64.870000000,8,4,5,3,64.710000000,64.880000000,8,4,7,3,64.700000000,64.890000000,7,3,6,2,MCLN5
2025-06-11T00:00:01.587752088Z,2025-06-11T00:00:01.587618411Z,10,1,42026514,M,A,3,64.830000000,1,130,11617,79291609,64.790000000,64.800000000,1,3,1,3,64.780000000,64.810000000,5,3,5,3,64.770000000,64.820000000,9,9,5,6,64.760000000,64.830000000,8,10,8,10,64.750000000,64.840000000,8,6,8,5,64.740000000,64.850000000,11,8,10,5,64.730000000,64.860000000,5,5,5,4,64.720000000,64.870000000,8,4,5,3,64.710000000,64.880000000,8,4,7,3,64.700000000,64.890000000,7,3,6,2,MCLN5
2025-06-11T00:00:01.587762103Z,2025-06-11T00:00:01.587619141Z,10,1,42026514,M,A,3,64.830000000,1,130,11479,79291610,64.790000000,64.800000000,1,3,1,3,64.780000000,64.810000000,5,3,5,3,64.770000000,64.820000000,9,9,5,6,64.760000000,64.830000000,8,11,8,11,64.750000000,64.840000000,8,5,8,4,64.740000000,64.850000000,11,8,10,5,64.730000000,64.860000000,5,5,5,4,64.720000000,64.870000000,8,4,5,3,64.710000000,64.880000000,8,4,7,3,64.700000000,64.890000000,7,3,6,2,MCLN5
2025-06-11T00:00:02.030945335Z,2025-06-11T00:00:02.030666591Z,10,1,42026514,T,A,0,64.790000000,1,0,10988,79291919,64.790000000,64.800000000,1,3,1,3,64.780000000,64.810000000,5,3,5,3,64.770000000,64.820000000,9,9,5,6,64.760000000,64.830000000,8,11,8,11,64.750000000,64.840000000,8,5,8,4,64.740000000,64.850000000,11,8,10,5,64.730000000,64.860000000,5,5,5,4,64.720000000,64.870000000,8,4,5,3,64.710000000,64.880000000,8,4,7,3,64.700000000,64.890000000,7,3,6,2,MCLN5
2025-06-11T00:00:02.030945335Z,2025-06-11T00:00:02.030666591Z,10,1,42026514,C,B,0,64.790000000,1,130,10988,79291919,64.780000000,64.800000000,5,3,5,3,64.770000000,64.810000000,9,3,5,3,64.760000000,64.820000000,8,9,8,6,64.750000000,64.830000000,8,11,8,11,64.740000000,64.840000000,11,5,10,4,64.730000000,64.850000000,5,8,5,5,64.720000000,64.860000000,8,5,5,4,64.710000000,64.870000000,8,4,7,3,64.700000000,64.880000000,7,4,6,3,64.690000000,64.890000000,4,3,3,2,MCLN5
2025-06-11T00:00:02.031031140Z,2025-06-11T00:00:02.030670175Z,10,1,42025623,A,A,0,63.710000000,1,130,16393,79291924,63.700000000,63.710000000,2,1,2,1,63.690000000,63.720000000,3,3,3,3,63.680000000,63.730000000,1,2,1,2,63.670000000,63.740000000,3,3,3,3,63.660000000,63.750000000,5,2,5,2,63.650000000,63.760000000,4,6,4,6,63.640000000,63.770000000,5,1,5,1,63.630000000,63.780000000,4,5,4,5,63.620000000,63.790000000,3,1,3,1,63.610000000,63.800000000,2,3,2,3,MCLQ5
2025-06-11T00:00:02.031062334Z,2025-06-11T00:00:02.030670615Z,10,1,42026514,A,A,0,64.790000000,2,130,18777,79291925,64.780000000,64.790000000,5,2,5,1,64.770000000,64.800000000,9,3,5,3,64.760000000,64.810000000,8,3,8,3,64.750000000,64.820000000,8,9,8,6,64.740000000,64.830000000,11,11,10,11,64.730000000,64.840000000,5,5,5,4,64.720000000,64.850000000,8,8,5,5,64.710000000,64.860000000,8,5,7,4,64.700000000,64.870000000,7,4,6,3,64.690000000,64.880000000,4,4,3,3,MCLN5
2025-06-11T00:00:02.031242697Z,2025-06-11T00:00:02.030675167Z,10,1,42025623,C,B,0,63.700000000,1,130,13428,79291935,63.700000000,63.710000000,1,1,1,1,63.690000000,63.720000000,3,3,3,3,63.680000000,63.730000000,1,2,1,2,63.670000000,63.740000000,3,3,3,3,63.660000000,63.750000000,5,2,5,2,63.650000000,63.760000000,4,6,4,6,63.640000000,63.770000000,5,1,5,1,63.630000000,63.780000000,4,5,4,5,63.620000000,63.790000000,3,1,3,1,63.610000000,63.800000000,2,3,2,3,MCLQ5
2025-06-11T00:00:02.031401842Z,2025-06-11T00:00:02.030679717Z,10,1,42026514,A,A,1,64.800000000,1,130,12709,79291940,64.780000000,64.790000000,5,2,5,1,64.770000000,64.800000000,9,4,5,4,64.760000000,64.810000000,8,3,8,3,64.750000000,64.820000000,8,9,8,6,64.740000000,64.830000000,11,11,10,11,64.730000000,64.840000000,5,5,5,4,64.720000000,64.850000000,8,8,5,5,64.710000000,64.860000000,8,5,7,4,64.700000000,64.870000000,7,4,6,3,64.690000000,64.880000000,4,4,3,3,MCLN5
2025-06-11T00:00:02.031568343Z,2025-06-11T00:00:02.030953671Z,10,1,42026514,M,A,4,64.840000000,1,130,11488,79291949,64.780000000,64.790000000,5,2,5,1,64.770000000,64.800000000,9,4,5,4,64.760000000,64.810000000,8,3,8,3,64.750000000,64.820000000,8,9,8,6,64.740000000,64.830000000,11,10,10,10,64.730000000,64.840000000,5,6,5,5,64.720000000,64.850000000,8,8,5,5,64.710000000,64.860000000,8,5,7,4,64.700000000,64.870000000,7,4,6,3,64.690000000,64.880000000,4,4,3,3,MCLN5
2025-06-11T00:00:02.031578641Z,2025-06-11T00:00:02.030954247Z,10,1,42026514,M,B,3,64.750000000,1,130,11596,79291950,64.780000000,64.790000000,5,2,5,1,64.770000000,64.800000000,9,4,5,4,64.760000000,64.810000000,8,3,8,3,64.750000000,64.820000000,9,9,9,6,64.740000000,64.830000000,10,10,9,10,64.730000000,64.840000000,5,6,5,5,64.720000000,64.850000000,8,8,5,5,64.710000000,64.860000000,8,5,7,4,64.700000000,64.870000000,7,4,6,3,64.690000000,64.880000000,4,4,3,3,MCLN5
2025-06-11T00:00:02.031588080Z,2025-06-11T00:00:02.030955187Z,10,1,42026514,C,B,4,64.740000000,1,130,11682,79291951,64.780000000,64.790000000,5,2,5,1,64.770000000,64.800000000,9,4,5,4,64.760000000,64.810000000,8,3,8,3,64.750000000,64.820000000,9,9,9,6,64.740000000,64.830000000,9,10,8,10,64.730000000,64.840000000,5,6,5,5,64.720000000,64.850000000,8,8,5,5,64.710000000,64.860000000,8,5,7,4,64.700000000,64.870000000,7,4,6,3,64.690000000,64.880000000,4,4,3,3,MCLN5
2025-06-11T00:00:02.031607317Z,2025-06-11T00:00:02.030965477Z,10,1,42026514,C,B,0,64.780000000,1,130,14459,79291952,64.780000000,64.790000000,4,2,4,1,64.770000000,64.800000000,9,4,5,4,64.760000000,64.810000000,8,3,8,3,64.750000000,64.820000000,9,9,9,6,64.740000000,64.830000000,9,10,8,10,64.730000000,64.840000000,5,6,5,5,64.720000000,64.850000000,8,8,5,5,64.710000000,64.860000000,8,5,7,4,64.700000000,64.870000000,7,4,6,3,64.690000000,64.880000000,4,4,3,3,MCLN5
2025-06-11T00:00:02.031709824Z,2025-06-11T00:00:02.031084743Z,10,1,42025623,M,B,4,63.650000000,1,130,11038,79291957,63.700000000,63.710000000,1,1,1,1,63.690000000,63.720000000,3,3,3,3,63.680000000,63.730000000,1,2,1,2,63.670000000,63.740000000,3,3,3,3,63.660000000,63.750000000,4,2,4,2,63.650000000,63.760000000,5,6,5,6,63.640000000,63.770000000,5,1,5,1,63.630000000,63.780000000,4,5,4,5,63.620000000,63.790000000,3,1,3,1,63.610000000,63.800000000,2,3,2,3,MCLQ5
2025-06-11T00:00:02.031723517Z,2025-06-11T00:00:02.031085279Z,10,1,42025623,M,A,4,63.750000000,1,130,12486,79291958,63.700000000,63.710000000,1,1,1,1,63.690000000,63.720000000,3,3,3,3,63.680000000,63.730000000,1,2,1,2,63.670000000,63.740000000,3,3,3,3,63.660000000,63.750000000,4,3,4,3,63.650000000,63.760000000,5,5,5,5,63.640000000,63.770000000,5,1,5,1,63.630000000,63.780000000,4,5,4,5,63.620000000,63.790000000,3,1,3,1,63.610000000,63.800000000,2,3,2,3,MCLQ5
2025-06-11T00:00:02.031733017Z,2025-06-11T00:00:02.031085683Z,10,1,42025623,M,B,4,63.650000000,1,130,11481,79291959,63.700000000,63.710000000,1,1,1,1,63.690000000,63.720000000,3,3,3,3,63.680000000,63.730000000,1,2,1,2,63.670000000,63.740000000,3,3,3,3,63.660000000,63.750000000,3,3,3,3,63.650000000,63.760000000,6,5,6,5,63.640000000,63.770000000,5,1,5,1,63.630000000,63.780000000,4,5,4,5,63.620000000,63.790000000,3,1,3,1,63.610000000,63.800000000,2,3,2,3,MCLQ5
2025-06-11T00:00:02.031744382Z,2025-06-11T00:00:02.031086259Z,10,1,42025623,M,A,4,63.750000000,1,130,11762,79291960,63.700000000,63.710000000,1,1,1,1,63.690000000,63.720000000,3,3,3,3,63.680000000,63.730000000,1,2,1,2,63.670000000,63.740000000,3,3,3,3,63.660000000,63.750000000,3,4,3,4,63.650000000,63.760000000,6,4,6,4,63.640000000,63.770000000,5,1,5,1,63.630000000,63.780000000,4,5,4,5,63.620000000,63.790000000,3,1,3,1,63.610000000,63.800000000,2,3,2,3,MCLQ5
2025-06-11T00:00:02.031768827Z,2025-06-11T00:00:02.031130993Z,10,1,42026514,C,B,0,64.780000000,1,130,17392,79291961,64.780000000,64.790000000,3,2,3,1,64.770000000,64.800000000,9,4,5,4,64.760000000,64.810000000,8,3,8,3,64.750000000,64.820000000,9,9,9,6,64.740000000,64.830000000,9,10,8,10,64.730000000,64.840000000,5,6,5,5,64.720000000,64.850000000,8,8,5,5,64.710000000,64.860000000,8,5,7,4,64.700000000,64.870000000,7,4,6,3,64.690000000,64.880000000,4,4,3,3,MCLN5
2025-06-11T00:00:02.031799192Z,2025-06-11T00:00:02.031163093Z,10,1,42026514,M,A,1,64.800000000,1,130,12474,79291963,64.780000000,64.790000000,3,2,3,1,64.770000000,64.800000000,9,5,5,5,64.760000000,64.810000000,8,3,8,3,64.750000000,64.820000000,9,9,9,6,64.740000000,64.830000000,9,10,8,10,64.730000000,64.840000000,5,6,5,5,64.720000000,64.850000000,8,8,5,5,64.710000000,64.860000000,8,5,7,4,64.700000000,64.870000000,7,4,6,3,64.690000000,64.880000000,4,4,3,3,MCLN5
2025-06-11T00:00:02.031837851Z,2025-06-11T00:00:02.031184867Z,10,1,42025623,M,A,1,63.720000000,1,130,12068,79291965,63.700000000,63.710000000,1,1,1,1,63.690000000,63.720000000,3,4,3,4,63.680000000,63.730000000,1,2,1,2,63.670000000,63.740000000,3,3,3,3,63.660000000,63.750000000,3,4,3,4,63.650000000,63.760000000,6,4,6,4,63.640000000,63.770000000,5,1,5,1,63.630000000,63.780000000,4,5,4,5,63.620000000,63.790000000,3,1,3,1,63.610000000,63.800000000,2,3,2,3,MCLQ5
2025-06-11T00:00:02.031923747Z,2025-06-11T00:00:02.031244403Z,10,1,42026514,A,A,0,64.790000000,1,130,13410,79291970,64.780000000,64.790000000,3,3,3,2,64.770000000,64.800000000,9,5,5,5,64.760000000,64.810000000,8,3,8,3,64.750000000,64.820000000,9,9,9,6,64.740000000,64.830000000,9,10,8,10,64.730000000,64.840000000,5,6,5,5,64.720000000,64.850000000,8,8,5,5,64.710000000,64.860000000,8,5,7,4,64.700000000,64.870000000,7,4,6,3,64.690000000,64.880000000,4,4,3,3,MCLN5
2025-06-11T00:00:02.031937363Z,2025-06-11T00:00:02.031276177Z,10,1,42025623,C,A,1,63.720000000,1,130,12704,79291971,63.700000000,63.710000000,1,1,1,1,63.690000000,63.720000000,3,3,3,3,63.680000000,63.730000000,1,2,1,2,63.670000000,63.740000000,3,3,3,3,63.660000000,63.750000000,3,4,3,4,63.650000000,63.760000000,6,4,6,4,63.640000000,63.770000000,5,1,5,1,63.630000000,63.780000000,4,5,4,5,63.620000000,63.790000000,3,1,3,1,63.610000000,63.800000000,2,3,2,3,MCLQ5
2025-06-11T00:00:02.031946494Z,2025-06-11T00:00:02.031302095Z,10,1,42026514,M,A,2,64.810000000,1,130,11393,79291972,64.780000000,64.790000000,3,3,3,2,64.770000000,64.800000000,9,5,5,5,64.760000000,64.810000000,8,4,8,4,64.750000000,64.820000000,9,9,9,6,64.740000000,64.830000000,9,10,8,10,64.730000000,64.840000000,5,6,5,5,64.720000000,64.850000000,8,8,5,5,64.710000000,64.860000000,8,5,7,4,64.700000000,64.870000000,7,4,6,3,64.690000000,64.880000000,4,4,3,3,MCLN5
2025-06-11T00:00:02.032132839Z,2025-06-11T00:00:02.031502957Z,10,1,42026514,C,A,1,64.800000000,1,130,12167,79291982,64.780000000,64.790000000,3,3,3,2,64.770000000,64.800000000,9,4,5,4,64.760000000,64.810000000,8,4,8,4,64.750000000,64.820000000,9,9,9,6,64.740000000,64.830000000,9,10,8,10,64.730000000,64.840000000,5,6,5,5,64.720000000,64.850000000,8,8,5,5,64.710000000,64.860000000,8,5,7,4,64.700000000,64.870000000,7,4,6,3,64.690000000,64.880000000,4,4,3,3,MCLN5
2025-06-11T00:00:02.032279212Z,2025-06-11T00:00:02.031940507Z,10,1,42026514,M,B,0,62.820000000,2,130,18151,79291989,64.780000000,64.790000000,2,3,2,2,64.770000000,64.800000000,9,4,5,4,64.760000000,64.810000000,8,4,8,4,64.750000000,64.820000000,9,9,9,6,64.740000000,64.830000000,9,10,8,10,64.730000000,64.840000000,5,6,5,5,64.720000000,64.850000000,8,8,5,5,64.710000000,64.860000000,8,5,7,4,64.700000000,64.870000000,7,4,6,3,64.690000000,64.880000000,4,4,3,3,MCLN5
2025-06-11T00:00:02.032408467Z,2025-06-11T00:00:02.031968325Z,10,1,42026514,M,B,3,64.740000000,1,130,13656,79291996,64.780000000,64.790000000,2,3,2,2,64.770000000,64.800000000,9,4,5,4,64.760000000,64.810000000,8,4,8,4,64.750000000,64.820000000,8,9,8,6,64.740000000,64.830000000,10,10,9,10,64.730000000,64.840000000,5,6,5,5,64.720000000,64.850000000,8,8,5,5,64.710000000,64.860000000,8,5,7,4,64.700000000,64.870000000,7,4,6,3,64.690000000,64.880000000,4,4,3,3,MCLN5
2025-06-11T00:00:02.032419511Z,2025-06-11T00:00:02.031968863Z,10,1,42026514,M,A,4,64.830000000,1,130,12786,79291997,64.780000000,64.790000000,2,3,2,2,64.770000000,64.800000000,9,4,5,4,64.760000000,64.810000000,8,4,8,4,64.750000000,64.820000000,8,9,8,6,64.740000000,64.830000000,10,11,9,11,64.730000000,64.840000000,5,5,5,4,64.720000000,64.850000000,8,8,5,5,64.710000000,64.860000000,8,5,7,4,64.700000000,64.870000000,7,4,6,3,64.690000000,64.880000000,4,4,3,3,MCLN5
2025-06-11T00:00:02.032819503Z,2025-06-11T00:00:02.031988849Z,10,1,42026514,A,A,0,64.790000000,2,130,16980,79292018,64.780000000,64.790000000,2,5,2,3,64.770000000,64.800000000,9,4,5,4,64.760000000,64.810000000,8,4,8,4,64.750000000,64.820000000,8,9,8,6,64.740000000,64.830000000,10,11,9,11,64.730000000,64.840000000,5,5,5,4,64.720000000,64.850000000,8,8,5,5,64.710000000,64.860000000,8,5,7,4,64.700000000,64.870000000,7,4,6,3,64.690000000,64.880000000,4,4,3,3,MCLN5
2025-06-11T00:00:02.033571005Z,2025-06-11T00:00:02.032319191Z,10,1,42026514,M,B,3,64.740000000,1,130,11587,79292068,64.780000000,64.790000000,2,5,2,3,64.770000000,64.800000000,9,4,5,4,64.760000000,64.810000000,8,4,8,4,64.750000000,64.820000000,7,9,7,6,64.740000000,64.830000000,11,11,10,11,64.730000000,64.840000000,5,5,5,4,64.720000000,64.850000000,8,8,5,5,64.710000000,64.860000000,8,5,7,4,64.700000000,64.870000000,7,4,6,3,64.690000000,64.880000000,4,4,3,3,MCLN5
2025-06-11T00:00:02.033582370Z,2025-06-11T00:00:02.032319689Z,10,1,42026514,M,A,3,64.820000000,1,130,12434,79292069,64.780000000,64.790000000,2,5,2,3,64.770000000,64.800000000,9,4,5,4,64.760000000,64.810000000,8,4,8,4,64.750000000,64.820000000,7,10,7,7,64.740000000,64.830000000,11,10,10,10,64.730000000,64.840000000,5,5,5,4,64.720000000,64.850000000,8,8,5,5,64.710000000,64.860000000,8,5,7,4,64.700000000,64.870000000,7,4,6,3,64.690000000,64.880000000,4,4,3,3,MCLN5
2025-06-11T00:00:02.033591209Z,2025-06-11T00:00:02.032320187Z,10,1,42026514,M,B,3,64.740000000,1,130,11923,79292070,64.780000000,64.790000000,2,5,2,3,64.770000000,64.800000000,9,4,5,4,64.760000000,64.810000000,8,4,8,4,64.750000000,64.820000000,6,10,6,7,64.740000000,64.830000000,12,10,11,10,64.730000000,64.840000000,5,5,5,4,64.720000000,64.850000000,8,8,5,5,64.710000000,64.860000000,8,5,7,4,64.700000000,64.870000000,7,4,6,3,64.690000000,64.880000000,4,4,3,3,MCLN5
2025-06-11T00:00:02.033599765Z,2025-06-11T00:00:02.032320687Z,10,1,42026514,M,A,3,64.820000000,1,130,11465,79292071,64.780000000,64.790000000,2,5,2,3,64.770000000,64.800000000,9,4,5,4,64.760000000,64.810000000,8,4,8,4,64.750000000,64.820000000,6,11,6,8,64.740000000,64.830000000,12,9,11,9,64.730000000,64.840000000,5,5,5,4,64.720000000,64.850000000,8,8,5,5,64.710000000,64.860000000,8,5,7,4,64.700000000,64.870000000,7,4,6,3,64.690000000,64.880000000,4,4,3,3,MCLN5
2025-06-11T00:00:02.033703746Z,2025-06-11T00:00:02.032338465Z,10,1,42025623,M,B,5,63.640000000,1,130,11811,79292080,63.700000000,63.710000000,1,1,1,1,63.690000000,63.720000000,3,3,3,3,63.680000000,63.730000000,1,2,1,2,63.670000000,63.740000000,3,3,3,3,63.660000000,63.750000000,3,4,3,4,63.650000000,63.760000000,5,4,5,4,63.640000000,63.770000000,6,1,6,1,63.630000000,63.780000000,4,5,4,5,63.620000000,63.790000000,3,1,3,1,63.610000000,63.800000000,2,3,2,3,MCLQ5
2025-06-11T00:00:02.033719036Z,2025-06-11T00:00:02.032338965Z,10,1,42025623,M,A,4,63.750000000,1,130,14790,79292081,63.700000000,63.710000000,1,1,1,1,63.690000000,63.720000000,3,3,3,3,63.680000000,63.730000000,1,2,1,2,63.670000000,63.740000000,3,3,3,3,63.660000000,63.750000000,3,5,3,5,63.650000000,63.760000000,5,3,5,3,63.640000000,63.770000000,6,1,6,1,63.630000000,63.780000000,4,5,4,5,63.620000000,63.790000000,3,1,3,1,63.610000000,63.800000000,2,3,2,3,MCLQ5
2025-06-11T00:00:02.033736861Z,2025-06-11T00:00:02.032346107Z,10,1,42022708,M,A,1,3.230000000,10,130,11758,79292083,2.810000000,2.830000000,1,2,1,2,2.800000000,2.840000000,12,2,3,2,2.790000000,2.850000000,2,1,2,1,2.780000000,2.870000000,1,1,1,1,,3.230000000,0,10,0,1,,,0,0,0,0,,,0,0,0,0,,,0,0,0,0,,,0,0,0,0,,,0,0,0,0,MCLN5-MCLV5
2025-06-11T00:00:02.034818210Z,2025-06-11T00:00:02.032960327Z,10,1,42026514,M,A,5,64.840000000,1,130,11491,79292134,64.780000000,64.790000000,2,5,2,3,64.770000000,64.800000000,9,4,5,4,64.760000000,64.810000000,8,4,8,4,64.750000000,64.820000000,6,11,6,8,64.740000000,64.830000000,12,9,11,9,64.730000000,64.840000000,5,6,5,5,64.720000000,64.850000000,8,8,5,5,64.710000000,64.860000000,8,5,7,4,64.700000000,64.870000000,7,4,6,3,64.690000000,64.880000000,4,4,3,3,MCLN5
2025-06-11T00:00:02.034939394Z,2025-06-11T00:00:02.033045207Z,10,1,42025611,C,A,0,2.080000000,3,130,11638,79292142,2.070000000,2.090000000,3,7,2,5,2.060000000,2.100000000,23,27,3,6,2.050000000,2.110000000,23,23,3,4,2.040000000,2.120000000,23,22,3,2,2.030000000,2.130000000,2,2,1,2,2.020000000,2.140000000,2,2,2,1,2.010000000,2.150000000,2,2,1,1,2.000000000,2.160000000,2,2,2,1,1.990000000,2.170000000,2,2,1,1,1.980000000,2.180000000,2,2,2,2,MCLN5-MCLU5
2025-06-11T00:00:02.035650125Z,2025-06-11T00:00:02.033435639Z,10,1,42025623,M,A,4,63.760000000,1,130,11486,79292190,63.700000000,63.710000000,1,1,1,1,63.690000000,63.720000000,3,3,3,3,63.680000000,63.730000000,1,2,1,2,63.670000000,63.740000000,3,3,3,3,63.660000000,63.750000000,3,4,3,4,63.650000000,63.760000000,5,4,5,4,63.640000000,63.770000000,6,1,6,1,63.630000000,63.780000000,4,5,4,5,63.620000000,63.790000000,3,1,3,1,63.610000000,63.800000000,2,3,2,3,MCLQ5
2025-06-11T00:00:02.035662620Z,2025-06-11T00:00:02.033436121Z,10,1,42025623,M,B,5,63.650000000,1,130,11705,79292191,63.700000000,63.710000000,1,1,1,1,63.690000000,63.720000000,3,3,3,3,63.680000000,63.730000000,1,2,1,2,63.670000000,63.740000000,3,3,3,3,63.660000000,63.750000000,3,4,3,4,63.650000000,63.760000000,6,4,6,4,63.640000000,63.770000000,5,1,5,1,63.630000000,63.780000000,4,5,4,5,63.620000000,63.790000000,3,1,3,1,63.610000000,63.800000000,2,3,2,3,MCLQ5
2025-06-11T00:00:02.035753961Z,2025-06-11T00:00:02.033440787Z,10,1,42022708,M,A,1,2.840000000,10,130,14561,79292195,2.810000000,2.830000000,1,2,1,2,2.800000000,2.840000000,12,12,3,3,2.790000000,2.850000000,2,1,2,1,2.780000000,2.870000000,1,1,1,1,,,0,0,0,0,,,0,0,0,0,,,0,0,0,0,,,0,0,0,0,,,0,0,0,0,,,0,0,0,0,MCLN5-MCLV5
2025-06-11T00:00:02.035999761Z,2025-06-11T00:00:02.033581381Z,10,1,42026514,C,A,0,64.790000000,2,130,13079,79292212,64.780000000,64.790000000,2,3,2,2,64.770000000,64.800000000,9,4,5,4,64.760000000,64.810000000,8,4,8,4,64.750000000,64.820000000,6,11,6,8,64.740000000,64.830000000,12,9,11,9,64.730000000,64.840000000,5,6,5,5,64.720000000,64.850000000,8,8,5,5,64.710000000,64.860000000,8,5,7,4,64.700000000,64.870000000,7,4,6,3,64.690000000,64.880000000,4,4,3,3,MCLN5
2025-06-11T00:00:02.037068346Z,2025-06-11T00:00:02.034583289Z,10,1,42025623,M,B,5,63.640000000,1,130,14984,79292281,63.700000000,63.710000000,1,1,1,1,63.690000000,63.720000000,3,3,3,3,63.680000000,63.730000000,1,2,1,2,63.670000000,63.740000000,3,3,3,3,63.660000000,63.750000000,3,4,3,4,63.650000000,63.760000000,5,4,5,4,63.640000000,63.770000000,6,1,6,1,63.630000000,63.780000000,4,5,4,5,63.620000000,63.790000000,3,1,3,1,63.610000000,63.800000000,2,3,2,3,MCLQ5
2025-06-11T00:00:02.037927915Z,2025-06-11T00:00:02.035696033Z,10,1,42026514,C,A,1,64.800000000,1,130,11269,79292332,64.780000000,64.790000000,2,3,2,2,64.770000000,64.800000000,9,3,5,3,64.760000000,64.810000000,8,4,8,4,64.750000000,64.820000000,6,11,6,8,64.740000000,64.830000000,12,9,11,9,64.730000000,64.840000000,5,6,5,5,64.720000000,64.850000000,8,8,5,5,64.710000000,64.860000000,8,5,7,4,64.700000000,64.870000000,7,4,6,3,64.690000000,64.880000000,4,4,3,3,MCLN5
2025-06-11T00:00:02.038152913Z,2025-06-11T00:00:02.036697729Z,10,1,42418117,M,B,0,3.240000000,10,130,11433,79292348,3.250000000,3.280000000,1,1,1,1,3.240000000,3.290000000,11,11,2,2,3.230000000,3.300000000,1,1,1,1,,,0,0,0,0,,,0,0,0,0,,,0,0,0,0,,,0,0,0,0,,,0,0,0,0,,,0,0,0,0,,,0,0,0,0,MCLN5-MCLX5
2025-06-11T00:00:02.042165793Z,2025-06-11T00:00:02.042056135Z,10,1,42026514,A,B,5,64.730000000,1,130,15533,79292442,64.780000000,64.790000000,2,3,2,2,64.770000000,64.800000000,9,3,5,3,64.760000000,64.810000000,8,4,8,4,64.750000000,64.820000000,6,11,6,8,64.740000000,64.830000000,12,9,11,9,64.730000000,64.840000000,6,6,6,5,64.720000000,64.850000000,8,8,5,5,64.710000000,64.860000000,8,5,7,4,64.700000000,64.870000000,7,4,6,3,64.690000000,64.880000000,4,4,3,3,MCLN5
2025-06-11T00:00:02.042174556Z,2025-06-11T00:00:02.042058573Z,10,1,42026514,C,A,7,64.860000000,1,130,11597,79292443,64.780000000,64.790000000,2,3,2,2,64.770000000,64.800000000,9,3,5,3,64.760000000,64.810000000,8,4,8,4,64.750000000,64.820000000,6,11,6,8,64.740000000,64.830000000,12,9,11,9,64.730000000,64.840000000,6,6,6,5,64.720000000,64.850000000,8,8,5,5,64.710000000,64.860000000,8,4,7,3,64.700000000,64.870000000,7,4,6,3,64.690000000,64.880000000,4,4,3,3,MCLN5
2025-06-11T00:00:02.042304717Z,2025-06-11T00:00:02.042206387Z,10,1,42026514,A,A,6,64.850000000,1,130,15033,79292444,64.780000000,64.790000000,2,3,2,2,64.770000000,64.800000000,9,3,5,3,64.760000000,64.810000000,8,4,8,4,64.750000000,64.820000000,6,11,6,8,64.740000000,64.830000000,12,9,11,9,64.730000000,64.840000000,6,6,6,5,64.720000000,64.850000000,8,9,5,6,64.710000000,64.860000000,8,4,7,3,64.700000000,64.870000000,7,4,6,3,64.690000000,64.880000000,4,4,3,3,MCLN5
2025-06-11T00:00:02.046648058Z,2025-06-11T00:00:02.046546663Z,10,1,42418117,M,B,0,3.250000000,10,130,14942,79292492,3.250000000,3.280000000,11,1,2,1,3.240000000,3.290000000,1,11,1,2,3.230000000,3.300000000,1,1,1,1,,,0,0,0,0,,,0,0,0,0,,,0,0,0,0,,,0,0,0,0,,,0,0,0,0,,,0,0,0,0,,,0,0,0,0,MCLN5-MCLX5
2025-06-11T00:00:02.055019838Z,2025-06-11T00:00:02.054920201Z,10,1,42026514,M,A,4,66.770000000,2,130,15076,79292733,64.780000000,64.790000000,2,3,2,2,64.770000000,64.800000000,9,3,5,3,64.760000000,64.810000000,8,4,8,4,64.750000000,64.820000000,6,11,6,8,64.740000000,64.830000000,12,8,11,8,64.730000000,64.840000000,6,6,6,5,64.720000000,64.850000000,8,9,5,6,64.710000000,64.860000000,8,4,7,3,64.700000000,64.870000000,7,4,6,3,64.690000000,64.880000000,4,4,3,3,MCLN5
2025-06-11T00:00:02.072254587Z,2025-06-11T00:00:02.072129591Z,10,1,42026514,C,A,0,64.790000000,2,130,20223,79292742,64.780000000,64.790000000,2,1,2,1,64.770000000,64.800000000,9,3,5,3,64.760000000,64.810000000,8,4,8,4,64.750000000,64.820000000,6,11,6,8,64.740000000,64.830000000,12,8,11,8,64.730000000,64.840000000,6,6,6,5,64.720000000,64.850000000,8,9,5,6,64.710000000,64.860000000,8,4,7,3,64.700000000,64.870000000,7,4,6,3,64.690000000,64.880000000,4,4,3,3,MCLN5
2025-06-11T00:00:02.128030108Z,2025-06-11T00:00:02.127703471Z,10,1,42064377,A,B,0,0.730000000,10,130,11291,79293019,0.730000000,0.750000000,21,15,5,5,0.720000000,0.760000000,15,15,4,4,0.710000000,0.770000000,16,16,4,4,0.700000000,0.780000000,12,12,3,3,0.690000000,0.790000000,6,5,3,3,0.680000000,0.800000000,6,6,4,4,0.670000000,0.810000000,2,2,2,1,0.660000000,0.820000000,2,1,1,1,0.600000000,0.830000000,10,1,1,1,0.560000000,0.880000000,10,10,1,1,MCLU5-MCLV5
2025-06-11T00:00:02.128866063Z,2025-06-11T00:00:02.128407083Z,10,1,42022708,M,B,0,2.810000000,1,130,11654,79293085,2.810000000,2.830000000,2,2,2,2,2.800000000,2.840000000,12,12,3,3,2.790000000,2.850000000,2,1,2,1,,2.870000000,0,1,0,1,,,0,0,0,0,,,0,0,0,0,,,0,0,0,0,,,0,0,0,0,,,0,0,0,0,,,0,0,0,0,MCLN5-MCLV5
2025-06-11T00:00:02.129311733Z,2025-06-11T00:00:02.128895683Z,10,1,42025611,M,B,0,2.070000000,1,130,11724,79293118,2.070000000,2.090000000,4,7,3,5,2.060000000,2.100000000,23,27,3,6,2.050000000,2.110000000,23,23,3,4,2.040000000,2.120000000,22,22,2,2,2.030000000,2.130000000,2,2,1,2,2.020000000,2.140000000,2,2,2,1,2.010000000,2.150000000,2,2,1,1,2.000000000,2.160000000,2,2,2,1,1.990000000,2.170000000,2,2,1,1,1.980000000,2.180000000,2,2,2,2,MCLN5-MCLU5
2025-06-11T00:00:02.133792032Z,2025-06-11T00:00:02.133496413Z,10,1,42284507,M,A,0,1.030000000,3,130,13055,79293192,0.990000000,1.000000000,7,7,3,3,0.980000000,1.010000000,19,25,6,8,0.970000000,1.020000000,18,21,5,6,0.960000000,1.030000000,23,20,8,6,0.950000000,1.040000000,10,15,6,4,0.940000000,1.050000000,4,8,3,4,0.930000000,1.060000000,3,4,2,2,0.920000000,1.070000000,3,2,2,1,0.910000000,1.080000000,3,2,2,1,0.900000000,1.090000000,2,4,1,2,MCLQ5-MCLU5
2025-06-11T00:00:02.133894001Z,2025-06-11T00:00:02.133799431Z,10,1,42284507,M,A,2,1.030000000,3,130,11510,79293196,0.990000000,1.000000000,7,7,3,3,0.980000000,1.010000000,19,25,6,8,0.970000000,1.020000000,18,18,5,5,0.960000000,1.030000000,23,23,8,7,0.950000000,1.040000000,10,15,6,4,0.940000000,1.050000000,4,8,3,4,0.930000000,1.060000000,3,4,2,2,0.920000000,1.070000000,3,2,2,1,0.910000000,1.080000000,3,2,2,1,0.900000000,1.090000000,2,4,1,2,MCLQ5-MCLU5
2025-06-11T00:00:02.133904392Z,2025-06-11T00:00:02.133799913Z,10,1,42284507,M,B,2,0.970000000,3,130,11615,79293197,0.990000000,1.000000000,7,7,3,3,0.980000000,1.010000000,19,25,6,8,0.970000000,1.020000000,21,18,6,5,0.960000000,1.030000000,20,23,7,7,0.950000000,1.040000000,10,15,6,4,0.940000000,1.050000000,4,8,3,4,0.930000000,1.060000000,3,4,2,2,0.920000000,1.070000000,3,2,2,1,0.910000000,1.080000000,3,2,2,1,0.900000000,1.090000000,2,4,1,2,MCLQ5-MCLU5
2025-06-11T00:00:02.152519648Z,2025-06-11T00:00:02.152393253Z,10,1,42026514,A,B,0,64.780000000,1,130,16843,79293307,64.780000000,64.790000000,3,1,3,1,64.770000000,64.800000000,9,3,5,3,64.760000000,64.810000000,8,4,8,4,64.750000000,64.820000000,6,11,6,8,64.740000000,64.830000000,12,8,11,8,64.730000000,64.840000000,6,6,6,5,64.720000000,64.850000000,8,9,5,6,64.710000000,64.860000000,8,4,7,3,64.700000000,64.870000000,7,4,6,3,64.690000000,64.880000000,4,4,3,3,MCLN5
2025-06-11T00:00:02.152813854Z,2025-06-11T00:00:02.152529701Z,10,1,42026514,T,B,0,64.790000000,1,0,14795,79293311,64.780000000,64.790000000,3,1,3,1,64.770000000,64.800000000,9,3,5,3,64.760000000,64.810000000,8,4,8,4,64.750000000,64.820000000,6,11,6,8,64.740000000,64.830000000,12,8,11,8,64.730000000,64.840000000,6,6,6,5,64.720000000,64.850000000,8,9,5,6,64.710000000,64.860000000,8,4,7,3,64.700000000,64.870000000,7,4,6,3,64.690000000,64.880000000,4,4,3,3,MCLN5
2025-06-11T00:00:02.152822263Z,2025-06-11T00:00:02.152529701Z,10,1,42026514,C,A,0,64.790000000,1,130,11378,79293312,64.780000000,64.800000000,3,3,3,3,64.770000000,64.810000000,9,4,5,4,64.760000000,64.820000000,8,11,8,8,64.750000000,64.830000000,6,8,6,8,64.740000000,64.840000000,12,6,11,5,64.730000000,64.850000000,6,9,6,6,64.720000000,64.860000000,8,4,5,3,64.710000000,64.870000000,8,4,7,3,64.700000000,64.880000000,7,4,6,3,64.690000000,64.890000000,4,3,3,2,MCLN5
2025-06-11T00:00:02.152846730Z,2025-06-11T00:00:02.152546137Z,10,1,42025623,A,B,0,63.700000000,1,130,15681,79293314,63.700000000,63.710000000,2,1,2,1,63.690000000,63.720000000,3,3,3,3,63.680000000,63.730000000,1,2,1,2,63.670000000,63.740000000,3,3,3,3,63.660000000,63.750000000,3,4,3,4,63.650000000,63.760000000,5,4,5,4,63.640000000,63.770000000,6,1,6,1,63.630000000,63.780000000,4,5,4,5,63.620000000,63.790000000,3,1,3,1,63.610000000,63.800000000,2,3,2,3,MCLQ5
2025-06-11T00:00:02.160895568Z,2025-06-11T00:00:02.152844511Z,10,1,42284507,C,A,0,1.000000000,3,130,15231,79293316,0.990000000,1.000000000,7,4,3,2,0.980000000,1.010000000,19,25,6,8,0.970000000,1.020000000,21,18,6,5,0.960000000,1.030000000,20,23,7,7,0.950000000,1.040000000,10,15,6,4,0.940000000,1.050000000,4,8,3,4,0.930000000,1.060000000,3,4,2,2,0.920000000,1.070000000,3,2,2,1,0.910000000,1.080000000,3,2,2,1,0.900000000,1.090000000,2,4,1,2,MCLQ5-MCLU5
2025-06-11T00:00:02.160919590Z,2025-06-11T00:00:02.152861481Z,10,1,42026514,C,A,0,64.800000000,1,130,13849,79293317,64.780000000,64.800000000,3,2,3,2,64.770000000,64.810000000,9,4,5,4,64.760000000,64.820000000,8,11,8,8,64.750000000,64.830000000,6,8,6,8,64.740000000,64.840000000,12,6,11,5,64.730000000,64.850000000,6,9,6,6,64.720000000,64.860000000,8,4,5,3,64.710000000,64.870000000,8,4,7,3,64.700000000,64.880000000,7,4,6,3,64.690000000,64.890000000,4,3,3,2,MCLN5
2025-06-11T00:00:02.160943197Z,2025-06-11T00:00:02.152871445Z,10,1,42025623,C,A,0,63.710000000,1,130,11493,79293318,63.700000000,63.720000000,2,3,2,3,63.690000000,63.730000000,3,2,3,2,63.680000000,63.740000000,1,3,1,3,63.670000000,63.750000000,3,4,3,4,63.660000000,63.760000000,3,4,3,4,63.650000000,63.770000000,5,1,5,1,63.640000000,63.780000000,6,5,6,5,63.630000000,63.790000000,4,1,4,1,63.620000000,63.800000000,3,3,3,3,63.610000000,63.810000000,2,4,2,2,MCLQ5
2025-06-11T00:00:02.160961797Z,2025-06-11T00:00:02.152956959Z,10,1,42026514,C,A,1,64.810000000,1,130,12994,79293320,64.780000000,64.800000000,3,2,3,2,64.770000000,64.810000000,9,3,5,3,64.760000000,64.820000000,8,11,8,8,64.750000000,64.830000000,6,8,6,8,64.740000000,64.840000000,12,6,11,5,64.730000000,64.850000000,6,9,6,6,64.720000000,64.860000000,8,4,5,3,64.710000000,64.870000000,8,4,7,3,64.700000000,64.880000000,7,4,6,3,64.690000000,64.890000000,4,3,3,2,MCLN5
2025-06-11T00:00:02.160970521Z,2025-06-11T00:00:02.153111591Z,10,1,42284507,M,A,0,1.000000000,1,130,11815,79293321,0.990000000,1.000000000,7,5,3,3,0.980000000,1.010000000,19,25,6,8,0.970000000,1.020000000,21,18,6,5,0.960000000,1.030000000,20,23,7,7,0.950000000,1.040000000,10,15,6,4,0.940000000,1.050000000,4,8,3,4,0.930000000,1.060000000,3,4,2,2,0.920000000,1.070000000,3,2,2,1,0.910000000,1.080000000,3,2,2,1,0.900000000,1.090000000,2,4,1,2,MCLQ5-MCLU5
2025-06-11T00:00:02.161190825Z,2025-06-11T00:00:02.160932325Z,10,1,42026514,A,B,0,64.780000000,1,130,11451,79293337,64.780000000,64.800000000,4,2,4,2,64.770000000,64.810000000,9,3,5,3,64.760000000,64.820000000,8,11,8,8,64.750000000,64.830000000,6,8,6,8,64.740000000,64.840000000,12,6,11,5,64.730000000,64.850000000,6,9,6,6,64.720000000,64.860000000,8,4,5,3,64.710000000,64.870000000,8,4,7,3,64.700000000,64.880000000,7,4,6,3,64.690000000,64.890000000,4,3,3,2,MCLN5
2025-06-11T00:00:02.161226044Z,2025-06-11T00:00:02.161020853Z,10,1,42026514,A,B,0,64.790000000,2,130,18860,79293339,64.790000000,64.800000000,2,2,1,2,64.780000000,64.810000000,4,3,4,3,64.770000000,64.820000000,9,11,5,8,64.760000000,64.830000000,8,8,8,8,64.750000000,64.840000000,6,6,6,5,64.740000000,64.850000000,12,9,11,6,64.730000000,64.860000000,6,4,6,3,64.720000000,64.870000000,8,4,5,3,64.710000000,64.880000000,8,4,7,3,64.700000000,64.890000000,7,3,6,2,MCLN5
2025-06-11T00:00:02.161236557Z,2025-06-11T00:00:02.161038035Z,10,1,42284507,M,B,0,0.990000000,1,130,11056,79293340,0.990000000,1.000000000,8,5,4,3,0.980000000,1.010000000,19,25,6,8,0.970000000,1.020000000,21,18,6,5,0.960000000,1.030000000,20,23,7,7,0.950000000,1.040000000,10,15,6,4,0.940000000,1.050000000,4,8,3,4,0.930000000,1.060000000,3,4,2,2,0.920000000,1.070000000,3,2,2,1,0.910000000,1.080000000,3,2,2,1,0.900000000,1.090000000,2,4,1,2,MCLQ5-MCLU5
2025-06-11T00:00:02.161326916Z,2025-06-11T00:00:02.161219755Z,10,1,42064377,M,A,0,0.840000000,1,130,15091,79293342,0.730000000,0.750000000,21,13,5,4,0.720000000,0.760000000,15,15,4,4,0.710000000,0.770000000,16,16,4,4,0.700000000,0.780000000,12,12,3,3,0.690000000,0.790000000,6,5,3,3,0.680000000,0.800000000,6,6,4,4,0.670000000,0.810000000,2,2,2,1,0.660000000,0.820000000,2,1,1,1,0.600000000,0.830000000,10,1,1,1,0.560000000,0.840000000,10,1,1,1,MCLU5-MCLV5
2025-06-11T00:00:02.161335456Z,2025-06-11T00:00:02.161232983Z,10,1,42026514,C,A,5,64.850000000,1,130,11514,79293343,64.790000000,64.800000000,2,2,1,2,64.780000000,64.810000000,4,3,4,3,64.770000000,64.820000000,9,11,5,8,64.760000000,64.830000000,8,8,8,8,64.750000000,64.840000000,6,6,6,5,64.740000000,64.850000000,12,8,11,5,64.730000000,64.860000000,6,4,6,3,64.720000000,64.870000000,8,4,5,3,64.710000000,64.880000000,8,4,7,3,64.700000000,64.890000000,7,3,6,2,MCLN5
2025-06-11T00:00:02.168455270Z,2025-06-11T00:00:02.168358307Z,10,1,42026514,M,A,4,66.780000000,3,130,14553,79293363,64.790000000,64.800000000,2,2,1,2,64.780000000,64.810000000,4,3,4,3,64.770000000,64.820000000,9,11,5,8,64.760000000,64.830000000,8,8,8,8,64.750000000,64.840000000,6,5,6,4,64.740000000,64.850000000,12,8,11,5,64.730000000,64.860000000,6,4,6,3,64.720000000,64.870000000,8,4,5,3,64.710000000,64.880000000,8,4,7,3,64.700000000,64.890000000,7,3,6,2,MCLN5
2025-06-11T00:00:02.178765980Z,2025-06-11T00:00:02.178656617Z,10,1,42026514,C,B,6,64.730000000,1,130,15481,79293377,64.790000000,64.800000000,2,2,1,2,64.780000000,64.810000000,4,3,4,3,64.770000000,64.820000000,9,11,5,8,64.760000000,64.830000000,8,8,8,8,64.750000000,64.840000000,6,5,6,4,64.740000000,64.850000000,12,8,11,5,64.730000000,64.860000000,5,4,5,3,64.720000000,64.870000000,8,4,5,3,64.710000000,64.880000000,8,4,7,3,64.700000000,64.890000000,7,3,6,2,MCLN5
2025-06-11T00:00:02.178773806Z,2025-06-11T00:00:02.178660169Z,10,1,42026514,A,A,6,64.860000000,1,130,11198,79293378,64.790000000,64.800000000,2,2,1,2,64.780000000,64.810000000,4,3,4,3,64.770000000,64.820000000,9,11,5,8,64.760000000,64.830000000,8,8,8,8,64.750000000,64.840000000,6,5,6,4,64.740000000,64.850000000,12,8,11,5,64.730000000,64.860000000,5,5,5,4,64.720000000,64.870000000,8,4,5,3,64.710000000,64.880000000,8,4,7,3,64.700000000,64.890000000,7,3,6,2,MCLN5
2025-06-11T00:00:02.178895143Z,2025-06-11T00:00:02.178795715Z,10,1,42026514,A,B,5,64.740000000,1,130,14715,79293379,64.790000000,64.800000000,2,2,1,2,64.780000000,64.810000000,4,3,4,3,64.770000000,64.820000000,9,11,5,8,64.760000000,64.830000000,8,8,8,8,64.750000000,64.840000000,6,5,6,4,64.740000000,64.850000000,13,8,12,5,64.730000000,64.860000000,5,5,5,4,64.720000000,64.870000000,8,4,5,3,64.710000000,64.880000000,8,4,7,3,64.700000000,64.890000000,7,3,6,2,MCLN5
2025-06-11T00:00:02.210419999Z,2025-06-11T00:00:02.210287757Z,10,1,42026514,C,B,0,64.790000000,2,130,11489,79293431,64.780000000,64.800000000,4,2,4,2,64.770000000,64.810000000,9,3,5,3,64.760000000,64.820000000,8,11,8,8,64.750000000,64.830000000,6,8,6,8,64.740000000,64.840000000,13,5,12,4,64.730000000,64.850000000,5,8,5,5,64.720000000,64.860000000,8,5,5,4,64.710000000,64.870000000,8,4,7,3,64.700000000,64.880000000,7,4,6,3,64.690000000,64.890000000,4,3,3,2,MCLN5
2025-06-11T00:00:02.210524365Z,2025-06-11T00:00:02.210428755Z,10,1,42026514,C,B,4,64.740000000,1,130,15171,79293436,64.780000000,64.800000000,4,2,4,2,64.770000000,64.810000000,9,3,5,3,64.760000000,64.820000000,8,11,8,8,64.750000000,64.830000000,6,8,6,8,64.740000000,64.840000000,12,5,11,4,64.730000000,64.850000000,5,8,5,5,64.720000000,64.860000000,8,5,5,4,64.710000000,64.870000000,8,4,7,3,64.700000000,64.880000000,7,4,6,3,64.690000000,64.890000000,4,3,3,2,MCLN5
2025-06-11T00:00:02.210623009Z,2025-06-11T00:00:02.210452389Z,10,1,42026514,C,B,0,64.780000000,1,130,17331,79293440,64.780000000,64.800000000,3,2,3,2,64.770000000,64.810000000,9,3,5,3,64.760000000,64.820000000,8,11,8,8,64.750000000,64.830000000,6,8,6,8,64.740000000,64.840000000,12,5,11,4,64.730000000,64.850000000,5,8,5,5,64.720000000,64.860000000,8,5,5,4,64.710000000,64.870000000,8,4,7,3,64.700000000,64.880000000,7,4,6,3,64.690000000,64.890000000,4,3,3,2,MCLN5
2025-06-11T00:00:02.222015452Z,2025-06-11T00:00:02.220609603Z,10,1,42026514,A,B,5,64.730000000,1,130,10905,79293834,64.780000000,64.800000000,3,2,3,2,64.770000000,64.810000000,9,3,5,3,64.760000000,64.820000000,8,11,8,8,64.750000000,64.830000000,6,8,6,8,64.740000000,64.840000000,12,5,11,4,64.730000000,64.850000000,6,8,6,5,64.720000000,64.860000000,8,5,5,4,64.710000000,64.870000000,8,4,7,3,64.700000000,64.880000000,7,4,6,3,64.690000000,64.890000000,4,3,3,2,MCLN5
2025-06-11T00:00:02.222024246Z,2025-06-11T00:00:02.220610755Z,10,1,42026514,C,A,6,64.860000000,1,130,11362,79293835,64.780000000,64.800000000,3,2,3,2,64.770000000,64.810000000,9,3,5,3,64.760000000,64.820000000,8,11,8,8,64.750000000,64.830000000,6,8,6,8,64.740000000,64.840000000,12,5,11,4,64.730000000,64.850000000,6,8,6,5,64.720000000,64.860000000,8,4,5,3,64.710000000,64.870000000,8,4,7,3,64.700000000,64.880000000,7,4,6,3,64.690000000,64.890000000,4,3,3,2,MCLN5
2025-06-11T00:00:02.222056293Z,2025-06-11T00:00:02.221777469Z,10,1,42026514,A,A,5,64.850000000,1,130,11459,79293838,64.780000000,64.800000000,3,2,3,2,64.770000000,64.810000000,9,3,5,3,64.760000000,64.820000000,8,11,8,8,64.750000000,64.830000000,6,8,6,8,64.740000000,64.840000000,12,5,11,4,64.730000000,64.850000000,6,9,6,6,64.720000000,64.860000000,8,4,5,3,64.710000000,64.870000000,8,4,7,3,64.700000000,64.880000000,7,4,6,3,64.690000000,64.890000000,4,3,3,2,MCLN5
2025-06-11T00:00:02.295921072Z,2025-06-11T00:00:02.295813677Z,10,1,42025623,M,B,5,63.650000000,1,130,14267,79294146,63.700000000,63.720000000,2,3,2,3,63.690000000,63.730000000,3,2,3,2,63.680000000,63.740000000,1,3,1,3,63.670000000,63.750000000,3,4,3,4,63.660000000,63.760000000,3,4,3,4,63.650000000,63.770000000,6,1,6,1,63.640000000,63.780000000,5,5,5,5,63.630000000,63.790000000,4,1,4,1,63.620000000,63.800000000,3,3,3,3,63.610000000,63.810000000,2,4,2,2,MCLQ5
2025-06-11T00:00:02.364241867Z,2025-06-11T00:00:02.364111891Z,10,1,42026514,C,B,0,64.780000000,1,130,19402,79294264,64.780000000,64.800000000,2,2,2,2,64.770000000,64.810000000,9,3,5,3,64.760000000,64.820000000,8,11,8,8,64.750000000,64.830000000,6,8,6,8,64.740000000,64.840000000,12,5,11,4,64.730000000,64.850000000,6,9,6,6,64.720000000,64.860000000,8,4,5,3,64.710000000,64.870000000,8,4,7,3,64.700000000,64.880000000,7,4,6,3,64.690000000,64.890000000,4,3,3,2,MCLN5
2025-06-11T00:00:02.364294634Z,2025-06-11T00:00:02.364131493Z,10,1,42026514,M,A,2,64.830000000,1,130,12684,79294267,64.780000000,64.800000000,2,2,2,2,64.770000000,64.810000000,9,3,5,3,64.760000000,64.820000000,8,10,8,7,64.750000000,64.830000000,6,9,6,9,64.740000000,64.840000000,12,5,11,4,64.730000000,64.850000000,6,9,6,6,64.720000000,64.860000000,8,4,5,3,64.710000000,64.870000000,8,4,7,3,64.700000000,64.880000000,7,4,6,3,64.690000000,64.890000000,4,3,3,2,MCLN5
2025-06-11T00:00:02.364294634Z,2025-06-11T00:00:02.364132129Z,10,1,42026514,M,B,3,64.750000000,1,130,12684,79294267,64.780000000,64.800000000,2,2,2,2,64.770000000,64.810000000,9,3,5,3,64.760000000,64.820000000,8,10,8,7,64.750000000,64.830000000,7,9,7,9,64.740000000,64.840000000,11,5,10,4,64.730000000,64.850000000,6,9,6,6,64.720000000,64.860000000,8,4,5,3,64.710000000,64.870000000,8,4,7,3,64.700000000,64.880000000,7,4,6,3,64.690000000,64.890000000,4,3,3,2,MCLN5
2025-06-11T00:00:02.364302667Z,2025-06-11T00:00:02.364132991Z,10,1,42026514,M,A,2,64.830000000,1,130,11601,79294268,64.780000000,64.800000000,2,2,2,2,64.770000000,64.810000000,9,3,5,3,64.760000000,64.820000000,8,9,8,6,64.750000000,64.830000000,7,10,7,10,64.740000000,64.840000000,11,5,10,4,64.730000000,64.850000000,6,9,6,6,64.720000000,64.860000000,8,4,5,3,64.710000000,64.870000000,8,4,7,3,64.700000000,64.880000000,7,4,6,3,64.690000000,64.890000000,4,3,3,2,MCLN5
2025-06-11T00:00:02.364313349Z,2025-06-11T00:00:02.364133473Z,10,1,42026514,M,B,3,64.750000000,1,130,10587,79294269,64.780000000,64.800000000,2,2,2,2,64.770000000,64.810000000,9,3,5,3,64.760000000,64.820000000,8,9,8,6,64.750000000,64.830000000,8,10,8,10,64.740000000,64.840000000,10,5,9,4,64.730000000,64.850000000,6,9,6,6,64.720000000,64.860000000,8,4,5,3,64.710000000,64.870000000,8,4,7,3,64.700000000,64.880000000,7,4,6,3,64.690000000,64.890000000,4,3,3,2,MCLN5
2025-06-11T00:00:02.364321750Z,2025-06-11T00:00:02.364133797Z,10,1,42026514,A,A,0,64.800000000,1,130,12581,79294270,64.780000000,64.800000000,2,3,2,3,64.770000000,64.810000000,9,3,5,3,64.760000000,64.820000000,8,9,8,6,64.750000000,64.830000000,8,10,8,10,64.740000000,64.840000000,10,5,9,4,64.730000000,64.850000000,6,9,6,6,64.720000000,64.860000000,8,4,5,3,64.710000000,64.870000000,8,4,7,3,64.700000000,64.880000000,7,4,6,3,64.690000000,64.890000000,4,3,3,2,MCLN5
2025-06-11T00:00:02.364349919Z,2025-06-11T00:00:02.364134123Z,10,1,42026514,M,A,3,64.840000000,1,130,11992,79294272,64.780000000,64.800000000,2,3,2,3,64.770000000,64.810000000,9,3,5,3,64.760000000,64.820000000,8,9,8,6,64.750000000,64.830000000,8,9,8,9,64.740000000,64.840000000,10,6,9,5,64.730000000,64.850000000,6,9,6,6,64.720000000,64.860000000,8,4,5,3,64.710000000,64.870000000,8,4,7,3,64.700000000,64.880000000,7,4,6,3,64.690000000,64.890000000,4,3,3,2,MCLN5
2025-06-11T00:00:02.364358444Z,2025-06-11T00:00:02.364134605Z,10,1,42026514,M,B,3,64.750000000,1,130,12012,79294273,64.780000000,64.800000000,2,3,2,3,64.770000000,64.810000000,9,3,5,3,64.760000000,64.820000000,8,9,8,6,64.750000000,64.830000000,9,9,9,9,64.740000000,64.840000000,9,6,8,5,64.730000000,64.850000000,6,9,6,6,64.720000000,64.860000000,8,4,5,3,64.710000000,64.870000000,8,4,7,3,64.700000000,64.880000000,7,4,6,3,64.690000000,64.890000000,4,3,3,2,MCLN5
2025-06-11T00:00:02.364443357Z,2025-06-11T00:00:02.364141591Z,10,1,42025623,A,A,0,63.710000000,1,130,19776,79294275,63.700000000,63.710000000,2,1,2,1,63.690000000,63.720000000,3,3,3,3,63.680000000,63.730000000,1,2,1,2,63.670000000,63.740000000,3,3,3,3,63.660000000,63.750000000,3,4,3,4,63.650000000,63.760000000,6,4,6,4,63.640000000,63.770000000,5,1,5,1,63.630000000,63.780000000,4,5,4,5,63.620000000,63.790000000,3,1,3,1,63.610000000,63.800000000,2,3,2,3,MCLQ5
2025-06-11T00:00:02.364454431Z,2025-06-11T00:00:02.364145031Z,10,1,42025623,C,B,0,63.700000000,1,130,12686,79294276,63.700000000,63.710000000,1,1,1,1,63.690000000,63.720000000,3,3,3,3,63.680000000,63.730000000,1,2,1,2,63.670000000,63.740000000,3,3,3,3,63.660000000,63.750000000,3,4,3,4,63.650000000,63.760000000,6,4,6,4,63.640000000,63.770000000,5,1,5,1,63.630000000,63.780000000,4,5,4,5,63.620000000,63.790000000,3,1,3,1,63.610000000,63.800000000,2,3,2,3,MCLQ5
2025-06-11T00:00:02.364464737Z,2025-06-11T00:00:02.364151135Z,10,1,42025623,M,A,4,63.760000000,1,130,11778,79294277,63.700000000,63.710000000,1,1,1,1,63.690000000,63.720000000,3,3,3,3,63.680000000,63.730000000,1,2,1,2,63.670000000,63.740000000,3,3,3,3,63.660000000,63.750000000,3,3,3,3,63.650000000,63.760000000,6,5,6,5,63.640000000,63.770000000,5,1,5,1,63.630000000,63.780000000,4,5,4,5,63.620000000,63.790000000,3,1,3,1,63.610000000,63.800000000,2,3,2,3,MCLQ5
2025-06-11T00:00:02.364474482Z,2025-06-11T00:00:02.364151575Z,10,1,42025623,M,B,4,63.660000000,1,130,10808,79294278,63.700000000,63.710000000,1,1,1,1,63.690000000,63.720000000,3,3,3,3,63.680000000,63.730000000,1,2,1,2,63.670000000,63.740000000,3,3,3,3,63.660000000,63.750000000,4,3,4,3,63.650000000,63.760000000,5,5,5,5,63.640000000,63.770000000,5,1,5,1,63.630000000,63.780000000,4,5,4,5,63.620000000,63.790000000,3,1,3,1,63.610000000,63.800000000,2,3,2,3,MCLQ5
2025-06-11T00:00:02.364485986Z,2025-06-11T00:00:02.364152249Z,10,1,42025623,M,A,4,63.760000000,1,130,11420,79294279,63.700000000,63.710000000,1,1,1,1,63.690000000,63.720000000,3,3,3,3,63.680000000,63.730000000,1,2,1,2,63.670000000,63.740000000,3,3,3,3,63.660000000,63.750000000,4,2,4,2,63.650000000,63.760000000,5,6,5,6,63.640000000,63.770000000,5,1,5,1,63.630000000,63.780000000,4,5,4,5,63.620000000,63.790000000,3,1,3,1,63.610000000,63.800000000,2,3,2,3,MCLQ5
2025-06-11T00:00:02.364496569Z,2025-06-11T00:00:02.364152805Z,10,1,42025623,M,B,4,63.660000000,1,130,11128,79294280,63.700000000,63.710000000,1,1,1,1,63.690000000,63.720000000,3,3,3,3,63.680000000,63.730000000,1,2,1,2,63.670000000,63.740000000,3,3,3,3,63.660000000,63.750000000,5,2,5,2,63.650000000,63.760000000,4,6,4,6,63.640000000,63.770000000,5,1,5,1,63.630000000,63.780000000,4,5,4,5,63.620000000,63.790000000,3,1,3,1,63.610000000,63.800000000,2,3,2,3,MCLQ5
2025-06-11T00:00:02.364625455Z,2025-06-11T00:00:02.364372231Z,10,1,42026514,A,A,0,64.790000000,2,130,11617,79294285,64.780000000,64.790000000,2,2,2,1,64.770000000,64.800000000,9,3,5,3,64.760000000,64.810000000,8,3,8,3,64.750000000,64.820000000,9,9,9,6,64.740000000,64.830000000,9,9,8,9,64.730000000,64.840000000,6,6,6,5,64.720000000,64.850000000,8,9,5,6,64.710000000,64.860000000,8,4,7,3,64.700000000,64.870000000,7,4,6,3,64.690000000,64.880000000,4,4,3,3,MCLN5
2025-06-11T00:00:02.364695846Z,2025-06-11T00:00:02.364595709Z,10,1,42025623,M,A,1,63.720000000,1,130,12327,79294289,63.700000000,63.710000000,1,1,1,1,63.690000000,63.720000000,3,4,3,4,63.680000000,63.730000000,1,2,1,2,63.670000000,63.740000000,3,3,3,3,63.660000000,63.750000000,5,2,5,2,63.650000000,63.760000000,4,6,4,6,63.640000000,63.770000000,5,1,5,1,63.630000000,63.780000000,4,5,4,5,63.620000000,63.790000000,3,1,3,1,63.610000000,63.800000000,2,3,2,3,MCLQ5
2025-06-11T00:00:02.364713855Z,2025-06-11T00:00:02.364616119Z,10,1,42022708,M,B,0,2.780000000,1,130,11917,79294290,2.810000000,2.830000000,1,2,1,2,2.800000000,2.840000000,12,12,3,3,2.790000000,2.850000000,2,1,2,1,2.780000000,2.870000000,1,1,1,1,,,0,0,0,0,,,0,0,0,0,,,0,0,0,0,,,0,0,0,0,,,0,0,0,0,,,0,0,0,0,MCLN5-MCLV5
2025-06-11T00:00:02.364779531Z,2025-06-11T00:00:02.364675253Z,10,1,42026514,M,A,1,64.800000000,1,130,15837,79294291,64.780000000,64.790000000,2,2,2,1,64.770000000,64.800000000,9,4,5,4,64.760000000,64.810000000,8,3,8,3,64.750000000,64.820000000,9,9,9,6,64.740000000,64.830000000,9,9,8,9,64.730000000,64.840000000,6,6,6,5,64.720000000,64.850000000,8,9,5,6,64.710000000,64.860000000,8,4,7,3,64.700000000,64.870000000,7,4,6,3,64.690000000,64.880000000,4,4,3,3,MCLN5
2025-06-11T00:00:02.364864890Z,2025-06-11T00:00:02.364771459Z,10,1,42025623,C,A,1,63.720000000,1,130,12009,79294293,63.700000000,63.710000000,1,1,1,1,63.690000000,63.720000000,3,3,3,3,63.680000000,63.730000000,1,2,1,2,63.670000000,63.740000000,3,3,3,3,63.660000000,63.750000000,5,2,5,2,63.650000000,63.760000000,4,6,4,6,63.640000000,63.770000000,5,1,5,1,63.630000000,63.780000000,4,5,4,5,63.620000000,63.790000000,3,1,3,1,63.610000000,63.800000000,2,3,2,3,MCLQ5
2025-06-11T00:00:02.364884880Z,2025-06-11T00:00:02.364783901Z,10,1,42026514,C,A,1,64.800000000,1,130,16586,79294294,64.780000000,64.790000000,2,2,2,1,64.770000000,64.800000000,9,3,5,3,64.760000000,64.810000000,8,3,8,3,64.750000000,64.820000000,9,9,9,6,64.740000000,64.830000000,9,9,8,9,64.730000000,64.840000000,6,6,6,5,64.720000000,64.850000000,8,9,5,6,64.710000000,64.860000000,8,4,7,3,64.700000000,64.870000000,7,4,6,3,64.690000000,64.880000000,4,4,3,3,MCLN5
2025-06-11T00:00:02.364898764Z,2025-06-11T00:00:02.364803271Z,10,1,42026514,M,A,2,64.810000000,1,130,11697,79294295,64.780000000,64.790000000,2,2,2,1,64.770000000,64.800000000,9,3,5,3,64.760000000,64.810000000,8,4,8,4,64.750000000,64.820000000,9,9,9,6,64.740000000,64.830000000,9,9,8,9,64.730000000,64.840000000,6,6,6,5,64.720000000,64.850000000,8,9,5,6,64.710000000,64.860000000,8,4,7,3,64.700000000,64.870000000,7,4,6,3,64.690000000,64.880000000,4,4,3,3,MCLN5
2025-06-11T00:00:02.367712438Z,2025-06-11T00:00:02.367591143Z,10,1,42026514,C,A,0,64.790000000,2,130,11404,79294364,64.780000000,64.800000000,2,3,2,3,64.770000000,64.810000000,9,4,5,4,64.760000000,64.820000000,8,9,8,6,64.750000000,64.830000000,9,9,9,9,64.740000000,64.840000000,9,6,8,5,64.730000000,64.850000000,6,9,6,6,64.720000000,64.860000000,8,4,5,3,64.710000000,64.870000000,8,4,7,3,64.700000000,64.880000000,7,4,6,3,64.690000000,64.890000000,4,3,3,2,MCLN5
2025-06-11T00:00:02.368004109Z,2025-06-11T00:00:02.367901247Z,10,1,42026514,M,A,1,66.770000000,3,130,16667,79294371,64.780000000,64.800000000,2,3,2,3,64.770000000,64.810000000,9,3,5,3,64.760000000,64.820000000,8,9,8,6,64.750000000,64.830000000,9,9,9,9,64.740000000,64.840000000,9,6,8,5,64.730000000,64.850000000,6,9,6,6,64.720000000,64.860000000,8,4,5,3,64.710000000,64.870000000,8,4,7,3,64.700000000,64.880000000,7,4,6,3,64.690000000,64.890000000,4,3,3,2,MCLN5
2025-06-11T00:00:02.375829440Z,2025-06-11T00:00:02.375703149Z,10,1,42025623,C,A,0,63.710000000,1,130,15191,79294375,63.700000000,63.720000000,1,3,1,3,63.690000000,63.730000000,3,2,3,2,63.680000000,63.740000000,1,3,1,3,63.670000000,63.750000000,3,2,3,2,63.660000000,63.760000000,5,6,5,6,63.650000000,63.770000000,4,1,4,1,63.640000000,63.780000000,5,5,5,5,63.630000000,63.790000000,4,1,4,1,63.620000000,63.800000000,3,3,3,3,63.610000000,63.810000000,2,4,2,2,MCLQ5
2025-06-11T00:00:02.377234384Z,2025-06-11T00:00:02.376937309Z,10,1,42026514,A,B,0,64.780000000,1,130,16019,79294386,64.780000000,64.800000000,3,3,3,3,64.770000000,64.810000000,9,3,5,3,64.760000000,64.820000000,8,9,8,6,64.750000000,64.830000000,9,9,9,9,64.740000000,64.840000000,9,6,8,5,64.730000000,64.850000000,6,9,6,6,64.720000000,64.860000000,8,4,5,3,64.710000000,64.870000000,8,4,7,3,64.700000000,64.880000000,7,4,6,3,64.690000000,64.890000000,4,3,3,2,MCLN5
2025-06-11T00:00:02.377246372Z,2025-06-11T00:00:02.376938459Z,10,1,42026514,C,A,0,64.800000000,1,130,15127,79294387,64.780000000,64.800000000,3,2,3,2,64.770000000,64.810000000,9,3,5,3,64.760000000,64.820000000,8,9,8,6,64.750000000,64.830000000,9,9,9,9,64.740000000,64.840000000,9,6,8,5,64.730000000,64.850000000,6,9,6,6,64.720000000,64.860000000,8,4,5,3,64.710000000,64.870000000,8,4,7,3,64.700000000,64.880000000,7,4,6,3,64.690000000,64.890000000,4,3,3,2,MCLN5
2025-06-11T00:00:02.377291451Z,2025-06-11T00:00:02.377113383Z,10,1,42026514,A,B,0,64.790000000,2,130,20477,79294390,64.790000000,64.800000000,2,2,1,2,64.780000000,64.810000000,3,3,3,3,64.770000000,64.820000000,9,9,5,6,64.760000000,64.830000000,8,9,8,9,64.750000000,64.840000000,9,6,9,5,64.740000000,64.850000000,9,9,8,6,64.730000000,64.860000000,6,4,6,3,64.720000000,64.870000000,8,4,5,3,64.710000000,64.880000000,8,4,7,3,64.700000000,64.890000000,7,3,6,2,MCLN5
2025-06-11T00:00:02.377400847Z,2025-06-11T00:00:02.377194271Z,10,1,42026514,A,A,0,64.800000000,1,130,13589,79294395,64.790000000,64.800000000,2,3,1,3,64.780000000,64.810000000,3,3,3,3,64.770000000,64.820000000,9,9,5,6,64.760000000,64.830000000,8,9,8,9,64.750000000,64.840000000,9,6,9,5,64.740000000,64.850000000,9,9,8,6,64.730000000,64.860000000,6,4,6,3,64.720000000,64.870000000,8,4,5,3,64.710000000,64.880000000,8,4,7,3,64.700000000,64.890000000,7,3,6,2,MCLN5
2025-06-11T00:00:02.377415899Z,2025-06-11T00:00:02.377214947Z,10,1,42026514,C,B,1,64.780000000,1,130,12522,79294396,64.790000000,64.800000000,2,3,1,3,64.780000000,64.810000000,2,3,2,3,64.770000000,64.820000000,9,9,5,6,64.760000000,64.830000000,8,9,8,9,64.750000000,64.840000000,9,6,9,5,64.740000000,64.850000000,9,9,8,6,64.730000000,64.860000000,6,4,6,3,64.720000000,64.870000000,8,4,5,3,64.710000000,64.880000000,8,4,7,3,64.700000000,64.890000000,7,3,6,2,MCLN5
2025-06-11T00:00:02.377461500Z,2025-06-11T00:00:02.377299041Z,10,1,42026514,C,A,5,64.850000000,1,130,12777,79294400,64.790000000,64.800000000,2,3,1,3,64.780000000,64.810000000,2,3,2,3,64.770000000,64.820000000,9,9,5,6,64.760000000,64.830000000,8,9,8,9,64.750000000,64.840000000,9,6,9,5,64.740000000,64.850000000,9,8,8,5,64.730000000,64.860000000,6,4,6,3,64.720000000,64.870000000,8,4,5,3,64.710000000,64.880000000,8,4,7,3,64.700000000,64.890000000,7,3,6,2,MCLN5
2025-06-11T00:00:02.377568140Z,2025-06-11T00:00:02.377443763Z,10,1,42025623,A,A,0,63.710000000,1,130,18965,79294403,63.700000000,63.710000000,1,1,1,1,63.690000000,63.720000000,3,3,3,3,63.680000000,63.730000000,1,2,1,2,63.670000000,63.740000000,3,3,3,3,63.660000000,63.750000000,5,2,5,2,63.650000000,63.760000000,4,6,4,6,63.640000000,63.770000000,5,1,5,1,63.630000000,63.780000000,4,5,4,5,63.620000000,63.790000000,3,1,3,1,63.610000000,63.800000000,2,3,2,3,MCLQ5
2025-06-11T00:00:02.377586640Z,2025-06-11T00:00:02.377472505Z,10,1,42026514,C,A,0,64.800000000,1,130,13600,79294404,64.790000000,64.800000000,2,2,1,2,64.780000000,64.810000000,2,3,2,3,64.770000000,64.820000000,9,9,5,6,64.760000000,64.830000000,8,9,8,9,64.750000000,64.840000000,9,6,9,5,64.740000000,64.850000000,9,8,8,5,64.730000000,64.860000000,6,4,6,3,64.720000000,64.870000000,8,4,5,3,64.710000000,64.880000000,8,4,7,3,64.700000000,64.890000000,7,3,6,2,MCLN5
2025-06-11T00:00:02.377683456Z,2025-06-11T00:00:02.377568827Z,10,1,42026514,M,A,0,64.800000000,1,130,13101,79294409,64.790000000,64.800000000,2,3,1,3,64.780000000,64.810000000,2,3,2,3,64.770000000,64.820000000,9,9,5,6,64.760000000,64.830000000,8,9,8,9,64.750000000,64.840000000,9,6,9,5,64.740000000,64.850000000,9,8,8,5,64.730000000,64.860000000,6,4,6,3,64.720000000,64.870000000,8,4,5,3,64.710000000,64.880000000,8,4,7,3,64.700000000,64.890000000,7,3,6,2,MCLN5
2025-06-11T00:00:02.377825314Z,2025-06-11T00:00:02.377719655Z,10,1,42025623,M,A,1,63.720000000,1,130,11408,79294411,63.700000000,63.710000000,1,1,1,1,63.690000000,63.720000000,3,4,3,4,63.680000000,63.730000000,1,2,1,2,63.670000000,63.740000000,3,3,3,3,63.660000000,63.750000000,5,2,5,2,63.650000000,63.760000000,4,6,4,6,63.640000000,63.770000000,5,1,5,1,63.630000000,63.780000000,4,5,4,5,63.620000000,63.790000000,3,1,3,1,63.610000000,63.800000000,2,3,2,3,MCLQ5
2025-06-11T00:00:02.378265063Z,2025-06-11T00:00:02.378154823Z,10,1,42026514,C,B,0,64.790000000,2,130,14671,79294412,64.780000000,64.800000000,2,3,2,3,64.770000000,64.810000000,9,3,5,3,64.760000000,64.820000000,8,9,8,6,64.750000000,64.830000000,9,9,9,9,64.740000000,64.840000000,9,6,8,5,64.730000000,64.850000000,6,8,6,5,64.720000000,64.860000000,8,4,5,3,64.710000000,64.870000000,8,4,7,3,64.700000000,64.880000000,7,4,6,3,64.690000000,64.890000000,4,3,3,2,MCLN5
2025-06-11T00:00:02.378899674Z,2025-06-11T00:00:02.378799127Z,10,1,42025623,M,A,1,65.090000000,1,130,15324,79294416,63.700000000,63.710000000,1,1,1,1,63.690000000,63.720000000,3,3,3,3,63.680000000,63.730000000,1,2,1,2,63.670000000,63.740000000,3,3,3,3,63.660000000,63.750000000,5,2,5,2,63.650000000,63.760000000,4,6,4,6,63.640000000,63.770000000,5,1,5,1,63.630000000,63.780000000,4,5,4,5,63.620000000,63.790000000,3,1,3,1,63.610000000,63.800000000,2,3,2,3,MCLQ5
2025-06-11T00:00:02.391940941Z,2025-06-11T00:00:02.391830935Z,10,1,42025623,C,A,0,63.710000000,1,130,14769,79294429,63.700000000,63.720000000,1,3,1,3,63.690000000,63.730000000,3,2,3,2,63.680000000,63.740000000,1,3,1,3,63.670000000,63.750000000,3,2,3,2,63.660000000,63.760000000,5,6,5,6,63.650000000,63.770000000,4,1,4,1,63.640000000,63.780000000,5,5,5,5,63.630000000,63.790000000,4,1,4,1,63.620000000,63.800000000,3,3,3,3,63.610000000,63.810000000,2,4,2,2,MCLQ5
2025-06-11T00:00:02.391987817Z,2025-06-11T00:00:02.391848791Z,10,1,42026514,A,B,0,64.780000000,1,130,14290,79294432,64.780000000,64.800000000,3,3,3,3,64.770000000,64.810000000,9,3,5,3,64.760000000,64.820000000,8,9,8,6,64.750000000,64.830000000,9,9,9,9,64.740000000,64.840000000,9,6,8,5,64.730000000,64.850000000,6,8,6,5,64.720000000,64.860000000,8,4,5,3,64.710000000,64.870000000,8,4,7,3,64.700000000,64.880000000,7,4,6,3,64.690000000,64.890000000,4,3,3,2,MCLN5
2025-06-11T00:00:02.391995028Z,2025-06-11T00:00:02.391862057Z,10,1,42026514,A,A,5,64.850000000,1,130,11362,79294433,64.780000000,64.800000000,3,3,3,3,64.770000000,64.810000000,9,3,5,3,64.760000000,64.820000000,8,9,8,6,64.750000000,64.830000000,9,9,9,9,64.740000000,64.840000000,9,6,8,5,64.730000000,64.850000000,6,9,6,6,64.720000000,64.860000000,8,4,5,3,64.710000000,64.870000000,8,4,7,3,64.700000000,64.880000000,7,4,6,3,64.690000000,64.890000000,4,3,3,2,MCLN5
2025-06-11T00:00:02.403574630Z,2025-06-11T00:00:02.403457019Z,10,1,42026514,M,A,0,66.760000000,3,130,14105,79294473,64.780000000,64.800000000,3,2,3,2,64.770000000,64.810000000,9,3,5,3,64.760000000,64.820000000,8,9,8,6,64.750000000,64.830000000,9,9,9,9,64.740000000,64.840000000,9,6,8,5,64.730000000,64.850000000,6,9,6,6,64.720000000,64.860000000,8,4,5,3,64.710000000,64.870000000,8,4,7,3,64.700000000,64.880000000,7,4,6,3,64.690000000,64.890000000,4,3,3,2,MCLN5
2025-06-11T00:00:03.001839135Z,2025-06-11T00:00:03.001737929Z,10,1,42025611,M,B,0,2.040000000,1,130,13651,79295040,2.070000000,2.090000000,3,7,2,5,2.060000000,2.100000000,23,27,3,6,2.050000000,2.110000000,23,23,3,4,2.040000000,2.120000000,23,22,3,2,2.030000000,2.130000000,2,2,1,2,2.020000000,2.140000000,2,2,2,1,2.010000000,2.150000000,2,2,1,1,2.000000000,2.160000000,2,2,2,1,1.990000000,2.170000000,2,2,1,1,1.980000000,2.180000000,2,2,2,2,MCLN5-MCLU5
2025-06-11T00:00:03.267065989Z,2025-06-11T00:00:03.266499753Z,10,1,42022708,M,B,0,2.810000000,1,130,11768,79295538,2.810000000,2.830000000,2,2,2,2,2.800000000,2.840000000,12,12,3,3,2.790000000,2.850000000,2,1,2,1,,2.870000000,0,1,0,1,,,0,0,0,0,,,0,0,0,0,,,0,0,0,0,,,0,0,0,0,,,0,0,0,0,,,0,0,0,0,MCLN5-MCLV5
2025-06-11T00:00:03.267340834Z,2025-06-11T00:00:03.266552455Z,10,1,42418117,M,B,0,3.260000000,1,130,15207,79295561,3.260000000,3.280000000,1,1,1,1,3.250000000,3.290000000,11,11,2,2,3.240000000,3.300000000,1,1,1,1,,,0,0,0,0,,,0,0,0,0,,,0,0,0,0,,,0,0,0,0,,,0,0,0,0,,,0,0,0,0,,,0,0,0,0,MCLN5-MCLX5
2025-06-11T00:00:03.273999457Z,2025-06-11T00:00:03.273487361Z,10,1,42022708,M,B,0,2.810000000,10,130,11935,79295898,2.810000000,2.830000000,12,2,3,2,2.800000000,2.840000000,2,12,2,3,2.790000000,2.850000000,2,1,2,1,,2.870000000,0,1,0,1,,,0,0,0,0,,,0,0,0,0,,,0,0,0,0,,,0,0,0,0,,,0,0,0,0,,,0,0,0,0,MCLN5-MCLV5
2025-06-11T00:00:03.274894261Z,2025-06-11T00:00:03.273988055Z,10,1,42022708,M,B,0,2.800000000,10,130,11452,79295925,2.810000000,2.830000000,2,2,2,2,2.800000000,2.840000000,12,12,3,3,2.790000000,2.850000000,2,1,2,1,,2.870000000,0,1,0,1,,,0,0,0,0,,,0,0,0,0,,,0,0,0,0,,,0,0,0,0,,,0,0,0,0,,,0,0,0,0,MCLN5-MCLV5
2025-06-11T00:00:03.274903615Z,2025-06-11T00:00:03.274017469Z,10,1,42022708,M,B,0,2.810000000,10,130,11311,79295926,2.810000000,2.830000000,12,2,3,2,2.800000000,2.840000000,2,12,2,3,2.790000000,2.850000000,2,1,2,1,,2.870000000,0,1,0,1,,,0,0,0,0,,,0,0,0,0,,,0,0,0,0,,,0,0,0,0,,,0,0,0,0,,,0,0,0,0,MCLN5-MCLV5
2025-06-11T00:00:03.274962325Z,2025-06-11T00:00:03.274051087Z,10,1,42284507,M,B,0,0.990000000,3,130,14916,79295931,0.990000000,1.000000000,11,5,5,3,0.980000000,1.010000000,19,25,6,8,0.970000000,1.020000000,21,18,6,5,0.960000000,1.030000000,17,23,6,7,0.950000000,1.040000000,10,15,6,4,0.940000000,1.050000000,4,8,3,4,0.930000000,1.060000000,3,4,2,2,0.920000000,1.070000000,3,2,2,1,0.910000000,1.080000000,3,2,2,1,0.900000000,1.090000000,2,4,1,2,MCLQ5-MCLU5
2025-06-11T00:00:03.275179627Z,2025-06-11T00:00:03.274951737Z,10,1,42022708,M,B,0,2.800000000,10,130,10826,79295951,2.810000000,2.830000000,2,2,2,2,2.800000000,2.840000000,12,12,3,3,2.790000000,2.850000000,2,1,2,1,,2.870000000,0,1,0,1,,,0,0,0,0,,,0,0,0,0,,,0,0,0,0,,,0,0,0,0,,,0,0,0,0,,,0,0,0,0,MCLN5-MCLV5
2025-06-11T00:00:03.412138589Z,2025-06-11T00:00:03.411980745Z,10,1,42025623,A,A,0,63.710000000,1,130,19595,79296233,63.700000000,63.710000000,1,1,1,1,63.690000000,63.720000000,3,3,3,3,63.680000000,63.730000000,1,2,1,2,63.670000000,63.740000000,3,3,3,3,63.660000000,63.750000000,5,2,5,2,63.650000000,63.760000000,4,6,4,6,63.640000000,63.770000000,5,1,5,1,63.630000000,63.780000000,4,5,4,5,63.620000000,63.790000000,3,1,3,1,63.610000000,63.800000000,2,3,2,3,MCLQ5
2025-06-11T00:00:03.412404180Z,2025-06-11T00:00:03.412303003Z,10,1,42025623,M,A,1,63.720000000,1,130,15510,79296234,63.700000000,63.710000000,1,1,1,1,63.690000000,63.720000000,3,4,3,4,63.680000000,63.730000000,1,2,1,2,63.670000000,63.740000000,3,3,3,3,63.660000000,63.750000000,5,2,5,2,63.650000000,63.760000000,4,6,4,6,63.640000000,63.770000000,5,1,5,1,63.630000000,63.780000000,4,5,4,5,63.620000000,63.790000000,3,1,3,1,63.610000000,63.800000000,2,3,2,3,MCLQ5
2025-06-11T00:00:03.412473189Z,2025-06-11T00:00:03.412377785Z,10,1,42025623,C,A,1,63.720000000,1,130,12129,79296235,63.700000000,63.710000000,1,1,1,1,63.690000000,63.720000000,3,3,3,3,63.680000000,63.730000000,1,2,1,2,63.670000000,63.740000000,3,3,3,3,63.660000000,63.750000000,5,2,5,2,63.650000000,63.760000000,4,6,4,6,63.640000000,63.770000000,5,1,5,1,63.630000000,63.780000000,4,5,4,5,63.620000000,63.790000000,3,1,3,1,63.610000000,63.800000000,2,3,2,3,MCLQ5
2025-06-11T00:00:03.431466848Z,2025-06-11T00:00:03.431365033Z,10,1,42284507,M,B,0,0.990000000,1,130,11361,79296286,0.990000000,1.000000000,12,5,6,3,0.980000000,1.010000000,19,25,6,8,0.970000000,1.020000000,21,18,6,5,0.960000000,1.030000000,17,23,6,7,0.950000000,1.040000000,10,15,6,4,0.940000000,1.050000000,4,8,3,4,0.930000000,1.060000000,3,4,2,2,0.920000000,1.070000000,3,2,2,1,0.910000000,1.080000000,3,2,2,1,0.900000000,1.090000000,2,4,1,2,MCLQ5-MCLU5
2025-06-11T00:00:03.673275706Z,2025-06-11T00:00:03.673123509Z,10,1,42025623,C,A,0,63.710000000,1,130,12241,79296416,63.700000000,63.720000000,1,3,1,3,63.690000000,63.730000000,3,2,3,2,63.680000000,63.740000000,1,3,1,3,63.670000000,63.750000000,3,2,3,2,63.660000000,63.760000000,5,6,5,6,63.650000000,63.770000000,4,1,4,1,63.640000000,63.780000000,5,5,5,5,63.630000000,63.790000000,4,1,4,1,63.620000000,63.800000000,3,3,3,3,63.610000000,63.810000000,2,4,2,2,MCLQ5
2025-06-11T00:00:04.206334645Z,2025-06-11T00:00:04.206116267Z,10,1,42025623,A,A,0,63.710000000,1,130,15426,79296544,63.700000000,63.710000000,1,1,1,1,63.690000000,63.720000000,3,3,3,3,63.680000000,63.730000000,1,2,1,2,63.670000000,63.740000000,3,3,3,3,63.660000000,63.750000000,5,2,5,2,63.650000000,63.760000000,4,6,4,6,63.640000000,63.770000000,5,1,5,1,63.630000000,63.780000000,4,5,4,5,63.620000000,63.790000000,3,1,3,1,63.610000000,63.800000000,2,3,2,3,MCLQ5
2025-06-11T00:00:04.208019387Z,2025-06-11T00:00:04.206291825Z,10,1,42026514,A,A,0,64.800000000,1,130,16627,79296563,64.780000000,64.800000000,3,3,3,3,64.770000000,64.810000000,9,3,5,3,64.760000000,64.820000000,8,9,8,6,64.750000000,64.830000000,9,9,9,9,64.740000000,64.840000000,9,6,8,5,64.730000000,64.850000000,6,9,6,6,64.720000000,64.860000000,8,4,5,3,64.710000000,64.870000000,8,4,7,3,64.700000000,64.880000000,7,4,6,3,64.690000000,64.890000000,4,3,3,2,MCLN5
2025-06-11T00:00:04.208034055Z,2025-06-11T00:00:04.206292169Z,10,1,42026514,A,A,0,64.800000000,1,130,13507,79296564,64.780000000,64.800000000,3,4,3,4,64.770000000,64.810000000,9,3,5,3,64.760000000,64.820000000,8,9,8,6,64.750000000,64.830000000,9,9,9,9,64.740000000,64.840000000,9,6,8,5,64.730000000,64.850000000,6,9,6,6,64.720000000,64.860000000,8,4,5,3,64.710000000,64.870000000,8,4,7,3,64.700000000,64.880000000,7,4,6,3,64.690000000,64.890000000,4,3,3,2,MCLN5
2025-06-11T00:00:04.208055804Z,2025-06-11T00:00:04.206295857Z,10,1,42026514,C,B,0,64.780000000,1,130,12883,79296565,64.780000000,64.800000000,2,4,2,4,64.770000000,64.810000000,9,3,5,3,64.760000000,64.820000000,8,9,8,6,64.750000000,64.830000000,9,9,9,9,64.740000000,64.840000000,9,6,8,5,64.730000000,64.850000000,6,9,6,6,64.720000000,64.860000000,8,4,5,3,64.710000000,64.870000000,8,4,7,3,64.700000000,64.880000000,7,4,6,3,64.690000000,64.890000000,4,3,3,2,MCLN5
2025-06-11T00:00:04.210680375Z,2025-06-11T00:00:04.208042499Z,10,1,42026514,M,B,3,64.740000000,1,130,12834,79296709,64.780000000,64.800000000,2,4,2,4,64.770000000,64.810000000,9,3,5,3,64.760000000,64.820000000,8,9,8,6,64.750000000,64.830000000,8,9,8,9,64.740000000,64.840000000,10,6,9,5,64.730000000,64.850000000,6,9,6,6,64.720000000,64.860000000,8,4,5,3,64.710000000,64.870000000,8,4,7,3,64.700000000,64.880000000,7,4,6,3,64.690000000,64.890000000,4,3,3,2,MCLN5
2025-06-11T00:00:04.210687840Z,2025-06-11T00:00:04.208043019Z,10,1,42026514,M,A,3,64.830000000,1,130,11658,79296710,64.780000000,64.800000000,2,4,2,4,64.770000000,64.810000000,9,3,5,3,64.760000000,64.820000000,8,9,8,6,64.750000000,64.830000000,8,10,8,10,64.740000000,64.840000000,10,5,9,4,64.730000000,64.850000000,6,9,6,6,64.720000000,64.860000000,8,4,5,3,64.710000000,64.870000000,8,4,7,3,64.700000000,64.880000000,7,4,6,3,64.690000000,64.890000000,4,3,3,2,MCLN5
2025-06-11T00:00:04.210728864Z,2025-06-11T00:00:04.208069839Z,10,1,42026514,C,A,0,64.800000000,1,130,16629,79296713,64.780000000,64.800000000,2,3,2,3,64.770000000,64.810000000,9,3,5,3,64.760000000,64.820000000,8,9,8,6,64.750000000,64.830000000,8,10,8,10,64.740000000,64.840000000,10,5,9,4,64.730000000,64.850000000,6,9,6,6,64.720000000,64.860000000,8,4,5,3,64.710000000,64.870000000,8,4,7,3,64.700000000,64.880000000,7,4,6,3,64.690000000,64.890000000,4,3,3,2,MCLN5
2025-06-11T00:00:04.210746189Z,2025-06-11T00:00:04.208081433Z,10,1,42026514,A,B,0,64.780000000,1,130,13774,79296714,64.780000000,64.800000000,3,3,3,3,64.770000000,64.810000000,9,3,5,3,64.760000000,64.820000000,8,9,8,6,64.750000000,64.830000000,8,10,8,10,64.740000000,64.840000000,10,5,9,4,64.730000000,64.850000000,6,9,6,6,64.720000000,64.860000000,8,4,5,3,64.710000000,64.870000000,8,4,7,3,64.700000000,64.880000000,7,4,6,3,64.690000000,64.890000000,4,3,3,2,MCLN5
2025-06-11T00:00:04.210769735Z,2025-06-11T00:00:04.208081801Z,10,1,42026514,A,A,0,64.790000000,2,130,10665,79296715,64.780000000,64.790000000,3,2,3,1,64.770000000,64.800000000,9,3,5,3,64.760000000,64.810000000,8,3,8,3,64.750000000,64.820000000,8,9,8,6,64.740000000,64.830000000,10,10,9,10,64.730000000,64.840000000,6,5,6,4,64.720000000,64.850000000,8,9,5,6,64.710000000,64.860000000,8,4,7,3,64.700000000,64.870000000,7,4,6,3,64.690000000,64.880000000,4,4,3,3,MCLN5
2025-06-11T00:00:04.210920472Z,2025-06-11T00:00:04.208203119Z,10,1,42026514,M,A,1,64.800000000,1,130,16730,79296727,64.780000000,64.790000000,3,2,3,1,64.770000000,64.800000000,9,4,5,4,64.760000000,64.810000000,8,3,8,3,64.750000000,64.820000000,8,9,8,6,64.740000000,64.830000000,10,10,9,10,64.730000000,64.840000000,6,5,6,4,64.720000000,64.850000000,8,9,5,6,64.710000000,64.860000000,8,4,7,3,64.700000000,64.870000000,7,4,6,3,64.690000000,64.880000000,4,4,3,3,MCLN5
2025-06-11T00:00:04.211138348Z,2025-06-11T00:00:04.208399547Z,10,1,42025623,M,B,4,63.650000000,1,130,12019,79296743,63.700000000,63.710000000,1,1,1,1,63.690000000,63.720000000,3,3,3,3,63.680000000,63.730000000,1,2,1,2,63.670000000,63.740000000,3,3,3,3,63.660000000,63.750000000,4,2,4,2,63.650000000,63.760000000,5,6,5,6,63.640000000,63.770000000,5,1,5,1,63.630000000,63.780000000,4,5,4,5,63.620000000,63.790000000,3,1,3,1,63.610000000,63.800000000,2,3,2,3,MCLQ5
2025-06-11T00:00:04.211148477Z,2025-06-11T00:00:04.208399987Z,10,1,42025623,M,A,4,63.750000000,1,130,11363,79296744,63.700000000,63.710000000,1,1,1,1,63.690000000,63.720000000,3,3,3,3,63.680000000,63.730000000,1,2,1,2,63.670000000,63.740000000,3,3,3,3,63.660000000,63.750000000,4,3,4,3,63.650000000,63.760000000,5,5,5,5,63.640000000,63.770000000,5,1,5,1,63.630000000,63.780000000,4,5,4,5,63.620000000,63.790000000,3,1,3,1,63.610000000,63.800000000,2,3,2,3,MCLQ5
2025-06-11T00:00:04.211158630Z,2025-06-11T00:00:04.208400601Z,10,1,42025623,M,B,4,63.650000000,1,130,11388,79296745,63.700000000,63.710000000,1,1,1,1,63.690000000,63.720000000,3,3,3,3,63.680000000,63.730000000,1,2,1,2,63.670000000,63.740000000,3,3,3,3,63.660000000,63.750000000,3,3,3,3,63.650000000,63.760000000,6,5,6,5,63.640000000,63.770000000,5,1,5,1,63.630000000,63.780000000,4,5,4,5,63.620000000,63.790000000,3,1,3,1,63.610000000,63.800000000,2,3,2,3,MCLQ5
2025-06-11T00:00:04.211169550Z,2025-06-11T00:00:04.208401255Z,10,1,42025623,M,A,4,63.750000000,1,130,11440,79296746,63.700000000,63.710000000,1,1,1,1,63.690000000,63.720000000,3,3,3,3,63.680000000,63.730000000,1,2,1,2,63.670000000,63.740000000,3,3,3,3,63.660000000,63.750000000,3,4,3,4,63.650000000,63.760000000,6,4,6,4,63.640000000,63.770000000,5,1,5,1,63.630000000,63.780000000,4,5,4,5,63.620000000,63.790000000,3,1,3,1,63.610000000,63.800000000,2,3,2,3,MCLQ5
2025-06-11T00:00:04.211301332Z,2025-06-11T00:00:04.208700799Z,10,1,42026514,C,B,0,64.780000000,1,130,13796,79296757,64.780000000,64.790000000,2,2,2,1,64.770000000,64.800000000,9,4,5,4,64.760000000,64.810000000,8,3,8,3,64.750000000,64.820000000,8,9,8,6,64.740000000,64.830000000,10,10,9,10,64.730000000,64.840000000,6,5,6,4,64.720000000,64.850000000,8,9,5,6,64.710000000,64.860000000,8,4,7,3,64.700000000,64.870000000,7,4,6,3,64.690000000,64.880000000,4,4,3,3,MCLN5
2025-06-11T00:00:04.211907098Z,2025-06-11T00:00:04.209313635Z,10,1,42026514,M,B,3,64.740000000,1,130,11615,79296796,64.780000000,64.790000000,2,2,2,1,64.770000000,64.800000000,9,4,5,4,64.760000000,64.810000000,8,3,8,3,64.750000000,64.820000000,7,9,7,6,64.740000000,64.830000000,11,10,10,10,64.730000000,64.840000000,6,5,6,4,64.720000000,64.850000000,8,9,5,6,64.710000000,64.860000000,8,4,7,3,64.700000000,64.870000000,7,4,6,3,64.690000000,64.880000000,4,4,3,3,MCLN5
2025-06-11T00:00:04.211918177Z,2025-06-11T00:00:04.209314115Z,10,1,42026514,M,A,3,64.820000000,1,130,12232,79296797,64.780000000,64.790000000,2,2,2,1,64.770000000,64.800000000,9,4,5,4,64.760000000,64.810000000,8,3,8,3,64.750000000,64.820000000,7,10,7,7,64.740000000,64.830000000,11,9,10,9,64.730000000,64.840000000,6,5,6,4,64.720000000,64.850000000,8,9,5,6,64.710000000,64.860000000,8,4,7,3,64.700000000,64.870000000,7,4,6,3,64.690000000,64.880000000,4,4,3,3,MCLN5
2025-06-11T00:00:04.211927718Z,2025-06-11T00:00:04.209314615Z,10,1,42026514,M,B,3,64.740000000,1,130,12191,79296798,64.780000000,64.790000000,2,2,2,1,64.770000000,64.800000000,9,4,5,4,64.760000000,64.810000000,8,3,8,3,64.750000000,64.820000000,6,10,6,7,64.740000000,64.830000000,12,9,11,9,64.730000000,64.840000000,6,5,6,4,64.720000000,64.850000000,8,9,5,6,64.710000000,64.860000000,8,4,7,3,64.700000000,64.870000000,7,4,6,3,64.690000000,64.880000000,4,4,3,3,MCLN5
2025-06-11T00:00:04.211937136Z,2025-06-11T00:00:04.209315095Z,10,1,42026514,M,A,3,64.820000000,1,130,12091,79296799,64.780000000,64.790000000,2,2,2,1,64.770000000,64.800000000,9,4,5,4,64.760000000,64.810000000,8,3,8,3,64.750000000,64.820000000,6,11,6,8,64.740000000,64.830000000,12,8,11,8,64.730000000,64.840000000,6,5,6,4,64.720000000,64.850000000,8,9,5,6,64.710000000,64.860000000,8,4,7,3,64.700000000,64.870000000,7,4,6,3,64.690000000,64.880000000,4,4,3,3,MCLN5
2025-06-11T00:00:04.212329185Z,2025-06-11T00:00:04.209916355Z,10,1,42025623,M,A,1,63.720000000,1,130,12198,79296827,63.700000000,63.710000000,1,1,1,1,63.690000000,63.720000000,3,4,3,4,63.680000000,63.730000000,1,2,1,2,63.670000000,63.740000000,3,3,3,3,63.660000000,63.750000000,3,4,3,4,63.650000000,63.760000000,6,4,6,4,63.640000000,63.770000000,5,1,5,1,63.630000000,63.780000000,4,5,4,5,63.620000000,63.790000000,3,1,3,1,63.610000000,63.800000000,2,3,2,3,MCLQ5
2025-06-11T00:00:04.212677163Z,2025-06-11T00:00:04.210792471Z,10,1,42025623,M,B,5,63.640000000,1,130,12056,79296857,63.700000000,63.710000000,1,1,1,1,63.690000000,63.720000000,3,4,3,4,63.680000000,63.730000000,1,2,1,2,63.670000000,63.740000000,3,3,3,3,63.660000000,63.750000000,3,4,3,4,63.650000000,63.760000000,5,4,5,4,63.640000000,63.770000000,6,1,6,1,63.630000000,63.780000000,4,5,4,5,63.620000000,63.790000000,3,1,3,1,63.610000000,63.800000000,2,3,2,3,MCLQ5
2025-06-11T00:00:04.212688620Z,2025-06-11T00:00:04.210793141Z,10,1,42025623,M,A,4,63.750000000,1,130,14601,79296858,63.700000000,63.710000000,1,1,1,1,63.690000000,63.720000000,3,4,3,4,63.680000000,63.730000000,1,2,1,2,63.670000000,63.740000000,3,3,3,3,63.660000000,63.750000000,3,5,3,5,63.650000000,63.760000000,5,3,5,3,63.640000000,63.770000000,6,1,6,1,63.630000000,63.780000000,4,5,4,5,63.620000000,63.790000000,3,1,3,1,63.610000000,63.800000000,2,3,2,3,MCLQ5
2025-06-11T00:00:04.212753022Z,2025-06-11T00:00:04.210929321Z,10,1,42026514,M,A,2,64.810000000,1,130,11550,79296863,64.780000000,64.790000000,2,2,2,1,64.770000000,64.800000000,9,4,5,4,64.760000000,64.810000000,8,4,8,4,64.750000000,64.820000000,6,11,6,8,64.740000000,64.830000000,12,8,11,8,64.730000000,64.840000000,6,5,6,4,64.720000000,64.850000000,8,9,5,6,64.710000000,64.860000000,8,4,7,3,64.700000000,64.870000000,7,4,6,3,64.690000000,64.880000000,4,4,3,3,MCLN5
2025-06-11T00:00:04.212853148Z,2025-06-11T00:00:04.211400621Z,10,1,42026514,M,A,3,64.830000000,1,130,11437,79296870,64.780000000,64.790000000,2,2,2,1,64.770000000,64.800000000,9,4,5,4,64.760000000,64.810000000,8,4,8,4,64.750000000,64.820000000,6,10,6,7,64.740000000,64.830000000,12,9,11,9,64.730000000,64.840000000,6,5,6,4,64.720000000,64.850000000,8,9,5,6,64.710000000,64.860000000,8,4,7,3,64.700000000,64.870000000,7,4,6,3,64.690000000,64.880000000,4,4,3,3,MCLN5
2025-06-11T00:00:04.212863116Z,2025-06-11T00:00:04.211401083Z,10,1,42026514,M,B,3,64.750000000,1,130,11422,79296871,64.780000000,64.790000000,2,2,2,1,64.770000000,64.800000000,9,4,5,4,64.760000000,64.810000000,8,4,8,4,64.750000000,64.820000000,7,10,7,7,64.740000000,64.830000000,11,9,10,9,64.730000000,64.840000000,6,5,6,4,64.720000000,64.850000000,8,9,5,6,64.710000000,64.860000000,8,4,7,3,64.700000000,64.870000000,7,4,6,3,64.690000000,64.880000000,4,4,3,3,MCLN5
2025-06-11T00:00:04.212874375Z,2025-06-11T00:00:04.211401639Z,10,1,42026514,M,A,3,64.830000000,1,130,12054,79296872,64.780000000,64.790000000,2,2,2,1,64.770000000,64.800000000,9,4,5,4,64.760000000,64.810000000,8,4,8,4,64.750000000,64.820000000,7,9,7,6,64.740000000,64.830000000,11,10,10,10,64.730000000,64.840000000,6,5,6,4,64.720000000,64.850000000,8,9,5,6,64.710000000,64.860000000,8,4,7,3,64.700000000,64.870000000,7,4,6,3,64.690000000,64.880000000,4,4,3,3,MCLN5
2025-06-11T00:00:04.212883843Z,2025-06-11T00:00:04.211402101Z,10,1,42026514,M,B,3,64.750000000,1,130,11759,79296873,64.780000000,64.790000000,2,2,2,1,64.770000000,64.800000000,9,4,5,4,64.760000000,64.810000000,8,4,8,4,64.750000000,64.820000000,8,9,8,6,64.740000000,64.830000000,10,10,9,10,64.730000000,64.840000000,6,5,6,4,64.720000000,64.850000000,8,9,5,6,64.710000000,64.860000000,8,4,7,3,64.700000000,64.870000000,7,4,6,3,64.690000000,64.880000000,4,4,3,3,MCLN5
2025-06-11T00:00:04.213337439Z,2025-06-11T00:00:04.211777023Z,10,1,42418117,M,B,0,3.230000000,1,130,12102,79296905,3.250000000,3.280000000,11,1,2,1,3.240000000,3.290000000,1,11,1,2,3.230000000,3.300000000,1,1,1,1,,,0,0,0,0,,,0,0,0,0,,,0,0,0,0,,,0,0,0,0,,,0,0,0,0,,,0,0,0,0,,,0,0,0,0,MCLN5-MCLX5
2025-06-11T00:00:04.214094393Z,2025-06-11T00:00:04.212002131Z,10,1,42026514,M,B,3,64.740000000,1,130,11508,79296966,64.780000000,64.790000000,2,2,2,1,64.770000000,64.800000000,9,4,5,4,64.760000000,64.810000000,8,4,8,4,64.750000000,64.820000000,7,9,7,6,64.740000000,64.830000000,11,10,10,10,64.730000000,64.840000000,6,5,6,4,64.720000000,64.850000000,8,9,5,6,64.710000000,64.860000000,8,4,7,3,64.700000000,64.870000000,7,4,6,3,64.690000000,64.880000000,4,4,3,3,MCLN5
2025-06-11T00:00:04.214108332Z,2025-06-11T00:00:04.212003035Z,10,1,42026514,M,B,3,64.740000000,1,130,15860,79296967,64.780000000,64.790000000,2,2,2,1,64.770000000,64.800000000,9,4,5,4,64.760000000,64.810000000,8,4,8,4,64.750000000,64.820000000,6,9,6,6,64.740000000,64.830000000,12,10,11,10,64.730000000,64.840000000,6,5,6,4,64.720000000,64.850000000,8,9,5,6,64.710000000,64.860000000,8,4,7,3,64.700000000,64.870000000,7,4,6,3,64.690000000,64.880000000,4,4,3,3,MCLN5
2025-06-11T00:00:04.214142553Z,2025-06-11T00:00:04.212007085Z,10,1,42026514,A,A,0,64.790000000,2,130,13816,79296969,64.780000000,64.790000000,2,4,2,2,64.770000000,64.800000000,9,4,5,4,64.760000000,64.810000000,8,4,8,4,64.750000000,64.820000000,6,9,6,6,64.740000000,64.830000000,12,10,11,10,64.730000000,64.840000000,6,5,6,4,64.720000000,64.850000000,8,9,5,6,64.710000000,64.860000000,8,4,7,3,64.700000000,64.870000000,7,4,6,3,64.690000000,64.880000000,4,4,3,3,MCLN5
2025-06-11T00:00:04.215467513Z,2025-06-11T00:00:04.212851521Z,10,1,42025623,M,B,1,62.320000000,1,130,16379,79297058,63.700000000,63.710000000,1,1,1,1,63.690000000,63.720000000,2,4,2,4,63.680000000,63.730000000,1,2,1,2,63.670000000,63.740000000,3,3,3,3,63.660000000,63.750000000,3,5,3,5,63.650000000,63.760000000,5,3,5,3,63.640000000,63.770000000,6,1,6,1,63.630000000,63.780000000,4,5,4,5,63.620000000,63.790000000,3,1,3,1,63.610000000,63.800000000,2,3,2,3,MCLQ5
2025-06-11T00:00:04.215886197Z,2025-06-11T00:00:04.213263093Z,10,1,42025623,C,B,1,63.690000000,1,130,15796,79297087,63.700000000,63.710000000,1,1,1,1,63.690000000,63.720000000,1,4,1,4,63.680000000,63.730000000,1,2,1,2,63.670000000,63.740000000,3,3,3,3,63.660000000,63.750000000,3,5,3,5,63.650000000,63.760000000,5,3,5,3,63.640000000,63.770000000,6,1,6,1,63.630000000,63.780000000,4,5,4,5,63.620000000,63.790000000,3,1,3,1,63.610000000,63.800000000,2,3,2,3,MCLQ5
2025-06-11T00:00:04.216621573Z,2025-06-11T00:00:04.213845403Z,10,1,42022708,M,B,0,2.780000000,1,130,11834,79297143,2.810000000,2.830000000,1,2,1,2,2.800000000,2.840000000,12,12,3,3,2.790000000,2.850000000,2,1,2,1,2.780000000,2.870000000,1,1,1,1,,,0,0,0,0,,,0,0,0,0,,,0,0,0,0,,,0,0,0,0,,,0,0,0,0,,,0,0,0,0,MCLN5-MCLV5
2025-06-11T00:00:04.217230979Z,2025-06-11T00:00:04.214724167Z,10,1,42026514,M,A,5,64.840000000,1,130,11707,79297192,64.780000000,64.790000000,2,4,2,2,64.770000000,64.800000000,9,4,5,4,64.760000000,64.810000000,8,4,8,4,64.750000000,64.820000000,6,9,6,6,64.740000000,64.830000000,12,10,11,10,64.730000000,64.840000000,6,6,6,5,64.720000000,64.850000000,8,9,5,6,64.710000000,64.860000000,8,4,7,3,64.700000000,64.870000000,7,4,6,3,64.690000000,64.880000000,4,4,3,3,MCLN5
2025-06-11T00:00:04.217419336Z,2025-06-11T00:00:04.214790713Z,10,1,42026514,C,B,0,64.780000000,1,130,18684,79297200,64.780000000,64.790000000,1,4,1,2,64.770000000,64.800000000,9,4,5,4,64.760000000,64.810000000,8,4,8,4,64.750000000,64.820000000,6,9,6,6,64.740000000,64.830000000,12,10,11,10,64.730000000,64.840000000,6,6,6,5,64.720000000,64.850000000,8,9,5,6,64.710000000,64.860000000,8,4,7,3,64.700000000,64.870000000,7,4,6,3,64.690000000,64.880000000,4,4,3,3,MCLN5
2025-06-11T00:00:04.217950257Z,2025-06-11T00:00:04.215766855Z,10,1,42026514,A,A,0,64.790000000,1,130,12993,79297243,64.780000000,64.790000000,1,5,1,3,64.770000000,64.800000000,9,4,5,4,64.760000000,64.810000000,8,4,8,4,64.750000000,64.820000000,6,9,6,6,64.740000000,64.830000000,12,10,11,10,64.730000000,64.840000000,6,6,6,5,64.720000000,64.850000000,8,9,5,6,64.710000000,64.860000000,8,4,7,3,64.700000000,64.870000000,7,4,6,3,64.690000000,64.880000000,4,4,3,3,MCLN5
2025-06-11T00:00:04.218142593Z,2025-06-11T00:00:04.216024719Z,10,1,42026514,C,B,0,64.780000000,1,130,11656,79297257,64.770000000,64.790000000,9,5,5,3,64.760000000,64.800000000,8,4,8,4,64.750000000,64.810000000,6,4,6,4,64.740000000,64.820000000,12,9,11,6,64.730000000,64.830000000,6,10,6,10,64.720000000,64.840000000,8,6,5,5,64.710000000,64.850000000,8,9,7,6,64.700000000,64.860000000,7,4,6,3,64.690000000,64.870000000,4,4,3,3,64.680000000,64.880000000,4,4,2,3,MCLN5
2025-06-11T00:00:04.219621361Z,2025-06-11T00:00:04.217432363Z,10,1,42026514,C,A,0,64.790000000,1,130,11515,79297377,64.770000000,64.790000000,9,4,5,2,64.760000000,64.800000000,8,4,8,4,64.750000000,64.810000000,6,4,6,4,64.740000000,64.820000000,12,9,11,6,64.730000000,64.830000000,6,10,6,10,64.720000000,64.840000000,8,6,5,5,64.710000000,64.850000000,8,9,7,6,64.700000000,64.860000000,7,4,6,3,64.690000000,64.870000000,4,4,3,3,64.680000000,64.880000000,4,4,2,3,MCLN5
2025-06-11T00:00:04.220005333Z,2025-06-11T00:00:04.217966789Z,10,1,42025623,T,A,0,63.700000000,1,0,11481,79297411,63.700000000,63.710000000,1,1,1,1,63.690000000,63.720000000,1,4,1,4,63.680000000,63.730000000,1,2,1,2,63.670000000,63.740000000,3,3,3,3,63.660000000,63.750000000,3,5,3,5,63.650000000,63.760000000,5,3,5,3,63.640000000,63.770000000,6,1,6,1,63.630000000,63.780000000,4,5,4,5,63.620000000,63.790000000,3,1,3,1,63.610000000,63.800000000,2,3,2,3,MCLQ5
2025-06-11T00:00:04.220025047Z,2025-06-11T00:00:04.217966789Z,10,1,42025623,C,B,0,63.700000000,1,130,15230,79297412,63.690000000,63.710000000,1,1,1,1,63.680000000,63.720000000,1,4,1,4,63.670000000,63.730000000,3,2,3,2,63.660000000,63.740000000,3,3,3,3,63.650000000,63.750000000,5,5,5,5,63.640000000,63.760000000,6,3,6,3,63.630000000,63.770000000,4,1,4,1,63.620000000,63.780000000,3,5,3,5,63.610000000,63.790000000,2,1,2,1,63.600000000,63.800000000,6,3,6,3,MCLQ5
2025-06-11T00:00:04.220238347Z,2025-06-11T00:00:04.218414917Z,10,1,42026514,A,A,0,64.780000000,1,130,14893,79297429,64.770000000,64.780000000,9,1,5,1,64.760000000,64.790000000,8,4,8,2,64.750000000,64.800000000,6,4,6,4,64.740000000,64.810000000,12,4,11,4,64.730000000,64.820000000,6,9,6,6,64.720000000,64.830000000,8,10,5,10,64.710000000,64.840000000,8,6,7,5,64.700000000,64.850000000,7,9,6,6,64.690000000,64.860000000,4,4,3,3,64.680000000,64.870000000,4,4,2,3,MCLN5
2025-06-11T00:00:04.220407014Z,2025-06-11T00:00:04.218866845Z,10,1,42025623,M,B,2,62.310000000,1,130,13031,79297442,63.690000000,63.710000000,1,1,1,1,63.680000000,63.720000000,1,4,1,4,63.670000000,63.730000000,2,2,2,2,63.660000000,63.740000000,3,3,3,3,63.650000000,63.750000000,5,5,5,5,63.640000000,63.760000000,6,3,6,3,63.630000000,63.770000000,4,1,4,1,63.620000000,63.780000000,3,5,3,5,63.610000000,63.790000000,2,1,2,1,63.600000000,63.800000000,6,3,6,3,MCLQ5
2025-06-11T00:00:04.220726209Z,2025-06-11T00:00:04.219664341Z,10,1,42026514,C,A,0,64.780000000,1,130,11573,79297473,64.770000000,64.790000000,9,4,5,2,64.760000000,64.800000000,8,4,8,4,64.750000000,64.810000000,6,4,6,4,64.740000000,64.820000000,12,9,11,6,64.730000000,64.830000000,6,10,6,10,64.720000000,64.840000000,8,6,5,5,64.710000000,64.850000000,8,9,7,6,64.700000000,64.860000000,7,4,6,3,64.690000000,64.870000000,4,4,3,3,64.680000000,64.880000000,4,4,2,3,MCLN5
2025-06-11T00:00:04.220747820Z,2025-06-11T00:00:04.219733841Z,10,1,42026514,M,A,1,66.750000000,2,130,12978,79297475,64.770000000,64.790000000,9,4,5,2,64.760000000,64.800000000,8,3,8,3,64.750000000,64.810000000,6,4,6,4,64.740000000,64.820000000,12,9,11,6,64.730000000,64.830000000,6,10,6,10,64.720000000,64.840000000,8,6,5,5,64.710000000,64.850000000,8,9,7,6,64.700000000,64.860000000,7,4,6,3,64.690000000,64.870000000,4,4,3,3,64.680000000,64.880000000,4,4,2,3,MCLN5
2025-06-11T00:00:04.220888640Z,2025-06-11T00:00:04.220014457Z,10,1,42025623,C,B,5,63.640000000,1,130,11932,79297487,63.690000000,63.710000000,1,1,1,1,63.680000000,63.720000000,1,4,1,4,63.670000000,63.730000000,2,2,2,2,63.660000000,63.740000000,3,3,3,3,63.650000000,63.750000000,5,5,5,5,63.640000000,63.760000000,5,3,5,3,63.630000000,63.770000000,4,1,4,1,63.620000000,63.780000000,3,5,3,5,63.610000000,63.790000000,2,1,2,1,63.600000000,63.800000000,6,3,6,3,MCLQ5
2025-06-11T00:00:04.220899568Z,2025-06-11T00:00:04.220037129Z,10,1,42026514,C,B,4,64.730000000,1,130,12150,79297488,64.770000000,64.790000000,9,4,5,2,64.760000000,64.800000000,8,3,8,3,64.750000000,64.810000000,6,4,6,4,64.740000000,64.820000000,12,9,11,6,64.730000000,64.830000000,5,10,5,10,64.720000000,64.840000000,8,6,5,5,64.710000000,64.850000000,8,9,7,6,64.700000000,64.860000000,7,4,6,3,64.690000000,64.870000000,4,4,3,3,64.680000000,64.880000000,4,4,2,3,MCLN5
2025-06-11T00:00:04.221007175Z,2025-06-11T00:00:04.220187403Z,10,1,42025611,M,A,0,2.090000000,20,130,11685,79297496,2.070000000,2.090000000,3,27,2,6,2.060000000,2.100000000,23,27,3,6,2.050000000,2.110000000,23,23,3,4,2.040000000,2.120000000,23,2,3,1,2.030000000,2.130000000,2,2,1,2,2.020000000,2.140000000,2,2,2,1,2.010000000,2.150000000,2,2,1,1,2.000000000,2.160000000,2,2,2,1,1.990000000,2.170000000,2,2,1,1,1.980000000,2.180000000,2,2,2,2,MCLN5-MCLU5
2025-06-11T00:00:04.221015830Z,2025-06-11T00:00:04.220266579Z,10,1,42405621,M,A,0,3.770000000,10,130,11393,79297497,3.000000000,3.770000000,10,10,1,1,,,0,0,0,0,,,0,0,0,0,,,0,0,0,0,,,0,0,0,0,,,0,0,0,0,,,0,0,0,0,,,0,0,0,0,,,0,0,0,0,,,0,0,0,0,MCLN5-MCLK6
2025-06-11T00:00:04.221318859Z,2025-06-11T00:00:04.220757271Z,10,1,42405621,M,A,0,3.780000000,10,130,11515,79297520,3.000000000,3.780000000,10,10,1,1,,,0,0,0,0,,,0,0,0,0,,,0,0,0,0,,,0,0,0,0,,,0,0,0,0,,,0,0,0,0,,,0,0,0,0,,,0,0,0,0,,,0,0,0,0,MCLN5-MCLK6
2025-06-11T00:00:04.221380749Z,2025-06-11T00:00:04.220886463Z,10,1,42025623,M,A,1,65.090000000,1,130,11951,79297525,63.690000000,63.710000000,1,1,1,1,63.680000000,63.720000000,1,3,1,3,63.670000000,63.730000000,2,2,2,2,63.660000000,63.740000000,3,3,3,3,63.650000000,63.750000000,5,5,5,5,63.640000000,63.760000000,5,3,5,3,63.630000000,63.770000000,4,1,4,1,63.620000000,63.780000000,3,5,3,5,63.610000000,63.790000000,2,1,2,1,63.600000000,63.800000000,6,3,6,3,MCLQ5
2025-06-11T00:00:04.221428600Z,2025-06-11T00:00:04.220937973Z,10,1,42026514,M,A,1,64.800000000,1,130,12580,79297528,64.770000000,64.790000000,9,4,5,2,64.760000000,64.800000000,8,4,8,4,64.750000000,64.810000000,6,4,6,4,64.740000000,64.820000000,12,9,11,6,64.730000000,64.830000000,5,10,5,10,64.720000000,64.840000000,8,6,5,5,64.710000000,64.850000000,8,9,7,6,64.700000000,64.860000000,7,4,6,3,64.690000000,64.870000000,4,4,3,3,64.680000000,64.880000000,4,4,2,3,MCLN5
2025-06-11T00:00:04.221510419Z,2025-06-11T00:00:04.221072637Z,10,1,42405621,M,A,0,3.760000000,10,130,11433,79297535,3.000000000,3.760000000,10,10,1,1,,,0,0,0,0,,,0,0,0,0,,,0,0,0,0,,,0,0,0,0,,,0,0,0,0,,,0,0,0,0,,,0,0,0,0,,,0,0,0,0,,,0,0,0,0,MCLN5-MCLK6
2025-06-11T00:00:04.221574598Z,2025-06-11T00:00:04.221325431Z,10,1,42405621,M,A,0,3.770000000,10,130,11740,79297539,3.000000000,3.770000000,10,10,1,1,,,0,0,0,0,,,0,0,0,0,,,0,0,0,0,,,0,0,0,0,,,0,0,0,0,,,0,0,0,0,,,0,0,0,0,,,0,0,0,0,,,0,0,0,0,MCLN5-MCLK6
2025-06-11T00:00:04.221596385Z,2025-06-11T00:00:04.221393549Z,10,1,42026514,A,B,0,64.780000000,1,130,14900,79297540,64.780000000,64.790000000,1,4,1,2,64.770000000,64.800000000,9,4,5,4,64.760000000,64.810000000,8,4,8,4,64.750000000,64.820000000,6,9,6,6,64.740000000,64.830000000,12,10,11,10,64.730000000,64.840000000,5,6,5,5,64.720000000,64.850000000,8,9,5,6,64.710000000,64.860000000,8,4,7,3,64.700000000,64.870000000,7,4,6,3,64.690000000,64.880000000,4,4,3,3,MCLN5
2025-06-11T00:00:04.221923566Z,2025-06-11T00:00:04.221752517Z,10,1,42026514,M,A,1,66.740000000,2,130,15031,79297548,64.780000000,64.790000000,1,4,1,2,64.770000000,64.800000000,9,3,5,3,64.760000000,64.810000000,8,4,8,4,64.750000000,64.820000000,6,9,6,6,64.740000000,64.830000000,12,10,11,10,64.730000000,64.840000000,5,6,5,5,64.720000000,64.850000000,8,9,5,6,64.710000000,64.860000000,8,4,7,3,64.700000000,64.870000000,7,4,6,3,64.690000000,64.880000000,4,4,3,3,MCLN5
2025-06-11T00:00:04.233782445Z,2025-06-11T00:00:04.233671139Z,10,1,42026514,A,B,5,64.730000000,1,130,15081,79297604,64.780000000,64.790000000,1,4,1,2,64.770000000,64.800000000,9,3,5,3,64.760000000,64.810000000,8,4,8,4,64.750000000,64.820000000,6,9,6,6,64.740000000,64.830000000,12,10,11,10,64.730000000,64.840000000,6,6,6,5,64.720000000,64.850000000,8,9,5,6,64.710000000,64.860000000,8,4,7,3,64.700000000,64.870000000,7,4,6,3,64.690000000,64.880000000,4,4,3,3,MCLN5
2025-06-11T00:00:04.233792213Z,2025-06-11T00:00:04.233673211Z,10,1,42025623,A,B,6,63.630000000,1,130,11840,79297605,63.690000000,63.710000000,1,1,1,1,63.680000000,63.720000000,1,3,1,3,63.670000000,63.730000000,2,2,2,2,63.660000000,63.740000000,3,3,3,3,63.650000000,63.750000000,5,5,5,5,63.640000000,63.760000000,5,3,5,3,63.630000000,63.770000000,5,1,5,1,63.620000000,63.780000000,3,5,3,5,63.610000000,63.790000000,2,1,2,1,63.600000000,63.800000000,6,3,6,3,MCLQ5
2025-06-11T00:00:04.233802742Z,2025-06-11T00:00:04.233675841Z,10,1,42025623,C,A,7,63.780000000,1,130,11519,79297606,63.690000000,63.710000000,1,1,1,1,63.680000000,63.720000000,1,3,1,3,63.670000000,63.730000000,2,2,2,2,63.660000000,63.740000000,3,3,3,3,63.650000000,63.750000000,5,5,5,5,63.640000000,63.760000000,5,3,5,3,63.630000000,63.770000000,5,1,5,1,63.620000000,63.780000000,3,4,3,4,63.610000000,63.790000000,2,1,2,1,63.600000000,63.800000000,6,3,6,3,MCLQ5
2025-06-11T00:00:04.233936851Z,2025-06-11T00:00:04.233839305Z,10,1,42025623,A,A,6,63.770000000,1,130,14792,79297607,63.690000000,63.710000000,1,1,1,1,63.680000000,63.720000000,1,3,1,3,63.670000000,63.730000000,2,2,2,2,63.660000000,63.740000000,3,3,3,3,63.650000000,63.750000000,5,5,5,5,63.640000000,63.760000000,5,3,5,3,63.630000000,63.770000000,5,2,5,2,63.620000000,63.780000000,3,4,3,4,63.610000000,63.790000000,2,1,2,1,63.600000000,63.800000000,6,3,6,3,MCLQ5
2025-06-11T00:00:04.234067673Z,2025-06-11T00:00:04.233946915Z,10,1,42026514,C,B,0,64.780000000,1,130,14256,79297608,64.770000000,64.790000000,9,4,5,2,64.760000000,64.800000000,8,3,8,3,64.750000000,64.810000000,6,4,6,4,64.740000000,64.820000000,12,9,11,6,64.730000000,64.830000000,6,10,6,10,64.720000000,64.840000000,8,6,5,5,64.710000000,64.850000000,8,9,7,6,64.700000000,64.860000000,7,4,6,3,64.690000000,64.870000000,4,4,3,3,64.680000000,64.880000000,4,4,2,3,MCLN5
2025-06-11T00:00:04.234185593Z,2025-06-11T00:00:04.234076029Z,10,1,42026514,C,B,4,64.730000000,1,130,14270,79297611,64.770000000,64.790000000,9,4,5,2,64.760000000,64.800000000,8,3,8,3,64.750000000,64.810000000,6,4,6,4,64.740000000,64.820000000,12,9,11,6,64.730000000,64.830000000,5,10,5,10,64.720000000,64.840000000,8,6,5,5,64.710000000,64.850000000,8,9,7,6,64.700000000,64.860000000,7,4,6,3,64.690000000,64.870000000,4,4,3,3,64.680000000,64.880000000,4,4,2,3,MCLN5
2025-06-11T00:00:04.234318312Z,2025-06-11T00:00:04.234209713Z,10,1,42026514,M,A,1,64.800000000,1,130,15005,79297612,64.770000000,64.790000000,9,4,5,2,64.760000000,64.800000000,8,4,8,4,64.750000000,64.810000000,6,4,6,4,64.740000000,64.820000000,12,9,11,6,64.730000000,64.830000000,5,10,5,10,64.720000000,64.840000000,8,6,5,5,64.710000000,64.850000000,8,9,7,6,64.700000000,64.860000000,7,4,6,3,64.690000000,64.870000000,4,4,3,3,64.680000000,64.880000000,4,4,2,3,MCLN5
2025-06-11T00:00:04.245157425Z,2025-06-11T00:00:04.245042123Z,10,1,42026514,A,B,5,64.720000000,1,130,11211,79297655,64.770000000,64.790000000,9,4,5,2,64.760000000,64.800000000,8,4,8,4,64.750000000,64.810000000,6,4,6,4,64.740000000,64.820000000,12,9,11,6,64.730000000,64.830000000,5,10,5,10,64.720000000,64.840000000,9,6,6,5,64.710000000,64.850000000,8,9,7,6,64.700000000,64.860000000,7,4,6,3,64.690000000,64.870000000,4,4,3,3,64.680000000,64.880000000,4,4,2,3,MCLN5
2025-06-11T00:00:04.245167547Z,2025-06-11T00:00:04.245044121Z,10,1,42026514,C,A,6,64.850000000,1,130,11135,79297656,64.770000000,64.790000000,9,4,5,2,64.760000000,64.800000000,8,4,8,4,64.750000000,64.810000000,6,4,6,4,64.740000000,64.820000000,12,9,11,6,64.730000000,64.830000000,5,10,5,10,64.720000000,64.840000000,9,6,6,5,64.710000000,64.850000000,8,8,7,5,64.700000000,64.860000000,7,4,6,3,64.690000000,64.870000000,4,4,3,3,64.680000000,64.880000000,4,4,2,3,MCLN5
2025-06-11T00:00:04.245266491Z,2025-06-11T00:00:04.245171297Z,10,1,42026514,A,A,5,64.840000000,1,130,15134,79297657,64.770000000,64.790000000,9,4,5,2,64.760000000,64.800000000,8,4,8,4,64.750000000,64.810000000,6,4,6,4,64.740000000,64.820000000,12,9,11,6,64.730000000,64.830000000,5,10,5,10,64.720000000,64.840000000,9,7,6,6,64.710000000,64.850000000,8,8,7,5,64.700000000,64.860000000,7,4,6,3,64.690000000,64.870000000,4,4,3,3,64.680000000,64.880000000,4,4,2,3,MCLN5
2025-06-11T00:00:04.336666499Z,2025-06-11T00:00:04.336533029Z,10,1,42026514,A,B,0,64.780000000,1,130,15717,79297766,64.780000000,64.790000000,1,4,1,2,64.770000000,64.800000000,9,4,5,4,64.760000000,64.810000000,8,4,8,4,64.750000000,64.820000000,6,9,6,6,64.740000000,64.830000000,12,10,11,10,64.730000000,64.840000000,5,7,5,6,64.720000000,64.850000000,9,8,6,5,64.710000000,64.860000000,8,4,7,3,64.700000000,64.870000000,7,4,6,3,64.690000000,64.880000000,4,4,3,3,MCLN5
2025-06-11T00:00:04.336767117Z,2025-06-11T00:00:04.336674411Z,10,1,42026514,C,A,5,64.840000000,1,130,14651,79297767,64.780000000,64.790000000,1,4,1,2,64.770000000,64.800000000,9,4,5,4,64.760000000,64.810000000,8,4,8,4,64.750000000,64.820000000,6,9,6,6,64.740000000,64.830000000,12,10,11,10,64.730000000,64.840000000,5,6,5,5,64.720000000,64.850000000,9,8,6,5,64.710000000,64.860000000,8,4,7,3,64.700000000,64.870000000,7,4,6,3,64.690000000,64.880000000,4,4,3,3,MCLN5
2025-06-11T00:00:04.336962601Z,2025-06-11T00:00:04.336858223Z,10,1,42026514,M,A,1,66.760000000,2,130,15195,79297768,64.780000000,64.790000000,1,4,1,2,64.770000000,64.800000000,9,3,5,3,64.760000000,64.810000000,8,4,8,4,64.750000000,64.820000000,6,9,6,6,64.740000000,64.830000000,12,10,11,10,64.730000000,64.840000000,5,6,5,5,64.720000000,64.850000000,9,8,6,5,64.710000000,64.860000000,8,4,7,3,64.700000000,64.870000000,7,4,6,3,64.690000000,64.880000000,4,4,3,3,MCLN5
2025-06-11T00:00:04.349069845Z,2025-06-11T00:00:04.348968953Z,10,1,42026514,C,B,6,64.720000000,1,130,14930,79297794,64.780000000,64.790000000,1,4,1,2,64.770000000,64.800000000,9,3,5,3,64.760000000,64.810000000,8,4,8,4,64.750000000,64.820000000,6,9,6,6,64.740000000,64.830000000,12,10,11,10,64.730000000,64.840000000,5,6,5,5,64.720000000,64.850000000,8,8,5,5,64.710000000,64.860000000,8,4,7,3,64.700000000,64.870000000,7,4,6,3,64.690000000,64.880000000,4,4,3,3,MCLN5
2025-06-11T00:00:04.349081365Z,2025-06-11T00:00:04.348971891Z,10,1,42026514,A,A,6,64.850000000,1,130,11331,79297795,64.780000000,64.790000000,1,4,1,2,64.770000000,64.800000000,9,3,5,3,64.760000000,64.810000000,8,4,8,4,64.750000000,64.820000000,6,9,6,6,64.740000000,64.830000000,12,10,11,10,64.730000000,64.840000000,5,6,5,5,64.720000000,64.850000000,8,9,5,6,64.710000000,64.860000000,8,4,7,3,64.700000000,64.870000000,7,4,6,3,64.690000000,64.880000000,4,4,3,3,MCLN5
2025-06-11T00:00:04.349196006Z,2025-06-11T00:00:04.349098181Z,10,1,42026514,A,B,5,64.730000000,1,130,15020,79297796,64.780000000,64.790000000,1,4,1,2,64.770000000,64.800000000,9,3,5,3,64.760000000,64.810000000,8,4,8,4,64.750000000,64.820000000,6,9,6,6,64.740000000,64.830000000,12,10,11,10,64.730000000,64.840000000,6,6,6,5,64.720000000,64.850000000,8,9,5,6,64.710000000,64.860000000,8,4,7,3,64.700000000,64.870000000,7,4,6,3,64.690000000,64.880000000,4,4,3,3,MCLN5
2025-06-11T00:00:04.426459726Z,2025-06-11T00:00:04.426336789Z,10,1,42284507,A,B,1,0.980000000,4,130,15432,79297952,0.990000000,1.000000000,12,5,6,3,0.980000000,1.010000000,23,25,7,8,0.970000000,1.020000000,21,18,6,5,0.960000000,1.030000000,17,23,6,7,0.950000000,1.040000000,10,15,6,4,0.940000000,1.050000000,4,8,3,4,0.930000000,1.060000000,3,4,2,2,0.920000000,1.070000000,3,2,2,1,0.910000000,1.080000000,3,2,2,1,0.900000000,1.090000000,2,4,1,2,MCLQ5-MCLU5
2025-06-11T00:00:04.426467989Z,2025-06-11T00:00:04.426339705Z,10,1,42022708,M,A,0,2.830000000,10,130,11521,79297953,2.810000000,2.830000000,1,12,1,3,2.800000000,2.840000000,12,2,3,2,2.790000000,2.850000000,2,1,2,1,2.780000000,2.870000000,1,1,1,1,,,0,0,0,0,,,0,0,0,0,,,0,0,0,0,,,0,0,0,0,,,0,0,0,0,,,0,0,0,0,MCLN5-MCLV5
2025-06-11T00:00:04.426755536Z,2025-06-11T00:00:04.426643937Z,10,1,42022708,M,A,0,2.840000000,10,130,11967,79297970,2.810000000,2.830000000,1,2,1,2,2.800000000,2.840000000,12,12,3,3,2.790000000,2.850000000,2,1,2,1,2.780000000,2.870000000,1,1,1,1,,,0,0,0,0,,,0,0,0,0,,,0,0,0,0,,,0,0,0,0,,,0,0,0,0,,,0,0,0,0,MCLN5-MCLV5
2025-06-11T00:00:04.462428367Z,2025-06-11T00:00:04.462310353Z,10,1,42026514,C,B,0,64.780000000,1,130,15382,79298034,64.770000000,64.790000000,9,4,5,2,64.760000000,64.800000000,8,3,8,3,64.750000000,64.810000000,6,4,6,4,64.740000000,64.820000000,12,9,11,6,64.730000000,64.830000000,6,10,6,10,64.720000000,64.840000000,8,6,5,5,64.710000000,64.850000000,8,9,7,6,64.700000000,64.860000000,7,4,6,3,64.690000000,64.870000000,4,4,3,3,64.680000000,64.880000000,4,4,2,3,MCLN5
